Workbook

Sheet Data
A1: GM_code | B1: number_of_cars | C1: number_of_vans | D1: number_of_trucks | E1: number_of_buses
A2: GM1680 | B2: =INDEX(Calculation!$A$1:$F$607,MATCH($A2,Calculation!$B:$B,0),MATCH(B$1,Calculation!$1:$1,0)) -> 15568 | C2: =INDEX(Calculation!$A$1:$F$607,MATCH($A2,Calculation!$B:$B,0),MATCH(C$1,Calculation!$1:$1,0)) -> 1826 | D2: =INDEX(Calculation!$A$1:$F$607,MATCH($A2,Calculation!$B:$B,0),MATCH(D$1,Calculation!$1:$1,0)) -> 101 | E2: =INDEX(Calculation!$A$1:$F$607,MATCH($A2,Calculation!$B:$B,0),MATCH(E$1,Calculation!$1:$1,0)) -> 3
A3: GM0358 | B3: =INDEX(Calculation!$A$1:$F$607,MATCH($A3,Calculation!$B:$B,0),MATCH(B$1,Calculation!$1:$1,0)) -> 17396 | C3: =INDEX(Calculation!$A$1:$F$607,MATCH($A3,Calculation!$B:$B,0),MATCH(C$1,Calculation!$1:$1,0)) -> 1963 | D3: =INDEX(Calculation!$A$1:$F$607,MATCH($A3,Calculation!$B:$B,0),MATCH(D$1,Calculation!$1:$1,0)) -> 181 | E3: =INDEX(Calculation!$A$1:$F$607,MATCH($A3,Calculation!$B:$B,0),MATCH(E$1,Calculation!$1:$1,0)) -> 17
A4: GM0197 | B4: =INDEX(Calculation!$A$1:$F$607,MATCH($A4,Calculation!$B:$B,0),MATCH(B$1,Calculation!$1:$1,0)) -> 14912 | C4: =INDEX(Calculation!$A$1:$F$607,MATCH($A4,Calculation!$B:$B,0),MATCH(C$1,Calculation!$1:$1,0)) -> 1763 | D4: =INDEX(Calculation!$A$1:$F$607,MATCH($A4,Calculation!$B:$B,0),MATCH(D$1,Calculation!$1:$1,0)) -> 91 | E4: =INDEX(Calculation!$A$1:$F$607,MATCH($A4,Calculation!$B:$B,0),MATCH(E$1,Calculation!$1:$1,0)) -> 2
A5: GM0059 | B5: =INDEX(Calculation!$A$1:$F$607,MATCH($A5,Calculation!$B:$B,0),MATCH(B$1,Calculation!$1:$1,0)) -> 15604 | C5: =INDEX(Calculation!$A$1:$F$607,MATCH($A5,Calculation!$B:$B,0),MATCH(C$1,Calculation!$1:$1,0)) -> 2554 | D5: =INDEX(Calculation!$A$1:$F$607,MATCH($A5,Calculation!$B:$B,0),MATCH(D$1,Calculation!$1:$1,0)) -> 152 | E5: =INDEX(Calculation!$A$1:$F$607,MATCH($A5,Calculation!$B:$B,0),MATCH(E$1,Calculation!$1:$1,0)) -> 40
A6: GM0482 | B6: =INDEX(Calculation!$A$1:$F$607,MATCH($A6,Calculation!$B:$B,0),MATCH(B$1,Calculation!$1:$1,0)) -> 9531 | C6: =INDEX(Calculation!$A$1:$F$607,MATCH($A6,Calculation!$B:$B,0),MATCH(C$1,Calculation!$1:$1,0)) -> 1210 | D6: =INDEX(Calculation!$A$1:$F$607,MATCH($A6,Calculation!$B:$B,0),MATCH(D$1,Calculation!$1:$1,0)) -> 83 | E6: =INDEX(Calculation!$A$1:$F$607,MATCH($A6,Calculation!$B:$B,0),MATCH(E$1,Calculation!$1:$1,0)) -> 28
A7: GM0613 | B7: =INDEX(Calculation!$A$1:$F$607,MATCH($A7,Calculation!$B:$B,0),MATCH(B$1,Calculation!$1:$1,0)) -> 12936 | C7: =INDEX(Calculation!$A$1:$F$607,MATCH($A7,Calculation!$B:$B,0),MATCH(C$1,Calculation!$1:$1,0)) -> 908 | D7: =INDEX(Calculation!$A$1:$F$607,MATCH($A7,Calculation!$B:$B,0),MATCH(D$1,Calculation!$1:$1,0)) -> 49 | E7: =INDEX(Calculation!$A$1:$F$607,MATCH($A7,Calculation!$B:$B,0),MATCH(E$1,Calculation!$1:$1,0)) -> 4
A8: GM0361 | B8: =INDEX(Calculation!$A$1:$F$607,MATCH($A8,Calculation!$B:$B,0),MATCH(B$1,Calculation!$1:$1,0)) -> 58882 | C8: =INDEX(Calculation!$A$1:$F$607,MATCH($A8,Calculation!$B:$B,0),MATCH(C$1,Calculation!$1:$1,0)) -> 6290 | D8: =INDEX(Calculation!$A$1:$F$607,MATCH($A8,Calculation!$B:$B,0),MATCH(D$1,Calculation!$1:$1,0)) -> 479 | E8: =INDEX(Calculation!$A$1:$F$607,MATCH($A8,Calculation!$B:$B,0),MATCH(E$1,Calculation!$1:$1,0)) -> 20
A9: GM0141 | B9: =INDEX(Calculation!$A$1:$F$607,MATCH($A9,Calculation!$B:$B,0),MATCH(B$1,Calculation!$1:$1,0)) -> 36279 | C9: =INDEX(Calculation!$A$1:$F$607,MATCH($A9,Calculation!$B:$B,0),MATCH(C$1,Calculation!$1:$1,0)) -> 3787 | D9: =INDEX(Calculation!$A$1:$F$607,MATCH($A9,Calculation!$B:$B,0),MATCH(D$1,Calculation!$1:$1,0)) -> 201 | E9: =INDEX(Calculation!$A$1:$F$607,MATCH($A9,Calculation!$B:$B,0),MATCH(E$1,Calculation!$1:$1,0)) -> 5
A10: GM0034 | B10: =INDEX(Calculation!$A$1:$F$607,MATCH($A10,Calculation!$B:$B,0),MATCH(B$1,Calculation!$1:$1,0)) -> 258677 | C10: =INDEX(Calculation!$A$1:$F$607,MATCH($A10,Calculation!$B:$B,0),MATCH(C$1,Calculation!$1:$1,0)) -> 31940 | D10: =INDEX(Calculation!$A$1:$F$607,MATCH($A10,Calculation!$B:$B,0),MATCH(D$1,Calculation!$1:$1,0)) -> 658 | E10: =INDEX(Calculation!$A$1:$F$607,MATCH($A10,Calculation!$B:$B,0),MATCH(E$1,Calculation!$1:$1,0)) -> 21
A11: GM0484 | B11: =INDEX(Calculation!$A$1:$F$607,MATCH($A11,Calculation!$B:$B,0),MATCH(B$1,Calculation!$1:$1,0)) -> 55413 | C11: =INDEX(Calculation!$A$1:$F$607,MATCH($A11,Calculation!$B:$B,0),MATCH(C$1,Calculation!$1:$1,0)) -> 6214 | D11: =INDEX(Calculation!$A$1:$F$607,MATCH($A11,Calculation!$B:$B,0),MATCH(D$1,Calculation!$1:$1,0)) -> 557 | E11: =INDEX(Calculation!$A$1:$F$607,MATCH($A11,Calculation!$B:$B,0),MATCH(E$1,Calculation!$1:$1,0)) -> 33
A12: GM1723 | B12: =INDEX(Calculation!$A$1:$F$607,MATCH($A12,Calculation!$B:$B,0),MATCH(B$1,Calculation!$1:$1,0)) -> 6532 | C12: =INDEX(Calculation!$A$1:$F$607,MATCH($A12,Calculation!$B:$B,0),MATCH(C$1,Calculation!$1:$1,0)) -> 966 | D12: =INDEX(Calculation!$A$1:$F$607,MATCH($A12,Calculation!$B:$B,0),MATCH(D$1,Calculation!$1:$1,0)) -> 56 | E12: =INDEX(Calculation!$A$1:$F$607,MATCH($A12,Calculation!$B:$B,0),MATCH(E$1,Calculation!$1:$1,0)) -> 0
A13: GM1959 | B13: =INDEX(Calculation!$A$1:$F$607,MATCH($A13,Calculation!$B:$B,0),MATCH(B$1,Calculation!$1:$1,0)) -> 31112 | C13: =INDEX(Calculation!$A$1:$F$607,MATCH($A13,Calculation!$B:$B,0),MATCH(C$1,Calculation!$1:$1,0)) -> 4893 | D13: =INDEX(Calculation!$A$1:$F$607,MATCH($A13,Calculation!$B:$B,0),MATCH(D$1,Calculation!$1:$1,0)) -> 424 | E13: =INDEX(Calculation!$A$1:$F$607,MATCH($A13,Calculation!$B:$B,0),MATCH(E$1,Calculation!$1:$1,0)) -> 19
... A343: GM0193 | B343: =INDEX(Calculation!$A$1:$F$607,MATCH($A343,Calculation!$B:$B,0),MATCH(B$1,Calculation!$1:$1,0)) -> 58042 | C343: =INDEX(Calculation!$A$1:$F$607,MATCH($A343,Calculation!$B:$B,0),MATCH(C$1,Calculation!$1:$1,0)) -> 5862 | D343: =INDEX(Calculation!$A$1:$F$607,MATCH($A343,Calculation!$B:$B,0),MATCH(D$1,Calculation!$1:$1,0)) -> 211 | E343: =INDEX(Calculation!$A$1:$F$607,MATCH($A343,Calculation!$B:$B,0),MATCH(E$1,Calculation!$1:$1,0)) -> 14

Sheet Calculation
A1: Gemeentenaam | B1: GM_code | C1: number_of_cars | D1: number_of_vans | E1: number_of_trucks | F1: number_of_buses
A2: =Source_wegvoertuigen_CBS!A6 -> Aa en Hunze | B2: =INDEX(Source_GM_code_CBS!$B:$B,MATCH($A2,Source_GM_code_CBS!$C:$C,0)) -> GM1680 | C2: =Source_wegvoertuigen_CBS!C6 -> 15568 | D2: =Source_wegvoertuigen_CBS!D6 -> 1826 | E2: =Source_wegvoertuigen_CBS!E6 -> 101 | F2: =Source_wegvoertuigen_CBS!F6 -> 3
A3: =Source_wegvoertuigen_CBS!A7 -> Aalburg | B3: =INDEX(Source_GM_code_CBS!$B:$B,MATCH($A3,Source_GM_code_CBS!$C:$C,0)) -> #N/A | C3: =Source_wegvoertuigen_CBS!C7 -> 0 | D3: =Source_wegvoertuigen_CBS!D7 -> 0 | E3: =Source_wegvoertuigen_CBS!E7 -> 0 | F3: =Source_wegvoertuigen_CBS!F7 -> 0
A4: =Source_wegvoertuigen_CBS!A8 -> Aalsmeer | B4: =INDEX(Source_GM_code_CBS!$B:$B,MATCH($A4,Source_GM_code_CBS!$C:$C,0)) -> GM0358 | C4: =Source_wegvoertuigen_CBS!C8 -> 17396 | D4: =Source_wegvoertuigen_CBS!D8 -> 1963 | E4: =Source_wegvoertuigen_CBS!E8 -> 181 | F4: =Source_wegvoertuigen_CBS!F8 -> 17
A5: =Source_wegvoertuigen_CBS!A9 -> Aalten | B5: =INDEX(Source_GM_code_CBS!$B:$B,MATCH($A5,Source_GM_code_CBS!$C:$C,0)) -> GM0197 | C5: =Source_wegvoertuigen_CBS!C9 -> 14912 | D5: =Source_wegvoertuigen_CBS!D9 -> 1763 | E5: =Source_wegvoertuigen_CBS!E9 -> 91 | F5: =Source_wegvoertuigen_CBS!F9 -> 2
A6: =Source_wegvoertuigen_CBS!A10 -> Ter Aar | B6: =INDEX(Source_GM_code_CBS!$B:$B,MATCH($A6,Source_GM_code_CBS!$C:$C,0)) -> #N/A | C6: =Source_wegvoertuigen_CBS!C10 -> 0 | D6: =Source_wegvoertuigen_CBS!D10 -> 0 | E6: =Source_wegvoertuigen_CBS!E10 -> 0 | F6: =Source_wegvoertuigen_CBS!F10 -> 0
A7: =Source_wegvoertuigen_CBS!A11 -> Abcoude | B7: =INDEX(Source_GM_code_CBS!$B:$B,MATCH($A7,Source_GM_code_CBS!$C:$C,0)) -> #N/A | C7: =Source_wegvoertuigen_CBS!C11 -> 0 | D7: =Source_wegvoertuigen_CBS!D11 -> 0 | E7: =Source_wegvoertuigen_CBS!E11 -> 0 | F7: =Source_wegvoertuigen_CBS!F11 -> 0
A8: =Source_wegvoertuigen_CBS!A12 -> Achtkarspelen | B8: =INDEX(Source_GM_code_CBS!$B:$B,MATCH($A8,Source_GM_code_CBS!$C:$C,0)) -> GM0059 | C8: =Source_wegvoertuigen_CBS!C12 -> 15604 | D8: =Source_wegvoertuigen_CBS!D12 -> 2554 | E8: =Source_wegvoertuigen_CBS!E12 -> 152 | F8: =Source_wegvoertuigen_CBS!F12 -> 40
A9: =Source_wegvoertuigen_CBS!A13 -> Akersloot | B9: =INDEX(Source_GM_code_CBS!$B:$B,MATCH($A9,Source_GM_code_CBS!$C:$C,0)) -> #N/A | C9: =Source_wegvoertuigen_CBS!C13 -> 0 | D9: =Source_wegvoertuigen_CBS!D13 -> 0 | E9: =Source_wegvoertuigen_CBS!E13 -> 0 | F9: =Source_wegvoertuigen_CBS!F13 -> 0
A10: =Source_wegvoertuigen_CBS!A14 -> Alblasserdam | B10: =INDEX(Source_GM_code_CBS!$B:$B,MATCH($A10,Source_GM_code_CBS!$C:$C,0)) -> GM0482 | C10: =Source_wegvoertuigen_CBS!C14 -> 9531 | D10: =Source_wegvoertuigen_CBS!D14 -> 1210 | E10: =Source_wegvoertuigen_CBS!E14 -> 83 | F10: =Source_wegvoertuigen_CBS!F14 -> 28
A11: =Source_wegvoertuigen_CBS!A15 -> Albrandswaard | B11: =INDEX(Source_GM_code_CBS!$B:$B,MATCH($A11,Source_GM_code_CBS!$C:$C,0)) -> GM0613 | C11: =Source_wegvoertuigen_CBS!C15 -> 12936 | D11: =Source_wegvoertuigen_CBS!D15 -> 908 | E11: =Source_wegvoertuigen_CBS!E15 -> 49 | F11: =Source_wegvoertuigen_CBS!F15 -> 4
A12: =Source_wegvoertuigen_CBS!A16 -> Alkemade | B12: =INDEX(Source_GM_code_CBS!$B:$B,MATCH($A12,Source_GM_code_CBS!$C:$C,0)) -> #N/A | C12: =Source_wegvoertuigen_CBS!C16 -> 0 | D12: =Source_wegvoertuigen_CBS!D16 -> 0 | E12: =Source_wegvoertuigen_CBS!E16 -> 0 | F12: =Source_wegvoertuigen_CBS!F16 -> 0
A13: =Source_wegvoertuigen_CBS!A17 -> Alkmaar | B13: =INDEX(Source_GM_code_CBS!$B:$B,MATCH($A13,Source_GM_code_CBS!$C:$C,0)) -> GM0361 | C13: =Source_wegvoertuigen_CBS!C17 -> 58882 | D13: =Source_wegvoertuigen_CBS!D17 -> 6290 | E13: =Source_wegvoertuigen_CBS!E17 -> 479 | F13: =Source_wegvoertuigen_CBS!F17 -> 20
... A42: =Source_wegvoertuigen_CBS!A46 -> Bedum | B42: =INDEX(Source_GM_code_CBS!$B:$B,MATCH($A42,Source_GM_code_CBS!$C:$C,0)) -> #N/A | C42: =Source_wegvoertuigen_CBS!C46 -> 0 | D42: =Source_wegvoertuigen_CBS!D46 -> 0 | E42: =Source_wegvoertuigen_CBS!E46 -> 0 | F42: =Source_wegvoertuigen_CBS!F46 -> 0
A43: Beek | B43: =INDEX(Source_GM_code_CBS!$B:$B,MATCH($A43,Source_GM_code_CBS!$C:$C,0)) -> GM0888 | C43: =Source_wegvoertuigen_CBS!C47 -> 9695 | D43: =Source_wegvoertuigen_CBS!D47 -> 811 | E43: =Source_wegvoertuigen_CBS!E47 -> 61 | F43: =Source_wegvoertuigen_CBS!F47 -> 1
A44: =Source_wegvoertuigen_CBS!A48 -> Beekdaelen | B44: =INDEX(Source_GM_code_CBS!$B:$B,MATCH($A44,Source_GM_code_CBS!$C:$C,0)) -> GM1954 | C44: =Source_wegvoertuigen_CBS!C48 -> 22365 | D44: =Source_wegvoertuigen_CBS!D48 -> 2074 | E44: =Source_wegvoertuigen_CBS!E48 -> 154 | F44: =Source_wegvoertuigen_CBS!F48 -> 1
A45: =Source_wegvoertuigen_CBS!A49 -> Beemster | B45: =INDEX(Source_GM_code_CBS!$B:$B,MATCH($A45,Source_GM_code_CBS!$C:$C,0)) -> #N/A | C45: =Source_wegvoertuigen_CBS!C49 -> 0 | D45: =Source_wegvoertuigen_CBS!D49 -> 0 | E45: =Source_wegvoertuigen_CBS!E49 -> 0 | F45: =Source_wegvoertuigen_CBS!F49 -> 0
A46: =Source_wegvoertuigen_CBS!A50 -> Beesel | B46: =INDEX(Source_GM_code_CBS!$B:$B,MATCH($A46,Source_GM_code_CBS!$C:$C,0)) -> GM0889 | C46: =Source_wegvoertuigen_CBS!C50 -> 7338 | D46: =Source_wegvoertuigen_CBS!D50 -> 548 | E46: =Source_wegvoertuigen_CBS!E50 -> 41 | F46: =Source_wegvoertuigen_CBS!F50 -> 0
A47: =Source_wegvoertuigen_CBS!A51 -> Belfeld | B47: =INDEX(Source_GM_code_CBS!$B:$B,MATCH($A47,Source_GM_code_CBS!$C:$C,0)) -> #N/A | C47: =Source_wegvoertuigen_CBS!C51 -> 0 | D47: =Source_wegvoertuigen_CBS!D51 -> 0 | E47: =Source_wegvoertuigen_CBS!E51 -> 0 | F47: =Source_wegvoertuigen_CBS!F51 -> 0
A48: =Source_wegvoertuigen_CBS!A52 -> Bellingwedde | B48: =INDEX(Source_GM_code_CBS!$B:$B,MATCH($A48,Source_GM_code_CBS!$C:$C,0)) -> #N/A | C48: =Source_wegvoertuigen_CBS!C52 -> 0 | D48: =Source_wegvoertuigen_CBS!D52 -> 0 | E48: =Source_wegvoertuigen_CBS!E52 -> 0 | F48: =Source_wegvoertuigen_CBS!F52 -> 0
A49: =Source_wegvoertuigen_CBS!A53 -> Berg en Dal | B49: =INDEX(Source_GM_code_CBS!$B:$B,MATCH($A49,Source_GM_code_CBS!$C:$C,0)) -> GM1945 | C49: =Source_wegvoertuigen_CBS!C53 -> 19031 | D49: =Source_wegvoertuigen_CBS!D53 -> 1763 | E49: =Source_wegvoertuigen_CBS!E53 -> 69 | F49: =Source_wegvoertuigen_CBS!F53 -> 10
A50: =Source_wegvoertuigen_CBS!A54 -> Bemmel | B50: =INDEX(Source_GM_code_CBS!$B:$B,MATCH($A50,Source_GM_code_CBS!$C:$C,0)) -> #N/A | C50: =Source_wegvoertuigen_CBS!C54 -> 0 | D50: =Source_wegvoertuigen_CBS!D54 -> 0 | E50: =Source_wegvoertuigen_CBS!E54 -> 0 | F50: =Source_wegvoertuigen_CBS!F54 -> 0
A51: =Source_wegvoertuigen_CBS!A55 -> Bennebroek | B51: =INDEX(Source_GM_code_CBS!$B:$B,MATCH($A51,Source_GM_code_CBS!$C:$C,0)) -> #N/A | C51: =Source_wegvoertuigen_CBS!C55 -> 0 | D51: =Source_wegvoertuigen_CBS!D55 -> 0 | E51: =Source_wegvoertuigen_CBS!E55 -> 0 | F51: =Source_wegvoertuigen_CBS!F55 -> 0
A52: =Source_wegvoertuigen_CBS!A56 -> Bergambacht | B52: =INDEX(Source_GM_code_CBS!$B:$B,MATCH($A52,Source_GM_code_CBS!$C:$C,0)) -> #N/A | C52: =Source_wegvoertuigen_CBS!C56 -> 0 | D52: =Source_wegvoertuigen_CBS!D56 -> 0 | E52: =Source_wegvoertuigen_CBS!E56 -> 0 | F52: =Source_wegvoertuigen_CBS!F56 -> 0
A53: =Source_wegvoertuigen_CBS!A57 -> Bergeijk | B53: =INDEX(Source_GM_code_CBS!$B:$B,MATCH($A53,Source_GM_code_CBS!$C:$C,0)) -> GM1724 | C53: =Source_wegvoertuigen_CBS!C57 -> 11303 | D53: =Source_wegvoertuigen_CBS!D57 -> 1837 | E53: =Source_wegvoertuigen_CBS!E57 -> 69 | F53: =Source_wegvoertuigen_CBS!F57 -> 19
A54: =Source_wegvoertuigen_CBS!A58 -> Bergen (L.) | B54: =INDEX(Source_GM_code_CBS!$B:$B,MATCH($A54,Source_GM_code_CBS!$C:$C,0)) -> GM0893 | C54: =Source_wegvoertuigen_CBS!C58 -> 8123 | D54: =Source_wegvoertuigen_CBS!D58 -> 915 | E54: =Source_wegvoertuigen_CBS!E58 -> 55 | F54: =Source_wegvoertuigen_CBS!F58 -> 1
A55: =Source_wegvoertuigen_CBS!A59 -> Bergen (NH.) | B55: =INDEX(Source_GM_code_CBS!$B:$B,MATCH($A55,Source_GM_code_CBS!$C:$C,0)) -> GM0373 | C55: =Source_wegvoertuigen_CBS!C59 -> 16520 | D55: =Source_wegvoertuigen_CBS!D59 -> 1395 | E55: =Source_wegvoertuigen_CBS!E59 -> 66 | F55: =Source_wegvoertuigen_CBS!F59 -> 2
... A175: =Source_wegvoertuigen_CBS!A179 -> Goes | B175: =INDEX(Source_GM_code_CBS!$B:$B,MATCH($A175,Source_GM_code_CBS!$C:$C,0)) -> GM0664 | C175: =Source_wegvoertuigen_CBS!C179 -> 21617 | D175: =Source_wegvoertuigen_CBS!D179 -> 2483 | E175: =Source_wegvoertuigen_CBS!E179 -> 130 | F175: =Source_wegvoertuigen_CBS!F179 -> 1
A176: Goirle | B176: =INDEX(Source_GM_code_CBS!$B:$B,MATCH($A176,Source_GM_code_CBS!$C:$C,0)) -> GM0785 | C176: =Source_wegvoertuigen_CBS!C180 -> 12645 | D176: =Source_wegvoertuigen_CBS!D180 -> 1146 | E176: =Source_wegvoertuigen_CBS!E180 -> 85 | F176: =Source_wegvoertuigen_CBS!F180 -> 2
A177: =Source_wegvoertuigen_CBS!A181 -> Gooise Meren | B177: =INDEX(Source_GM_code_CBS!$B:$B,MATCH($A177,Source_GM_code_CBS!$C:$C,0)) -> GM1942 | C177: =Source_wegvoertuigen_CBS!C181 -> 29412 | D177: =Source_wegvoertuigen_CBS!D181 -> 1838 | E177: =Source_wegvoertuigen_CBS!E181 -> 47 | F177: =Source_wegvoertuigen_CBS!F181 -> 0
A178: =Source_wegvoertuigen_CBS!A182 -> Goor | B178: =INDEX(Source_GM_code_CBS!$B:$B,MATCH($A178,Source_GM_code_CBS!$C:$C,0)) -> #N/A | C178: =Source_wegvoertuigen_CBS!C182 -> 0 | D178: =Source_wegvoertuigen_CBS!D182 -> 0 | E178: =Source_wegvoertuigen_CBS!E182 -> 0 | F178: =Source_wegvoertuigen_CBS!F182 -> 0
A179: =Source_wegvoertuigen_CBS!A183 -> Gorinchem | B179: =INDEX(Source_GM_code_CBS!$B:$B,MATCH($A179,Source_GM_code_CBS!$C:$C,0)) -> GM0512 | C179: =Source_wegvoertuigen_CBS!C183 -> 17719 | D179: =Source_wegvoertuigen_CBS!D183 -> 1901 | E179: =Source_wegvoertuigen_CBS!E183 -> 97 | F179: =Source_wegvoertuigen_CBS!F183 -> 5
A180: =Source_wegvoertuigen_CBS!A184 -> Gorssel | B180: =INDEX(Source_GM_code_CBS!$B:$B,MATCH($A180,Source_GM_code_CBS!$C:$C,0)) -> #N/A | C180: =Source_wegvoertuigen_CBS!C184 -> 0 | D180: =Source_wegvoertuigen_CBS!D184 -> 0 | E180: =Source_wegvoertuigen_CBS!E184 -> 0 | F180: =Source_wegvoertuigen_CBS!F184 -> 0
A181: =Source_wegvoertuigen_CBS!A185 -> Gouda | B181: =INDEX(Source_GM_code_CBS!$B:$B,MATCH($A181,Source_GM_code_CBS!$C:$C,0)) -> GM0513 | C181: =Source_wegvoertuigen_CBS!C185 -> 29676 | D181: =Source_wegvoertuigen_CBS!D185 -> 2498 | E181: =Source_wegvoertuigen_CBS!E185 -> 94 | F181: =Source_wegvoertuigen_CBS!F185 -> 3
A182: =Source_wegvoertuigen_CBS!A186 -> Graafstroom | B182: =INDEX(Source_GM_code_CBS!$B:$B,MATCH($A182,Source_GM_code_CBS!$C:$C,0)) -> #N/A | C182: =Source_wegvoertuigen_CBS!C186 -> 0 | D182: =Source_wegvoertuigen_CBS!D186 -> 0 | E182: =Source_wegvoertuigen_CBS!E186 -> 0 | F182: =Source_wegvoertuigen_CBS!F186 -> 0
A183: =Source_wegvoertuigen_CBS!A187 -> Graft-De Rijp | B183: =INDEX(Source_GM_code_CBS!$B:$B,MATCH($A183,Source_GM_code_CBS!$C:$C,0)) -> #N/A | C183: =Source_wegvoertuigen_CBS!C187 -> 0 | D183: =Source_wegvoertuigen_CBS!D187 -> 0 | E183: =Source_wegvoertuigen_CBS!E187 -> 0 | F183: =Source_wegvoertuigen_CBS!F187 -> 0
A184: =Source_wegvoertuigen_CBS!A188 -> Gramsbergen | B184: =INDEX(Source_GM_code_CBS!$B:$B,MATCH($A184,Source_GM_code_CBS!$C:$C,0)) -> #N/A | C184: =Source_wegvoertuigen_CBS!C188 -> 0 | D184: =Source_wegvoertuigen_CBS!D188 -> 0 | E184: =Source_wegvoertuigen_CBS!E188 -> 0 | F184: =Source_wegvoertuigen_CBS!F188 -> 0
A185: =Source_wegvoertuigen_CBS!A189 -> Grave | B185: =INDEX(Source_GM_code_CBS!$B:$B,MATCH($A185,Source_GM_code_CBS!$C:$C,0)) -> #N/A | C185: =Source_wegvoertuigen_CBS!C189 -> 0 | D185: =Source_wegvoertuigen_CBS!D189 -> 0 | E185: =Source_wegvoertuigen_CBS!E189 -> 0 | F185: =Source_wegvoertuigen_CBS!F189 -> 0
A186: =Source_wegvoertuigen_CBS!A190 -> 's-Graveland | B186: =INDEX(Source_GM_code_CBS!$B:$B,MATCH($A186,Source_GM_code_CBS!$C:$C,0)) -> #N/A | C186: =Source_wegvoertuigen_CBS!C190 -> 0 | D186: =Source_wegvoertuigen_CBS!D190 -> 0 | E186: =Source_wegvoertuigen_CBS!E190 -> 0 | F186: =Source_wegvoertuigen_CBS!F190 -> 0
A187: =Source_wegvoertuigen_CBS!A191 -> 's-Gravendeel | B187: =INDEX(Source_GM_code_CBS!$B:$B,MATCH($A187,Source_GM_code_CBS!$C:$C,0)) -> #N/A | C187: =Source_wegvoertuigen_CBS!C191 -> 0 | D187: =Source_wegvoertuigen_CBS!D191 -> 0 | E187: =Source_wegvoertuigen_CBS!E191 -> 0 | F187: =Source_wegvoertuigen_CBS!F191 -> 0
...

Sheet Source_wegvoertuigen_CBS
A1: Motorvoertuigen | B1: voertuigtype, postcode en regio's, 1 januari, 2000-2022
C3: Onderwerp
C4: Wegvoertuigen per 1 januari|Personenauto | D4: Wegvoertuigen per 1 januari|Bedrijfsvoertuigen|Bedrijfsmotorvoertuigen|Bestelauto | E4: Wegvoertuigen per 1 januari|Bedrijfsvoertuigen|Bedrijfsmotorvoertuigen|Vrachtauto (excl. trekker voor oplegger) | F4: Wegvoertuigen per 1 januari|Bedrijfsvoertuigen|Bedrijfsmotorvoertuigen|Bus
A5: Regio's | B5: Perioden | C5: aantal | D5: aantal | E5: aantal | F5: aantal
A6: Aa en Hunze | B6: 2022 | C6: 15568 | D6: 1826 | E6: 101 | F6: 3
A7: Aalburg | B7: 2022 | C7: 0 | D7: 0 | E7: 0 | F7: 0
A8: Aalsmeer | B8: 2022 | C8: 17396 | D8: 1963 | E8: 181 | F8: 17
A9: Aalten | B9: 2022 | C9: 14912 | D9: 1763 | E9: 91 | F9: 2
A10: Ter Aar | B10: 2022 | C10: 0 | D10: 0 | E10: 0 | F10: 0
A11: Abcoude | B11: 2022 | C11: 0 | D11: 0 | E11: 0 | F11: 0
A12: Achtkarspelen | B12: 2022 | C12: 15604 | D12: 2554 | E12: 152 | F12: 40
A13: Akersloot | B13: 2022 | C13: 0 | D13: 0 | E13: 0 | F13: 0
A14: Alblasserdam | B14: 2022 | C14: 9531 | D14: 1210 | E14: 83 | F14: 28
A15: Albrandswaard | B15: 2022 | C15: 12936 | D15: 908 | E15: 49 | F15: 4
A16: Alkemade | B16: 2022 | C16: 0 | D16: 0 | E16: 0 | F16: 0
A17: Alkmaar | B17: 2022 | C17: 58882 | D17: 6290 | E17: 479 | F17: 20
... A609: Zwolle | B609: 2022 | C609: 58042 | D609: 5862 | E609: 211 | F609: 14
A610: Bron: RDW, CBS

Sheet Source_GM_code_CBS
A1: Gemeentecode | B1: GemeentecodeGM | C1: Gemeentenaam | D1: Provinciecode | E1: ProvinciecodePV | F1: Provincienaam
A2: 1680 | B2: GM1680 | C2: Aa en Hunze | D2: 22 | E2: PV22 | F2: Drenthe
A3: 0358 | B3: GM0358 | C3: Aalsmeer | D3: 27 | E3: PV27 | F3: Noord-Holland
A4: 0197 | B4: GM0197 | C4: Aalten | D4: 25 | E4: PV25 | F4: Gelderland
A5: 0059 | B5: GM0059 | C5: Achtkarspelen | D5: 21 | E5: PV21 | F5: Fryslân
A6: 0482 | B6: GM0482 | C6: Alblasserdam | D6: 28 | E6: PV28 | F6: Zuid-Holland
A7: 0613 | B7: GM0613 | C7: Albrandswaard | D7: 28 | E7: PV28 | F7: Zuid-Holland
A8: 0361 | B8: GM0361 | C8: Alkmaar | D8: 27 | E8: PV27 | F8: Noord-Holland
A9: 0141 | B9: GM0141 | C9: Almelo | D9: 23 | E9: PV23 | F9: Overijssel
A10: 0034 | B10: GM0034 | C10: Almere | D10: 24 | E10: PV24 | F10: Flevoland
A11: 0484 | B11: GM0484 | C11: Alphen aan den Rijn | D11: 28 | E11: PV28 | F11: Zuid-Holland
A12: 1723 | B12: GM1723 | C12: Alphen-Chaam | D12: 30 | E12: PV30 | F12: Noord-Brabant
... A343: 0193 | B343: GM0193 | C343: Zwolle | D343: 23 | E343: PV23 | F343: Overijssel
