Workbook

Sheet Data
A1: GM_code | B1: train_share_in_nl
A2: GM1680 | B2: =SUMIF(Calculation!C:C,Data!A2,Calculation!H:H) -> 0
A3: GM0358 | B3: =SUMIF(Calculation!C:C,Data!A3,Calculation!H:H) -> 0
A4: GM0197 | B4: =SUMIF(Calculation!C:C,Data!A4,Calculation!H:H) -> 0.0006062442
A5: GM0059 | B5: =SUMIF(Calculation!C:C,Data!A5,Calculation!H:H) -> 0
A6: GM0482 | B6: =SUMIF(Calculation!C:C,Data!A6,Calculation!H:H) -> 0
A7: GM0613 | B7: =SUMIF(Calculation!C:C,Data!A7,Calculation!H:H) -> 0
A8: GM0361 | B8: =SUMIF(Calculation!C:C,Data!A8,Calculation!H:H) -> 0.0074436175
A9: GM0141 | B9: =SUMIF(Calculation!C:C,Data!A9,Calculation!H:H) -> 0.0026633563
A10: GM0034 | B10: =SUMIF(Calculation!C:C,Data!A10,Calculation!H:H) -> 0.019053728
A11: GM0484 | B11: =SUMIF(Calculation!C:C,Data!A11,Calculation!H:H) -> 0.0049307333
A12: GM1723 | B12: =SUMIF(Calculation!C:C,Data!A12,Calculation!H:H) -> 0
A13: GM1959 | B13: =SUMIF(Calculation!C:C,Data!A13,Calculation!H:H) -> 0
... A343: GM0193 | B343: =SUMIF(Calculation!C:C,Data!A343,Calculation!H:H) -> 0.017017603

Sheet Calculation
A1: =Source_NS_Dashboard!B1 -> Plaats | B1: Gemeente | C1: GemeentecodeGM | D1: =Source_NS_Dashboard!I1 -> Reizigers per dag | E1: converted to number | H1: train_share_in_nl
A2: =Source_NS_Dashboard!B2 -> Aalten | B2: Aalten | C2: =INDEX(Source_GM_code_CBS!B:B,MATCH(Calculation!B2,Source_GM_code_CBS!C:C,0)) -> GM0197 | D2: =Source_NS_Dashboard!I2 -> 1.531 (2008) | E2: =IFERROR(LEFT(D2,FIND(" ",D2,1)-1),"0") -> 1.531 | F2: =SUBSTITUTE(E2,".","") -> 1531 | G2: =VALUE(F2) -> 1531 | H2: =G2/(SUM($G$2:$G$399)) -> 0.0006062442 | J2: =SUM(H2:H399) -> 1
A3: =Source_NS_Dashboard!B3 -> Abcoude | B3: De Ronde Venen | C3: =INDEX(Source_GM_code_CBS!B:B,MATCH(Calculation!B3,Source_GM_code_CBS!C:C,0)) -> GM0736 | D3: =Source_NS_Dashboard!I3 -> 1.599 (2022) | E3: =IFERROR(LEFT(D3,FIND(" ",D3,1)-1),"0") -> 1.599 | F3: =SUBSTITUTE(E3,".","") -> 1599 | G3: =VALUE(F3) -> 1599 | H3: =G3/(SUM($G$2:$G$399)) -> 0.00063317078
A4: =Source_NS_Dashboard!B4 -> Akkrum | B4: Heerenveen | C4: =INDEX(Source_GM_code_CBS!B:B,MATCH(Calculation!B4,Source_GM_code_CBS!C:C,0)) -> GM0074 | D4: =Source_NS_Dashboard!I4 -> 725 (2023) | E4: =IFERROR(LEFT(D4,FIND(" ",D4,1)-1),"0") -> 725 | F4: =SUBSTITUTE(E4,".","") -> 725 | G4: =VALUE(F4) -> 725 | H4: =G4/(SUM($G$2:$G$399)) -> 0.00028708494
A5: =Source_NS_Dashboard!B5 -> Alkmaar | B5: Alkmaar | C5: =INDEX(Source_GM_code_CBS!B:B,MATCH(Calculation!B5,Source_GM_code_CBS!C:C,0)) -> GM0361 | D5: =Source_NS_Dashboard!I5 -> 15.272 (2024) | E5: =IFERROR(LEFT(D5,FIND(" ",D5,1)-1),"0") -> 15.272 | F5: =SUBSTITUTE(E5,".","") -> 15272 | G5: =VALUE(F5) -> 15272 | H5: =G5/(SUM($G$2:$G$399)) -> 0.0060473948
A6: =Source_NS_Dashboard!B6 -> Alkmaar | B6: Alkmaar | C6: =INDEX(Source_GM_code_CBS!B:B,MATCH(Calculation!B6,Source_GM_code_CBS!C:C,0)) -> GM0361 | D6: =Source_NS_Dashboard!I6 -> 3.526 (2023) | E6: =IFERROR(LEFT(D6,FIND(" ",D6,1)-1),"0") -> 3.526 | F6: =SUBSTITUTE(E6,".","") -> 3526 | G6: =VALUE(F6) -> 3526 | H6: =G6/(SUM($G$2:$G$399)) -> 0.0013962228
A7: =Source_NS_Dashboard!B7 -> Almelo | B7: Almelo | C7: =INDEX(Source_GM_code_CBS!B:B,MATCH(Calculation!B7,Source_GM_code_CBS!C:C,0)) -> GM0141 | D7: =Source_NS_Dashboard!I7 -> 6.544 (2024) (NS) | E7: =IFERROR(LEFT(D7,FIND(" ",D7,1)-1),"0") -> 6.544 | F7: =SUBSTITUTE(E7,".","") -> 6544 | G7: =VALUE(F7) -> 6544 | H7: =G7/(SUM($G$2:$G$399)) -> 0.0025912881
A8: =Source_NS_Dashboard!B8 -> Almelo | B8: Almelo | C8: =INDEX(Source_GM_code_CBS!B:B,MATCH(Calculation!B8,Source_GM_code_CBS!C:C,0)) -> GM0141 | D8: =Source_NS_Dashboard!I8 -> 182 (2023) (NS) | E8: =IFERROR(LEFT(D8,FIND(" ",D8,1)-1),"0") -> 182 | F8: =SUBSTITUTE(E8,".","") -> 182 | G8: =VALUE(F8) -> 182 | H8: =G8/(SUM($G$2:$G$399)) -> 7.2068219e-05
A9: =Source_NS_Dashboard!B9 -> Almere Buiten | B9: Almere | C9: =INDEX(Source_GM_code_CBS!B:B,MATCH(Calculation!B9,Source_GM_code_CBS!C:C,0)) -> GM0034 | D9: =Source_NS_Dashboard!I9 -> 4.679 (2024) | E9: =IFERROR(LEFT(D9,FIND(" ",D9,1)-1),"0") -> 4.679 | F9: =SUBSTITUTE(E9,".","") -> 4679 | G9: =VALUE(F9) -> 4679 | H9: =G9/(SUM($G$2:$G$399)) -> 0.0018527868
A10: =Source_NS_Dashboard!B10 -> Almere Stad | B10: Almere | C10: =INDEX(Source_GM_code_CBS!B:B,MATCH(Calculation!B10,Source_GM_code_CBS!C:C,0)) -> GM0034 | D10: =Source_NS_Dashboard!I10 -> 26.979 (2024) (NS) | E10: =IFERROR(LEFT(D10,FIND(" ",D10,1)-1),"0") -> 26.979 | F10: =SUBSTITUTE(E10,".","") -> 26979 | G10: =VALUE(F10) -> 26979 | H10: =G10/(SUM($G$2:$G$399)) -> 0.010683124
A11: =Source_NS_Dashboard!B11 -> Almere Stad | B11: Almere | C11: =INDEX(Source_GM_code_CBS!B:B,MATCH(Calculation!B11,Source_GM_code_CBS!C:C,0)) -> GM0034 | D11: =Source_NS_Dashboard!I11 -> 4.585 (2023) | E11: =IFERROR(LEFT(D11,FIND(" ",D11,1)-1),"0") -> 4.585 | F11: =SUBSTITUTE(E11,".","") -> 4585 | G11: =VALUE(F11) -> 4585 | H11: =G11/(SUM($G$2:$G$399)) -> 0.0018155648
A12: =Source_NS_Dashboard!B12 -> Almere Buiten | B12: Almere | C12: =INDEX(Source_GM_code_CBS!B:B,MATCH(Calculation!B12,Source_GM_code_CBS!C:C,0)) -> GM0034 | D12: =Source_NS_Dashboard!I12 -> 3.849 (2023) | E12: =IFERROR(LEFT(D12,FIND(" ",D12,1)-1),"0") -> 3.849 | F12: =SUBSTITUTE(E12,".","") -> 3849 | G12: =VALUE(F12) -> 3849 | H12: =G12/(SUM($G$2:$G$399)) -> 0.001524124
A13: =Source_NS_Dashboard!B13 -> Almere Stad | B13: Almere | C13: =INDEX(Source_GM_code_CBS!B:B,MATCH(Calculation!B13,Source_GM_code_CBS!C:C,0)) -> GM0034 | D13: =Source_NS_Dashboard!I13 -> 2.208 (2023) | E13: =IFERROR(LEFT(D13,FIND(" ",D13,1)-1),"0") -> 2.208 | F13: =SUBSTITUTE(E13,".","") -> 2208 | G13: =VALUE(F13) -> 2208 | H13: =G13/(SUM($G$2:$G$399)) -> 0.00087432213
A14: =Source_NS_Dashboard!B14 -> Almere Poort | B14: Almere | C14: =INDEX(Source_GM_code_CBS!B:B,MATCH(Calculation!B14,Source_GM_code_CBS!C:C,0)) -> GM0034 | D14: =Source_NS_Dashboard!I14 -> 5.818 (2023) | E14: =IFERROR(LEFT(D14,FIND(" ",D14,1)-1),"0") -> 5.818 | F14: =SUBSTITUTE(E14,".","") -> 5818 | G14: =VALUE(F14) -> 5818 | H14: =G14/(SUM($G$2:$G$399)) -> 0.0023038071
... A71: =Source_NS_Dashboard!B71 -> Brummen | B71: Brummen | C71: =INDEX(Source_GM_code_CBS!B:B,MATCH(Calculation!B71,Source_GM_code_CBS!C:C,0)) -> GM0213 | D71: =Source_NS_Dashboard!I71 -> 821 (2023) | E71: =IFERROR(LEFT(D71,FIND(" ",D71,1)-1),"0") -> 821 | F71: =SUBSTITUTE(E71,".","") -> 821 | G71: =VALUE(F71) -> 821 | H71: =G71/(SUM($G$2:$G$399)) -> 0.00032509895
A72: =Source_NS_Dashboard!B72 -> Buitenpost | C72: =INDEX(Source_GM_code_CBS!B:B,MATCH(Calculation!B72,Source_GM_code_CBS!C:C,0)) -> #N/A | D72: =Source_NS_Dashboard!I72 -> - | E72: =IFERROR(LEFT(D72,FIND(" ",D72,1)-1),"0") -> 0 | F72: =SUBSTITUTE(E72,".","") -> 0 | G72: =VALUE(F72) -> 0 | H72: =G72/(SUM($G$2:$G$399)) -> 0
A73: =Source_NS_Dashboard!B73 -> Bunde | B73: Meerssen | C73: =INDEX(Source_GM_code_CBS!B:B,MATCH(Calculation!B73,Source_GM_code_CBS!C:C,0)) -> GM0938 | D73: =Source_NS_Dashboard!I73 -> 838 (2016) | E73: =IFERROR(LEFT(D73,FIND(" ",D73,1)-1),"0") -> 838 | F73: =SUBSTITUTE(E73,".","") -> 838 | G73: =VALUE(F73) -> 838 | H73: =G73/(SUM($G$2:$G$399)) -> 0.00033183059
A74: =Source_NS_Dashboard!B74 -> Bunnik | B74: Bunnik | C74: =INDEX(Source_GM_code_CBS!B:B,MATCH(Calculation!B74,Source_GM_code_CBS!C:C,0)) -> GM0312 | D74: =Source_NS_Dashboard!I74 -> 2.007 (2023) | E74: =IFERROR(LEFT(D74,FIND(" ",D74,1)-1),"0") -> 2.007 | F74: =SUBSTITUTE(E74,".","") -> 2007 | G74: =VALUE(F74) -> 2007 | H74: =G74/(SUM($G$2:$G$399)) -> 0.00079473031
A75: =Source_NS_Dashboard!B75 -> Bussum | B75: Gooise Meren | C75: =INDEX(Source_GM_code_CBS!B:B,MATCH(Calculation!B75,Source_GM_code_CBS!C:C,0)) -> GM1942 | D75: =Source_NS_Dashboard!I75 -> 3.700 (2023) | E75: =IFERROR(LEFT(D75,FIND(" ",D75,1)-1),"0") -> 3.700 | F75: =SUBSTITUTE(E75,".","") -> 3700 | G75: =VALUE(F75) -> 3700 | H75: =G75/(SUM($G$2:$G$399)) -> 0.0014651231
A76: =Source_NS_Dashboard!B76 -> Capelle aan den IJssel | B76: Capelle aan den IJssel | C76: =INDEX(Source_GM_code_CBS!B:B,MATCH(Calculation!B76,Source_GM_code_CBS!C:C,0)) -> GM0502 | D76: =Source_NS_Dashboard!I76 -> 1.930 (2023) | E76: =IFERROR(LEFT(D76,FIND(" ",D76,1)-1),"0") -> 1.930 | F76: =SUBSTITUTE(E76,".","") -> 1930 | G76: =VALUE(F76) -> 1930 | H76: =G76/(SUM($G$2:$G$399)) -> 0.00076423991
A77: =Source_NS_Dashboard!B77 -> Castricum | B77: Castricum | C77: =INDEX(Source_GM_code_CBS!B:B,MATCH(Calculation!B77,Source_GM_code_CBS!C:C,0)) -> GM0383 | D77: =Source_NS_Dashboard!I77 -> 6.458 (2024) | E77: =IFERROR(LEFT(D77,FIND(" ",D77,1)-1),"0") -> 6.458 | F77: =SUBSTITUTE(E77,".","") -> 6458 | G77: =VALUE(F77) -> 6458 | H77: =G77/(SUM($G$2:$G$399)) -> 0.0025572338
A78: =Source_NS_Dashboard!B78 -> Kerkrade | C78: =INDEX(Source_GM_code_CBS!B:B,MATCH(Calculation!B78,Source_GM_code_CBS!C:C,0)) -> #N/A | D78: =Source_NS_Dashboard!I78 -> - | E78: =IFERROR(LEFT(D78,FIND(" ",D78,1)-1),"0") -> 0 | F78: =SUBSTITUTE(E78,".","") -> 0 | G78: =VALUE(F78) -> 0 | H78: =G78/(SUM($G$2:$G$399)) -> 0
A79: =Source_NS_Dashboard!B79 -> Coevorden | B79: Coevorden | C79: =INDEX(Source_GM_code_CBS!B:B,MATCH(Calculation!B79,Source_GM_code_CBS!C:C,0)) -> GM0109 | D79: =Source_NS_Dashboard!I79 -> 1.399 (2009) | E79: =IFERROR(LEFT(D79,FIND(" ",D79,1)-1),"0") -> 1.399 | F79: =SUBSTITUTE(E79,".","") -> 1399 | G79: =VALUE(F79) -> 1399 | H79: =G79/(SUM($G$2:$G$399)) -> 0.00055397494
A80: =Source_NS_Dashboard!B80 -> Cuijk | B80: Land van Cuijk | C80: =INDEX(Source_GM_code_CBS!B:B,MATCH(Calculation!B80,Source_GM_code_CBS!C:C,0)) -> GM1982 | D80: =Source_NS_Dashboard!I80 -> 2.948 (2006) | E80: =IFERROR(LEFT(D80,FIND(" ",D80,1)-1),"0") -> 2.948 | F80: =SUBSTITUTE(E80,".","") -> 2948 | G80: =VALUE(F80) -> 2948 | H80: =G80/(SUM($G$2:$G$399)) -> 0.0011673468
A81: =Source_NS_Dashboard!B81 -> Culemborg | B81: Culemborg | C81: =INDEX(Source_GM_code_CBS!B:B,MATCH(Calculation!B81,Source_GM_code_CBS!C:C,0)) -> GM0216 | D81: =Source_NS_Dashboard!I81 -> 7.842 (2024) | E81: =IFERROR(LEFT(D81,FIND(" ",D81,1)-1),"0") -> 7.842 | F81: =SUBSTITUTE(E81,".","") -> 7842 | G81: =VALUE(F81) -> 7842 | H81: =G81/(SUM($G$2:$G$399)) -> 0.0031052691
A82: =Source_NS_Dashboard!B82 -> Daarlerveen | B82: Hellendoorn | C82: =INDEX(Source_GM_code_CBS!B:B,MATCH(Calculation!B82,Source_GM_code_CBS!C:C,0)) -> GM0163 | D82: =Source_NS_Dashboard!I82 -> <100 (2005) | E82: 100 | F82: =SUBSTITUTE(E82,".","") -> 100 | G82: =VALUE(F82) -> 100 | H82: =G82/(SUM($G$2:$G$399)) -> 3.9597923e-05
A83: =Source_NS_Dashboard!B83 -> Dalen | B83: Coevorden | C83: =INDEX(Source_GM_code_CBS!B:B,MATCH(Calculation!B83,Source_GM_code_CBS!C:C,0)) -> GM0109 | D83: =Source_NS_Dashboard!I83 -> 253 (2008) | E83: =IFERROR(LEFT(D83,FIND(" ",D83,1)-1),"0") -> 253 | F83: =SUBSTITUTE(E83,".","") -> 253 | G83: =VALUE(F83) -> 253 | H83: =G83/(SUM($G$2:$G$399)) -> 0.00010018274
A84: =Source_NS_Dashboard!B84 -> Dalfsen | B84: Dalfsen | C84: =INDEX(Source_GM_code_CBS!B:B,MATCH(Calculation!B84,Source_GM_code_CBS!C:C,0)) -> GM0148 | D84: =Source_NS_Dashboard!I84 -> 1.147 (2008) | E84: =IFERROR(LEFT(D84,FIND(" ",D84,1)-1),"0") -> 1.147 | F84: =SUBSTITUTE(E84,".","") -> 1147 | G84: =VALUE(F84) -> 1147 | H84: =G84/(SUM($G$2:$G$399)) -> 0.00045418817
A85: =Source_NS_Dashboard!B85 -> Leiden Voorschoten | B85: Leiden | C85: =INDEX(Source_GM_code_CBS!B:B,MATCH(Calculation!B85,Source_GM_code_CBS!C:C,0)) -> GM0546 | D85: =Source_NS_Dashboard!I85 -> 2.603 (2023) | E85: =IFERROR(LEFT(D85,FIND(" ",D85,1)-1),"0") -> 2.603 | F85: =SUBSTITUTE(E85,".","") -> 2603 | G85: =VALUE(F85) -> 2603 | H85: =G85/(SUM($G$2:$G$399)) -> 0.0010307339
A86: =Source_NS_Dashboard!B86 -> Zwaagwesteinde | C86: =INDEX(Source_GM_code_CBS!B:B,MATCH(Calculation!B86,Source_GM_code_CBS!C:C,0)) -> #N/A | D86: =Source_NS_Dashboard!I86 -> - | E86: =IFERROR(LEFT(D86,FIND(" ",D86,1)-1),"0") -> 0 | F86: =SUBSTITUTE(E86,".","") -> 0 | G86: =VALUE(F86) -> 0 | H86: =G86/(SUM($G$2:$G$399)) -> 0
A87: =Source_NS_Dashboard!B87 -> Deinum | B87: Waadhoeke | C87: =INDEX(Source_GM_code_CBS!B:B,MATCH(Calculation!B87,Source_GM_code_CBS!C:C,0)) -> GM1949 | D87: =Source_NS_Dashboard!I87 -> 154 (2009) | E87: =IFERROR(LEFT(D87,FIND(" ",D87,1)-1),"0") -> 154 | F87: =SUBSTITUTE(E87,".","") -> 154 | G87: =VALUE(F87) -> 154 | H87: =G87/(SUM($G$2:$G$399)) -> 6.0980801e-05
A88: =Source_NS_Dashboard!B88 -> Delden | C88: =INDEX(Source_GM_code_CBS!B:B,MATCH(Calculation!B88,Source_GM_code_CBS!C:C,0)) -> #N/A | D88: =Source_NS_Dashboard!I88 -> - | E88: =IFERROR(LEFT(D88,FIND(" ",D88,1)-1),"0") -> 0 | F88: =SUBSTITUTE(E88,".","") -> 0 | G88: =VALUE(F88) -> 0 | H88: =G88/(SUM($G$2:$G$399)) -> 0
A89: =Source_NS_Dashboard!B89 -> Delft | B89: Delft | C89: =INDEX(Source_GM_code_CBS!B:B,MATCH(Calculation!B89,Source_GM_code_CBS!C:C,0)) -> GM0503 | D89: =Source_NS_Dashboard!I89 -> 34.989 (2024) | E89: =IFERROR(LEFT(D89,FIND(" ",D89,1)-1),"0") -> 34.989 | F89: =SUBSTITUTE(E89,".","") -> 34989 | G89: =VALUE(F89) -> 34989 | H89: =G89/(SUM($G$2:$G$399)) -> 0.013854917
A90: =Source_NS_Dashboard!B90 -> Delft | B90: Delft | C90: =INDEX(Source_GM_code_CBS!B:B,MATCH(Calculation!B90,Source_GM_code_CBS!C:C,0)) -> GM0503 | D90: =Source_NS_Dashboard!I90 -> 4.232 (2023) | E90: =IFERROR(LEFT(D90,FIND(" ",D90,1)-1),"0") -> 4.232 | F90: =SUBSTITUTE(E90,".","") -> 4232 | G90: =VALUE(F90) -> 4232 | H90: =G90/(SUM($G$2:$G$399)) -> 0.0016757841
A91: =Source_NS_Dashboard!B91 -> Delfzijl | B91: Eemsdelta | C91: =INDEX(Source_GM_code_CBS!B:B,MATCH(Calculation!B91,Source_GM_code_CBS!C:C,0)) -> GM1979 | D91: =Source_NS_Dashboard!I91 -> 1.290 (2009) | E91: =IFERROR(LEFT(D91,FIND(" ",D91,1)-1),"0") -> 1.290 | F91: =SUBSTITUTE(E91,".","") -> 1290 | G91: =VALUE(F91) -> 1290 | H91: =G91/(SUM($G$2:$G$399)) -> 0.0005108132
A92: =Source_NS_Dashboard!B92 -> Delfzijl | B92: Eemsdelta | C92: =INDEX(Source_GM_code_CBS!B:B,MATCH(Calculation!B92,Source_GM_code_CBS!C:C,0)) -> GM1979 | D92: =Source_NS_Dashboard!I92 -> 465 (2009) | E92: =IFERROR(LEFT(D92,FIND(" ",D92,1)-1),"0") -> 465 | F92: =SUBSTITUTE(E92,".","") -> 465 | G92: =VALUE(F92) -> 465 | H92: =G92/(SUM($G$2:$G$399)) -> 0.00018413034
A93: =Source_NS_Dashboard!B93 -> Den Dolder | B93: Zeist | C93: =INDEX(Source_GM_code_CBS!B:B,MATCH(Calculation!B93,Source_GM_code_CBS!C:C,0)) -> GM0355 | D93: =Source_NS_Dashboard!I93 -> 1.783 (2023) | E93: =IFERROR(LEFT(D93,FIND(" ",D93,1)-1),"0") -> 1.783 | F93: =SUBSTITUTE(E93,".","") -> 1783 | G93: =VALUE(F93) -> 1783 | H93: =G93/(SUM($G$2:$G$399)) -> 0.00070603096
A94: =Source_NS_Dashboard!B94 -> Den Haag | B94: 's-Gravenhage | C94: =INDEX(Source_GM_code_CBS!B:B,MATCH(Calculation!B94,Source_GM_code_CBS!C:C,0)) -> GM0518 | D94: =Source_NS_Dashboard!I94 -> 80.091 (2024) | E94: =IFERROR(LEFT(D94,FIND(" ",D94,1)-1),"0") -> 80.091 | F94: =SUBSTITUTE(E94,".","") -> 80091 | G94: =VALUE(F94) -> 80091 | H94: =G94/(SUM($G$2:$G$399)) -> 0.031714372
A95: =Source_NS_Dashboard!B95 -> Den Haag | B95: 's-Gravenhage | C95: =INDEX(Source_GM_code_CBS!B:B,MATCH(Calculation!B95,Source_GM_code_CBS!C:C,0)) -> GM0518 | D95: =Source_NS_Dashboard!I95 -> 31.212 (2024) (NS) | E95: =IFERROR(LEFT(D95,FIND(" ",D95,1)-1),"0") -> 31.212 | F95: =SUBSTITUTE(E95,".","") -> 31212 | G95: =VALUE(F95) -> 31212 | H95: =G95/(SUM($G$2:$G$399)) -> 0.012359304
A96: =Source_NS_Dashboard!B96 -> Den Haag | B96: 's-Gravenhage | C96: =INDEX(Source_GM_code_CBS!B:B,MATCH(Calculation!B96,Source_GM_code_CBS!C:C,0)) -> GM0518 | D96: =Source_NS_Dashboard!I96 -> 16.862 (2024) | E96: =IFERROR(LEFT(D96,FIND(" ",D96,1)-1),"0") -> 16.862 | F96: =SUBSTITUTE(E96,".","") -> 16862 | G96: =VALUE(F96) -> 16862 | H96: =G96/(SUM($G$2:$G$399)) -> 0.0066770017
...

Sheet Source_NS_Dashboard
A1: Naam | B1: Plaats | C1: Afk | D1: Opening | E1: Per | F1: Psp | G1: Spoorlijn | H1: Vervoerders | I1: Reizigers per dag | J1: 0 | K1: 1
A2: Aalten | B2: Aalten | C2: Atn | D2: 1885 | E2: 1 | F2: 2 | G2: Winterswijk-Zevenaar | H2: Arriva | I2: 1.531 (2008)
A3: Abcoude | B3: Abcoude | C3: Ac | D3: 1843 | E3: 1 | F3: 2 | G3: Rhijnspoorweg | H3: NS | I3: 1.599 (2022)
A4: Akkrum | B4: Akkrum | C4: Akm | D4: 1868 | E4: 1 | F4: 2 | G4: Staatslijn A | H4: NS | I4: 725 (2023)
A5: Alkmaar | B5: Alkmaar | C5: Amr | D5: 1865 | E5: 3 | F5: 5 | G5: Staatslijn K Alkmaar-Hoorn | H5: NS | I5: 15.272 (2024)
A6: Alkmaar Noord | B6: Alkmaar | C6: Amrn | D6: 1980 | E6: 2 | F6: 2 | G6: Staatslijn K Alkmaar-Hoorn | H6: NS | I6: 3.526 (2023)
A7: Almelo | B7: Almelo | C7: Aml | D7: 1865 | E7: 1 | F7: 3 | G7: Almelo-Salzbergen Zwolle-Almelo Deventer-Almelo Mariënberg-Almelo | H7: Arriva Keolis NS | I7: 6.544 (2024) (NS)
A8: Almelo De Riet | B8: Almelo | C8: Amri | D8: 1926 | E8: 2 | F8: 2 | G8: Almelo-Salzbergen | H8: Keolis NS | I8: 182 (2023) (NS)
A9: Almere Buiten | B9: Almere Buiten | C9: Almb | D9: 1987 | E9: 2 | F9: 2 | G9: Flevolijn | H9: NS | I9: 4.679 (2024)
A10: Almere Centrum | B10: Almere Stad | C10: Alm | D10: 1987 | E10: 2 | F10: 4 | G10: Flevolijn | H10: Arriva NS | I10: 26.979 (2024) (NS)
A11: Almere Muziekwijk | B11: Almere Stad | C11: Almm | D11: 1987 | E11: 2 | F11: 2 | G11: Flevolijn | H11: NS | I11: 4.585 (2023)
A12: Almere Oostvaarders | B12: Almere Buiten | C12: Almo | D12: 2004 | E12: 2 | F12: 4 | G12: Flevolijn | H12: NS | I12: 3.849 (2023)
A13: Almere Parkwijk | B13: Almere Stad | C13: Almp | D13: 1996 | E13: 2 | F13: 2 | G13: Flevolijn | H13: NS | I13: 2.208 (2023)
... A208: Hurdegaryp | B208: Hardegarijp | C208: Hdg | D208: 1866 | E208: 2 | F208: 2 | G208: Staatslijn B | H208: Arriva | I208: -
A209: IJlst | B209: IJlst | C209: IJt | D209: 1985 | E209: 1 | F209: 1 | G209: Leeuwarden-Stavoren | H209: Arriva
A210: Kampen | B210: Kampen | C210: Kpn | D210: 1865 | E210: 1 | F210: 1 | G210: Centraalspoorweg (Kamperlijntje) | H210: Keolis | I210: -
A211: Kampen Zuid | B211: Kampen | C211: Kpnz | D211: 2012 | E211: 2 | F211: 2 | G211: Hanzelijn | H211: NS | I211: 1.612 (2023)
A212: Kapelle-Biezelinge | B212: Biezelinge Kapelle | C212: Bzl | D212: 1868 | E212: 2 | F212: 2 | G212: Staatslijn F | H212: NS | I212: 962 (2023)
A213: Kerkrade Centrum | B213: Kerkrade | C213: Krd | D213: 1949 | E213: 1 | F213: 2 | G213: Heuvellandlijn Miljoenenlijn | H213: Arriva ZLSM | I213: -
A214: Kesteren | B214: Kesteren | C214: Ktr | D214: 1882 | E214: 2 | F214: 2 | G214: Betuwelijn | H214: Arriva | I214: -
A215: Klarenbeek | B215: Klarenbeek | C215: Kbk | D215: 1882 | E215: 2 | F215: 2 | G215: Oosterspoorweg | H215: Arriva | I215: -
A216: Klimmen-Ransdaal | B216: Klimmen Ransdaal | C216: Kmr | D216: 1915 | E216: 2 | F216: 2 | G216: Heuvellandlijn | H216: Arriva | I216: -
A217: Koog aan de Zaan | B217: Koog aan de Zaan | C217: Kz | D217: 1869 | E217: 2 | F217: 2 | G217: Staatslijn K | H217: NS | I217: 2.551 (2023)
A218: Koudum-Molkwerum | B218: Molkwerum | C218: Kmw | D218: 1885 | E218: 1 | F218: 1 | G218: Leeuwarden-Stavoren | H218: Arriva | I218: 49 (2018)
A219: Krabbendijke | B219: Krabbendijke | C219: Kbd | D219: 1868 | E219: 2 | F219: 2 | G219: Staatslijn F | H219: NS | I219: 696 (2023)
A220: Krommenie-Assendelft | B220: Assendelft Krommenie | C220: Kma | D220: 2008 | E220: 2 | F220: 2 | G220: Staatslijn K | H220: NS | I220: 4.579 (2023)
A221: Kropswolde | B221: Kropswolde | C221: Kw | D221: 1868 | E221: 2 | F221: 2 | G221: Staatslijn B | H221: Arriva | I221: 511 (2009)
... A384: Zaandam | B384: Zaandam | C384: Zd | D384: 1869 | E384: 2 | F384: 4 | G384: Staatslijn K Zaandam-Enkhuizen | H384: NS | I384: 23.093 (2023)
B385: Zaandam | C385: Zdk | D385: 1989 | E385: 2 | F385: 2 | G385: Zaandam-Enkhuizen | H385: NS | I385: 1.349 (2023)
A386: Zaandijk Zaanse Schans | B386: Zaandijk | C386: Zzs | D386: 1869 | E386: 1 | F386: 2 | G386: Staatslijn K | H386: NS | I386: 3.677 (2023)
A387: Zaltbommel | B387: Zaltbommel | C387: Zbm | D387: 1869 | E387: 2 | F387: 2 | G387: Staatslijn H | H387: NS | I387: 3.272 (2023)
A388: Zandvoort aan Zee | B388: Zandvoort | C388: Zvt | D388: 1908 | E388: 3 | F388: 2 | G388: Haarlem-Zandvoort | H388: NS | I388: 5.476 (2023)
A389: Zetten-Andelst | B389: Zetten | C389: Za | D389: 1882 | E389: 2 | F389: 2 | G389: Betuwelijn | H389: Arriva | I389: -
A390: Zevenaar | B390: Zevenaar | C390: Zv | D390: 1856 | E390: 2 | F390: 3 | G390: Rhijnspoorweg Winterswijk-Zevenaar | H390: Arriva Breng VIAS GmbH | I390: 3.641 (2005)
A391: Zevenbergen | B391: Zevenbergen | C391: Zvb | D391: 1854 | E391: 2 | F391: 2 | G391: Spoorlijn 12 | H391: NS | I391: 939 (2023)
A392: Zoetermeer | B392: Zoetermeer | C392: Ztm | D392: 1973 | E392: 2 | F392: 2 | G392: Gouda-Den Haag | H392: NS | I392: 2.302 (2023)
A393: Zoetermeer Oost | B393: Zoetermeer | C393: Ztmo | D393: 1965 | E393: 1 | F393: 2 | G393: Gouda-Den Haag | H393: NS | I393: 1.691 (2023)
A394: Zuidbroek | B394: Zuidbroek | C394: Zb | D394: 1868 | E394: 2 | F394: 3 | G394: Staatslijn B Stadskanaal-Zuidbroek | H394: Arriva | I394: 838 (2009)
A395: Zuidhorn | B395: Zuidhorn | C395: Zh | D395: 1866 | E395: 3 | F395: 3 | G395: Staatslijn B | H395: Arriva | I395: -
A396: Zutphen | B396: Zutphen | C396: Zp | D396: 1865 | E396: 2 | F396: 3 | G396: Oosterspoorweg Staatslijn A Staatslijn D Zutphen-Winterswijk | H396: Arriva NS | I396: 10.763 (2023) (NS)
...

Sheet Source_GM_code_CBS
A1: Gemeentecode | B1: GemeentecodeGM | C1: Gemeentenaam | D1: Provinciecode | E1: ProvinciecodePV | F1: Provincienaam
A2: 1680 | B2: GM1680 | C2: Aa en Hunze | D2: 22 | E2: PV22 | F2: Drenthe
A3: 0358 | B3: GM0358 | C3: Aalsmeer | D3: 27 | E3: PV27 | F3: Noord-Holland
A4: 0197 | B4: GM0197 | C4: Aalten | D4: 25 | E4: PV25 | F4: Gelderland
A5: 0059 | B5: GM0059 | C5: Achtkarspelen | D5: 21 | E5: PV21 | F5: Fryslân
A6: 0482 | B6: GM0482 | C6: Alblasserdam | D6: 28 | E6: PV28 | F6: Zuid-Holland
A7: 0613 | B7: GM0613 | C7: Albrandswaard | D7: 28 | E7: PV28 | F7: Zuid-Holland
A8: 0361 | B8: GM0361 | C8: Alkmaar | D8: 27 | E8: PV27 | F8: Noord-Holland
A9: 0141 | B9: GM0141 | C9: Almelo | D9: 23 | E9: PV23 | F9: Overijssel
A10: 0034 | B10: GM0034 | C10: Almere | D10: 24 | E10: PV24 | F10: Flevoland
A11: 0484 | B11: GM0484 | C11: Alphen aan den Rijn | D11: 28 | E11: PV28 | F11: Zuid-Holland
A12: 1723 | B12: GM1723 | C12: Alphen-Chaam | D12: 30 | E12: PV30 | F12: Noord-Brabant
... A343: 0193 | B343: GM0193 | C343: Zwolle | D343: 23 | E343: PV23 | F343: Overijssel
