Workbook
Name Gemeenten_alfabetisch_2018: #REF!
Name Gemeenten_alfabetisch_2019: CBS_gemeenten_2019_2018!$A$2:$F$357

Sheet Calculation
A1: GM_code | B1: energy_production_wet_biomass_max_demand | C1: energy_production_dry_biomass_max_demand | D1: energy_production_oily_biomass_max_demand
A2: GM1680 | B2: =IFERROR(INDEX(data!$A$1:$J$385,MATCH($A2,data!$A:$A,0),MATCH(B$1,data!$1:$1,0)),INDEX(Calculation_mapping!$B$58:$E$75,MATCH($A2,Calculation_mapping!$B$58:$B$75,0),MATCH(B$1,Calculation_mapping!$B$58:$E$58,0)))*1000 -> 395.37229 | C2: =IFERROR(INDEX(data!$A$1:$J$385,MATCH($A2,data!$A:$A,0),MATCH(C$1,data!$1:$1,0)),INDEX(Calculation_mapping!$B$58:$E$75,MATCH($A2,Calculation_mapping!$B$58:$B$75,0),MATCH(C$1,Calculation_mapping!$B$58:$E$58,0)))*1000 -> 206.60893 | D2: =IFERROR(INDEX(data!$A$1:$J$385,MATCH($A2,data!$A:$A,0),MATCH(D$1,data!$1:$1,0)),INDEX(Calculation_mapping!$B$58:$E$75,MATCH($A2,Calculation_mapping!$B$58:$B$75,0),MATCH(D$1,Calculation_mapping!$B$58:$E$58,0)))*1000 -> 15.42359
A3: GM0358 | B3: =IFERROR(INDEX(data!$A$1:$J$385,MATCH($A3,data!$A:$A,0),MATCH(B$1,data!$1:$1,0)),INDEX(Calculation_mapping!$B$58:$E$75,MATCH($A3,Calculation_mapping!$B$58:$B$75,0),MATCH(B$1,Calculation_mapping!$B$58:$E$58,0)))*1000 -> 192.87007 | C3: =IFERROR(INDEX(data!$A$1:$J$385,MATCH($A3,data!$A:$A,0),MATCH(C$1,data!$1:$1,0)),INDEX(Calculation_mapping!$B$58:$E$75,MATCH($A3,Calculation_mapping!$B$58:$B$75,0),MATCH(C$1,Calculation_mapping!$B$58:$E$58,0)))*1000 -> 83.722821 | D3: =IFERROR(INDEX(data!$A$1:$J$385,MATCH($A3,data!$A:$A,0),MATCH(D$1,data!$1:$1,0)),INDEX(Calculation_mapping!$B$58:$E$75,MATCH($A3,Calculation_mapping!$B$58:$B$75,0),MATCH(D$1,Calculation_mapping!$B$58:$E$58,0)))*1000 -> 19.276754
A4: GM0197 | B4: =IFERROR(INDEX(data!$A$1:$J$385,MATCH($A4,data!$A:$A,0),MATCH(B$1,data!$1:$1,0)),INDEX(Calculation_mapping!$B$58:$E$75,MATCH($A4,Calculation_mapping!$B$58:$B$75,0),MATCH(B$1,Calculation_mapping!$B$58:$E$58,0)))*1000 -> 246.52073 | C4: =IFERROR(INDEX(data!$A$1:$J$385,MATCH($A4,data!$A:$A,0),MATCH(C$1,data!$1:$1,0)),INDEX(Calculation_mapping!$B$58:$E$75,MATCH($A4,Calculation_mapping!$B$58:$B$75,0),MATCH(C$1,Calculation_mapping!$B$58:$E$58,0)))*1000 -> 117.79276 | D4: =IFERROR(INDEX(data!$A$1:$J$385,MATCH($A4,data!$A:$A,0),MATCH(D$1,data!$1:$1,0)),INDEX(Calculation_mapping!$B$58:$E$75,MATCH($A4,Calculation_mapping!$B$58:$B$75,0),MATCH(D$1,Calculation_mapping!$B$58:$E$58,0)))*1000 -> 16.41088
A5: GM0059 | B5: =IFERROR(INDEX(data!$A$1:$J$385,MATCH($A5,data!$A:$A,0),MATCH(B$1,data!$1:$1,0)),INDEX(Calculation_mapping!$B$58:$E$75,MATCH($A5,Calculation_mapping!$B$58:$B$75,0),MATCH(B$1,Calculation_mapping!$B$58:$E$58,0)))*1000 -> 206.59389 | C5: =IFERROR(INDEX(data!$A$1:$J$385,MATCH($A5,data!$A:$A,0),MATCH(C$1,data!$1:$1,0)),INDEX(Calculation_mapping!$B$58:$E$75,MATCH($A5,Calculation_mapping!$B$58:$B$75,0),MATCH(C$1,Calculation_mapping!$B$58:$E$58,0)))*1000 -> 150.53426 | D5: =IFERROR(INDEX(data!$A$1:$J$385,MATCH($A5,data!$A:$A,0),MATCH(D$1,data!$1:$1,0)),INDEX(Calculation_mapping!$B$58:$E$75,MATCH($A5,Calculation_mapping!$B$58:$B$75,0),MATCH(D$1,Calculation_mapping!$B$58:$E$58,0)))*1000 -> 16.92184
A6: GM0482 | B6: =IFERROR(INDEX(data!$A$1:$J$385,MATCH($A6,data!$A:$A,0),MATCH(B$1,data!$1:$1,0)),INDEX(Calculation_mapping!$B$58:$E$75,MATCH($A6,Calculation_mapping!$B$58:$B$75,0),MATCH(B$1,Calculation_mapping!$B$58:$E$58,0)))*1000 -> 41.201929 | C6: =IFERROR(INDEX(data!$A$1:$J$385,MATCH($A6,data!$A:$A,0),MATCH(C$1,data!$1:$1,0)),INDEX(Calculation_mapping!$B$58:$E$75,MATCH($A6,Calculation_mapping!$B$58:$B$75,0),MATCH(C$1,Calculation_mapping!$B$58:$E$58,0)))*1000 -> 51.742699 | D6: =IFERROR(INDEX(data!$A$1:$J$385,MATCH($A6,data!$A:$A,0),MATCH(D$1,data!$1:$1,0)),INDEX(Calculation_mapping!$B$58:$E$75,MATCH($A6,Calculation_mapping!$B$58:$B$75,0),MATCH(D$1,Calculation_mapping!$B$58:$E$58,0)))*1000 -> 12.193179
A7: GM0613 | B7: =IFERROR(INDEX(data!$A$1:$J$385,MATCH($A7,data!$A:$A,0),MATCH(B$1,data!$1:$1,0)),INDEX(Calculation_mapping!$B$58:$E$75,MATCH($A7,Calculation_mapping!$B$58:$B$75,0),MATCH(B$1,Calculation_mapping!$B$58:$E$58,0)))*1000 -> 68.674876 | C7: =IFERROR(INDEX(data!$A$1:$J$385,MATCH($A7,data!$A:$A,0),MATCH(C$1,data!$1:$1,0)),INDEX(Calculation_mapping!$B$58:$E$75,MATCH($A7,Calculation_mapping!$B$58:$B$75,0),MATCH(C$1,Calculation_mapping!$B$58:$E$58,0)))*1000 -> 74.128048 | D7: =IFERROR(INDEX(data!$A$1:$J$385,MATCH($A7,data!$A:$A,0),MATCH(D$1,data!$1:$1,0)),INDEX(Calculation_mapping!$B$58:$E$75,MATCH($A7,Calculation_mapping!$B$58:$B$75,0),MATCH(D$1,Calculation_mapping!$B$58:$E$58,0)))*1000 -> 15.35372
A8: GM0361 | B8: =IFERROR(INDEX(data!$A$1:$J$385,MATCH($A8,data!$A:$A,0),MATCH(B$1,data!$1:$1,0)),INDEX(Calculation_mapping!$B$58:$E$75,MATCH($A8,Calculation_mapping!$B$58:$B$75,0),MATCH(B$1,Calculation_mapping!$B$58:$E$58,0)))*1000 -> 405.45866 | C8: =IFERROR(INDEX(data!$A$1:$J$385,MATCH($A8,data!$A:$A,0),MATCH(C$1,data!$1:$1,0)),INDEX(Calculation_mapping!$B$58:$E$75,MATCH($A8,Calculation_mapping!$B$58:$B$75,0),MATCH(C$1,Calculation_mapping!$B$58:$E$58,0)))*1000 -> 317.04221 | D8: =IFERROR(INDEX(data!$A$1:$J$385,MATCH($A8,data!$A:$A,0),MATCH(D$1,data!$1:$1,0)),INDEX(Calculation_mapping!$B$58:$E$75,MATCH($A8,Calculation_mapping!$B$58:$B$75,0),MATCH(D$1,Calculation_mapping!$B$58:$E$58,0)))*1000 -> 65.955807
A9: GM0141 | B9: =IFERROR(INDEX(data!$A$1:$J$385,MATCH($A9,data!$A:$A,0),MATCH(B$1,data!$1:$1,0)),INDEX(Calculation_mapping!$B$58:$E$75,MATCH($A9,Calculation_mapping!$B$58:$B$75,0),MATCH(B$1,Calculation_mapping!$B$58:$E$58,0)))*1000 -> 218.59215 | C9: =IFERROR(INDEX(data!$A$1:$J$385,MATCH($A9,data!$A:$A,0),MATCH(C$1,data!$1:$1,0)),INDEX(Calculation_mapping!$B$58:$E$75,MATCH($A9,Calculation_mapping!$B$58:$B$75,0),MATCH(C$1,Calculation_mapping!$B$58:$E$58,0)))*1000 -> 224.26839 | D9: =IFERROR(INDEX(data!$A$1:$J$385,MATCH($A9,data!$A:$A,0),MATCH(D$1,data!$1:$1,0)),INDEX(Calculation_mapping!$B$58:$E$75,MATCH($A9,Calculation_mapping!$B$58:$B$75,0),MATCH(D$1,Calculation_mapping!$B$58:$E$58,0)))*1000 -> 44.260345
A10: GM0034 | B10: =IFERROR(INDEX(data!$A$1:$J$385,MATCH($A10,data!$A:$A,0),MATCH(B$1,data!$1:$1,0)),INDEX(Calculation_mapping!$B$58:$E$75,MATCH($A10,Calculation_mapping!$B$58:$B$75,0),MATCH(B$1,Calculation_mapping!$B$58:$E$58,0)))*1000 -> 588.57011 | C10: =IFERROR(INDEX(data!$A$1:$J$385,MATCH($A10,data!$A:$A,0),MATCH(C$1,data!$1:$1,0)),INDEX(Calculation_mapping!$B$58:$E$75,MATCH($A10,Calculation_mapping!$B$58:$B$75,0),MATCH(C$1,Calculation_mapping!$B$58:$E$58,0)))*1000 -> 610.69085 | D10: =IFERROR(INDEX(data!$A$1:$J$385,MATCH($A10,data!$A:$A,0),MATCH(D$1,data!$1:$1,0)),INDEX(Calculation_mapping!$B$58:$E$75,MATCH($A10,Calculation_mapping!$B$58:$B$75,0),MATCH(D$1,Calculation_mapping!$B$58:$E$58,0)))*1000 -> 126.31474
A11: GM0484 | B11: =IFERROR(INDEX(data!$A$1:$J$385,MATCH($A11,data!$A:$A,0),MATCH(B$1,data!$1:$1,0)),INDEX(Calculation_mapping!$B$58:$E$75,MATCH($A11,Calculation_mapping!$B$58:$B$75,0),MATCH(B$1,Calculation_mapping!$B$58:$E$58,0)))*1000 -> 406.04847 | C11: =IFERROR(INDEX(data!$A$1:$J$385,MATCH($A11,data!$A:$A,0),MATCH(C$1,data!$1:$1,0)),INDEX(Calculation_mapping!$B$58:$E$75,MATCH($A11,Calculation_mapping!$B$58:$B$75,0),MATCH(C$1,Calculation_mapping!$B$58:$E$58,0)))*1000 -> 318.28344 | D11: =IFERROR(INDEX(data!$A$1:$J$385,MATCH($A11,data!$A:$A,0),MATCH(D$1,data!$1:$1,0)),INDEX(Calculation_mapping!$B$58:$E$75,MATCH($A11,Calculation_mapping!$B$58:$B$75,0),MATCH(D$1,Calculation_mapping!$B$58:$E$58,0)))*1000 -> 67.430969
A12: GM1723 | B12: =IFERROR(INDEX(data!$A$1:$J$385,MATCH($A12,data!$A:$A,0),MATCH(B$1,data!$1:$1,0)),INDEX(Calculation_mapping!$B$58:$E$75,MATCH($A12,Calculation_mapping!$B$58:$B$75,0),MATCH(B$1,Calculation_mapping!$B$58:$E$58,0)))*1000 -> 204.47047 | C12: =IFERROR(INDEX(data!$A$1:$J$385,MATCH($A12,data!$A:$A,0),MATCH(C$1,data!$1:$1,0)),INDEX(Calculation_mapping!$B$58:$E$75,MATCH($A12,Calculation_mapping!$B$58:$B$75,0),MATCH(C$1,Calculation_mapping!$B$58:$E$58,0)))*1000 -> 107.02505 | D12: =IFERROR(INDEX(data!$A$1:$J$385,MATCH($A12,data!$A:$A,0),MATCH(D$1,data!$1:$1,0)),INDEX(Calculation_mapping!$B$58:$E$75,MATCH($A12,Calculation_mapping!$B$58:$B$75,0),MATCH(D$1,Calculation_mapping!$B$58:$E$58,0)))*1000 -> 6.1661552
A13: GM1959 | B13: =IFERROR(INDEX(data!$A$1:$J$385,MATCH($A13,data!$A:$A,0),MATCH(B$1,data!$1:$1,0)),INDEX(Calculation_mapping!$B$58:$E$75,MATCH($A13,Calculation_mapping!$B$58:$B$75,0),MATCH(B$1,Calculation_mapping!$B$58:$E$58,0)))*1000 -> 643.2952 | C13: =IFERROR(INDEX(data!$A$1:$J$385,MATCH($A13,data!$A:$A,0),MATCH(C$1,data!$1:$1,0)),INDEX(Calculation_mapping!$B$58:$E$75,MATCH($A13,Calculation_mapping!$B$58:$B$75,0),MATCH(C$1,Calculation_mapping!$B$58:$E$58,0)))*1000 -> 232.17257 | D13: =IFERROR(INDEX(data!$A$1:$J$385,MATCH($A13,data!$A:$A,0),MATCH(D$1,data!$1:$1,0)),INDEX(Calculation_mapping!$B$58:$E$75,MATCH($A13,Calculation_mapping!$B$58:$B$75,0),MATCH(D$1,Calculation_mapping!$B$58:$E$58,0)))*1000 -> 33.650475
... A343: GM0193 | B343: =IFERROR(INDEX(data!$A$1:$J$385,MATCH($A343,data!$A:$A,0),MATCH(B$1,data!$1:$1,0)),INDEX(Calculation_mapping!$B$58:$E$75,MATCH($A343,Calculation_mapping!$B$58:$B$75,0),MATCH(B$1,Calculation_mapping!$B$58:$E$58,0)))*1000 -> 383.96941 | C343: =IFERROR(INDEX(data!$A$1:$J$385,MATCH($A343,data!$A:$A,0),MATCH(C$1,data!$1:$1,0)),INDEX(Calculation_mapping!$B$58:$E$75,MATCH($A343,Calculation_mapping!$B$58:$B$75,0),MATCH(C$1,Calculation_mapping!$B$58:$E$58,0)))*1000 -> 357.32033 | D343: =IFERROR(INDEX(data!$A$1:$J$385,MATCH($A343,data!$A:$A,0),MATCH(D$1,data!$1:$1,0)),INDEX(Calculation_mapping!$B$58:$E$75,MATCH($A343,Calculation_mapping!$B$58:$B$75,0),MATCH(D$1,Calculation_mapping!$B$58:$E$58,0)))*1000 -> 77.462439

Sheet Calculation_mapping
A1: Oude gemeente | B1: code | C1: Nieuwe gemeente | D1: code_2 | E1: energy_production_wet_biomass_max_demand | F1: energy_production_dry_biomass_max_demand | G1: energy_production_oily_biomass_max_demand
A2: Aalburg | B2: GM0738 | C2: Altena | D2: GM1959 | E2: =INDEX(data!$A$1:$J$385,MATCH($B2,data!$A:$A,0),MATCH(E$1,data!$1:$1,0)) -> 0.135413 | F2: =INDEX(data!$A$1:$J$385,MATCH($B2,data!$A:$A,0),MATCH(F$1,data!$1:$1,0)) -> 0.050706043 | G2: =INDEX(data!$A$1:$J$385,MATCH($B2,data!$A:$A,0),MATCH(G$1,data!$1:$1,0)) -> 0.0080933446
A3: Onderbanken | B3: GM0881 | C3: Beekdaelen | D3: GM1954 | E3: =INDEX(data!$A$1:$J$385,MATCH($B3,data!$A:$A,0),MATCH(E$1,data!$1:$1,0)) -> 0.02960459 | F3: =INDEX(data!$A$1:$J$385,MATCH($B3,data!$A:$A,0),MATCH(F$1,data!$1:$1,0)) -> 0.02951955 | G3: =INDEX(data!$A$1:$J$385,MATCH($B3,data!$A:$A,0),MATCH(G$1,data!$1:$1,0)) -> 0.004728054
A4: Zederik | B4: GM0707 | C4: Vijfheerenlanden | D4: GM1961 | E4: =INDEX(data!$A$1:$J$385,MATCH($B4,data!$A:$A,0),MATCH(E$1,data!$1:$1,0)) -> #N/A | F4: =INDEX(data!$A$1:$J$385,MATCH($B4,data!$A:$A,0),MATCH(F$1,data!$1:$1,0)) -> #N/A | G4: =INDEX(data!$A$1:$J$385,MATCH($B4,data!$A:$A,0),MATCH(G$1,data!$1:$1,0)) -> #N/A
A5: Franekeradeel | B5: GM0070 | C5: Waadhoeke | D5: GM1949 | E5: =INDEX(data!$A$1:$J$385,MATCH($B5,data!$A:$A,0),MATCH(E$1,data!$1:$1,0)) -> #N/A | F5: =INDEX(data!$A$1:$J$385,MATCH($B5,data!$A:$A,0),MATCH(F$1,data!$1:$1,0)) -> #N/A | G5: =INDEX(data!$A$1:$J$385,MATCH($B5,data!$A:$A,0),MATCH(G$1,data!$1:$1,0)) -> #N/A
A6: Geldermalsen | B6: GM0236 | C6: West Betuwe | D6: GM1960 | E6: =INDEX(data!$A$1:$J$385,MATCH($B6,data!$A:$A,0),MATCH(E$1,data!$1:$1,0)) -> #N/A | F6: =INDEX(data!$A$1:$J$385,MATCH($B6,data!$A:$A,0),MATCH(F$1,data!$1:$1,0)) -> #N/A | G6: =INDEX(data!$A$1:$J$385,MATCH($B6,data!$A:$A,0),MATCH(G$1,data!$1:$1,0)) -> #N/A
A7: Marum | B7: GM0025 | C7: Westerkwartier | D7: GM1969 | E7: =INDEX(data!$A$1:$J$385,MATCH($B7,data!$A:$A,0),MATCH(E$1,data!$1:$1,0)) -> 0.11961962 | F7: =INDEX(data!$A$1:$J$385,MATCH($B7,data!$A:$A,0),MATCH(F$1,data!$1:$1,0)) -> 0.046582139 | G7: =INDEX(data!$A$1:$J$385,MATCH($B7,data!$A:$A,0),MATCH(G$1,data!$1:$1,0)) -> 0.0063696888
A8: Bellingwedde | B8: GM0007 | C8: Westerwolde | D8: GM1950 | E8: =INDEX(data!$A$1:$J$385,MATCH($B8,data!$A:$A,0),MATCH(E$1,data!$1:$1,0)) -> #N/A | F8: =INDEX(data!$A$1:$J$385,MATCH($B8,data!$A:$A,0),MATCH(F$1,data!$1:$1,0)) -> #N/A | G8: =INDEX(data!$A$1:$J$385,MATCH($B8,data!$A:$A,0),MATCH(G$1,data!$1:$1,0)) -> #N/A
A9: Woudrichem | B9: GM0874 | C9: Altena | D9: GM1959 | E9: =INDEX(data!$A$1:$J$385,MATCH($B9,data!$A:$A,0),MATCH(E$1,data!$1:$1,0)) -> 0.15373995 | F9: =INDEX(data!$A$1:$J$385,MATCH($B9,data!$A:$A,0),MATCH(F$1,data!$1:$1,0)) -> 0.077058053 | G9: =INDEX(data!$A$1:$J$385,MATCH($B9,data!$A:$A,0),MATCH(G$1,data!$1:$1,0)) -> 0.0089737031
A10: Nuth | B10: GM0951 | C10: Beekdaelen | D10: GM1954 | E10: =INDEX(data!$A$1:$J$385,MATCH($B10,data!$A:$A,0),MATCH(E$1,data!$1:$1,0)) -> 0.059147119 | F10: =INDEX(data!$A$1:$J$385,MATCH($B10,data!$A:$A,0),MATCH(F$1,data!$1:$1,0)) -> 0.050337816 | G10: =INDEX(data!$A$1:$J$385,MATCH($B10,data!$A:$A,0),MATCH(G$1,data!$1:$1,0)) -> 0.0092270568
A11: Vianen | B11: GM0620 | C11: Vijfheerenlanden | D11: GM1961 | E11: =INDEX(data!$A$1:$J$385,MATCH($B11,data!$A:$A,0),MATCH(E$1,data!$1:$1,0)) -> #N/A | F11: =INDEX(data!$A$1:$J$385,MATCH($B11,data!$A:$A,0),MATCH(F$1,data!$1:$1,0)) -> #N/A | G11: =INDEX(data!$A$1:$J$385,MATCH($B11,data!$A:$A,0),MATCH(G$1,data!$1:$1,0)) -> #N/A
A12: het Bildt | B12: GM0063 | C12: Waadhoeke | D12: GM1949 | E12: =INDEX(data!$A$1:$J$385,MATCH($B12,data!$A:$A,0),MATCH(E$1,data!$1:$1,0)) -> #N/A | F12: =INDEX(data!$A$1:$J$385,MATCH($B12,data!$A:$A,0),MATCH(F$1,data!$1:$1,0)) -> #N/A | G12: =INDEX(data!$A$1:$J$385,MATCH($B12,data!$A:$A,0),MATCH(G$1,data!$1:$1,0)) -> #N/A
A13: Lingewaal | B13: GM0733 | C13: West Betuwe | D13: GM1960 | E13: =INDEX(data!$A$1:$J$385,MATCH($B13,data!$A:$A,0),MATCH(E$1,data!$1:$1,0)) -> #N/A | F13: =INDEX(data!$A$1:$J$385,MATCH($B13,data!$A:$A,0),MATCH(F$1,data!$1:$1,0)) -> #N/A | G13: =INDEX(data!$A$1:$J$385,MATCH($B13,data!$A:$A,0),MATCH(G$1,data!$1:$1,0)) -> #N/A
... A55: Heerhugowaard | B55: GM0398 | C55: Dijk en Waard | D55: GM1981 | E55: =INDEX(data!$A$1:$J$385,MATCH($B55,data!$A:$A,0),MATCH(E$1,data!$1:$1,0)) -> 0.14906539 | F55: =INDEX(data!$A$1:$J$385,MATCH($B55,data!$A:$A,0),MATCH(F$1,data!$1:$1,0)) -> 0.16472114 | G55: =INDEX(data!$A$1:$J$385,MATCH($B55,data!$A:$A,0),MATCH(G$1,data!$1:$1,0)) -> 0.034474331
A58: gemeente | B58: code | C58: energy_production_wet_biomass_max_demand | D58: energy_production_dry_biomass_max_demand | E58: energy_production_oily_biomass_max_demand
A59: Altena | B59: GM1959 | C59: =SUMIF($D$2:$D$55,$B59,$E$2:$E$55) -> 0.6432952 | D59: =SUMIF($D$2:$D$55,$B59,$F$2:$F$55) -> 0.23217257 | E59: =SUMIF($D$2:$D$55,$B59,$G$2:$G$55) -> 0.033650475
A60: Beekdaelen | B60: GM1954 | C60: =SUMIF($D$2:$D$55,$B60,$E$2:$E$55) -> 0.12833467 | D60: =SUMIF($D$2:$D$55,$B60,$F$2:$F$55) -> 0.12376643 | E60: =SUMIF($D$2:$D$55,$B60,$G$2:$G$55) -> 0.021706398
A61: Vijfheerenlanden | B61: GM1961 | C61: =SUMIF($D$2:$D$55,$B61,$E$2:$E$55) -> #N/A | D61: =SUMIF($D$2:$D$55,$B61,$F$2:$F$55) -> #N/A | E61: =SUMIF($D$2:$D$55,$B61,$G$2:$G$55) -> #N/A
A62: Waadhoeke | B62: GM1949 | C62: =SUMIF($D$2:$D$55,$B62,$E$2:$E$55) -> #N/A | D62: =SUMIF($D$2:$D$55,$B62,$F$2:$F$55) -> #N/A | E62: =SUMIF($D$2:$D$55,$B62,$G$2:$G$55) -> #N/A
A63: West Betuwe | B63: GM1960 | C63: =SUMIF($D$2:$D$55,$B63,$E$2:$E$55) -> #N/A | D63: =SUMIF($D$2:$D$55,$B63,$F$2:$F$55) -> #N/A | E63: =SUMIF($D$2:$D$55,$B63,$G$2:$G$55) -> #N/A
A64: Westerkwartier | B64: GM1969 | C64: =SUMIF($D$2:$D$55,$B64,$E$2:$E$55) -> 0.70880231 | D64: =SUMIF($D$2:$D$55,$B64,$F$2:$F$55) -> 0.3176045 | E64: =SUMIF($D$2:$D$55,$B64,$G$2:$G$55) -> 0.03734871
A65: Westerwolde | B65: GM1950 | C65: =SUMIF($D$2:$D$55,$B65,$E$2:$E$55) -> #N/A | D65: =SUMIF($D$2:$D$55,$B65,$F$2:$F$55) -> #N/A | E65: =SUMIF($D$2:$D$55,$B65,$G$2:$G$55) -> #N/A
A66: Hoeksche Waard | B66: GM1963 | C66: =SUMIF($D$2:$D$55,$B66,$E$2:$E$55) -> 0.88208486 | D66: =SUMIF($D$2:$D$55,$B66,$F$2:$F$55) -> 0.33528094 | E66: =SUMIF($D$2:$D$55,$B66,$G$2:$G$55) -> 0.052648965
A67: Het hogeland | B67: GM1966 | C67: =SUMIF($D$2:$D$55,$B67,$E$2:$E$55) -> #N/A | D67: =SUMIF($D$2:$D$55,$B67,$F$2:$F$55) -> #N/A | E67: =SUMIF($D$2:$D$55,$B67,$G$2:$G$55) -> #N/A
A68: Midden-Groningen | B68: GM1952 | C68: =SUMIF($D$2:$D$55,$B68,$E$2:$E$55) -> #N/A | D68: =SUMIF($D$2:$D$55,$B68,$F$2:$F$55) -> #N/A | E68: =SUMIF($D$2:$D$55,$B68,$G$2:$G$55) -> #N/A
A69: Molenlanden | B69: GM1978 | C69: =SUMIF($D$2:$D$55,$B69,$E$2:$E$55) -> 0.51389615 | D69: =SUMIF($D$2:$D$55,$B69,$F$2:$F$55) -> 0.16875871 | E69: =SUMIF($D$2:$D$55,$B69,$G$2:$G$55) -> 0.026646491
A70: Noardeast-Fryslân | B70: GM1970 | C70: =SUMIF($D$2:$D$55,$B70,$E$2:$E$55) -> 1.152551 | D70: =SUMIF($D$2:$D$55,$B70,$F$2:$F$55) -> 0.29511998 | E70: =SUMIF($D$2:$D$55,$B70,$G$2:$G$55) -> 0.027450297
... A75: Dijk en Waard | B75: GM1980 | C75: =SUMIF($D$2:$D$55,$B75,$E$2:$E$55) -> 0.10156538 | D75: =SUMIF($D$2:$D$55,$B75,$F$2:$F$55) -> 0.074479586 | E75: =SUMIF($D$2:$D$55,$B75,$G$2:$G$55) -> 0.017006899

Sheet Source_GM_code_CBS
A1: Gemeentecode | B1: GemeentecodeGM | C1: Gemeentenaam | D1: Provinciecode | E1: ProvinciecodePV | F1: Provincienaam
A2: 1680 | B2: GM1680 | C2: Aa en Hunze | D2: 22 | E2: PV22 | F2: Drenthe
A3: 0358 | B3: GM0358 | C3: Aalsmeer | D3: 27 | E3: PV27 | F3: Noord-Holland
A4: 0197 | B4: GM0197 | C4: Aalten | D4: 25 | E4: PV25 | F4: Gelderland
A5: 0059 | B5: GM0059 | C5: Achtkarspelen | D5: 21 | E5: PV21 | F5: Fryslân
A6: 0482 | B6: GM0482 | C6: Alblasserdam | D6: 28 | E6: PV28 | F6: Zuid-Holland
A7: 0613 | B7: GM0613 | C7: Albrandswaard | D7: 28 | E7: PV28 | F7: Zuid-Holland
A8: 0361 | B8: GM0361 | C8: Alkmaar | D8: 27 | E8: PV27 | F8: Noord-Holland
A9: 0141 | B9: GM0141 | C9: Almelo | D9: 23 | E9: PV23 | F9: Overijssel
A10: 0034 | B10: GM0034 | C10: Almere | D10: 24 | E10: PV24 | F10: Flevoland
A11: 0484 | B11: GM0484 | C11: Alphen aan den Rijn | D11: 28 | E11: PV28 | F11: Zuid-Holland
A12: 1723 | B12: GM1723 | C12: Alphen-Chaam | D12: 30 | E12: PV30 | F12: Noord-Brabant
... A343: 0193 | B343: GM0193 | C343: Zwolle | D343: 23 | E343: PV23 | F343: Overijssel

Sheet Overzicht
A1: SECTOR | B1: PRODUCT | C1: SOORT | D1: MAX_DEMAND PJ (droge stof basis) | E1: DEMAND 2015 PJ (droge stof basis) | F1: Verdeelsleutel
A2: Voedings en genotmiddelen industrie | B2: Frituur en restvettten | C2: VET | D2: 10.5 | E2: 10.5 | F2: Bevolking (aantal)
B3: Natte stromen VGI | C3: NAT | D3: 6.5 | E3: 3.6 | F3: Cultuurgrond - blijvend grasland (are)
A4: RWZI/AWZI-slib | B4: Slib RWZI | C4: NAT | D4: 3.52 | E4: 2.4 | F4: Bevolking (aantal)
B5: Slib AWZI | C5: NAT | D5: 1.353 | E5: 0.42 | F5: Cultuurgrond - blijvend grasland (are)
B6: Slib verbrand | C6: AFVAL | D6: 3.39526 | E6: 3.6 | F6: Bevolking (aantal)
A7: Agrarische reststromen | B7: Drijfmest | C7: NAT | D7: 25 | E7: 2.5 | F7: Drijfmest_verdeelsleutel | G7: 0,84*mln melkoeien/1,62 mln+0,16*mln varkens/12,4mln
B8: Droge mest | C8: DROOG | D8: 8.8 | E8: 8.8 | F8: Droge_mest_verdeelsleutel | G8: 0,26*mln melkoeien/1,62 mln+0,74*mln kippen/97mln
B9: Stro | C9: DROOG | D9: 2.6 | E9: 0 | F9: Granen (are)
B10: Natte gewasresten | C10: NAT | D10: 11 | E10: 3 | F10: Akkerbouwgroenten (are)
A11: Groente-, Fruit- en Tuinafval & Organische Natte Fractie (GFT en ONF) | B11: GFT | C11: NAT | D11: 8.7 | E11: 3.5625 | F11: Bevolking (aantal)
B12: ONF in Afval (NAT) | C12: NAT | D12: 1.8 | E12: 0.6375 | F12: Bevolking (aantal)
B13: ONF in Afval (AFVAL) | C13: AFVAL | D13: 3.6864 | E13: 4.9 | F13: Bevolking (aantal)
B14: Zeefoverloop | C14: DROOG | D14: 0.728 | E14: 0.156 | F14: Bevolking (aantal)
A15: Droge biomassa | B15: Resthout uit houtverwerkende industrie | C15: DROOG | D15: 5.32 | E15: 4 | F15: Bevolking (aantal)
B16: Afvalhout | C16: DROOG | D16: 19.76 | E16: 12.5 | F16: Bevolking (aantal)
B17: Afvalhout particulier | C17: DROOG | D17: 2 | E17: 2 | F17: Bevolking (aantal)
B18: Papierresiduen | C18: AFVAL | D18: 2.3 | E18: 1.1 | F18: Bevolking (aantal)
B19: Papier in Afval | C19: AFVAL | D19: 12 | E19: 12 | F19: Bevolking (aantal)
A20: Nederlandse productiebossen | B20: Productiebos | C20: DROOG | D20: 3.2 | E20: 1.9 | F20: Bos (ha)
B21: Productiebos particulier | C21: DROOG | D21: 4 | E21: 4 | F21: Bevolking (aantal)
B22: Korte omloop bomen | C22: DROOG | D22: 0.000855 | E22: 0.000855 | F22: Totaal agrarisch terrein (ha)
B23: Korte omloop bomen (bijschatting) | C23: DROOG | D23: 0.38 | E23: 0 | F23: Totaal agrarisch terrein (ha)
B24: Import/onbekend particulier | C24: DROOG | D24: 2 | E24: 2 | F24: Bevolking (aantal)
A25: Natuur en landschapsbeheer | B25: Hout van fruit- en boomteelt | C25: DROOG | D25: 0.396 | E25: 0.02 | F25: Totaal agrarisch terrein (ha)
B26: Hout uit landschap | C26: DROOG | D26: 4.752 | E26: 5 | F26: Hout_uit_landschap_verdeelsleutel | G26: ?? 0,5*km totaal gemeentelijke en waterschapswegen/126523 km + 0,5* ha park en plantsoen/30819 ha
B27: Tuin/landbouw/openbaar groen | C27: DROOG | D27: 7 | E27: 7 | F27: Bevolking (aantal)
B28: Natuurgras+bermgras | C28: NAT | D28: 5 | E28: 0.4 | F28: Natuurgras+bermgras_verdeelsleutel | G28: ?? 0,4*km totaal gemeentelijke en waterschapswegen/126523 km + 0,6* ha bos/341270 ha (er zijn geen betere indicatoren)
B29: Heide | C29: DROOG | D29: 0.023375 | E29: 0 | F29: Open droog natuurlijk terrein (ha)
A30: Aquatische biomassa | B30: Riet en andere waterplanten | C30: NAT | D30: 18 | E30: 0 | F30: Open nat natuurlijk terrein + recreatief binnenwater + overig binnenwater (ha)
B31: Microalgen | C31: NAT | D31: 1.5 | E31: 0 | F31: Totaal agrarisch terrein (ha)
B32: Zeewier | C32: NAT | D32: 12 | E32: 0 | F32: Bevolking (aantal)
A33: Energieteelt | B33: Totale natte energieteelt | C33: NAT | D33: 3.5 | E33: 0.26 | F33: Totaal agrarisch terrein (ha)
B34: Totale droge energieteelt | C34: DROOG | D34: 1.2 | E34: 0.04 | F34: Totaal agrarisch terrein (ha)
B35: Grassoorten op zoute grond | C35: NAT | D35: 12 | E35: 0 | F35: Grassoorten_op_zoute_grond_verdeelsleutel | G35: 50% zeeland, 10% noord Holland 40% Groningen
G36: Noord Beveland 10% Veere 20% Vlissingen 10% Middelburg 10% Texel 10% Het Hogeland 40%
B38: TOTAAL
B39: NATTE BIOMASSA | D39: =SUMIF(C2:C35,"NAT",D2:D35) -> 109.873 | E39: =SUMIF(C$2:C$35,"NAT",E$2:E$35) -> 16.78
B40: DROGE BIOMASSA | D40: =SUMIF($C2:C$37,"DROOG",D2:D37) -> 62.16023 | E40: =SUMIF($C2:D$37,"DROOG",E2:E37) -> 47.416855
B41: VETHOUDENDE BIOMASSA | D41: =SUMIF($C2:$C37,"VET",D2:D37) -> 10.5 | E41: =SUMIF($C2:$C37,"VET",E2:E37) -> 10.5
...

Sheet Verdeelsleutels_absoluut
B1: geo_id | D1: Bevolking (aantal) | E1: Cultuurgrond (are) | F1: Blijvend grasland (are) | G1: Melk- en kalfkoeien (>= 2 jaar) (aantal) | H1: Varkens | I1: Kippen | J1: Granen (are) | K1: Akkerbouwgroenten (are) | L1: Cultuurgrond - blijvend grasland (are) | M1: Totaal agrarisch terrein (ha) | N1: Park en plantsoen (ha) | O1: Bos (ha) | P1: Open droog natuurlijk terrein (ha) | Q1: Open nat natuurlijk terrein (ha) | R1: Recreatief binnenwater (ha) | S1: Overig binnenwater (ha) | T1: Open nat natuurlijk terrein + recreatief binnenwater + overig binnenwater (ha) | U1: Totaal gemeentelijke en waterschapswegen [km]
C2: Nederland | D2: =INDEX(CBS_bevolking_2018!B:C,MATCH(Verdeelsleutels_absoluut!C2,CBS_bevolking_2018!B:B,0),2) -> 17282163 | E2: =INDEX(CBS_landbouw_2018!$C:$I,MATCH(Verdeelsleutels_absoluut!$C2,CBS_landbouw_2018!$B:$B,0),MATCH(Verdeelsleutels_absoluut!E$1,CBS_landbouw_2018!$C$1:$I$1,0)) -> 176837075 | F2: =INDEX(CBS_landbouw_2018!$C:$I,MATCH(Verdeelsleutels_absoluut!$C2,CBS_landbouw_2018!$B:$B,0),MATCH(Verdeelsleutels_absoluut!F$1,CBS_landbouw_2018!$C$1:$I$1,0)) -> 68373958 | G2: =INDEX(CBS_landbouw_2018!$C:$I,MATCH(Verdeelsleutels_absoluut!$C2,CBS_landbouw_2018!$B:$B,0),MATCH(Verdeelsleutels_absoluut!G$1,CBS_landbouw_2018!$C$1:$I$1,0)) -> 1621914 | H2: =INDEX(CBS_landbouw_2018!$C:$I,MATCH(Verdeelsleutels_absoluut!$C2,CBS_landbouw_2018!$B:$B,0),MATCH(Verdeelsleutels_absoluut!H$1,CBS_landbouw_2018!$C$1:$I$1,0)) -> 12406749 | I2: =INDEX(CBS_landbouw_2018!$C:$I,MATCH(Verdeelsleutels_absoluut!$C2,CBS_landbouw_2018!$B:$B,0),MATCH(Verdeelsleutels_absoluut!I$1,CBS_landbouw_2018!$C$1:$I$1,0)) -> 96985787 | J2: =INDEX(CBS_landbouw_2018!$C:$I,MATCH(Verdeelsleutels_absoluut!$C2,CBS_landbouw_2018!$B:$B,0),MATCH(Verdeelsleutels_absoluut!J$1,CBS_landbouw_2018!$C$1:$I$1,0)) -> 16756666 | K2: =INDEX(CBS_landbouw_2018!$C:$I,MATCH(Verdeelsleutels_absoluut!$C2,CBS_landbouw_2018!$B:$B,0),MATCH(Verdeelsleutels_absoluut!K$1,CBS_landbouw_2018!$C$1:$I$1,0)) -> 6053282 | L2: =E2-F2 -> 108463117 | M2: =INDEX(CBS_bodemgebruik_2015!$C:$F,MATCH(Verdeelsleutels_absoluut!$C2,CBS_bodemgebruik_2015!$B:$B,0),MATCH(Verdeelsleutels_absoluut!M$1,CBS_bodemgebruik_2015!$C$1:$F$1,0)) -> 2236317 | N2: =INDEX(CBS_bodemgebruik_2015!$C:$F,MATCH(Verdeelsleutels_absoluut!$C2,CBS_bodemgebruik_2015!$B:$B,0),MATCH(Verdeelsleutels_absoluut!N$1,CBS_bodemgebruik_2015!$C$1:$F$1,0)) -> 30819 | O2: =INDEX(CBS_bodemgebruik_2015!$C:$F,MATCH(Verdeelsleutels_absoluut!$C2,CBS_bodemgebruik_2015!$B:$B,0),MATCH(Verdeelsleutels_absoluut!O$1,CBS_bodemgebruik_2015!$C$1:$F$1,0)) -> 341270 | P2: =INDEX(CBS_bodemgebruik_2015!$C:$F,MATCH(Verdeelsleutels_absoluut!$C2,CBS_bodemgebruik_2015!$B:$B,0),MATCH(Verdeelsleutels_absoluut!P$1,CBS_bodemgebruik_2015!$C$1:$F$1,0)) -> 95055 | Q2: =INDEX(CBS_bodemgebruik_2015!$C:$I,MATCH(Verdeelsleutels_absoluut!$C2,CBS_bodemgebruik_2015!$B:$B,0),MATCH(Verdeelsleutels_absoluut!Q$1,CBS_bodemgebruik_2015!$C$1:$I$1,0)) -> 62631 | R2: =INDEX(CBS_bodemgebruik_2015!$C:$I,MATCH(Verdeelsleutels_absoluut!$C2,CBS_bodemgebruik_2015!$B:$B,0),MATCH(Verdeelsleutels_absoluut!R$1,CBS_bodemgebruik_2015!$C$1:$I$1,0)) -> 10544 | S2: =INDEX(CBS_bodemgebruik_2015!$C:$I,MATCH(Verdeelsleutels_absoluut!$C2,CBS_bodemgebruik_2015!$B:$B,0),MATCH(Verdeelsleutels_absoluut!S$1,CBS_bodemgebruik_2015!$C$1:$I$1,0)) -> 107129 | T2: =SUM(Q2:S2) -> 180304 | U2: =INDEX(CBS_wegen_2019!B:C,MATCH(C2,CBS_wegen_2019!B:B,0),2) -> 126523
A4: Provincies | B4: PV20 | C4: Groningen (PV) | D4: =INDEX(CBS_bevolking_2018!B:C,MATCH(Verdeelsleutels_absoluut!C4,CBS_bevolking_2018!B:B,0),2) -> 583990 | E4: =INDEX(CBS_landbouw_2018!$C:$I,MATCH(Verdeelsleutels_absoluut!$C4,CBS_landbouw_2018!$B:$B,0),MATCH(Verdeelsleutels_absoluut!E$1,CBS_landbouw_2018!$C$1:$I$1,0)) -> 15828796 | F4: =INDEX(CBS_landbouw_2018!$C:$I,MATCH(Verdeelsleutels_absoluut!$C4,CBS_landbouw_2018!$B:$B,0),MATCH(Verdeelsleutels_absoluut!F$1,CBS_landbouw_2018!$C$1:$I$1,0)) -> 4821022 | G4: =INDEX(CBS_landbouw_2018!$C:$I,MATCH(Verdeelsleutels_absoluut!$C4,CBS_landbouw_2018!$B:$B,0),MATCH(Verdeelsleutels_absoluut!G$1,CBS_landbouw_2018!$C$1:$I$1,0)) -> 105790 | H4: =INDEX(CBS_landbouw_2018!$C:$I,MATCH(Verdeelsleutels_absoluut!$C4,CBS_landbouw_2018!$B:$B,0),MATCH(Verdeelsleutels_absoluut!H$1,CBS_landbouw_2018!$C$1:$I$1,0)) -> 178548 | I4: =INDEX(CBS_landbouw_2018!$C:$I,MATCH(Verdeelsleutels_absoluut!$C4,CBS_landbouw_2018!$B:$B,0),MATCH(Verdeelsleutels_absoluut!I$1,CBS_landbouw_2018!$C$1:$I$1,0)) -> 4685331 | J4: =INDEX(CBS_landbouw_2018!$C:$I,MATCH(Verdeelsleutels_absoluut!$C4,CBS_landbouw_2018!$B:$B,0),MATCH(Verdeelsleutels_absoluut!J$1,CBS_landbouw_2018!$C$1:$I$1,0)) -> 3635021 | K4: =INDEX(CBS_landbouw_2018!$C:$I,MATCH(Verdeelsleutels_absoluut!$C4,CBS_landbouw_2018!$B:$B,0),MATCH(Verdeelsleutels_absoluut!K$1,CBS_landbouw_2018!$C$1:$I$1,0)) -> 256628 | L4: =E4-F4 -> 11007774 | M4: =INDEX(CBS_bodemgebruik_2015!$C:$F,MATCH(Verdeelsleutels_absoluut!$C4,CBS_bodemgebruik_2015!$B:$B,0),MATCH(Verdeelsleutels_absoluut!M$1,CBS_bodemgebruik_2015!$C$1:$F$1,0)) -> 187007 | N4: =INDEX(CBS_bodemgebruik_2015!$C:$F,MATCH(Verdeelsleutels_absoluut!$C4,CBS_bodemgebruik_2015!$B:$B,0),MATCH(Verdeelsleutels_absoluut!N$1,CBS_bodemgebruik_2015!$C$1:$F$1,0)) -> 1410 | O4: =INDEX(CBS_bodemgebruik_2015!$C:$F,MATCH(Verdeelsleutels_absoluut!$C4,CBS_bodemgebruik_2015!$B:$B,0),MATCH(Verdeelsleutels_absoluut!O$1,CBS_bodemgebruik_2015!$C$1:$F$1,0)) -> 6383 | P4: =INDEX(CBS_bodemgebruik_2015!$C:$I,MATCH(Verdeelsleutels_absoluut!$C4,CBS_bodemgebruik_2015!$B:$B,0),MATCH(Verdeelsleutels_absoluut!P$1,CBS_bodemgebruik_2015!$C$1:$I$1,0)) -> 3210 | Q4: =INDEX(CBS_bodemgebruik_2015!$C:$I,MATCH(Verdeelsleutels_absoluut!$C4,CBS_bodemgebruik_2015!$B:$B,0),MATCH(Verdeelsleutels_absoluut!Q$1,CBS_bodemgebruik_2015!$C$1:$I$1,0)) -> 5316 | R4: =INDEX(CBS_bodemgebruik_2015!$C:$I,MATCH(Verdeelsleutels_absoluut!$C4,CBS_bodemgebruik_2015!$B:$B,0),MATCH(Verdeelsleutels_absoluut!R$1,CBS_bodemgebruik_2015!$C$1:$I$1,0)) -> 393 | S4: =INDEX(CBS_bodemgebruik_2015!$C:$I,MATCH(Verdeelsleutels_absoluut!$C4,CBS_bodemgebruik_2015!$B:$B,0),MATCH(Verdeelsleutels_absoluut!S$1,CBS_bodemgebruik_2015!$C$1:$I$1,0)) -> 6117 | T4: =SUM(Q4:S4) -> 11826 | U4: =INDEX(CBS_wegen_2019!B:C,MATCH(C4,CBS_wegen_2019!B:B,0),2) -> 5922
B5: PV21 | C5: Friesland (PV) | D5: =INDEX(CBS_bevolking_2018!B:C,MATCH(Verdeelsleutels_absoluut!C5,CBS_bevolking_2018!B:B,0),2) -> 647672 | E5: =INDEX(CBS_landbouw_2018!$C:$I,MATCH(Verdeelsleutels_absoluut!$C5,CBS_landbouw_2018!$B:$B,0),MATCH(Verdeelsleutels_absoluut!E$1,CBS_landbouw_2018!$C$1:$I$1,0)) -> 21718364 | F5: =INDEX(CBS_landbouw_2018!$C:$I,MATCH(Verdeelsleutels_absoluut!$C5,CBS_landbouw_2018!$B:$B,0),MATCH(Verdeelsleutels_absoluut!F$1,CBS_landbouw_2018!$C$1:$I$1,0)) -> 15396762 | G5: =INDEX(CBS_landbouw_2018!$C:$I,MATCH(Verdeelsleutels_absoluut!$C5,CBS_landbouw_2018!$B:$B,0),MATCH(Verdeelsleutels_absoluut!G$1,CBS_landbouw_2018!$C$1:$I$1,0)) -> 301603 | H5: =INDEX(CBS_landbouw_2018!$C:$I,MATCH(Verdeelsleutels_absoluut!$C5,CBS_landbouw_2018!$B:$B,0),MATCH(Verdeelsleutels_absoluut!H$1,CBS_landbouw_2018!$C$1:$I$1,0)) -> 112109 | I5: =INDEX(CBS_landbouw_2018!$C:$I,MATCH(Verdeelsleutels_absoluut!$C5,CBS_landbouw_2018!$B:$B,0),MATCH(Verdeelsleutels_absoluut!I$1,CBS_landbouw_2018!$C$1:$I$1,0)) -> 6886629 | J5: =INDEX(CBS_landbouw_2018!$C:$I,MATCH(Verdeelsleutels_absoluut!$C5,CBS_landbouw_2018!$B:$B,0),MATCH(Verdeelsleutels_absoluut!J$1,CBS_landbouw_2018!$C$1:$I$1,0)) -> 696744 | K5: =INDEX(CBS_landbouw_2018!$C:$I,MATCH(Verdeelsleutels_absoluut!$C5,CBS_landbouw_2018!$B:$B,0),MATCH(Verdeelsleutels_absoluut!K$1,CBS_landbouw_2018!$C$1:$I$1,0)) -> 133836 | L5: =E5-F5 -> 6321602 | M5: =INDEX(CBS_bodemgebruik_2015!$C:$F,MATCH(Verdeelsleutels_absoluut!$C5,CBS_bodemgebruik_2015!$B:$B,0),MATCH(Verdeelsleutels_absoluut!M$1,CBS_bodemgebruik_2015!$C$1:$F$1,0)) -> 257646 | N5: =INDEX(CBS_bodemgebruik_2015!$C:$F,MATCH(Verdeelsleutels_absoluut!$C5,CBS_bodemgebruik_2015!$B:$B,0),MATCH(Verdeelsleutels_absoluut!N$1,CBS_bodemgebruik_2015!$C$1:$F$1,0)) -> 1091 | O5: =INDEX(CBS_bodemgebruik_2015!$C:$F,MATCH(Verdeelsleutels_absoluut!$C5,CBS_bodemgebruik_2015!$B:$B,0),MATCH(Verdeelsleutels_absoluut!O$1,CBS_bodemgebruik_2015!$C$1:$F$1,0)) -> 11309 | P5: =INDEX(CBS_bodemgebruik_2015!$C:$I,MATCH(Verdeelsleutels_absoluut!$C5,CBS_bodemgebruik_2015!$B:$B,0),MATCH(Verdeelsleutels_absoluut!P$1,CBS_bodemgebruik_2015!$C$1:$I$1,0)) -> 15047 | Q5: =INDEX(CBS_bodemgebruik_2015!$C:$I,MATCH(Verdeelsleutels_absoluut!$C5,CBS_bodemgebruik_2015!$B:$B,0),MATCH(Verdeelsleutels_absoluut!Q$1,CBS_bodemgebruik_2015!$C$1:$I$1,0)) -> 14821 | R5: =INDEX(CBS_bodemgebruik_2015!$C:$I,MATCH(Verdeelsleutels_absoluut!$C5,CBS_bodemgebruik_2015!$B:$B,0),MATCH(Verdeelsleutels_absoluut!R$1,CBS_bodemgebruik_2015!$C$1:$I$1,0)) -> 562 | S5: =INDEX(CBS_bodemgebruik_2015!$C:$I,MATCH(Verdeelsleutels_absoluut!$C5,CBS_bodemgebruik_2015!$B:$B,0),MATCH(Verdeelsleutels_absoluut!S$1,CBS_bodemgebruik_2015!$C$1:$I$1,0)) -> 18972 | T5: =SUM(Q5:S5) -> 34355 | U5: =INDEX(CBS_wegen_2019!B:C,MATCH(C5,CBS_wegen_2019!B:B,0),2) -> 7993
B6: PV22 | C6: Drenthe (PV) | D6: =INDEX(CBS_bevolking_2018!B:C,MATCH(Verdeelsleutels_absoluut!C6,CBS_bevolking_2018!B:B,0),2) -> 492167 | E6: =INDEX(CBS_landbouw_2018!$C:$I,MATCH(Verdeelsleutels_absoluut!$C6,CBS_landbouw_2018!$B:$B,0),MATCH(Verdeelsleutels_absoluut!E$1,CBS_landbouw_2018!$C$1:$I$1,0)) -> 14455377 | F6: =INDEX(CBS_landbouw_2018!$C:$I,MATCH(Verdeelsleutels_absoluut!$C6,CBS_landbouw_2018!$B:$B,0),MATCH(Verdeelsleutels_absoluut!F$1,CBS_landbouw_2018!$C$1:$I$1,0)) -> 4012736 | G6: =INDEX(CBS_landbouw_2018!$C:$I,MATCH(Verdeelsleutels_absoluut!$C6,CBS_landbouw_2018!$B:$B,0),MATCH(Verdeelsleutels_absoluut!G$1,CBS_landbouw_2018!$C$1:$I$1,0)) -> 107155 | H6: =INDEX(CBS_landbouw_2018!$C:$I,MATCH(Verdeelsleutels_absoluut!$C6,CBS_landbouw_2018!$B:$B,0),MATCH(Verdeelsleutels_absoluut!H$1,CBS_landbouw_2018!$C$1:$I$1,0)) -> 226213 | I6: =INDEX(CBS_landbouw_2018!$C:$I,MATCH(Verdeelsleutels_absoluut!$C6,CBS_landbouw_2018!$B:$B,0),MATCH(Verdeelsleutels_absoluut!I$1,CBS_landbouw_2018!$C$1:$I$1,0)) -> 7020529 | J6: =INDEX(CBS_landbouw_2018!$C:$I,MATCH(Verdeelsleutels_absoluut!$C6,CBS_landbouw_2018!$B:$B,0),MATCH(Verdeelsleutels_absoluut!J$1,CBS_landbouw_2018!$C$1:$I$1,0)) -> 1383572 | K6: =INDEX(CBS_landbouw_2018!$C:$I,MATCH(Verdeelsleutels_absoluut!$C6,CBS_landbouw_2018!$B:$B,0),MATCH(Verdeelsleutels_absoluut!K$1,CBS_landbouw_2018!$C$1:$I$1,0)) -> 141259 | L6: =E6-F6 -> 10442641 | M6: =INDEX(CBS_bodemgebruik_2015!$C:$F,MATCH(Verdeelsleutels_absoluut!$C6,CBS_bodemgebruik_2015!$B:$B,0),MATCH(Verdeelsleutels_absoluut!M$1,CBS_bodemgebruik_2015!$C$1:$F$1,0)) -> 186226 | N6: =INDEX(CBS_bodemgebruik_2015!$C:$F,MATCH(Verdeelsleutels_absoluut!$C6,CBS_bodemgebruik_2015!$B:$B,0),MATCH(Verdeelsleutels_absoluut!N$1,CBS_bodemgebruik_2015!$C$1:$F$1,0)) -> 1003 | O6: =INDEX(CBS_bodemgebruik_2015!$C:$F,MATCH(Verdeelsleutels_absoluut!$C6,CBS_bodemgebruik_2015!$B:$B,0),MATCH(Verdeelsleutels_absoluut!O$1,CBS_bodemgebruik_2015!$C$1:$F$1,0)) -> 32599 | P6: =INDEX(CBS_bodemgebruik_2015!$C:$I,MATCH(Verdeelsleutels_absoluut!$C6,CBS_bodemgebruik_2015!$B:$B,0),MATCH(Verdeelsleutels_absoluut!P$1,CBS_bodemgebruik_2015!$C$1:$I$1,0)) -> 9603 | Q6: =INDEX(CBS_bodemgebruik_2015!$C:$I,MATCH(Verdeelsleutels_absoluut!$C6,CBS_bodemgebruik_2015!$B:$B,0),MATCH(Verdeelsleutels_absoluut!Q$1,CBS_bodemgebruik_2015!$C$1:$I$1,0)) -> 4773 | R6: =INDEX(CBS_bodemgebruik_2015!$C:$I,MATCH(Verdeelsleutels_absoluut!$C6,CBS_bodemgebruik_2015!$B:$B,0),MATCH(Verdeelsleutels_absoluut!R$1,CBS_bodemgebruik_2015!$C$1:$I$1,0)) -> 381 | S6: =INDEX(CBS_bodemgebruik_2015!$C:$I,MATCH(Verdeelsleutels_absoluut!$C6,CBS_bodemgebruik_2015!$B:$B,0),MATCH(Verdeelsleutels_absoluut!S$1,CBS_bodemgebruik_2015!$C$1:$I$1,0)) -> 3876 | T6: =SUM(Q6:S6) -> 9030 | U6: =INDEX(CBS_wegen_2019!B:C,MATCH(C6,CBS_wegen_2019!B:B,0),2) -> 6818
B7: PV23 | C7: Overijssel (PV) | D7: =INDEX(CBS_bevolking_2018!B:C,MATCH(Verdeelsleutels_absoluut!C7,CBS_bevolking_2018!B:B,0),2) -> 1156431 | E7: =INDEX(CBS_landbouw_2018!$C:$I,MATCH(Verdeelsleutels_absoluut!$C7,CBS_landbouw_2018!$B:$B,0),MATCH(Verdeelsleutels_absoluut!E$1,CBS_landbouw_2018!$C$1:$I$1,0)) -> 19249557 | F7: =INDEX(CBS_landbouw_2018!$C:$I,MATCH(Verdeelsleutels_absoluut!$C7,CBS_landbouw_2018!$B:$B,0),MATCH(Verdeelsleutels_absoluut!F$1,CBS_landbouw_2018!$C$1:$I$1,0)) -> 10542144 | G7: =INDEX(CBS_landbouw_2018!$C:$I,MATCH(Verdeelsleutels_absoluut!$C7,CBS_landbouw_2018!$B:$B,0),MATCH(Verdeelsleutels_absoluut!G$1,CBS_landbouw_2018!$C$1:$I$1,0)) -> 259468 | H7: =INDEX(CBS_landbouw_2018!$C:$I,MATCH(Verdeelsleutels_absoluut!$C7,CBS_landbouw_2018!$B:$B,0),MATCH(Verdeelsleutels_absoluut!H$1,CBS_landbouw_2018!$C$1:$I$1,0)) -> 1562448 | I7: =INDEX(CBS_landbouw_2018!$C:$I,MATCH(Verdeelsleutels_absoluut!$C7,CBS_landbouw_2018!$B:$B,0),MATCH(Verdeelsleutels_absoluut!I$1,CBS_landbouw_2018!$C$1:$I$1,0)) -> 11230759 | J7: =INDEX(CBS_landbouw_2018!$C:$I,MATCH(Verdeelsleutels_absoluut!$C7,CBS_landbouw_2018!$B:$B,0),MATCH(Verdeelsleutels_absoluut!J$1,CBS_landbouw_2018!$C$1:$I$1,0)) -> 455770 | K7: =INDEX(CBS_landbouw_2018!$C:$I,MATCH(Verdeelsleutels_absoluut!$C7,CBS_landbouw_2018!$B:$B,0),MATCH(Verdeelsleutels_absoluut!K$1,CBS_landbouw_2018!$C$1:$I$1,0)) -> 54391 | L7: =E7-F7 -> 8707413 | M7: =INDEX(CBS_bodemgebruik_2015!$C:$F,MATCH(Verdeelsleutels_absoluut!$C7,CBS_bodemgebruik_2015!$B:$B,0),MATCH(Verdeelsleutels_absoluut!M$1,CBS_bodemgebruik_2015!$C$1:$F$1,0)) -> 237910 | N7: =INDEX(CBS_bodemgebruik_2015!$C:$F,MATCH(Verdeelsleutels_absoluut!$C7,CBS_bodemgebruik_2015!$B:$B,0),MATCH(Verdeelsleutels_absoluut!N$1,CBS_bodemgebruik_2015!$C$1:$F$1,0)) -> 1933 | O7: =INDEX(CBS_bodemgebruik_2015!$C:$F,MATCH(Verdeelsleutels_absoluut!$C7,CBS_bodemgebruik_2015!$B:$B,0),MATCH(Verdeelsleutels_absoluut!O$1,CBS_bodemgebruik_2015!$C$1:$F$1,0)) -> 34474 | P7: =INDEX(CBS_bodemgebruik_2015!$C:$I,MATCH(Verdeelsleutels_absoluut!$C7,CBS_bodemgebruik_2015!$B:$B,0),MATCH(Verdeelsleutels_absoluut!P$1,CBS_bodemgebruik_2015!$C$1:$I$1,0)) -> 4396 | Q7: =INDEX(CBS_bodemgebruik_2015!$C:$I,MATCH(Verdeelsleutels_absoluut!$C7,CBS_bodemgebruik_2015!$B:$B,0),MATCH(Verdeelsleutels_absoluut!Q$1,CBS_bodemgebruik_2015!$C$1:$I$1,0)) -> 7664 | R7: =INDEX(CBS_bodemgebruik_2015!$C:$I,MATCH(Verdeelsleutels_absoluut!$C7,CBS_bodemgebruik_2015!$B:$B,0),MATCH(Verdeelsleutels_absoluut!R$1,CBS_bodemgebruik_2015!$C$1:$I$1,0)) -> 359 | S7: =INDEX(CBS_bodemgebruik_2015!$C:$I,MATCH(Verdeelsleutels_absoluut!$C7,CBS_bodemgebruik_2015!$B:$B,0),MATCH(Verdeelsleutels_absoluut!S$1,CBS_bodemgebruik_2015!$C$1:$I$1,0)) -> 7261 | T7: =SUM(Q7:S7) -> 15284 | U7: =INDEX(CBS_wegen_2019!B:C,MATCH(C7,CBS_wegen_2019!B:B,0),2) -> 12388
B8: PV24 | C8: Flevoland (PV) | D8: =INDEX(CBS_bevolking_2018!B:C,MATCH(Verdeelsleutels_absoluut!C8,CBS_bevolking_2018!B:B,0),2) -> 416546 | E8: =INDEX(CBS_landbouw_2018!$C:$I,MATCH(Verdeelsleutels_absoluut!$C8,CBS_landbouw_2018!$B:$B,0),MATCH(Verdeelsleutels_absoluut!E$1,CBS_landbouw_2018!$C$1:$I$1,0)) -> 8924087 | F8: =INDEX(CBS_landbouw_2018!$C:$I,MATCH(Verdeelsleutels_absoluut!$C8,CBS_landbouw_2018!$B:$B,0),MATCH(Verdeelsleutels_absoluut!F$1,CBS_landbouw_2018!$C$1:$I$1,0)) -> 402062 | G8: =INDEX(CBS_landbouw_2018!$C:$I,MATCH(Verdeelsleutels_absoluut!$C8,CBS_landbouw_2018!$B:$B,0),MATCH(Verdeelsleutels_absoluut!G$1,CBS_landbouw_2018!$C$1:$I$1,0)) -> 34867 | H8: =INDEX(CBS_landbouw_2018!$C:$I,MATCH(Verdeelsleutels_absoluut!$C8,CBS_landbouw_2018!$B:$B,0),MATCH(Verdeelsleutels_absoluut!H$1,CBS_landbouw_2018!$C$1:$I$1,0)) -> 49515 | I8: =INDEX(CBS_landbouw_2018!$C:$I,MATCH(Verdeelsleutels_absoluut!$C8,CBS_landbouw_2018!$B:$B,0),MATCH(Verdeelsleutels_absoluut!I$1,CBS_landbouw_2018!$C$1:$I$1,0)) -> 2746970 | J8: =INDEX(CBS_landbouw_2018!$C:$I,MATCH(Verdeelsleutels_absoluut!$C8,CBS_landbouw_2018!$B:$B,0),MATCH(Verdeelsleutels_absoluut!J$1,CBS_landbouw_2018!$C$1:$I$1,0)) -> 1415843 | K8: =INDEX(CBS_landbouw_2018!$C:$I,MATCH(Verdeelsleutels_absoluut!$C8,CBS_landbouw_2018!$B:$B,0),MATCH(Verdeelsleutels_absoluut!K$1,CBS_landbouw_2018!$C$1:$I$1,0)) -> 1798702 | L8: =E8-F8 -> 8522025 | M8: =INDEX(CBS_bodemgebruik_2015!$C:$F,MATCH(Verdeelsleutels_absoluut!$C8,CBS_bodemgebruik_2015!$B:$B,0),MATCH(Verdeelsleutels_absoluut!M$1,CBS_bodemgebruik_2015!$C$1:$F$1,0)) -> 98530 | N8: =INDEX(CBS_bodemgebruik_2015!$C:$F,MATCH(Verdeelsleutels_absoluut!$C8,CBS_bodemgebruik_2015!$B:$B,0),MATCH(Verdeelsleutels_absoluut!N$1,CBS_bodemgebruik_2015!$C$1:$F$1,0)) -> 1664 | O8: =INDEX(CBS_bodemgebruik_2015!$C:$F,MATCH(Verdeelsleutels_absoluut!$C8,CBS_bodemgebruik_2015!$B:$B,0),MATCH(Verdeelsleutels_absoluut!O$1,CBS_bodemgebruik_2015!$C$1:$F$1,0)) -> 17033 | P8: =INDEX(CBS_bodemgebruik_2015!$C:$I,MATCH(Verdeelsleutels_absoluut!$C8,CBS_bodemgebruik_2015!$B:$B,0),MATCH(Verdeelsleutels_absoluut!P$1,CBS_bodemgebruik_2015!$C$1:$I$1,0)) -> 2289 | Q8: =INDEX(CBS_bodemgebruik_2015!$C:$I,MATCH(Verdeelsleutels_absoluut!$C8,CBS_bodemgebruik_2015!$B:$B,0),MATCH(Verdeelsleutels_absoluut!Q$1,CBS_bodemgebruik_2015!$C$1:$I$1,0)) -> 3734 | R8: =INDEX(CBS_bodemgebruik_2015!$C:$I,MATCH(Verdeelsleutels_absoluut!$C8,CBS_bodemgebruik_2015!$B:$B,0),MATCH(Verdeelsleutels_absoluut!R$1,CBS_bodemgebruik_2015!$C$1:$I$1,0)) -> 472 | S8: =INDEX(CBS_bodemgebruik_2015!$C:$I,MATCH(Verdeelsleutels_absoluut!$C8,CBS_bodemgebruik_2015!$B:$B,0),MATCH(Verdeelsleutels_absoluut!S$1,CBS_bodemgebruik_2015!$C$1:$I$1,0)) -> 5020 | T8: =SUM(Q8:S8) -> 9226 | U8: =INDEX(CBS_wegen_2019!B:C,MATCH(C8,CBS_wegen_2019!B:B,0),2) -> 3116
B9: PV25 | C9: Gelderland (PV) | D9: =INDEX(CBS_bevolking_2018!B:C,MATCH(Verdeelsleutels_absoluut!C9,CBS_bevolking_2018!B:B,0),2) -> 2071972 | E9: =INDEX(CBS_landbouw_2018!$C:$I,MATCH(Verdeelsleutels_absoluut!$C9,CBS_landbouw_2018!$B:$B,0),MATCH(Verdeelsleutels_absoluut!E$1,CBS_landbouw_2018!$C$1:$I$1,0)) -> 22086318 | F9: =INDEX(CBS_landbouw_2018!$C:$I,MATCH(Verdeelsleutels_absoluut!$C9,CBS_landbouw_2018!$B:$B,0),MATCH(Verdeelsleutels_absoluut!F$1,CBS_landbouw_2018!$C$1:$I$1,0)) -> 11722450 | G9: =INDEX(CBS_landbouw_2018!$C:$I,MATCH(Verdeelsleutels_absoluut!$C9,CBS_landbouw_2018!$B:$B,0),MATCH(Verdeelsleutels_absoluut!G$1,CBS_landbouw_2018!$C$1:$I$1,0)) -> 241389 | H9: =INDEX(CBS_landbouw_2018!$C:$I,MATCH(Verdeelsleutels_absoluut!$C9,CBS_landbouw_2018!$B:$B,0),MATCH(Verdeelsleutels_absoluut!H$1,CBS_landbouw_2018!$C$1:$I$1,0)) -> 1902961 | I9: =INDEX(CBS_landbouw_2018!$C:$I,MATCH(Verdeelsleutels_absoluut!$C9,CBS_landbouw_2018!$B:$B,0),MATCH(Verdeelsleutels_absoluut!I$1,CBS_landbouw_2018!$C$1:$I$1,0)) -> 17580389 | J9: =INDEX(CBS_landbouw_2018!$C:$I,MATCH(Verdeelsleutels_absoluut!$C9,CBS_landbouw_2018!$B:$B,0),MATCH(Verdeelsleutels_absoluut!J$1,CBS_landbouw_2018!$C$1:$I$1,0)) -> 1011002 | K9: =INDEX(CBS_landbouw_2018!$C:$I,MATCH(Verdeelsleutels_absoluut!$C9,CBS_landbouw_2018!$B:$B,0),MATCH(Verdeelsleutels_absoluut!K$1,CBS_landbouw_2018!$C$1:$I$1,0)) -> 116160 | L9: =E9-F9 -> 10363868 | M9: =INDEX(CBS_bodemgebruik_2015!$C:$F,MATCH(Verdeelsleutels_absoluut!$C9,CBS_bodemgebruik_2015!$B:$B,0),MATCH(Verdeelsleutels_absoluut!M$1,CBS_bodemgebruik_2015!$C$1:$F$1,0)) -> 298443 | N9: =INDEX(CBS_bodemgebruik_2015!$C:$F,MATCH(Verdeelsleutels_absoluut!$C9,CBS_bodemgebruik_2015!$B:$B,0),MATCH(Verdeelsleutels_absoluut!N$1,CBS_bodemgebruik_2015!$C$1:$F$1,0)) -> 3088 | O9: =INDEX(CBS_bodemgebruik_2015!$C:$F,MATCH(Verdeelsleutels_absoluut!$C9,CBS_bodemgebruik_2015!$B:$B,0),MATCH(Verdeelsleutels_absoluut!O$1,CBS_bodemgebruik_2015!$C$1:$F$1,0)) -> 93292 | P9: =INDEX(CBS_bodemgebruik_2015!$C:$I,MATCH(Verdeelsleutels_absoluut!$C9,CBS_bodemgebruik_2015!$B:$B,0),MATCH(Verdeelsleutels_absoluut!P$1,CBS_bodemgebruik_2015!$C$1:$I$1,0)) -> 20347 | Q9: =INDEX(CBS_bodemgebruik_2015!$C:$I,MATCH(Verdeelsleutels_absoluut!$C9,CBS_bodemgebruik_2015!$B:$B,0),MATCH(Verdeelsleutels_absoluut!Q$1,CBS_bodemgebruik_2015!$C$1:$I$1,0)) -> 1788 | R9: =INDEX(CBS_bodemgebruik_2015!$C:$I,MATCH(Verdeelsleutels_absoluut!$C9,CBS_bodemgebruik_2015!$B:$B,0),MATCH(Verdeelsleutels_absoluut!R$1,CBS_bodemgebruik_2015!$C$1:$I$1,0)) -> 1901 | S9: =INDEX(CBS_bodemgebruik_2015!$C:$I,MATCH(Verdeelsleutels_absoluut!$C9,CBS_bodemgebruik_2015!$B:$B,0),MATCH(Verdeelsleutels_absoluut!S$1,CBS_bodemgebruik_2015!$C$1:$I$1,0)) -> 7013 | T9: =SUM(Q9:S9) -> 10702 | U9: =INDEX(CBS_wegen_2019!B:C,MATCH(C9,CBS_wegen_2019!B:B,0),2) -> 18593
B10: PV26 | C10: Utrecht (PV) | D10: =INDEX(CBS_bevolking_2018!B:C,MATCH(Verdeelsleutels_absoluut!C10,CBS_bevolking_2018!B:B,0),2) -> 1306890 | E10: =INDEX(CBS_landbouw_2018!$C:$I,MATCH(Verdeelsleutels_absoluut!$C10,CBS_landbouw_2018!$B:$B,0),MATCH(Verdeelsleutels_absoluut!E$1,CBS_landbouw_2018!$C$1:$I$1,0)) -> 6069537 | F10: =INDEX(CBS_landbouw_2018!$C:$I,MATCH(Verdeelsleutels_absoluut!$C10,CBS_landbouw_2018!$B:$B,0),MATCH(Verdeelsleutels_absoluut!F$1,CBS_landbouw_2018!$C$1:$I$1,0)) -> 4586471 | G10: =INDEX(CBS_landbouw_2018!$C:$I,MATCH(Verdeelsleutels_absoluut!$C10,CBS_landbouw_2018!$B:$B,0),MATCH(Verdeelsleutels_absoluut!G$1,CBS_landbouw_2018!$C$1:$I$1,0)) -> 85519 | H10: =INDEX(CBS_landbouw_2018!$C:$I,MATCH(Verdeelsleutels_absoluut!$C10,CBS_landbouw_2018!$B:$B,0),MATCH(Verdeelsleutels_absoluut!H$1,CBS_landbouw_2018!$C$1:$I$1,0)) -> 268430 | I10: =INDEX(CBS_landbouw_2018!$C:$I,MATCH(Verdeelsleutels_absoluut!$C10,CBS_landbouw_2018!$B:$B,0),MATCH(Verdeelsleutels_absoluut!I$1,CBS_landbouw_2018!$C$1:$I$1,0)) -> 2637940 | J10: =INDEX(CBS_landbouw_2018!$C:$I,MATCH(Verdeelsleutels_absoluut!$C10,CBS_landbouw_2018!$B:$B,0),MATCH(Verdeelsleutels_absoluut!J$1,CBS_landbouw_2018!$C$1:$I$1,0)) -> 58281 | K10: =INDEX(CBS_landbouw_2018!$C:$I,MATCH(Verdeelsleutels_absoluut!$C10,CBS_landbouw_2018!$B:$B,0),MATCH(Verdeelsleutels_absoluut!K$1,CBS_landbouw_2018!$C$1:$I$1,0)) -> 2667 | L10: =E10-F10 -> 1483066 | M10: =INDEX(CBS_bodemgebruik_2015!$C:$F,MATCH(Verdeelsleutels_absoluut!$C10,CBS_bodemgebruik_2015!$B:$B,0),MATCH(Verdeelsleutels_absoluut!M$1,CBS_bodemgebruik_2015!$C$1:$F$1,0)) -> 80572 | N10: =INDEX(CBS_bodemgebruik_2015!$C:$F,MATCH(Verdeelsleutels_absoluut!$C10,CBS_bodemgebruik_2015!$B:$B,0),MATCH(Verdeelsleutels_absoluut!N$1,CBS_bodemgebruik_2015!$C$1:$F$1,0)) -> 2006 | O10: =INDEX(CBS_bodemgebruik_2015!$C:$F,MATCH(Verdeelsleutels_absoluut!$C10,CBS_bodemgebruik_2015!$B:$B,0),MATCH(Verdeelsleutels_absoluut!O$1,CBS_bodemgebruik_2015!$C$1:$F$1,0)) -> 18261 | P10: =INDEX(CBS_bodemgebruik_2015!$C:$I,MATCH(Verdeelsleutels_absoluut!$C10,CBS_bodemgebruik_2015!$B:$B,0),MATCH(Verdeelsleutels_absoluut!P$1,CBS_bodemgebruik_2015!$C$1:$I$1,0)) -> 1813 | Q10: =INDEX(CBS_bodemgebruik_2015!$C:$I,MATCH(Verdeelsleutels_absoluut!$C10,CBS_bodemgebruik_2015!$B:$B,0),MATCH(Verdeelsleutels_absoluut!Q$1,CBS_bodemgebruik_2015!$C$1:$I$1,0)) -> 896 | R10: =INDEX(CBS_bodemgebruik_2015!$C:$I,MATCH(Verdeelsleutels_absoluut!$C10,CBS_bodemgebruik_2015!$B:$B,0),MATCH(Verdeelsleutels_absoluut!R$1,CBS_bodemgebruik_2015!$C$1:$I$1,0)) -> 537 | S10: =INDEX(CBS_bodemgebruik_2015!$C:$I,MATCH(Verdeelsleutels_absoluut!$C10,CBS_bodemgebruik_2015!$B:$B,0),MATCH(Verdeelsleutels_absoluut!S$1,CBS_bodemgebruik_2015!$C$1:$I$1,0)) -> 5046 | T10: =SUM(Q10:S10) -> 6479 | U10: =INDEX(CBS_wegen_2019!B:C,MATCH(C10,CBS_wegen_2019!B:B,0),2) -> 6265
B11: PV27 | C11: Noord-Holland (PV) | D11: =INDEX(CBS_bevolking_2018!B:C,MATCH(Verdeelsleutels_absoluut!C11,CBS_bevolking_2018!B:B,0),2) -> 2853359 | E11: =INDEX(CBS_landbouw_2018!$C:$I,MATCH(Verdeelsleutels_absoluut!$C11,CBS_landbouw_2018!$B:$B,0),MATCH(Verdeelsleutels_absoluut!E$1,CBS_landbouw_2018!$C$1:$I$1,0)) -> 12202209 | F11: =INDEX(CBS_landbouw_2018!$C:$I,MATCH(Verdeelsleutels_absoluut!$C11,CBS_landbouw_2018!$B:$B,0),MATCH(Verdeelsleutels_absoluut!F$1,CBS_landbouw_2018!$C$1:$I$1,0)) -> 4378018 | G11: =INDEX(CBS_landbouw_2018!$C:$I,MATCH(Verdeelsleutels_absoluut!$C11,CBS_landbouw_2018!$B:$B,0),MATCH(Verdeelsleutels_absoluut!G$1,CBS_landbouw_2018!$C$1:$I$1,0)) -> 88481 | H11: =INDEX(CBS_landbouw_2018!$C:$I,MATCH(Verdeelsleutels_absoluut!$C11,CBS_landbouw_2018!$B:$B,0),MATCH(Verdeelsleutels_absoluut!H$1,CBS_landbouw_2018!$C$1:$I$1,0)) -> 22083 | I11: =INDEX(CBS_landbouw_2018!$C:$I,MATCH(Verdeelsleutels_absoluut!$C11,CBS_landbouw_2018!$B:$B,0),MATCH(Verdeelsleutels_absoluut!I$1,CBS_landbouw_2018!$C$1:$I$1,0)) -> 1490968 | J11: =INDEX(CBS_landbouw_2018!$C:$I,MATCH(Verdeelsleutels_absoluut!$C11,CBS_landbouw_2018!$B:$B,0),MATCH(Verdeelsleutels_absoluut!J$1,CBS_landbouw_2018!$C$1:$I$1,0)) -> 907228 | K11: =INDEX(CBS_landbouw_2018!$C:$I,MATCH(Verdeelsleutels_absoluut!$C11,CBS_landbouw_2018!$B:$B,0),MATCH(Verdeelsleutels_absoluut!K$1,CBS_landbouw_2018!$C$1:$I$1,0)) -> 324693 | L11: =E11-F11 -> 7824191 | M11: =INDEX(CBS_bodemgebruik_2015!$C:$F,MATCH(Verdeelsleutels_absoluut!$C11,CBS_bodemgebruik_2015!$B:$B,0),MATCH(Verdeelsleutels_absoluut!M$1,CBS_bodemgebruik_2015!$C$1:$F$1,0)) -> 156968 | N11: =INDEX(CBS_bodemgebruik_2015!$C:$F,MATCH(Verdeelsleutels_absoluut!$C11,CBS_bodemgebruik_2015!$B:$B,0),MATCH(Verdeelsleutels_absoluut!N$1,CBS_bodemgebruik_2015!$C$1:$F$1,0)) -> 5004 | O11: =INDEX(CBS_bodemgebruik_2015!$C:$F,MATCH(Verdeelsleutels_absoluut!$C11,CBS_bodemgebruik_2015!$B:$B,0),MATCH(Verdeelsleutels_absoluut!O$1,CBS_bodemgebruik_2015!$C$1:$F$1,0)) -> 12959 | P11: =INDEX(CBS_bodemgebruik_2015!$C:$I,MATCH(Verdeelsleutels_absoluut!$C11,CBS_bodemgebruik_2015!$B:$B,0),MATCH(Verdeelsleutels_absoluut!P$1,CBS_bodemgebruik_2015!$C$1:$I$1,0)) -> 14814 | Q11: =INDEX(CBS_bodemgebruik_2015!$C:$I,MATCH(Verdeelsleutels_absoluut!$C11,CBS_bodemgebruik_2015!$B:$B,0),MATCH(Verdeelsleutels_absoluut!Q$1,CBS_bodemgebruik_2015!$C$1:$I$1,0)) -> 3484 | R11: =INDEX(CBS_bodemgebruik_2015!$C:$I,MATCH(Verdeelsleutels_absoluut!$C11,CBS_bodemgebruik_2015!$B:$B,0),MATCH(Verdeelsleutels_absoluut!R$1,CBS_bodemgebruik_2015!$C$1:$I$1,0)) -> 1557 | S11: =INDEX(CBS_bodemgebruik_2015!$C:$I,MATCH(Verdeelsleutels_absoluut!$C11,CBS_bodemgebruik_2015!$B:$B,0),MATCH(Verdeelsleutels_absoluut!S$1,CBS_bodemgebruik_2015!$C$1:$I$1,0)) -> 17977 | T11: =SUM(Q11:S11) -> 23018 | U11: =INDEX(CBS_wegen_2019!B:C,MATCH(C11,CBS_wegen_2019!B:B,0),2) -> 12192
B12: PV28 | C12: Zuid-Holland (PV) | D12: =INDEX(CBS_bevolking_2018!B:C,MATCH(Verdeelsleutels_absoluut!C12,CBS_bevolking_2018!B:B,0),2) -> 3709161 | E12: =INDEX(CBS_landbouw_2018!$C:$I,MATCH(Verdeelsleutels_absoluut!$C12,CBS_landbouw_2018!$B:$B,0),MATCH(Verdeelsleutels_absoluut!E$1,CBS_landbouw_2018!$C$1:$I$1,0)) -> 11968760 | F12: =INDEX(CBS_landbouw_2018!$C:$I,MATCH(Verdeelsleutels_absoluut!$C12,CBS_landbouw_2018!$B:$B,0),MATCH(Verdeelsleutels_absoluut!F$1,CBS_landbouw_2018!$C$1:$I$1,0)) -> 5843673 | G12: =INDEX(CBS_landbouw_2018!$C:$I,MATCH(Verdeelsleutels_absoluut!$C12,CBS_landbouw_2018!$B:$B,0),MATCH(Verdeelsleutels_absoluut!G$1,CBS_landbouw_2018!$C$1:$I$1,0)) -> 101865 | H12: =INDEX(CBS_landbouw_2018!$C:$I,MATCH(Verdeelsleutels_absoluut!$C12,CBS_landbouw_2018!$B:$B,0),MATCH(Verdeelsleutels_absoluut!H$1,CBS_landbouw_2018!$C$1:$I$1,0)) -> 126902 | I12: =INDEX(CBS_landbouw_2018!$C:$I,MATCH(Verdeelsleutels_absoluut!$C12,CBS_landbouw_2018!$B:$B,0),MATCH(Verdeelsleutels_absoluut!I$1,CBS_landbouw_2018!$C$1:$I$1,0)) -> 720574 | J12: =INDEX(CBS_landbouw_2018!$C:$I,MATCH(Verdeelsleutels_absoluut!$C12,CBS_landbouw_2018!$B:$B,0),MATCH(Verdeelsleutels_absoluut!J$1,CBS_landbouw_2018!$C$1:$I$1,0)) -> 1238467 | K12: =INDEX(CBS_landbouw_2018!$C:$I,MATCH(Verdeelsleutels_absoluut!$C12,CBS_landbouw_2018!$B:$B,0),MATCH(Verdeelsleutels_absoluut!K$1,CBS_landbouw_2018!$C$1:$I$1,0)) -> 554946 | L12: =E12-F12 -> 6125087 | M12: =INDEX(CBS_bodemgebruik_2015!$C:$F,MATCH(Verdeelsleutels_absoluut!$C12,CBS_bodemgebruik_2015!$B:$B,0),MATCH(Verdeelsleutels_absoluut!M$1,CBS_bodemgebruik_2015!$C$1:$F$1,0)) -> 162858 | N12: =INDEX(CBS_bodemgebruik_2015!$C:$F,MATCH(Verdeelsleutels_absoluut!$C12,CBS_bodemgebruik_2015!$B:$B,0),MATCH(Verdeelsleutels_absoluut!N$1,CBS_bodemgebruik_2015!$C$1:$F$1,0)) -> 6825 | O12: =INDEX(CBS_bodemgebruik_2015!$C:$F,MATCH(Verdeelsleutels_absoluut!$C12,CBS_bodemgebruik_2015!$B:$B,0),MATCH(Verdeelsleutels_absoluut!O$1,CBS_bodemgebruik_2015!$C$1:$F$1,0)) -> 8077 | P12: =INDEX(CBS_bodemgebruik_2015!$C:$I,MATCH(Verdeelsleutels_absoluut!$C12,CBS_bodemgebruik_2015!$B:$B,0),MATCH(Verdeelsleutels_absoluut!P$1,CBS_bodemgebruik_2015!$C$1:$I$1,0)) -> 9033 | Q12: =INDEX(CBS_bodemgebruik_2015!$C:$I,MATCH(Verdeelsleutels_absoluut!$C12,CBS_bodemgebruik_2015!$B:$B,0),MATCH(Verdeelsleutels_absoluut!Q$1,CBS_bodemgebruik_2015!$C$1:$I$1,0)) -> 6024 | R12: =INDEX(CBS_bodemgebruik_2015!$C:$I,MATCH(Verdeelsleutels_absoluut!$C12,CBS_bodemgebruik_2015!$B:$B,0),MATCH(Verdeelsleutels_absoluut!R$1,CBS_bodemgebruik_2015!$C$1:$I$1,0)) -> 1545 | S12: =INDEX(CBS_bodemgebruik_2015!$C:$I,MATCH(Verdeelsleutels_absoluut!$C12,CBS_bodemgebruik_2015!$B:$B,0),MATCH(Verdeelsleutels_absoluut!S$1,CBS_bodemgebruik_2015!$C$1:$I$1,0)) -> 18687 | T12: =SUM(Q12:S12) -> 26256 | U12: =INDEX(CBS_wegen_2019!B:C,MATCH(C12,CBS_wegen_2019!B:B,0),2) -> 15052
B13: PV29 | C13: Zeeland (PV) | D13: =INDEX(CBS_bevolking_2018!B:C,MATCH(Verdeelsleutels_absoluut!C13,CBS_bevolking_2018!B:B,0),2) -> 383032 | E13: =INDEX(CBS_landbouw_2018!$C:$I,MATCH(Verdeelsleutels_absoluut!$C13,CBS_landbouw_2018!$B:$B,0),MATCH(Verdeelsleutels_absoluut!E$1,CBS_landbouw_2018!$C$1:$I$1,0)) -> 11750782 | F13: =INDEX(CBS_landbouw_2018!$C:$I,MATCH(Verdeelsleutels_absoluut!$C13,CBS_landbouw_2018!$B:$B,0),MATCH(Verdeelsleutels_absoluut!F$1,CBS_landbouw_2018!$C$1:$I$1,0)) -> 874034 | G13: =INDEX(CBS_landbouw_2018!$C:$I,MATCH(Verdeelsleutels_absoluut!$C13,CBS_landbouw_2018!$B:$B,0),MATCH(Verdeelsleutels_absoluut!G$1,CBS_landbouw_2018!$C$1:$I$1,0)) -> 22555 | H13: =INDEX(CBS_landbouw_2018!$C:$I,MATCH(Verdeelsleutels_absoluut!$C13,CBS_landbouw_2018!$B:$B,0),MATCH(Verdeelsleutels_absoluut!H$1,CBS_landbouw_2018!$C$1:$I$1,0)) -> 50483 | I13: =INDEX(CBS_landbouw_2018!$C:$I,MATCH(Verdeelsleutels_absoluut!$C13,CBS_landbouw_2018!$B:$B,0),MATCH(Verdeelsleutels_absoluut!I$1,CBS_landbouw_2018!$C$1:$I$1,0)) -> 1787407 | J13: =INDEX(CBS_landbouw_2018!$C:$I,MATCH(Verdeelsleutels_absoluut!$C13,CBS_landbouw_2018!$B:$B,0),MATCH(Verdeelsleutels_absoluut!J$1,CBS_landbouw_2018!$C$1:$I$1,0)) -> 3022336 | K13: =INDEX(CBS_landbouw_2018!$C:$I,MATCH(Verdeelsleutels_absoluut!$C13,CBS_landbouw_2018!$B:$B,0),MATCH(Verdeelsleutels_absoluut!K$1,CBS_landbouw_2018!$C$1:$I$1,0)) -> 1128601 | L13: =E13-F13 -> 10876748 | M13: =INDEX(CBS_bodemgebruik_2015!$C:$F,MATCH(Verdeelsleutels_absoluut!$C13,CBS_bodemgebruik_2015!$B:$B,0),MATCH(Verdeelsleutels_absoluut!M$1,CBS_bodemgebruik_2015!$C$1:$F$1,0)) -> 136312 | N13: =INDEX(CBS_bodemgebruik_2015!$C:$F,MATCH(Verdeelsleutels_absoluut!$C13,CBS_bodemgebruik_2015!$B:$B,0),MATCH(Verdeelsleutels_absoluut!N$1,CBS_bodemgebruik_2015!$C$1:$F$1,0)) -> 767 | O13: =INDEX(CBS_bodemgebruik_2015!$C:$F,MATCH(Verdeelsleutels_absoluut!$C13,CBS_bodemgebruik_2015!$B:$B,0),MATCH(Verdeelsleutels_absoluut!O$1,CBS_bodemgebruik_2015!$C$1:$F$1,0)) -> 4071 | P13: =INDEX(CBS_bodemgebruik_2015!$C:$I,MATCH(Verdeelsleutels_absoluut!$C13,CBS_bodemgebruik_2015!$B:$B,0),MATCH(Verdeelsleutels_absoluut!P$1,CBS_bodemgebruik_2015!$C$1:$I$1,0)) -> 3831 | Q13: =INDEX(CBS_bodemgebruik_2015!$C:$I,MATCH(Verdeelsleutels_absoluut!$C13,CBS_bodemgebruik_2015!$B:$B,0),MATCH(Verdeelsleutels_absoluut!Q$1,CBS_bodemgebruik_2015!$C$1:$I$1,0)) -> 6350 | R13: =INDEX(CBS_bodemgebruik_2015!$C:$I,MATCH(Verdeelsleutels_absoluut!$C13,CBS_bodemgebruik_2015!$B:$B,0),MATCH(Verdeelsleutels_absoluut!R$1,CBS_bodemgebruik_2015!$C$1:$I$1,0)) -> 247 | S13: =INDEX(CBS_bodemgebruik_2015!$C:$I,MATCH(Verdeelsleutels_absoluut!$C13,CBS_bodemgebruik_2015!$B:$B,0),MATCH(Verdeelsleutels_absoluut!S$1,CBS_bodemgebruik_2015!$C$1:$I$1,0)) -> 5085 | T13: =SUM(Q13:S13) -> 11682 | U13: =INDEX(CBS_wegen_2019!B:C,MATCH(C13,CBS_wegen_2019!B:B,0),2) -> 6248
B14: PV30 | C14: Noord-Brabant (PV) | D14: =INDEX(CBS_bevolking_2018!B:C,MATCH(Verdeelsleutels_absoluut!C14,CBS_bevolking_2018!B:B,0),2) -> 2544806 | E14: =INDEX(CBS_landbouw_2018!$C:$I,MATCH(Verdeelsleutels_absoluut!$C14,CBS_landbouw_2018!$B:$B,0),MATCH(Verdeelsleutels_absoluut!E$1,CBS_landbouw_2018!$C$1:$I$1,0)) -> 23211455 | F14: =INDEX(CBS_landbouw_2018!$C:$I,MATCH(Verdeelsleutels_absoluut!$C14,CBS_landbouw_2018!$B:$B,0),MATCH(Verdeelsleutels_absoluut!F$1,CBS_landbouw_2018!$C$1:$I$1,0)) -> 4192599 | G14: =INDEX(CBS_landbouw_2018!$C:$I,MATCH(Verdeelsleutels_absoluut!$C14,CBS_landbouw_2018!$B:$B,0),MATCH(Verdeelsleutels_absoluut!G$1,CBS_landbouw_2018!$C$1:$I$1,0)) -> 221900 | H14: =INDEX(CBS_landbouw_2018!$C:$I,MATCH(Verdeelsleutels_absoluut!$C14,CBS_landbouw_2018!$B:$B,0),MATCH(Verdeelsleutels_absoluut!H$1,CBS_landbouw_2018!$C$1:$I$1,0)) -> 5933851 | I14: =INDEX(CBS_landbouw_2018!$C:$I,MATCH(Verdeelsleutels_absoluut!$C14,CBS_landbouw_2018!$B:$B,0),MATCH(Verdeelsleutels_absoluut!I$1,CBS_landbouw_2018!$C$1:$I$1,0)) -> 24671562 | J14: =INDEX(CBS_landbouw_2018!$C:$I,MATCH(Verdeelsleutels_absoluut!$C14,CBS_landbouw_2018!$B:$B,0),MATCH(Verdeelsleutels_absoluut!J$1,CBS_landbouw_2018!$C$1:$I$1,0)) -> 1652080 | K14: =INDEX(CBS_landbouw_2018!$C:$I,MATCH(Verdeelsleutels_absoluut!$C14,CBS_landbouw_2018!$B:$B,0),MATCH(Verdeelsleutels_absoluut!K$1,CBS_landbouw_2018!$C$1:$I$1,0)) -> 1092551 | L14: =E14-F14 -> 19018856 | M14: =INDEX(CBS_bodemgebruik_2015!$C:$F,MATCH(Verdeelsleutels_absoluut!$C14,CBS_bodemgebruik_2015!$B:$B,0),MATCH(Verdeelsleutels_absoluut!M$1,CBS_bodemgebruik_2015!$C$1:$F$1,0)) -> 304515 | N14: =INDEX(CBS_bodemgebruik_2015!$C:$F,MATCH(Verdeelsleutels_absoluut!$C14,CBS_bodemgebruik_2015!$B:$B,0),MATCH(Verdeelsleutels_absoluut!N$1,CBS_bodemgebruik_2015!$C$1:$F$1,0)) -> 4019 | O14: =INDEX(CBS_bodemgebruik_2015!$C:$F,MATCH(Verdeelsleutels_absoluut!$C14,CBS_bodemgebruik_2015!$B:$B,0),MATCH(Verdeelsleutels_absoluut!O$1,CBS_bodemgebruik_2015!$C$1:$F$1,0)) -> 70780 | P14: =INDEX(CBS_bodemgebruik_2015!$C:$I,MATCH(Verdeelsleutels_absoluut!$C14,CBS_bodemgebruik_2015!$B:$B,0),MATCH(Verdeelsleutels_absoluut!P$1,CBS_bodemgebruik_2015!$C$1:$I$1,0)) -> 7951 | Q14: =INDEX(CBS_bodemgebruik_2015!$C:$I,MATCH(Verdeelsleutels_absoluut!$C14,CBS_bodemgebruik_2015!$B:$B,0),MATCH(Verdeelsleutels_absoluut!Q$1,CBS_bodemgebruik_2015!$C$1:$I$1,0)) -> 6581 | R14: =INDEX(CBS_bodemgebruik_2015!$C:$I,MATCH(Verdeelsleutels_absoluut!$C14,CBS_bodemgebruik_2015!$B:$B,0),MATCH(Verdeelsleutels_absoluut!R$1,CBS_bodemgebruik_2015!$C$1:$I$1,0)) -> 1511 | S14: =INDEX(CBS_bodemgebruik_2015!$C:$I,MATCH(Verdeelsleutels_absoluut!$C14,CBS_bodemgebruik_2015!$B:$B,0),MATCH(Verdeelsleutels_absoluut!S$1,CBS_bodemgebruik_2015!$C$1:$I$1,0)) -> 9082 | T14: =SUM(Q14:S14) -> 17174 | U14: =INDEX(CBS_wegen_2019!B:C,MATCH(C14,CBS_wegen_2019!B:B,0),2) -> 21336
B15: PV31 | C15: Limburg (PV) | D15: =INDEX(CBS_bevolking_2018!B:C,MATCH(Verdeelsleutels_absoluut!C15,CBS_bevolking_2018!B:B,0),2) -> 1116137 | E15: =INDEX(CBS_landbouw_2018!$C:$I,MATCH(Verdeelsleutels_absoluut!$C15,CBS_landbouw_2018!$B:$B,0),MATCH(Verdeelsleutels_absoluut!E$1,CBS_landbouw_2018!$C$1:$I$1,0)) -> 9371835 | F15: =INDEX(CBS_landbouw_2018!$C:$I,MATCH(Verdeelsleutels_absoluut!$C15,CBS_landbouw_2018!$B:$B,0),MATCH(Verdeelsleutels_absoluut!F$1,CBS_landbouw_2018!$C$1:$I$1,0)) -> 1601987 | G15: =INDEX(CBS_landbouw_2018!$C:$I,MATCH(Verdeelsleutels_absoluut!$C15,CBS_landbouw_2018!$B:$B,0),MATCH(Verdeelsleutels_absoluut!G$1,CBS_landbouw_2018!$C$1:$I$1,0)) -> 51322 | H15: =INDEX(CBS_landbouw_2018!$C:$I,MATCH(Verdeelsleutels_absoluut!$C15,CBS_landbouw_2018!$B:$B,0),MATCH(Verdeelsleutels_absoluut!H$1,CBS_landbouw_2018!$C$1:$I$1,0)) -> 1973206 | I15: =INDEX(CBS_landbouw_2018!$C:$I,MATCH(Verdeelsleutels_absoluut!$C15,CBS_landbouw_2018!$B:$B,0),MATCH(Verdeelsleutels_absoluut!I$1,CBS_landbouw_2018!$C$1:$I$1,0)) -> 15526729 | J15: =INDEX(CBS_landbouw_2018!$C:$I,MATCH(Verdeelsleutels_absoluut!$C15,CBS_landbouw_2018!$B:$B,0),MATCH(Verdeelsleutels_absoluut!J$1,CBS_landbouw_2018!$C$1:$I$1,0)) -> 1280322 | K15: =INDEX(CBS_landbouw_2018!$C:$I,MATCH(Verdeelsleutels_absoluut!$C15,CBS_landbouw_2018!$B:$B,0),MATCH(Verdeelsleutels_absoluut!K$1,CBS_landbouw_2018!$C$1:$I$1,0)) -> 448848 | L15: =E15-F15 -> 7769848 | M15: =INDEX(CBS_bodemgebruik_2015!$C:$F,MATCH(Verdeelsleutels_absoluut!$C15,CBS_bodemgebruik_2015!$B:$B,0),MATCH(Verdeelsleutels_absoluut!M$1,CBS_bodemgebruik_2015!$C$1:$F$1,0)) -> 129331 | N15: =INDEX(CBS_bodemgebruik_2015!$C:$F,MATCH(Verdeelsleutels_absoluut!$C15,CBS_bodemgebruik_2015!$B:$B,0),MATCH(Verdeelsleutels_absoluut!N$1,CBS_bodemgebruik_2015!$C$1:$F$1,0)) -> 2010 | O15: =INDEX(CBS_bodemgebruik_2015!$C:$F,MATCH(Verdeelsleutels_absoluut!$C15,CBS_bodemgebruik_2015!$B:$B,0),MATCH(Verdeelsleutels_absoluut!O$1,CBS_bodemgebruik_2015!$C$1:$F$1,0)) -> 32032 | P15: =INDEX(CBS_bodemgebruik_2015!$C:$I,MATCH(Verdeelsleutels_absoluut!$C15,CBS_bodemgebruik_2015!$B:$B,0),MATCH(Verdeelsleutels_absoluut!P$1,CBS_bodemgebruik_2015!$C$1:$I$1,0)) -> 2720 | Q15: =INDEX(CBS_bodemgebruik_2015!$C:$I,MATCH(Verdeelsleutels_absoluut!$C15,CBS_bodemgebruik_2015!$B:$B,0),MATCH(Verdeelsleutels_absoluut!Q$1,CBS_bodemgebruik_2015!$C$1:$I$1,0)) -> 1199 | R15: =INDEX(CBS_bodemgebruik_2015!$C:$I,MATCH(Verdeelsleutels_absoluut!$C15,CBS_bodemgebruik_2015!$B:$B,0),MATCH(Verdeelsleutels_absoluut!R$1,CBS_bodemgebruik_2015!$C$1:$I$1,0)) -> 1079 | S15: =INDEX(CBS_bodemgebruik_2015!$C:$I,MATCH(Verdeelsleutels_absoluut!$C15,CBS_bodemgebruik_2015!$B:$B,0),MATCH(Verdeelsleutels_absoluut!S$1,CBS_bodemgebruik_2015!$C$1:$I$1,0)) -> 2993 | T15: =SUM(Q15:S15) -> 5271 | U15: =INDEX(CBS_wegen_2019!B:C,MATCH(C15,CBS_wegen_2019!B:B,0),2) -> 10600
