Workbook

Sheet Data
A1: GemeentecodeGM | B1: share_gas_demand
A2: GM0014 | B2: =INDEX(Calculation!$Z:$Z,MATCH($A2,Calculation!$B:$B,0)) -> 0.011806352
A3: GM0034 | B3: =INDEX(Calculation!$Z:$Z,MATCH($A3,Calculation!$B:$B,0)) -> 0.0028103239
A4: GM0037 | B4: =INDEX(Calculation!$Z:$Z,MATCH($A4,Calculation!$B:$B,0)) -> 0.0012248425
A5: GM0047 | B5: =INDEX(Calculation!$Z:$Z,MATCH($A5,Calculation!$B:$B,0)) -> 0.0010104535
A6: GM0050 | B6: =INDEX(Calculation!$Z:$Z,MATCH($A6,Calculation!$B:$B,0)) -> 0.0011317744
A7: GM0059 | B7: =INDEX(Calculation!$Z:$Z,MATCH($A7,Calculation!$B:$B,0)) -> 0.0013195726
A8: GM0060 | B8: =INDEX(Calculation!$Z:$Z,MATCH($A8,Calculation!$B:$B,0)) -> 0.00031576673
A9: GM0072 | B9: =INDEX(Calculation!$Z:$Z,MATCH($A9,Calculation!$B:$B,0)) -> 0.00050190291
A10: GM0074 | B10: =INDEX(Calculation!$Z:$Z,MATCH($A10,Calculation!$B:$B,0)) -> 0.0031377242
A11: GM0080 | B11: =INDEX(Calculation!$Z:$Z,MATCH($A11,Calculation!$B:$B,0)) -> 0.0063735022
A12: GM0085 | B12: =INDEX(Calculation!$Z:$Z,MATCH($A12,Calculation!$B:$B,0)) -> 0.001023749
A13: GM0086 | B13: =INDEX(Calculation!$Z:$Z,MATCH($A13,Calculation!$B:$B,0)) -> 0.001047016
... A343: GM1992 | B343: =INDEX(Calculation!$Z:$Z,MATCH($A343,Calculation!$B:$B,0)) -> 0.0025626963

Sheet Calculation
D1: 2019 | E1: 2020 | F1: 2021 | G1: 2022 | H1: 2023 | I1: 2019 | J1: 2020 | K1: 2021 | L1: 2022 | M1: 2023 | N1: 2019 | O1: 2020 | P1: 2021 | Q1: 2022 | R1: 2023 | S1: jaartal | T1: jaartal | U1: jaartal | V1: value | W1: value | X1: value | Y1: optelling | Z1: uitkomst
A2: Gemeentecode | B2: GemeentecodeGM | C2: Gemeentenaam | D2: Aardgasverbruik Gebouwde omgeving_2019 | E2: Aardgasverbruik Gebouwde omgeving_2020 | F2: Aardgasverbruik Gebouwde omgeving_2021 | G2: Aardgasverbruik Gebouwde omgeving_2022 | H2: Aardgasverbruik Gebouwde omgeving_2023 | I2: Totaal bekend aardgasverbruik Industrie, Energie, Afval en Water (excl. Energievoorziening, SBI D)_2019 | J2: Totaal bekend aardgasverbruik Industrie, Energie, Afval en Water (excl. Energievoorziening, SBI D)_2020 | K2: Totaal bekend aardgasverbruik Industrie, Energie, Afval en Water (excl. Energievoorziening, SBI D)_2021 | L2: Totaal bekend aardgasverbruik Industrie, Energie, Afval en Water (excl. Energievoorziening, SBI D)_2022 | M2: Totaal bekend aardgasverbruik Industrie, Energie, Afval en Water (excl. Energievoorziening, SBI D)_2023 | N2: Aardgas geleverd aan Landbouw, bosbouw en visserij (SBI A)_2019 | O2: Aardgas geleverd aan Landbouw, bosbouw en visserij (SBI A)_2020 | P2: Aardgas geleverd aan Landbouw, bosbouw en visserij (SBI A)_2021 | Q2: Aardgas geleverd aan Landbouw, bosbouw en visserij (SBI A)_2022 | R2: Aardgas geleverd aan Landbouw, bosbouw en visserij (SBI A)_2023 | S2: Aardgasverbruik Gebouwde omgeving | T2: Totaal bekend aardgasverbruik Industrie, Energie, Afval en Water (excl. Energievoorziening, SBI D) | U2: Aardgas geleverd aan Landbouw, bosbouw en visserij (SBI A) | V2: Aardgasverbruik Gebouwde omgeving | W2: Totaal bekend aardgasverbruik Industrie, Energie, Afval en Water (excl. Energievoorziening, SBI D) | X2: Aardgas geleverd aan Landbouw, bosbouw en visserij (SBI A) | Y2: Totaal aardgasverbruik | Z2: share_gas_demand
A3: 0518 | B3: GM0518 | C3: Den Haag | D3: =INDEX('Energieverbruik in TJ Gemeente'!$B$4:$Q$347,MATCH($C3,'Energieverbruik in TJ Gemeente'!$B$4:$B$347,0),MATCH(D$2,'Energieverbruik in TJ Gemeente'!$B$4:$Q$4,0)) -> 11688 | E3: =INDEX('Energieverbruik in TJ Gemeente'!$B$4:$Q$347,MATCH($C3,'Energieverbruik in TJ Gemeente'!$B$4:$B$347,0),MATCH(E$2,'Energieverbruik in TJ Gemeente'!$B$4:$Q$4,0)) -> 11297 | F3: =INDEX('Energieverbruik in TJ Gemeente'!$B$4:$Q$347,MATCH($C3,'Energieverbruik in TJ Gemeente'!$B$4:$B$347,0),MATCH(F$2,'Energieverbruik in TJ Gemeente'!$B$4:$Q$4,0)) -> 11499 | G3: =INDEX('Energieverbruik in TJ Gemeente'!$B$4:$Q$347,MATCH($C3,'Energieverbruik in TJ Gemeente'!$B$4:$B$347,0),MATCH(G$2,'Energieverbruik in TJ Gemeente'!$B$4:$Q$4,0)) -> 10186 | H3: =INDEX('Energieverbruik in TJ Gemeente'!$B$4:$Q$347,MATCH($C3,'Energieverbruik in TJ Gemeente'!$B$4:$B$347,0),MATCH(H$2,'Energieverbruik in TJ Gemeente'!$B$4:$Q$4,0)) -> 8940 | I3: =INDEX('Energieverbruik in TJ Gemeente'!$B$4:$Q$347,MATCH($C3,'Energieverbruik in TJ Gemeente'!$B$4:$B$347,0),MATCH(I$2,'Energieverbruik in TJ Gemeente'!$B$4:$Q$4,0)) -> 225 | J3: =INDEX('Energieverbruik in TJ Gemeente'!$B$4:$Q$347,MATCH($C3,'Energieverbruik in TJ Gemeente'!$B$4:$B$347,0),MATCH(J$2,'Energieverbruik in TJ Gemeente'!$B$4:$Q$4,0)) -> 195 | K3: =INDEX('Energieverbruik in TJ Gemeente'!$B$4:$Q$347,MATCH($C3,'Energieverbruik in TJ Gemeente'!$B$4:$B$347,0),MATCH(K$2,'Energieverbruik in TJ Gemeente'!$B$4:$Q$4,0)) -> 185 | ... R3: =INDEX('Energieverbruik in TJ Gemeente'!$B$4:$Q$347,MATCH($C3,'Energieverbruik in TJ Gemeente'!$B$4:$B$347,0),MATCH(R$2,'Energieverbruik in TJ Gemeente'!$B$4:$Q$4,0)) -> 18 | S3: {=MAX(_xlfn._xlws.FILTER(D$1:H$1, D3:H3<>"?"))} -> 2023 | T3: {=MAX(_xlfn._xlws.FILTER(I$1:M$1, I3:M3<>"?"))} -> 2023 | U3: {=MAX(_xlfn._xlws.FILTER(F$1:J$1, F3:J3<>"?"))} -> 2023 | V3: =IFERROR(INDEX($D3:$H3,MATCH(S3,$D$1:$H$1,0)),0) -> 8940 | W3: =IFERROR(INDEX($I3:$M3,MATCH(T3,$I$1:$M$1,0)),0) -> 129 | X3: =IFERROR(INDEX($N3:$R3,MATCH(U3,$N$1:$R$1,0)),0) -> 18 | Y3: =SUM(V3:X3) -> 9087 | Z3: =Y3/SUM($Y$3:$Y$344) -> 0.015101959
A4: 0796 | B4: GM0796 | C4: s-Hertogenbosch | D4: =INDEX('Energieverbruik in TJ Gemeente'!$B$4:$Q$347,MATCH($C4,'Energieverbruik in TJ Gemeente'!$B$4:$B$347,0),MATCH(D$2,'Energieverbruik in TJ Gemeente'!$B$4:$Q$4,0)) -> 3861 | E4: =INDEX('Energieverbruik in TJ Gemeente'!$B$4:$Q$347,MATCH($C4,'Energieverbruik in TJ Gemeente'!$B$4:$B$347,0),MATCH(E$2,'Energieverbruik in TJ Gemeente'!$B$4:$Q$4,0)) -> 3738 | F4: =INDEX('Energieverbruik in TJ Gemeente'!$B$4:$Q$347,MATCH($C4,'Energieverbruik in TJ Gemeente'!$B$4:$B$347,0),MATCH(F$2,'Energieverbruik in TJ Gemeente'!$B$4:$Q$4,0)) -> 3797 | G4: =INDEX('Energieverbruik in TJ Gemeente'!$B$4:$Q$347,MATCH($C4,'Energieverbruik in TJ Gemeente'!$B$4:$B$347,0),MATCH(G$2,'Energieverbruik in TJ Gemeente'!$B$4:$Q$4,0)) -> 3316 | H4: =INDEX('Energieverbruik in TJ Gemeente'!$B$4:$Q$347,MATCH($C4,'Energieverbruik in TJ Gemeente'!$B$4:$B$347,0),MATCH(H$2,'Energieverbruik in TJ Gemeente'!$B$4:$Q$4,0)) -> 2828 | I4: =INDEX('Energieverbruik in TJ Gemeente'!$B$4:$Q$347,MATCH($C4,'Energieverbruik in TJ Gemeente'!$B$4:$B$347,0),MATCH(I$2,'Energieverbruik in TJ Gemeente'!$B$4:$Q$4,0)) -> 559 | J4: =INDEX('Energieverbruik in TJ Gemeente'!$B$4:$Q$347,MATCH($C4,'Energieverbruik in TJ Gemeente'!$B$4:$B$347,0),MATCH(J$2,'Energieverbruik in TJ Gemeente'!$B$4:$Q$4,0)) -> 537 | K4: =INDEX('Energieverbruik in TJ Gemeente'!$B$4:$Q$347,MATCH($C4,'Energieverbruik in TJ Gemeente'!$B$4:$B$347,0),MATCH(K$2,'Energieverbruik in TJ Gemeente'!$B$4:$Q$4,0)) -> 513 | ... R4: =INDEX('Energieverbruik in TJ Gemeente'!$B$4:$Q$347,MATCH($C4,'Energieverbruik in TJ Gemeente'!$B$4:$B$347,0),MATCH(R$2,'Energieverbruik in TJ Gemeente'!$B$4:$Q$4,0)) -> 16 | S4: {=MAX(_xlfn._xlws.FILTER(D$1:H$1, D4:H4<>"?"))} -> 2023 | T4: {=MAX(_xlfn._xlws.FILTER(I$1:M$1, I4:M4<>"?"))} -> 2023 | U4: {=MAX(_xlfn._xlws.FILTER(F$1:J$1, F4:J4<>"?"))} -> 2023 | V4: =IFERROR(INDEX($D4:$H4,MATCH(S4,$D$1:$H$1,0)),0) -> 2828 | W4: =IFERROR(INDEX($I4:$M4,MATCH(T4,$I$1:$M$1,0)),0) -> 399 | X4: =IFERROR(INDEX($N4:$R4,MATCH(U4,$N$1:$R$1,0)),0) -> 16 | Y4: =SUM(V4:X4) -> 3243 | Z4: =Y4/SUM($Y$3:$Y$344) -> 0.0053896395
A5: 1680 | B5: GM1680 | C5: Aa en Hunze | D5: =INDEX('Energieverbruik in TJ Gemeente'!$B$4:$Q$347,MATCH($C5,'Energieverbruik in TJ Gemeente'!$B$4:$B$347,0),MATCH(D$2,'Energieverbruik in TJ Gemeente'!$B$4:$Q$4,0)) -> 928 | E5: =INDEX('Energieverbruik in TJ Gemeente'!$B$4:$Q$347,MATCH($C5,'Energieverbruik in TJ Gemeente'!$B$4:$B$347,0),MATCH(E$2,'Energieverbruik in TJ Gemeente'!$B$4:$Q$4,0)) -> ? | F5: =INDEX('Energieverbruik in TJ Gemeente'!$B$4:$Q$347,MATCH($C5,'Energieverbruik in TJ Gemeente'!$B$4:$B$347,0),MATCH(F$2,'Energieverbruik in TJ Gemeente'!$B$4:$Q$4,0)) -> ? | G5: =INDEX('Energieverbruik in TJ Gemeente'!$B$4:$Q$347,MATCH($C5,'Energieverbruik in TJ Gemeente'!$B$4:$B$347,0),MATCH(G$2,'Energieverbruik in TJ Gemeente'!$B$4:$Q$4,0)) -> ? | H5: =INDEX('Energieverbruik in TJ Gemeente'!$B$4:$Q$347,MATCH($C5,'Energieverbruik in TJ Gemeente'!$B$4:$B$347,0),MATCH(H$2,'Energieverbruik in TJ Gemeente'!$B$4:$Q$4,0)) -> ? | I5: =INDEX('Energieverbruik in TJ Gemeente'!$B$4:$Q$347,MATCH($C5,'Energieverbruik in TJ Gemeente'!$B$4:$B$347,0),MATCH(I$2,'Energieverbruik in TJ Gemeente'!$B$4:$Q$4,0)) -> ? | J5: =INDEX('Energieverbruik in TJ Gemeente'!$B$4:$Q$347,MATCH($C5,'Energieverbruik in TJ Gemeente'!$B$4:$B$347,0),MATCH(J$2,'Energieverbruik in TJ Gemeente'!$B$4:$Q$4,0)) -> ? | K5: =INDEX('Energieverbruik in TJ Gemeente'!$B$4:$Q$347,MATCH($C5,'Energieverbruik in TJ Gemeente'!$B$4:$B$347,0),MATCH(K$2,'Energieverbruik in TJ Gemeente'!$B$4:$Q$4,0)) -> ? | ... R5: =INDEX('Energieverbruik in TJ Gemeente'!$B$4:$Q$347,MATCH($C5,'Energieverbruik in TJ Gemeente'!$B$4:$B$347,0),MATCH(R$2,'Energieverbruik in TJ Gemeente'!$B$4:$Q$4,0)) -> 22 | S5: {=MAX(_xlfn._xlws.FILTER(D$1:H$1, D5:H5<>"?"))} -> 2019 | T5: {=MAX(_xlfn._xlws.FILTER(I$1:M$1, I5:M5<>"?"))} -> #VALUE! | U5: {=MAX(_xlfn._xlws.FILTER(F$1:J$1, F5:J5<>"?"))} -> #VALUE! | V5: =IFERROR(INDEX($D5:$H5,MATCH(S5,$D$1:$H$1,0)),0) -> 928 | W5: =IFERROR(INDEX($I5:$M5,MATCH(T5,$I$1:$M$1,0)),0) -> 0 | X5: =IFERROR(INDEX($N5:$R5,MATCH(U5,$N$1:$R$1,0)),0) -> 0 | Y5: =SUM(V5:X5) -> 928 | Z5: =Y5/SUM($Y$3:$Y$344) -> 0.0015422712
A6: 0358 | B6: GM0358 | C6: Aalsmeer | D6: =INDEX('Energieverbruik in TJ Gemeente'!$B$4:$Q$347,MATCH($C6,'Energieverbruik in TJ Gemeente'!$B$4:$B$347,0),MATCH(D$2,'Energieverbruik in TJ Gemeente'!$B$4:$Q$4,0)) -> ? | E6: =INDEX('Energieverbruik in TJ Gemeente'!$B$4:$Q$347,MATCH($C6,'Energieverbruik in TJ Gemeente'!$B$4:$B$347,0),MATCH(E$2,'Energieverbruik in TJ Gemeente'!$B$4:$Q$4,0)) -> ? | F6: =INDEX('Energieverbruik in TJ Gemeente'!$B$4:$Q$347,MATCH($C6,'Energieverbruik in TJ Gemeente'!$B$4:$B$347,0),MATCH(F$2,'Energieverbruik in TJ Gemeente'!$B$4:$Q$4,0)) -> ? | G6: =INDEX('Energieverbruik in TJ Gemeente'!$B$4:$Q$347,MATCH($C6,'Energieverbruik in TJ Gemeente'!$B$4:$B$347,0),MATCH(G$2,'Energieverbruik in TJ Gemeente'!$B$4:$Q$4,0)) -> 760 | H6: =INDEX('Energieverbruik in TJ Gemeente'!$B$4:$Q$347,MATCH($C6,'Energieverbruik in TJ Gemeente'!$B$4:$B$347,0),MATCH(H$2,'Energieverbruik in TJ Gemeente'!$B$4:$Q$4,0)) -> ? | I6: =INDEX('Energieverbruik in TJ Gemeente'!$B$4:$Q$347,MATCH($C6,'Energieverbruik in TJ Gemeente'!$B$4:$B$347,0),MATCH(I$2,'Energieverbruik in TJ Gemeente'!$B$4:$Q$4,0)) -> ? | J6: =INDEX('Energieverbruik in TJ Gemeente'!$B$4:$Q$347,MATCH($C6,'Energieverbruik in TJ Gemeente'!$B$4:$B$347,0),MATCH(J$2,'Energieverbruik in TJ Gemeente'!$B$4:$Q$4,0)) -> ? | K6: =INDEX('Energieverbruik in TJ Gemeente'!$B$4:$Q$347,MATCH($C6,'Energieverbruik in TJ Gemeente'!$B$4:$B$347,0),MATCH(K$2,'Energieverbruik in TJ Gemeente'!$B$4:$Q$4,0)) -> ? | ... R6: =INDEX('Energieverbruik in TJ Gemeente'!$B$4:$Q$347,MATCH($C6,'Energieverbruik in TJ Gemeente'!$B$4:$B$347,0),MATCH(R$2,'Energieverbruik in TJ Gemeente'!$B$4:$Q$4,0)) -> 514 | S6: {=MAX(_xlfn._xlws.FILTER(D$1:H$1, D6:H6<>"?"))} -> 2022 | T6: {=MAX(_xlfn._xlws.FILTER(I$1:M$1, I6:M6<>"?"))} -> #VALUE! | U6: {=MAX(_xlfn._xlws.FILTER(F$1:J$1, F6:J6<>"?"))} -> 2022 | V6: =IFERROR(INDEX($D6:$H6,MATCH(S6,$D$1:$H$1,0)),0) -> 760 | W6: =IFERROR(INDEX($I6:$M6,MATCH(T6,$I$1:$M$1,0)),0) -> 0 | X6: =IFERROR(INDEX($N6:$R6,MATCH(U6,$N$1:$R$1,0)),0) -> 482 | Y6: =SUM(V6:X6) -> 1242 | Z6: =Y6/SUM($Y$3:$Y$344) -> 0.0020641173
A7: 0197 | B7: GM0197 | C7: Aalten | D7: =INDEX('Energieverbruik in TJ Gemeente'!$B$4:$Q$347,MATCH($C7,'Energieverbruik in TJ Gemeente'!$B$4:$B$347,0),MATCH(D$2,'Energieverbruik in TJ Gemeente'!$B$4:$Q$4,0)) -> ? | E7: =INDEX('Energieverbruik in TJ Gemeente'!$B$4:$Q$347,MATCH($C7,'Energieverbruik in TJ Gemeente'!$B$4:$B$347,0),MATCH(E$2,'Energieverbruik in TJ Gemeente'!$B$4:$Q$4,0)) -> 662 | F7: =INDEX('Energieverbruik in TJ Gemeente'!$B$4:$Q$347,MATCH($C7,'Energieverbruik in TJ Gemeente'!$B$4:$B$347,0),MATCH(F$2,'Energieverbruik in TJ Gemeente'!$B$4:$Q$4,0)) -> 665 | G7: =INDEX('Energieverbruik in TJ Gemeente'!$B$4:$Q$347,MATCH($C7,'Energieverbruik in TJ Gemeente'!$B$4:$B$347,0),MATCH(G$2,'Energieverbruik in TJ Gemeente'!$B$4:$Q$4,0)) -> 594 | H7: =INDEX('Energieverbruik in TJ Gemeente'!$B$4:$Q$347,MATCH($C7,'Energieverbruik in TJ Gemeente'!$B$4:$B$347,0),MATCH(H$2,'Energieverbruik in TJ Gemeente'!$B$4:$Q$4,0)) -> 477 | I7: =INDEX('Energieverbruik in TJ Gemeente'!$B$4:$Q$347,MATCH($C7,'Energieverbruik in TJ Gemeente'!$B$4:$B$347,0),MATCH(I$2,'Energieverbruik in TJ Gemeente'!$B$4:$Q$4,0)) -> 69 | J7: =INDEX('Energieverbruik in TJ Gemeente'!$B$4:$Q$347,MATCH($C7,'Energieverbruik in TJ Gemeente'!$B$4:$B$347,0),MATCH(J$2,'Energieverbruik in TJ Gemeente'!$B$4:$Q$4,0)) -> 64 | K7: =INDEX('Energieverbruik in TJ Gemeente'!$B$4:$Q$347,MATCH($C7,'Energieverbruik in TJ Gemeente'!$B$4:$B$347,0),MATCH(K$2,'Energieverbruik in TJ Gemeente'!$B$4:$Q$4,0)) -> 70 | ... R7: =INDEX('Energieverbruik in TJ Gemeente'!$B$4:$Q$347,MATCH($C7,'Energieverbruik in TJ Gemeente'!$B$4:$B$347,0),MATCH(R$2,'Energieverbruik in TJ Gemeente'!$B$4:$Q$4,0)) -> 19 | S7: {=MAX(_xlfn._xlws.FILTER(D$1:H$1, D7:H7<>"?"))} -> 2023 | T7: {=MAX(_xlfn._xlws.FILTER(I$1:M$1, I7:M7<>"?"))} -> 2023 | U7: {=MAX(_xlfn._xlws.FILTER(F$1:J$1, F7:J7<>"?"))} -> 2023 | V7: =IFERROR(INDEX($D7:$H7,MATCH(S7,$D$1:$H$1,0)),0) -> 477 | W7: =IFERROR(INDEX($I7:$M7,MATCH(T7,$I$1:$M$1,0)),0) -> 44 | X7: =IFERROR(INDEX($N7:$R7,MATCH(U7,$N$1:$R$1,0)),0) -> 19 | Y7: =SUM(V7:X7) -> 540 | Z7: =Y7/SUM($Y$3:$Y$344) -> 0.00089744229
A8: 0059 | B8: GM0059 | C8: Achtkarspelen | D8: =INDEX('Energieverbruik in TJ Gemeente'!$B$4:$Q$347,MATCH($C8,'Energieverbruik in TJ Gemeente'!$B$4:$B$347,0),MATCH(D$2,'Energieverbruik in TJ Gemeente'!$B$4:$Q$4,0)) -> 725 | E8: =INDEX('Energieverbruik in TJ Gemeente'!$B$4:$Q$347,MATCH($C8,'Energieverbruik in TJ Gemeente'!$B$4:$B$347,0),MATCH(E$2,'Energieverbruik in TJ Gemeente'!$B$4:$Q$4,0)) -> 726 | F8: =INDEX('Energieverbruik in TJ Gemeente'!$B$4:$Q$347,MATCH($C8,'Energieverbruik in TJ Gemeente'!$B$4:$B$347,0),MATCH(F$2,'Energieverbruik in TJ Gemeente'!$B$4:$Q$4,0)) -> 723 | G8: =INDEX('Energieverbruik in TJ Gemeente'!$B$4:$Q$347,MATCH($C8,'Energieverbruik in TJ Gemeente'!$B$4:$B$347,0),MATCH(G$2,'Energieverbruik in TJ Gemeente'!$B$4:$Q$4,0)) -> 630 | H8: =INDEX('Energieverbruik in TJ Gemeente'!$B$4:$Q$347,MATCH($C8,'Energieverbruik in TJ Gemeente'!$B$4:$B$347,0),MATCH(H$2,'Energieverbruik in TJ Gemeente'!$B$4:$Q$4,0)) -> 508 | I8: =INDEX('Energieverbruik in TJ Gemeente'!$B$4:$Q$347,MATCH($C8,'Energieverbruik in TJ Gemeente'!$B$4:$B$347,0),MATCH(I$2,'Energieverbruik in TJ Gemeente'!$B$4:$Q$4,0)) -> 347 | J8: =INDEX('Energieverbruik in TJ Gemeente'!$B$4:$Q$347,MATCH($C8,'Energieverbruik in TJ Gemeente'!$B$4:$B$347,0),MATCH(J$2,'Energieverbruik in TJ Gemeente'!$B$4:$Q$4,0)) -> 319 | K8: =INDEX('Energieverbruik in TJ Gemeente'!$B$4:$Q$347,MATCH($C8,'Energieverbruik in TJ Gemeente'!$B$4:$B$347,0),MATCH(K$2,'Energieverbruik in TJ Gemeente'!$B$4:$Q$4,0)) -> 286 | ... R8: =INDEX('Energieverbruik in TJ Gemeente'!$B$4:$Q$347,MATCH($C8,'Energieverbruik in TJ Gemeente'!$B$4:$B$347,0),MATCH(R$2,'Energieverbruik in TJ Gemeente'!$B$4:$Q$4,0)) -> 9 | S8: {=MAX(_xlfn._xlws.FILTER(D$1:H$1, D8:H8<>"?"))} -> 2023 | T8: {=MAX(_xlfn._xlws.FILTER(I$1:M$1, I8:M8<>"?"))} -> 2023 | U8: {=MAX(_xlfn._xlws.FILTER(F$1:J$1, F8:J8<>"?"))} -> 2023 | V8: =IFERROR(INDEX($D8:$H8,MATCH(S8,$D$1:$H$1,0)),0) -> 508 | W8: =IFERROR(INDEX($I8:$M8,MATCH(T8,$I$1:$M$1,0)),0) -> 277 | X8: =IFERROR(INDEX($N8:$R8,MATCH(U8,$N$1:$R$1,0)),0) -> 9 | Y8: =SUM(V8:X8) -> 794 | Z8: =Y8/SUM($Y$3:$Y$344) -> 0.0013195726
A9: 0482 | B9: GM0482 | C9: Alblasserdam | D9: =INDEX('Energieverbruik in TJ Gemeente'!$B$4:$Q$347,MATCH($C9,'Energieverbruik in TJ Gemeente'!$B$4:$B$347,0),MATCH(D$2,'Energieverbruik in TJ Gemeente'!$B$4:$Q$4,0)) -> ? | E9: =INDEX('Energieverbruik in TJ Gemeente'!$B$4:$Q$347,MATCH($C9,'Energieverbruik in TJ Gemeente'!$B$4:$B$347,0),MATCH(E$2,'Energieverbruik in TJ Gemeente'!$B$4:$Q$4,0)) -> 394 | F9: =INDEX('Energieverbruik in TJ Gemeente'!$B$4:$Q$347,MATCH($C9,'Energieverbruik in TJ Gemeente'!$B$4:$B$347,0),MATCH(F$2,'Energieverbruik in TJ Gemeente'!$B$4:$Q$4,0)) -> 399 | G9: =INDEX('Energieverbruik in TJ Gemeente'!$B$4:$Q$347,MATCH($C9,'Energieverbruik in TJ Gemeente'!$B$4:$B$347,0),MATCH(G$2,'Energieverbruik in TJ Gemeente'!$B$4:$Q$4,0)) -> 347 | H9: =INDEX('Energieverbruik in TJ Gemeente'!$B$4:$Q$347,MATCH($C9,'Energieverbruik in TJ Gemeente'!$B$4:$B$347,0),MATCH(H$2,'Energieverbruik in TJ Gemeente'!$B$4:$Q$4,0)) -> 280 | I9: =INDEX('Energieverbruik in TJ Gemeente'!$B$4:$Q$347,MATCH($C9,'Energieverbruik in TJ Gemeente'!$B$4:$B$347,0),MATCH(I$2,'Energieverbruik in TJ Gemeente'!$B$4:$Q$4,0)) -> 392 | J9: =INDEX('Energieverbruik in TJ Gemeente'!$B$4:$Q$347,MATCH($C9,'Energieverbruik in TJ Gemeente'!$B$4:$B$347,0),MATCH(J$2,'Energieverbruik in TJ Gemeente'!$B$4:$Q$4,0)) -> 372 | K9: =INDEX('Energieverbruik in TJ Gemeente'!$B$4:$Q$347,MATCH($C9,'Energieverbruik in TJ Gemeente'!$B$4:$B$347,0),MATCH(K$2,'Energieverbruik in TJ Gemeente'!$B$4:$Q$4,0)) -> 432 | ... R9: =INDEX('Energieverbruik in TJ Gemeente'!$B$4:$Q$347,MATCH($C9,'Energieverbruik in TJ Gemeente'!$B$4:$B$347,0),MATCH(R$2,'Energieverbruik in TJ Gemeente'!$B$4:$Q$4,0)) -> ? | S9: {=MAX(_xlfn._xlws.FILTER(D$1:H$1, D9:H9<>"?"))} -> 2023 | T9: {=MAX(_xlfn._xlws.FILTER(I$1:M$1, I9:M9<>"?"))} -> 2023 | U9: {=MAX(_xlfn._xlws.FILTER(F$1:J$1, F9:J9<>"?"))} -> 2023 | V9: =IFERROR(INDEX($D9:$H9,MATCH(S9,$D$1:$H$1,0)),0) -> 280 | W9: =IFERROR(INDEX($I9:$M9,MATCH(T9,$I$1:$M$1,0)),0) -> 335 | X9: =IFERROR(INDEX($N9:$R9,MATCH(U9,$N$1:$R$1,0)),0) -> ? | Y9: =SUM(V9:X9) -> 615 | Z9: =Y9/SUM($Y$3:$Y$344) -> 0.0010220871
A10: 0613 | B10: GM0613 | C10: Albrandswaard | D10: =INDEX('Energieverbruik in TJ Gemeente'!$B$4:$Q$347,MATCH($C10,'Energieverbruik in TJ Gemeente'!$B$4:$B$347,0),MATCH(D$2,'Energieverbruik in TJ Gemeente'!$B$4:$Q$4,0)) -> 533 | E10: =INDEX('Energieverbruik in TJ Gemeente'!$B$4:$Q$347,MATCH($C10,'Energieverbruik in TJ Gemeente'!$B$4:$B$347,0),MATCH(E$2,'Energieverbruik in TJ Gemeente'!$B$4:$Q$4,0)) -> 520 | F10: =INDEX('Energieverbruik in TJ Gemeente'!$B$4:$Q$347,MATCH($C10,'Energieverbruik in TJ Gemeente'!$B$4:$B$347,0),MATCH(F$2,'Energieverbruik in TJ Gemeente'!$B$4:$Q$4,0)) -> 527 | G10: =INDEX('Energieverbruik in TJ Gemeente'!$B$4:$Q$347,MATCH($C10,'Energieverbruik in TJ Gemeente'!$B$4:$B$347,0),MATCH(G$2,'Energieverbruik in TJ Gemeente'!$B$4:$Q$4,0)) -> ? | H10: =INDEX('Energieverbruik in TJ Gemeente'!$B$4:$Q$347,MATCH($C10,'Energieverbruik in TJ Gemeente'!$B$4:$B$347,0),MATCH(H$2,'Energieverbruik in TJ Gemeente'!$B$4:$Q$4,0)) -> ? | I10: =INDEX('Energieverbruik in TJ Gemeente'!$B$4:$Q$347,MATCH($C10,'Energieverbruik in TJ Gemeente'!$B$4:$B$347,0),MATCH(I$2,'Energieverbruik in TJ Gemeente'!$B$4:$Q$4,0)) -> 14 | J10: =INDEX('Energieverbruik in TJ Gemeente'!$B$4:$Q$347,MATCH($C10,'Energieverbruik in TJ Gemeente'!$B$4:$B$347,0),MATCH(J$2,'Energieverbruik in TJ Gemeente'!$B$4:$Q$4,0)) -> 11 | K10: =INDEX('Energieverbruik in TJ Gemeente'!$B$4:$Q$347,MATCH($C10,'Energieverbruik in TJ Gemeente'!$B$4:$B$347,0),MATCH(K$2,'Energieverbruik in TJ Gemeente'!$B$4:$Q$4,0)) -> 13 | ... R10: =INDEX('Energieverbruik in TJ Gemeente'!$B$4:$Q$347,MATCH($C10,'Energieverbruik in TJ Gemeente'!$B$4:$B$347,0),MATCH(R$2,'Energieverbruik in TJ Gemeente'!$B$4:$Q$4,0)) -> ? | S10: {=MAX(_xlfn._xlws.FILTER(D$1:H$1, D10:H10<>"?"))} -> 2021 | T10: {=MAX(_xlfn._xlws.FILTER(I$1:M$1, I10:M10<>"?"))} -> 2021 | U10: {=MAX(_xlfn._xlws.FILTER(F$1:J$1, F10:J10<>"?"))} -> 2021 | V10: =IFERROR(INDEX($D10:$H10,MATCH(S10,$D$1:$H$1,0)),0) -> 527 | W10: =IFERROR(INDEX($I10:$M10,MATCH(T10,$I$1:$M$1,0)),0) -> 13 | X10: =IFERROR(INDEX($N10:$R10,MATCH(U10,$N$1:$R$1,0)),0) -> ? | Y10: =SUM(V10:X10) -> 540 | Z10: =Y10/SUM($Y$3:$Y$344) -> 0.00089744229
A11: 0361 | B11: GM0361 | C11: Alkmaar | D11: =INDEX('Energieverbruik in TJ Gemeente'!$B$4:$Q$347,MATCH($C11,'Energieverbruik in TJ Gemeente'!$B$4:$B$347,0),MATCH(D$2,'Energieverbruik in TJ Gemeente'!$B$4:$Q$4,0)) -> 2636 | E11: =INDEX('Energieverbruik in TJ Gemeente'!$B$4:$Q$347,MATCH($C11,'Energieverbruik in TJ Gemeente'!$B$4:$B$347,0),MATCH(E$2,'Energieverbruik in TJ Gemeente'!$B$4:$Q$4,0)) -> 2560 | F11: =INDEX('Energieverbruik in TJ Gemeente'!$B$4:$Q$347,MATCH($C11,'Energieverbruik in TJ Gemeente'!$B$4:$B$347,0),MATCH(F$2,'Energieverbruik in TJ Gemeente'!$B$4:$Q$4,0)) -> 2579 | G11: =INDEX('Energieverbruik in TJ Gemeente'!$B$4:$Q$347,MATCH($C11,'Energieverbruik in TJ Gemeente'!$B$4:$B$347,0),MATCH(G$2,'Energieverbruik in TJ Gemeente'!$B$4:$Q$4,0)) -> 2286 | H11: =INDEX('Energieverbruik in TJ Gemeente'!$B$4:$Q$347,MATCH($C11,'Energieverbruik in TJ Gemeente'!$B$4:$B$347,0),MATCH(H$2,'Energieverbruik in TJ Gemeente'!$B$4:$Q$4,0)) -> 1958 | I11: =INDEX('Energieverbruik in TJ Gemeente'!$B$4:$Q$347,MATCH($C11,'Energieverbruik in TJ Gemeente'!$B$4:$B$347,0),MATCH(I$2,'Energieverbruik in TJ Gemeente'!$B$4:$Q$4,0)) -> ? | J11: =INDEX('Energieverbruik in TJ Gemeente'!$B$4:$Q$347,MATCH($C11,'Energieverbruik in TJ Gemeente'!$B$4:$B$347,0),MATCH(J$2,'Energieverbruik in TJ Gemeente'!$B$4:$Q$4,0)) -> ? | K11: =INDEX('Energieverbruik in TJ Gemeente'!$B$4:$Q$347,MATCH($C11,'Energieverbruik in TJ Gemeente'!$B$4:$B$347,0),MATCH(K$2,'Energieverbruik in TJ Gemeente'!$B$4:$Q$4,0)) -> ? | ... R11: =INDEX('Energieverbruik in TJ Gemeente'!$B$4:$Q$347,MATCH($C11,'Energieverbruik in TJ Gemeente'!$B$4:$B$347,0),MATCH(R$2,'Energieverbruik in TJ Gemeente'!$B$4:$Q$4,0)) -> 27 | S11: {=MAX(_xlfn._xlws.FILTER(D$1:H$1, D11:H11<>"?"))} -> 2023 | T11: {=MAX(_xlfn._xlws.FILTER(I$1:M$1, I11:M11<>"?"))} -> #VALUE! | U11: {=MAX(_xlfn._xlws.FILTER(F$1:J$1, F11:J11<>"?"))} -> 2023 | V11: =IFERROR(INDEX($D11:$H11,MATCH(S11,$D$1:$H$1,0)),0) -> 1958 | W11: =IFERROR(INDEX($I11:$M11,MATCH(T11,$I$1:$M$1,0)),0) -> 0 | X11: =IFERROR(INDEX($N11:$R11,MATCH(U11,$N$1:$R$1,0)),0) -> 27 | Y11: =SUM(V11:X11) -> 1985 | Z11: =Y11/SUM($Y$3:$Y$344) -> 0.0032989314
A12: 0141 | B12: GM0141 | C12: Almelo | D12: =INDEX('Energieverbruik in TJ Gemeente'!$B$4:$Q$347,MATCH($C12,'Energieverbruik in TJ Gemeente'!$B$4:$B$347,0),MATCH(D$2,'Energieverbruik in TJ Gemeente'!$B$4:$Q$4,0)) -> ? | E12: =INDEX('Energieverbruik in TJ Gemeente'!$B$4:$Q$347,MATCH($C12,'Energieverbruik in TJ Gemeente'!$B$4:$B$347,0),MATCH(E$2,'Energieverbruik in TJ Gemeente'!$B$4:$Q$4,0)) -> 1880 | F12: =INDEX('Energieverbruik in TJ Gemeente'!$B$4:$Q$347,MATCH($C12,'Energieverbruik in TJ Gemeente'!$B$4:$B$347,0),MATCH(F$2,'Energieverbruik in TJ Gemeente'!$B$4:$Q$4,0)) -> 2027 | G12: =INDEX('Energieverbruik in TJ Gemeente'!$B$4:$Q$347,MATCH($C12,'Energieverbruik in TJ Gemeente'!$B$4:$B$347,0),MATCH(G$2,'Energieverbruik in TJ Gemeente'!$B$4:$Q$4,0)) -> ? | H12: =INDEX('Energieverbruik in TJ Gemeente'!$B$4:$Q$347,MATCH($C12,'Energieverbruik in TJ Gemeente'!$B$4:$B$347,0),MATCH(H$2,'Energieverbruik in TJ Gemeente'!$B$4:$Q$4,0)) -> 1512 | I12: =INDEX('Energieverbruik in TJ Gemeente'!$B$4:$Q$347,MATCH($C12,'Energieverbruik in TJ Gemeente'!$B$4:$B$347,0),MATCH(I$2,'Energieverbruik in TJ Gemeente'!$B$4:$Q$4,0)) -> ? | J12: =INDEX('Energieverbruik in TJ Gemeente'!$B$4:$Q$347,MATCH($C12,'Energieverbruik in TJ Gemeente'!$B$4:$B$347,0),MATCH(J$2,'Energieverbruik in TJ Gemeente'!$B$4:$Q$4,0)) -> 484 | K12: =INDEX('Energieverbruik in TJ Gemeente'!$B$4:$Q$347,MATCH($C12,'Energieverbruik in TJ Gemeente'!$B$4:$B$347,0),MATCH(K$2,'Energieverbruik in TJ Gemeente'!$B$4:$Q$4,0)) -> 615 | ... R12: =INDEX('Energieverbruik in TJ Gemeente'!$B$4:$Q$347,MATCH($C12,'Energieverbruik in TJ Gemeente'!$B$4:$B$347,0),MATCH(R$2,'Energieverbruik in TJ Gemeente'!$B$4:$Q$4,0)) -> 11 | S12: {=MAX(_xlfn._xlws.FILTER(D$1:H$1, D12:H12<>"?"))} -> 2023 | T12: {=MAX(_xlfn._xlws.FILTER(I$1:M$1, I12:M12<>"?"))} -> 2023 | U12: {=MAX(_xlfn._xlws.FILTER(F$1:J$1, F12:J12<>"?"))} -> 2023 | V12: =IFERROR(INDEX($D12:$H12,MATCH(S12,$D$1:$H$1,0)),0) -> 1512 | W12: =IFERROR(INDEX($I12:$M12,MATCH(T12,$I$1:$M$1,0)),0) -> 499 | X12: =IFERROR(INDEX($N12:$R12,MATCH(U12,$N$1:$R$1,0)),0) -> 11 | Y12: =SUM(V12:X12) -> 2022 | Z12: =Y12/SUM($Y$3:$Y$344) -> 0.0033604228
A13: 0034 | B13: GM0034 | C13: Almere | D13: =INDEX('Energieverbruik in TJ Gemeente'!$B$4:$Q$347,MATCH($C13,'Energieverbruik in TJ Gemeente'!$B$4:$B$347,0),MATCH(D$2,'Energieverbruik in TJ Gemeente'!$B$4:$Q$4,0)) -> ? | E13: =INDEX('Energieverbruik in TJ Gemeente'!$B$4:$Q$347,MATCH($C13,'Energieverbruik in TJ Gemeente'!$B$4:$B$347,0),MATCH(E$2,'Energieverbruik in TJ Gemeente'!$B$4:$Q$4,0)) -> ? | F13: =INDEX('Energieverbruik in TJ Gemeente'!$B$4:$Q$347,MATCH($C13,'Energieverbruik in TJ Gemeente'!$B$4:$B$347,0),MATCH(F$2,'Energieverbruik in TJ Gemeente'!$B$4:$Q$4,0)) -> 1585 | G13: =INDEX('Energieverbruik in TJ Gemeente'!$B$4:$Q$347,MATCH($C13,'Energieverbruik in TJ Gemeente'!$B$4:$B$347,0),MATCH(G$2,'Energieverbruik in TJ Gemeente'!$B$4:$Q$4,0)) -> 1363 | H13: =INDEX('Energieverbruik in TJ Gemeente'!$B$4:$Q$347,MATCH($C13,'Energieverbruik in TJ Gemeente'!$B$4:$B$347,0),MATCH(H$2,'Energieverbruik in TJ Gemeente'!$B$4:$Q$4,0)) -> 1174 | I13: =INDEX('Energieverbruik in TJ Gemeente'!$B$4:$Q$347,MATCH($C13,'Energieverbruik in TJ Gemeente'!$B$4:$B$347,0),MATCH(I$2,'Energieverbruik in TJ Gemeente'!$B$4:$Q$4,0)) -> 198 | J13: =INDEX('Energieverbruik in TJ Gemeente'!$B$4:$Q$347,MATCH($C13,'Energieverbruik in TJ Gemeente'!$B$4:$B$347,0),MATCH(J$2,'Energieverbruik in TJ Gemeente'!$B$4:$Q$4,0)) -> 202 | K13: =INDEX('Energieverbruik in TJ Gemeente'!$B$4:$Q$347,MATCH($C13,'Energieverbruik in TJ Gemeente'!$B$4:$B$347,0),MATCH(K$2,'Energieverbruik in TJ Gemeente'!$B$4:$Q$4,0)) -> 247 | ... R13: =INDEX('Energieverbruik in TJ Gemeente'!$B$4:$Q$347,MATCH($C13,'Energieverbruik in TJ Gemeente'!$B$4:$B$347,0),MATCH(R$2,'Energieverbruik in TJ Gemeente'!$B$4:$Q$4,0)) -> 323 | S13: {=MAX(_xlfn._xlws.FILTER(D$1:H$1, D13:H13<>"?"))} -> 2023 | T13: {=MAX(_xlfn._xlws.FILTER(I$1:M$1, I13:M13<>"?"))} -> 2022 | U13: {=MAX(_xlfn._xlws.FILTER(F$1:J$1, F13:J13<>"?"))} -> 2023 | V13: =IFERROR(INDEX($D13:$H13,MATCH(S13,$D$1:$H$1,0)),0) -> 1174 | W13: =IFERROR(INDEX($I13:$M13,MATCH(T13,$I$1:$M$1,0)),0) -> 194 | X13: =IFERROR(INDEX($N13:$R13,MATCH(U13,$N$1:$R$1,0)),0) -> 323 | Y13: =SUM(V13:X13) -> 1691 | Z13: =Y13/SUM($Y$3:$Y$344) -> 0.0028103239
A14: 0484 | B14: GM0484 | C14: Alphen aan den Rijn | D14: =INDEX('Energieverbruik in TJ Gemeente'!$B$4:$Q$347,MATCH($C14,'Energieverbruik in TJ Gemeente'!$B$4:$B$347,0),MATCH(D$2,'Energieverbruik in TJ Gemeente'!$B$4:$Q$4,0)) -> ? | E14: =INDEX('Energieverbruik in TJ Gemeente'!$B$4:$Q$347,MATCH($C14,'Energieverbruik in TJ Gemeente'!$B$4:$B$347,0),MATCH(E$2,'Energieverbruik in TJ Gemeente'!$B$4:$Q$4,0)) -> 2352 | F14: =INDEX('Energieverbruik in TJ Gemeente'!$B$4:$Q$347,MATCH($C14,'Energieverbruik in TJ Gemeente'!$B$4:$B$347,0),MATCH(F$2,'Energieverbruik in TJ Gemeente'!$B$4:$Q$4,0)) -> 2381 | G14: =INDEX('Energieverbruik in TJ Gemeente'!$B$4:$Q$347,MATCH($C14,'Energieverbruik in TJ Gemeente'!$B$4:$B$347,0),MATCH(G$2,'Energieverbruik in TJ Gemeente'!$B$4:$Q$4,0)) -> 2068 | H14: =INDEX('Energieverbruik in TJ Gemeente'!$B$4:$Q$347,MATCH($C14,'Energieverbruik in TJ Gemeente'!$B$4:$B$347,0),MATCH(H$2,'Energieverbruik in TJ Gemeente'!$B$4:$Q$4,0)) -> 1782 | I14: =INDEX('Energieverbruik in TJ Gemeente'!$B$4:$Q$347,MATCH($C14,'Energieverbruik in TJ Gemeente'!$B$4:$B$347,0),MATCH(I$2,'Energieverbruik in TJ Gemeente'!$B$4:$Q$4,0)) -> ? | J14: =INDEX('Energieverbruik in TJ Gemeente'!$B$4:$Q$347,MATCH($C14,'Energieverbruik in TJ Gemeente'!$B$4:$B$347,0),MATCH(J$2,'Energieverbruik in TJ Gemeente'!$B$4:$Q$4,0)) -> 172 | K14: =INDEX('Energieverbruik in TJ Gemeente'!$B$4:$Q$347,MATCH($C14,'Energieverbruik in TJ Gemeente'!$B$4:$B$347,0),MATCH(K$2,'Energieverbruik in TJ Gemeente'!$B$4:$Q$4,0)) -> 189 | ... R14: =INDEX('Energieverbruik in TJ Gemeente'!$B$4:$Q$347,MATCH($C14,'Energieverbruik in TJ Gemeente'!$B$4:$B$347,0),MATCH(R$2,'Energieverbruik in TJ Gemeente'!$B$4:$Q$4,0)) -> 63 | S14: {=MAX(_xlfn._xlws.FILTER(D$1:H$1, D14:H14<>"?"))} -> 2023 | T14: {=MAX(_xlfn._xlws.FILTER(I$1:M$1, I14:M14<>"?"))} -> 2022 | U14: {=MAX(_xlfn._xlws.FILTER(F$1:J$1, F14:J14<>"?"))} -> 2023 | V14: =IFERROR(INDEX($D14:$H14,MATCH(S14,$D$1:$H$1,0)),0) -> 1782 | W14: =IFERROR(INDEX($I14:$M14,MATCH(T14,$I$1:$M$1,0)),0) -> 171 | X14: =IFERROR(INDEX($N14:$R14,MATCH(U14,$N$1:$R$1,0)),0) -> 63 | Y14: =SUM(V14:X14) -> 2016 | Z14: =Y14/SUM($Y$3:$Y$344) -> 0.0033504512
... A344: 0193 | B344: GM0193 | C344: Zwolle | D344: =INDEX('Energieverbruik in TJ Gemeente'!$B$4:$Q$347,MATCH($C344,'Energieverbruik in TJ Gemeente'!$B$4:$B$347,0),MATCH(D$2,'Energieverbruik in TJ Gemeente'!$B$4:$Q$4,0)) -> ? | E344: =INDEX('Energieverbruik in TJ Gemeente'!$B$4:$Q$347,MATCH($C344,'Energieverbruik in TJ Gemeente'!$B$4:$B$347,0),MATCH(E$2,'Energieverbruik in TJ Gemeente'!$B$4:$Q$4,0)) -> ? | F344: =INDEX('Energieverbruik in TJ Gemeente'!$B$4:$Q$347,MATCH($C344,'Energieverbruik in TJ Gemeente'!$B$4:$B$347,0),MATCH(F$2,'Energieverbruik in TJ Gemeente'!$B$4:$Q$4,0)) -> 3004 | G344: =INDEX('Energieverbruik in TJ Gemeente'!$B$4:$Q$347,MATCH($C344,'Energieverbruik in TJ Gemeente'!$B$4:$B$347,0),MATCH(G$2,'Energieverbruik in TJ Gemeente'!$B$4:$Q$4,0)) -> 2611 | H344: =INDEX('Energieverbruik in TJ Gemeente'!$B$4:$Q$347,MATCH($C344,'Energieverbruik in TJ Gemeente'!$B$4:$B$347,0),MATCH(H$2,'Energieverbruik in TJ Gemeente'!$B$4:$Q$4,0)) -> 2221 | I344: =INDEX('Energieverbruik in TJ Gemeente'!$B$4:$Q$347,MATCH($C344,'Energieverbruik in TJ Gemeente'!$B$4:$B$347,0),MATCH(I$2,'Energieverbruik in TJ Gemeente'!$B$4:$Q$4,0)) -> 700 | J344: =INDEX('Energieverbruik in TJ Gemeente'!$B$4:$Q$347,MATCH($C344,'Energieverbruik in TJ Gemeente'!$B$4:$B$347,0),MATCH(J$2,'Energieverbruik in TJ Gemeente'!$B$4:$Q$4,0)) -> 756 | K344: =INDEX('Energieverbruik in TJ Gemeente'!$B$4:$Q$347,MATCH($C344,'Energieverbruik in TJ Gemeente'!$B$4:$B$347,0),MATCH(K$2,'Energieverbruik in TJ Gemeente'!$B$4:$Q$4,0)) -> 744 | ... R344: =INDEX('Energieverbruik in TJ Gemeente'!$B$4:$Q$347,MATCH($C344,'Energieverbruik in TJ Gemeente'!$B$4:$B$347,0),MATCH(R$2,'Energieverbruik in TJ Gemeente'!$B$4:$Q$4,0)) -> 19 | S344: {=MAX(_xlfn._xlws.FILTER(D$1:H$1, D344:H344<>"?"))} -> 2023 | T344: {=MAX(_xlfn._xlws.FILTER(I$1:M$1, I344:M344<>"?"))} -> 2023 | U344: {=MAX(_xlfn._xlws.FILTER(F$1:J$1, F344:J344<>"?"))} -> 2023 | V344: =IFERROR(INDEX($D344:$H344,MATCH(S344,$D$1:$H$1,0)),0) -> 2221 | W344: =IFERROR(INDEX($I344:$M344,MATCH(T344,$I$1:$M$1,0)),0) -> 669 | X344: =IFERROR(INDEX($N344:$R344,MATCH(U344,$N$1:$R$1,0)),0) -> 19 | Y344: =SUM(V344:X344) -> 2909 | Z344: =Y344/SUM($Y$3:$Y$344) -> 0.0048345549

Sheet Energieverbruik in TJ Gemeente
A1: Energieverbruik (in TJ) - Gemeenten van Nederland
C2: 2019 | D2: 2019 | E2: 2019 | F2: 2020 | G2: 2020 | H2: 2020 | I2: 2021 | J2: 2021 | K2: 2021 | L2: 2022 | M2: 2022 | N2: 2022 | O2: 2023 | P2: 2023 | Q2: 2023
C3: Aardgasverbruik Gebouwde omgeving | D3: Totaal bekend aardgasverbruik Industrie, Energie, Afval en Water (excl. Energievoorziening, SBI D) | E3: Aardgas geleverd aan Landbouw, bosbouw en visserij (SBI A) | F3: Aardgasverbruik Gebouwde omgeving | G3: Totaal bekend aardgasverbruik Industrie, Energie, Afval en Water (excl. Energievoorziening, SBI D) | H3: Aardgas geleverd aan Landbouw, bosbouw en visserij (SBI A) | I3: Aardgasverbruik Gebouwde omgeving | J3: Totaal bekend aardgasverbruik Industrie, Energie, Afval en Water (excl. Energievoorziening, SBI D) | K3: Aardgas geleverd aan Landbouw, bosbouw en visserij (SBI A) | L3: Aardgasverbruik Gebouwde omgeving | M3: Totaal bekend aardgasverbruik Industrie, Energie, Afval en Water (excl. Energievoorziening, SBI D) | N3: Aardgas geleverd aan Landbouw, bosbouw en visserij (SBI A) | O3: Aardgasverbruik Gebouwde omgeving | P3: Totaal bekend aardgasverbruik Industrie, Energie, Afval en Water (excl. Energievoorziening, SBI D) | Q3: Aardgas geleverd aan Landbouw, bosbouw en visserij (SBI A)
C4: =C3&"_"&C2 -> Aardgasverbruik Gebouwde omgeving_2019 | D4: =D3&"_"&D2 -> Totaal bekend aardgasverbruik Industrie, Energie, Afval en Water (excl. Energievoorziening, SBI D)_2019 | E4: =E3&"_"&E2 -> Aardgas geleverd aan Landbouw, bosbouw en visserij (SBI A)_2019 | F4: =F3&"_"&F2 -> Aardgasverbruik Gebouwde omgeving_2020 | G4: =G3&"_"&G2 -> Totaal bekend aardgasverbruik Industrie, Energie, Afval en Water (excl. Energievoorziening, SBI D)_2020 | H4: =H3&"_"&H2 -> Aardgas geleverd aan Landbouw, bosbouw en visserij (SBI A)_2020 | I4: =I3&"_"&I2 -> Aardgasverbruik Gebouwde omgeving_2021 | J4: =J3&"_"&J2 -> Totaal bekend aardgasverbruik Industrie, Energie, Afval en Water (excl. Energievoorziening, SBI D)_2021 | ... Q4: =Q3&"_"&Q2 -> Aardgas geleverd aan Landbouw, bosbouw en visserij (SBI A)_2023
A5: Nederland | B5: Aa en Hunze | C5: 928 | D5: ? | E5: 38 | F5: ? | G5: ? | H5: 31 | I5: ? | J5: ? | K5: 33 | L5: ? | M5: ? | N5: 27 | O5: ? | P5: ? | Q5: 22
A6: Nederland | B6: Aalsmeer | C6: ? | D6: ? | E6: 710 | F6: ? | G6: ? | H6: 723 | I6: ? | J6: ? | K6: 758 | L6: 760 | M6: ? | N6: 482 | O6: ? | P6: ? | Q6: 514
A7: Nederland | B7: Aalten | C7: ? | D7: 69 | E7: 49 | F7: 662 | G7: 64 | H7: 28 | I7: 665 | J7: 70 | K7: 31 | L7: 594 | M7: 57 | N7: 25 | O7: 477 | P7: 44 | Q7: 19
A8: Nederland | B8: Achtkarspelen | C8: 725 | D8: 347 | E8: 23 | F8: 726 | G8: 319 | H8: 13 | I8: 723 | J8: 286 | K8: 14 | L8: 630 | M8: 282 | N8: 11 | O8: 508 | P8: 277 | Q8: 9
A9: Nederland | B9: Alblasserdam | C9: ? | D9: 392 | E9: ? | F9: 394 | G9: 372 | H9: ? | I9: 399 | J9: 432 | K9: ? | L9: 347 | M9: 348 | N9: ? | O9: 280 | P9: 335 | Q9: ?
A10: Nederland | B10: Albrandswaard | C10: 533 | D10: 14 | E10: 36 | F10: 520 | G10: 11 | H10: ? | I10: 527 | J10: 13 | K10: ? | L10: ? | M10: ? | N10: ? | O10: ? | P10: ? | Q10: ?
A11: Nederland | B11: Alkmaar | C11: 2636 | D11: ? | E11: 44 | F11: 2560 | G11: ? | H11: 39 | I11: 2579 | J11: ? | K11: 40 | L11: 2286 | M11: ? | N11: 30 | O11: 1958 | P11: ? | Q11: 27
A12: Nederland | B12: Almelo | C12: ? | D12: ? | E12: 17 | F12: 1880 | G12: 484 | H12: 13 | I12: 2027 | J12: 615 | K12: 16 | L12: ? | M12: ? | N12: 13 | O12: 1512 | P12: 499 | Q12: 11
A13: Nederland | B13: Almere | C13: ? | D13: 198 | E13: 386 | F13: ? | G13: 202 | H13: 386 | I13: 1585 | J13: 247 | K13: 419 | L13: 1363 | M13: 194 | N13: 304 | O13: 1174 | P13: ? | Q13: 323
A14: Nederland | B14: Alphen aan den Rijn | C14: ? | D14: ? | E14: 104 | F14: 2352 | G14: 172 | H14: 75 | I14: 2381 | J14: 189 | K14: 89 | L14: 2068 | M14: 171 | N14: 68 | O14: 1782 | P14: ? | Q14: 63
A15: Nederland | B15: Alphen-Chaam | C15: ? | D15: 13 | E15: 98 | F15: 278 | G15: 13 | H15: 84 | I15: 281 | J15: 15 | K15: 83 | L15: 246 | M15: 14 | N15: 55 | O15: 199 | P15: 11 | Q15: 45
A16: Nederland | B16: Altena | C16: 1251 | D16: 177 | E16: 184 | F16: 1230 | G16: 200 | H16: 184 | I16: 1228 | J16: 215 | K16: 255 | L16: 1059 | M16: 186 | N16: 171 | O16: 923 | P16: 134 | Q16: 187
A17: Nederland | B17: Ameland | C17: 239 | D17: 4 | E17: 4 | F17: 229 | G17: 4 | H17: 2 | I17: 242 | J17: 4 | K17: 2 | L17: 211 | M17: 3 | N17: 2 | O17: 185 | P17: 3 | Q17: 2
A18: Nederland | B18: Amersfoort | C18: 3390 | D18: 138 | E18: 5 | F18: 3316 | G18: 122 | H18: 5 | I18: 3378 | J18: 130 | K18: 5 | L18: 2932 | M18: 104 | N18: 4 | O18: 2532 | P18: 95 | Q18: 4
A19: Nederland | B19: Amstelveen | C19: 2048 | D19: 34 | E19: 359 | F19: 1951 | G19: 31 | H19: 337 | I19: 1959 | J19: 43 | K19: 326 | L19: 1752 | M19: ? | N19: 268 | O19: 1525 | P19: 29 | Q19: 300
A20: Nederland | B20: Amsterdam | C20: 19783 | D20: 4736 | E20: ? | F20: 18783 | G20: 4664 | H20: ? | I20: 19016 | J20: 4660 | K20: 43 | L20: 16764 | M20: ? | N20: ? | O20: ? | P20: 4299 | Q20: 9
A21: Nederland | B21: Apeldoorn | C21: 4696 | D21: 1219 | E21: 50 | F21: 4516 | G21: 1102 | H21: 35 | I21: 4549 | J21: 1213 | K21: 39 | L21: 4017 | M21: 1153 | N21: 30 | O21: 3347 | P21: 1099 | Q21: 24
A22: Nederland | B22: Arnhem | C22: 3976 | D22: 223 | E22: 18 | F22: 3786 | G22: 197 | H22: 17 | I22: 3918 | J22: 214 | K22: 19 | L22: 3441 | M22: 201 | N22: 16 | O22: ? | P22: 207 | Q22: 16
A23: Nederland | B23: Assen | C23: 1859 | D23: ? | E23: 11 | F23: 1837 | G23: ? | H23: 13 | I23: 1865 | J23: ? | K23: 13 | L23: 1644 | M23: ? | N23: 10 | O23: 1419 | P23: 55 | Q23: 9
A24: Nederland | B24: Asten | C24: 426 | D24: 56 | E24: 1653 | F24: 415 | G24: 56 | H24: 1786 | I24: 414 | J24: 59 | K24: 1550 | L24: 367 | M24: 55 | N24: 941 | O24: 303 | P24: 50 | Q24: 1082
A25: Nederland | B25: Baarle-Nassau | C25: 204 | D25: 86 | E25: 61 | F25: 196 | G25: 88 | H25: 53 | I25: 198 | J25: 90 | K25: 56 | L25: 175 | M25: 84 | N25: 41 | O25: 145 | P25: 87 | Q25: 38
A26: Nederland | B26: Baarn | C26: 762 | D26: 34 | E26: 3 | F26: 739 | G26: 33 | H26: 3 | I26: 756 | J26: 36 | K26: 3 | L26: 665 | M26: 33 | N26: 3 | O26: 569 | P26: 31 | Q26: 2
A27: Nederland | B27: Barendrecht | C27: 889 | D27: 20 | E27: 70 | F27: 866 | G27: ? | H27: ? | I27: 902 | J27: 22 | K27: 64 | L27: ? | M27: ? | N27: 25 | O27: ? | P27: ? | Q27: ?
A28: Nederland | B28: Barneveld | C28: 1520 | D28: 314 | E28: 98 | F28: 1444 | G28: 299 | H28: ? | I28: 1481 | J28: 332 | K28: 69 | L28: 1302 | M28: 317 | N28: ? | O28: 1089 | P28: 305 | Q28: 39
A29: Nederland | B29: Beek | C29: ? | D29: ? | E29: ? | F29: ? | G29: ? | H29: 3 | I29: ? | J29: 147 | K29: 2 | L29: 411 | M29: 145 | N29: 2 | O29: ? | P29: 137 | Q29: 1
A30: Nederland | B30: Beekdaelen | C30: 1029 | D30: 159 | E30: 9 | F30: 985 | G30: 143 | H30: 8 | I30: 988 | J30: 141 | K30: 9 | L30: 864 | M30: 130 | N30: 8 | O30: 687 | P30: 115 | Q30: 6
A31: Nederland | B31: Beesel | C31: 346 | D31: 117 | E31: 31 | F31: 338 | G31: 111 | H31: 41 | I31: 334 | J31: 119 | K31: 45 | L31: 296 | M31: 104 | N31: 41 | O31: 243 | P31: 76 | Q31: 48
A32: Nederland | B32: Berg en Dal | C32: ? | D32: ? | E32: 16 | F32: 948 | G32: ? | H32: 8 | I32: 929 | J32: ? | K32: 10 | L32: ? | M32: ? | N32: 9 | O32: ? | P32: ? | Q32: ?
A33: Nederland | B33: Bergeijk | C33: 572 | D33: 50 | E33: 27 | F33: 549 | G33: 47 | H33: 19 | I33: 553 | J33: 54 | K33: 18 | L33: 490 | M33: 46 | N33: 15 | O33: 417 | P33: 45 | Q33: 19
A34: Nederland | B34: Bergen (L.) | C34: 351 | D34: 94 | E34: 399 | F34: 342 | G34: 95 | H34: 461 | I34: 345 | J34: 99 | K34: 491 | L34: ? | M34: 95 | N34: 361 | O34: ? | P34: 90 | Q34: 429
A35: Nederland | B35: Bergen (NH.) | C35: ? | D35: ? | E35: 59 | F35: 974 | G35: 9 | H35: 50 | I35: 994 | J35: 10 | K35: 55 | L35: 865 | M35: 8 | N35: 38 | O35: 741 | P35: 7 | Q35: 36
A36: Nederland | B36: Bergen op Zoom | C36: 1535 | D36: 7413 | E36: ? | F36: 1567 | G36: 8335 | H36: 336 | I36: 1460 | J36: 7995 | K36: 360 | L36: 1369 | M36: 7498 | N36: 251 | O36: 1181 | P36: 7682 | Q36: 256
A37: Nederland | B37: Berkelland | C37: 1213 | D37: 840 | E37: 106 | F37: 1166 | G37: 724 | H37: 66 | I37: 1175 | J37: 715 | K37: 75 | L37: 1043 | M37: 848 | N37: 61 | O37: 851 | P37: 923 | Q37: 47
A38: Nederland | B38: Bernheze | C38: 754 | D38: 35 | E38: 81 | F38: 731 | G38: 31 | H38: 61 | I38: 742 | J38: 35 | K38: 64 | L38: 654 | M38: 31 | N38: 50 | O38: 533 | P38: 34 | Q38: 38
A39: Nederland | B39: Best | C39: ? | D39: 131 | E39: 14 | F39: ? | G39: 137 | H39: 9 | I39: 701 | J39: 141 | K39: 10 | L39: 615 | M39: 125 | N39: 8 | O39: 516 | P39: 121 | Q39: 6
A40: Nederland | B40: Beuningen | C40: 617 | D40: ? | E40: 31 | F40: 571 | G40: ? | H40: 25 | I40: 602 | J40: ? | K40: 27 | L40: 508 | M40: ? | N40: 10 | O40: 413 | P40: 210 | Q40: 7
...
