Workbook

Sheet Overview
A1: key | B1: value | C1: comment
A2: input_energy_chp_local_engine_ht_network_gas_production | B2: =ROUND(Calculations!B7,2) -> 10478.75 | C2: Derived from the SEAI energy balance (2019). See <a href="https://github.com/quintel/etdataset-public/tree/master/source_analyses/IE_ireland/2019/production/CHP.xlsx">this file</a> for more information.
A3: input_energy_chp_local_ht_wood_pellets_production | B3: =ROUND(Calculations!B11,2) -> 62.6 | C3: Derived from the SEAI energy balance (2019). See <a href="https://github.com/quintel/etdataset-public/tree/master/source_analyses/IE_ireland/2019/production/CHP.xlsx">this file</a> for more information.
A4: input_energy_chp_local_engine_ht_biogas_production | B4: =ROUND(Calculations!B15,2) -> 199.52 | C4: Derived from the SEAI energy balance (2019). See <a href="https://github.com/quintel/etdataset-public/tree/master/source_analyses/IE_ireland/2019/production/CHP.xlsx">this file</a> for more information.
A5: input_energy_chp_ultra_supercritical_ht_lignite_production | B5: 0 | C5: No lignite CHP present

Sheet Calculations
A1: Values are retrieved from the SEAI Energy Balance (2019) (https://www.seai.ie/data-and-insights/seai-statistics/key-publications/national-energy-balance) and are shown in corresponding tab. Since these values are shown in ktoe, in here they are multiplied by their corresponding electrical efficiency (retrieved from the current dataset) and are converted to TJ.
B3: value | C3: unit
A4: Gas plant (small-scale) with heat production (CHP) (ktoe) | B4: ='SEAI Energy Balance 2019'!AA11 -> 263.6609 | C4: ktoe
A5: Electrical efficiency | B5: 94.925237 | C5: %
A6: Conversion to TJ | B6: 41.868 | C6: TJ/ktoe
A7: Gas plant (small-scale) with heat production (CHP) (TJ) | B7: =B4*(B5/100)*B6 -> 10478.754 | C7: TJ
A9: Biomass CHP (ktoe) | B9: ='SEAI Energy Balance 2019'!AE11 -> 3.0508783 | C9: ktoe
A10: Electrical efficiency | B10: 49.011226 | C10: %
A11: Biomass CHP (TJ) | B11: =B9*(B10/100)*B6 -> 62.604084 | C11: TJ
A13: Biogas CHP (ktoe) | B13: ='SEAI Energy Balance 2019'!AH11 -> 8.6764691 | C13: ktoe
A14: Electrical efficiency | B14: 54.924766 | C14: %
A15: Biogas CHP (TJ) | B15: =B13*(B14/100)*B6 -> 199.52323 | C15: TJ

Sheet SEAI Energy Balance 2019
A1: 2019 Units = ktoe | B1: NACE (Rev 2) | C1: Coal | D1: Bituminous Coal | E1: Anthracite + Manufactured Ovoids | F1: Coke | G1: Lignite \ Brown Coal Briquettes | H1: Peat | I1: Milled Peat | J1: Sod Peat | K1: Briquettes | L1: Oil | M1: Crude | N1: Refinery Feedstocks | O1: Refinery Gas | P1: Gasoline | Q1: Kerosene | R1: Jet Kerosene | S1: Fueloil | T1: LPG | U1: Gasoil / Diesel /DERV | V1: Petroleum Coke | W1: Naphta | X1: Bitumen | Y1: White Spirit | Z1: Lubricants | AA1: Natural Gas | AB1: Renewables | AC1: Hydro | AD1: Wind | AE1: Biomass | AF1: Renewable Waste | AG1: Landfill Gas | AH1: Biogas | AI1: Biodiesel | AJ1: Bioethanol | AK1: Solar Photovoltaic | AL1: Solar Thermal | AM1: Ambient Heat | AN1: Non-Renewable Waste | AO1: Electricity | AP1: Heat | AQ1: TOTAL
A2: Indigenous Production | C2: =SUM(D2:G2) -> 0 | D2: 0 | H2: =SUM(I2:K2) -> 390.56916 | I2: 262.86516 | J2: 127.704 | L2: =SUM(M2:Z2) -> 0 | AA2: 2146.95 | AB2: =SUM(AC2:AM2) -> 1481.9779 | AC2: 76.246217 | AD2: 875.90522 | AE2: 237.30386 | AF2: 136.80851 | AG2: 31.773826 | AH2: 18.863526 | AI2: 41.448697 | AJ2: 4.2536495 | AK2: 2.9072166 | AL2: 13.693209 | AM2: 42.773986 | AN2: 145.31908 | AQ2: =C2+H2+L2+AA2+AB2+AN2+AO2+AP2 -> 4164.8162
A3: Imports | C3: =SUM(D3:G3) -> 260.65321 | D3: 191.54589 | E3: 59.028749 | G3: 10.078575 | H3: =SUM(I3:K3) -> 0 | L3: =SUM(M3:Z3) -> 9048.5517 | M3: 2653.5268 | N3: 157.337 | O3: 0 | P3: 542.64897 | Q3: 348.38683 | R3: 1570.8212 | S3: 110.02381 | T3: 156.63084 | U3: 3092.313 | V3: 161.03086 | W3: 0 | X3: 207.73662 | Y3: 2.1978004 | Z3: 45.897972 | AA3: 2424.3477 | AB3: =SUM(AC3:AM3) -> 184.89241 | AE3: 32.276634 | AI3: 127.46985 | AJ3: 25.145929 | AO3: 187.41006 | AQ3: =C3+H3+L3+AA3+AB3+AN3+AO3+AP3 -> 12105.855
A4: Exports | C4: =SUM(D4:G4) -> 8.1980003 | D4: 0 | E4: 7.9590085 | G4: 0.23899175 | H4: =SUM(I4:K4) -> 5.849372 | K4: 5.849372 | L4: =SUM(M4:Z4) -> 1567.563 | M4: 43.019194 | N4: 7.8404003 | P4: 432.94982 | Q4: 74.101066 | R4: 63.60888 | S4: 712.70293 | T4: 23.602785 | U4: 164.05673 | V4: 0.029787872 | W4: 28.749404 | X4: 9.4628384 | Y4: 0.019112571 | Z4: 7.4200742 | AA4: 0 | AB4: =SUM(AC4:AM4) -> 6.702355 | AE4: 0 | AI4: 6.702355 | AJ4: 0 | AO4: 131.98956 | AQ4: =C4+H4+L4+AA4+AB4+AN4+AO4+AP4 -> 1720.3023
A5: Mar. Bunkers | C5: =SUM(D5:G5) -> 0 | H5: =SUM(I5:K5) -> 0 | L5: =SUM(M5:Z5) -> 142.20252 | S5: 10.240728 | U5: 131.96179 | AB5: =SUM(AC5:AM5) -> 0 | AQ5: =C5+H5+L5+AA5+AB5+AN5+AO5+AP5 -> 142.20252
A6: Stock Change | C6: =SUM(D6:G6) -> 124.36366 | D6: 123.51081 | E6: 1.0966176 | G6: -0.24376922 | H6: =SUM(I6:K6) -> 244.39862 | I6: 237.15181 | J6: 0 | K6: 7.2468155 | L6: =SUM(M6:Z6) -> 78.387631 | M6: -22.361378 | N6: 6.6791467 | P6: 135.33215 | Q6: 2.5411915 | R6: -80.382526 | S6: -0.94198822 | T6: 3.4576857 | U6: 39.480529 | V6: -2.7286637 | W6: -2.6885197 | X6: 0 | Y6: 0 | Z6: 0 | AA6: 0 | AB6: =SUM(AC6:AM6) -> -4.9037208 | AE6: -2.9300421 | AI6: 0.51408602 | AJ6: -2.4877648 | AQ6: =C6+H6+L6+AA6+AB6+AN6+AO6+AP6 -> 442.2462
A7: Primary Energy Supply (incl non-energy) | C7: =C2+C3-C4-C5+C6 -> 376.81887 | D7: =D2+D3-D4-D5+D6 -> 315.0567 | E7: =E2+E3-E4-E5+E6 -> 52.166358 | F7: =F2+F3-F4-F5+F6 -> 0 | G7: =G2+G3-G4-G5+G6 -> 9.5958139 | H7: =H2+H3-H4-H5+H6 -> 629.11841 | I7: =I2+I3-I4-I5+I6 -> 500.01697 | J7: =J2+J3-J4-J5+J6 -> 127.704 | ... AP7: =AP2+AP3-AP4-AP5+AP6 -> 0 | AQ7: =C7+H7+L7+AA7+AB7+AN7+AO7+AP7 -> 14850.413
A8: Primary Energy Requirement (excl. non-energy) | C8: =C7-C27 -> 376.81887 | D8: =D7-D27 -> 315.0567 | E8: =E7-E27 -> 52.166358 | F8: =F7-F27 -> 0 | G8: =G7-G27 -> 9.5958139 | H8: =H7-H27 -> 629.11841 | I8: =I7-I27 -> 500.01697 | J8: =J7-J27 -> 127.704 | ... AP8: =AP7-AP27 -> 0 | AQ8: =C8+H8+L8+AA8+AB8+AN8+AO8+AP8 -> 14611.482
A9: Transformation Input | C9: =SUM(C10:C14) -> 147.86636 | D9: =SUM(D10:D14) -> 147.86636 | E9: =SUM(E10:E14) -> 0 | F9: =SUM(F10:F14) -> 0 | G9: =SUM(G10:G14) -> 0 | H9: =SUM(H10:H14) -> 491.61137 | I9: =SUM(I10:I14) -> 491.61137 | J9: =SUM(J10:J14) -> 0 | ... AP9: =SUM(AP10:AP14) -> 0 | AQ9: =C9+H9+L9+AA9+AB9+AN9+AO9+AP9 -> 6486.4295
A10: Public Thermal Power Plants (Input) | C10: =SUM(D10:G10) -> 147.86636 | D10: 147.86636 | H10: =SUM(I10:K10) -> 429.59646 | I10: 429.59646 | J10: 0 | L10: =SUM(M10:Z10) -> 77.823018 | S10: 65.449798 | U10: 12.373221 | AA10: 2262.9232 | AB10: =SUM(AC10:AM10) -> 202.1097 | AE10: 73.93024 | AF10: 96.405637 | AG10: 31.773826 | AI10: 0 | AN10: 88.646478 | AQ10: =C10+H10+L10+AA10+AB10+AN10+AO10+AP10 -> 3208.9652
A11: Combined Heat and Power Plants (Input) | C11: =SUM(D11:G11) -> 0 | D11: 0 | H11: =SUM(I11:K11) -> 4.7597803 | I11: 4.7597803 | L11: =SUM(M11:Z11) -> 0.63864537 | O11: 0 | S11: 0 | T11: 0.63864537 | U11: 0 | AA11: 263.6609 | AB11: =SUM(AC11:AM11) -> 11.727347 | AE11: 3.0508783 | AH11: 8.6764691 | AQ11: =C11+H11+L11+AA11+AB11+AN11+AO11+AP11 -> 280.78668
A12: Pumped & Battery Storage (Input) | AO12: 41.127758 | AQ12: =C12+H12+L12+AA12+AB12+AN12+AO12+AP12 -> 41.127758
A13: Briquetting Plants (Input) | C13: =SUM(D13:G13) -> 0 | H13: =SUM(I13:K13) -> 57.255125 | I13: 57.255125 | L13: =SUM(M13:Z13) -> 0 | AB13: =SUM(AC13:AM13) -> 0 | AQ13: =C13+H13+L13+AA13+AB13+AN13+AO13+AP13 -> 57.255125
A14: Oil Refineries & other energy sector (Input) | C14: =SUM(D14:G14) -> 0 | H14: =SUM(I14:K14) -> 0 | L14: =SUM(M14:Z14) -> 2842.7662 | M14: 2588.1463 | N14: 254.61996 | AA14: 43.82646 | AB14: =SUM(AC14:AM14) -> 0 | AO14: 11.701978 | AQ14: =C14+H14+L14+AA14+AB14+AN14+AO14+AP14 -> 2898.2947
A15: Transformation Output | C15: =SUM(C16:C20) -> 0 | D15: =SUM(D16:D20) -> 0 | E15: =SUM(E16:E20) -> 0 | F15: =SUM(F16:F20) -> 0 | G15: =SUM(G16:G20) -> 0 | H15: =SUM(H16:H20) -> 54.392368 | I15: =SUM(I16:I20) -> 0 | J15: =SUM(J16:J20) -> 0 | ... AP15: =SUM(AP16:AP20) -> 0 | AQ15: =C15+H15+L15+AA15+AB15+AN15+AO15+AP15 -> 4632.5842
A16: Public Thermal Power Plants (Output) | C16: =SUM(D16:G16) -> 0 | H16: =SUM(I16:K16) -> 0 | L16: =SUM(M16:Z16) -> 0 | AB16: =SUM(AC16:AL16) -> 0 | AO16: 1520.7803 | AQ16: =C16+H16+L16+AA16+AO16+AP16 -> 1520.7803
A17: Combined Heat and Power Plants (Output) | C17: =SUM(D17:G17) -> 0 | H17: =SUM(I17:K17) -> 0 | L17: =SUM(M17:Z17) -> 0 | AB17: =SUM(AC17:AL17) -> 0 | AO17: 179.15896 | AQ17: =C17+H17+L17+AA17+AO17+AP17 -> 179.15896
A18: Pumped & Battery Storage (Output) | AO18: 21.093617 | AQ18: =C18+H18+L18+AA18+AB18+AN18+AO18+AP18 -> 21.093617
A19: Briquetting Plants (Output) | H19: =SUM(I19:K19) -> 54.392368 | K19: 54.392368 | L19: =SUM(M19:Z19) -> 0 | AB19: =SUM(AC19:AL19) -> 0 | AQ19: =C19+H19+L19+AA19+AB19+AN19+AO19+AP19 -> 54.392368
A20: Oil Refineries & other energy sector (Output) | H20: =SUM(I20:K20) -> 0 | L20: =SUM(M20:Z20) -> 2857.159 | O20: 75.391323 | P20: 552.13663 | Q20: 323.67831 | R20: 0 | S20: 713.77718 | T20: 50.547599 | U20: 1097.9679 | W20: 43.660045 | AB20: =SUM(AC20:AL20) -> 0 | AQ20: =C20+H20+L20+AA20+AB20+AN20+AO20+AP20 -> 2857.159
A21: Exchanges and transfers | C21: =SUM(C22:C24) -> 17.334134 | D21: =SUM(D22:D24) -> -16.109347 | E21: =SUM(E22:E24) -> 33.443481 | F21: =SUM(F22:F24) -> 0 | G21: =SUM(G22:G24) -> 0 | H21: =SUM(I21:K21) -> 0 | I21: =SUM(I22:I24) -> 0 | J21: =SUM(J22:J24) -> 0 | K21: =SUM(K22:K24) -> 0 | L21: =SUM(M21:Z21) -> -50.752198 | M21: =SUM(M22:M24) -> 0 | N21: =SUM(N22:N24) -> 97.460756 | O21: =SUM(O22:O24) -> 0 | P21: =SUM(P22:P24) -> -49.15199 | Q21: =SUM(Q22:Q24) -> 307.59405 | R21: =SUM(R22:R24) -> -306.92385 | S21: =SUM(S22:S24) -> -0.043509951 | T21: =SUM(T22:T24) -> 0 | ... AQ21: =SUM(AQ22:AQ24) -> -33.418064
A22: Electricity Exchange & Transfers | AB22: =SUM(AC22:AM22) -> -955.05865 | AC22: =-AC2 -> -76.246217 | AD22: =-AD2 -> -875.90522 | AK22: -2.9072166 | AO22: =-(C22+H22+L22+AA22+AB22) -> 955.05865 | AQ22: =C22+H22+L22+AA22+AB22+AN22+AO22+AP22 -> 0
A23: Heat Exchange & Transfers | AQ23: =C23+H23+L23+AA23+AB23+AN23+AO23+AP23 -> 0
A24: Other Exchange & Transfers | C24: =SUM(D24:G24) -> 17.334134 | D24: -16.109347 | E24: =-D24-V24 -> 33.443481 | G24: 0 | L24: =SUM(N24:Z24) -> -50.752198 | N24: 97.460756 | P24: -49.15199 | Q24: 307.59405 | R24: -306.92385 | S24: -0.043509951 | U24: -70.130393 | V24: -17.334134 | W24: -12.22313 | AA24: =-AH24 -> 0 | AB24: =SUM(AC24:AM24) -> 0 | AH24: 0 | AQ24: =C24+H24+L24+AA24+AB24+AN24+AO24+AP24 -> -33.418064
A25: Own Use and Distribution Losses | C25: =SUM(D25:G25) -> 0 | H25: =SUM(I25:K25) -> 8.4053953 | I25: 8.4053953 | L25: =SUM(O25:Z25) -> 80.472443 | O25: 78.350008 | S25: 0 | T25: 0.0041693256 | U25: 2.1182661 | AA25: 65.873591 | AB25: =SUM(AC25:AI25) -> 0 | AO25: 268.73104 | AQ25: =C25+H25+L25+AA25+AB25+AN25+AO25+AP25 -> 423.48246
A26: Available Final Energy Consumption | C26: =C7-C9+C15+C21-C25 -> 246.28665 | D26: =D7-D9+D15+D21-D25 -> 151.08099 | E26: =E7-E9+E15+E21-E25 -> 85.609838 | F26: =F7-F9+F15+F21-F25 -> 0 | G26: =G7-G9+G15+G21-G25 -> 9.5958139 | H26: =H7-H9+H15+H21-H25 -> 183.49401 | I26: =I7-I9+I15+I21-I25 -> 0.00020251834 | J26: =J7-J9+J15+J21-J25 -> 127.704 | ... AP26: =AP7-AP9+AP15+AP21-AP25 -> 0 | AQ26: =C26+H26+L26+AA26+AB26+AN26+AO26+AP26 -> 12539.667
A27: Non-Energy Consumption | C27: =C28 -> 0 | D27: =D28 -> 0 | E27: =E28 -> 0 | F27: =F28 -> 0 | G27: =G28 -> 0 | H27: =H28 -> 0 | I27: =I28 -> 0 | J27: =J28 -> 0 | ... V27: =V28 -> 0 | X27: =X28 -> 198.27378 | Y27: =Y28 -> 2.1786878 | Z27: =Z28 -> 38.477898 | AA27: =AA28 -> 0 | AB27: =AB28 -> 0 | AC27: =AC28 -> 0 | AD27: =AD28 -> 0 | AE27: =AE28 -> 0 | ... AQ27: =AQ28 -> 238.93036
A28: Final non-Energy Consumption (Feedstocks) | C28: =SUM(D28:G28) -> 0 | H28: =SUM(I28:K28) -> 0 | L28: =SUM(M28:Z28) -> 238.93036 | X28: =X26 -> 198.27378 | Y28: =Y26 -> 2.1786878 | Z28: =Z26 -> 38.477898 | AA28: 0 | AB28: =SUM(AC28:AI28) -> 0 | AQ28: =C28+H28+L28+AA28+AB28+AN28+AO28+AP28 -> 238.93036
A29: Total Final Energy Consumption | C29: =C30+C45+C56+C58+C65+C70+C71 -> 255.34477 | D29: =D30+D45+D56+D58+D65+D70+D71 -> 158.01647 | E29: =E30+E45+E56+E58+E65+E70+E71 -> 88.256827 | F29: =F30+F45+F56+F58+F65+F70+F71 -> 0 | G29: =G30+G45+G56+G58+G65+G70+G71 -> 9.0714766 | H29: =H30+H45+H56+H58+H65+H70+H71 -> 183.4932 | I29: =I30+I45+I56+I58+I65+I70+I71 -> 0 | J29: =J30+J45+J56+J58+J65+J70+J71 -> 127.704 | ... AQ29: =AQ30+AQ45+AQ56+AQ58+AQ65+AQ70+AQ71 -> 12414.626
A30: Industry* | C30: =SUM(C31:C44) -> 68.839406 | D30: 68.839406 | E30: 0 | H30: =SUM(H31:H44) -> 0 | I30: =SUM(I31:I44) -> 0 | J30: =SUM(J31:J44) -> 0 | K30: =SUM(K31:K44) -> 0 | L30: =SUM(L31:L44) -> 394.75217 | M30: =SUM(M31:M44) -> 0 | N30: =SUM(N31:N44) -> 0 | O30: =SUM(O31:O44) -> 0 | P30: =SUM(P31:P44) -> 0 | Q30: 6.3323883 | R30: =SUM(R31:R44) -> 0 | S30: 29.485886 | T30: 62.661195 | U30: 159.29424 | V30: 136.97845 | W30: =SUM(W31:W44) -> 0 | X30: =SUM(X31:X44) -> 0 | Y30: =SUM(Y31:Y44) -> 0 | Z30: =SUM(Z31:Z44) -> 0 | AA30: 997.43668 | AB30: =SUM(AB31:AB44) -> 191.59737 | AC30: =SUM(AC31:AC44) -> 0 | AD30: =SUM(AD31:AD44) -> 0 | AE30: =SUM(AE31:AE44) -> 147.31898 | AF30: =SUM(AF31:AF44) -> 40.402869 | AG30: =SUM(AG31:AG44) -> 0 | AH30: =SUM(AH31:AH44) -> 3.8755161 | AI30: =SUM(AI31:AI44) -> 0 | ... AN30: =SUM(AN31:AN44) -> 56.672602 | AO30: 563.96409 | AP30: =SUM(AP31:AP44) -> 0 | AQ30: =C30+H30+L30+AA30+AB30+AN30+AO30+AP30 -> 2273.2623
A31: Non-Energy Mining | B31: 05-09 | C31: =SUM(D31:G31) -> 0 | D31: 0 | H31: =SUM(I31:K31) -> 0 | L31: =SUM(M31:Z31) -> 16.584169 | Q31: 0.175 | S31: 0 | T31: 1.5261686 | U31: 14.883 | V31: 0 | AA31: 13.039794 | AB31: =SUM(AC31:AM31) -> 0.033998405 | AE31: 0.033998405 | AI31: 0 | AO31: 21.201558 | AQ31: =C31+H31+L31+AA31+AB31+AN31+AO31+AP31 -> 50.859519
A32: Food & beverages | B32: 10-11 | C32: =SUM(D32:G32) -> 0 | D32: 0 | H32: =SUM(I32:K32) -> 0 | I32: 0 | L32: =SUM(M32:Z32) -> 67.123884 | Q32: 1.508 | S32: 19.314129 | T32: 35.993755 | U32: 10.308 | V32: 0 | AA32: 298.05055 | AB32: =SUM(AC32:AM32) -> 33.904713 | AE32: 30.029197 | AH32: 3.8755161 | AI32: 0 | AO32: 93.158914 | AQ32: =C32+H32+L32+AA32+AB32+AN32+AO32+AP32 -> 492.23806
A33: Textiles and textile products | B33: 13-14 | C33: =SUM(D33:G33) -> 0 | D33: 0 | H33: =SUM(I33:K33) -> 0 | L33: =SUM(M33:Z33) -> 5.6408727 | Q33: 0.009 | S33: 0 | T33: 5.4718727 | U33: 0.16 | V33: 0 | AA33: 2.4502481 | AB33: =SUM(AC33:AM33) -> 0.12189672 | AE33: 0.12189672 | AI33: 0 | AO33: 2.305974 | AQ33: =C33+H33+L33+AA33+AB33+AN33+AO33+AP33 -> 10.518992
A34: Wood and wood products | B34: 16 | C34: =SUM(D34:G34) -> 0 | D34: 0 | H34: =SUM(I34:K34) -> 0 | L34: =SUM(M34:Z34) -> 2.190686 | Q34: 0.081 | S34: 0 | T34: 0.513686 | U34: 1.596 | V34: 0 | AA34: 5.923239 | AB34: =SUM(AC34:AM34) -> 115.59832 | AE34: 115.59832 | AI34: 0 | AO34: 23.289221 | AQ34: =C34+H34+L34+AA34+AB34+AN34+AO34+AP34 -> 147.00147
A35: Pulp, paper, publishing and printing | B35: 17-18 | C35: =SUM(D35:G35) -> 0 | D35: 0 | H35: =SUM(I35:K35) -> 0 | L35: =SUM(M35:Z35) -> 0.70068096 | Q35: 0.035 | S35: 0 | T35: 0.37968096 | U35: 0.286 | V35: 0 | AA35: 7.0445508 | AB35: =SUM(AC35:AM35) -> 0.0084581398 | AE35: 0.0084581398 | AI35: 0 | AO35: 6.5137928 | AQ35: =C35+H35+L35+AA35+AB35+AN35+AO35+AP35 -> 14.267483
A36: Chemicals & man-made fibres | B36: 20-21 | C36: =SUM(D36:G36) -> 0 | D36: 0 | H36: =SUM(I36:K36) -> 0 | L36: =SUM(M36:Z36) -> 19.46618 | Q36: 0.267 | S36: 3.406319 | T36: 3.108917 | U36: 3.588 | V36: 9.0959443 | AA36: 121.23101 | AB36: =SUM(AC36:AM36) -> 0.069257239 | AE36: 0.069257239 | AI36: 0 | AO36: 86.273484 | AQ36: =C36+H36+L36+AA36+AB36+AN36+AO36+AP36 -> 227.03993
A37: Rubber and plastic products | B37: 22 | C37: =SUM(D37:G37) -> 0 | D37: 0 | H37: =SUM(I37:K37) -> 0 | L37: =SUM(M37:Z37) -> 3.5619898 | Q37: 0.64 | S37: 0 | T37: 2.0889898 | U37: 0.833 | V37: 0 | AA37: 10.913217 | AB37: =SUM(AC37:AM37) -> 0.046536353 | AE37: 0.046536353 | AI37: 0 | AO37: 20.928415 | AQ37: =C37+H37+L37+AA37+AB37+AN37+AO37+AP37 -> 35.450158
A38: Other non-metallic mineral products | B38: 23 | C38: =SUM(D38:G38) -> 68.839406 | D38: 68.839406 | H38: =SUM(I38:K38) -> 0 | L38: =SUM(M38:Z38) -> 157.30446 | Q38: 0.926 | S38: 0 | T38: 2.3629556 | U38: 26.133 | V38: 127.88251 | AA38: 35.713503 | AB38: =SUM(AC38:AM38) -> 41.564346 | AE38: 1.1614769 | AF38: 40.402869 | AI38: 0 | AN38: 56.672602 | AO38: 65.698429 | AQ38: =C38+H38+L38+AA38+AB38+AN38+AO38+AP38 -> 425.79275
A39: Basic metals and fabricated metal products | B39: 24-25 | C39: =SUM(D39:G39) -> 0 | D39: 0 | H39: =SUM(I39:K39) -> 0 | L39: =SUM(M39:Z39) -> 6.5266396 | Q39: 0.391 | S39: 3.2590364 | T39: 1.2656032 | U39: 1.611 | V39: 0 | AA39: 419.59853 | AB39: =SUM(AC39:AM39) -> 0.028193799 | AE39: 0.028193799 | AI39: 0 | AO39: 60.368593 | AQ39: =C39+H39+L39+AA39+AB39+AN39+AO39+AP39 -> 486.52195
A40: Machinery and equipment n.e.c. | B40: 28 | C40: =SUM(D40:G40) -> 0 | D40: 0 | H40: =SUM(I40:K40) -> 0 | L40: =SUM(M40:Z40) -> 3.2800902 | Q40: 0.27 | S40: 0 | T40: 1.8060902 | U40: 1.204 | V40: 0 | AA40: 16.314249 | AB40: =SUM(AC40:AM40) -> 0.04023421 | AE40: 0.04023421 | AI40: 0 | AO40: 17.966492 | AQ40: =C40+H40+L40+AA40+AB40+AN40+AO40+AP40 -> 37.601065
...
