Workbook

Sheet Overview
A1: key | B1: value | C1: comment
A2: input_energy_power_ultra_supercritical_coal_production | B2: =ROUND(Calculations!B7,2) -> 2847.8 | C2: Derived from the Eurostat energy balance (2019). Ireland has a single coal-fired power plant (Moneypoint), a pulverised coal plant; all coal demand is therefore attributed to pulverised coal. See <a href="https://github.com/quintel/etdataset-public/tree/master/source_analyses/IE_ireland/2019/production/electricity.xlsx">this file</a> for more information.
A3: input_energy_power_supercritical_coal_production | B3: =Calculations!B9 -> 0 | C3: Derived from the Eurostat energy balance (2019). Ireland has a single coal-fired power plant (Moneypoint), a pulverised coal plant; all coal demand is therefore attributed to pulverised coal. See <a href="https://github.com/quintel/etdataset-public/tree/master/source_analyses/IE_ireland/2019/production/electricity.xlsx">this file</a> for more information.
A4: input_energy_power_ultra_supercritical_lignite_production | B4: =Calculations!B10 -> 0 | C4: Derived from the Eurostat energy balance (2019). Ireland has a single coal-fired power plant (Moneypoint), a pulverised coal plant; all coal demand is therefore attributed to pulverised coal. See <a href="https://github.com/quintel/etdataset-public/tree/master/source_analyses/IE_ireland/2019/production/electricity.xlsx">this file</a> for more information.
A5: input_energy_power_turbine_network_gas_production | B5: =Calculations!B40 -> 5724.8306 | C5: Derived from the Eurostat Energy balance (2019). Gas demand for fossil electricity plants is distributed over gas turbines and CCGT plants proportionally to their installed capacities (source: EirGrid & SONI, All Island Generation Capacity Statement Data Workbook, 2022). See <a href="https://github.com/quintel/etdataset-public/tree/master/source_analyses/IE_ireland/2019/production/electricity.xlsx">this file</a> for more information.
A6: input_energy_power_combined_cycle_network_gas_production | B6: =ROUND(Calculations!B39,2) -> 40988.93 | C6: Derived from the Eurostat Energy balance (2019). Gas demand for fossil electricity plants is distributed over gas turbines and CCGT plants proportionally to their installed capacities (source: EirGrid & SONI, All Island Generation Capacity Statement Data Workbook, 2022). See <a href="https://github.com/quintel/etdataset-public/tree/master/source_analyses/IE_ireland/2019/production/electricity.xlsx">this file</a> for more information.
A7: input_energy_power_wind_turbine_inland_production | B7: =Calculations!B52 -> 34632 | C7: EirGrid & SONI, All Island Generation Capacity Statement Data Workbook, 2022. See <a href="https://github.com/quintel/etdataset-public/tree/master/source_analyses/IE_ireland/2019/production/electricity.xlsx">this file</a> for more information.
A8: input_energy_power_engine_diesel_production | B8: =ROUND(Calculations!B47,2) -> 196.99 | C8: The data orginates from the Eurostat <a href='https://ec.europa.eu/eurostat/databrowser/view/nrg_bal_c__custom_22103730/default/table'>Energy balance</a>, 2019, multiplied by its corresponding efficiency.
A9: energy_power_wind_turbine_inland_full_load_hours | B9: =ROUND(Calculations!B53,2) -> 2313.11 | C9: EirGrid & SONI, All Island Generation Capacity Statement Data Workbook, 2022. See <a href="https://github.com/quintel/etdataset-public/tree/master/source_analyses/IE_ireland/2019/production/electricity.xlsx">this file</a> for more information.

Sheet Calculations
A1: Coal plants
A2: Ireland only has a single coal-fired power plant (Moneypoint), which is a pulvarised coal plant; all coal demand is therefore attributed to this technology. See the tab '2022-2031 GCS data-workbook' for mentioning Moneypont as the only coal plant in Ireland. The authors of this workbook are Eirgrid and SONI (https://cms.eirgrid.ie/2022-2031-all-island-generation-capacity-statement-data-workbook).
B4: value | C4: unit | D4: source
A5: Transformation input | B5: 6190.864 | C5: TJ | D5: https://ec.europa.eu/eurostat/databrowser/view/nrg_bal_c__custom_22102229/default/table
A6: Efficiency | B6: 46 | C6: % | D6: Value retrieved from Ireland dataset update 2024
A7: Pulvarized coal demand | B7: =B5*B6/100 -> 2847.7974 | C7: TJ
A9: Coal conventional demand | B9: 0 | C9: TJ
A10: Coal lignite demand | B10: 0 | C10: TJ
A13: Gas plants
A14: The data workbook shows which power plants were present in 2022 (with corresponding capacitites in MW), split into gas turbine and CCGT plants. The Eurostat Energy Balance, however, only reports combined electricity demand (2019) for gas plants, without distinguishing between the two types. To split this 2019 demand, we allocate it proportionally to each plant type's installed capacity in 2022.
A16: 2022 (workbook) - installed capacity in MW | B16: value | C16: unit | D16: source | E16: remark
A17: CCGT plant | B17: =SUM('GCS data-workbook (gas)'!G29:G32,'GCS data-workbook (gas)'!G35,'GCS data-workbook (gas)'!G42,'GCS data-workbook (gas)'!G43:G44,'GCS data-workbook (gas)'!G51:G52,'GCS data-workbook (gas)'!G64,'GCS data-workbook (gas)'!G65) -> 3650 | C17: MW | D17: Eirgrid and SONI Data-workbook | E17: As the workbook distinguishes between more plant categories than simply gas turbines and CCGT, including plants that do not use CCGT technology, we examied the individual plants and categorized them accordingly ourselves.
A18: Gas turbine plant | B18: =SUM('GCS data-workbook (gas)'!G53:G54,'GCS data-workbook (gas)'!G55:G56,'GCS data-workbook (gas)'!G61:G62) -> 370 | C18: MW | D18: Eirgrid and SONI Data-workbook | E18: As the workbook distinguishes between more plant categories than simply gas turbines and CCGT, including plants that do not use CCGT technology, we examied the individual plants and categorized them accordingly ourselves.
A20: conversion to TJ
A21: Full load hours CCGT (ETM) | B21: 3742.0988 | C21: h | D21: Value retrieved from Ireland dataset update 2022
A22: Full load hours gas turbine plant (ETM) | B22: 8000 | C22: h | D22: Value retrieved from Ireland dataset update 2022
A24: 2022 (workbook) - installed capacity in TJ
A25: CCGT plant | B25: =B17*B21*0.0036 -> 49171.179 | C25: TJ
A26: Gas turbine plant | B26: =B18*B22*0.0036 -> 10656 | C26: TJ
A28: Share CCGT | B28: =B25/SUM(B25:B26) *100 -> 82.188697 | C28: %
A29: Share gas turbine | B29: =B26/SUM(B25:B26) *100 -> 17.811303 | C29: %
A31: 2019 - Eurostat EB electricity demand gas plants | B31: 94534 | C31: TJ | D31: https://ec.europa.eu/eurostat/databrowser/view/nrg_bal_c__custom_22103112/default/table
A32: CCGT plant | B32: =B31*B28/100 -> 77696.263 | C32: TJ
A33: Gas turbine plant | B33: =B31*B29/100 -> 16837.737 | C33: TJ
A35: Input to output conversion
A36: Efficiency CCGT (ETM) | B36: 52.755341 | C36: % | D36: Value retrieved from Ireland dataset update 2024
A37: Efficiency gas turbine plant (ETM) | B37: 34 | C37: % | D37: Value retrieved from Ireland dataset update 2024
A39: CCGT plant | B39: =B32*B36/100 -> 40988.928 | C39: TJ
A40: Gas turbine plant | B40: =B33*B37/100 -> 5724.8306 | C40: TJ
A43: Diesel plants
A44: Based on complete energy balance from Eurostat. Converted to electricity output with efficiency from IE dataset
A45: Transformation input | B45: =Eurostat!B12 -> 518.4 | C45: TJ
A46: Efficiency | B46: 0.38
A47: Electricity production | B47: =B45*B46 -> 196.992 | C47: TJ
A50: Wind - inland
A51: Normalised wind generation in GWh | B51: ='GCS data-workbook (wind)'!F43 -> 9620 | C51: GWh | D51: Used the normalized generation, not the actual generation (total wind generation). Total wind generation reflects that specific year's weather (windy vs. calm year). The normalised figure corrects for that, showing what the installed capacity would have produced in an average wind year.
A52: Normalised wind generation in TJ | B52: =B51 *3.6 -> 34632 | C52: TJ
A53: Full load hours | B53: ='GCS data-workbook (wind)'!E43/'GCS data-workbook (wind)'!D43 *1000 -> 2313.1068 | C53: h

Sheet GCS data-workbook (gas)
B2: Retrieved from: https://cms.eirgrid.ie/2022-2031-all-island-generation-capacity-statement-data-workbook
B3: Conventional Generation - IE
B5: 3.2 Changes to Conventional Generation in Ireland
B7: Table 3.3 -Assumptions for conventional plant changes in Ireland
C10: Plant | D10: Units | E10: Export Capacity (MW) | F10: Modelled as closing by the end of: | G10: Comment
C11: Aghada | D11: AT1 | E11: 90 | F11: 2023 | G11: IED Limited Life-time Derogation. ESB has provided a closure notice for these units.
D12: AD2 | E12: 449 | F12: Remains open for study horizon | G12: Note AD2 has increased capacity from 431 MW to 449 MW
C13: Tarbert | D13: TB1 | E13: 54 | F13: 2021 | G13: SSE has previously provided a closure notice for this unit to close at end of 2023. TB1 has since been placed on outage until Dec 2023 so will be excluded from studies
D14: TB2 | E14: 54 | F14: 2021 | G14: SSE has previously provided a closure notice for this unit to close at end of 2023. TB2 has since been placed on outage until Dec 2023 so will be excluded from studies
D15: TB3 | E15: 241 | F15: 2023 | G15: SSE has provided a closure notice for this unit to close at end of 2023.
D16: TB4 | E16: 243 | F16: 2021 | G16: SSE has previously provided a closure notice for this unit to close at end of 2023. TB4 has since been placed on outage until end of March 2023. Will be excluded from studies
C17: Moneypoint | D17: MP1 | E17: 285 | F17: 2024 | G17: Moneypoint units could not qualify for the 2024/2025 T-4 Capacity Auction[1]. On this basis, these units will be excluded from end of 2024. EirGrid notes that ESB has not provided a closure notice for these units. MP2 is now running on HFO with a capacity of 250 MW.
D18: MP2 | E18: 250
D19: MP3 | E19: 285
C20: Edenderry | D20: ED1 | E20: 118 | F20: 2030 | G20: The Bord na Móna plant ED1 was due to close at the end of 2023. Planning permission was recently awarded to keep this unit operating until 2030, running on 100% biomass from 2024.
B23: Appendix 3 Generation Plant Information
B25: Table A3-1 Registered Capacity of dispatchable generation and interconnectors in Ireland in 2022 (MW) DSU: Demand Side Unit; HFO: Heavy Fuel Oil; DO: Distillate Oil
D28: ID | E28: Fuel Type | F28: Technology Category | G28: 2022 | H28: Comment
C29: Aghada | D29: AT1 | E29: Gas/DO | F29: Gas Turbine | G29: 90 | H29: To close before end of 2023
D30: AT2 | E30: Gas/DO | F30: Gas Turbine | G30: 90
D31: AT4 | E31: Gas/DO | F31: Gas Turbine | G31: 90
D32: AD2 | E32: Gas/DO | F32: Gas Turbine | G32: 449 | H32: Increased capacity from 431 MW
C33: All DSU | D33: DSU | E33: DSU | F33: DSU | G33: 604
C34: Ardnacrusha | D34: AA1-4 | E34: Hydro | F34: Hydro | G34: 86
C35: Dublin Bay | D35: DB1 | E35: Gas/DO | F35: Gas Turbine | G35: 415
C36: Dublin Waste | D36: DW1 | E36: Waste | F36: Steam Turbine | G36: 61
C37: Edenderry | D37: ED1 | E37: Milled peat/ Biomass | F37: Steam Turbine | G37: 118 | H37: Planning Permission was granted to extend operation to 2030. Will run exclusively on biomass from Jan 2024
D38: ED3 | E38: DO/Gas | F38: Gas Turbine | G38: 58 | H38: Operating on gas from Oct 2025
D39: ED5 | E39: DO/Gas | F39: Gas Turbine | G39: 58 | H39: Operating on gas from Oct 2025
C40: Erne | D40: ER1-4 | E40: Hydro | F40: Hydro | G40: 65
C41: EWIC | D41: EW1 | E41: DC Interconnector | G41: 500
C42: Great Island CCGT | D42: GI4 | E42: Gas/DO | F42: Gas Turbine | G42: 464
C43: Huntstown | D43: HNC | E43: Gas/DO | F43: Gas Turbine | G43: 337
D44: HN2 | E44: Gas/DO | F44: Gas Turbine | G44: 408
C45: Indaver Waste | D45: IW1 | E45: Waste | F45: Steam Turbine | G45: 17
C46: Lee | D46: LE1-4 | E46: Hydro | F46: Hydro | G46: 27
C47: Liffey | D47: LI1-4 | E47: Hydro | F47: Hydro | G47: 38
C48: Moneypoint | D48: MP1 | E48: Coal/HFO | F48: Steam Turbine | G48: 285 | H48: Modelled as not available from October 2024
D49: MP2 | E49: HFO | F49: Steam Turbine | G49: 250 | H49: Modelled as not available from October 2024
D50: MP3 | E50: Coal/HFO | F50: Steam Turbine | G50: 285 | H50: Modelled as not available from October 2024
...

Sheet GCS data-workbook (wind)
B2: Retrieved from: https://cms.eirgrid.ie/2022-2031-all-island-generation-capacity-statement-data-workbook
B3: Renewable Generation - IE
B5: 3.5(a) Wind Power in Ireland
B7: Figure 3.3 - Assumed Build-out of renewables
C10: Year | D10: Waste (GW) | E10: Biomass (GW) | F10: Solar (GW) | G10: Onshore Wind (GW) | H10: Offshore Wind (GW) | I10: Hydro (GW)
C11: 2019 | D11: 0.077 | E11: 0.088 | F11: 0.016 | G11: 4.088 | H11: 0.025 | I11: 0.242
C12: 2020 | D12: 0.077 | E12: 0.088 | F12: 0.139 | G12: 4.234 | H12: 0.025 | I12: 0.242
C13: 2021 | D13: 0.077 | E13: 0.088 | F13: 0 | G13: 4.33 | H13: 0.025 | I13: 0.242
C14: 2022 | D14: 0.077 | E14: 0.131 | F14: 0.167 | G14: 4.482 | H14: 0.025 | I14: 0.242
C15: 2023 | D15: 0.077 | E15: 0.131 | F15: 0.333 | G15: 4.634 | H15: 0.025 | I15: 0.242
C16: 2024 | D16: 0.077 | E16: 0.172 | F16: 0.5 | G16: 4.787 | H16: 0.025 | I16: 0.242
C17: 2025 | D17: 0.077 | E17: 0.172 | F17: 0.667 | G17: 4.939 | H17: 0.025 | I17: 0.242
C18: 2026 | D18: 0.077 | E18: 0.172 | F18: 0.833 | G18: 5.091 | H18: 0.025 | I18: 0.242
C19: 2027 | D19: 0.077 | E19: 0.172 | F19: 1 | G19: 5.243 | H19: 0.025 | I19: 0.242
C20: 2028 | D20: 0.077 | E20: 0.172 | F20: 1.167 | G20: 5.396 | H20: 0.725 | I20: 0.242
C21: 2029 | D21: 0.077 | E21: 0.172 | F21: 1.333 | G21: 5.548 | H21: 2.863 | I21: 0.242
C22: 2030 | D22: 0.077 | E22: 0.172 | F22: 1.5 | G22: 5.7 | H22: 5 | I22: 0.242
C23: 2031 | D23: 0.077 | E23: 0.172 | F23: 1.667 | G23: 5.852 | H23: 7.138 | I23: 0.242
B31: Figure 3.4 - The actual and normalised energy produced from wind power in Ireland over the last ten years
C35: Year | D35: Wind Installed Capacity (MW) | E35: Total Wind Generation (GWh) | F35: Normalised Wind Generation (GWh) | G35: Wind CapacityFactor | H35: Average Capacity Factor
C36: 2012 | D36: 1700 | E36: 4100 | F36: 4120 | G36: 0.28 | H36: 0.28
C37: 2013 | D37: 1920 | E37: 4640 | F37: 4600 | G37: 0.29
C38: 2014 | D38: 2270 | E38: 5120 | F38: 5250 | G38: 0.28
C39: 2015 | D39: 2450 | E39: 6540 | F39: 6190 | G39: 0.32
C40: 2016 | D40: 2800 | E40: 6120 | F40: 6600 | G40: 0.27
C41: 2017 | D41: 3310 | E41: 7230 | F41: 7580 | G41: 0.27
C42: 2018 | D42: 3670 | E42: 8690 | F42: 8630 | G42: 0.28
C43: 2019 | D43: 4120 | E43: 9530 | F43: 9620 | G43: 0.28
C44: 2020 | D44: 4300 | E44: 11140 | F44: 10410 | G44: 0.3
C45: 2021 | D45: 4330 | E45: 9530 | F45: 10500 | G45: 0.25
B52: Appendix 3 Generation Plant Information
B54: Table A3-2 Partially/Non-Dispatchable plant in Ireland (MW)
C57: At year end: | D57: 2022 | E57: 2023 | F57: 2024 | G57: 2025 | H57: 2026 | I57: 2027 | J57: 2028 | K57: 2029 | L57: 2030 | M57: 2031
C58: Wind Onshore* | D58: 4480 | E58: 4630 | F58: 4790 | G58: 4940 | H58: 5100 | I58: 5250 | J58: 5400 | K58: 5550 | L58: 5700 | M58: 5850
C59: Wind Offshore* | D59: 25 | E59: 25 | F59: 25 | G59: 25 | H59: 25 | I59: 25 | J59: 725 | K59: 2865 | L59: 5000 | M59: 7140
C60: Small Scale Hydro | D60: 26 | E60: 26 | F60: 26 | G60: 26 | H60: 26 | I60: 26 | J60: 26 | K60: 26 | L60: 26 | M60: 26
C61: Biomass and Biogas | D61: 24 | E61: 24 | F61: 24 | G61: 24 | H61: 24 | I61: 24 | J61: 24 | K61: 24 | L61: 24 | M61: 24
C62: Biomass CHP | D62: 30 | E62: 30 | F62: 30 | G62: 30 | H62: 30 | I62: 30 | J62: 30 | K62: 30 | L62: 30 | M62: 30
C63: Industrial | D63: 9 | E63: 9 | F63: 9 | G63: 9 | H63: 9 | I63: 9 | J63: 9 | K63: 9 | L63: 9 | M63: 9
C64: Conventional CHP | D64: 129 | E64: 129 | F64: 129 | G64: 129 | H64: 129 | I64: 129 | J64: 129 | K64: 129 | L64: 129 | M64: 129
...

Sheet Eurostat
A1: Data extracted on 07/08/2026 13:58:44 from [ESTAT]
A2: Dataset: | B2: Complete energy balances [nrg_bal_c__custom_22103730]
A3: Last updated: | B3: 02/06/2026 23:00
A5: Time frequency | C5: Annual
A6: Unit of measure | C6: Terajoule
A7: Geopolitical entity (reporting) | C7: Ireland
A8: Time | C8: 2019
A10: NRG_BAL (Labels) | B10: Transformation input - electricity and heat generation - main activity producer electricity only - energy use
A11: SIEC (Labels)
A12: Gas oil and diesel oil (excluding biofuel portion) | B12: 518.4
A14: Special value
A15: : | B15: not available
