Workbook

Sheet mapping (2)
A1: {=LEFT(_xlfn._xlws.FILTER('unit_conversion_overview_XCL-A'!A:A,'unit_conversion_overview_XCL-A'!A:A<>""),IFERROR(SEARCH("2019",_xlfn._xlws.FILTER('unit_conversion_overview_XCL-A'!A:A,'unit_conversion_overview_XCL-A'!A:A<>""))-2,LEN(_xlfn._xlws.FILTER('unit_conversion_overview_XCL-A'!A:A,'unit_conversion_overview_XCL-A'!A:A<>""))))} -> Variable Klimaatmonitor | B1: {=_xlfn._xlws.FILTER('unit_conversion_overview_XCL-A'!B:B,'unit_conversion_overview_XCL-A'!B:B<>"")} -> Internal variable name | C1: {=_xlfn._xlws.FILTER('unit_conversion_overview_XCL-A'!C:C,'unit_conversion_overview_XCL-A'!C:C<>"")} -> Conversion | D1: {=_xlfn._xlws.FILTER('unit_conversion_overview_XCL-A'!D:D,'unit_conversion_overview_XCL-A'!D:D<>"")} -> Converted unit | E1: {=_xlfn._xlws.FILTER('unit_conversion_overview_XCL-A'!E:E,'unit_conversion_overview_XCL-A'!E:E<>"")} -> Conversion factor
A2: inwoners | B2: no_inhabitants | C2: no conversion | D2: # | E2: 1
A3: woningen | B3: no_residences | C3: no conversion | D3: # | E3: 1
A4: pautos | B4: no_cars | C4: no conversion | D4: # | E4: 1
A5: energie_totaal_combi | B5: total_energy_tj | C5: no conversion | D5: TJ | E5: 1
A6: verk_totaal | B6: tp_total_energy_tj | C6: no conversion | D6: TJ | E6: 1
A7: elektra_totaal_combi | B7: total_electricity_tj | C7: no conversion | D7: TJ | E7: 1
A8: warm_totaal_combi | B8: total_gas_heat_tj_temp_corrected | C8: no conversion | D8: TJ | E8: 1
A9: zonpvachtermeter_kwh | B9: solar_pv_own_use_total_tj | C9: mln KWh to TJ | D9: TJ | E9: 3.6
A10: hern_warm_tot | B10: total_renewable_heat_tj | C10: no conversion | D10: TJ | E10: 1
A11: gas_woningen_tj | B11: hh_gas_tj_temp_corrected | C11: no conversion | D11: TJ | E11: 1
A12: warmwontjcor | B12: hh_heat_tj_temp_corrected | C12: no conversion | D12: TJ | E12: 1
A13: kwbelektotaal | B13: hh_electricity_tj | C13: mln KWh to TJ | D13: TJ | E13: 3.6
... A138: ondieptj | B138: bd_thermal_storage_tj | C138: no conversion | D138: TJ | E138: 1

Sheet A_km-var_to_ivar.csv
A1: km-variable | B1: internal variable (ivar) | C1: ivar unit
A2: {=mapping!B2:B144} -> inwoners | B2: {=mapping!C2:C144} -> no_inhabitants | C2: {=mapping!F2:F144} -> #
A3: woningen | B3: no_residences | C3: #
A4: pautos | B4: no_cars | C4: #
A5: energie_totaal_combi | B5: total_energy_tj | C5: TJ
A6: verk_totaal | B6: tp_total_energy_tj | C6: TJ
A7: elektra_totaal_combi | B7: total_electricity_tj | C7: TJ
A8: warm_totaal_combi | B8: total_gas_heat_tj_temp_corrected | C8: TJ
A9: zonpvachtermeter_kwh | B9: solar_pv_own_use_total_tj | C9: TJ
A10: hern_warm_tot | B10: total_renewable_heat_tj | C10: TJ
A11: gas_woningen_tj | B11: hh_gas_tj_temp_corrected | C11: TJ
A12: warmwontjcor | B12: hh_heat_tj_temp_corrected | C12: TJ
A13: kwbelektotaal | B13: hh_electricity_tj | C13: TJ
A14: kwbgastotaal | B14: hh_gas_tj | C14: TJ
... A144: co2_sw_ba_cng | B144: tp_van_gas_co2_motorway | C144: tonne

Sheet mapping
A1: {=LEFT(_xlfn._xlws.FILTER('unit_conversion_overview_XCL-A'!A:A,'unit_conversion_overview_XCL-A'!A:A<>""),IFERROR(SEARCH("2019",_xlfn._xlws.FILTER('unit_conversion_overview_XCL-A'!A:A,'unit_conversion_overview_XCL-A'!A:A<>""))-2,LEN(_xlfn._xlws.FILTER('unit_conversion_overview_XCL-A'!A:A,'unit_conversion_overview_XCL-A'!A:A<>""))))} -> Variable Klimaatmonitor | B1: Variable Klimaatmonitor corrected | C1: {=_xlfn._xlws.FILTER('unit_conversion_overview_XCL-A'!B:B,'unit_conversion_overview_XCL-A'!B:B<>"")} -> Internal variable name | D1: {=_xlfn._xlws.FILTER('unit_conversion_overview_XCL-A'!C:C,'unit_conversion_overview_XCL-A'!C:C<>"")} -> Conversion | E1: {=_xlfn._xlws.FILTER('unit_conversion_overview_XCL-A'!D:D,'unit_conversion_overview_XCL-A'!D:D<>"")} -> Converted unit | F1: Converted unit corrected | G1: {=_xlfn._xlws.FILTER('unit_conversion_overview_XCL-A'!E:E,'unit_conversion_overview_XCL-A'!E:E<>"")} -> Conversion factor
A2: inwoners | B2: =A2 -> inwoners | C2: no_inhabitants | D2: no conversion | E2: # | F2: =E2 -> # | G2: 1
A3: woningen | B3: =A3 -> woningen | C3: no_residences | D3: no conversion | E3: # | F3: =E3 -> # | G3: 1
A4: pautos | B4: =A4 -> pautos | C4: no_cars | D4: no conversion | E4: # | F4: =E4 -> # | G4: 1
A5: energie_totaal_combi | B5: =A5 -> energie_totaal_combi | C5: total_energy_tj | D5: no conversion | E5: TJ | F5: =E5 -> TJ | G5: 1
A6: verk_totaal | B6: =A6 -> verk_totaal | C6: tp_total_energy_tj | D6: no conversion | E6: TJ | F6: =E6 -> TJ | G6: 1
A7: elektra_totaal_combi | B7: =A7 -> elektra_totaal_combi | C7: total_electricity_tj | D7: no conversion | E7: TJ | F7: =E7 -> TJ | G7: 1
A8: warm_totaal_combi | B8: =A8 -> warm_totaal_combi | C8: total_gas_heat_tj_temp_corrected | D8: no conversion | E8: TJ | F8: =E8 -> TJ | G8: 1
A9: zonpvachtermeter_kwh | B9: =A9 -> zonpvachtermeter_kwh | C9: solar_pv_own_use_total_tj | D9: mln KWh to TJ | E9: TJ | F9: =E9 -> TJ | G9: 3.6
A10: hern_warm_tot | B10: =A10 -> hern_warm_tot | C10: total_renewable_heat_tj | D10: no conversion | E10: TJ | F10: =E10 -> TJ | G10: 1
A11: gas_woningen_tj | B11: =A11 -> gas_woningen_tj | C11: hh_gas_tj_temp_corrected | D11: no conversion | E11: TJ | F11: =E11 -> TJ | G11: 1
A12: warmwontjcor | B12: =A12 -> warmwontjcor | C12: hh_heat_tj_temp_corrected | D12: no conversion | E12: TJ | F12: =E12 -> TJ | G12: 1
A13: kwbelektotaal | B13: =A13 -> kwbelektotaal | C13: hh_electricity_tj | D13: mln KWh to TJ | E13: TJ | F13: =E13 -> TJ | G13: 3.6
... A69: wbz_h2 | B69: =A69 -> wbz_h2 | C69: no_h2_trucks | D69: no conversion | E69: # | F69: =E69 -> # | G69: 1
A70: co2enmobwerk | B70: =A70 -> co2enmobwerk | C70: tp_mobile_machines_co2 | D70: no conversion | E70: tonne | F70: tonne | G70: 1
A71: co2bkabdsl | B71: co2_bk_ab_diesel | C71: tp_bus_diesel_co2_built_env | D71: no conversion | E71: tonne | F71: tonne | G71: 1
A72: co2bkbabzn | B72: co2_bk_ba_gasoline | C72: tp_van_gasoline_co2_built_env | D72: no conversion | E72: tonne | F72: tonne | G72: 1
A73: co2bkbalpg | B73: co2_bk_ba_lpg | C73: tp_van_lpg_co2_built_env | D73: no conversion | E73: tonne | F73: tonne | G73: 1
A74: co2bkbadsl | B74: co2_bk_ba_diesel | C74: tp_van_diesel_co2_built_env | D74: no conversion | E74: tonne | F74: tonne | G74: 1
A75: co2bkpabzn | B75: co2_bk_pa_gasoline | C75: tp_car_gasoline_co2_built_env | D75: no conversion | E75: tonne | F75: tonne | G75: 1
A76: co2bkpadsl | B76: co2_bk_pa_diesel | C76: tp_car_diesel_co2_built_env | D76: no conversion | E76: tonne | F76: tonne | G76: 1
A77: co2bkpalpg | B77: co2_bk_pa_lpg | C77: tp_car_lpg_co2_built_env | D77: no conversion | E77: tonne | F77: tonne | G77: 1
A78: co2bktw | B78: =A78 -> co2bktw | C78: tp_motorcycle_co2_built_env | D78: no conversion | E78: tonne | F78: tonne | G78: 1
A79: co2bkzbv | B79: =A79 -> co2bkzbv | C79: tp_truck_co2_built_env | D79: no conversion | E79: tonne | F79: tonne | G79: 1
A80: co2bkabag | B80: co2_bk_ab_cng | C80: tp_bus_gas_co2_built_env | D80: no conversion | E80: tonne | F80: tonne | G80: 1
A81: co2bwabdsl | B81: co2_bw_ab_diesel | C81: tp_bus_diesel_co2_road | D81: no conversion | E81: tonne | F81: tonne | G81: 1
A82: co2bwbabzn | B82: co2_bw_ba_gasoline | C82: tp_van_gasoline_co2_road | D82: no conversion | E82: tonne | F82: tonne | G82: 1
A83: co2bwbadsl | B83: co2_bw_ba_diesel | C83: tp_van_diesel_co2_road | D83: no conversion | E83: tonne | F83: tonne | G83: 1
A84: co2bwbalpg | B84: co2_bw_ba_lpg | C84: tp_van_lpg_co2_road | D84: no conversion | E84: tonne | F84: tonne | G84: 1
A85: co2bwpabzn | B85: co2_bw_pa_gasoline | C85: tp_car_gasoline_co2_road | D85: no conversion | E85: tonne | F85: tonne | G85: 1
A86: co2bwpadsl | B86: co2_bw_pa_diesel | C86: tp_car_diesel_co2_road | D86: no conversion | E86: tonne | F86: tonne | G86: 1
A87: co2bwpalpg | B87: co2_bw_pa_lpg | C87: tp_car_lpg_co2_road | D87: no conversion | E87: tonne | F87: tonne | G87: 1
A88: co2bwtw | B88: =A88 -> co2bwtw | C88: tp_motorcycle_co2_road | D88: no conversion | E88: tonne | F88: tonne | G88: 1
A89: co2bwzbv | B89: =A89 -> co2bwzbv | C89: tp_truck_co2_road | D89: no conversion | E89: tonne | F89: tonne | G89: 1
A90: co2bwabag | B90: co2_bw_ab_cng | C90: tp_bus_gas_co2_road | D90: no conversion | E90: tonne | F90: tonne | G90: 1
A91: co2swabdsl | B91: co2_sw_ab_diesel | C91: tp_bus_diesel_co2_motorway | D91: no conversion | E91: tonne | F91: tonne | G91: 1
A92: co2swbadsl | B92: co2_sw_ba_diesel | C92: tp_van_diesel_co2_motorway | D92: no conversion | E92: tonne | F92: tonne | G92: 1
A93: co2swbabzn | B93: co2_sw_ba_gasoline | C93: tp_van_gasoline_co2_motorway | D93: no conversion | E93: tonne | F93: tonne | G93: 1
A94: co2swbalpg | B94: co2_sw_ba_lpg | C94: tp_van_lpg_co2_motorway | D94: no conversion | E94: tonne | F94: tonne | G94: 1
A95: co2swpabzn | B95: co2_sw_pa_gasoline | C95: tp_car_gasoline_co2_motorway | D95: no conversion | E95: tonne | F95: tonne | G95: 1
...

Sheet unit_conversion_overview_XCL-A
A1: Variable Klimaatmonitor | B1: Internal variable name | C1: Conversion | D1: Converted unit | E1: Conversion factor | H1: Unit conversion table
A2: inwoners_2019 | B2: no_inhabitants | C2: no conversion | D2: # | E2: =VLOOKUP($C2,$H$3:$J$25,3,0) -> 1 | H2: from-to | J2: factor
A3: woningen_2019 | B3: no_residences | C3: no conversion | D3: # | E3: =VLOOKUP($C3,$H$3:$J$25,3,0) -> 1 | H3: kWh to TJ | J3: 3.6e-06
A4: pautos_2019 | B4: no_cars | C4: no conversion | D4: # | E4: =VLOOKUP($C4,$H$3:$J$25,3,0) -> 1 | H4: mln kWh to TJ | J4: =J3*1000000 -> 3.6
A5: energie_totaal_combi_2019 | B5: total_energy_tj | C5: no conversion | D5: TJ | E5: =VLOOKUP($C5,$H$3:$J$25,3,0) -> 1 | H5: MWh to TJ | J5: =0.0036 -> 0.0036
A6: verk_totaal_2019 | B6: tp_total_energy_tj | C6: no conversion | D6: TJ | E6: =VLOOKUP($C6,$H$3:$J$25,3,0) -> 1 | H6: GWh to TJ | J6: 3.6
A7: elektra_totaal_combi_2019 | B7: total_electricity_tj | C7: no conversion | D7: TJ | E7: =VLOOKUP($C7,$H$3:$J$25,3,0) -> 1 | H7: m3 (natural gas) to TJ | J7: 3.165e-05
A8: warm_totaal_combi_2019 | B8: total_gas_heat_tj_temp_corrected | C8: no conversion | D8: TJ | E8: =VLOOKUP($C8,$H$3:$J$25,3,0) -> 1 | H8: mln m3 (natural gas) to TJ | J8: =J7*1000000 -> 31.65
A9: zonpvachtermeter_kwh_2019 | B9: solar_pv_own_use_total_tj | C9: mln KWh to TJ | D9: TJ | E9: =VLOOKUP($C9,$H$3:$J$25,3,0) -> 3.6 | H9: GJ to TJ | J9: =1/1000 -> 0.001
A10: hern_warm_tot_2019 | B10: total_renewable_heat_tj | C10: no conversion | D10: TJ | E10: =VLOOKUP($C10,$H$3:$J$25,3,0) -> 1 | H10: no conversion | J10: 1
A11: gas_woningen_tj_2019 | B11: hh_gas_tj_temp_corrected | C11: no conversion | D11: TJ | E11: =VLOOKUP($C11,$H$3:$J$25,3,0) -> 1 | H11: ton/m3 to ton/TJ (natural gas) | J11: =1/31.65*1000000 -> 31595.577
A12: warmwontjcor_2019 | B12: hh_heat_tj_temp_corrected | C12: no conversion | D12: TJ | E12: =VLOOKUP($C12,$H$3:$J$25,3,0) -> 1 | H12: MW to kW | J12: =1000 -> 1000
A13: kwbelektotaal_2019 | B13: hh_electricity_tj | C13: mln KWh to TJ | D13: TJ | E13: =VLOOKUP($C13,$H$3:$J$25,3,0) -> 3.6
A14: kwbgastotaal_2019 | B14: hh_gas_tj | C14: mln m3 (natural gas) to TJ | D14: TJ | E14: =VLOOKUP($C14,$H$3:$J$25,3,0) -> 31.65
A15: warmwontier2_2019 | B15: hh_heat_tj | C15: GJ to TJ | D15: TJ | E15: =VLOOKUP($C15,$H$3:$J$25,3,0) -> 0.001 | H15: ton/kwh to ton/TJ (electricity) | J15: =1/J3 -> 277777.78
A16: houtskool_2019 | B16: hh_biomass_cooking_tj | C16: no conversion | D16: TJ | E16: =VLOOKUP($C16,$H$3:$J$25,3,0) -> 1
A17: houtwontj_2019 | B17: hh_biomass_heat_tj | C17: no conversion | D17: TJ | E17: =VLOOKUP($C17,$H$3:$J$25,3,0) -> 1
A18: gascomdv_2019 | B18: bd_commercial_gas_tj | C18: m3 (natural gas) to TJ | D18: TJ | E18: =VLOOKUP($C18,$H$3:$J$25,3,0) -> 3.165e-05
A19: gaspubldv_2019 | B19: bd_public_gas_tj | C19: m3 (natural gas) to TJ | D19: TJ | E19: =VLOOKUP($C19,$H$3:$J$25,3,0) -> 3.165e-05
A20: elcomdv_2019 | B20: bd_commercial_electricity_tj | C20: kWh to TJ | D20: TJ | E20: =VLOOKUP($C20,$H$3:$J$25,3,0) -> 3.6e-06
A21: elpubldv_2019 | B21: bd_public_electricity_tj | C21: kWh to TJ | D21: TJ | E21: =VLOOKUP($C21,$H$3:$J$25,3,0) -> 3.6e-06
A22: vbrzg_g1_2019 | B22: bd_gas_sbi_g_tj | C22: m3 (natural gas) to TJ | D22: TJ | E22: =VLOOKUP($C22,$H$3:$J$25,3,0) -> 3.165e-05
A23: vbrzg_h_2019 | B23: bd_gas_sbi_h_tj | C23: m3 (natural gas) to TJ | D23: TJ | E23: =VLOOKUP($C23,$H$3:$J$25,3,0) -> 3.165e-05
A24: vbrzg_i_2019 | B24: bd_gas_sbi_i_tj | C24: m3 (natural gas) to TJ | D24: TJ | E24: =VLOOKUP($C24,$H$3:$J$25,3,0) -> 3.165e-05
A25: vbrzg_j_2019 | B25: bd_gas_sbi_j_tj | C25: m3 (natural gas) to TJ | D25: TJ | E25: =VLOOKUP($C25,$H$3:$J$25,3,0) -> 3.165e-05
A26: vbrzg_k_2019 | B26: bd_gas_sbi_k_tj | C26: m3 (natural gas) to TJ | D26: TJ | E26: =VLOOKUP($C26,$H$3:$J$25,3,0) -> 3.165e-05
A27: vbrzg_l_2019 | B27: bd_gas_sbi_l_tj | C27: m3 (natural gas) to TJ | D27: TJ | E27: =VLOOKUP($C27,$H$3:$J$25,3,0) -> 3.165e-05
... A136: efacel_2019 | B136: electricity_tonne_co2_per_tj | C136: ton/kwh to ton/TJ (electricity) | D136: tonne/TJ (electricity) | E136: =VLOOKUP($C136,$H$3:$J$25,3,0) -> 277777.78
A137: warwarmte_2019 | B137: waste_heat_used_in_area_tj | C137: no conversion | D137: TJ | E137: =VLOOKUP($C137,$H$3:$J$25,3,0) -> 1 | G137: Note: leaving some empty rows in case more variables are added
A138: ondieptj_2019 | B138: bd_thermal_storage_tj | C138: no conversion | D138: TJ | E138: =VLOOKUP($C138,$H$3:$J$25,3,0) -> 1
