Workbook
Name base_year: Dashboard!$E$12
Name country: Dashboard!$E$11
Name Eff_cooking_biomass: technical_specs!$R$46
Name Eff_cooking_electric: technical_specs!$R$43
Name Eff_cooking_gas: technical_specs!$R$42
Name Eff_cooking_halogen: technical_specs!$R$44
Name Eff_cooking_induction: technical_specs!$R$45
Name Eff_cooling_airco: technical_specs!$R$39
Name Eff_cooling_pump_air: technical_specs!$R$38
Name Eff_cooling_pump_ground: technical_specs!$R$37
Name Eff_hot_water_coal: technical_specs!$R$32
Name Eff_hot_water_combi_boiler: technical_specs!$R$24
Name Eff_hot_water_district: technical_specs!$R$26
Name Eff_hot_water_electric: technical_specs!$R$29
Name Eff_hot_water_fuel_cell: technical_specs!#REF!
Name Eff_hot_water_gas: technical_specs!$R$30
Name Eff_hot_water_hhp_gas: technical_specs!$R$34
Name Eff_hot_water_hhp_heatpump: technical_specs!$R$33
Name Eff_hot_water_micro_CHP: technical_specs!#REF!
Name Eff_hot_water_oil: technical_specs!$R$31
Name Eff_hot_water_pump_air: technical_specs!$R$27
Name Eff_hot_water_pump_ground: technical_specs!$R$25
Name Eff_hot_water_solar_thermal_panel: technical_specs!#REF!
Name Eff_hot_water_woodpellets: technical_specs!$R$28
Name Eff_lighting_fluorescent: technical_specs!$R$50
Name Eff_lighting_incandescent: technical_specs!$R$49
Name Eff_lighting_led: technical_specs!$R$51
Name Eff_space_heating_coal: technical_specs!$R$19
Name Eff_space_heating_combi_boiler: technical_specs!$R$11
Name Eff_space_heating_district: technical_specs!$R$13
Name Eff_space_heating_electric: technical_specs!$R$16
Name Eff_space_heating_gas: technical_specs!$R$17
Name Eff_space_heating_hhp_gas: technical_specs!$R$21
Name Eff_space_heating_hhp_heatpump: technical_specs!$R$20
Name Eff_space_heating_micro_CHP: technical_specs!#REF!
Name Eff_space_heating_oil: technical_specs!$R$18
Name Eff_space_heating_pump_add_on: technical_specs!$R$20
Name Eff_space_heating_pump_air: technical_specs!$R$14
Name Eff_space_heating_pump_ground: technical_specs!$R$12
Name Eff_space_heating_solar_thermal: technical_specs!#REF!
Name Eff_space_heating_woodpellets: technical_specs!$R$15
Name Final_demand_appliances: Dashboard!$E$25
Name Final_demand_coal: 'Fuel aggregation'!$C$11
Name Final_demand_cooking: Dashboard!$E$24
Name Final_demand_cooling: Dashboard!$E$22
Name Final_demand_electricity: 'Fuel aggregation'!$I$11
Name Final_demand_gas: 'Fuel aggregation'!$D$11
Name Final_demand_heat: 'Fuel aggregation'!$J$11
Name Final_demand_hot_water: Dashboard!$E$21
Name Final_demand_lighting: Dashboard!$E$23
Name Final_demand_oil: 'Fuel aggregation'!$E$11
Name Final_demand_other: 'Fuel aggregation'!$H$11
Name Final_demand_residences: 'Fuel aggregation'!$L$11
Name Final_demand_solar_thermal: 'Fuel aggregation'!$G$11
Name Final_demand_space_heating: Dashboard!$E$20
Name Final_demand_woodpellets: 'Fuel aggregation'!$F$11

Sheet Cover Sheet
B2: Cover Sheet
B4: Document | C4: ="Residence analysis "&C6&" "&C7 -> Residence analysis nl 2019
B5: Version # | C5: =MAX(Changelog!D:D) -> 2.26
B6: Country | C6: nl
B7: Year data | C7: 2019
B8: Date | C8: August 19, 2025
B9: Author | C9: Mathijs Bijkerk
B10: Organization | C10: Quintel
B12: Legend
B14: Cells | C14: Intermediate (calculation)
C15: Result
C16: Manual input
C17: Reference to manual input or data input
B19: Sheets | C19: Introductory
C20: Research data
C21: Sources
C22: Dashboard
C23: Results
C24: Main calculations
C25: Additional calculations
C26: CSV-files
B29: Comments
C30: This analysis has a different way of aggregating fuels via an indirect HLOOKUP to the energy balance. This is an experiment and should not be imitated by other analyses.

Sheet Changelog
B2: Changelog
B4: Date | C4: Changes | D4: Version
B6: 41474 | C6: Created this document | D6: 1
B7: 41484 | C7: Inserted latest EB, fixed solar pv value (SD) | D7: 1
B8: 41485 | C8: Removing solar_PV calculation, they are moved to centra production table | D8: 1.01
C9: Added links and justification for national vs final gas demand
B10: 41486 | C10: Added Share of demand allocated to final demand in residencesto calculation of Technology split final demand
C11: CSV files: Added 'key' and 'share' in new new line.
B12: 41490 | C12: Added two redundant sheets for automatically generating edges and noes | D12: 2
C13: improved the Dashboard layout
C14: Improved the layout of calculations
C15: Deleted many names
B16: 41491 | C16: Changed Dataflow layout | D16: 2.01
B17: 41492 | C17: general adaptations of good practice | D17: 2.02
B18: 41494 | C18: Added child shares for the converters that recreive energy from solar thermal and electric add on converters | D18: 2.02
B19: 41495 | C19: Added parent_share that fixes problem in the graph https://github.com/quintel/refinery/issues/37 | D19: 2.03
B20: 41500 | C20: Renamed energy balance | D20: 2.04
B21: 41505 | C21: Corrected cell links in Applications Shares | D21: 2.05
B22: 41507 | C22: updating dashboard button | D22: -
B23: 41507 | C23: Update "Contents", minor layout changes in various sheets, link average usefull demand in "Houses shares" to "Dashboard" (WT) | D23: 2.06
B24: 41512 | C24: Changed the way that the useful demand in heating/cooling share is calculated, regarding the old/new houses split | D24: 2.07
B25: 41534 | C25: removed technical specs | D25: 2.08
B26: 41535 | C26: made Average R-value of a typical old/new residences a fixed dashboard input (it is an assumption) | D26: 2.09
B27: 41535 | C27: cleaned up fuel aggregation sheet and tech_specs sheet | D27: 2.1
B28: 41561 | C28: removing Charcoal from analysis | D28: 2.11
B29: 41562 | C29: removing sheets with edges and nodes | D29: 2.12
B30: 41578 | C30: reworking checks and layout on dashboard | D30: 2.13
B31: 41618 | C31: improved text of intro sheet | D31: 2.14
B32: May 23, 2014 | C32: Increased robustness of technology share calculation if the energy input of a whole share group is zero. An IF statement is used to avoid #DIV/0! errors | D32: 2.15
B33: May 29, 2014 | C33: Increased robustness of aplication share calculation if the energy input of a whole share group is zero. An IF statement is used to avoid #DIV/0! errors | D33: 2.16
B34: June 3, 2014 | C34: Correct misstake in application share calculation for district heat | D34: 2.17
B35: December 4, 2015 | C35: Added hybrid heatpump to this analysis (results exported in heating_network_gas, heating_electricity, water_network_gas and water_electricity csv's), deleted heatpump_add_on csv | D35: 2.18
B36: November 5, 2018 | C36: Extended housing stock division. Before it was old/new, now the housing stock can be divided in five housing types. Removed solar thermal for space heating, removed micro CHP, fuel cell for space heating and hot water | D36: 2.19
B37: November 5, 2018 | C37: Set average heat demand per house type. This determines the UD space heating split to different housing types. | D37: 2.2
B38: July 6, 2021 | C38: HHP fix by Marlieke Verweij. We had troubles with the formerly fixed input shares in HHPs. Therefore, we have made these input shares for HHPs dynamic: they can now be set per dataset. For this change, I have added hard-coded input shares for HHPs to 'technical_specs' tab, sbecause this analysis needs the input shares as input. For NL2015 and other country datasets these hard -coded shares have been used. I have also added two new csv-files where the input shares are calculated for HHPs in households. | D38: 2.21
B39: November 23, 2023 | C39: Removed solar thermal child share for hot water in households. | D39: 2.22
B40: November 23, 2023 | C40: Reduced housing stock type categories from five to four by including corner houses in semi-detached houses and expanded housing stock division by adding period of construction. | D40: 2.23
B41: November 23, 2023 | C41: Changed data initialisation of space heating for households from insulation inputs to share in useful demand per housing type and construction period. | D41: 2.24
B42: July 17, 2025 | C42: Add surface water technologies to export CSVs with zero share. | D42: 2.25
B43: August 19, 2026 | C43: The hardcoded specs for HHPs in the 'technical_specs' sheet were outdated and too high for the space heating part. These have been updated based the new node source analyses for the corresponding technology. Additionally, for the hot water part, we assume that the cutoff COP is set at 6.0, effectively ensuring that only network gas is used. To reflect this, the input of network gas is set to 100% and electricity to 0%. These are improvements of the fix in 2.21. | D43: 2.26

Sheet Contents
B2: Contents
B4: Tab | C4: Description
B6: Cover Sheet | C6: Information about this document and a legend to tab and cell formatting
B7: Changelog | C7: A documentation of the changes to this analysis
B8: To Do | C8: A list of suggested improvements
B9: Contents | C9: An index with description of all the tabs in this analysis
B10: Introduction | C10: A short introduction to the Energytransition model (ETM) and the Residence Analysis
B11: Dataflow | C11: A visualization of the dataflow in this analysis
B12: Assumptions | C12: A description of the modeling and country-specific assumptions for this analysis
B13: Corrected energy balance step 2 | C13: Here the corrected energy balance created in the CHP analysis should be pasted for your country and year
B14: Technological specifications | C14: The technological specifications of energy conversion technologies used in the ETM are listed here
B15: Dashboard | C15: On the dashboard, the country-specific assumptions can be changed manually. It also shows the most important checks
B16: Application Shares | C16: Input data' is generated. The shares that break down the final demand of a carrier per application are defined.
... B38: csv_appliances_electricity | C38: A CSV-file with a converter output share (parent_share)
B39: csv_export_to_area_analysis
B40: csv_heating_hhp_efficiencies
B41: csv_hot_water_hhp_efficiencies

Sheet Introduction
B2: Introduction
B4: This analysis
B6: The main goal of this analysis is to provide a breakdown of the residential energy consumption. Energy is consumed in the applications space heating, hot water, space cooling, lighting, cooking and electric applications. Furthermore, the energy use within these applications is split over certain technologies (for example: coal, gas and oil heaters in space heating). Note that Solar PV production is not covered by this analysis as that results from the Energy Balance and the Autoproduction table (both available from IEA). To see what solar PV production is for your dataset, open the "2_power_and_heat_plant_analysis", import all the required data (including the Energy Balance and Autoproducer table, which both need to be bought from IEA), and proceed to 'Results by machine' or the 'PV solar' sheets.
B8: Steps to perform this analysis
B10: 1. Import the corrected energy balance using the import button on the Dashboard sheet.
B11: 2. Look over all the assumptions and checks on the Assumptions sheet and the Dashboard sheet. Consult the documentation for additional information.
B12: 3. Fill in the assumptions on the Dashboard sheet using reliable sources and/or use the source analysis mentioned in the comments. Please document your sources.
B13: 4. Keep in mind the checks on the Dashboard. If a check fails, try to understand what goes wrong and adjust your assumptions as long as you feel it is still realistic.
B14: 5. If you encounter other problems please contact Quintel Intelligence.
B15: 6. Export the csv files using the export button on the Dashboard sheet.
B18: The Energytransition model
B20: In short, the Energy Transition Model (ETM) is a calculation engine with a front-end interface that is free to be used by private, commercial and public users. The engine exists of a collection of 'converters' that are linked together to approach the structure of an energy system at the country level. It includes for example import, export, electricity and heat production, final demand sectors and useful demand applications. Every converter has technical and economical specifications that were determined from scientific and technical literature. The model's initial configuration is mostly based on 2010 statistical data. Useful demand of energy applications is gathered from other sources. By moving sliders in a front end dashboard, representing energy use, energy production or socio-economical parameters, the calculation engine determines the results from these actions in a future scenario and communicates them to the user.

Sheet Dataflow
B2: Dataflow Household Analysis
B3: Notes
B4: A visualization of the dataflow in this analysis
C6: Analysis inputs | AO6: Analysis calculations | BV6: Analysis ouputs

Sheet Assumptions
B2: Assumptions
B4: Notes
B5: On this page, a description of the assumptions for this analysis is given. There are two types of assumptions, Modeling assumptions and Country specific assumptions. The modeling assumptions form the structure or framework to be able to do this analysis. They are the same for every country. The country specific assumptions must be entered by the researcher on the Dashboard page and are used to correctly adjust the calculations to the specific country. The fuels table gives an overview of how the ETM fuel carriers correspond with the IEA fuel carriers.
B7: Modeling assumptions
B9: Type | C9: Assumption | D9: Source
B10: General
C11: There are six main energy use groups in the built environment: space heating, hot water, space cooling cooking, lighting and electrical appliances.
C14: The technological specifications of these technologies are the same for all countries.
C16: Energy can only be converted by the technologies mentioned in the Dashboard
C18: In the residential sector the only source of auto-produced electricity is solar PV. | D18: estimate
C20: The ETM graph contains a number of converters that are used to model future energy saving effects of improved insulation. The inluence of these converters is set to 'zero' in the 'present' scenario:
C21: households_old_houses_cooling_savings_from_insulation | D21: results form ETM modelling logic
C22: households_new_houses_cooling_savings_from_insulation | D22: results form ETM modelling logic
C23: households_new_houses_heating_savings_from_insulation | D23: results form ETM modelling logic
C24: households_old_houses_heating_savings_from_insulation | D24: results form ETM modelling logic
C26: The usefule demand for space heating and space cooling is split over new and old residences. This ratio of old and new residences can be set in the dashbord. However, the insulation level of old and new residences cannot be changed by the user. It is fixed input on the "Technology specifications" tab. The current implementation therefore sets the same useful demand share for cooling and space heating.
C28: The 'average R-value of a typical old/new residence' is hard-coded in the Dashboard. | D28: Source analsysis by Quintel, Chael Kruip
C30: There is a converter in the graph that is currently not being used at all: | D30: results form ETM modelling logic
C31: households_useful_demand_for_hot_water_for_houses_with_add_on
C32: In consequence, the are two parent shares that need to be hard-coded to 0.0
C33: - residences_useful_demand_for_hot_water_after_solar_heater_and_add_on_parent_share
C34: - residences_space_heater_heatpump_add_on_electricity_parent_share
B41: Country specific assumptions
B43: Type | C43: Assumption | D43: Proposed source
B44: Final demand in Residences
C45: Final energy demand used for Space Heating | D45: -
C46: Final energy demand used for Hot Water | D46: -
C47: Final energy demand used for Space Cooling | D47: -
C48: Final energy demand used for Lighting | D48: -
C49: Final energy demand used for Cooking | D49: -
C50: Final energy demand used for Electrical Appliances | D50: -
B52: Space Heating
C53: Percentage of heat delivered by Condensing Combi Boiler | D53: -
C54: Percentage of heat delivered by solar thermal panels | D54: -
C55: Percentage of heat delivered by gas-fired Heat Pump (ground) | D55: -
C56: Percentage of heat delivered by gas-fired micro CHP | D56: -
C57: Percentage of heat delivered by District Heating | D57: -
C58: Percentage of heat delivered by electricity-driven Heat pump (air) | D58: -
C59: Percentage of heat delivered by woodpellets (biomass) heaters | D59: -
C60: Percentage of heat delivered by Electric Heaters (resistance) | D60: -
...

Sheet Dashboard
B2: Dashboard | I2: Automatically import/export analysis data
B4: Notes
B5: On this sheet you can fill the country specific assumptions for your country. Please mind the checks, if one or more become red it means that with the information you provided we cannot run the Energy Transition Model. Concerning your assumptions please provide sources.
B7: Assumptions | K7: Checks
B9: Sector | C9: Assumption | D9: Unit | E9: Value | G9: Name | I9: Source | K9: Check | L9: Status | M9: Notes | O9: Key | P9: Critical check
B10: General | K10: All critical checks are positive | L10: =IF(COUNTIF(P:P,0)+COUNTIF(P:P,FALSE)=0,TRUE,FALSE) -> FALSE
C11: Country | E11: eu | G11: country | O11: country
C12: The base year for this analysis | E12: 2011 | G12: base_year | K12: All assumptions are filled | L12: =IF(COUNTBLANK(E11:E85)-COUNTBLANK(C11:C85)=7,TRUE,FALSE) -> FALSE | O12: base_year | P12: =IF(L12=TRUE,1,0) -> 0
B16: Final demand
C17: Final energy demand of Residences (from energy balance) | D17: TJ | E17: =Final_demand_residences -> 0 | I17: Taken from the energy balance | K17: Relative error in fuel consumption (energy balance value and value computed from dashboard input):
C19: Final energy demand for | K19: {=TRANSPOSE('Final demand per energy carrier'!E71:K71)} -> Network gas | L19: {=TRANSPOSE('Final demand per energy carrier'!E74:K74)} -> #DIV/0! | M19: =IF(ABS(L19)<0.03," ","Consider adjusting your inputs that influence the demand for gas.") -> #DIV/0!
C20: Space Heating | D20: TJ | G20: Final_demand_space_heating | K20: Electricity | L20: #DIV/0! | M20: =IF(ABS(L20)<0.03," ","Consider adjusting your inputs that influence the demand for electricity.") -> #DIV/0! | O20: residences_final_demand_space_heating
C21: Hot Water | D21: TJ | G21: Final_demand_hot_water | K21: Solar thermal | L21: 0 | M21: No longer relevant | O21: residences_final_demand_hot_water
C22: Space Cooling | D22: TJ | G22: Final_demand_cooling | K22: Coal | L22: #DIV/0! | M22: =IF(ABS(L22)<0.03," ","Consider adjusting your inputs that influence the demand for coal.") -> #DIV/0! | O22: residences_final_demand_cooling
C23: Lighting | D23: TJ | G23: Final_demand_lighting | K23: Oil | L23: #DIV/0! | M23: =IF(ABS(L23)<0.03," ","Consider adjusting your inputs that influence the demand for oil.") -> #DIV/0! | O23: residences_final_demand_lighting
C24: Cooking | D24: TJ | G24: Final_demand_cooking | K24: Woodpellets | L24: #DIV/0! | M24: =IF(ABS(L24)<0.03," ","Consider adjusting your inputs that influence the demand for wood pellets.") -> #DIV/0! | O24: residences_final_demand_cooking
C25: Electrical Appliances | D25: TJ | G25: Final_demand_appliances | K25: District heat | L25: #DIV/0! | M25: =IF(ABS(L25)<0.03," ","Consider adjusting your inputs that influence the demand for district heat.") -> #DIV/0! | O25: residences_final_demand_appliances
C27: Remaining final energy, not accounted for in the calculation of shares. | D27: TJ | E27: =E17-SUM(E20:E25) -> 0 | K27: Remaining final energy is less than 5% of total final energy use. | L27: =IF(ABS(E27)/E17<0.05,TRUE,E27/E17) -> #DIV/0! | M27: =IF(L27=TRUE," ","Consider adjusting the final demands for space heating, space cooling....") -> #DIV/0!
B29: Space Heating | K29: Percentages add up to 100% | L29: =IF(SUM(E31:E40)=1,TRUE,SUM(E31:E40)) -> 0 | M29: =IF(L29=TRUE," ","Please adjust the percentages on the left. You might find it usefule to temporarily define one share as '1-sum( all others )' ") -> Please adjust the percentages on the left. You might find it usefule to temporarily define one share as '1-sum( all others )' | P29: =IF(L29=TRUE,1,0) -> 0
C30: Percentage of useful heat in space heating delivered by
C31: Condensing Combi Boiler | O31: residences_percentage_space_heating_combi_boiiler
C32: Electric Heat Pump (ground) | O32: residences_percentage_space_heating_heat_pump_ground
C33: District Heating | O33: residences_percentage_space_heating_district
C34: electricity-driven Heat pump (air) | O34: residences_percentage_space_heating_heat_pump_air
C35: woodpellets (biomass) heaters | O35: residences_percentage_space_heating_woodpellets
C36: Electric Heaters (resistance) | O36: residences_percentage_space_heating_electric_resistance
C37: Gas-fired Heaters | O37: residences_percentage_space_heating_gas_burner
C38: Oil-fired Heaters | O38: residences_percentage_space_heating_oil_burner
C39: Coal-fired Heaters | O39: residences_percentage_space_heating_coal_burner
C40: Hybrid heatpump | O40: residences_percentage_space_heating_hybrid_heatpump
B42: Hot Water | K42: Percentages add up to 100% | L42: =IF(SUM(E44:E53)=1,TRUE,SUM(E44:E53)) -> 0 | M42: =IF(L42=TRUE," ","Please adjust the percentages on the left. You might find it usefule to temporarily define one share as '1-sum( all others )' ") -> Please adjust the percentages on the left. You might find it usefule to temporarily define one share as '1-sum( all others )' | P42: =IF(L42=TRUE,1,0) -> 0
C43: Percentage of hot water (useful heat) delivered by
C44: Condensing Combi Boiler | O44: residences_percentage_hot_water_combi_boiiler
C45: Electric Heat Pump (ground) | O45: residences_percentage_hot_water_heat_pump_ground
C46: District heating | O46: residences_percentage_hot_water_district
C47: electricity-driven heat pump (air) | O47: residences_percentage_hot_water_heat_pump_air
C48: woodpellets (biomass) stoves | O48: residences_percentage_hot_water_woodpellets
C49: Electric heaters (resistance) | O49: residences_percentage_hot_water_electric_resistance
C50: Gas-fired heaters | O50: residences_percentage_hot_water_gas_burner
C51: Oil-fired heaters | O51: residences_percentage_hot_water_oil_burner
...

Sheet Corrected energy balance step 2
B2: Corrected energy balance step 2
B4: Notes
B7: PRODUCT | C7: Hard coal (if no detail) | D7: Brown coal (if no detail) | E7: Anthracite | F7: Coking coal | G7: Other bituminous coal | H7: Sub-bituminous coal | I7: Lignite | J7: Patent fuel | K7: Coke oven coke | L7: Gas coke | M7: Coal tar | N7: BKB/peat briquettes | O7: Gas works gas | P7: Coke oven gas | Q7: Blast furnace gas | R7: Other recovered gases | S7: Peat | T7: Natural Gas | U7: Crude/NGL/feedstocks (if no detail) | V7: Crude oil | W7: Natural gas liquids | X7: Refinery feedstocks | Y7: Additives/blending components | Z7: Other hydrocarbons | AA7: Refinery gas | AB7: Ethane | AC7: Liquefied petroleum gases (LPG) | AD7: Motor gasoline | AE7: Aviation gasoline | AF7: Gasoline type jet fuel | AG7: Kerosene type jet fuel | AH7: Other Kerosene | AI7: Gas/diesel oil | AJ7: Fuel oil | AK7: Naphtha | AL7: White spirit & SBP | AM7: Lubricants | AN7: Bitumen | AO7: Paraffin waxes | AP7: Petroleum coke | AQ7: Non-specified oil products | AR7: Industrial waste | AS7: Municipal waste (renewable) | AT7: Municipal waste (non-renewable) | AU7: Primary solid biofuels | AV7: Biogases | AW7: Biogasoline | AX7: Biodiesels | AY7: Other liquid biofuels | AZ7: Non-specified primary biofuels and waste | BA7: Charcoal | BB7: Elec/heat output from non-specified manufactured gases | BC7: Heat output from non-specified combustible fuels | BD7: Nuclear | BE7: Hydro | BF7: Geothermal | BG7: Solar photovoltaics | BH7: Solar thermal | BI7: Tide, wave and ocean | BJ7: Wind | BK7: Other sources | BL7: Electricity | BM7: Heat | BN7: Total | BO7: Memo: Renewables
B8: FLOW
B9: Production
B10: Imports
B11: Exports
B12: International marine bunkers
B13: International aviation bunkers
B14: Stock changes
B15: Total primary energy supply
B16: Transfers
B17: Statistical differences
B18: Transformation processes
B19: Main activity producer electricity plants
... B101: Heat output-autoproducer heat plants

Sheet technical_specs
B2: Technological specifications
B4: Notes
B5: Here, the technological specifications are imported from ETSource (automatically). These values are not country-specific and cannot be changed.
B7: Technological Specifications | E7: Extract data from Etsource | F7: Converter attributes | L7: HARDCODED (see issue in Changelog)
B8: Application | C8: Technology | E8: converter key | F8: heat efficiency | G8: heat efficiency gas subtechnology | H8: 1 / COP | I8: network gas input | J8: electrical efficiency | K8: light efficiency | L8: input electricity | M8: input network gas | N8: Heating efficiency | O8: Coefficient of performance (COP) | P8: Electrical efficiency | Q8: UD share network_gas | R8: Effective heating efficiency | S8: Name in this excel file
F9: output.useable_heat | G9: output.useable_heat.network_gas | H9: input.electricity | I9: input.network_gas | J9: output.electricity | K9: output.light
B10: Space Heating
C11: Condensing Combi Boiler (space heating) | E11: households_space_heater_combined_network_gas.converter | N11: =F11 -> 0 | R11: =N11 -> 0 | S11: Eff_space_heating_combi_boiler
C12: Electric Heat Pump (ground) (space heating) | E12: households_space_heater_heatpump_ground_water_electricity.converter | O12: =1/H12 -> #DIV/0! | R12: =O12 -> #DIV/0! | S12: Eff_space_heating_pump_ground
C13: District Heating (space heating) | E13: households_space_heater_district_heating_ht_steam_hot_water | N13: =F13 -> 0 | R13: =N13 -> 0 | S13: Eff_space_heating_district
C14: electricity-driven Heat pump (air) (space heating) | E14: households_space_heater_heatpump_air_water_electricity | O14: =1/H14 -> #DIV/0! | R14: =O14 -> #DIV/0! | S14: Eff_space_heating_pump_air
C15: woodpellets (biomass) heaters (space heating) | E15: households_space_heater_wood_pellets.converter | N15: =F15 -> 0 | R15: =N15 -> 0 | S15: Eff_space_heating_woodpellets
C16: Electric Heaters (resistance) (space heating) | E16: households_space_heater_electricity.converter | N16: =F16 -> 0 | R16: =N16 -> 0 | S16: Eff_space_heating_electric
C17: Gas-fired Heaters (space heating) | E17: households_space_heater_network_gas.converter | N17: =F17 -> 0 | R17: =N17 -> 0 | S17: Eff_space_heating_gas
C18: Oil-fired Heaters (space heating) | E18: households_space_heater_crude_oil.converter | N18: =F18 -> 0 | R18: =N18 -> 0 | S18: Eff_space_heating_oil
C19: Coal-fired Heaters (space heating) | E19: households_space_heater_coal.converter | N19: =F19 -> 0 | R19: =N19 -> 0 | S19: Eff_space_heating_coal
C20: Hybrid heatpump, heatpump part (space heating) | E20: households_space_heater_hybrid_heatpump_air_water_electricity | L20: 0.226111 | M20: 0.20861 | O20: =(1-M20)/L20 -> 3.5000066 | R20: =O20 -> 3.5000066 | S20: Eff_space_heating_hhp_heatpump
C21: Hybrid heatpump, gas part (space heating) | F21: =F20 -> 0 | G21: =G20 -> 0 | H21: =L20 -> 0.226111 | I21: =M20 -> 0.20861 | J21: =J20 -> 0 | K21: =K20 -> 0 | N21: =G21 -> 0 | Q21: =G21*I21/((G21*I21)+((1-(SUM(H21:I21))+H21))) -> 0 | R21: =N21 -> 0 | S21: Eff_space_heating_hhp_gas
B23: Hot Water
C24: Condensing Combi Boiler (hot water) | E24: households_water_heater_combined_network_gas.converter | N24: =F24 -> 0 | R24: =N24 -> 0 | S24: Eff_hot_water_combi_boiler
C25: Electric Heat Pump (ground) (hot water) | E25: households_water_heater_heatpump_ground_water_electricity.converter | O25: =1/H25 -> #DIV/0! | R25: =O25 -> #DIV/0! | S25: Eff_hot_water_pump_ground
C26: District Heating (hot water) | E26: households_water_heater_district_heating_ht_steam_hot_water | N26: =F26 -> 0 | R26: =N26 -> 0 | S26: Eff_hot_water_district
C27: electricity-driven Heat pump (air) (hot water) | E27: households_water_heater_heatpump_air_water_electricity | O27: =1/H27 -> #DIV/0! | R27: =O27 -> #DIV/0! | S27: Eff_hot_water_pump_air
C28: woodpellets (biomass) heaters (hot water) | E28: households_water_heater_wood_pellets.converter | N28: =F28 -> 0 | R28: =N28 -> 0 | S28: Eff_hot_water_woodpellets
C29: Electric Heaters (resistance) (hot water) | E29: households_water_heater_resistive_electricity.converter | N29: =F29 -> 0 | R29: =N29 -> 0 | S29: Eff_hot_water_electric
C30: Gas-fired Heaters (hot water) | E30: households_water_heater_network_gas.converter | N30: =F30 -> 0 | R30: =N30 -> 0 | S30: Eff_hot_water_gas
C31: Oil-fired Heaters (hot water) | E31: households_water_heater_crude_oil.converter | N31: =F31 -> 0 | R31: =N31 -> 0 | S31: Eff_hot_water_oil
C32: Coal-fired Heaters (hot water) | E32: households_water_heater_coal.converter | N32: =F32 -> 0 | R32: =N32 -> 0 | S32: Eff_hot_water_coal
C33: Hybrid heatpump, heatpump part (hot water) | E33: households_water_heater_hybrid_heatpump_air_water_electricity | L33: 0 | M33: 1 | O33: 1 | R33: =O33 -> 1 | S33: Eff_hot_water_hhp_heatpump
C34: Hybrid heatpump, gas part (hot water) | F34: =F33 -> 0 | G34: =G33 -> 0 | H34: =L33 -> 0 | I34: =M33 -> 1 | J34: =J33 -> 0 | K34: =K33 -> 0 | N34: =G34 -> 0 | Q34: =G34*I34/((G34*I34)+((1-(SUM(H34:I34))+H34))) -> #DIV/0! | R34: =N34 -> 0 | S34: Eff_hot_water_hhp_gas
B36: Space Cooling
C37: Electric heat pump ground | E37: households_cooling_heatpump_ground_water_electricity.converter | O37: =1/H37 -> #DIV/0! | R37: =O37 -> #DIV/0! | S37: Eff_cooling_pump_ground
C38: Electric heat pump air | E38: households_cooling_heatpump_air_water_electricity.converter | O38: =1/H38 -> #DIV/0! | R38: =O38 -> #DIV/0! | S38: Eff_cooling_pump_air
C39: Conventional electric airconditioning | E39: households_cooling_airconditioning_electricity.converter | O39: =1/H39 -> #DIV/0! | R39: =O39 -> #DIV/0! | S39: Eff_cooling_airco
B41: Cooking
C42: Gas stoves | E42: households_cooker_network_gas.converter | N42: =F42 -> 0 | R42: =N42 -> 0 | S42: Eff_cooking_gas
C43: Electric stoves (resistance) | E43: households_cooker_resistive_electricity.converter | N43: =F43 -> 0 | R43: =N43 -> 0 | S43: Eff_cooking_electric
C44: Electric halogen stoves | E44: households_cooker_halogen_electricity.converter | N44: =F44 -> 0 | R44: =N44 -> 0 | S44: Eff_cooking_halogen
C45: Electric induction stoves | E45: households_cooker_induction_electricity.converter | N45: =F45 -> 0 | R45: =N45 -> 0 | S45: Eff_cooking_induction
C46: Biomass stoves | E46: households_cooker_wood_pellets.converter | N46: =F46 -> 0 | R46: =N46 -> 0 | S46: Eff_cooking_biomass
...

Sheet Application Shares
B2: Application splits of final demands
B4: Notes
B5: In this sheet the shares per carrier per application needed for the Energy Transition Model are defined.
B7: Carrier | C7: Application | D7: Final demand per carrier per application (TJ) | E7: Shares per carrier per application
B8: Coal
C9: Space heating | D9: =SUM('Final demand per energy carrier'!H15:H25) -> #DIV/0! | E9: =IF(SUM($D$9:$D$10)=0,1,D9/SUM($D$9:$D$10)) -> #DIV/0!
C10: Hot water | D10: =SUM('Final demand per energy carrier'!H28:H38) -> #DIV/0! | E10: =IF(SUM($D$9:$D$10)=0,0,D10/SUM($D$9:$D$10)) -> #DIV/0!
B12: Oil
C13: Space heating | D13: =SUM('Final demand per energy carrier'!I15:I25) -> #DIV/0! | E13: =IF(SUM($D$13:$D$14)=0,1,D13/SUM($D$13:$D$14)) -> #DIV/0!
C14: Hot Water | D14: =SUM('Final demand per energy carrier'!I28:I38) -> #DIV/0! | E14: =IF(SUM($D$13:$D$14)=0,0,D14/SUM($D$13:$D$14)) -> #DIV/0!
B16: Network gas
C17: Space heating | D17: =SUM('Final demand per energy carrier'!E15:E25) -> #DIV/0! | E17: =IF(SUM($D$17:$D$20)=0,1,D17/SUM($D$17:$D$20)) -> #DIV/0!
C18: Hot water | D18: =SUM('Final demand per energy carrier'!E28:E38) -> #DIV/0! | E18: =IF(SUM($D$17:$D$20)=0,0,D18/SUM($D$17:$D$20)) -> #DIV/0!
C19: Space cooling | D19: =SUM('Final demand per energy carrier'!E41:E43) -> 0 | E19: =IF(SUM($D$17:$D$20)=0,0,D19/SUM($D$17:$D$20)) -> #DIV/0!
C20: Cooking | D20: =SUM('Final demand per energy carrier'!E47:E51) -> #DIV/0! | E20: =IF(SUM($D$17:$D$20)=0,0,D20/SUM($D$17:$D$20)) -> #DIV/0!
B22: Woodpellets
C23: Space heating | D23: =SUM('Final demand per energy carrier'!J15:J25) -> #DIV/0! | E23: =IF(SUM($D$23:$D$25)=0,1,D23/SUM($D$23:$D$25)) -> #DIV/0!
C24: Hot water | D24: =SUM('Final demand per energy carrier'!J28:J38) -> #DIV/0! | E24: =IF(SUM($D$23:$D$25)=0,0,D24/SUM($D$23:$D$25)) -> #DIV/0!
C25: Cooking | D25: =SUM('Final demand per energy carrier'!J47:J51) -> #DIV/0! | E25: =IF(SUM($D$23:$D$25)=0,0,D25/SUM($D$23:$D$25)) -> #DIV/0!
B27: Electrity
C28: Space heating | D28: =SUM('Final demand per energy carrier'!F15:F25) -> #DIV/0! | E28: =IF(SUM($D$28:$D$33)=0,1,D28/SUM($D$28:$D$33)) -> #DIV/0!
C29: Hot water | D29: =SUM('Final demand per energy carrier'!F28:F38) -> #DIV/0! | E29: =IF(SUM($D$28:$D$33)=0,0,D29/SUM($D$28:$D$33)) -> #DIV/0!
C30: Cooking | D30: =SUM('Final demand per energy carrier'!F47:F51) -> #DIV/0! | E30: =IF(SUM($D$28:$D$33)=0,0,D30/SUM($D$28:$D$33)) -> #DIV/0!
C31: Lighting | D31: =SUM('Final demand per energy carrier'!F55:F57) -> #DIV/0! | E31: =IF(SUM($D$28:$D$33)=0,0,D31/SUM($D$28:$D$33)) -> #DIV/0!
C32: Electrical applicances | D32: =SUM('Final demand per energy carrier'!F61:F68) -> 0 | E32: =IF(SUM($D$28:$D$33)=0,0,D32/SUM($D$28:$D$33)) -> #DIV/0!
C33: Space cooling | D33: =SUM('Final demand per energy carrier'!F41:F43) -> #DIV/0! | E33: =IF(SUM($D$28:$D$33)=0,0,D33/SUM($D$28:$D$33)) -> #DIV/0!
B35: District Heat (steam_hot_water)
C36: Space heating | D36: =SUM('Final demand per energy carrier'!K15:K25) -> #DIV/0! | E36: =IF(SUM($D$36:$D$37)=0,1,D36/SUM($D$36:$D$37)) -> #DIV/0!
C37: Hot water | D37: =SUM('Final demand per energy carrier'!K28:K38) -> #DIV/0! | E37: =IF(SUM($D$36:$D$37)=0,0,D37/SUM($D$36:$D$37)) -> #DIV/0!

Sheet Technology Shares
B2: Technology splits of Final demand
B4: Notes
B5: In this sheet the shares per technology per carrier needed for the Energy Transition Model are defined. Carriers that do not show up here, do not need to be split over more than one technology.
B7: Application | C7: Carrier | E7: Percentage of final demand converted by this technology (%) | F7: Share per technology and carrier
B8: Space heating
C9: Network gas | D9: =technical_specs!C17 -> Gas-fired Heaters (space heating) | E9: ='Technology split final demand'!I17 -> #DIV/0! | F9: =IF(SUM($E$9:$E$11)=0,0,E9/SUM($E$9:$E$11)) -> #DIV/0!
D10: =technical_specs!C11 -> Condensing Combi Boiler (space heating) | E10: ='Technology split final demand'!I11 -> #DIV/0! | F10: =IF(SUM($E$9:$E$11)=0,0,E10/SUM($E$9:$E$11)) -> #DIV/0!
D11: =technical_specs!C21 -> Hybrid heatpump, gas part (space heating) | E11: ='Technology split final demand'!I21 -> #DIV/0! | F11: =IF(SUM($E$9:$E$11)=0,0,E11/SUM($E$9:$E$11)) -> #DIV/0!
C13: Electricity | D13: =technical_specs!C16 -> Electric Heaters (resistance) (space heating) | E13: ='Technology split final demand'!I16 -> #DIV/0! | F13: =IF(SUM($E$13:$E$16)=0,1,E13/SUM($E$13:$E$16)) -> #DIV/0!
D14: =technical_specs!C14 -> electricity-driven Heat pump (air) (space heating) | E14: ='Technology split final demand'!I14 -> #DIV/0! | F14: =IF(SUM($E$13:$E$16)=0,0,E14/SUM($E$13:$E$16)) -> #DIV/0!
D15: =technical_specs!C12 -> Electric Heat Pump (ground) (space heating) | E15: ='Technology split final demand'!I12 -> #DIV/0! | F15: =IF(SUM($E$13:$E$16)=0,0,E15/SUM($E$13:$E$16)) -> #DIV/0!
D16: =technical_specs!C20 -> Hybrid heatpump, heatpump part (space heating) | E16: ='Technology split final demand'!I20 -> #DIV/0! | F16: =IF(SUM($E$13:$E$16)=0,0,E16/SUM($E$13:$E$16)) -> #DIV/0!
B18: Hot water
C19: Network gas | D19: =technical_specs!C24 -> Condensing Combi Boiler (hot water) | E19: ='Technology split final demand'!I24 -> #DIV/0! | F19: =IF(SUM($E$19:$E$21)=0,0,E19/SUM($E$19:$E$21)) -> #DIV/0!
D20: =technical_specs!C30 -> Gas-fired Heaters (hot water) | E20: ='Technology split final demand'!I30 -> #DIV/0! | F20: =IF(SUM($E$19:$E$21)=0,0,E20/SUM($E$19:$E$21)) -> #DIV/0!
D21: =technical_specs!C34 -> Hybrid heatpump, gas part (hot water) | E21: ='Technology split final demand'!I34 -> #DIV/0! | F21: =IF(SUM($E$19:$E$21)=0,0,E21/SUM($E$19:$E$21)) -> #DIV/0!
C23: Electricity | D23: =technical_specs!C27 -> electricity-driven Heat pump (air) (hot water) | E23: ='Technology split final demand'!I27 -> #DIV/0! | F23: =IF(SUM($E$23:$E$26)=0,0,E23/SUM($E$23:$E$26)) -> #DIV/0!
D24: =technical_specs!C25 -> Electric Heat Pump (ground) (hot water) | E24: ='Technology split final demand'!I25 -> #DIV/0! | F24: =IF(SUM($E$23:$E$26)=0,0,E24/SUM($E$23:$E$26)) -> #DIV/0!
D25: =technical_specs!C29 -> Electric Heaters (resistance) (hot water) | E25: ='Technology split final demand'!I29 -> #DIV/0! | F25: =IF(SUM($E$23:$E$26)=0,0,E25/SUM($E$23:$E$26)) -> #DIV/0!
D26: =technical_specs!C33 -> Hybrid heatpump, heatpump part (hot water) | E26: ='Technology split final demand'!I33 -> #DIV/0! | F26: =IF(SUM($E$23:$E$26)=0,0,E26/SUM($E$23:$E$26)) -> #DIV/0!
B28: Space heating / hot water
C29: Solar thermal | D29: ='Technology split final demand'!#REF! -> #REF! | E29: ='Technology split final demand'!#REF! -> #REF! | F29: =IF(SUM($E$29:$E$29)=0,1,E29/SUM($E$29:$E$29)) -> #REF!
B31: Space cooling
C32: Electricity | D32: =technical_specs!C39 -> Conventional electric airconditioning | E32: ='Technology split final demand'!I39 -> #DIV/0! | F32: =IF(SUM($E$32:$E$34)=0,1,E32/SUM($E$32:$E$34)) -> #DIV/0!
D33: =technical_specs!C37 -> Electric heat pump ground | E33: ='Technology split final demand'!I37 -> #DIV/0! | F33: =IF(SUM($E$32:$E$34)=0,0,E33/SUM($E$32:$E$34)) -> #DIV/0!
D34: =technical_specs!C38 -> Electric heat pump air | E34: ='Technology split final demand'!I38 -> #DIV/0! | F34: =IF(SUM($E$32:$E$34)=0,0,E34/SUM($E$32:$E$34)) -> #DIV/0!
B36: Cooking
C37: Electricity | D37: =technical_specs!C44 -> Electric halogen stoves | E37: ='Technology split final demand'!I44 -> #DIV/0! | F37: =IF(SUM($E$37:$E$39)=0,0,E37/SUM($E$37:$E$39)) -> #DIV/0!
D38: =technical_specs!C45 -> Electric induction stoves | E38: ='Technology split final demand'!I45 -> #DIV/0! | F38: =IF(SUM($E$37:$E$39)=0,0,E38/SUM($E$37:$E$39)) -> #DIV/0!
D39: =technical_specs!C43 -> Electric stoves (resistance) | E39: ='Technology split final demand'!I43 -> #DIV/0! | F39: =IF(SUM($E$37:$E$39)=0,1,E39/SUM($E$37:$E$39)) -> #DIV/0!
B41: Lighting
C42: Electricity
D43: =technical_specs!C50 -> Low energy light bulbs / fluorescent lighting | E43: ='Technology split final demand'!I50 -> #DIV/0! | F43: =IF(SUM($E$43:$E$45)=0,1,E43/SUM($E$43:$E$45)) -> #DIV/0!
D44: =technical_specs!C49 -> Incandescent lamps | E44: ='Technology split final demand'!I49 -> #DIV/0! | F44: =IF(SUM($E$43:$E$45)=0,0,E44/SUM($E$43:$E$45)) -> #DIV/0!
D45: =technical_specs!C51 -> LED lamps | E45: ='Technology split final demand'!I51 -> #DIV/0! | F45: =IF(SUM($E$43:$E$45)=0,0,E45/SUM($E$43:$E$45)) -> #DIV/0!
B47: Electric Appliances
C48: Electricity
D49: ='Final demand per energy carrier'!C61 -> Dishwashers | E49: ='Final demand per energy carrier'!D61 -> 0 | F49: =IF(SUM($E$49:$E$56)=0,0,E49/SUM($E$49:$E$56)) -> 0
D50: ='Final demand per energy carrier'!C62 -> Fridges / Freezers | E50: ='Final demand per energy carrier'!D62 -> 0 | F50: =IF(SUM($E$49:$E$56)=0,0,E50/SUM($E$49:$E$56)) -> 0
D51: ='Final demand per energy carrier'!C63 -> Washing Machines | E51: ='Final demand per energy carrier'!D63 -> 0 | F51: =IF(SUM($E$49:$E$56)=0,0,E51/SUM($E$49:$E$56)) -> 0
...

Sheet Final demand per energy carrier
B2: Final demand per energy carrier
B4: Notes
B5: In this sheet an overview is presented of the allocation of energy carriers over the different technologies and applications. At the bottom of this sheet the size of the electrical appliances and the other appliances are determined.
B7: Final demand per energy carrier | M7: CALCULATING INPUT SHARES FOR HYBRID HEAT PUMP NODES
B9: Application | C9: Technology used | D9: Percentage of final demand | E9: Final demand for network gas (TJ) | F9: Final demand for electricity (TJ) | G9: Final demand for solar thermal (TJ) | H9: Final demand for coal (TJ) | I9: Final demand for oil (TJ) | J9: Final demand for woodpellets (TJ) | K9: Final demand for district heat (TJ) | M9: COP | N9: Final demand for ambient_heat | O9: Total demand HHP | P9: input.electricity | Q9: input.network_gas | R9: input.ambient_heat
B10: Total IEA value
C11: All | E11: =Final_demand_gas -> 0 | F11: =Final_demand_electricity -> 0 | G11: =Final_demand_solar_thermal -> 0 | H11: =Final_demand_coal -> 0 | I11: =Final_demand_oil -> 0 | J11: =Final_demand_woodpellets -> 0 | K11: =Final_demand_heat -> 0
B14: ='Technology split final demand'!B10 -> Space Heating
C15: ='Technology split final demand'!C11 -> Condensing Combi Boiler (space heating) | D15: ='Technology split final demand'!I11 -> #DIV/0! | E15: =D15*Final_demand_space_heating -> #DIV/0!
C16: ='Technology split final demand'!C12 -> Electric Heat Pump (ground) (space heating) | D16: ='Technology split final demand'!I12 -> #DIV/0! | F16: =D16*Final_demand_space_heating -> #DIV/0!
C17: ='Technology split final demand'!C13 -> District Heating (space heating) | D17: ='Technology split final demand'!I13 -> #DIV/0! | K17: =D17*Final_demand_space_heating -> #DIV/0!
C18: ='Technology split final demand'!C14 -> electricity-driven Heat pump (air) (space heating) | D18: ='Technology split final demand'!I14 -> #DIV/0! | F18: =D18*Final_demand_space_heating -> #DIV/0!
C19: ='Technology split final demand'!C15 -> woodpellets (biomass) heaters (space heating) | D19: ='Technology split final demand'!I15 -> #DIV/0! | J19: =D19*Final_demand_space_heating -> #DIV/0!
C20: ='Technology split final demand'!C16 -> Electric Heaters (resistance) (space heating) | D20: ='Technology split final demand'!I16 -> #DIV/0! | F20: =D20*Final_demand_space_heating -> #DIV/0!
C21: ='Technology split final demand'!C17 -> Gas-fired Heaters (space heating) | D21: ='Technology split final demand'!I17 -> #DIV/0! | E21: =D21*Final_demand_space_heating -> #DIV/0!
C22: ='Technology split final demand'!C18 -> Oil-fired Heaters (space heating) | D22: ='Technology split final demand'!I18 -> #DIV/0! | I22: =D22*Final_demand_space_heating -> #DIV/0!
C23: ='Technology split final demand'!C19 -> Coal-fired Heaters (space heating) | D23: ='Technology split final demand'!I19 -> #DIV/0! | H23: =D23*Final_demand_space_heating -> #DIV/0!
C24: Hybrid Heatpump, Heatpump part (space heating) | D24: ='Technology split final demand'!I20 -> #DIV/0! | F24: =D24*Final_demand_space_heating -> #DIV/0! | M24: =technical_specs!O20 -> 3.5000066 | N24: =F24*M24 -> #DIV/0! | O24: =SUM(N24,F24,E25) -> #DIV/0! | P24: =F24/$O24 -> #DIV/0! | Q24: =E25/$O24 -> #DIV/0! | R24: =N24/$O24 -> #DIV/0!
C25: Hybrid Heatpump, Gas part (space heating) | D25: ='Technology split final demand'!I21 -> #DIV/0! | E25: =D25*Final_demand_space_heating -> #DIV/0!
B27: ='Technology split final demand'!B23 -> Hot Water
C28: ='Technology split final demand'!C24 -> Condensing Combi Boiler (hot water) | D28: ='Technology split final demand'!I24 -> #DIV/0! | E28: =D28*Final_demand_hot_water -> #DIV/0!
C29: ='Technology split final demand'!C25 -> Electric Heat Pump (ground) (hot water) | D29: ='Technology split final demand'!I25 -> #DIV/0! | F29: =D29*Final_demand_hot_water -> #DIV/0!
C30: ='Technology split final demand'!C26 -> District Heating (hot water) | D30: ='Technology split final demand'!I26 -> #DIV/0! | K30: =D30*Final_demand_hot_water -> #DIV/0!
C31: ='Technology split final demand'!C27 -> electricity-driven Heat pump (air) (hot water) | D31: ='Technology split final demand'!I27 -> #DIV/0! | F31: =D31*Final_demand_hot_water -> #DIV/0!
C32: ='Technology split final demand'!C28 -> woodpellets (biomass) heaters (hot water) | D32: ='Technology split final demand'!I28 -> #DIV/0! | J32: =D32*Final_demand_hot_water -> #DIV/0!
C33: ='Technology split final demand'!C29 -> Electric Heaters (resistance) (hot water) | D33: ='Technology split final demand'!I29 -> #DIV/0! | F33: =D33*Final_demand_hot_water -> #DIV/0!
C34: ='Technology split final demand'!C30 -> Gas-fired Heaters (hot water) | D34: ='Technology split final demand'!I30 -> #DIV/0! | E34: =D34*Final_demand_hot_water -> #DIV/0!
C35: ='Technology split final demand'!C31 -> Oil-fired Heaters (hot water) | D35: ='Technology split final demand'!I31 -> #DIV/0! | I35: =D35*Final_demand_hot_water -> #DIV/0!
C36: ='Technology split final demand'!C32 -> Coal-fired Heaters (hot water) | D36: ='Technology split final demand'!I32 -> #DIV/0! | H36: =D36*Final_demand_hot_water -> #DIV/0!
C37: ='Technology split final demand'!C33 -> Hybrid heatpump, heatpump part (hot water) | D37: ='Technology split final demand'!I33 -> #DIV/0! | F37: =D37*Final_demand_hot_water -> #DIV/0! | M37: =technical_specs!O33 -> 1 | N37: =F37*M37 -> #DIV/0! | O37: =SUM(N37,F37,E38) -> #DIV/0! | P37: =F37/$O37 -> #DIV/0! | Q37: =E38/$O37 -> #DIV/0! | R37: =N37/$O37 -> #DIV/0!
C38: ='Technology split final demand'!C34 -> Hybrid heatpump, gas part (hot water) | D38: ='Technology split final demand'!I34 -> #DIV/0! | E38: =D38*Final_demand_hot_water -> #DIV/0!
B40: ='Technology split final demand'!B36 -> Space Cooling
C41: ='Technology split final demand'!C37 -> Electric heat pump ground | D41: ='Technology split final demand'!I37 -> #DIV/0! | F41: =D41*Final_demand_cooling -> #DIV/0!
C42: ='Technology split final demand'!C38 -> Electric heat pump air | D42: ='Technology split final demand'!I38 -> #DIV/0! | F42: =D42*Final_demand_cooling -> #DIV/0!
C43: ='Technology split final demand'!C39 -> Conventional electric airconditioning | D43: ='Technology split final demand'!I39 -> #DIV/0! | F43: =D43*Final_demand_cooling -> #DIV/0!
B46: ='Technology split final demand'!B41 -> Cooking
C47: ='Technology split final demand'!C42 -> Gas stoves | D47: ='Technology split final demand'!I42 -> #DIV/0! | E47: =$D47*Final_demand_cooking -> #DIV/0!
C48: ='Technology split final demand'!C43 -> Electric stoves (resistance) | D48: ='Technology split final demand'!I43 -> #DIV/0! | F48: =$D48*Final_demand_cooking -> #DIV/0!
C49: ='Technology split final demand'!C44 -> Electric halogen stoves | D49: ='Technology split final demand'!I44 -> #DIV/0! | F49: =$D49*Final_demand_cooking -> #DIV/0!
C50: ='Technology split final demand'!C45 -> Electric induction stoves | D50: ='Technology split final demand'!I45 -> #DIV/0! | F50: =$D50*Final_demand_cooking -> #DIV/0!
...

Sheet Technology split final demand
B2: Conversion 'useful demand shares' to 'final demand shares'
B4: Notes
B5: In this sheet the percentages of heat delivered are converted in percentages of final demand converted per technology by using the technological efficiencies specified in the sheet 'Technological specifications'. An exception to this workflow are the percentages of final demand for district heating, biomass heating and solar thermal panels, which have been directly determined in the sheet 'Final demand extracted from EB'.
B7: Percentages of energy demand
B9: Application | C9: Technology | D9: Percentage of useful demand delivered per technology (Dashboard input) | E9: Percentage of useful demand delivered per subtechnology (same as column D except for HHP) | F9: Effective Efficiency (heating) (Technology specification) | G9: Share of demand allocated to final demand in residences | H9: Relative size of final demand converted by this technology | I9: Percentage of final demand converted by this technology
B10: Space Heating
C11: =technical_specs!C11 -> Condensing Combi Boiler (space heating) | D11: =Dashboard!E31 -> 0 | E11: =D11 -> 0 | F11: =Eff_space_heating_combi_boiler -> 0 | G11: 1 | H11: =E11/F11*G11 -> #DIV/0! | I11: =H11/SUM($H$11:$H$21) -> #DIV/0!
C12: =technical_specs!C12 -> Electric Heat Pump (ground) (space heating) | D12: =Dashboard!E32 -> 0 | E12: =D12 -> 0 | F12: =Eff_space_heating_pump_ground -> #DIV/0! | G12: 1 | H12: =E12/F12*G12 -> #DIV/0! | I12: =H12/SUM($H$11:$H$21) -> #DIV/0!
C13: =technical_specs!C13 -> District Heating (space heating) | D13: =Dashboard!E33 -> 0 | E13: =D13 -> 0 | F13: =Eff_space_heating_district -> 0 | G13: 1 | H13: =E13/F13*G13 -> #DIV/0! | I13: =H13/SUM($H$11:$H$21) -> #DIV/0!
C14: =technical_specs!C14 -> electricity-driven Heat pump (air) (space heating) | D14: =Dashboard!E34 -> 0 | E14: =D14 -> 0 | F14: =Eff_space_heating_pump_air -> #DIV/0! | G14: 1 | H14: =E14/F14*G14 -> #DIV/0! | I14: =H14/SUM($H$11:$H$21) -> #DIV/0!
C15: =technical_specs!C15 -> woodpellets (biomass) heaters (space heating) | D15: =Dashboard!E35 -> 0 | E15: =D15 -> 0 | F15: =Eff_space_heating_woodpellets -> 0 | G15: 1 | H15: =E15/F15*G15 -> #DIV/0! | I15: =H15/SUM($H$11:$H$21) -> #DIV/0!
C16: =technical_specs!C16 -> Electric Heaters (resistance) (space heating) | D16: =Dashboard!E36 -> 0 | E16: =D16 -> 0 | F16: =Eff_space_heating_electric -> 0 | G16: 1 | H16: =E16/F16*G16 -> #DIV/0! | I16: =H16/SUM($H$11:$H$21) -> #DIV/0!
C17: =technical_specs!C17 -> Gas-fired Heaters (space heating) | D17: =Dashboard!E37 -> 0 | E17: =D17 -> 0 | F17: =Eff_space_heating_gas -> 0 | G17: 1 | H17: =E17/F17*G17 -> #DIV/0! | I17: =H17/SUM($H$11:$H$21) -> #DIV/0!
C18: =technical_specs!C18 -> Oil-fired Heaters (space heating) | D18: =Dashboard!E38 -> 0 | E18: =D18 -> 0 | F18: =Eff_space_heating_oil -> 0 | G18: 1 | H18: =E18/F18*G18 -> #DIV/0! | I18: =H18/SUM($H$11:$H$21) -> #DIV/0!
C19: =technical_specs!C19 -> Coal-fired Heaters (space heating) | D19: =Dashboard!E39 -> 0 | E19: =D19 -> 0 | F19: =Eff_space_heating_coal -> 0 | G19: 1 | H19: =E19/F19*G19 -> #DIV/0! | I19: =H19/SUM($H$11:$H$21) -> #DIV/0!
C20: =technical_specs!C20 -> Hybrid heatpump, heatpump part (space heating) | D20: =Dashboard!E40 -> 0 | E20: =D20*(1-technical_specs!Q21) -> 0 | F20: =Eff_space_heating_hhp_heatpump -> 3.5000066 | G20: 1 | H20: =E20/F20*G20 -> 0 | I20: =H20/SUM($H$11:$H$21) -> #DIV/0!
C21: =technical_specs!C21 -> Hybrid heatpump, gas part (space heating) | E21: =D20*technical_specs!Q21 -> 0 | F21: =Eff_space_heating_hhp_gas -> 0 | G21: 1 | H21: =E21/F21*G21 -> #DIV/0! | I21: =H21/SUM($H$11:$H$21) -> #DIV/0!
B23: Hot Water
C24: =technical_specs!C24 -> Condensing Combi Boiler (hot water) | D24: =Dashboard!E44 -> 0 | E24: =D24 -> 0 | F24: =Eff_hot_water_combi_boiler -> 0 | G24: 1 | H24: =E24/F24*G24 -> #DIV/0! | I24: =H24/SUM($H$24:$H$34) -> #DIV/0!
C25: =technical_specs!C25 -> Electric Heat Pump (ground) (hot water) | D25: =Dashboard!E45 -> 0 | E25: =D25 -> 0 | F25: =Eff_hot_water_pump_ground -> #DIV/0! | G25: 1 | H25: =E25/F25*G25 -> #DIV/0! | I25: =H25/SUM($H$24:$H$34) -> #DIV/0!
C26: =technical_specs!C26 -> District Heating (hot water) | D26: =Dashboard!E46 -> 0 | E26: =D26 -> 0 | F26: =Eff_hot_water_district -> 0 | G26: 1 | H26: =E26/F26*G26 -> #DIV/0! | I26: =H26/SUM($H$24:$H$34) -> #DIV/0!
C27: =technical_specs!C27 -> electricity-driven Heat pump (air) (hot water) | D27: =Dashboard!E47 -> 0 | E27: =D27 -> 0 | F27: =Eff_hot_water_pump_air -> #DIV/0! | G27: 1 | H27: =E27/F27*G27 -> #DIV/0! | I27: =H27/SUM($H$24:$H$34) -> #DIV/0!
C28: =technical_specs!C28 -> woodpellets (biomass) heaters (hot water) | D28: =Dashboard!E48 -> 0 | E28: =D28 -> 0 | F28: =Eff_hot_water_woodpellets -> 0 | G28: 1 | H28: =E28/F28*G28 -> #DIV/0! | I28: =H28/SUM($H$24:$H$34) -> #DIV/0!
C29: =technical_specs!C29 -> Electric Heaters (resistance) (hot water) | D29: =Dashboard!E49 -> 0 | E29: =D29 -> 0 | F29: =Eff_hot_water_electric -> 0 | G29: 1 | H29: =E29/F29*G29 -> #DIV/0! | I29: =H29/SUM($H$24:$H$34) -> #DIV/0!
C30: =technical_specs!C30 -> Gas-fired Heaters (hot water) | D30: =Dashboard!E50 -> 0 | E30: =D30 -> 0 | F30: =Eff_hot_water_gas -> 0 | G30: 1 | H30: =E30/F30*G30 -> #DIV/0! | I30: =H30/SUM($H$24:$H$34) -> #DIV/0!
C31: =technical_specs!C31 -> Oil-fired Heaters (hot water) | D31: =Dashboard!E51 -> 0 | E31: =D31 -> 0 | F31: =Eff_hot_water_oil -> 0 | G31: 1 | H31: =E31/F31*G31 -> #DIV/0! | I31: =H31/SUM($H$24:$H$34) -> #DIV/0!
C32: =technical_specs!C32 -> Coal-fired Heaters (hot water) | D32: =Dashboard!E52 -> 0 | E32: =D32 -> 0 | F32: =Eff_hot_water_coal -> 0 | G32: 1 | H32: =E32/F32*G32 -> #DIV/0! | I32: =H32/SUM($H$24:$H$34) -> #DIV/0!
C33: =technical_specs!C33 -> Hybrid heatpump, heatpump part (hot water) | D33: =Dashboard!E53 -> 0 | E33: =D33*(1-technical_specs!Q34) -> #DIV/0! | F33: =Eff_hot_water_hhp_heatpump -> 1 | G33: 1 | H33: =E33/F33*G33 -> #DIV/0! | I33: =H33/SUM($H$24:$H$34) -> #DIV/0!
C34: =technical_specs!C34 -> Hybrid heatpump, gas part (hot water) | E34: =D33*technical_specs!Q34 -> #DIV/0! | F34: =Eff_hot_water_hhp_gas -> 0 | G34: 1 | H34: =E34/F34*G34 -> #DIV/0! | I34: =H34/SUM($H$24:$H$34) -> #DIV/0!
B36: Space Cooling
C37: =technical_specs!C37 -> Electric heat pump ground | D37: =Dashboard!E57 -> 0 | E37: =D37 -> 0 | F37: =Eff_cooling_pump_ground -> #DIV/0! | H37: =E37/F37 -> #DIV/0! | I37: =H37/SUM($H$37:$H$39) -> #DIV/0!
C38: =technical_specs!C38 -> Electric heat pump air | D38: =Dashboard!E58 -> 0 | E38: =D38 -> 0 | F38: =Eff_cooling_pump_air -> #DIV/0! | H38: =E38/F38 -> #DIV/0! | I38: =H38/SUM($H$37:$H$39) -> #DIV/0!
C39: =technical_specs!C39 -> Conventional electric airconditioning | D39: =Dashboard!E59 -> 0 | E39: =D39 -> 0 | F39: =Eff_cooling_airco -> #DIV/0! | H39: =E39/F39 -> #DIV/0! | I39: =H39/SUM($H$37:$H$39) -> #DIV/0!
B41: Cooking
C42: =technical_specs!C42 -> Gas stoves | D42: =Dashboard!E69 -> 0 | E42: =D42 -> 0 | F42: =Eff_cooking_gas -> 0 | H42: =E42/F42 -> #DIV/0! | I42: =H42/SUM($H$42:$H$46) -> #DIV/0!
C43: =technical_specs!C43 -> Electric stoves (resistance) | D43: =Dashboard!E70 -> 0 | E43: =D43 -> 0 | F43: =Eff_cooking_electric -> 0 | H43: =E43/F43 -> #DIV/0! | I43: =H43/SUM($H$42:$H$46) -> #DIV/0!
C44: =technical_specs!C44 -> Electric halogen stoves | D44: =Dashboard!E71 -> 0 | E44: =D44 -> 0 | F44: =Eff_cooking_halogen -> 0 | H44: =E44/F44 -> #DIV/0! | I44: =H44/SUM($H$42:$H$46) -> #DIV/0!
C45: =technical_specs!C45 -> Electric induction stoves | D45: =Dashboard!E72 -> 0 | E45: =D45 -> 0 | F45: =Eff_cooking_induction -> 0 | H45: =E45/F45 -> #DIV/0! | I45: =H45/SUM($H$42:$H$46) -> #DIV/0!
C46: =technical_specs!C46 -> Biomass stoves | D46: =Dashboard!E73 -> 0 | E46: =D46 -> 0 | F46: =Eff_cooking_biomass -> 0 | H46: =E46/F46 -> #DIV/0! | I46: =H46/SUM($H$42:$H$46) -> #DIV/0!
B48: Lighting
...

Sheet Fuel aggregation
B2: Fuel Aggregation
B4: Notes
B5: In this sheet the carriers from the energy balance are summed into the carriers that are being used in the commercial and public services sector of the ETM. The result for other carriers should be zero, because these carriers cannot be used in the commercial and public services sector. To see what you should do, please see the dashboard. If you want to trace the problem, please check the energy balance for red cells.
B7: Final demand per energy carrier
B9: Application | C9: Coal | D9: Natural gas | E9: Oil | F9: Woodpellets | G9: Solar thermal | H9: Other | I9: Electricity | J9: Heat | K9: Total demand of aggregated carriers | L9: Total demand in energy balance
B11: Final demand per energy carrier (TJ) | C11: =SUM('Corrected energy balance step 2'!C82:N82)+'Corrected energy balance step 2'!S82 -> 0 | D11: ='Corrected energy balance step 2'!T82+'Corrected energy balance step 2'!AV82 -> 0 | E11: =SUM('Corrected energy balance step 2'!U82:AQ82) -> 0 | F11: ='Corrected energy balance step 2'!AU82+'Corrected energy balance step 2'!AZ82 -> 0 | G11: ='Corrected energy balance step 2'!BH82 -> 0 | H11: =SUM('Corrected energy balance step 2'!O82:R82,'Corrected energy balance step 2'!AR82:AT82,'Corrected energy balance step 2'!AV82:AZ82,,'Corrected energy balance step 2'!BB82:BE82,'Corrected energy balance step 2'!BF82:BG82,'Corrected energy balance step 2'!BI82:BK82) -> 0 | I11: ='Corrected energy balance step 2'!BL82 -> 0 | J11: ='Corrected energy balance step 2'!BM82 -> 0 | K11: =SUM(C11:J11) -> 0 | L11: ='Corrected energy balance step 2'!BN82 -> 0
B12: Name in Excel file | C12: Final_demand_coal | D12: Final_demand_gas | E12: Final_demand_oil | F12: Final_demand_woodpellets | G12: Final_demand_solar_thermal | H12: Final_demand_other | I12: Final_demand_electricity | J12: Final_demand_heat | L12: Final_demand_residences
K16: Check:
K17: If the
K18: ="- total demand of aggregated carriers" -> - total demand of aggregated carriers
K19: ="- total demand in energy balance" -> - total demand in energy balance
K20: are the same,,
K21: the energy carriers have been aggregated correctly.
K23: Difference: | L23: =K11-Final_demand_residences -> 0
K24: It is possible that the energy balance of particular countries contains carriers that we do not aggregate to ETM carriers. In that case, this check will fail. For example, we currently do not consider Charcoal in this analysis.

Sheet HHP input shares
B2: HHP input shares
B4: We had troubles with the formerly fixed input shares in HHPs in households. Therefore, we have made these input shares for HHPs dynamic: they can now be set per dataset. For this change, I have added hard-coded input shares for HHPs to 'technical_specs' tab, sbecause this analysis needs the input shares as input. For NL2015 and other country datasets these hard -coded shares have been used. I have also added two new csv-files where the input shares are calculated for HHPs in households.
D8: Final demand households [energy balance] | E8: Share to space heating | F8: Share to HHP space heating | G8: COP | H8: Final demand for HHP | I8: Input shares HHP node
B9: HHP space heating | C9: Network gas | D9: =Final_demand_gas -> 0 | E9: ='Application Shares'!E17 -> #DIV/0! | F9: ='Technology Shares'!F11 -> #DIV/0! | H9: =D9*E9*F9 -> #DIV/0! | I9: =H9/SUM(H$9:H$11) -> #DIV/0!
C10: Electricity | D10: =Final_demand_electricity -> 0 | E10: ='Application Shares'!E28 -> #DIV/0! | F10: ='Technology Shares'!F16 -> #DIV/0! | G10: =technical_specs!O20 -> 3.5000066 | H10: =D10*E10*F10 -> #DIV/0! | I10: =H10/SUM(H$9:H$11) -> #DIV/0!
C11: Ambient heat | H11: =H10*G10 -> #DIV/0! | I11: =H11/SUM(H$9:H$11) -> #DIV/0!
E13: Share to hot water | F13: Share to HHP hot water | H13: Final demand for HHP | I13: Input shares HHP node
B14: HHP hot water | C14: Network gas | D14: =Final_demand_gas -> 0 | E14: ='Application Shares'!E18 -> #DIV/0! | F14: ='Technology Shares'!F21 -> #DIV/0! | H14: =D14*E14*F14 -> #DIV/0! | I14: =H14/SUM(H$14:H$16) -> #DIV/0!
C15: Electricity | D15: =Final_demand_electricity -> 0 | E15: ='Application Shares'!E29 -> #DIV/0! | F15: ='Technology Shares'!F26 -> #DIV/0! | G15: =technical_specs!O33 -> 1 | H15: =D15*E15*F15 -> #DIV/0! | I15: =H15/SUM(H$14:H$16) -> #DIV/0!
C16: Ambient heat | H16: =H15*G15 -> #DIV/0! | I16: =H16/SUM(H$14:H$16) -> #DIV/0!

Sheet Useful-final demand percentage
B2: Useful and final demand conversion - reproducing Dashboard figures
B4: Notes
B5: In this sheet the percentages of useful demand delivered by a technology are defined. The figures reproduce the Dashboard input.
B7: Technology Splits
C9: Technology | D9: Percentage of final demand converted per technology | E9: Final demand converted per technology (TJ) | F9: Effective efficiency | G9: Useful demand created per subtechnology (same as column H, except for HHP) (TJ) | H9: Useful demand created per technology (TJ) | I9: Percentage of useful demand delivered per technology, Dashboard figures
B10: Space Heating
C11: ='Technology split final demand'!C11 -> Condensing Combi Boiler (space heating) | D11: ='Technology split final demand'!I11 -> #DIV/0! | E11: =Final_demand_space_heating*D11 -> #DIV/0! | F11: =technical_specs!R11 -> 0 | G11: =F11*E11 -> #DIV/0! | H11: =G11 -> #DIV/0! | I11: =H11/SUM($H$11:$H$21) -> #DIV/0!
C12: ='Technology split final demand'!C12 -> Electric Heat Pump (ground) (space heating) | D12: ='Technology split final demand'!I12 -> #DIV/0! | E12: =Final_demand_space_heating*D12 -> #DIV/0! | F12: =technical_specs!R12 -> #DIV/0! | G12: =F12*E12 -> #DIV/0! | H12: =G12 -> #DIV/0! | I12: =H12/SUM($H$11:$H$21) -> #DIV/0!
