Workbook
Name base_year: Dashboard!$E$12
Name country: Dashboard!$E$11
Name Eff_cooling_air_heatpump: technical_specs!$L$27
Name Eff_cooling_airco: technical_specs!$L$26
Name Eff_cooling_pump: technical_specs!$L$24
Name Eff_cooling_pump_storage: technical_specs!$L$25
Name Eff_lighting_lamp_fluorescent: technical_specs!#REF!
Name Eff_lighting_lamp_incandescent: technical_specs!#REF!
Name Eff_lighting_led: technical_specs!$L$32
Name Eff_lighting_tube_fluorescent_efficient: technical_specs!$L$31
Name Eff_lighting_tube_fluorescent_standartd: technical_specs!$L$30
Name Eff_space_heating_air_heatpump: technical_specs!$M$18+technical_specs!$L$17
Name Eff_space_heating_coal: technical_specs!$L$15
Name Eff_space_heating_district: technical_specs!$L$21
Name Eff_space_heating_electric: technical_specs!$L$14
Name Eff_space_heating_gas: technical_specs!$L$11
Name Eff_space_heating_oil: technical_specs!$L$16
Name Eff_space_heating_pump_gas: technical_specs!$L$13
Name Eff_space_heating_pump_storage: technical_specs!$L$12
Name Eff_space_heating_solar_thermal: technical_specs!$L$19
Name Eff_space_heating_woodpellets: technical_specs!$L$20
Name Final_demand_lighting: Dashboard!$E$25
Name Final_demand_residences: 'Fuel aggregation'!$L$11
Name Final_demand_space_cooling: Dashboard!$E$24
Name Final_demand_space_heating: Dashboard!$E$23

Sheet Cover Sheet
B2: Cover Sheet
B4: Document | C4: Commercial and Public Services analysis
B5: Version # | C5: =MAX(Changelog!D:D) -> 1.42
B6: Country | C6: =Dashboard!E11 -> nl
B7: Year data | C7: =Dashboard!E12 -> 2023
B8: Date | C8: 46041
B9: Author | C9: Kyra de Haan
B10: Organization | C10: Quintel
B12: Legend
B14: Cells | C14: Intermediate (calculation)
C15: Result
C16: Manual input
C17: Reference to manual input or data input
B19: Tabs | C19: Introductory
C20: Research data
C21: Sources
C22: Dashboard
C23: Results
C24: Main calculations
C25: Additional calculations
C26: CSV-files
B29: Comments

Sheet Changelog
B2: Changelog
B4: Date | C4: Changes | D4: Version
B6: 41450 | C6: Created this document | D6: 1
B7: 41452 | C7: Deleted all source analysis | D7: 1.01
B8: 41457 | C8: Improved lay-out | D8: 1.02
B9: 41457 | C9: Added dataflow V3.2 | D9: 1.03
B10: 41458 | C10: Added all carriers | D10: 1.04
B11: 41459 | C11: Added auto-producers table to calculate PV solar | D11: 1.05
B12: 41460 | C12: Changed dataflow to V5 | D12: 1.06
B13: 41463 | C13: Various improvements | D13: 1.07
B14: 41464 | C14: Including backwards calculation SWH | D14: 1.08
B15: 41464 | C15: Removed sources of district heating, included backward calculations for district heating and biomass | D15: 1.09
B16: 41465 | C16: Updated dataflow and included CSV files | D16: 1.1
B17: 41465 | C17: Deleted all non-used carriers and checks and made minor alterations | D17: 1.11
... B35: 41509 | C35: Fixing the order of keys on the dashboard / renaming one key | D35: 1.28
B36: ? | C36: ? | D36: 1.29
B37: 41534 | C37: enabling automatic import of technical specs | D37: 1.3
B38: 41542 | C38: removing Lody's "wrong" efficiencies, replacing them with efficiencies that are imporrted from etsource. Lody's efficiencies can be found in the source analysis folder. | D38: 1.31
B39: 41562 | C39: removing sheets with edges and nodes | D39: 1.32
B40: 41578 | C40: major layout change to dashboard. Improving checks | D40: 1.33
B41: 41578 | C41: added 'Biogases' to network gas aggregation. Renaming natural gas to network gas in some instances | D41: 1.34
B42: 41782 | C42: Implemented if-statement in Application shares to avoid #DIV/0 errors | D42: 1.35
B43: 41782 | C43: Implemented if-statement in Technology share to avoid #DIV/0 errors | D43: 1.36
B44: 42600 | C44: Created an optional split of the central ICT sector (directed to the industry sector in the graph) | D44: 1.37
B45: 44607 | C45: Removed incandescent and fluorescent lighting from analysis | D45: 1.38
B46: November 30, 2023 | C46: Updated technical specs to refer to new district heating node with high temperate (HT). | D46: 1.39
B47: May 28, 2025 | C47: Removed sheet csv_heating_useful_insulation due to updated modelling where insulation has been changed and is now directly applied to the useful demand node, making this output redundant. | D47: 1.4
B48: July 17, 2025 | C48: Add surface water technologies to export CSVs with zero share. | D48: 1.41
B49: 46041 | C49: Remove intelligent light control keys | D49: 1.42

Sheet Contents
B2: Contents
B4: Tab | C4: Description
B6: Cover Sheet | C6: Information about this document and a legend to tab and cell formatting
B7: Changelog | C7: A documentation of the changes to this analysis
B8: Contents | C8: An index with description of all the tabs in this analysis
B9: Introduction | C9: A short introduction to the Energytransition model (ETM) and the Commercial and Public services analysis
B10: Dataflow | C10: A visualization of the dataflow in this analysis
B11: Assumptions | C11: A description of the modeling and country-specific assumptions for this analysis
B12: Dashboard | C12: On the dashboard, the country-specific assumptions can be changed manually. It also shows the most important checks
B13: Corrected energy balance step 2 | C13: Here the corrected energy balance created in the CHP analysis should be pasted for your country and year
B14: Technological specifications | C14: The technological specifications of energy conversion technologies used in the ETM are listed here
B15: Application shares | C15: The split over the several application is defined here for several carriers.
B16: Technology shares | C16: The shares of several technologies with the same application and energy carrier are determined here
... B34: csv_ps_sector_electricity | C34: A CSV-file with a converter output share (parent_share) that sends part of the energy flow to the industry sector, and the rest to the services sector.

Sheet Introduction
B2: Introduction
B4: This analysis
B6: The main goal of this analysis is to create a representative energy use per application for the commercial and public services sector. The applications that are defined in this analysis are: space heating, space cooling, lighting, electric applications and other applications. Note that Solar PV production is not covered by this analysis as that results from the Energy Balance and the Autoproduction table (both available from IEA). To see what solar PV production is for your dataset, open the "2_power_and_heat_plant_analysis", import all the required data (including the Energy Balance and Autoproducer table, which both need to be bought from IEA), and proceed to 'Results by machine' or the 'PV solar' sheets.
B8: Steps to perform this analysis
B10: 1. Import the corrected energy balance using the import button on the Dashboard sheet.
B11: 2. Look over all the assumptions and checks on the Assumptions page and the Dashboard. Consult the documentation for additional information.
B12: 3. Fill in the (country-specific) assumptions on the Dashboard using reliable sources and/or use the source analysis mentioned in the comments. Please document your sources.
B13: 4. Keep in mind the checks on the Dashboard. If a check fails, try to understand what goes wrong and adjust your assumptions as long as you feel it is still realistic
B14: 5. If you encounter other problems please contact Quintel Intelligence
B15: 6. Export the csv files using the export button on the Dashboard sheet.
B18: The Energytransition model
B20: In short, the energytransition model (ETM) is a calculation engine with a front-end interface that is free to be used by private, commercial and public users. The engine exists of a collection of 'converters' that are linked together to approach the structure of an energy system at the country level. It includes for example import, export, electricity and heat production, final demand sectors and useful demand applications. Every converter has technical and economical specifications that were determined from scientific and technical literature. The model's initial configuration is mostly based on 2010 statistical data. Useful demand of energy applications is gathered from other sources. By moving sliders in a front end dashboard, representing energy use, energy production or socio-economical parameters, the calculation engine determines the results from these actions in a future scenario and communicates them to the user.

Sheet Dataflow
B2: Dataflow Commercial and Public Services
B3: Notes
B4: A visualization of the dataflow in this analysis
C6: Analysis inputs | AN6: Analysis calculations | BU6: Analysis ouputs

Sheet Assumptions
B2: Assumptions
B4: Notes
B5: On this page, a description of the assumptions for this analysis is given. There are two types of assumptions, Modeling assumptions and Country specific assumptions. The modeling assumptions form the structure or framework to be able to do this analysis. They are the same for every country. The country specific assumptions must be entered by the researcher on the Dashboard page and are used to correctly adjust the calculations to the specific country. The fuels table gives an overview of how the ETM fuel carriers correspond with the IEA fuel carriers.
B7: Modeling assumptions
B9: Type | C9: Assumption | D9: Source
B10: General
C11: There are three main energy use groups in the built environment: space heating, space cooling and lighting. All other forms of energy use are piled up in this analysis as "other applications". The size and content of this sector is determined by subtracting the use for space heating, space cooling and lighting from the corrected IEA energy balance. The remaining electricity is allocated to electrical appliances and all other carriers are allocated to other appliances.
C12: The factors heat, biomass and solar from the energy balance are directly allocated to space heating by this model to respectively: district heating, biomass heater and solar thermal panels.
C13: The only technologies available for space heating, space cooling and lighting are the ones listed in the dashboard. These technologies are the ones used in the ETM.
C14: The technological specifications of these technologies are the same for all countries.
C15: In residential sector the only source of auto-produced electricity is solar PV. By making this assumption we can determine the amount of electricity produced by solar PV for the commercial and public services sector. But this happens in the PP&HP analysis
C16: The ETM graph contains a number of converters that are used to model future energy saving effects of improved insulation. The inluence of these converters is set to 'zero' in the 'present' scenario:
C17: buildings_cooling_savings_insulation_cooling | D17: results from ETM modelling logic
C18: buildings_heating_savings_from_insulation_useable_heat | D18: results from ETM modelling logic
B21: Country specific assumptions
B23: Type | C23: Assumption | D23: Proposed source
B24: Final demand
C25: Final energy demand used in the Commercial and Public Services sector for Space Heating | D25: Use 'Source analysis Commercial and Pulic services sector' which can be found at ….
C26: Final energy demand used in the Commercial and Public Services sector for Space Cooling | D26: Use 'Source analysis Commercial and Pulic services sector' which can be found at ….
C27: Final energy demand used in the Commercial and Public Services sector for Lighting | D27: Use 'Source analysis Commercial and Pulic services sector' which can be found at ….
B29: Space Heating
C30: Percentage of heat delivered by coal-fired heaters | D30: National energy agency or an expert estimation
C31: Percentage of heat delivered by gas-fired heaters | D31: National energy agency or an expert estimation
C32: Percentage of heat delivered by gas-fired heat pumps | D32: National energy agency or an expert estimation
C33: Percentage of heat delivered by oil-fired heaters | D33: National energy agency or an expert estimation
C34: Percentage of heat delivered by electric heat pumps with thermal storage | D34: National energy agency or an expert estimation
C35: Percentage of heat delivered by electric heaters | D35: National energy agency or an expert estimation
B37: Space Cooling
C38: Percentage of cold delivered by gas-fired heat pumps | D38: National energy agency or an expert estimation
C39: Percentage of cold delivered by electric heat pumps with thermal storage | D39: National energy agency or an expert estimation
C40: Percentage of cold delivered by airconditioning | D40: National energy agency or an expert estimation
B42: Lighting
C43: Percentage of light delivered by incandescent lamps | D43: National energy agency or an expert estimation
C44: Percentage of light delivered by fluorescent lamps | D44: National energy agency or an expert estimation
C45: Percentage of light delivered by standard fluorescent tubes | D45: National energy agency or an expert estimation
C46: Percentage of light delivered by fluorescent tubes | D46: National energy agency or an expert estimation
C47: Percentage of light delivered by LED lamps | D47: National energy agency or an expert estimation
B49: Insulation
C50: Average thermal resistivity of roof | D50: National energy agency or an expert estimation
C51: Average thermal resistivity of floor | D51: National energy agency or an expert estimation
...

Sheet Dashboard
B2: Dashboard | K2: Automatically import/export analysis data
B4: Notes
B5: On this sheet you can fill the country specific assumptions for your country. Please mind the checks, if one or more become red it means that with the information you provided we cannot run the Energy Transition Model. Concerning your assumptions please provide sources.
B7: Assumptions | K7: Checks
B9: Sector | C9: Assumption | D9: Unit | E9: Value | G9: Name | I9: Source | K9: Check | L9: Status | M9: Notes | O9: Key | P9: Critical check
B10: General | K10: All critical checks correct | L10: =IF(COUNTIF(P:P,0)+COUNTIF(P:P,FALSE)=0,TRUE,FALSE) -> FALSE
C11: Country | E11: nl | G11: country | K11: All assumptions are filled | L11: =IF(COUNTBLANK(E11:E64)-COUNTBLANK(C11:C64)=3,TRUE,FALSE) -> FALSE | O11: country | P11: =IF(L11=TRUE,1,0) -> 0
C12: The base year for this analysis | E12: 2023 | G12: base_year | O12: base_year
K14: The following cannot be negative
K15: Coal demand in other appliances | L15: =IF('Final demand per energy carrier'!E43<0,FALSE,TRUE) -> #DIV/0! | M15: =IF(L15=TRUE," ","The demand for coal in 'other appliances' is negative. Have a look at the 'Final demand per energy carrier' sheet. Please correct the application and/or technology splits in the dashboard. ") -> #DIV/0! | P15: =IF(L15=TRUE,1,0) -> #DIV/0!
K16: Network gas demand in other appliances | L16: =IF('Final demand per energy carrier'!F43<0,FALSE,TRUE) -> #DIV/0! | M16: =IF(L16=TRUE," ","The demand for network gas in 'other appliances' is negative. Have a look at the 'Final demand per energy carrier' sheet. Please correct the application and/or technology splits in the dashboard. ") -> #DIV/0! | P16: =IF(L16=TRUE,1,0) -> #DIV/0!
K17: Oil demand in other appliances | L17: =IF('Final demand per energy carrier'!G43<0,FALSE,TRUE) -> #DIV/0! | M17: =IF(L17=TRUE," ","The demand for oil in 'other appliances' is negative. Have a look at the 'Final demand per energy carrier' sheet. Please correct the application and/or technology splits in the dashboard. ") -> #DIV/0! | P17: =IF(L17=TRUE,1,0) -> #DIV/0!
K19: Energy in services sector, not accounted for in ETM: | L19: =IF('Fuel aggregation'!J11=0,TRUE,'Fuel aggregation'!J11) -> TRUE | M19: =IF(L19=TRUE," ","(TJ) There are energy flows related to the services sector that cannot be processed by the ETM. If the amount of disregarded energy is relatively large, consider contacting Quintel Intelligence. Have a look at the fuel aggregation sheet.")
B20: Final demand
C21: Final energy demand Commercial and Public Services (from energy balance) | D21: TJ | E21: =Final_demand_residences -> 0 | I21: Taken from corrected energy balance
C23: Final energy demand used for Space Heating | D23: TJ | G23: Final_demand_space_heating | O23: services_final_demand_space_heating
C24: Final energy demand used for Space Cooling | D24: TJ | G24: Final_demand_space_cooling | O24: services_final_demand_space_cooling
C25: Final energy demand used for Lighting | D25: TJ | G25: Final_demand_lighting | O25: services_final_demand_lighting
C28: Indicate "yes" to add the central ICT sector; also input the required data in row 29 | O28: ict_split
C29: Final electricity demand used for central ICT | D29: TJ | E29: =IF(E28="no",0,"") | G29: Final_demand_industry_ict | K29: Final energy demand for central ICT is a positive number | L29: =IF(E29>=0,TRUE,E29) -> TRUE | M29: =IF(L29=TRUE," ","Please adjust your final demands for space heating, space cooling and lighting (and central ICT, if filled in), or alter the technology shares below.") | O29: industry_final_demand_ict_electricity | P29: =IF(L29=TRUE,1,0) -> 1
C31: Final electricity demand used for Electrical Appliances | D31: TJ | E31: ='Final demand per energy carrier'!J42 -> #DIV/0! | K31: Final energy demand for electrical appliances is a positive number | L31: =IF(E31>0,TRUE,E31) -> #DIV/0! | M31: =IF(L31=TRUE," ","Please adjust your final demands for space heating, space cooling and lighting (and central ICT, if filled in), or alter the technology shares below.") -> #DIV/0! | P31: =IF(L31=TRUE,1,0) -> #DIV/0!
C32: Final energy demand used for other Appliances (non-electric) | D32: TJ | E32: =SUM('Final demand per energy carrier'!E43:G43) -> #DIV/0! | K32: Final energy demand for other appliances is a positive number | L32: =IF(E32>0,TRUE,E32) -> #DIV/0! | M32: =IF(L32=TRUE," ","Please adjust your final demands for space heating, space cooling and/or lighting (and central ICT, if filled in.") -> #DIV/0! | P32: =IF(L32=TRUE,1,0) -> #DIV/0!
B34: Space Heating | K34: Percentages add up to 100% | L34: =IF(SUM(E44:E50)=1,TRUE,SUM(E44:E50)) -> 0 | M34: =IF(L34=TRUE," ","If this check is red please adjust the percentages of heat delivered by the technologies to the left.") -> If this check is red please adjust the percentages of heat delivered by the technologies to the left. | P34: =IF(L34=TRUE,1,0) -> 0
C35: Final energy demand used for space heating | E35: =Final_demand_space_heating -> 0
C37: Final energy use by solar thermal panels | E37: ='Final demand extracted from EB'!D13 -> 0 | I37: extracted from corrected energy balance
C38: Final energy use by biomass-fired heaters | E38: ='Final demand extracted from EB'!D9 -> 0 | I38: extracted from corrected energy balance
C39: Final energy use by district heating | E39: ='Final demand extracted from EB'!D17 -> 0 | I39: extracted from corrected energy balance
C41: Remaining final energy demand for space heating, after solar thermal panels, biomass heaters and district heating: | E41: =E35-SUM(E37:E39) -> 0
C43: Percentage of useful heat delivered by the remaining technologies
C44: Gas-fired heaters | O44: services_space_heating_share_gas_fired_heaters
C45: Electric heat pumps with thermal storage | O45: services_space_heating_share_electric_heat_pump_with_storage
C46: Gas-fired heat pumps | O46: services_space_heating_share_gas_fired_heat_pumps
C47: Electric heaters | O47: services_space_heating_share_electric_heaters
C48: Coal-fired heaters | O48: services_space_heating_share_coal_fired_heater
C49: Oil-fired heaters | O49: services_space_heating_share_oil_fired_heater
C50: Electric air heatpumps | O50: services_space_heating_share_air_heatpump
B52: Space Cooling | K52: Percentages add up to 100% | L52: =IF(SUM(E54:E57)=1,TRUE,SUM(E54:E57)) -> 0 | M52: =IF(L52=TRUE," ","If this check is red please adjust the percentages of heat delivered by the technologies to the left.") -> If this check is red please adjust the percentages of heat delivered by the technologies to the left. | P52: =IF(L52=TRUE,1,0) -> 0
C53: Percentage of useful cold delivered by
C54: Gas-fired heat pumps | O54: services_space_cooling_share_gas_fired_heat_pump
C55: Electric heat pumps with thermal storage | O55: services_space_cooling_share_electric_heat_pump
...

Sheet Corrected energy balance step 2
B2: Corrected energy balance step 2
B4: Notes
B5: Please paste (as values) the energy balance resulting from the Power Plant-analysis (in TeraJoules) for your country in the table below. This data will be used in the analysis.
B7: PRODUCT | C7: Hard coal (if no detail) | D7: Brown coal (if no detail) | E7: Anthracite | F7: Coking coal | G7: Other bituminous coal | H7: Sub-bituminous coal | I7: Lignite | J7: Patent fuel | K7: Coke oven coke | L7: Gas coke | M7: Coal tar | N7: BKB/peat briquettes | O7: Gas works gas | P7: Coke oven gas | Q7: Blast furnace gas | R7: Other recovered gases | S7: Peat | T7: Natural Gas | U7: Crude/NGL/feedstocks (if no detail) | V7: Crude oil | W7: Natural gas liquids | X7: Refinery feedstocks | Y7: Additives/blending components | Z7: Other hydrocarbons | AA7: Refinery gas | AB7: Ethane | AC7: Liquefied petroleum gases (LPG) | AD7: Motor gasoline | AE7: Aviation gasoline | AF7: Gasoline type jet fuel | AG7: Kerosene type jet fuel | AH7: Other Kerosene | AI7: Gas/diesel oil | AJ7: Fuel oil | AK7: Naphtha | AL7: White spirit & SBP | AM7: Lubricants | AN7: Bitumen | AO7: Paraffin waxes | AP7: Petroleum coke | AQ7: Non-specified oil products | AR7: Industrial waste | AS7: Municipal waste (renewable) | AT7: Municipal waste (non-renewable) | AU7: Primary solid biofuels | AV7: Biogases | AW7: Biogasoline | AX7: Biodiesels | AY7: Other liquid biofuels | AZ7: Non-specified primary biofuels and waste | BA7: Charcoal | BB7: Elec/heat output from non-specified manufactured gases | BC7: Heat output from non-specified combustible fuels | BD7: Nuclear | BE7: Hydro | BF7: Geothermal | BG7: Solar photovoltaics | BH7: Solar thermal | BI7: Tide, wave and ocean | BJ7: Wind | BK7: Other sources | BL7: Electricity | BM7: Heat | BN7: Total | BO7: Memo: Renewables
B8: FLOW
B9: Production
B10: Imports
B11: Exports
B12: International marine bunkers
B13: International aviation bunkers
B14: Stock changes
B15: Total primary energy supply
B16: Transfers
B17: Statistical differences
B18: Transformation processes
B19: Main activity producer electricity plants
... B101: Heat output-autoproducer heat plants

Sheet technical_specs
B2: Technological specifications
B4: Notes
B5: Here, the technological specifications are imported from Etsource (automatically). These values are not country-specific and cannot be changed.
B7: Technological Specifications | E7: Extract data from Etsource | F7: Converter attributes | M7: Name in this excel file
B8: Application | C8: Technology | E8: converter key | F8: heat efficiency | G8: 1 / COP | H8: 1 / COP | I8: light efficiency | J8: Efficiency (%) | K8: Coëfficient of Performance (COP) | L8: Effective efficiency
F9: output.useable_heat | G9: input.electricity | H9: input.network_gas | I9: output.light
B11: Space Heating | C11: Gas-fired heater | E11: buildings_space_heater_network_gas.converter | G11: - | H11: - | I11: - | J11: =F11 -> 0 | L11: =J11 -> 0 | M11: Eff_space_heating_gas
C12: Electric heat pump with thermal storage | E12: buildings_space_heater_collective_heatpump_water_water_ts_electricity.converter | H12: - | I12: - | K12: =1/G12 -> #DIV/0! | L12: =K12 -> #DIV/0! | M12: Eff_space_heating_pump_storage
C13: Gas-fired heat pump | E13: buildings_space_heater_heatpump_air_water_network_gas.converter | G13: - | I13: - | K13: =1/H13 -> #DIV/0! | L13: =K13 -> #DIV/0! | M13: Eff_space_heating_pump_gas
C14: Electric heater | E14: buildings_space_heater_electricity.converter | G14: - | H14: - | I14: - | J14: =F14 -> 0 | L14: =J14 -> 0 | M14: Eff_space_heating_electric
C15: Coal-fired heater | E15: buildings_space_heater_coal.converter | G15: - | H15: - | I15: - | J15: =F15 -> 0 | L15: =J15 -> 0 | M15: Eff_space_heating_coal
C16: Oil-fired heater | E16: buildings_space_heater_crude_oil.converter | G16: - | H16: - | I16: - | J16: =F16 -> 0 | L16: =J16 -> 0 | M16: Eff_space_heating_oil
C17: Electric air heatpump | E17: buildings_space_heater_heatpump_air_water_electricity.converter | H17: - | I17: - | K17: =1/G17 -> #DIV/0! | L17: =K17 -> #DIV/0! | M17: Eff_space_heating_air_heatpump
C19: Solar thermal panels | E19: buildings_space_heater_solar_thermal | G19: - | H19: - | I19: - | J19: =F19 -> 0 | L19: =J19 -> 0 | M19: Eff_space_heating_solar_thermal
C20: Biomass-fired heater | E20: buildings_space_heater_wood_pellets.converter | G20: - | H20: - | I20: - | J20: =F20 -> 0 | L20: =J20 -> 0 | M20: Eff_space_heating_woodpellets
C21: District heating | E21: buildings_space_heater_district_heating_ht_steam_hot_water | G21: - | H21: - | I21: - | J21: =F21 -> 0 | L21: =J21 -> 0 | M21: Eff_space_heating_district
B23: Space Cooling
C24: Gas-fired heat pump | E24: buildings_cooling_heatpump_air_water_network_gas.converter | F24: - | G24: - | I24: - | K24: =1/H24 -> #DIV/0! | L24: =K24 -> #DIV/0! | M24: Eff_cooling_pump
C25: Electric heat pump with thermal storage | E25: buildings_cooling_collective_heatpump_water_water_ts_electricity.converter | F25: - | H25: - | I25: - | K25: =1/G25 -> #DIV/0! | L25: =K25 -> #DIV/0! | M25: Eff_cooling_pump_storage
C26: Airconditioning | E26: buildings_cooling_airconditioning_electricity.converter | F26: - | H26: - | I26: - | K26: =1/G26 -> #DIV/0! | L26: =K26 -> #DIV/0! | M26: Eff_cooling_airco
C27: Electric air heatpump | E27: buildings_cooling_heatpump_air_water_electricity.converter | F27: - | H27: - | I27: - | K27: =1/G27 -> #DIV/0! | L27: =K27 -> #DIV/0! | M27: Eff_cooling_air_heatpump
B29: Lighting
C30: Standard fluorescent tubes | E30: buildings_lighting_standard_fluorescent_electricity.converter | F30: - | G30: - | H30: - | J30: =I30 -> 0 | L30: =J30 -> 0 | M30: Eff_lighting_tube_fluorescent_standartd
C31: Efficient fluorescent tubes | E31: buildings_lighting_efficient_fluorescent_electricity.converter | F31: - | G31: - | H31: - | J31: =I31 -> 0 | L31: =J31 -> 0 | M31: Eff_lighting_tube_fluorescent_efficient
C32: LED lamps | E32: buildings_lighting_led_electricity.converter | F32: - | G32: - | H32: - | J32: =I32 -> 0 | L32: =J32 -> 0 | M32: Eff_lighting_led

Sheet Application shares
B2: Shares per carrier per application
B4: Notes
B5: In this sheet the shares per carrier per application needed for the Energy Transition Model are defined. In the last section of the table, the electricity shares per sector are determined for the services sector and industry sector (central ICT).
B7: Carrier | C7: Application | D7: Final demand per carrier per application (TJ) | E7: Shares per carrier per application
B8: Coal
C9: Space heating | D9: =SUM('Final demand per energy carrier'!E15:E23) -> #DIV/0! | E9: =IF(SUM($D$9:$D$10)=0,0,D9/SUM($D$9:$D$10)) -> #DIV/0!
C10: Other appliances | D10: ='Final demand per energy carrier'!E43 -> #DIV/0! | E10: =IF(SUM($D$9:$D$10)=0,1,D10/SUM($D$9:$D$10)) -> #DIV/0!
B12: Network gas
C13: Space heating | D13: =SUM('Final demand per energy carrier'!F15:F23) -> #DIV/0! | E13: =IF(SUM($D$13:$D$15)=0,0,D13/SUM($D$13:$D$15)) -> #DIV/0!
C14: Space cooling | D14: =SUM('Final demand per energy carrier'!F26:F28) -> #DIV/0! | E14: =IF(SUM($D$13:$D$15)=0,0,D14/SUM($D$13:$D$15)) -> #DIV/0!
C15: Other appliances | D15: ='Final demand per energy carrier'!F43 -> #DIV/0! | E15: =IF(SUM($D$13:$D$15)=0,1,D15/SUM($D$13:$D$15)) -> #DIV/0!
B17: Oil
C18: Space heating | D18: =SUM('Final demand per energy carrier'!G15:G23) -> #DIV/0! | E18: =IF(SUM($D$18:$D$19)=0,0,D18/SUM($D$18:$D$19)) -> #DIV/0!
C19: Other appliances | D19: ='Final demand per energy carrier'!G43 -> #DIV/0! | E19: =IF(SUM($D$18:$D$19)=0,1,D19/SUM($D$18:$D$19)) -> #DIV/0!
B21: Electrity
C22: Space heating | D22: =SUM('Final demand per energy carrier'!J15:J23) -> #DIV/0! | E22: =IF(SUM($D$22:$D$25)=0,0,D22/SUM($D$22:$D$25)) -> #DIV/0!
C23: Space cooling | D23: =SUM('Final demand per energy carrier'!J26:J28) -> #DIV/0! | E23: =IF(SUM($D$22:$D$25)=0,0,D23/SUM($D$22:$D$25)) -> #DIV/0!
C24: Lighting | D24: =SUM('Final demand per energy carrier'!J31:J33) -> #DIV/0! | E24: =IF(SUM($D$22:$D$25)=0,0,D24/SUM($D$22:$D$25)) -> #DIV/0!
C25: Electric appliances | D25: ='Final demand per energy carrier'!J42 -> #DIV/0! | E25: =IF(SUM($D$22:$D$25)=0,1,D25/SUM($D$22:$D$25)) -> #DIV/0!
B26: Electrity
C27: Services | D27: =SUM(D22:D25) -> #DIV/0! | E27: =IF(SUM($D$27:$D$28)=0,1,D27/SUM($D$27:$D$28)) -> #DIV/0!
C28: Central ICT | D28: =SUM('Final demand per energy carrier'!J39) -> 0 | E28: =IF(SUM($D$27:$D$28)=0,0,D28/SUM($D$27:$D$28)) -> #DIV/0!

Sheet Technology shares
B2: Shares per technology per carrier
B4: Notes
B5: In this sheet the shares per technology per carrier needed for the Energy Transition Model are defined.
B7: Application | C7: Carrier | D7: Technology | E7: Percentage of final demand converted by this technology (%) | F7: Share per technology and carrier
B8: Space Heating
C9: Network Gas | D9: Gas-fired heater | E9: ='Technology split final demand'!G11 -> #DIV/0! | F9: =IF(SUM($E$9:$E$10)=0,1,E9/SUM($E$9:$E$10)) -> #DIV/0!
D10: Gas-fired heat pump | E10: ='Technology split final demand'!G13 -> #DIV/0! | F10: =IF(SUM($E$9:$E$10)=0,0,E10/SUM($E$9:$E$10)) -> #DIV/0!
C12: Electricity | D12: Electric heat pump with thermal storage | E12: ='Technology split final demand'!G12 -> #DIV/0! | F12: =IF(SUM($E$12:$E$14)=0,1,E12/SUM($E$12:$E$14)) -> #DIV/0!
D13: Electric heater | E13: ='Technology split final demand'!G14 -> #DIV/0! | F13: =IF(SUM($E$12:$E$14)=0,1,E13/SUM($E$12:$E$14)) -> #DIV/0!
D14: Electric air heat pump | E14: ='Technology split final demand'!G17 -> #DIV/0! | F14: =IF(SUM($E$12:$E$14)=0,1,E14/SUM($E$12:$E$14)) -> #DIV/0!
B16: Space Cooling
C17: Electricity | D17: Electric heat pump with thermal storage | E17: ='Technology split final demand'!G25 -> #DIV/0! | F17: =IF(SUM($E$17:$E$19)=0,0,E17/SUM($E$17:$E$19)) -> #DIV/0!
D18: Airconditioning | E18: ='Technology split final demand'!G26 -> #DIV/0! | F18: =IF(SUM($E$17:$E$19)=0,0,E18/SUM($E$17:$E$19)) -> #DIV/0!
D19: Electric air heat pump | E19: ='Technology split final demand'!G27 -> #DIV/0! | F19: =IF(SUM($E$17:$E$19)=0,0,E19/SUM($E$17:$E$19)) -> #DIV/0!
B21: Lighting
D22: Standard fluorescent tubes | E22: ='Technology split final demand'!G30 -> #DIV/0! | F22: =IF(SUM($E$22:$E$24)=0,0,E22/SUM($E$22:$E$24)) -> #DIV/0!
D23: Efficient fluorescent tubes | E23: ='Technology split final demand'!G31 -> #DIV/0! | F23: =IF(SUM($E$22:$E$24)=0,0,E23/SUM($E$22:$E$24)) -> #DIV/0!
D24: LED lamps | E24: ='Technology split final demand'!G32 -> #DIV/0! | F24: =IF(SUM($E$22:$E$24)=0,0,E24/SUM($E$22:$E$24)) -> #DIV/0!

Sheet Final demand per energy carrier
B2: Final demand per energy carrier
B4: Notes
B5: In this sheet an overview is presented of the allocation of energy carriers over the different technologies and applications. At the bottom of this sheet the size of the electrical appliances and the other appliances are determined.
B7: Final demand per energy carrier
B9: Application | C9: Technology used | D9: Percentage of final demand | E9: Final demand for coal (TJ) | F9: Final demand for network gas (TJ) | G9: Final demand for oil (TJ) | H9: Final demand for woodpellets (TJ) | I9: Final demand for Solar thermal (TJ) | J9: Final demand for electricity (TJ) | K9: Final demand for heat (TJ)
B11: Total IEA value | C11: All | E11: ='Fuel aggregation'!C11 -> 0 | F11: ='Fuel aggregation'!D11 -> 0 | G11: ='Fuel aggregation'!E11 -> 0 | H11: ='Fuel aggregation'!F11 -> 0 | I11: ='Fuel aggregation'!G11 -> 0 | J11: ='Fuel aggregation'!H11 -> 0 | K11: ='Fuel aggregation'!I11 -> 0
B14: Space heating
C15: Gas-fired heater | D15: ='Technology split final demand'!G11 -> #DIV/0! | F15: =D15*Final_demand_space_heating -> #DIV/0!
C16: Electric heat pump with thermal storage | D16: ='Technology split final demand'!G12 -> #DIV/0! | J16: =D16*Final_demand_space_heating -> #DIV/0!
C17: Gas-fired heat pump | D17: ='Technology split final demand'!G13 -> #DIV/0! | F17: =D17*Final_demand_space_heating -> #DIV/0!
C18: Electric heater | D18: ='Technology split final demand'!G14 -> #DIV/0! | J18: =D18*Final_demand_space_heating -> #DIV/0!
C19: Coal-fired heater | D19: ='Technology split final demand'!G15 -> #DIV/0! | E19: =D19*Final_demand_space_heating -> #DIV/0!
C20: Oil-fired heater | D20: ='Technology split final demand'!G16 -> #DIV/0! | G20: =D20*Final_demand_space_heating -> #DIV/0!
C21: Solar thermal panels | D21: ='Technology split final demand'!G19 -> #DIV/0! | I21: =D21*Final_demand_space_heating -> #DIV/0!
C22: Biomass-fired heater | D22: ='Technology split final demand'!G20 -> #DIV/0! | H22: =D22*Final_demand_space_heating -> #DIV/0!
C23: District heating | D23: ='Technology split final demand'!G21 -> #DIV/0! | K23: =D23*Final_demand_space_heating -> #DIV/0!
B25: Space cooling
C26: Gas-fired heat pump | D26: ='Technology split final demand'!G24 -> #DIV/0! | F26: =D26*Final_demand_space_cooling -> #DIV/0!
C27: Electric heat pump with thermal storage | D27: ='Technology split final demand'!G25 -> #DIV/0! | J27: =D27*Final_demand_space_cooling -> #DIV/0!
C28: Airconditioning | D28: ='Technology split final demand'!G26 -> #DIV/0! | J28: =D28*Final_demand_space_cooling -> #DIV/0!
B30: Lighting
C31: Standard fluorescent tubes | D31: ='Technology split final demand'!G30 -> #DIV/0! | J31: =D31*Final_demand_lighting -> #DIV/0!
C32: Efficient fluorescent tubes | D32: ='Technology split final demand'!G31 -> #DIV/0! | J32: =D32*Final_demand_lighting -> #DIV/0!
C33: LED lamps | D33: ='Technology split final demand'!G32 -> #DIV/0! | J33: =D33*Final_demand_lighting -> #DIV/0!
B35: Subtotal of defined appliances
C36: Subtotal (TJ) | E36: =SUM(E15:E33) -> #DIV/0! | F36: =SUM(F15:F33) -> #DIV/0! | G36: =SUM(G15:G33) -> #DIV/0! | H36: =SUM(H15:H33) -> #DIV/0! | I36: =SUM(I15:I33) -> #DIV/0! | J36: =SUM(J15:J33) -> #DIV/0! | K36: =SUM(K15:K33) -> #DIV/0!
B38: Central ICT
C39: Electricity use | E39: - | F39: - | G39: - | H39: - | I39: - | J39: =Dashboard!E29 | K39: -
B41: Other Applicances
C42: Electric appliances | J42: =J11-J36-J39 -> #DIV/0!
C43: Other appliances (non-electric) - remaining energy flows | E43: =E11-E36 -> #DIV/0! | F43: =F11-F36 -> #DIV/0! | G43: =G11-G36 -> #DIV/0! | H43: - | I43: - | J43: - | K43: -

Sheet Technology split final demand
B2: Technology splits of final demands
B4: Notes
B5: In this sheet the percentages of heat delivered are converted into percentages of final demand converted per technology by using the technological efficiencies specified in the sheet 'Technological specifications'. An exception to this workflow are the percentages of final demand for district heating, biomass heating and solar thermal panels, which have been directly determined in the sheet 'Final demand extracted from EB'.
B7: Percentages of energy demand
B9: Application | C9: Technology | D9: Percentage of heat delivered per technology | E9: Technological efficiency | F9: Relative size of final demand converted by this technology | G9: Percentage of final demand converted by this technology | H9: Comments
B10: Space heating
C11: Gas-fired heater | D11: =Dashboard!E44 -> 0 | E11: =Eff_space_heating_gas -> 0 | F11: =D11/E11 -> #DIV/0! | G11: =F11/SUM($F$11:$F$17)*(1-SUM($G$19:$G$21)) -> #DIV/0!
C12: Electric heat pump with thermal storage | D12: =Dashboard!E45 -> 0 | E12: =Eff_space_heating_pump_storage -> #DIV/0! | F12: =D12/E12 -> #DIV/0! | G12: =F12/SUM($F$11:$F$17)*(1-SUM($G$19:$G$21)) -> #DIV/0!
C13: Gas-fired heat pump | D13: =Dashboard!E46 -> 0 | E13: =Eff_space_heating_pump_gas -> #DIV/0! | F13: =D13/E13 -> #DIV/0! | G13: =F13/SUM($F$11:$F$17)*(1-SUM($G$19:$G$21)) -> #DIV/0!
C14: Electric heater | D14: =Dashboard!E47 -> 0 | E14: =Eff_space_heating_electric -> 0 | F14: =D14/E14 -> #DIV/0! | G14: =F14/SUM($F$11:$F$17)*(1-SUM($G$19:$G$21)) -> #DIV/0!
C15: Coal-fired heater | D15: =Dashboard!E48 -> 0 | E15: =Eff_space_heating_coal -> 0 | F15: =D15/E15 -> #DIV/0! | G15: =F15/SUM($F$11:$F$17)*(1-SUM($G$19:$G$21)) -> #DIV/0!
C16: Oil-fired heater | D16: =Dashboard!E49 -> 0 | E16: =Eff_space_heating_oil -> 0 | F16: =D16/E16 -> #DIV/0! | G16: =F16/SUM($F$11:$F$17)*(1-SUM($G$19:$G$21)) -> #DIV/0!
C17: Electric air heat pump | D17: =Dashboard!E50 -> 0 | E17: {=Eff_space_heating_air_heatpump} -> #DIV/0! | F17: =D17/E17 -> #DIV/0! | G17: =F17/SUM($F$11:$F$17)*(1-SUM($G$19:$G$21)) -> #DIV/0!
C19: Solar thermal panels | G19: ='Final demand extracted from EB'!D14 -> #DIV/0! | H19: These percentages are determined directly from the energy balance and the final demand specified on the dashboard
C20: Biomass-fired heater | G20: ='Final demand extracted from EB'!D10 -> #DIV/0!
C21: District heating | G21: ='Final demand extracted from EB'!D18 -> #DIV/0!
B23: Space Cooling
C24: Gas-fired heat pump | D24: =Dashboard!E54 -> 0 | E24: =Eff_cooling_pump -> #DIV/0! | F24: =D24/E24 -> #DIV/0! | G24: =F24/SUM($F$24:$F$27) -> #DIV/0!
C25: Electric heat pump with thermal storage | D25: =Dashboard!E55 -> 0 | E25: =Eff_cooling_pump_storage -> #DIV/0! | F25: =D25/E25 -> #DIV/0! | G25: =F25/SUM($F$24:$F$27) -> #DIV/0!
C26: Airconditioning | D26: =Dashboard!E56 -> 0 | E26: =Eff_cooling_airco -> #DIV/0! | F26: =D26/E26 -> #DIV/0! | G26: =F26/SUM($F$24:$F$27) -> #DIV/0!
C27: Electric air heat pump | D27: =Dashboard!E57 -> 0 | E27: {=Eff_cooling_air_heatpump} -> #DIV/0! | F27: =D27/E27 -> #DIV/0! | G27: =F27/SUM($F$24:$F$27) -> #DIV/0!
B29: Lighting
C30: Standard fluorescent tubes | D30: =Dashboard!E61 -> 0 | E30: =Eff_lighting_tube_fluorescent_standartd -> 0 | F30: =D30/E30 -> #DIV/0! | G30: =F30/SUM($F$30:$F$32) -> #DIV/0!
C31: Efficient fluorescent tubes | D31: =Dashboard!E62 -> 0 | E31: =Eff_lighting_tube_fluorescent_efficient -> 0 | F31: =D31/E31 -> #DIV/0! | G31: =F31/SUM($F$30:$F$32) -> #DIV/0!
C32: LED lamps | D32: =Dashboard!E63 -> 0 | E32: =Eff_lighting_led -> 0 | F32: =D32/E32 -> #DIV/0! | G32: =F32/SUM($F$30:$F$32) -> #DIV/0!

Sheet Final demand extracted from EB
B2: Final demands extracted from the energy balance
B4: Notes
B5: In this sheet the percentage of final demand for space heating fulfilled by district heating, biomass and solar thermal is determined based on the final demand specified on the dashboard and the values in the energy balance.
B7: Carriers | C7: Parameters | D7: Values
B8: Biomass
C9: Final demand for biomass | D9: ='Fuel aggregation'!F11 -> 0
C10: Percentage of final demand for space heating delivered by biomass | D10: =D9/Final_demand_space_heating -> #DIV/0!
B12: Solar thermal
C13: Final demand for solar thermal | D13: ='Fuel aggregation'!G11 -> 0
C14: Percentage of final demand for space heating delivered by solar thermal | D14: =D13/Final_demand_space_heating -> #DIV/0!
B16: District heating
C17: Final demand for (district) heat | D17: ='Fuel aggregation'!I11 -> 0
C18: Percentage of final demand for space heating delivered by district heating | D18: =D17/Final_demand_space_heating -> #DIV/0!

Sheet Fuel aggregation
B2: Fuel Aggregation
B4: Notes
B5: In this sheet the carriers from the energy balance are summed into the carriers that the ETM uses in the commercial and public services sector. The result for other carriers should be zero, because the ETM does not allow for the use of these carriers in the commercial and public services sector. To see what you should do, please see the dashboard. If you want to trace the problem, please check the energy balance for red cells.
B7: Final demand per energy carrier
C9: Final demand for coal | D9: Final demand for network gas | E9: Final demand for oil | F9: Final demand for woodpellets | G9: Final demand for Solar thermal | H9: Final demand for electricity | I9: Final demand for heat | J9: Final demand for Other | K9: Total demand of aggregated carriers | L9: Total demand in energy balancen (IEA)
B11: Final demand per energy carrier (TJ) | C11: =SUM('Corrected energy balance step 2'!C83:N83)+'Corrected energy balance step 2'!S83 -> 0 | D11: ='Corrected energy balance step 2'!T83+'Corrected energy balance step 2'!AV83 -> 0 | E11: =SUM('Corrected energy balance step 2'!U83:AQ83,'Corrected energy balance step 2'!AW83:AY83) -> 0 | F11: ='Corrected energy balance step 2'!AU83+'Corrected energy balance step 2'!AZ83+'Corrected energy balance step 2'!BA83 -> 0 | G11: ='Corrected energy balance step 2'!BH83 -> 0 | H11: ='Corrected energy balance step 2'!BL83 -> 0 | I11: ='Corrected energy balance step 2'!BM83+'Corrected energy balance step 2'!BF83 -> 0 | J11: =SUM('Corrected energy balance step 2'!O83:R83,'Corrected energy balance step 2'!AR83:AT83,'Corrected energy balance step 2'!BB83:BE83,'Corrected energy balance step 2'!BG83,'Corrected energy balance step 2'!BI83:BK83) -> 0 | K11: =SUM(C10:J11) -> 0 | L11: ='Corrected energy balance step 2'!$BN$83 -> 0
J17: Check:
J18: If the
J19: ="- total demand of aggregated carriers" -> - total demand of aggregated carriers
J20: ="- total demand in energy balance (IEA)" -> - total demand in energy balance (IEA)
J21: are the same,,
J22: the energy carriers have been aggregated correctly.
J24: Difference: | K24: =K11-Final_demand_residences -> 0

Sheet Tech split of useful demand
B2: Technology split of useful demand fo space heating
B4: Notes
B5: In this sheet the percentage of heat delivered per technology is determined for district heating, biomass fired heaters and solar thermal panels. For the other technologies the value is the same as defined by you on the dashboard.
B7: Space Heating
D8: Percentage of final demand converted per technology (%) | E8: Final demand converted per technology (TJ) | F8: Useful demand created per technology (TJ) | G8: Percentage of heat delivered per technology (%)
C9: Gas-fired heater | D9: ='Technology split final demand'!G11 -> #DIV/0! | E9: =D9*Final_demand_space_heating -> #DIV/0! | F9: =Eff_space_heating_gas*E9 -> #DIV/0! | G9: =F9/SUM($F$9:$F$19) -> #DIV/0!
C10: Electric heat pump with thermal storage | D10: ='Technology split final demand'!G12 -> #DIV/0! | E10: =D10*Final_demand_space_heating -> #DIV/0! | F10: =Eff_space_heating_pump_storage*E10 -> #DIV/0! | G10: =F10/SUM($F$9:$F$19) -> #DIV/0!
C11: Gas-fired heat pump | D11: ='Technology split final demand'!G13 -> #DIV/0! | E11: =D11*Final_demand_space_heating -> #DIV/0! | F11: =Eff_space_heating_pump_gas*E11 -> #DIV/0! | G11: =F11/SUM($F$9:$F$19) -> #DIV/0!
C12: Electric heater | D12: ='Technology split final demand'!G14 -> #DIV/0! | E12: =D12*Final_demand_space_heating -> #DIV/0! | F12: =Eff_space_heating_electric*E12 -> #DIV/0! | G12: =F12/SUM($F$9:$F$19) -> #DIV/0!
C13: Coal-fired heater | D13: ='Technology split final demand'!G15 -> #DIV/0! | E13: =D13*Final_demand_space_heating -> #DIV/0! | F13: =Eff_space_heating_coal*E13 -> #DIV/0! | G13: =F13/SUM($F$9:$F$19) -> #DIV/0!
C14: Oil-fired heater | D14: ='Technology split final demand'!G16 -> #DIV/0! | E14: =D14*Final_demand_space_heating -> #DIV/0! | F14: =Eff_space_heating_oil*E14 -> #DIV/0! | G14: =F14/SUM($F$9:$F$19) -> #DIV/0!
C15: Electric air heat pump | D15: ='Technology split final demand'!G17 -> #DIV/0! | E15: =D15*Final_demand_space_heating -> #DIV/0! | F15: =Eff_space_heating_oil*E15 -> #DIV/0! | G15: =F15/SUM($F$9:$F$19) -> #DIV/0!
C17: Solar thermal panels | D17: ='Technology split final demand'!G19 -> #DIV/0! | E17: =D17*Final_demand_space_heating -> #DIV/0! | F17: =Eff_space_heating_solar_thermal*E17 -> #DIV/0! | G17: =F17/SUM($F$9:$F$19) -> #DIV/0!
C18: Biomass-fired heater | D18: ='Technology split final demand'!G20 -> #DIV/0! | E18: =D18*Final_demand_space_heating -> #DIV/0! | F18: =Eff_space_heating_woodpellets*E18 -> #DIV/0! | G18: =F18/SUM($F$9:$F$19) -> #DIV/0!
C19: District heating | D19: ='Technology split final demand'!G21 -> #DIV/0! | E19: =D19*Final_demand_space_heating -> #DIV/0! | F19: =Eff_space_heating_district*E19 -> #DIV/0! | G19: =F19/SUM($F$9:$F$19) -> #DIV/0!

Sheet csv_ps_final_demand_lighting
A1: buildings_final_demand_for_lighting_electricity_parent_share
A2: key | B2: share
A3: buildings_lighting_standard_fluorescent_electricity | B3: ='Technology shares'!F22 -> #DIV/0!
A4: buildings_lighting_efficient_fluorescent_electricity | B4: ='Technology shares'!F23 -> #DIV/0!
A5: buildings_lighting_led_electricity | B5: ='Technology shares'!F24 -> #DIV/0!

Sheet csv_ps_space_heating_electricit
A1: buildings_final_demand_for_space_heating_electricity_parent_share
A2: key | B2: share
A3: buildings_space_heater_electricity | B3: ='Technology shares'!F13 -> #DIV/0!
A4: buildings_space_heater_collective_heatpump_water_water_ts_electricity | B4: ='Technology shares'!F12 -> #DIV/0!
A5: buildings_space_heater_heatpump_air_water_electricity | B5: ='Technology shares'!F14 -> #DIV/0!
A6: buildings_space_heater_heatpump_surface_water_water_ts_electricity | B6: 0

Sheet csv_ps_cooling_electricity
A1: buildings_final_demand_for_cooling_electricity_parent_share
A2: key | B2: share
A3: buildings_cooling_airconditioning_electricity | B3: ='Technology shares'!F18 -> #DIV/0!
A4: buildings_cooling_collective_heatpump_water_water_ts_electricity | B4: ='Technology shares'!F17 -> #DIV/0!
A5: buildings_cooling_heatpump_air_water_electricity | B5: ='Technology shares'!F19 -> #DIV/0!
A6: buildings_cooling_heatpump_surface_water_water_ts_electricity | B6: 0

Sheet csv_ps_space_heating_gas
A1: buildings_final_demand_for_space_heating_network_gas_parent_share
A2: key | B2: share
A3: buildings_space_heater_network_gas | B3: ='Technology shares'!F9 -> #DIV/0!
A4: buildings_space_heater_heatpump_air_water_network_gas | B4: ='Technology shares'!F10 -> #DIV/0!

Sheet csv_ps_final_demand_coal
A1: buildings_final_demand_coal_parent_share
A2: key | B2: share
A3: buildings_final_demand_for_space_heating_coal | B3: ='Application shares'!E9 -> #DIV/0!
A4: buildings_final_demand_for_appliances_coal | B4: ='Application shares'!E10 -> #DIV/0!

Sheet csv_ps_final_demand_gas
A1: buildings_final_demand_network_gas_parent_share
A2: key | B2: share
A3: buildings_final_demand_for_space_heating_network_gas | B3: ='Application shares'!E13 -> #DIV/0!
A4: buildings_final_demand_for_cooling_network_gas | B4: ='Application shares'!E14 -> #DIV/0!
A5: buildings_final_demand_for_appliances_network_gas | B5: ='Application shares'!E15 -> #DIV/0!

Sheet csv_ps_final_demand_oil
A1: buildings_final_demand_crude_oil_parent_share
A2: key | B2: share
A3: buildings_final_demand_for_space_heating_crude_oil | B3: ='Application shares'!E18 -> #DIV/0!
A4: buildings_final_demand_for_appliances_crude_oil | B4: ='Application shares'!E19 -> #DIV/0!

Sheet csv_ps_final_demand_electricity
A1: buildings_final_demand_electricity_parent_share
A2: key | B2: share
A3: buildings_final_demand_for_space_heating_electricity | B3: ='Application shares'!E22 -> #DIV/0!
A4: buildings_final_demand_for_cooling_electricity | B4: ='Application shares'!E23 -> #DIV/0!
A5: buildings_final_demand_for_lighting_electricity | B5: ='Application shares'!E24 -> #DIV/0!
A6: buildings_final_demand_for_appliances_electricity | B6: ='Application shares'!E25 -> #DIV/0!

Sheet csv_ps_final_demand_wood_p
A1: buildings_final_demand_wood_pellets_parent_share
A2: key | B2: share
A3: buildings_final_demand_for_space_heating_wood_pellets | B3: =Dashboard!E66 -> 1
A4: buildings_final_demand_for_appliances_wood_pellets | B4: =Dashboard!E67 -> 0

Sheet csv_cooling_useful_insulation
A1: buildings_useful_demand_cooling_child_share
A2: key | B2: share
A3: buildings_cooling_savings_insulation_cooling | B3: 0
A4: buildings_useful_demand_after_insulation_cooling | B4: 1

Sheet csv_ps_sector_electricity
A1: buildings_local_production_electricity_parent_share
A2: key | B2: share
A3: buildings_final_demand_electricity | B3: ='Application shares'!E27 -> #DIV/0!
A4: industry_final_demand_for_other_ict_electricity | B4: ='Application shares'!E28 -> #DIV/0!
