Workbook
Name exchange_rate_2011_2010: #REF!
Name Final_demand_residences: '[1]Fuel aggregation'!$L$11
Name hours_a_year: #REF!
Name km2_to_m2: #REF!
Name kW_to_MW: #REF!
Name kW_to_W: #REF!
Name kWp_to_MWp: #REF!
Name m2_to_km2: #REF!
Name STC: #REF!
Name STC_insolation: #REF!
Name W_to_MW: #REF!
Name Wp_to_kWp: #REF!
Name WP_to_MWp: #REF!

Sheet Dashboard
B2: Node | C2: households_space_heater_hybrid_heatpump_air_water_electricity.ad | E2: Description | F2: This sheet summarizes all node attributes formatted in the way they are used by the Energy Transition Model. Use the Excel formulas to find the original data and sources for these numbers. You can also use this document to update the attribute value. Once you have finished updating, save this document and run rake import:node NODE="nodename" to update the node attributes on ETSource. Note: in the final dashboard values, use ROUND to avoid long floats.
B3: Author | C3: Jort Wolda
B4: Organisation | C4: Quintel
C7: Attribute | D7: Unit | E7: Value | G7: Definition | I7: Source
C9: Technical
C10: input.ambient_heat | D10: - | E10: =ROUND(Analysis!$D$5,6) -> 0.561977 | G10: Dataset specific, should be excluded when exporting | I10: Installatiemonitor 3.0
C11: input.electricity | D11: - | E11: =ROUND(Analysis!$D$6,6) -> 0.226111 | G11: Dataset specific, should be excluded when exporting | I11: Installatiemonitor 3.0
C12: input.network_gas | E12: =ROUND(Analysis!D7,6) -> 0.20861 | G12: Dataset specific, should be excluded when exporting | I12: Installatiemonitor 3.0
C13: output.useable_heat.ambient_heat | D13: - | E13: 1 | I13: Quintel assumption
C14: output.useable_heat.electricity | D14: - | E14: 1 | I14: Quintel assumption
C15: output.useable_heat.network_gas | D15: - | E15: =Analysis!D80 -> 1.07 | I15: Based on HR-107 condensing boiler - From households_space_heater_combined_network_gas - Vesta is used as source
C16: fever.base_cop | D16: - | E16: =ROUND(Analysis!$D$17,6) -> 3.0584 | I16: Bogdanov et al. (2024)
C17: fever.capacity.electricity | D17: MW | E17: =ROUND(Analysis!D34,6) -> 0.001704 | I17: Installatiemonitor 3.0 & Bofdanov et al. (2024)
C18: fever.capacity.network_gas | D18: MW | E18: =ROUND(Analysis!D79,6) -> 0.022 | I18: Based on HR-107 condensing boiler - From households_space_heater_combined_network_gas - Vesta is used as source
C19: fever.cop_cutoff | D19: - | E19: =ROUND(Analysis!D66, 6) -> 2.600238 | I19: Quintel assumption (using several sources)
C20: fever.cop_per_degree | D20: - | E20: =ROUND(Analysis!$D$18,6) -> 0.0593 | I20: Bogdanov et al. (2024)
C21: storage.volume | D21: MWh | E21: 0 | I21: Quintel assumption
C22: availability | D22: - | E22: 0 | I22: Quintel assumption
C23: full_load_hours | D23: - | E23: 0 | I23: Quintel assumption
C24: households_supplied_per_unit | D24: - | E24: 1 | I24: Quintel assumption
C25: heat_output_capacity | D25: MW | E25: =ROUND(Analysis!D85,6) -> 0.02354 | G25: Heat output capacity | I25: Installatiemonitor 3.0
C27: Cost
C28: initial_investment | D28: euro | E28: =Analysis!D48 -> 6931.5 | G28: Initial investment costs | I28: Update kentallen installaties Vesta MAIS
C29: ccs_investment | D29: euro | E29: 0 | G29: Investment cost with ccs | I29: Quintel assumption
C30: cost_of_installing | D30: euro | E30: 0 | G30: Installation cost | I30: Quintel assumption
C31: decommissioning_costs | D31: euro | E31: 0 | G31: Decommissioning cost | I31: Quintel assumption
C32: fixed_operation_and_maintenance_costs_per_year | D32: euro/year | E32: =Analysis!D49 -> 50 | G32: Fixed operational and maintenance costs per year | I32: Update kentallen installaties Vesta MAIS
C33: variable_operation_and_maintenance_costs_per_full_load_hour | D33: euro/FLH | E33: 0 | G33: Variable operational and maintenance costs | I33: Quintel assumption
C34: variable_operation_and_maintenance_costs_for_ccs_per_full_load_hour | D34: euro/FLH | E34: 0 | G34: Variable operational and maintenance costs for ccs | I34: Quintel assumption
C35: wacc | D35: % | E35: 0.02 | G35: Weighted average cost of capita | I35: Quintel assumption, see https://docs.energytransitionmodel.com/main/cost-wacc/
C36: takes_part_in_ets | D36: yes=1, no=0 | E36: 0 | I36: Quintel assumption
C37: storage.cost_per_mwh | D37: eur0/MWh | E37: 0 | I37: Quintel assumption
C39: Other
C40: construction_time | D40: years | E40: 0 | G40: Construction time of the plant | I40: Quintel assumption
C41: technical_lifetime | D41: years | E41: 15 | G41: Technical lifetime of the plant | I41: Factsheet luchtwarmtepomp
C42: free_co2_factor | D42: - | E42: 0 | I42: Quintel assumption

Sheet Sources
C3: Variables | D3: Title | E3: Author / organisation | F3: Subject country | G3: Published year | H3: Subject year | I3: Retreived year | J3: Link
C4: input.ambient_heat, input.electricity, heat_output_capacity, fever.capacity.electricity | D4: Installatiemonitor 3.0 - De warmtepomp in de gebouwde omgeving | E4: BDH | F4: NL | G4: 2026 | I4: 2026 | J4: https://kennisdelen.rvo.nl/file/download/a29e1ec4-ad00-4a5b-ba62-287ca7602ddf/Installatiemonitor_3_eindrapportage_v1.02.pdf
C5: input.ambient_heat, input.electricity | D5: 20 jahre wärmepumpen-monitoring am Fraunhofer ISE | E5: Franhofer ISE | F5: DE | G5: 2025 | H5: 2023 - 2024 | I5: 2026 | J5: https://www.ise.fraunhofer.de/en/research-projects/wp-qs-im-bestand.html
C6: fever.base_cop, fever.cop_per_degree, heat_output_capacity, fever.capacity.electricity | D6: Impact of temperature dependent coefficient of performance of heat pumps on heating systems in national and regional energy systems modelling | E6: Bogdanov, Stymov, Breyer (LUT University) | F6: - | G6: 2024 | I6: 2026 | J6: https://pdf.sciencedirectassets.com/271429/1-s2.0-S0306261924X00148/1-s2.0-S0306261924010304/main.pdf?X-Amz-Security-Token=IQoJb3JpZ2luX2VjEDcaCXVzLWVhc3QtMSJHMEUCIDayx60tWfHNKXVVv8qS6t7aPyy1YM%2BiBAF7FCuifT67AiEAuYqhuC5gy%2FAawde7fGCHiyLrCKGdXwEYRSiojbmpQdMqvAUI%2F%2F%2F%2F%2F%2F%2F%2F%2F%2F%2F%2FARAFGgwwNTkwMDM1NDY4NjUiDOxvvumY1HhRiHczdCqQBRl5ICXGeg74c%2B%2BGt6IdqbTCtLh0Cu69IR5DEAACTsA%2FYwbWrgDr%2BzXwqBDPa6GZ8rgoLiR9YP9HwXG8g%2FsR0yi1Kld1R%2B%2FWY4sYSSMxxVoJmr9SAtWFnzKuv3LwQ0U2Adpceq1YsXSRwmaVFGy7fk389lcW%2Fx0PaB8USbARFUz8p03pCT3wcy8uXWXyCUsRNl6eN2pTmmamMv3RKEWuw3extsuoc3KfxXjb1TvnEDTIgZx1P8BYBcpoGfOuxdPLkVGa8bhbYyZ3HVNKrf7pzMaq17fTLj4PtFdLFyyhuxiXNV3Vv%2BnsdmEbZhPvp99m3lYJsMRX7bHAtXdbw661dYT3M%2BPCe%2B2kJQwMikZxWfs%2FihlZaEbdIlQpMbfX7xST6xM%2BeeEEIvV%2ByABbJ5kxzBBjHzbJtSk%2FN4YhVLoyXDdq1LEenN5CVcFf0YztFQk8SMQoMi%2BAhVpoSV3LUK5DFisHXeXWMHsc3QUDM9XFp26Y1GovhZJ%2FijGUhgTn%2FTC00qogUqGKkhG8ws4pnu94DzqgWxmVjyWX%2FqX30i6fDPpUxSHKujCyTj8siOS1lTNWWz3UoZDFmz3frOI2ztMm%2FVfWe5OVeVblN87IRAYyyxJ5uKCv5C66BGzW4YUiIVBSFkFdv872uvoP5J61SJVs9v20T6SbGfxJM5LLK4KqvQHWYs4YCMzA%2BVEwwXF4hhZ8CVD4PK9cTnxzsdFLLFOkBdrcoYL4uEIaufqbnZthK%2FbpUrMgMYWi2jgW8wG4s9ipCWTg6R5bvu2Ds6Q3UmUo7CglQ%2FJD5ASTEHmqR%2BCGYqUNRAeH4YlHSwliIoR6X77fyWpfWOBygE8rtJa%2FtVr82LfTpIljxYkK79XYmiKV0ls9MPfA%2FNMGOrEBYjfBchqkKUY1si0EA8Zq2hP92hHujyBIqLntJvfEzpLLYb0g37kv5ohpd%2F6qPuxSJ3%2BhVhPJfzDptMtbBx3zUZ4IhdZMgyeZOemV8w1F17hV0fBa03MzuejvBr2JtTLZICTYLwr%2BH0yS3XH9QU13P7vE%2BPpZc5gSh9J9CBi%2FtIddCYJZ1A8g073sJV7VbQyodWrsmfyWIvppurgch2bZZGxtV3uCtxOjTIPHblTrWVX7&X-Amz-Algorithm=AWS4-HMAC-SHA256&X-Amz-Date=20260814T142629Z&X-Amz-SignedHeaders=host&X-Amz-Expires=300&X-Amz-Credential=ASIAQ3PHCVTYQ7GBCDX4%2F20260814%2Fus-east-1%2Fs3%2Faws4_request&X-Amz-Signature=f5505e1ab0c3d216f958b3dd2da6d768b974147a086a958ae13c8ff067f3f793&hash=700ab74877321dbaa56e45a1d6afdbe3b6e32748e211e8ec3c9cab8c75cadcf4&host=68042c943591013ac2b2430a89b270f6af2c76d8dfd086a07176afe7c76c2c61&pii=S0306261924010304&tid=spdf-df67c04d-858b-4d71-8345-3792de26f625&sid=71107c3f109b914cd36b34220ded9018ec04gxrqb&type=client&tsoh=d3d3LnNjaWVuY2VkaXJlY3QuY29t&rh=d3d3LnNjaWVuY2VkaXJlY3QuY29t&ua=140a0653005505515b5757&rr=a2b0a2864a59feb4&cc=nl
C7: fever.base_cop, fever.cop_per_degree | D7: Time series of heat demand and heat pump efficiency for energy system modeling (When2Heat) | E7: Ruhnau, O., Hirth, L. & Praktiknjo, A. | F7: - | G7: 2019 | H7: 2016 | I7: 2026 | J7: https://www.nature.com/articles/s41597-019-0199-y
C8: fever.capacity.electricity | D8: Sinclair SHP-140ICA + SHP-140ECA product fiche | E8: Sinclair | F8: - | G8: - | H8: - | I8: - | J8: https://www.sinclair-solutions.com/files/product-fiche/sinclair-prfi-shp-140ica-shp-140eca2.pdf
C9: initial_investment, fixed_operation_and_maintenance_costs_per_year | D9: Update kentallen installaties Vesta MAIS | E9: CE Delft | F9: NL | G9: 2023 | I9: 2026 | J9: https://ce.nl/wp-content/uploads/2023/03/CE_Delft_210348_Update_kentallen_installaties_Vesta_MAIS_Def.pdf
C10: technical_lifetime | D10: Factsheet Luchtwarmtepomp | E10: CE Delft | F10: NL | G10: 2021 | I10: 2026 | J10: https://ce.nl/wp-content/uploads/2021/04/04_Factsheet-Luchtwarmtepomp_DEF.pdf
C11: fever.cop_cutoff | D11: Gemiddelde energietarieven voor consumenten | E11: CBS | F11: NL | G11: 2026 | H11: 2025 | I11: 2026 | J11: https://opendata.cbs.nl/#/CBS/nl/dataset/85592NED/table
C31: Note: "published year" might deviate from "subject year". For example, a study can be published in 2024 about costs parameters in 2020.

Sheet Analysis
C3: variable | D3: value | E3: unit | F3: comment | G3: source | M3: Screenshots
C4: output.useable_heat | D4: =1 -> 1 | F4: The Installatiemonitor tracks smart meter data from households with heat pumps, collected between 01-2023 and 01-2026, and therefore reflects real-world performance. The sample covers 200–250 all-electric and 1,955 hybrid heat pumps with a complete dataset. The average SCOP for space heating with all-electric heat pumps is 3.5, for hybrid it is 3.4. The lower value is surprising on first notice since hybrid heat pumps can switch to gas when the outdoor temperature is lowest and the heat pumps performance is at its weakest (resulting in a 'dekkingsgraad' of 78%). However, precisely for this reason the insulation and delivery system is on average more modern in residences with all-electric households. Since the difference is marginal and related to how and where the technology is used, the same SCOP of 3.5 is assumed for hybrids. The 'dekkingsgraad' shows that 22% of the heat is provided by natural gas, with an efficiency of 107% (due to LHV). Of this 22% of heat, 0.07/1.07 is condensation heat, the rest comes from network gas. Because we need inputs that count up to 1, we correct for the condensation to at least keep the ratio between ambient, electricity and gas correct. Hard coded values in calculation: 0.78 = share of heat provided by heatpump (dekkingsgraad), 0.22 = share of heat provided by gas boiler, 3.5 = COP, 1.07 = efficiency gas boiler, 0.07 part of efficiency above 1 (due to condensation). | G4: Main source: | H4: Installatiemonitor 3.0
C5: input.ambient_heat | D5: =(0.78-D6)*(1/(1-$D$8)) -> 0.56197681
C6: input.electricity | D6: =0.78/3.5*(1/(1-$D$8)) -> 0.22611146
C7: input.network_gas | D7: =0.22 / 1.07*(1/(1-$D$8)) -> 0.2086099
C8: Condensation (LHV/HHV correction) | D8: =0.07*0.22/1.07 -> 0.014392523
C17: fever.base_cop | D17: =AQ29 -> 3.0584 | F17: Bogdanov et al. (2024) give COP formulas as a function of delta T for air, ground and water source heat pumps. The formulas originate from Ruhnau et al. (2019), which used 2016 manufacturer data, but Bogdanov et al. updated the coefficients. The changes are small but the fact they're revised in 2024 improves credibility. While the formula has a quadratic term, the curve is nearly linear in the relevant range (see chart). These attributes should reproduce a SCOP broadly in line with the static value under typical conditions. Identical to the all_electric version, a sink temperature of 40 °C is assumed. Combined with an heat-demand-weighted average outside temperature of ~7 °C, this formula finds a COP of 3.5. The COP per degree is derived from the average step between −10 and 15 °C outside temperature. Since the difference in performance between hybrid and all-electric is related to how and where it's used, these values are identical to the all-electric values. | G17: Main source: | H17: Bogdanov et al. (2024) | AH17: Test formule (ASHP) | AN17: Test formule (ASHP) | AT17: Test formule (ASHP)
C18: fever.cop_per_degree | D18: =AQ46 -> 0.0593 | G18: Supporting source: | H18: Ruhnau et al. (2019) | AH18: Outside temp | AI18: Sink temp | AJ18: delta T | AK18: COP | AL18: COP (lineair aproximation) | AN18: Outside temp | AO18: Sink temp | AP18: delta T | AQ18: COP | AR18: COP (lineair aproximation) | AT18: Outside temp | AU18: Sink temp | AV18: delta T | AW18: COP | AX18: COP (lineair aproximation)
AH19: -10 | AI19: 35 | AJ19: =AI19-AH19 -> 45 | AK19: =6.08 - 0.0941 * AJ19 + 0.000464 * AJ19^2 -> 2.7851 | AL19: =AL20-$AK$46 -> 2.7155 | AN19: -10 | AO19: 40 | AP19: =AO19-AN19 -> 50 | AQ19: =6.08 - 0.0941 * AP19 + 0.000464 * AP19^2 -> 2.535 | AR19: =AR20-$AQ$46 -> 2.4654 | AT19: -10 | AU19: 45 | AV19: =AU19-AT19 -> 55 | AW19: =6.08 - 0.0941 * AV19 + 0.000464 * AV19^2 -> 2.3081 | AX19: =AX20-$AW$46 -> 2.2385
AH20: =AH19+1 -> -9 | AI20: 35 | AJ20: =AI20-AH20 -> 44 | AK20: =6.08 - 0.0941 * AJ20 + 0.000464 * AJ20^2 -> 2.837904 | AL20: =AL21-$AK$46 -> 2.77944 | AN20: =AN19+1 -> -9 | AO20: 40 | AP20: =AO20-AN20 -> 49 | AQ20: =6.08 - 0.0941 * AP20 + 0.000464 * AP20^2 -> 2.583164 | AR20: =AR21-$AQ$46 -> 2.5247 | AT20: =AT19+1 -> -9 | AU20: 45 | AV20: =AU20-AT20 -> 54 | AW20: =6.08 - 0.0941 * AV20 + 0.000464 * AV20^2 -> 2.351624 | AX20: =AX21-$AW$46 -> 2.29316
AH21: =AH20+1 -> -8 | AI21: 35 | AJ21: =AI21-AH21 -> 43 | AK21: =6.08 - 0.0941 * AJ21 + 0.000464 * AJ21^2 -> 2.891636 | AL21: =AL22-$AK$46 -> 2.84338 | AN21: =AN20+1 -> -8 | AO21: 40 | AP21: =AO21-AN21 -> 48 | AQ21: =6.08 - 0.0941 * AP21 + 0.000464 * AP21^2 -> 2.632256 | AR21: =AR22-$AQ$46 -> 2.584 | AT21: =AT20+1 -> -8 | AU21: 45 | AV21: =AU21-AT21 -> 53 | AW21: =6.08 - 0.0941 * AV21 + 0.000464 * AV21^2 -> 2.396076 | AX21: =AX22-$AW$46 -> 2.34782
AH22: =AH21+1 -> -7 | AI22: 35 | AJ22: =AI22-AH22 -> 42 | AK22: =6.08 - 0.0941 * AJ22 + 0.000464 * AJ22^2 -> 2.946296 | AL22: =AL23-$AK$46 -> 2.90732 | AN22: =AN21+1 -> -7 | AO22: 40 | AP22: =AO22-AN22 -> 47 | AQ22: =6.08 - 0.0941 * AP22 + 0.000464 * AP22^2 -> 2.682276 | AR22: =AR23-$AQ$46 -> 2.6433 | AT22: =AT21+1 -> -7 | AU22: 45 | AV22: =AU22-AT22 -> 52 | AW22: =6.08 - 0.0941 * AV22 + 0.000464 * AV22^2 -> 2.441456 | AX22: =AX23-$AW$46 -> 2.40248
AH23: =AH22+1 -> -6 | AI23: 35 | AJ23: =AI23-AH23 -> 41 | AK23: =6.08 - 0.0941 * AJ23 + 0.000464 * AJ23^2 -> 3.001884 | AL23: =AL24-$AK$46 -> 2.97126 | AN23: =AN22+1 -> -6 | AO23: 40 | AP23: =AO23-AN23 -> 46 | AQ23: =6.08 - 0.0941 * AP23 + 0.000464 * AP23^2 -> 2.733224 | AR23: =AR24-$AQ$46 -> 2.7026 | AT23: =AT22+1 -> -6 | AU23: 45 | AV23: =AU23-AT23 -> 51 | AW23: =6.08 - 0.0941 * AV23 + 0.000464 * AV23^2 -> 2.487764 | AX23: =AX24-$AW$46 -> 2.45714
AH24: =AH23+1 -> -5 | AI24: 35 | AJ24: =AI24-AH24 -> 40 | AK24: =6.08 - 0.0941 * AJ24 + 0.000464 * AJ24^2 -> 3.0584 | AL24: =AL25-$AK$46 -> 3.0352 | AN24: =AN23+1 -> -5 | AO24: 40 | AP24: =AO24-AN24 -> 45 | AQ24: =6.08 - 0.0941 * AP24 + 0.000464 * AP24^2 -> 2.7851 | AR24: =AR25-$AQ$46 -> 2.7619 | AT24: =AT23+1 -> -5 | AU24: 45 | AV24: =AU24-AT24 -> 50 | AW24: =6.08 - 0.0941 * AV24 + 0.000464 * AV24^2 -> 2.535 | AX24: =AX25-$AW$46 -> 2.5118
AH25: =AH24+1 -> -4 | AI25: 35 | AJ25: =AI25-AH25 -> 39 | AK25: =6.08 - 0.0941 * AJ25 + 0.000464 * AJ25^2 -> 3.115844 | AL25: =AL26-$AK$46 -> 3.09914 | AN25: =AN24+1 -> -4 | AO25: 40 | AP25: =AO25-AN25 -> 44 | AQ25: =6.08 - 0.0941 * AP25 + 0.000464 * AP25^2 -> 2.837904 | AR25: =AR26-$AQ$46 -> 2.8212 | AT25: =AT24+1 -> -4 | AU25: 45 | AV25: =AU25-AT25 -> 49 | AW25: =6.08 - 0.0941 * AV25 + 0.000464 * AV25^2 -> 2.583164 | AX25: =AX26-$AW$46 -> 2.56646
AH26: =AH25+1 -> -3 | AI26: 35 | AJ26: =AI26-AH26 -> 38 | AK26: =6.08 - 0.0941 * AJ26 + 0.000464 * AJ26^2 -> 3.174216 | AL26: =AL27-$AK$46 -> 3.16308 | AN26: =AN25+1 -> -3 | AO26: 40 | AP26: =AO26-AN26 -> 43 | AQ26: =6.08 - 0.0941 * AP26 + 0.000464 * AP26^2 -> 2.891636 | AR26: =AR27-$AQ$46 -> 2.8805 | AT26: =AT25+1 -> -3 | AU26: 45 | AV26: =AU26-AT26 -> 48 | AW26: =6.08 - 0.0941 * AV26 + 0.000464 * AV26^2 -> 2.632256 | AX26: =AX27-$AW$46 -> 2.62112
AH27: =AH26+1 -> -2 | AI27: 35 | AJ27: =AI27-AH27 -> 37 | AK27: =6.08 - 0.0941 * AJ27 + 0.000464 * AJ27^2 -> 3.233516 | AL27: =AL28-$AK$46 -> 3.22702 | AN27: =AN26+1 -> -2 | AO27: 40 | AP27: =AO27-AN27 -> 42 | AQ27: =6.08 - 0.0941 * AP27 + 0.000464 * AP27^2 -> 2.946296 | AR27: =AR28-$AQ$46 -> 2.9398 | AT27: =AT26+1 -> -2 | AU27: 45 | AV27: =AU27-AT27 -> 47 | AW27: =6.08 - 0.0941 * AV27 + 0.000464 * AV27^2 -> 2.682276 | AX27: =AX28-$AW$46 -> 2.67578
AH28: =AH27+1 -> -1 | AI28: 35 | AJ28: =AI28-AH28 -> 36 | AK28: =6.08 - 0.0941 * AJ28 + 0.000464 * AJ28^2 -> 3.293744 | AL28: =AL29-$AK$46 -> 3.29096 | AN28: =AN27+1 -> -1 | AO28: 40 | AP28: =AO28-AN28 -> 41 | AQ28: =6.08 - 0.0941 * AP28 + 0.000464 * AP28^2 -> 3.001884 | AR28: =AR29-$AQ$46 -> 2.9991 | AT28: =AT27+1 -> -1 | AU28: 45 | AV28: =AU28-AT28 -> 46 | AW28: =6.08 - 0.0941 * AV28 + 0.000464 * AV28^2 -> 2.733224 | AX28: =AX29-$AW$46 -> 2.73044
AG29: Base COP | AH29: =AH28+1 -> 0 | AI29: 35 | AJ29: =AI29-AH29 -> 35 | AK29: =6.08 - 0.0941 * AJ29 + 0.000464 * AJ29^2 -> 3.3549 | AL29: =AK29 -> 3.3549 | AN29: =AN28+1 -> 0 | AO29: 40 | AP29: =AO29-AN29 -> 40 | AQ29: =6.08 - 0.0941 * AP29 + 0.000464 * AP29^2 -> 3.0584 | AR29: =AQ29 -> 3.0584 | AT29: =AT28+1 -> 0 | AU29: 45 | AV29: =AU29-AT29 -> 45 | AW29: =6.08 - 0.0941 * AV29 + 0.000464 * AV29^2 -> 2.7851 | AX29: =AW29 -> 2.7851
AH30: =AH29+1 -> 1 | AI30: 35 | AJ30: =AI30-AH30 -> 34 | AK30: =6.08 - 0.0941 * AJ30 + 0.000464 * AJ30^2 -> 3.416984 | AL30: =AL29+$AK$46 -> 3.41884 | AN30: =AN29+1 -> 1 | AO30: 40 | AP30: =AO30-AN30 -> 39 | AQ30: =6.08 - 0.0941 * AP30 + 0.000464 * AP30^2 -> 3.115844 | AR30: =AR29+$AQ$46 -> 3.1177 | AT30: =AT29+1 -> 1 | AU30: 45 | AV30: =AU30-AT30 -> 44 | AW30: =6.08 - 0.0941 * AV30 + 0.000464 * AV30^2 -> 2.837904 | AX30: =AX29+$AW$46 -> 2.83976
AH31: =AH30+1 -> 2 | AI31: 35 | AJ31: =AI31-AH31 -> 33 | AK31: =6.08 - 0.0941 * AJ31 + 0.000464 * AJ31^2 -> 3.479996 | AL31: =AL30+$AK$46 -> 3.48278 | AN31: =AN30+1 -> 2 | AO31: 40 | AP31: =AO31-AN31 -> 38 | AQ31: =6.08 - 0.0941 * AP31 + 0.000464 * AP31^2 -> 3.174216 | AR31: =AR30+$AQ$46 -> 3.177 | AT31: =AT30+1 -> 2 | AU31: 45 | AV31: =AU31-AT31 -> 43 | AW31: =6.08 - 0.0941 * AV31 + 0.000464 * AV31^2 -> 2.891636 | AX31: =AX30+$AW$46 -> 2.89442
AH32: =AH31+1 -> 3 | AI32: 35 | AJ32: =AI32-AH32 -> 32 | AK32: =6.08 - 0.0941 * AJ32 + 0.000464 * AJ32^2 -> 3.543936 | AL32: =AL31+$AK$46 -> 3.54672 | AN32: =AN31+1 -> 3 | AO32: 40 | AP32: =AO32-AN32 -> 37 | AQ32: =6.08 - 0.0941 * AP32 + 0.000464 * AP32^2 -> 3.233516 | AR32: =AR31+$AQ$46 -> 3.2363 | AT32: =AT31+1 -> 3 | AU32: 45 | AV32: =AU32-AT32 -> 42 | AW32: =6.08 - 0.0941 * AV32 + 0.000464 * AV32^2 -> 2.946296 | AX32: =AX31+$AW$46 -> 2.94908
C33: heat.output_capacity (heat pump only) | D33: =4.6/10^3 -> 0.0046 | E33: MW | F33: The average bivalence capacity* of hybrid heat pumps in the Installatiemonitor research was 4.6 kW. The heat.output_capacity is calculated here but not used, see row 85. The COP at bivalence capacity according to Bogdanov et al. (2024) is 2.7. Which is used to find the electrical capacity. *The capacity of the heat pump at the lowest outdoor temperature point at which the heat pump is declared to have a capacity able to meet 100 % of the heating load without supplementary heater This temperature is often around -7 °C as for the Sinclair SHP-140ICA + SHP-140ECA | G33: Main source: | H33: Installatiemonitor 3.0 | AH33: =AH32+1 -> 4 | AI33: 35 | AJ33: =AI33-AH33 -> 31 | AK33: =6.08 - 0.0941 * AJ33 + 0.000464 * AJ33^2 -> 3.608804 | AL33: =AL32+$AK$46 -> 3.61066 | AN33: =AN32+1 -> 4 | AO33: 40 | AP33: =AO33-AN33 -> 36 | AQ33: =6.08 - 0.0941 * AP33 + 0.000464 * AP33^2 -> 3.293744 | AR33: =AR32+$AQ$46 -> 3.2956 | AT33: =AT32+1 -> 4 | AU33: 45 | AV33: =AU33-AT33 -> 41 | AW33: =6.08 - 0.0941 * AV33 + 0.000464 * AV33^2 -> 3.001884 | AX33: =AX32+$AW$46 -> 3.00374
C34: fever.capacity.electricity | D34: =0.0046/2.7 -> 0.0017037037 | E34: MW | G34: Supporting source: | H34: Bogdanov et al. (2024) | AH34: =AH33+1 -> 5 | AI34: 35 | AJ34: =AI34-AH34 -> 30 | AK34: =6.08 - 0.0941 * AJ34 + 0.000464 * AJ34^2 -> 3.6746 | AL34: =AL33+$AK$46 -> 3.6746 | AN34: =AN33+1 -> 5 | AO34: 40 | AP34: =AO34-AN34 -> 35 | AQ34: =6.08 - 0.0941 * AP34 + 0.000464 * AP34^2 -> 3.3549 | AR34: =AR33+$AQ$46 -> 3.3549 | AT34: =AT33+1 -> 5 | AU34: 45 | AV34: =AU34-AT34 -> 40 | AW34: =6.08 - 0.0941 * AV34 + 0.000464 * AV34^2 -> 3.0584 | AX34: =AX33+$AW$46 -> 3.0584
G35: Supporting source: | H35: Sinclair | AH35: =AH34+1 -> 6 | AI35: 35 | AJ35: =AI35-AH35 -> 29 | AK35: =6.08 - 0.0941 * AJ35 + 0.000464 * AJ35^2 -> 3.741324 | AL35: =AL34+$AK$46 -> 3.73854 | AN35: =AN34+1 -> 6 | AO35: 40 | AP35: =AO35-AN35 -> 34 | AQ35: =6.08 - 0.0941 * AP35 + 0.000464 * AP35^2 -> 3.416984 | AR35: =AR34+$AQ$46 -> 3.4142 | AT35: =AT34+1 -> 6 | AU35: 45 | AV35: =AU35-AT35 -> 39 | AW35: =6.08 - 0.0941 * AV35 + 0.000464 * AV35^2 -> 3.115844 | AX35: =AX34+$AW$46 -> 3.11306
AH36: =AH35+1 -> 7 | AI36: 35 | AJ36: =AI36-AH36 -> 28 | AK36: =6.08 - 0.0941 * AJ36 + 0.000464 * AJ36^2 -> 3.808976 | AL36: =AL35+$AK$46 -> 3.80248 | AN36: =AN35+1 -> 7 | AO36: 40 | AP36: =AO36-AN36 -> 33 | AQ36: =6.08 - 0.0941 * AP36 + 0.000464 * AP36^2 -> 3.479996 | AR36: =AR35+$AQ$46 -> 3.4735 | AT36: =AT35+1 -> 7 | AU36: 45 | AV36: =AU36-AT36 -> 38 | AW36: =6.08 - 0.0941 * AV36 + 0.000464 * AV36^2 -> 3.174216 | AX36: =AX35+$AW$46 -> 3.16772
AH37: =AH36+1 -> 8 | AI37: 35 | AJ37: =AI37-AH37 -> 27 | AK37: =6.08 - 0.0941 * AJ37 + 0.000464 * AJ37^2 -> 3.877556 | AL37: =AL36+$AK$46 -> 3.86642 | AN37: =AN36+1 -> 8 | AO37: 40 | AP37: =AO37-AN37 -> 32 | AQ37: =6.08 - 0.0941 * AP37 + 0.000464 * AP37^2 -> 3.543936 | AR37: =AR36+$AQ$46 -> 3.5328 | AT37: =AT36+1 -> 8 | AU37: 45 | AV37: =AU37-AT37 -> 37 | AW37: =6.08 - 0.0941 * AV37 + 0.000464 * AV37^2 -> 3.233516 | AX37: =AX36+$AW$46 -> 3.22238
AH38: =AH37+1 -> 9 | AI38: 35 | AJ38: =AI38-AH38 -> 26 | AK38: =6.08 - 0.0941 * AJ38 + 0.000464 * AJ38^2 -> 3.947064 | AL38: =AL37+$AK$46 -> 3.93036 | AN38: =AN37+1 -> 9 | AO38: 40 | AP38: =AO38-AN38 -> 31 | AQ38: =6.08 - 0.0941 * AP38 + 0.000464 * AP38^2 -> 3.608804 | AR38: =AR37+$AQ$46 -> 3.5921 | AT38: =AT37+1 -> 9 | AU38: 45 | AV38: =AU38-AT38 -> 36 | AW38: =6.08 - 0.0941 * AV38 + 0.000464 * AV38^2 -> 3.293744 | AX38: =AX37+$AW$46 -> 3.27704
AH39: =AH38+1 -> 10 | AI39: 35 | AJ39: =AI39-AH39 -> 25 | AK39: =6.08 - 0.0941 * AJ39 + 0.000464 * AJ39^2 -> 4.0175 | AL39: =AL38+$AK$46 -> 3.9943 | AN39: =AN38+1 -> 10 | AO39: 40 | AP39: =AO39-AN39 -> 30 | AQ39: =6.08 - 0.0941 * AP39 + 0.000464 * AP39^2 -> 3.6746 | AR39: =AR38+$AQ$46 -> 3.6514 | AT39: =AT38+1 -> 10 | AU39: 45 | AV39: =AU39-AT39 -> 35 | AW39: =6.08 - 0.0941 * AV39 + 0.000464 * AV39^2 -> 3.3549 | AX39: =AX38+$AW$46 -> 3.3317
AH40: =AH39+1 -> 11 | AI40: 35 | AJ40: =AI40-AH40 -> 24 | AK40: =6.08 - 0.0941 * AJ40 + 0.000464 * AJ40^2 -> 4.088864 | AL40: =AL39+$AK$46 -> 4.05824 | AN40: =AN39+1 -> 11 | AO40: 40 | AP40: =AO40-AN40 -> 29 | AQ40: =6.08 - 0.0941 * AP40 + 0.000464 * AP40^2 -> 3.741324 | AR40: =AR39+$AQ$46 -> 3.7107 | AT40: =AT39+1 -> 11 | AU40: 45 | AV40: =AU40-AT40 -> 34 | AW40: =6.08 - 0.0941 * AV40 + 0.000464 * AV40^2 -> 3.416984 | AX40: =AX39+$AW$46 -> 3.38636
AH41: =AH40+1 -> 12 | AI41: 35 | AJ41: =AI41-AH41 -> 23 | AK41: =6.08 - 0.0941 * AJ41 + 0.000464 * AJ41^2 -> 4.161156 | AL41: =AL40+$AK$46 -> 4.12218 | AN41: =AN40+1 -> 12 | AO41: 40 | AP41: =AO41-AN41 -> 28 | AQ41: =6.08 - 0.0941 * AP41 + 0.000464 * AP41^2 -> 3.808976 | AR41: =AR40+$AQ$46 -> 3.77 | AT41: =AT40+1 -> 12 | AU41: 45 | AV41: =AU41-AT41 -> 33 | AW41: =6.08 - 0.0941 * AV41 + 0.000464 * AV41^2 -> 3.479996 | AX41: =AX40+$AW$46 -> 3.44102
AH42: =AH41+1 -> 13 | AI42: 35 | AJ42: =AI42-AH42 -> 22 | AK42: =6.08 - 0.0941 * AJ42 + 0.000464 * AJ42^2 -> 4.234376 | AL42: =AL41+$AK$46 -> 4.18612 | AN42: =AN41+1 -> 13 | AO42: 40 | AP42: =AO42-AN42 -> 27 | AQ42: =6.08 - 0.0941 * AP42 + 0.000464 * AP42^2 -> 3.877556 | AR42: =AR41+$AQ$46 -> 3.8293 | AT42: =AT41+1 -> 13 | AU42: 45 | AV42: =AU42-AT42 -> 32 | AW42: =6.08 - 0.0941 * AV42 + 0.000464 * AV42^2 -> 3.543936 | AX42: =AX41+$AW$46 -> 3.49568
AH43: =AH42+1 -> 14 | AI43: 35 | AJ43: =AI43-AH43 -> 21 | AK43: =6.08 - 0.0941 * AJ43 + 0.000464 * AJ43^2 -> 4.308524 | AL43: =AL42+$AK$46 -> 4.25006 | AN43: =AN42+1 -> 14 | AO43: 40 | AP43: =AO43-AN43 -> 26 | AQ43: =6.08 - 0.0941 * AP43 + 0.000464 * AP43^2 -> 3.947064 | AR43: =AR42+$AQ$46 -> 3.8886 | AT43: =AT42+1 -> 14 | AU43: 45 | AV43: =AU43-AT43 -> 31 | AW43: =6.08 - 0.0941 * AV43 + 0.000464 * AV43^2 -> 3.608804 | AX43: =AX42+$AW$46 -> 3.55034
AH44: =AH43+1 -> 15 | AI44: 35 | AJ44: =AI44-AH44 -> 20 | AK44: =6.08 - 0.0941 * AJ44 + 0.000464 * AJ44^2 -> 4.3836 | AL44: =AL43+$AK$46 -> 4.314 | AN44: =AN43+1 -> 15 | AO44: 40 | AP44: =AO44-AN44 -> 25 | AQ44: =6.08 - 0.0941 * AP44 + 0.000464 * AP44^2 -> 4.0175 | AR44: =AR43+$AQ$46 -> 3.9479 | AT44: =AT43+1 -> 15 | AU44: 45 | AV44: =AU44-AT44 -> 30 | AW44: =6.08 - 0.0941 * AV44 + 0.000464 * AV44^2 -> 3.6746 | AX44: =AX43+$AW$46 -> 3.605
AH46: Average COP per degree | AK46: =(AK44-AK19)/(AH44-AH19) -> 0.06394 | AN46: Average COP per degree | AQ46: =(AQ44-AQ19)/(AN44-AN19) -> 0.0593 | AT46: Average COP per degree | AW46: =(AW44-AW19)/(AT44-AT19) -> 0.05466
C48: initial_investment | D48: =AVERAGE(8512, 5351) -> 6931.5 | E48: € / # | F48: Average between min and max | G48: Main source: | H48: Update kengetallen Vesta Mais
C49: fixed_operation_and_maintenance_costs_per_year | D49: 50 | E49: € / year | F49: Directly from source
C60: technical_lifetime | D60: 15 | E60: years | G60: Main source: | H60: Factsheet warmtepompen
C66: fever.cop_cutoff | D66: =F76 -> 2.600238 | F66: Energy prices originate from older version of this node source analysis. The prices are outdated and should be updated. This update cannot, however, be isolated to this node. Interdependancies must be checked.
F68: Gas price: 81.4 euro /m3
...
