Workbook
Name base_year: [1]Dashboard!$E$14
Name base_year: [2]Dashboard!$E$13
Name BKB_plants: '[2]CEB allocation factors step 1'!$D$55
Name BKB_plants_carriers: '[2]CEB allocation factors step 1'!$F$17:$AT$17
Name blast_furnaces: '[2]CEB allocation factors step 1'!$D$50
Name blast_furnaces_carriers: '[2]CEB allocation factors step 1'!$F$12:$AT$12
Name charcoal_production_plants: '[2]CEB allocation factors step 1'!$D$63
Name charcoal_production_plants_carriers: '[2]CEB allocation factors step 1'!$F$25:$AT$25
Name chemical_and_petrochemical: '[2]CEB allocation factors step 1'!$D$69
Name chemical_and_petrochemical_carriers: '[2]CEB allocation factors step 1'!$F$31:$BC$31
Name coal_liquefaction_plants: '[2]CEB allocation factors step 1'!$D$57
Name coal_liquefaction_plants_carriers: '[2]CEB allocation factors step 1'!$F$19:$AT$19
Name coal_mines: '[2]CEB allocation factors step 1'!$D$48
Name coal_mines_carriers: '[2]CEB allocation factors step 1'!$F$10:$AT$10
Name coke_ovens: '[2]CEB allocation factors step 1'!$D$53
Name coke_ovens_carriers: '[2]CEB allocation factors step 1'!$F$15:$AT$15
Name construction: '[2]CEB allocation factors step 1'!$D$78
Name construction_carriers: '[2]CEB allocation factors step 1'!$F$40:$BC$40
Name country: [1]Dashboard!$E$13
Name country: [2]Dashboard!$E$12
Name ei_subsector_allo: '[2]CEB allocation factors step 2'!#REF!
Name food: '[2]CEB allocation factors step 1'!$D$75
Name food_carriers: '[2]CEB allocation factors step 1'!$F$37:$BC$37
Name gas_to_liquids_plants: '[2]CEB allocation factors step 1'!$D$59
Name gas_to_liquids_plants_carriers: '[2]CEB allocation factors step 1'!$F$21:$AT$21
Name gas_works: '[2]CEB allocation factors step 1'!$D$51
Name gas_works_carriers: '[2]CEB allocation factors step 1'!$F$13:$AT$13
Name gasification_plants: '[2]CEB allocation factors step 1'!$D$52
Name gasification_plants_carriers: '[2]CEB allocation factors step 1'!$F$14:$AT$14
Name i_subsector_allo: '[2]CEB allocation factors step 2'!#REF!
Name iron_and_steel: '[2]CEB allocation factors step 1'!$D$68
Name iron_and_steel_carriers: '[2]CEB allocation factors step 1'!$F$30:$BC$30
Name kWh_MJ_conversion: [2]Assumptions!$C$173
Name LangChoice: '[3]Main Menu'!$L$3
Name Liquefaction_regasification_plants: '[2]CEB allocation factors step 1'!$D$58
Name Liquefaction_regasification_plants_carriers: '[2]CEB allocation factors step 1'!$F$20:$AT$20
Name machinery: '[2]CEB allocation factors step 1'!$D$73
Name machinery_carriers: '[2]CEB allocation factors step 1'!$F$35:$BC$35
Name mining: '[2]CEB allocation factors step 1'!$D$74
Name mining_carriers: '[2]CEB allocation factors step 1'!$F$36:$BC$36
Name net_gross_conv: '[2]AP net-gross conversion'!$D$12
Name non_ferrous_metals: '[2]CEB allocation factors step 1'!$D$70
Name non_ferrous_metals_carriers: '[2]CEB allocation factors step 1'!$F$32:$BC$32
Name non_metallic_minerals: '[2]CEB allocation factors step 1'!$D$71
Name non_metallic_minerals_carriers: '[2]CEB allocation factors step 1'!$F$33:$BC$33
Name non_specified: '[2]CEB allocation factors step 1'!$D$64
Name non_specified_energy_carriers: '[2]CEB allocation factors step 1'!$F$26:$AT$26
Name non_specified_industry: '[2]CEB allocation factors step 1'!$D$80
Name non_specified_industry_carriers: '[2]CEB allocation factors step 1'!$F$42:$BC$42
Name oil_and_gas_extraction: '[2]CEB allocation factors step 1'!$D$49
Name oil_and_gas_extraction_carriers: '[2]CEB allocation factors step 1'!$F$11:$AT$11
Name oil_refineries: '[2]CEB allocation factors step 1'!$D$56
Name oil_refineries_carriers: '[2]CEB allocation factors step 1'!$F$18:$AT$18
Name paper: '[2]CEB allocation factors step 1'!$D$76
Name paper_carriers: '[2]CEB allocation factors step 1'!$F$38:$BC$38
Name patent_fuel_plants: '[2]CEB allocation factors step 1'!$D$54
Name patent_fuel_plants_carriers: '[2]CEB allocation factors step 1'!$F$16:$AT$16
Name switch_decc: '[2]Fuel allocation'!$C$130
Name switch_iea: '[2]Fuel allocation'!$C$89
Name switch_protermo: '[2]Fuel allocation'!$C$48

Sheet Cover Sheet
B2: Cover Sheet
B4: Document | C4: EB Eurostat to IEA format mapping
B5: Version # | C5: 2
B6: Country | C6: nl
B7: Year data | C7: 2023
B8: Date | C8: May 21, 2025
B9: Author | C9: Mathijs Bijkerk
B10: Organization | C10: Quintel
B12: Legend
B14: Cells | C14: Intermediate (calculation)
C15: Result
C16: Manual input
C17: Reference to manual input or data input
B19: Sheets | C19: Introductory
C20: Dashboard
C21: Research data
C22: Results
C23: Main calculations
C24: Additional calculations
C25: Output to csv
B28: Comments
B29: This file converts the energy balance from Eurostat to the IEA energy balance, which can then be imported to use for the ETM country dataset analyses.

Sheet Contents
B3: Unit conversion | C3: Value
B4: GJ per toe | C4: =41.868 -> 41.868
B5: TJ per ktoe | C5: =C4 -> 41.868
B6: TJ per GWh | C6: 3.6
B8: Energy balance sheets | C8: Explanation
B9: EUROSTAT EB TJ | C9: The energy balance loaded directly from Eurostat with values in TJ
B10: EUROSTAT CB GAS | C10: The commodity balance for gas loaded directly from Eurostat with values in TJ
B11: EUROSTAT CB OIL | C11: The commodity balance for oil loaded directly from Eurostat with values in thousand tonnes
B12: EUROSTAT CB summary | C12: The EUROSTAT CB GAS and EUROSTAT CB OIL combined. Missing values are set to 0 and the share of chemical and petrochemical industry in industry total for non-energetic demand is calculated
B13: EUROSTAT EB TJ GWH | C13: The EUROSTAT EB TJ with missing values set to 0, electricity production converted to GWh and non-energetic demand for chemical and petrochemical calculated based on the share calculated in EUROSTAT CB summary
B14: EUROSTAT EB products IEA | C14: The EUROSTAT EB TJ GWH with redundant flows removed and products mapped from Eurostat to IEA format
B15: EUROSTAT EB flows IEA | C15: The EUROSTAT EB products IEA with mapping of Eurostat flows to IEA format
B16: energy_balance | C16: Eurostat energy balance in IEA format that can be used as input for ETM analyses

Sheet Eurostat EB TJ
A1: Data extracted on 20/05/2025 09:24:04 from [ESTAT]
A2: Dataset: | B2: Complete energy balances [nrg_bal_c__custom_15262984]
A3: Last updated: | B3: 45779.958
A5: Time frequency | C5: Annual
A6: Unit of measure | C6: Terajoule
A7: Geopolitical entity (reporting) | C7: Netherlands
A8: Time | C8: 2023
A10: SIEC (Labels) | B10: Total | C10: Solid fossil fuels | D10: Anthracite | E10: Coking coal | F10: Other bituminous coal | G10: Sub-bituminous coal | H10: Lignite | I10: Coke oven coke | J10: Gas coke | K10: Patent fuel | L10: Brown coal briquettes | M10: Coal tar | N10: Manufactured gases | O10: Coke oven gas | P10: Gas works gas | Q10: Blast furnace gas | R10: Other recovered gases | S10: Peat and peat products | T10: Peat | U10: Peat products | V10: Oil shale and oil sands | W10: Natural gas | X10: Oil and petroleum products (excluding biofuel portion) | Y10: Crude oil | Z10: Natural gas liquids | AA10: Refinery feedstocks | AB10: Additives and oxygenates (excluding biofuel portion) | AC10: Other hydrocarbons | AD10: Refinery gas | AE10: Ethane | AF10: Liquefied petroleum gases | AG10: Naphtha | AH10: Aviation gasoline | AI10: Motor gasoline (excluding biofuel portion) | AJ10: Gasoline-type jet fuel | AK10: Kerosene-type jet fuel (excluding biofuel portion) | AL10: Other kerosene | AM10: Gas oil and diesel oil (excluding biofuel portion) | AN10: Fuel oil | AO10: White spirit and special boiling point industrial spirits | AP10: Lubricants | AQ10: Paraffin waxes | AR10: Petroleum coke | AS10: Bitumen | AT10: Other oil products n.e.c. | AU10: Renewables and biofuels | AV10: Hydro | AW10: Geothermal | AX10: Wind | AY10: Solar thermal | AZ10: Solar photovoltaic | BA10: Tide, wave, ocean | BB10: Ambient heat (heat pumps) | BC10: Primary solid biofuels | BD10: Charcoal | BE10: Pure biogasoline | BF10: Blended biogasoline | BG10: Pure biodiesels | BH10: Blended biodiesels | BI10: Pure bio jet kerosene | BJ10: Blended bio jet kerosene | BK10: Other liquid biofuels | BL10: Biogases | BM10: Industrial waste (non-renewable) | BN10: Renewable municipal waste | BO10: Non-renewable municipal waste | BP10: Non-renewable waste | BQ10: Nuclear heat | BR10: Electricity | BS10: Heat | BT10: Bioenergy | BU10: Fossil energy
A11: NRG_BAL (Labels)
A12: Primary production | B12: 867610.75 | C12: 0 | D12: 0 | E12: 0 | F12: 0 | G12: 0 | H12: 0 | I12: : | J12: : | K12: : | L12: : | M12: : | N12: : | O12: : | P12: : | Q12: : | R12: : | S12: 0 | T12: 0 | U12: : | V12: 0 | W12: 354715.59 | X12: 28144.413 | Y12: 13646.322 | Z12: 3753.552 | AA12: : | AB12: 10744.539 | AC12: 0 | AD12: : | AE12: : | AF12: : | AG12: : | AH12: : | AI12: : | AJ12: : | AK12: : | AL12: : | AM12: : | AN12: : | AO12: : | AP12: : | AQ12: : | AR12: : | AS12: : | AT12: : | AU12: 407113.1 | AV12: 249.728 | AW12: 6797.51 | AX12: 106290.29 | AY12: 1176 | AZ12: 70481.477 | BA12: 0 | BB12: 25524.613 | BC12: 65069.523 | BD12: : | BE12: 0 | BF12: : | BG12: 79792.507 | BH12: : | BI12: 0 | BJ12: : | BK12: 529.776 | BL12: 18758.186 | BM12: 1876.845 | BN12: 32443.485 | BO12: 28770.637 | BP12: 30647.482 | BQ12: 38959.053 | BR12: : | BS12: 8031.111 | BT12: 196593.48 | BU12: 413507.49
A13: Recovered and recycled products | B13: 13238.144 | C13: 0 | D13: 0 | E13: 0 | F13: 0 | G13: 0 | H13: 0 | I13: : | J13: : | K13: : | L13: : | M13: : | N13: : | O13: : | P13: : | Q13: : | R13: : | S13: 0 | T13: 0 | U13: : | V13: 0 | W13: : | X13: 13238.144 | Y13: : | Z13: : | AA13: : | AB13: : | AC13: : | AD13: 10953.163 | AE13: 0 | AF13: 0 | AG13: 0 | AH13: 0 | AI13: 0 | AJ13: 0 | AK13: 0 | AL13: 0 | AM13: 0 | AN13: 0 | AO13: 0 | AP13: 0 | AQ13: 0 | AR13: 0 | AS13: 0 | AT13: 2284.98 | AU13: 0 | AV13: : | AW13: : | AX13: : | AY13: : | AZ13: : | BA13: : | BB13: : | BC13: : | BD13: : | BE13: : | BF13: 0 | BG13: : | BH13: 0 | BI13: : | BJ13: 0 | BK13: : | BL13: : | BM13: : | BN13: : | BO13: : | BP13: : | BQ13: : | BR13: : | BS13: : | BT13: 0 | BU13: 13238.144
A14: Imports | B14: 7491212.8 | C14: 175944.88 | D14: 76.707 | E14: 104273.93 | F14: 70267.93 | G14: 0 | H14: 312.82 | I14: 1013.494 | J14: 0 | K14: 0 | L14: 0 | M14: 0 | N14: 0 | O14: 0 | P14: 0 | Q14: 0 | R14: 0 | S14: 0 | T14: 0 | U14: 0 | V14: 0 | W14: 1210080.1 | X14: 5974057.6 | Y14: 2294920 | Z14: 342371.57 | AA14: 0 | AB14: 49566.113 | AC14: 0 | AD14: : | AE14: 0 | AF14: 154555.46 | AG14: 809282.6 | AH14: 15.136 | AI14: 283288.16 | AJ14: 0 | AK14: 116138.49 | AL14: 26215.853 | AM14: 586131.1 | AN14: 987993.86 | AO14: 91210.988 | AP14: 98845.239 | AQ14: 8165.187 | AR14: 71527.952 | AS14: 19370.705 | AT14: 34459.2 | AU14: 56021.827 | AV14: : | AW14: 0 | AX14: : | AY14: 0 | AZ14: : | BA14: : | BB14: : | BC14: 33247.45 | BD14: 270 | BE14: 14512.149 | BF14: 0 | BG14: 0 | BH14: 0 | BI14: 0 | BJ14: 2646.424 | BK14: 0 | BL14: 0 | BM14: 0 | BN14: 5345.804 | BO14: 4740.619 | BP14: 4740.619 | BQ14: : | BR14: 70367.782 | BS14: 0 | BT14: 73101.232 | BU14: 7386950.8
A15: Exports | B15: 5249055.5 | C15: 13808.059 | D15: 0 | E15: 0 | F15: 0 | G15: 0 | H15: 0 | I15: 11551.996 | J15: 0 | K15: 0 | L15: 0 | M15: 2256.064 | N15: 0 | O15: 0 | P15: 0 | Q15: 0 | R15: 0 | S15: 0 | T15: 0 | U15: 0 | V15: 0 | W15: 598477.35 | X15: 4461947.2 | Y15: 788.797 | Z15: 4516.072 | AA15: 0 | AB15: 41038.536 | AC15: 0 | AD15: : | AE15: 0 | AF15: 95006.081 | AG15: 586802.53 | AH15: 2898.34 | AI15: 900051.24 | AJ15: 0 | AK15: 358648.68 | AL15: 36859.535 | AM15: 1113094.8 | AN15: 930513.51 | AO15: 97476.262 | AP15: 116913.85 | AQ15: 8041.743 | AR15: 59454.565 | AS15: 52617.433 | AT15: 57225.262 | AU15: 83245.667 | AV15: : | AW15: 0 | AX15: : | AY15: 0 | AZ15: : | BA15: : | BB15: : | BC15: 14253.745 | BD15: 0 | BE15: 0 | BF15: 3586.545 | BG15: 60817.298 | BH15: 3646.412 | BI15: 0 | BJ15: 0 | BK15: 0 | BL15: 0 | BM15: 0 | BN15: 941.667 | BO15: 835.063 | BP15: 835.063 | BQ15: : | BR15: 90742.1 | BS15: 0 | BT15: 95416.884 | BU15: 5113455.4
A16: Change in stock | B16: 59764.099 | C16: -3771.364 | D16: 0 | E16: -5064.566 | F16: 1532.651 | G16: 0 | H16: 0 | I16: -200.441 | J16: 0 | K16: 0 | L16: 0 | M16: -39.009 | N16: 0 | O16: 0 | P16: 0 | Q16: 0 | R16: 0 | S16: 0 | T16: 0 | U16: 0 | V16: 0 | W16: -28875.693 | X16: 79018.393 | Y16: 41615.452 | Z16: 1898.631 | AA16: 0 | AB16: 5334 | AC16: 0 | AD16: 0 | AE16: 0 | AF16: -726.803 | AG16: 1729.004 | AH16: 117.523 | AI16: 20247.457 | AJ16: 0 | AK16: -6270.947 | AL16: -536.971 | AM16: 10788.423 | AN16: 6224.694 | AO16: -320.472 | AP16: -1860.069 | AQ16: 278.699 | AR16: -3297.862 | AS16: 85.727 | AT16: 3711.908 | AU16: 13392.763 | AV16: : | AW16: : | AX16: : | AY16: : | AZ16: : | BA16: : | BB16: : | BC16: 0 | BD16: 0 | BE16: 222.045 | BF16: 0 | BG16: 13170.717 | BH16: 0 | BI16: 0 | BJ16: 0 | BK16: 0 | BL16: 0 | BM16: 0 | BN16: 0 | BO16: 0 | BP16: 0 | BQ16: : | BR16: : | BS16: : | BT16: 13096.992 | BU16: 46667.107
A17: Gross available energy | B17: 3182770.4 | C17: 158365.46 | D17: 76.707 | E17: 99209.364 | F17: 71800.581 | G17: 0 | H17: 312.82 | I17: -10738.942 | J17: 0 | K17: 0 | L17: 0 | M17: -2295.073 | N17: 0 | O17: 0 | P17: 0 | Q17: 0 | R17: 0 | S17: 0 | T17: 0 | U17: 0 | V17: 0 | W17: 937442.69 | X17: 1632511.3 | Y17: 2349392.9 | Z17: 343507.68 | AA17: 0 | AB17: 24606.116 | AC17: 0 | AD17: 10953.163 | AE17: 0 | AF17: 58822.581 | AG17: 224209.08 | AH17: -2765.681 | AI17: -596515.62 | AJ17: 0 | AK17: -248781.14 | AL17: -11180.653 | AM17: -516175.25 | AN17: 63705.041 | AO17: -6585.746 | AP17: -19928.679 | AQ17: 402.143 | AR17: 8775.525 | AS17: -33161.001 | AT17: -16769.173 | AU17: 393282.02 | AV17: 249.728 | AW17: 6797.51 | AX17: 106290.29 | AY17: 1176 | AZ17: 70481.477 | BA17: 0 | BB17: 25524.613 | BC17: 84063.228 | BD17: 270 | BE17: 14734.195 | BF17: -3586.545 | BG17: 32145.926 | BH17: -3646.412 | BI17: 0 | BJ17: 2646.424 | BK17: 529.776 | BL17: 18758.186 | BM17: 1876.845 | BN17: 36847.622 | BO17: 32676.193 | BP17: 34553.038 | BQ17: 38959.053 | BR17: -20374.319 | BS17: 8031.111 | BT17: 187374.82 | BU17: 2746908.1
A18: International maritime bunkers | B18: 448139.6 | C18: 0 | D18: 0 | E18: 0 | F18: 0 | G18: 0 | H18: 0 | I18: 0 | J18: 0 | K18: 0 | L18: 0 | M18: 0 | N18: 0 | O18: 0 | P18: 0 | Q18: 0 | R18: 0 | S18: 0 | T18: 0 | U18: 0 | V18: 0 | W18: 8644.067 | X18: 425726.08 | Y18: : | Z18: : | AA18: : | AB18: : | AC18: : | AD18: 0 | AE18: 0 | AF18: 0 | AG18: 0 | AH18: 0 | AI18: 0 | AJ18: 0 | AK18: 0 | AL18: 0 | AM18: 63394.95 | AN18: 357586.38 | AO18: 0 | AP18: 4744.75 | AQ18: 0 | AR18: 0 | AS18: 0 | AT18: 0 | AU18: 13769.454 | AV18: : | AW18: : | AX18: : | AY18: : | AZ18: : | BA18: : | BB18: : | BC18: : | BD18: : | BE18: : | BF18: 0 | BG18: : | BH18: 13769.454 | BI18: : | BJ18: 0 | BK18: : | BL18: : | BM18: : | BN18: : | BO18: : | BP18: : | BQ18: : | BR18: : | BS18: : | BT18: 13857.994 | BU18: 434281.6
A19: Gross inland consumption | B19: 2734630.8 | C19: 158365.46 | D19: 76.707 | E19: 99209.364 | F19: 71800.581 | G19: 0 | H19: 312.82 | I19: -10738.942 | J19: 0 | K19: 0 | L19: 0 | M19: -2295.073 | N19: 0 | O19: 0 | P19: 0 | Q19: 0 | R19: 0 | S19: 0 | T19: 0 | U19: 0 | V19: 0 | W19: 928798.63 | X19: 1206785.2 | Y19: 2349392.9 | Z19: 343507.68 | AA19: 0 | AB19: 24606.116 | AC19: 0 | AD19: 10953.163 | AE19: 0 | AF19: 58822.581 | AG19: 224209.08 | AH19: -2765.681 | AI19: -596515.62 | AJ19: 0 | AK19: -248781.14 | AL19: -11180.653 | AM19: -579570.2 | AN19: -293881.33 | AO19: -6585.746 | AP19: -24673.428 | AQ19: 402.143 | AR19: 8775.525 | AS19: -33161.001 | AT19: -16769.173 | AU19: 379512.57 | AV19: 249.728 | AW19: 6797.51 | AX19: 106290.29 | AY19: 1176 | AZ19: 70481.477 | BA19: 0 | BB19: 25524.613 | BC19: 84063.228 | BD19: 270 | BE19: 14734.195 | BF19: -3586.545 | BG19: 32145.926 | BH19: -17415.866 | BI19: 0 | BJ19: 2646.424 | BK19: 529.776 | BL19: 18758.186 | BM19: 1876.845 | BN19: 36847.622 | BO19: 32676.193 | BP19: 34553.038 | BQ19: 38959.053 | BR19: -20374.319 | BS19: 8031.111 | BT19: 173516.82 | BU19: 2312626.5
A20: International aviation | B20: 142333.25 | C20: : | D20: : | E20: : | F20: : | G20: : | H20: : | I20: : | J20: : | K20: : | L20: : | M20: : | N20: : | O20: : | P20: : | Q20: : | R20: : | S20: : | T20: : | U20: : | V20: : | W20: : | X20: 139686.82 | Y20: 0 | Z20: 0 | AA20: : | AB20: : | AC20: : | AD20: 0 | AE20: 0 | AF20: 0 | AG20: 0 | AH20: 0 | AI20: 0 | AJ20: 0 | AK20: 139686.82 | AL20: 0 | AM20: 0 | AN20: 0 | AO20: 0 | AP20: 0 | AQ20: 0 | AR20: 0 | AS20: 0 | AT20: 0 | AU20: 2646.424 | AV20: : | AW20: : | AX20: : | AY20: : | AZ20: : | BA20: : | BB20: : | BC20: : | BD20: : | BE20: : | BF20: 0 | BG20: : | BH20: 0 | BI20: : | BJ20: 2646.424 | BK20: : | BL20: : | BM20: : | BN20: : | BO20: : | BP20: : | BQ20: : | BR20: : | BS20: : | BT20: 2646.424 | BU20: 139686.82
A21: Total energy supply | B21: 2592297.5 | C21: 158365.46 | D21: 76.707 | E21: 99209.364 | F21: 71800.581 | G21: 0 | H21: 312.82 | I21: -10738.942 | J21: 0 | K21: 0 | L21: 0 | M21: -2295.073 | N21: 0 | O21: 0 | P21: 0 | Q21: 0 | R21: 0 | S21: 0 | T21: 0 | U21: 0 | V21: 0 | W21: 928798.63 | X21: 1067098.4 | Y21: 2349392.9 | Z21: 343507.68 | AA21: 0 | AB21: 24606.116 | AC21: 0 | AD21: 10953.163 | AE21: 0 | AF21: 58822.581 | AG21: 224209.08 | AH21: -2765.681 | AI21: -596515.62 | AJ21: 0 | AK21: -388467.96 | AL21: -11180.653 | AM21: -579570.2 | AN21: -293881.33 | AO21: -6585.746 | AP21: -24673.428 | AQ21: 402.143 | AR21: 8775.525 | AS21: -33161.001 | AT21: -16769.173 | AU21: 376866.14 | AV21: 249.728 | AW21: 6797.51 | AX21: 106290.29 | AY21: 1176 | AZ21: 70481.477 | BA21: 0 | BB21: 25524.613 | BC21: 84063.228 | BD21: 270 | BE21: 14734.195 | BF21: -3586.545 | BG21: 32145.926 | BH21: -17415.866 | BI21: 0 | BJ21: 0 | BK21: 529.776 | BL21: 18758.186 | BM21: 1876.845 | BN21: 36847.622 | BO21: 32676.193 | BP21: 34553.038 | BQ21: 38959.053 | BR21: -20374.319 | BS21: 8031.111 | BT21: 170870.4 | BU21: 2172939.7
A22: Gross inland consumption - Energy Efficiency Directive | B22: 2701075.1 | C22: : | D22: : | E22: : | F22: : | G22: : | H22: : | I22: : | J22: : | K22: : | L22: : | M22: : | N22: : | O22: : | P22: : | Q22: : | R22: : | S22: : | T22: : | U22: : | V22: : | W22: : | X22: : | Y22: : | Z22: : | AA22: : | AB22: : | AC22: : | AD22: : | AE22: : | AF22: : | AG22: : | AH22: : | AI22: : | AJ22: : | AK22: : | AL22: : | AM22: : | AN22: : | AO22: : | AP22: : | AQ22: : | AR22: : | AS22: : | AT22: : | AU22: : | AV22: : | AW22: : | AX22: : | AY22: : | AZ22: : | BA22: : | BB22: : | BC22: : | BD22: : | BE22: : | BF22: : | BG22: : | BH22: : | BI22: : | BJ22: : | BK22: : | BL22: : | BM22: : | BN22: : | BO22: : | BP22: : | BQ22: : | BR22: : | BS22: : | BT22: : | BU22: :
A23: Primary energy consumption - Energy Efficiency Directive | B23: 2252963.9 | C23: : | D23: : | E23: : | F23: : | G23: : | H23: : | I23: : | J23: : | K23: : | L23: : | M23: : | N23: : | O23: : | P23: : | Q23: : | R23: : | S23: : | T23: : | U23: : | V23: : | W23: : | X23: : | Y23: : | Z23: : | AA23: : | AB23: : | AC23: : | AD23: : | AE23: : | AF23: : | AG23: : | AH23: : | AI23: : | AJ23: : | AK23: : | AL23: : | AM23: : | AN23: : | AO23: : | AP23: : | AQ23: : | AR23: : | AS23: : | AT23: : | AU23: : | AV23: : | AW23: : | AX23: : | AY23: : | AZ23: : | BA23: : | BB23: : | BC23: : | BD23: : | BE23: : | BF23: : | BG23: : | BH23: : | BI23: : | BJ23: : | BK23: : | BL23: : | BM23: : | BN23: : | BO23: : | BP23: : | BQ23: : | BR23: : | BS23: : | BT23: : | BU23: :
A24: Final energy consumption - Energy Efficiency Directive | B24: 1715629.7 | C24: : | D24: : | E24: : | F24: : | G24: : | H24: : | I24: : | J24: : | K24: : | L24: : | M24: : | N24: : | O24: : | P24: : | Q24: : | R24: : | S24: : | T24: : | U24: : | V24: : | W24: : | X24: : | Y24: : | Z24: : | AA24: : | AB24: : | AC24: : | AD24: : | AE24: : | AF24: : | AG24: : | AH24: : | AI24: : | AJ24: : | AK24: : | AL24: : | AM24: : | AN24: : | AO24: : | AP24: : | AQ24: : | AR24: : | AS24: : | AT24: : | AU24: : | AV24: : | AW24: : | AX24: : | AY24: : | AZ24: : | BA24: : | BB24: : | BC24: : | BD24: : | BE24: : | BF24: : | BG24: : | BH24: : | BI24: : | BJ24: : | BK24: : | BL24: : | BM24: : | BN24: : | BO24: : | BP24: : | BQ24: : | BR24: : | BS24: : | BT24: : | BU24: :
A25: Gross inland consumption (Europe 2020-2030) | B25: : | C25: : | D25: : | E25: : | F25: : | G25: : | H25: : | I25: : | J25: : | K25: : | L25: : | M25: : | N25: : | O25: : | P25: : | Q25: : | R25: : | S25: : | T25: : | U25: : | V25: : | W25: : | X25: : | Y25: : | Z25: : | AA25: : | AB25: : | AC25: : | AD25: : | AE25: : | AF25: : | AG25: : | AH25: : | AI25: : | AJ25: : | AK25: : | AL25: : | AM25: : | AN25: : | AO25: : | AP25: : | AQ25: : | AR25: : | AS25: : | AT25: : | AU25: : | AV25: : | AW25: : | AX25: : | AY25: : | AZ25: : | BA25: : | BB25: : | BC25: : | BD25: : | BE25: : | BF25: : | BG25: : | BH25: : | BI25: : | BJ25: : | BK25: : | BL25: : | BM25: : | BN25: : | BO25: : | BP25: : | BQ25: : | BR25: : | BS25: : | BT25: : | BU25: :
A26: Primary energy consumption (Europe 2020-2030) | B26: : | C26: : | D26: : | E26: : | F26: : | G26: : | H26: : | I26: : | J26: : | K26: : | L26: : | M26: : | N26: : | O26: : | P26: : | Q26: : | R26: : | S26: : | T26: : | U26: : | V26: : | W26: : | X26: : | Y26: : | Z26: : | AA26: : | AB26: : | AC26: : | AD26: : | AE26: : | AF26: : | AG26: : | AH26: : | AI26: : | AJ26: : | AK26: : | AL26: : | AM26: : | AN26: : | AO26: : | AP26: : | AQ26: : | AR26: : | AS26: : | AT26: : | AU26: : | AV26: : | AW26: : | AX26: : | AY26: : | AZ26: : | BA26: : | BB26: : | BC26: : | BD26: : | BE26: : | BF26: : | BG26: : | BH26: : | BI26: : | BJ26: : | BK26: : | BL26: : | BM26: : | BN26: : | BO26: : | BP26: : | BQ26: : | BR26: : | BS26: : | BT26: : | BU26: :
A27: Final energy consumption (Europe 2020-2030) | B27: : | C27: : | D27: : | E27: : | F27: : | G27: : | H27: : | I27: : | J27: : | K27: : | L27: : | M27: : | N27: : | O27: : | P27: : | Q27: : | R27: : | S27: : | T27: : | U27: : | V27: : | W27: : | X27: : | Y27: : | Z27: : | AA27: : | AB27: : | AC27: : | AD27: : | AE27: : | AF27: : | AG27: : | AH27: : | AI27: : | AJ27: : | AK27: : | AL27: : | AM27: : | AN27: : | AO27: : | AP27: : | AQ27: : | AR27: : | AS27: : | AT27: : | AU27: : | AV27: : | AW27: : | AX27: : | AY27: : | AZ27: : | BA27: : | BB27: : | BC27: : | BD27: : | BE27: : | BF27: : | BG27: : | BH27: : | BI27: : | BJ27: : | BK27: : | BL27: : | BM27: : | BN27: : | BO27: : | BP27: : | BQ27: : | BR27: : | BS27: : | BT27: : | BU27: :
A28: Transformation input - energy use | B28: 5235619 | C28: 206016.9 | D28: 0 | E28: 99143.112 | F28: 71329.782 | G28: 0 | H28: 0 | I28: 35544.003 | J28: 0 | K28: 0 | L28: 0 | M28: 0 | N28: 18170.045 | O28: 1428.541 | P28: 0 | Q28: 16741.504 | R28: 0 | S28: 0 | T28: 0 | U28: 0 | V28: 0 | W28: 311308.08 | X28: 4282623.9 | Y28: 2427012.1 | Z28: 423903.74 | AA28: 366286 | AB28: 21733.941 | AC28: 0 | AD28: 114591.71 | AE28: 0 | AF28: 48544.435 | AG28: 582932.38 | AH28: 0.088 | AI28: 234.137 | AJ28: 0 | AK28: 60.075 | AL28: 4483.384 | AM28: 42952.313 | AN28: 136153.09 | AO28: 88997.347 | AP28: 13218.579 | AQ28: 3.416 | AR28: 0 | AS28: 52.207 | AT28: 11464.95 | AU28: 331913.16 | AV28: 249.728 | AW28: 0 | AX28: 106290.29 | AY28: 0 | AZ28: 70481.477 | BA28: 0 | BB28: 0 | BC28: 58457.757 | BD28: 0 | BE28: 14734.195 | BF28: 8.019 | BG28: 32145.926 | BH28: 0 | BI28: 0 | BJ28: 0 | BK28: 0 | BL28: 14208.23 | BM28: 1245.831 | BN28: 35337.54 | BO28: 31337.063 | BP28: 32582.894 | BQ28: 38959.053 | BR28: 362.92 | BS28: 13682.036 | BT28: 161108 | BU28: 4857192
A29: Transformation input - electricity and heat generation - energy use | B29: 780448.82 | C29: 71329.782 | D29: 0 | E29: 0 | F29: 71329.782 | G29: 0 | H29: 0 | I29: 0 | J29: 0 | K29: 0 | L29: 0 | M29: 0 | N29: 18170.045 | O29: 1428.541 | P29: 0 | Q29: 16741.504 | R29: 0 | S29: 0 | T29: 0 | U29: 0 | V29: 0 | W29: 311308.08 | X29: 18747.203 | Y29: 0 | Z29: 0 | AA29: 0 | AB29: 0 | AC29: 0 | AD29: 18291.896 | AE29: 0 | AF29: 0 | AG29: 0 | AH29: 0 | AI29: 0 | AJ29: 0 | AK29: 0 | AL29: 0 | AM29: 356.341 | AN29: 0 | AO29: 0 | AP29: 0 | AQ29: 0 | AR29: 0 | AS29: 0 | AT29: 98.966 | AU29: 275306.8 | AV29: 249.728 | AW29: 0 | AX29: 106290.29 | AY29: 0 | AZ29: 70481.477 | BA29: 0 | BB29: 0 | BC29: 58457.757 | BD29: 0 | BE29: 0 | BF29: 0 | BG29: 0 | BH29: 0 | BI29: 0 | BJ29: 0 | BK29: 0 | BL29: 4490.006 | BM29: 1245.831 | BN29: 35337.54 | BO29: 31337.063 | BP29: 32582.894 | BQ29: 38959.053 | BR29: 362.92 | BS29: 13682.036 | BT29: 104501.63 | BU29: 458628.18
A30: Transformation input - electricity and heat generation - main activity producer electricity only - energy use | B30: 358410.36 | C30: 41287.547 | D30: 0 | E30: 0 | F30: 41287.547 | G30: 0 | H30: 0 | I30: 0 | J30: 0 | K30: 0 | L30: 0 | M30: 0 | N30: 15697.981 | O30: 1331.16 | P30: 0 | Q30: 14366.821 | R30: 0 | S30: 0 | T30: 0 | U30: 0 | V30: 0 | W30: 137861.12 | X30: 98.942 | Y30: 0 | Z30: 0 | AA30: : | AB30: : | AC30: : | AD30: 0 | AE30: 0 | AF30: 0 | AG30: 0 | AH30: 0 | AI30: 0 | AJ30: 0 | AK30: 0 | AL30: 0 | AM30: 0 | AN30: 0 | AO30: 0 | AP30: 0 | AQ30: 0 | AR30: 0 | AS30: 0 | AT30: 98.942 | AU30: 124505.72 | AV30: 249.728 | AW30: 0 | AX30: 97847.003 | AY30: 0 | AZ30: 14464.667 | BA30: 0 | BB30: : | BC30: 11921.506 | BD30: : | BE30: 0 | BF30: 0 | BG30: 0 | BH30: 0 | BI30: 0 | BJ30: 0 | BK30: 0 | BL30: 22.813 | BM30: 0 | BN30: 0 | BO30: 0 | BP30: 0 | BQ30: 38959.053 | BR30: : | BS30: 0 | BT30: 13356.417 | BU30: 193533.49
A31: Transformation input - electricity and heat generation - main activity producer combined heat and power - energy use | B31: 142106.32 | C31: 30042.236 | D31: 0 | E31: 0 | F31: 30042.236 | G31: 0 | H31: 0 | I31: 0 | J31: 0 | K31: 0 | L31: 0 | M31: 0 | N31: 1672.513 | O31: 0.064 | P31: 0 | Q31: 1672.449 | R31: 0 | S31: 0 | T31: 0 | U31: 0 | V31: 0 | W31: 78425.109 | X31: 202.372 | Y31: 0 | Z31: 0 | AA31: : | AB31: : | AC31: : | AD31: 0 | AE31: 0 | AF31: 0 | AG31: 0 | AH31: 0 | AI31: 0 | AJ31: 0 | AK31: 0 | AL31: 0 | AM31: 202.372 | AN31: 0 | AO31: 0 | AP31: 0 | AQ31: 0 | AR31: 0 | AS31: 0 | AT31: 0 | AU31: 31509.637 | AV31: : | AW31: 0 | AX31: : | AY31: 0 | AZ31: : | BA31: : | BB31: : | BC31: 31227.247 | BD31: : | BE31: 0 | BF31: 0 | BG31: 0 | BH31: 0 | BI31: 0 | BJ31: 0 | BK31: 0 | BL31: 282.39 | BM31: 254.448 | BN31: 0 | BO31: 0 | BP31: 254.448 | BQ31: 0 | BR31: : | BS31: 0 | BT31: 32312.938 | BU31: 109793.38
A32: Transformation input - electricity and heat generation - main activity producer heat only - energy use | B32: 18399.78 | C32: 0 | D32: 0 | E32: 0 | F32: 0 | G32: 0 | H32: 0 | I32: 0 | J32: 0 | K32: 0 | L32: 0 | M32: 0 | N32: 0 | O32: 0 | P32: 0 | Q32: 0 | R32: 0 | S32: 0 | T32: 0 | U32: 0 | V32: 0 | W32: 10592.293 | X32: 3652.781 | Y32: 0 | Z32: 0 | AA32: : | AB32: : | AC32: : | AD32: 3652.757 | AE32: 0 | AF32: 0 | AG32: 0 | AH32: 0 | AI32: 0 | AJ32: 0 | AK32: 0 | AL32: 0 | AM32: 0 | AN32: 0 | AO32: 0 | AP32: 0 | AQ32: 0 | AR32: 0 | AS32: 0 | AT32: 0.024 | AU32: 4138.814 | AV32: : | AW32: 0 | AX32: : | AY32: 0 | AZ32: : | BA32: : | BB32: 0 | BC32: 4138.814 | BD32: : | BE32: 0 | BF32: 0 | BG32: 0 | BH32: 0 | BI32: 0 | BJ32: 0 | BK32: 0 | BL32: 0 | BM32: 15.892 | BN32: 0 | BO32: 0 | BP32: 15.892 | BQ32: 0 | BR32: : | BS32: 0 | BT32: 4247.31 | BU32: 14152.47
A33: Transformation input - electricity and heat generation - autoproducer electricity only - energy use | B33: 67696.36 | C33: 0 | D33: 0 | E33: 0 | F33: 0 | G33: 0 | H33: 0 | I33: 0 | J33: 0 | K33: 0 | L33: 0 | M33: 0 | N33: 0 | O33: 0 | P33: 0 | Q33: 0 | R33: 0 | S33: 0 | T33: 0 | U33: 0 | V33: 0 | W33: 2416.801 | X33: 625.532 | Y33: 0 | Z33: 0 | AA33: : | AB33: : | AC33: : | AD33: 621.131 | AE33: 0 | AF33: 0 | AG33: 0 | AH33: 0 | AI33: 0 | AJ33: 0 | AK33: 0 | AL33: 0 | AM33: 4.4 | AN33: 0 | AO33: 0 | AP33: 0 | AQ33: 0 | AR33: 0 | AS33: 0 | AT33: 0 | AU33: 64654.027 | AV33: 0 | AW33: 0 | AX33: 8443.289 | AY33: 0 | AZ33: 56016.81 | BA33: 0 | BB33: : | BC33: 0 | BD33: : | BE33: 0 | BF33: 0 | BG33: 0 | BH33: 0 | BI33: 0 | BJ33: 0 | BK33: 0 | BL33: 193.928 | BM33: 0 | BN33: 0 | BO33: 0 | BP33: 0 | BQ33: 0 | BR33: : | BS33: 0 | BT33: 218.683 | BU33: 3017.578
A34: Transformation input - electricity and heat generation - autoproducer combined heat and power - energy use | B34: 175821.42 | C34: 0 | D34: 0 | E34: 0 | F34: 0 | G34: 0 | H34: 0 | I34: 0 | J34: 0 | K34: 0 | L34: 0 | M34: 0 | N34: 799.551 | O34: 97.317 | P34: 0 | Q34: 702.234 | R34: 0 | S34: 0 | T34: 0 | U34: 0 | V34: 0 | W34: 79593.832 | X34: 13406.879 | Y34: 0 | Z34: 0 | AA34: : | AB34: : | AC34: : | AD34: 13257.311 | AE34: 0 | AF34: 0 | AG34: 0 | AH34: 0 | AI34: 0 | AJ34: 0 | AK34: 0 | AL34: 0 | AM34: 149.568 | AN34: 0 | AO34: 0 | AP34: 0 | AQ34: 0 | AR34: 0 | AS34: 0 | AT34: 0 | AU34: 50493.582 | AV34: : | AW34: 0 | AX34: : | AY34: 0 | AZ34: : | BA34: : | BB34: : | BC34: 11165.546 | BD34: : | BE34: 0 | BF34: 0 | BG34: 0 | BH34: 0 | BI34: 0 | BJ34: 0 | BK34: 0 | BL34: 3990.496 | BM34: 190.515 | BN34: 35337.54 | BO34: 31337.063 | BP34: 31527.578 | BQ34: 0 | BR34: : | BS34: 0 | BT34: 51308.854 | BU34: 124512.57
A35: Transformation input - electricity and heat generation - autoproducer heat only - energy use | B35: 12000.74 | C35: 0 | D35: 0 | E35: 0 | F35: 0 | G35: 0 | H35: 0 | I35: 0 | J35: 0 | K35: 0 | L35: 0 | M35: 0 | N35: 0 | O35: 0 | P35: 0 | Q35: 0 | R35: 0 | S35: 0 | T35: 0 | U35: 0 | V35: 0 | W35: 2418.933 | X35: 760.697 | Y35: 0 | Z35: 0 | AA35: : | AB35: : | AC35: : | AD35: 760.697 | AE35: 0 | AF35: 0 | AG35: 0 | AH35: 0 | AI35: 0 | AJ35: 0 | AK35: 0 | AL35: 0 | AM35: 0 | AN35: 0 | AO35: 0 | AP35: 0 | AQ35: 0 | AR35: 0 | AS35: 0 | AT35: 0 | AU35: 5.023 | AV35: : | AW35: 0 | AX35: : | AY35: 0 | AZ35: : | BA35: : | BB35: 0 | BC35: 4.644 | BD35: : | BE35: 0 | BF35: 0 | BG35: 0 | BH35: 0 | BI35: 0 | BJ35: 0 | BK35: 0 | BL35: 0.379 | BM35: 784.976 | BN35: 0 | BO35: 0 | BP35: 784.976 | BQ35: 0 | BR35: : | BS35: 8031.111 | BT35: 1792.784 | BU35: 9516.645
A36: Transformation input - electricity and heat generation - electrically driven heat pumps | B36: 0 | C36: : | D36: : | E36: : | F36: : | G36: : | H36: : | I36: : | J36: : | K36: : | L36: : | M36: : | N36: : | O36: : | P36: : | Q36: : | R36: : | S36: : | T36: : | U36: : | V36: : | W36: : | X36: : | Y36: : | Z36: : | AA36: : | AB36: : | AC36: : | AD36: : | AE36: : | AF36: : | AG36: : | AH36: : | AI36: : | AJ36: : | AK36: : | AL36: : | AM36: : | AN36: : | AO36: : | AP36: : | AQ36: : | AR36: : | AS36: : | AT36: : | AU36: : | AV36: : | AW36: : | AX36: : | AY36: : | AZ36: : | BA36: : | BB36: : | BC36: : | BD36: : | BE36: : | BF36: : | BG36: : | BH36: : | BI36: : | BJ36: : | BK36: : | BL36: : | BM36: : | BN36: : | BO36: : | BP36: : | BQ36: : | BR36: 0 | BS36: : | BT36: 0 | BU36: 0
A37: Transformation input - electricity and heat generation - electric boilers | B37: 0 | C37: : | D37: : | E37: : | F37: : | G37: : | H37: : | I37: : | J37: : | K37: : | L37: : | M37: : | N37: : | O37: : | P37: : | Q37: : | R37: : | S37: : | T37: : | U37: : | V37: : | W37: : | X37: : | Y37: : | Z37: : | AA37: : | AB37: : | AC37: : | AD37: : | AE37: : | AF37: : | AG37: : | AH37: : | AI37: : | AJ37: : | AK37: : | AL37: : | AM37: : | AN37: : | AO37: : | AP37: : | AQ37: : | AR37: : | AS37: : | AT37: : | AU37: : | AV37: : | AW37: : | AX37: : | AY37: : | AZ37: : | BA37: : | BB37: : | BC37: : | BD37: : | BE37: : | BF37: : | BG37: : | BH37: : | BI37: : | BJ37: : | BK37: : | BL37: : | BM37: : | BN37: : | BO37: : | BP37: : | BQ37: : | BR37: 0 | BS37: : | BT37: 0 | BU37: 0
A38: Transformation input - electricity and heat generation - electricity for pumped storage | B38: 0 | C38: : | D38: : | E38: : | F38: : | G38: : | H38: : | I38: : | J38: : | K38: : | L38: : | M38: : | N38: : | O38: : | P38: : | Q38: : | R38: : | S38: : | T38: : | U38: : | V38: : | W38: : | X38: : | Y38: : | Z38: : | AA38: : | AB38: : | AC38: : | AD38: : | AE38: : | AF38: : | AG38: : | AH38: : | AI38: : | AJ38: : | AK38: : | AL38: : | AM38: : | AN38: : | AO38: : | AP38: : | AQ38: : | AR38: : | AS38: : | AT38: : | AU38: : | AV38: : | AW38: : | AX38: : | AY38: : | AZ38: : | BA38: : | BB38: : | BC38: : | BD38: : | BE38: : | BF38: : | BG38: : | BH38: : | BI38: : | BJ38: : | BK38: : | BL38: : | BM38: : | BN38: : | BO38: : | BP38: : | BQ38: : | BR38: 0 | BS38: : | BT38: 0 | BU38: 0
A39: Transformation input - electricity and heat generation - derived heat for electricity production | B39: 5650.925 | C39: : | D39: : | E39: : | F39: : | G39: : | H39: : | I39: : | J39: : | K39: : | L39: : | M39: : | N39: : | O39: : | P39: : | Q39: : | R39: : | S39: : | T39: : | U39: : | V39: : | W39: : | X39: : | Y39: : | Z39: : | AA39: : | AB39: : | AC39: : | AD39: : | AE39: : | AF39: : | AG39: : | AH39: : | AI39: : | AJ39: : | AK39: : | AL39: : | AM39: : | AN39: : | AO39: : | AP39: : | AQ39: : | AR39: : | AS39: : | AT39: : | AU39: : | AV39: : | AW39: : | AX39: : | AY39: : | AZ39: : | BA39: : | BB39: : | BC39: : | BD39: : | BE39: : | BF39: : | BG39: : | BH39: : | BI39: : | BJ39: : | BK39: : | BL39: : | BM39: : | BN39: : | BO39: : | BP39: : | BQ39: : | BR39: : | BS39: 5650.925 | BT39: 1240.487 | BU39: 3924.011
A40: Transformation input - electricity and heat generation - charging batteries | B40: 362.92 | C40: : | D40: : | E40: : | F40: : | G40: : | H40: : | I40: : | J40: : | K40: : | L40: : | M40: : | N40: : | O40: : | P40: : | Q40: : | R40: : | S40: : | T40: : | U40: : | V40: : | W40: : | X40: : | Y40: : | Z40: : | AA40: : | AB40: : | AC40: : | AD40: : | AE40: : | AF40: : | AG40: : | AH40: : | AI40: : | AJ40: : | AK40: : | AL40: : | AM40: : | AN40: : | AO40: : | AP40: : | AQ40: : | AR40: : | AS40: : | AT40: : | AU40: : | AV40: : | AW40: : | AX40: : | AY40: : | AZ40: : | BA40: : | BB40: : | BC40: : | BD40: : | BE40: : | BF40: : | BG40: : | BH40: : | BI40: : | BJ40: : | BK40: : | BL40: : | BM40: : | BN40: : | BO40: : | BP40: : | BQ40: : | BR40: 362.92 | BS40: : | BT40: 24.161 | BU40: 178.048
A41: Transformation input - coke ovens - energy use | B41: 70878.617 | C41: 70878.617 | D41: 0 | E41: 70878.617 | F41: 0 | G41: 0 | H41: 0 | I41: 0 | J41: 0 | K41: 0 | L41: 0 | M41: 0 | N41: 0 | O41: 0 | P41: 0 | Q41: 0 | R41: 0 | S41: 0 | T41: 0 | U41: 0 | V41: 0 | W41: 0 | X41: 0 | Y41: 0 | Z41: 0 | AA41: : | AB41: : | AC41: : | AD41: 0 | AE41: 0 | AF41: 0 | AG41: 0 | AH41: 0 | AI41: 0 | AJ41: 0 | AK41: 0 | AL41: 0 | AM41: 0 | AN41: 0 | AO41: 0 | AP41: 0 | AQ41: 0 | AR41: 0 | AS41: 0 | AT41: 0 | AU41: 0 | AV41: : | AW41: : | AX41: : | AY41: : | AZ41: : | BA41: : | BB41: : | BC41: : | BD41: : | BE41: : | BF41: 0 | BG41: : | BH41: 0 | BI41: : | BJ41: 0 | BK41: : | BL41: : | BM41: : | BN41: : | BO41: : | BP41: : | BQ41: : | BR41: : | BS41: : | BT41: 0 | BU41: 70878.617
A42: Transformation input - blast furnaces - energy use | B42: 63808.498 | C42: 63808.498 | D42: 0 | E42: 28264.495 | F42: 0 | G42: 0 | H42: 0 | I42: 35544.003 | J42: 0 | K42: 0 | L42: 0 | M42: 0 | N42: 0 | O42: 0 | P42: 0 | Q42: 0 | R42: 0 | S42: 0 | T42: 0 | U42: 0 | V42: 0 | W42: 0 | X42: 0 | Y42: 0 | Z42: 0 | AA42: : | AB42: : | AC42: : | AD42: 0 | AE42: 0 | AF42: 0 | AG42: 0 | AH42: 0 | AI42: 0 | AJ42: 0 | AK42: 0 | AL42: 0 | AM42: 0 | AN42: 0 | AO42: 0 | AP42: 0 | AQ42: 0 | AR42: 0 | AS42: 0 | AT42: 0 | AU42: 0 | AV42: : | AW42: : | AX42: : | AY42: : | AZ42: : | BA42: : | BB42: : | BC42: : | BD42: 0 | BE42: 0 | BF42: 0 | BG42: 0 | BH42: 0 | BI42: 0 | BJ42: 0 | BK42: 0 | BL42: 0 | BM42: : | BN42: : | BO42: : | BP42: : | BQ42: : | BR42: : | BS42: : | BT42: 0 | BU42: 63808.498
...

Sheet EUROSTAT CB GAS
A1: Data extracted on 20/05/2025 17:13:51 from [ESTAT]
A2: Dataset: | B2: Supply, transformation and consumption of gas [nrg_cb_gas__custom_16789734]
A3: Last updated: | B3: 22/04/2025 23:00
A5: Time frequency | C5: Annual
A6: Unit of measure | C6: Terajoule (gross calorific value - GCV)
A7: Geopolitical entity (reporting) | C7: Netherlands
A8: Time | C8: 2023
A10: SIEC (Labels) | B10: Manufactured gases | D10: Coke oven gas | F10: Gas works gas | H10: Blast furnace gas | J10: Other recovered gases | L10: Natural gas
A11: NRG_BAL (Labels)
A12: Indigenous production | B12: 43816.264 | D12: 16684.745 | F12: 0 | H12: 27131.519 | J12: 0 | L12: 394128.44
A13: Indigenous production - associated gas | B13: : | D13: : | F13: : | H13: : | J13: : | L13: 0
A14: Indigenous production - non-associated gas | B14: : | D14: : | F14: : | H14: : | J14: : | L14: 394128.44
A15: Indigenous production - colliery gas | B15: : | D15: : | F15: : | H15: : | J15: : | L15: 0
A16: Transfer from other sources | B16: 0 | D16: 0 | F16: 0 | H16: 0 | J16: 0 | L16: 12592.766
A17: Transfer from other sources - oil | B17: 0 | D17: 0 | F17: 0 | H17: 0 | J17: 0 | L17: 1793.716
A18: Transfer from other sources - coal | B18: : | D18: : | F18: : | H18: : | J18: : | L18: 0
A19: Transfer from other sources - renewables | B19: 0 | D19: 0 | F19: 0 | H19: 0 | J19: 0 | L19: 10799.05
A20: Transfer from other sources - natural gas | B20: 0 | D20: 0 | F20: 0 | H20: 0 | J20: 0 | L20: :
A21: Imports | B21: 0 | D21: 0 | F21: 0 | H21: 0 | J21: 0 | L21: 1344533.5
A22: Exports | B22: 0 | D22: 0 | F22: 0 | H22: 0 | J22: 0 | L22: 664974.84
A23: Change in stock | B23: 0 | D23: 0 | F23: 0 | H23: 0 | J23: 0 | L23: -32084.103
A24: Change in stock - cushion gas | B24: : | D24: : | F24: : | H24: : | J24: : | L24: 0
A25: International maritime bunkers | B25: 0 | D25: 0 | F25: 0 | H25: 0 | J25: 0 | L25: 9604.519
A26: Inland consumption - calculated | B26: 43816.264 | D26: 16684.745 | F26: 0 | H26: 27131.519 | J26: 0 | L26: 1044591.2
A27: Inland consumption - observed | B27: : | D27: : | F27: : | H27: : | J27: : | L27: 1049006.5
A28: Inland demand | B28: : | D28: : | F28: : | H28: : | J28: : | L28: 1049006.5
A29: Transformation input - energy use | B29: 18328.772 | D29: 1587.268 | F29: 0 | H29: 16741.504 | J29: 0 | L29: 345897.87
A30: Transformation input - electricity and heat generation - main activity producer electricity only - energy use | B30: 15845.888 | D30: 1479.067 | F30: 0 | H30: 14366.821 | J30: 0 | L30: 153179.02
A31: Transformation input - electricity and heat generation - main activity producer combined heat and power - energy use | B31: 1672.52 | D31: 0.071 | F31: 0 | H31: 1672.449 | J31: 0 | L31: 87139.01
A32: Transformation input - electricity and heat generation - main activity producer heat only - energy use | B32: 0 | D32: 0 | F32: 0 | H32: 0 | J32: 0 | L32: 11769.215
A33: Transformation input - electricity and heat generation - autoproducer electricity only - energy use | B33: 0 | D33: 0 | F33: 0 | H33: 0 | J33: 0 | L33: 2685.335
A34: Transformation input - electricity and heat generation - autoproducer combined heat and power - energy use | B34: 810.364 | D34: 108.13 | F34: 0 | H34: 702.234 | J34: 0 | L34: 88437.591
A35: Transformation input - electricity and heat generation - autoproducer heat only - energy use | B35: 0 | D35: 0 | F35: 0 | H35: 0 | J35: 0 | L35: 2687.703
A36: Transformation input - coke ovens - energy use | B36: 0 | D36: 0 | F36: 0 | H36: 0 | J36: 0 | L36: 0
A37: Transformation input - blast furnaces - energy use | B37: 0 | D37: 0 | F37: 0 | H37: 0 | J37: 0 | L37: 0
A38: Transformation input - gas works - energy use | B38: 0 | D38: 0 | F38: 0 | H38: 0 | J38: 0 | L38: 0
A39: Transformation input - patent fuel plants - energy use | B39: 0 | D39: 0 | F39: 0 | H39: 0 | J39: 0 | L39: :
A40: Transformation input - brown coal briquettes and peat briquettes plants - energy use | B40: 0 | D40: 0 | F40: 0 | H40: 0 | J40: 0 | L40: :
A41: Transformation input - coal liquefaction plants - energy use | B41: 0 | D41: 0 | F41: 0 | H41: 0 | J41: 0 | L41: :
A42: Transformation input - for blending with natural gas - energy use | B42: 0 | D42: 0 | F42: 0 | H42: 0 | J42: 0 | L42: :
...

Sheet EUROSTAT CB OIL
A1: Data extracted on 20/05/2025 17:17:10 from [ESTAT]
A2: Dataset: | B2: Supply, transformation and consumption of oil and petroleum products [nrg_cb_oil__custom_16789812]
A3: Last updated: | B3: 10/04/2025 23:00
A5: Time frequency | C5: Annual
A6: Unit of measure | C6: Thousand tonnes
A7: Geopolitical entity (reporting) | C7: Netherlands
A8: Time | C8: 2023
A10: SIEC (Labels) | B10: Oil and petroleum products | D10: Oil and petroleum products (excluding biofuel portion) | F10: Crude oil, NGL, refinery feedstocks, additives and oxygenates and other hydrocarbons | H10: Crude oil, NGL, refinery feedstocks, additives and oxygenates and other hydrocarbons (excluding biofuel portion) | J10: Crude oil | L10: Natural gas liquids | N10: Refinery feedstocks | P10: Additives and oxygenates (excluding biofuel portion) | R10: Additives and oxygenates | T10: Biofuels for blending | V10: Other hydrocarbons | X10: Oil products | Z10: Oil products (excluding biofuel portion) | AB10: Refinery gas | AD10: Ethane | AF10: Liquefied petroleum gases | AH10: Naphtha | AJ10: Aviation gasoline | AL10: Motor gasoline | AN10: Motor gasoline (excluding biofuel portion) | AP10: Gasoline-type jet fuel | AR10: Kerosene-type jet fuel | AT10: Kerosene-type jet fuel (excluding biofuel portion) | AV10: Other kerosene | AX10: Gas oil and diesel oil | AZ10: Gas oil and diesel oil (excluding biofuel portion) | BB10: Road diesel | BD10: Heating and other gasoil | BF10: Fuel oil | BH10: Fuel oil (low sulphur <1%) | BJ10: Fuel oil (high sulphur >=1%) | BL10: White spirit and special boiling point industrial spirits | BN10: Lubricants | BP10: Paraffin waxes | BR10: Petroleum coke | BT10: Bitumen | BV10: Other oil products n.e.c. | BX10: Blended biogasoline | BZ10: Blended biodiesels | CB10: Blended bio jet kerosene
A11: NRG_BAL (Labels)
A12: Indigenous production | B12: 649.088 | D12: 649.088 | F12: 649.088 | H12: 649.088 | J12: 319.586 | L12: 85.308 | N12: : | P12: 244.194 | R12: 244.194 | T12: : | V12: 0 | X12: : | Z12: : | AB12: : | AD12: : | AF12: : | AH12: : | AJ12: : | AL12: : | AN12: : | AP12: : | AR12: : | AT12: : | AV12: : | AX12: : | AZ12: : | BB12: : | BD12: : | BF12: : | BH12: : | BJ12: : | BL12: : | BN12: : | BP12: : | BR12: : | BT12: : | BV12: : | BX12: : | BZ12: : | CB12: :
A13: Transfer from other sources | B13: 1011.033 | D13: 0 | F13: 1011.033 | H13: 0 | J13: : | L13: : | N13: : | P13: 0 | R13: 1011.033 | T13: 1011.033 | V13: 0 | X13: : | Z13: : | AB13: : | AD13: : | AF13: : | AH13: : | AJ13: : | AL13: : | AN13: : | AP13: : | AR13: : | AT13: : | AV13: : | AX13: : | AZ13: : | BB13: : | BD13: : | BF13: : | BH13: : | BJ13: : | BL13: : | BN13: : | BP13: : | BR13: : | BT13: : | BV13: : | BX13: : | BZ13: : | CB13: :
A14: Transfer from other sources - renewables | B14: 1011.033 | D14: 0 | F14: 1011.033 | H14: 0 | J14: : | L14: : | N14: : | P14: 0 | R14: 1011.033 | T14: 1011.033 | V14: 0 | X14: : | Z14: : | AB14: : | AD14: : | AF14: : | AH14: : | AJ14: : | AL14: : | AN14: : | AP14: : | AR14: : | AT14: : | AV14: : | AX14: : | AZ14: : | BB14: : | BD14: : | BF14: : | BH14: : | BJ14: : | BL14: : | BN14: : | BP14: : | BR14: : | BT14: : | BV14: : | BX14: : | BZ14: : | CB14: :
A15: Transfer from other sources - natural gas | B15: 0 | D15: 0 | F15: 0 | H15: 0 | J15: : | L15: : | N15: : | P15: 0 | R15: 0 | T15: 0 | V15: 0 | X15: : | Z15: : | AB15: : | AD15: : | AF15: : | AH15: : | AJ15: : | AL15: : | AN15: : | AP15: : | AR15: : | AT15: : | AV15: : | AX15: : | AZ15: : | BB15: : | BD15: : | BF15: : | BH15: : | BJ15: : | BL15: : | BN15: : | BP15: : | BR15: : | BT15: : | BV15: : | BX15: : | BZ15: : | CB15: :
A16: Recovered and recycled products | B16: 338.257 | D16: 338.257 | F16: : | H16: : | J16: : | L16: : | N16: : | P16: : | R16: : | T16: : | V16: : | X16: 338.257 | Z16: 338.257 | AB16: 242.347 | AD16: 0 | AF16: 0 | AH16: 0 | AJ16: 0 | AL16: 0 | AN16: 0 | AP16: 0 | AR16: 0 | AT16: 0 | AV16: 0 | AX16: 0 | AZ16: 0 | BB16: 0 | BD16: 0 | BF16: 0 | BH16: 0 | BJ16: 0 | BL16: 0 | BN16: 0 | BP16: 0 | BR16: 0 | BT16: 0 | BV16: 95.91 | BX16: 0 | BZ16: 0 | CB16: 0
A17: Imports | B17: 140657.88 | D17: 140597.73 | F17: 62659.727 | H17: 62659.727 | J17: 53745.266 | L17: 7781.345 | N17: 0 | P17: 1133.116 | R17: 1133.116 | T17: : | V17: 0 | X17: 77998.153 | Z17: 77938.007 | AB17: : | AD17: 0 | AF17: 3419.856 | AH17: 18400.959 | AJ17: 0.344 | AL17: 6540.847 | AN17: 6540.847 | AP17: 0 | AR17: 2729.928 | AT17: 2669.782 | AV17: 608.123 | AX17: 13586.538 | AZ17: 13586.538 | BB17: 9544.207 | BD17: 4042.331 | BF17: 24100.459 | BH17: 14956.399 | BJ17: 9144.06 | BL17: 2087.934 | BN17: 2387.556 | BP17: 191.225 | BR17: 2035.682 | BT17: 462.308 | BV17: 1446.394 | BX17: 0 | BZ17: 0 | CB17: 60.146
A18: Exports | B18: 105764.39 | D18: 105538.56 | F18: 1053.805 | H18: 1053.805 | J18: 18.473 | L18: 102.638 | N18: 0 | P18: 932.694 | R18: 932.694 | T18: : | V18: 0 | X18: 104710.58 | Z18: 104484.75 | AB18: : | AD18: 0 | AF18: 2102.204 | AH18: 13342.347 | AJ18: 65.872 | AL18: 20914.139 | AN18: 20781.304 | AP18: 0 | AR18: 8244.586 | AT18: 8244.586 | AV18: 855.022 | AX18: 25894.57 | AZ18: 25801.573 | BB18: 19038.224 | BD18: 6856.346 | BF18: 22698.322 | BH18: 17572.58 | BJ18: 5125.742 | BL18: 2231.354 | BN18: 2823.994 | BP18: 188.334 | BR18: 1692.074 | BT18: 1255.786 | BV18: 2401.979 | BX18: 132.835 | BZ18: 92.997 | CB18: 0
A19: Change in stock | B19: 2258.8 | D19: 1917.879 | F19: 1501.844 | H19: 1160.923 | J19: 974.603 | L19: 43.152 | N19: 0 | P19: 143.168 | R19: 484.089 | T19: 340.921 | V19: 0 | X19: 756.956 | Z19: 756.956 | AB19: 0 | AD19: 0 | AF19: -16.082 | AH19: 39.313 | AJ19: 2.671 | AL19: 467.494 | AN19: 467.494 | AP19: 0 | AR19: -144.156 | AT19: -144.156 | AV19: -12.456 | AX19: 250.076 | AZ19: 250.076 | BB19: 155.945 | BD19: 94.131 | BF19: 151.841 | BH19: 53.641 | BJ19: 98.2 | BL19: -7.336 | BN19: -44.929 | BP19: 6.527 | BR19: -93.857 | BT19: 2.046 | BV19: 155.804 | BX19: 0 | BZ19: 0 | CB19: 0
A20: Stock changes at main activity utilities | B20: 0 | D20: 0 | F20: 0 | H20: 0 | J20: 0 | L20: 0 | N20: : | P20: : | R20: : | T20: : | V20: : | X20: 0 | Z20: 0 | AB20: 0 | AD20: 0 | AF20: 0 | AH20: 0 | AJ20: 0 | AL20: 0 | AN20: 0 | AP20: 0 | AR20: 0 | AT20: 0 | AV20: 0 | AX20: 0 | AZ20: 0 | BB20: 0 | BD20: 0 | BF20: 0 | BH20: 0 | BJ20: 0 | BL20: 0 | BN20: 0 | BP20: 0 | BR20: 0 | BT20: 0 | BV20: 0 | BX20: 0 | BZ20: 0 | CB20: 0
A21: International maritime bunkers | B21: 10657.998 | D21: 10306.826 | F21: : | H21: : | J21: : | L21: : | N21: : | P21: : | R21: : | T21: : | V21: : | X21: 10657.998 | Z21: 10306.826 | AB21: 0 | AD21: 0 | AF21: 0 | AH21: 0 | AJ21: 0 | AL21: 0 | AN21: 0 | AP21: 0 | AR21: 0 | AT21: 0 | AV21: 0 | AX21: 1820.669 | AZ21: 1469.497 | BB21: 0 | BD21: 1820.669 | BF21: 8722.722 | BH21: 7691.833 | BJ21: 1030.889 | BL21: 0 | BN21: 114.607 | BP21: 0 | BR21: 0 | BT21: 0 | BV21: 0 | BX21: 0 | BZ21: 351.172 | CB21: 0
A22: Gross inland deliveries | B22: 28798.993 | D22: 27963.897 | F22: 3683.621 | H22: 3683.621 | J22: 0 | L22: 3683.621 | N22: : | P22: : | R22: : | T22: : | V22: : | X22: 25115.372 | Z22: 24280.276 | AB22: 2730.811 | AD22: 0 | AF22: 2405.974 | AH22: 5466.605 | AJ22: 1.292 | AL22: 4368.969 | AN22: 3969.69 | AP22: 0 | AR22: 3315.816 | AT22: 3255.67 | AV22: 46.933 | AX22: 5803.866 | AZ22: 5428.195 | BB22: 5398.555 | BD22: 405.313 | BF22: 0 | BH22: 0 | BJ22: 0 | BL22: 17.43 | BN22: 152.892 | BP22: 18.963 | BR22: 420.545 | BT22: 91.629 | BV22: 273.647 | BX22: 399.279 | BZ22: 375.671 | CB22: 60.146
A23: Gross inland deliveries - calculated | B23: 28799.292 | D23: 27964.196 | F23: 3683.621 | H23: 3683.621 | J23: 0 | L23: 3683.621 | N23: : | P23: : | R23: : | T23: : | V23: : | X23: 25115.671 | Z23: 24280.575 | AB23: 2730.811 | AD23: 0 | AF23: 2405.973 | AH23: 5466.605 | AJ23: 1.292 | AL23: 4369.267 | AN23: 3969.988 | AP23: 0 | AR23: 3315.816 | AT23: 3255.67 | AV23: 46.932 | AX23: 5803.869 | AZ23: 5428.198 | BB23: 5398.556 | BD23: 405.314 | BF23: -0.001 | BH23: -0.001 | BJ23: 0 | BL23: 17.43 | BN23: 152.893 | BP23: 18.963 | BR23: 420.544 | BT23: 91.629 | BV23: 273.648 | BX23: 399.279 | BZ23: 375.671 | CB23: 60.146
A24: Gross inland deliveries - observed | B24: 28798.993 | D24: 27963.897 | F24: 3683.621 | H24: 3683.621 | J24: 0 | L24: 3683.621 | N24: : | P24: : | R24: : | T24: : | V24: : | X24: 25115.372 | Z24: 24280.276 | AB24: 2730.811 | AD24: 0 | AF24: 2405.974 | AH24: 5466.605 | AJ24: 1.292 | AL24: 4368.969 | AN24: 3969.69 | AP24: 0 | AR24: 3315.816 | AT24: 3255.67 | AV24: 46.933 | AX24: 5803.866 | AZ24: 5428.195 | BB24: 5398.555 | BD24: 405.313 | BF24: 0 | BH24: 0 | BJ24: 0 | BL24: 17.43 | BN24: 152.892 | BP24: 18.963 | BR24: 420.545 | BT24: 91.629 | BV24: 273.647 | BX24: 399.279 | BZ24: 375.671 | CB24: 60.146
A25: Gross inland deliveries - energy use | B25: 19996.977 | D25: 19161.881 | F25: 1108.822 | H25: 1108.822 | J25: 0 | L25: 1108.822 | N25: : | P25: : | R25: : | T25: : | V25: : | X25: 18888.155 | Z25: 18053.059 | AB25: 2730.811 | AD25: 0 | AF25: 876.348 | AH25: 1740.095 | AJ25: 1.292 | AL25: 4368.969 | AN25: 3969.69 | AP25: 0 | AR25: 3315.816 | AT25: 3255.67 | AV25: 15.456 | AX25: 5803.293 | AZ25: 5427.622 | BB25: 5398.555 | BD25: 404.74 | BF25: 0 | BH25: 0 | BJ25: 0 | BL25: 0 | BN25: 0.944 | BP25: 0 | BR25: 1.827 | BT25: 0 | BV25: 33.304 | BX25: 399.279 | BZ25: 375.671 | CB25: 60.146
A26: Gross inland deliveries - non-energy use | B26: 8802.016 | D26: 8802.016 | F26: 2574.799 | H26: 2574.799 | J26: 0 | L26: 2574.799 | N26: : | P26: : | R26: : | T26: : | V26: : | X26: 6227.217 | Z26: 6227.217 | AB26: 0 | AD26: 0 | AF26: 1529.626 | AH26: 3726.51 | AJ26: 0 | AL26: 0 | AN26: 0 | AP26: 0 | AR26: 0 | AT26: 0 | AV26: 31.477 | AX26: 0.573 | AZ26: 0.573 | BB26: 0 | BD26: 0.573 | BF26: 0 | BH26: 0 | BJ26: 0 | BL26: 17.43 | BN26: 151.948 | BP26: 18.963 | BR26: 418.718 | BT26: 91.629 | BV26: 240.343 | BX26: 0 | BZ26: 0 | CB26: 0
A27: International aviation | B27: 3271.255 | D27: 3211.109 | F27: 0 | H27: 0 | J27: 0 | L27: 0 | N27: : | P27: : | R27: : | T27: : | V27: : | X27: 3271.255 | Z27: 3211.109 | AB27: 0 | AD27: 0 | AF27: 0 | AH27: 0 | AJ27: 0 | AL27: 0 | AN27: 0 | AP27: 0 | AR27: 3271.255 | AT27: 3211.109 | AV27: 0 | AX27: 0 | AZ27: 0 | BB27: 0 | BD27: 0 | BF27: 0 | BH27: 0 | BJ27: 0 | BL27: 0 | BN27: 0 | BP27: 0 | BR27: 0 | BT27: 0 | BV27: 0 | BX27: 0 | BZ27: 0 | CB27: 60.146
A28: International aviation - energy use | B28: 3271.255 | D28: 3211.109 | F28: 0 | H28: 0 | J28: 0 | L28: 0 | N28: : | P28: : | R28: : | T28: : | V28: : | X28: 3271.255 | Z28: 3211.109 | AB28: 0 | AD28: 0 | AF28: 0 | AH28: 0 | AJ28: 0 | AL28: 0 | AN28: 0 | AP28: 0 | AR28: 3271.255 | AT28: 3211.109 | AV28: 0 | AX28: 0 | AZ28: 0 | BB28: 0 | BD28: 0 | BF28: 0 | BH28: 0 | BJ28: 0 | BL28: 0 | BN28: 0 | BP28: 0 | BR28: 0 | BT28: 0 | BV28: 0 | BX28: 0 | BZ28: 0 | CB28: 60.146
A29: International aviation - non-energy use | B29: 0 | D29: 0 | F29: 0 | H29: 0 | J29: 0 | L29: 0 | N29: : | P29: : | R29: : | T29: : | V29: : | X29: 0 | Z29: 0 | AB29: 0 | AD29: 0 | AF29: 0 | AH29: 0 | AJ29: 0 | AL29: 0 | AN29: 0 | AP29: 0 | AR29: 0 | AT29: 0 | AV29: 0 | AX29: 0 | AZ29: 0 | BB29: 0 | BD29: 0 | BF29: 0 | BH29: 0 | BJ29: 0 | BL29: 0 | BN29: 0 | BP29: 0 | BR29: 0 | BT29: 0 | BV29: 0 | BX29: 0 | BZ29: 0 | CB29: 0
A30: Transformation input | B30: 3981.262 | D30: 3981.262 | F30: 1108.822 | H30: 1108.822 | J30: 0 | L30: 1108.822 | N30: : | P30: : | R30: : | T30: : | V30: : | X30: 2872.44 | Z30: 2872.44 | AB30: 440.437 | AD30: 0 | AF30: 665.973 | AH30: 1740.095 | AJ30: 0 | AL30: 0 | AN30: 0 | AP30: 0 | AR30: 0 | AT30: 0 | AV30: 10.401 | AX30: 8.509 | AZ30: 8.509 | BB30: 8.26 | BD30: 0.249 | BF30: 0 | BH30: 0 | BJ30: 0 | BL30: 0 | BN30: 0.944 | BP30: 0 | BR30: 0 | BT30: 0 | BV30: 6.081 | BX30: 0 | BZ30: 0 | CB30: 0
A31: Transformation input - energy use | B31: 3981.262 | D31: 3981.262 | F31: 1108.822 | H31: 1108.822 | J31: 0 | L31: 1108.822 | N31: : | P31: : | R31: : | T31: : | V31: : | X31: 2872.44 | Z31: 2872.44 | AB31: 440.437 | AD31: 0 | AF31: 665.973 | AH31: 1740.095 | AJ31: 0 | AL31: 0 | AN31: 0 | AP31: 0 | AR31: 0 | AT31: 0 | AV31: 10.401 | AX31: 8.509 | AZ31: 8.509 | BB31: 8.26 | BD31: 0.249 | BF31: 0 | BH31: 0 | BJ31: 0 | BL31: 0 | BN31: 0.944 | BP31: 0 | BR31: 0 | BT31: 0 | BV31: 6.081 | BX31: 0 | BZ31: 0 | CB31: 0
A32: Transformation input - electricity and heat generation - main activity producer electricity only | B32: 4.153 | D32: 4.153 | F32: 0 | H32: 0 | J32: 0 | L32: 0 | N32: : | P32: : | R32: : | T32: : | V32: : | X32: 4.153 | Z32: 4.153 | AB32: 0 | AD32: 0 | AF32: 0 | AH32: 0 | AJ32: 0 | AL32: 0 | AN32: 0 | AP32: 0 | AR32: 0 | AT32: 0 | AV32: 0 | AX32: 0 | AZ32: 0 | BB32: 0 | BD32: 0 | BF32: 0 | BH32: 0 | BJ32: 0 | BL32: 0 | BN32: 0 | BP32: 0 | BR32: 0 | BT32: 0 | BV32: 4.153 | BX32: 0 | BZ32: 0 | CB32: 0
A33: Transformation input - electricity and heat generation - main activity producer electricity only - energy use | B33: 4.153 | D33: 4.153 | F33: 0 | H33: 0 | J33: 0 | L33: 0 | N33: : | P33: : | R33: : | T33: : | V33: : | X33: 4.153 | Z33: 4.153 | AB33: 0 | AD33: 0 | AF33: 0 | AH33: 0 | AJ33: 0 | AL33: 0 | AN33: 0 | AP33: 0 | AR33: 0 | AT33: 0 | AV33: 0 | AX33: 0 | AZ33: 0 | BB33: 0 | BD33: 0 | BF33: 0 | BH33: 0 | BJ33: 0 | BL33: 0 | BN33: 0 | BP33: 0 | BR33: 0 | BT33: 0 | BV33: 4.153 | BX33: 0 | BZ33: 0 | CB33: 0
... A69: Transformation input - not elsewhere specified - non-energy use | B69: 0 | D69: 0 | F69: 0 | H69: 0 | J69: 0 | L69: 0 | N69: : | P69: : | R69: : | T69: : | V69: : | X69: 0 | Z69: 0 | AB69: 0 | AD69: 0 | AF69: 0 | AH69: 0 | AJ69: 0 | AL69: 0 | AN69: 0 | AP69: 0 | AR69: 0 | AT69: 0 | AV69: 0 | AX69: 0 | AZ69: 0 | BB69: 0 | BD69: 0 | BF69: 0 | BH69: 0 | BJ69: 0 | BL69: 0 | BN69: 0 | BP69: 0 | BR69: 0 | BT69: 0 | BV69: 0 | BX69: 0 | BZ69: 0 | CB69: 0
A70: Transformation output - refineries and petrochemical industry - refinery output | B70: 61047.505 | D70: 61047.505 | F70: : | H70: : | J70: : | L70: : | N70: : | P70: : | R70: : | T70: : | V70: : | X70: 61047.505 | Z70: 61047.505 | AB70: 2366.481 | AD70: 0 | AF70: 1288.171 | AH70: 11008.009 | AJ70: 64.151 | AL70: 4496.786 | AN70: 4496.786 | AP70: 0 | AR70: 7950.378 | AT70: 7950.378 | AV70: 398.768 | AX70: 19811.985 | AZ70: 19811.985 | BB70: 15350.033 | BD70: 4461.953 | BF70: 9589.994 | BH70: 8793.341 | BJ70: 796.653 | BL70: 913.367 | BN70: 1035.227 | BP70: 0 | BR70: 474.469 | BT70: 884.307 | BV70: 765.412 | BX70: 0 | BZ70: 0 | CB70: 0
A71: Energy sector | B71: 0.084 | D71: 0.084 | F71: 0 | H71: 0 | J71: 0 | L71: 0 | N71: : | P71: : | R71: : | T71: : | V71: : | X71: 0.084 | Z71: 0.084 | AB71: 0 | AD71: 0 | AF71: 0 | AH71: 0 | AJ71: 0 | AL71: 0 | AN71: 0 | AP71: 0 | AR71: 0 | AT71: 0 | AV71: 0 | AX71: 0.084 | AZ71: 0.084 | BB71: 0.084 | BD71: 0 | BF71: 0 | BH71: 0 | BJ71: 0 | BL71: 0 | BN71: 0 | BP71: 0 | BR71: 0 | BT71: 0 | BV71: 0 | BX71: 0 | BZ71: 0 | CB71: 0
A72: Energy sector - energy use | B72: 0.084 | D72: 0.084 | F72: 0 | H72: 0 | J72: 0 | L72: 0 | N72: : | P72: : | R72: : | T72: : | V72: : | X72: 0.084 | Z72: 0.084 | AB72: 0 | AD72: 0 | AF72: 0 | AH72: 0 | AJ72: 0 | AL72: 0 | AN72: 0 | AP72: 0 | AR72: 0 | AT72: 0 | AV72: 0 | AX72: 0.084 | AZ72: 0.084 | BB72: 0.084 | BD72: 0 | BF72: 0 | BH72: 0 | BJ72: 0 | BL72: 0 | BN72: 0 | BP72: 0 | BR72: 0 | BT72: 0 | BV72: 0 | BX72: 0 | BZ72: 0 | CB72: 0
A73: Energy sector - electricity and heat generation | B73: 0.084 | D73: 0.084 | F73: 0 | H73: 0 | J73: 0 | L73: 0 | N73: : | P73: : | R73: : | T73: : | V73: : | X73: 0.084 | Z73: 0.084 | AB73: 0 | AD73: 0 | AF73: 0 | AH73: 0 | AJ73: 0 | AL73: 0 | AN73: 0 | AP73: 0 | AR73: 0 | AT73: 0 | AV73: 0 | AX73: 0.084 | AZ73: 0.084 | BB73: 0.084 | BD73: 0 | BF73: 0 | BH73: 0 | BJ73: 0 | BL73: 0 | BN73: 0 | BP73: 0 | BR73: 0 | BT73: 0 | BV73: 0 | BX73: 0 | BZ73: 0 | CB73: 0
A74: Energy sector - electricity and heat generation - energy use | B74: 0.084 | D74: 0.084 | F74: 0 | H74: 0 | J74: 0 | L74: 0 | N74: : | P74: : | R74: : | T74: : | V74: : | X74: 0.084 | Z74: 0.084 | AB74: 0 | AD74: 0 | AF74: 0 | AH74: 0 | AJ74: 0 | AL74: 0 | AN74: 0 | AP74: 0 | AR74: 0 | AT74: 0 | AV74: 0 | AX74: 0.084 | AZ74: 0.084 | BB74: 0.084 | BD74: 0 | BF74: 0 | BH74: 0 | BJ74: 0 | BL74: 0 | BN74: 0 | BP74: 0 | BR74: 0 | BT74: 0 | BV74: 0 | BX74: 0 | BZ74: 0 | CB74: 0
A75: Energy sector - electricity and heat generation - non-energy use | B75: 0 | D75: 0 | F75: 0 | H75: 0 | J75: 0 | L75: 0 | N75: : | P75: : | R75: : | T75: : | V75: : | X75: 0 | Z75: 0 | AB75: 0 | AD75: 0 | AF75: 0 | AH75: 0 | AJ75: 0 | AL75: 0 | AN75: 0 | AP75: 0 | AR75: 0 | AT75: 0 | AV75: 0 | AX75: 0 | AZ75: 0 | BB75: 0 | BD75: 0 | BF75: 0 | BH75: 0 | BJ75: 0 | BL75: 0 | BN75: 0 | BP75: 0 | BR75: 0 | BT75: 0 | BV75: 0 | BX75: 0 | BZ75: 0 | CB75: 0
A76: Energy sector - coal mines | B76: 0 | D76: 0 | F76: 0 | H76: 0 | J76: 0 | L76: 0 | N76: : | P76: : | R76: : | T76: : | V76: : | X76: 0 | Z76: 0 | AB76: 0 | AD76: 0 | AF76: 0 | AH76: 0 | AJ76: 0 | AL76: 0 | AN76: 0 | AP76: 0 | AR76: 0 | AT76: 0 | AV76: 0 | AX76: 0 | AZ76: 0 | BB76: 0 | BD76: 0 | BF76: 0 | BH76: 0 | BJ76: 0 | BL76: 0 | BN76: 0 | BP76: 0 | BR76: 0 | BT76: 0 | BV76: 0 | BX76: 0 | BZ76: 0 | CB76: 0
A77: Energy sector - coal mines - energy use | B77: 0 | D77: 0 | F77: 0 | H77: 0 | J77: 0 | L77: 0 | N77: : | P77: : | R77: : | T77: : | V77: : | X77: 0 | Z77: 0 | AB77: 0 | AD77: 0 | AF77: 0 | AH77: 0 | AJ77: 0 | AL77: 0 | AN77: 0 | AP77: 0 | AR77: 0 | AT77: 0 | AV77: 0 | AX77: 0 | AZ77: 0 | BB77: 0 | BD77: 0 | BF77: 0 | BH77: 0 | BJ77: 0 | BL77: 0 | BN77: 0 | BP77: 0 | BR77: 0 | BT77: 0 | BV77: 0 | BX77: 0 | BZ77: 0 | CB77: 0
...

Sheet EUROSTAT CB summary
A1: SIEC (Labels) | B1: Manufactured gases | C1: Coke oven gas | D1: Gas works gas | E1: Blast furnace gas | F1: Other recovered gases | G1: Natural gas | H1: Oil and petroleum products | I1: Oil and petroleum products (excluding biofuel portion) | J1: Crude oil, NGL, refinery feedstocks, additives and oxygenates and other hydrocarbons | K1: Crude oil, NGL, refinery feedstocks, additives and oxygenates and other hydrocarbons (excluding biofuel portion) | L1: Crude oil | M1: Natural gas liquids | N1: Refinery feedstocks | O1: Additives and oxygenates (excluding biofuel portion) | P1: Additives and oxygenates | Q1: Biofuels for blending | R1: Other hydrocarbons | S1: Oil products | T1: Oil products (excluding biofuel portion) | U1: Refinery gas | V1: Ethane | W1: Liquefied petroleum gases | X1: Naphtha | Y1: Aviation gasoline | Z1: Motor gasoline | AA1: Motor gasoline (excluding biofuel portion) | AB1: Gasoline-type jet fuel | AC1: Kerosene-type jet fuel | AD1: Kerosene-type jet fuel (excluding biofuel portion) | AE1: Other kerosene | AF1: Gas oil and diesel oil | AG1: Gas oil and diesel oil (excluding biofuel portion) | AH1: Road diesel | AI1: Heating and other gasoil | AJ1: Fuel oil | AK1: Fuel oil (low sulphur <1%) | AL1: Fuel oil (high sulphur >=1%) | AM1: White spirit and special boiling point industrial spirits | AN1: Lubricants | AO1: Paraffin waxes | AP1: Petroleum coke | AQ1: Bitumen | AR1: Other oil products n.e.c. | AS1: Blended biogasoline | AT1: Blended biodiesels | AU1: Blended bio jet kerosene
A2: NRG_BAL (Labels)
