Workbook
Name ap_subfuel_allo: '[1]CEB allocation factors'!$F$12:$BC$12
Name base_year: [1]Dashboard!$E$13
Name country: [1]Dashboard!$E$12
Name Eff_cooking_biomass: [2]technical_specs!$M$50
Name Eff_cooking_electric: [2]technical_specs!$M$47
Name Eff_cooking_gas: [2]technical_specs!$M$46
Name Eff_cooking_halogen: [2]technical_specs!$M$48
Name Eff_cooking_induction: [2]technical_specs!$M$49
Name Eff_cooling_airco: [2]technical_specs!$M$43
Name Eff_cooling_pump_air: [2]technical_specs!$M$42
Name Eff_cooling_pump_ground: [2]technical_specs!$M$41
Name Eff_hot_water_coal: [2]technical_specs!$M$36
Name Eff_hot_water_combi_boiler: [2]technical_specs!$M$26
Name Eff_hot_water_district: [2]technical_specs!$M$30
Name Eff_hot_water_electric: [2]technical_specs!$M$33
Name Eff_hot_water_fuel_cell: [2]technical_specs!$M$37
Name Eff_hot_water_gas: [2]technical_specs!$M$34
Name Eff_hot_water_micro_CHP: [2]technical_specs!$M$29
Name Eff_hot_water_oil: [2]technical_specs!$M$35
Name Eff_hot_water_pump_air: [2]technical_specs!$M$31
Name Eff_hot_water_pump_ground: [2]technical_specs!$M$28
Name Eff_hot_water_solar_thermal_panel: [2]technical_specs!$M$27
Name Eff_hot_water_woodpellets: [2]technical_specs!$M$32
Name Eff_lighting_fluorescent: [2]technical_specs!$M$54
Name Eff_lighting_incandescent: [2]technical_specs!$M$53
Name Eff_lighting_led: [2]technical_specs!$M$55
Name Eff_space_heating_coal: [2]technical_specs!$M$21
Name Eff_space_heating_combi_boiler: [2]technical_specs!$M$11
Name Eff_space_heating_district: [2]technical_specs!$M$15
Name Eff_space_heating_electric: [2]technical_specs!$M$18
Name Eff_space_heating_gas: [2]technical_specs!$M$19
Name Eff_space_heating_micro_CHP: [2]technical_specs!$M$14
Name Eff_space_heating_oil: [2]technical_specs!$M$20
Name Eff_space_heating_pump_add_on: [2]technical_specs!$M$22
Name Eff_space_heating_pump_air: [2]technical_specs!$M$16
Name Eff_space_heating_pump_ground: [2]technical_specs!$M$13
Name Eff_space_heating_solar_thermal: [2]technical_specs!$M$12
Name Eff_space_heating_woodpellets: [2]technical_specs!$M$17
Name ei_subsector_allo: '[1]CEB allocation factors'!$D$17:$D$33
Name Final_demand_appliances: [2]Dashboard!$E$25
Name Final_demand_coal: '[2]Fuel aggregation'!$C$11
Name Final_demand_cooking: [2]Dashboard!$E$24
Name Final_demand_cooling: [2]Dashboard!$E$22
Name Final_demand_electricity: '[2]Fuel aggregation'!$I$11
Name Final_demand_gas: '[2]Fuel aggregation'!$D$11
Name Final_demand_heat: '[2]Fuel aggregation'!$J$11
Name Final_demand_hot_water: [2]Dashboard!$E$21
Name Final_demand_lighting: [2]Dashboard!$E$23
Name Final_demand_oil: '[2]Fuel aggregation'!$E$11
Name Final_demand_residences: '[2]Fuel aggregation'!$L$11
Name Final_demand_solar_thermal: '[2]Fuel aggregation'!$G$11
Name Final_demand_space_heating: [3]Dashboard!$E$23
Name Final_demand_woodpellets: '[2]Fuel aggregation'!$F$11
Name i_subsector_allo: '[1]CEB allocation factors'!$D$37:$D$49
Name kWh_MJ_conversion: [1]Assumptions!$C$174
Name net_gross_conv: '[1]AP net-gross conversion'!$D$12
Name switch_decc: '[1]Fuel allocation'!$C$130
Name switch_iea: '[1]Fuel allocation'!$C$89
Name switch_protermo: '[1]Fuel allocation'!$C$48
Name TWh_to_TJ: #REF!

Sheet Overview
A1: Category | B1: value | C1: unit | D1: comment
A2: number_of_inhabitants | B2: =CBS!C10 -> 17811291 | C2: - | D2: Bevolking; kerncijfers CBS; https://opendata.cbs.nl/statline/#/CBS/nl/dataset/70072ned/table?dl=C2207
A3: non_energetic_emissions_co2_chemical_industry | B3: =Emissions!B24 -> 7.9916497 | C3: Mton | D3: EEA 2023; see source_analyses/general/11_area/greenhouse_gas_emissions.xlsx
A4: non_energetic_emissions_co2_other_industry | B4: =Emissions!B25 -> 0.38933336 | C4: Mton | D4: Adjusted value based on expected non-energetic emissions from ETM
A5: non_energetic_emissions_co2_agriculture_manure | B5: =Emissions!B26 -> 0.06806927 | C5: Mton | D5: EEA 2023; see source_analyses/general/11_area/greenhouse_gas_emissions.xlsx
A6: non_energetic_emissions_co2_agriculture_soil_cultivation | B6: =Emissions!B27 -> 0.02514402 | C6: Mton | D6: EEA 2023; see source_analyses/general/11_area/greenhouse_gas_emissions.xlsx
A7: non_energetic_emissions_co2_waste_management | B7: =Emissions!B28 -> 0 | C7: Mton | D7: EEA 2023; see source_analyses/general/11_area/greenhouse_gas_emissions.xlsx
A8: indirect_emissions_co2 | B8: =Emissions!B29 -> 0.43273137 | C8: Mton | D8: EEA 2023; see source_analyses/general/11_area/greenhouse_gas_emissions.xlsx
A9: energetic_emissions_other_ghg_industry | B9: =Emissions!B30 -> 0.09816614 | C9: Mton | D9: EEA 2023; see source_analyses/general/11_area/greenhouse_gas_emissions.xlsx
A10: energetic_emissions_other_ghg_energy | B10: =Emissions!B31 -> 0.76029801 | C10: Mton | D10: EEA 2023; see source_analyses/general/11_area/greenhouse_gas_emissions.xlsx
A11: energetic_emissions_other_ghg_transport | B11: =Emissions!B32 -> 0.39751161 | C11: Mton | D11: EEA 2023; see source_analyses/general/11_area/greenhouse_gas_emissions.xlsx
A12: energetic_emissions_other_ghg_buildings | B12: =Emissions!B33 -> 0.06599546 | C12: Mton | D12: EEA 2023; see source_analyses/general/11_area/greenhouse_gas_emissions.xlsx
A13: energetic_emissions_other_ghg_households | B13: =Emissions!B34 -> 0.29499943 | C13: Mton | D13: EEA 2023; see source_analyses/general/11_area/greenhouse_gas_emissions.xlsx
A14: energetic_emissions_other_ghg_agriculture | B14: =Emissions!B35 -> 0.96057986 | C14: Mton | D14: EEA 2023; see source_analyses/general/11_area/greenhouse_gas_emissions.xlsx
... A21: non_energetic_emissions_other_ghg_waste_management | B21: =Emissions!B42 -> 2.6747815 | C21: Mton | D21: EEA 2023; see source_analyses/general/11_area/greenhouse_gas_emissions.xlsx
A22: present_number_of_buildings_present | B22: ='Building stock'!B4 -> 2791335.2 | D22: EU Building Stock Observatory; surface area covered by non-residential buildings and expressed in 'woningequivalenten' (WEQ)
A23: typical_useful_demand_for_space_heating_buildings_present | B23: =ROUND('Building stock'!B26,3) -> 242.357 | C23: kWh/m2 | D23: Aggregated result of built environment analysis for Dutch municipalities; see pipelines/Built environment stock Dutch municipalities.ipynb
A24: co2_price | B24: ='CO2 price'!B2 -> 0.085 | C24: euro/kg | D24: PBL KEV 2024; https://www.pbl.nl/publicaties/klimaat-en-energieverkenning-2024
A25: co2_percentage_free | B25: ='Free allocation'!$C$44 -> 0.13 | C25: % | D25: Share of free allowances in industry assigned to the share of industry in total electricity production; see sheet "Free allocation"
A26: number_of_cars | B26: ='Eurostat Cars'!B13 -> 9067393 | C26: - | D26: Retrieved from Eurostat table 'Passenger cars by age', https://doi.org/10.2908/ROAD_EQS_CARAGE
A27: number_of_busses | B27: ='Eurostat Buses'!B13 -> 8675 | C27: - | D27: Retrieved from Eurostat table 'Motor coaches, buses and trolley buses, by type of vehicle', https://doi.org/10.2908/ROAD_EQS_BUSVEH
A28: number_of_trucks | B28: ='Eurostat Vans and trucks'!B14 -> 61521 | C28: - | D28: Retrieved from Eurostat table 'Lorries, by type of motor energy', https://doi.org/10.2908/ROAD_EQS_LORMOT
A29: number_of_vans | B29: ='Eurostat Vans and trucks'!B15 -> 1006477 | C29: - | D29: Retrieved from Eurostat table 'Lorries, by type of motor energy', https://doi.org/10.2908/ROAD_EQS_LORMOT

Sheet Free allocation
B2: Unit type | C2: Total electricity production (TJ) | D2: Comment
B3: Coal/Wood pellets Ultra supercritical co-firing | C3: 9969.364 | D3: "Results by machine" taken from 2_power_and_heat_plant_analysis
B4: Coal Supercritical | C4: 1.3336237
B5: Coal Ultra supercritical | C5: 13489.767
B6: Coal Ultra supercritical ccs | C6: 0
B7: Coal Combined cycle | C7: 0
B8: Coal Combined cycle ccs | C8: 0
B9: Coal gas Combined cycle | C9: 6210.288
B10: Lignite Ultra supercritical | C10: 0
B11: Lignite Ultra supercritical oxyfuel ccs | C11: 0
B12: Gas Engine | C12: 58.306934
B13: Gas Turbine | C13: 0
B14: Gas Combined cycle | C14: 75472.294
B15: Gas Combined cycle ccs | C15: 0
... B35: Industry CHP engine fuelmix | C35: 7838.6034
B38: Calculations | C38: Value | D38: Comment
B39: Total electricity production | C39: =SUM(C3:C35) -> 352931.62 | D39: TJ
B40: Industry electricity production | C40: =SUM(C33+C35) -> 54985.688 | D40: TJ
B41: Share of industry in total | C41: =C40/C39 -> 0.155797 | D41: Only industry sector are assigned free allowances
B42: Share of free allowances in industry | C42: =84% -> 0.84 | D42: See Sandbag (2024)
B44: co2_percentage_free | C44: =ROUND(C42*C41,2) -> 0.13 | D44: Free allocation in the ETM is assigned to all electricity production instead of being excluded from the power sector. Therefore the average free allocation to electricity generation is defined here as the share of industry electricity production multiplied by the share of emissions covered by free allowances in the industry sector.
B56: Sandbag (2024), see https://sandbag.be/2024/10/07/a-closer-look-at-2023-emissions/

Sheet Emissions
A1: Emissions as given by UNFCCC | B1: Sector_code | C1: Pollutant_name | D1: Value | E1: Unit | F1: Comment
A2: Fertiliser industry non-energetic CO2 emissions | B2: 2.B.1 | C2: CO₂ | D2: =SUMIFS(UNFCCC!$J:$J,UNFCCC!$E:$E,Emissions!$B2,UNFCCC!$D:$D,Emissions!$C2)*10^-3 -> 1.9790046 | E2: Mton | F2: Datadump CO2 emissions: Sector_code 2.B.1
A5: Emissions as expected from ETM calculations | B5: Value new | C5: Unit | D5: Comment
A6: Fertiliser industry non-energetic natural gas demand | B6: 50.3 | C6: PJ | D6: https://opendata.cbs.nl/#/CBS/en/dataset/83989ENG/table?dl=C21B2
A7: Natural gas specific CO2 emissions | B7: 0.0565 | C7: kg/MJ | D7: nl2019 carriers.csv
A8: Fertiliser industry non-energetic CO2 emissions | B8: =B6*B7 -> 2.84195 | C8: Mton
A9: Fertiliser industry capture rate | B9: 0.65 | C9: % | D9: ETM
A10: Fertiliser industry non-energetic CO2 emissions on-the-spot | B10: =(1-B9)*B8 -> 0.9946825 | C10: Mton
A11: Fertiliser industry non-energetic CO2 emissions delayed | B11: =B9*B8 -> 1.8472675 | C11: Mton
A14: Emissions redestribution | B14: Value new | C14: Unit | D14: Comment
A15: Difference fertiliser industry on-the-spot non-energetic CO2 emissions | B15: =D2-B10 -> 0.98432211 | C15: Mton | D15: This is the amount of delayed emissions that the UNFCCC apparently still attributes to the fertiliser industry's non energetic CO2 emissions, instead of to the delayed emissions as the ETM does. Because the delayed emissions calculations cannot be changed, this amount needs to be subtracted from another sector that has non energetic CO2 emissions.
A16: non_energetic_emissions_co2_other_industry | B16: 1.3736555 | C16: Mton | D16: UNFCCC original value. Other industry is chosen because it is likely that the delayed emissions occur in the food sector.
A17: non_energetic_emissions_co2_other_industry | B17: =B16-B15 -> 0.38933336 | C17: Mton | D17: Value adjusted for delayed emissions.
A20: Emissions
A21: Values below are copied from source_analyses/general/11_area/greenhouse_gas_emissions.xlsx
A23: Key (ETDataset) | B23: Mton (COPY to ETDataset) | C23: Unit | D23: Source
A24: non_energetic_emissions_co2_chemical_industry | B24: 7.9916497 | C24: Mton | D24: UNFCCC
A25: non_energetic_emissions_co2_other_industry | B25: =B17 -> 0.38933336 | C25: Mton | D25: UNFCCC - adjusted value
A26: non_energetic_emissions_co2_agriculture_manure | B26: 0.06806927 | C26: Mton | D26: UNFCCC
A27: non_energetic_emissions_co2_agriculture_soil_cultivation | B27: 0.02514402 | C27: Mton | D27: UNFCCC
A28: non_energetic_emissions_co2_waste_management | B28: 0 | C28: Mton | D28: UNFCCC
A29: indirect_emissions_co2 | B29: 0.43273137 | C29: Mton | D29: UNFCCC
A30: energetic_emissions_other_ghg_industry | B30: 0.09816614 | C30: Mton | D30: UNFCCC
A31: energetic_emissions_other_ghg_energy | B31: 0.76029801 | C31: Mton | D31: UNFCCC
A32: energetic_emissions_other_ghg_transport | B32: 0.39751161 | C32: Mton | D32: UNFCCC
A33: energetic_emissions_other_ghg_buildings | B33: 0.06599546 | C33: Mton | D33: UNFCCC
A34: energetic_emissions_other_ghg_households | B34: 0.29499943 | C34: Mton | D34: UNFCCC
A35: energetic_emissions_other_ghg_agriculture | B35: 0.96057986 | C35: Mton | D35: UNFCCC
A36: non_energetic_emissions_other_ghg_chemical_industry | B36: 0.87984439 | C36: Mton | D36: UNFCCC
A37: non_energetic_emissions_other_ghg_other_industry | B37: 0.85699799 | C37: Mton | D37: UNFCCC
... A42: non_energetic_emissions_other_ghg_waste_management | B42: 2.6747815 | C42: Mton | D42: UNFCCC

Sheet Building stock
A1: Building stock expressed in WEQ | B1: Value | C1: Unit | D1: comment
A2: Woning equivalent | B2: 130 | C2: m2 | D2: https://www.nplw.nl/uploads/files/Warmteprogramma/Handreiking-Warmteprogramma-NPLW.pdf
A3: Total non-residential buildings surface | B3: =SUM(BSO!K4:K45) -> 362873578 | C3: m2 | D3: Building Stock Observatory, https://energy.ec.europa.eu/topics/energy-efficiency/energy-efficient-buildings/eu-building-stock-observatory_en
A4: Nr of WEQ | B4: =B3/B2 -> 2791335.2
A6: Comparison
A7: number of buildings | B7: =SUM(municipal_data_etlocal_export!BN2:BN353) -> 898616
A8: factor difference | B8: =B4/B7 -> 3.1062603
A19: Results of Jupyter notebook
A20: The Jupyter notebook is used for the regional datasets and does an aggregation for national values
A21: etdataset/pipelines/Built environment stock Dutch municipalities.ipynb
B23: nl2023
A24: vbo_opp_m2 | B24: 270622049
A25: Functionele vraag ruimteverwarming (kWh) | B25: 65587200607
A26: Gemiddelde netto warmtevraag (kWh/m2) | B26: 242.35719
A27: Aantal gebouwen (weq) | B27: 2081704
A30: Comparison BSO with Jupyter notebook
A31: Nr of WEQ BSO | B31: =B4 -> 2791335.2
A32: Nr of WEQ Jupyter | B32: =B27 -> 2081704
A33: factor difference | B33: =B31/B32 -> 1.3408896 | C33: difference is accceptable, the WBSO value is now assumed

Sheet CO2 price
A1: CO2 price | B1: 85 | C1: €/tonne
A2: CO2 price | B2: =B1*10^-3 -> 0.085 | C2: €/kg
A4: Source | B4: PBL KEV (2024) https://www.pbl.nl/publicaties/klimaat-en-energieverkenning-2024

Sheet BSO
A1: Copied from source_analyses/EU27_european_union/2019/eu_datasets/additional_data/Sources/Input_EU_building_stock_observatory.xlsx
A3: Domain | B3: Subject | C3: Measurement | D3: Country | E3: Construction period | F3: Sector | G3: Building use | H3: Unit | I3: Publication date | J3: Reference year | K3: Value
A4: Building stock | B4: Useful floor area | C4: Total | D4: Netherlands | E4: 0-1945 | F4: Service | G4: Educational buildings | H4: m2 | I4: 2023 | J4: 2020 | K4: 7802695
A5: Building stock | B5: Useful floor area | C5: Total | D5: Netherlands | E5: 0-1945 | F5: Service | G5: Health buildings | H5: m2 | I5: 2023 | J5: 2020 | K5: 2193767
A6: Building stock | B6: Useful floor area | C6: Total | D6: Netherlands | E6: 0-1945 | F6: Service | G6: Hotels and Restaurants | H6: m2 | I6: 2023 | J6: 2020 | K6: 5786801
A7: Building stock | B7: Useful floor area | C7: Total | D7: Netherlands | E7: 0-1945 | F7: Service | G7: Offices | H7: m2 | I7: 2023 | J7: 2020 | K7: 10324951
A8: Building stock | B8: Useful floor area | C8: Total | D8: Netherlands | E8: 0-1945 | F8: Service | G8: Other non-residential buildings | H8: m2 | I8: 2023 | J8: 2020 | K8: 58247472
A9: Building stock | B9: Useful floor area | C9: Total | D9: Netherlands | E9: 0-1945 | F9: Service | G9: Trade buildings | H9: m2 | I9: 2023 | J9: 2020 | K9: 54331238
A10: Building stock | B10: Useful floor area | C10: Total | D10: Netherlands | E10: 1946-1969 | F10: Service | G10: Educational buildings | H10: m2 | I10: 2023 | J10: 2020 | K10: 1351835
A11: Building stock | B11: Useful floor area | C11: Total | D11: Netherlands | E11: 1946-1969 | F11: Service | G11: Health buildings | H11: m2 | I11: 2023 | J11: 2020 | K11: 379462
A12: Building stock | B12: Useful floor area | C12: Total | D12: Netherlands | E12: 1946-1969 | F12: Service | G12: Hotels and Restaurants | H12: m2 | I12: 2023 | J12: 2020 | K12: 1494133
A13: Building stock | B13: Useful floor area | C13: Total | D13: Netherlands | E13: 1946-1969 | F13: Service | G13: Offices | H13: m2 | I13: 2023 | J13: 2020 | K13: 2801409
A14: Building stock | B14: Useful floor area | C14: Total | D14: Netherlands | E14: 1946-1969 | F14: Service | G14: Other non-residential buildings | H14: m2 | I14: 2023 | J14: 2020 | K14: 7612964
A15: Building stock | B15: Useful floor area | C15: Total | D15: Netherlands | E15: 1946-1969 | F15: Service | G15: Trade buildings | H15: m2 | I15: 2023 | J15: 2020 | K15: 6681257
... A45: Building stock | B45: Useful floor area | C45: Total | D45: Netherlands | E45: 2011-now | F45: Service | G45: Trade buildings | H45: m2 | I45: 2023 | J45: 2020 | K45: 434018

Sheet municipal_data_etlocal_export
A1: GEO_ID | B1: present_number_of_apartments_before_1945 | C1: present_number_of_apartments_1945_1964 | D1: present_number_of_apartments_1965_1984 | E1: present_number_of_apartments_1985_2004 | F1: present_number_of_apartments_2005_present | G1: present_number_of_detached_houses_before_1945 | H1: present_number_of_detached_houses_1945_1964 | I1: present_number_of_detached_houses_1965_1984 | J1: present_number_of_detached_houses_1985_2004 | K1: present_number_of_detached_houses_2005_present | L1: present_number_of_semi_detached_houses_before_1945 | M1: present_number_of_semi_detached_houses_1945_1964 | N1: present_number_of_semi_detached_houses_1965_1984 | O1: present_number_of_semi_detached_houses_1985_2004 | P1: present_number_of_semi_detached_houses_2005_present | Q1: present_number_of_terraced_houses_before_1945 | R1: present_number_of_terraced_houses_1945_1964 | S1: present_number_of_terraced_houses_1965_1984 | T1: present_number_of_terraced_houses_1985_2004 | U1: present_number_of_terraced_houses_2005_present | V1: typical_useful_demand_for_space_heating_apartments_before_1945 | W1: typical_useful_demand_for_space_heating_apartments_1945_1964 | X1: typical_useful_demand_for_space_heating_apartments_1965_1984 | Y1: typical_useful_demand_for_space_heating_apartments_1985_2004 | Z1: typical_useful_demand_for_space_heating_apartments_2005_present | AA1: typical_useful_demand_for_space_heating_apartments_future | AB1: typical_useful_demand_for_space_heating_detached_houses_before_1945 | AC1: typical_useful_demand_for_space_heating_detached_houses_1945_1964 | AD1: typical_useful_demand_for_space_heating_detached_houses_1965_1984 | AE1: typical_useful_demand_for_space_heating_detached_houses_1985_2004 | AF1: typical_useful_demand_for_space_heating_detached_houses_2005_present | AG1: typical_useful_demand_for_space_heating_detached_houses_future | AH1: typical_useful_demand_for_space_heating_semi_detached_houses_before_1945 | AI1: typical_useful_demand_for_space_heating_semi_detached_houses_1945_1964 | AJ1: typical_useful_demand_for_space_heating_semi_detached_houses_1965_1984 | AK1: typical_useful_demand_for_space_heating_semi_detached_houses_1985_2004 | AL1: typical_useful_demand_for_space_heating_semi_detached_houses_2005_present | AM1: typical_useful_demand_for_space_heating_semi_detached_houses_future | AN1: typical_useful_demand_for_space_heating_terraced_houses_before_1945 | AO1: typical_useful_demand_for_space_heating_terraced_houses_1945_1964 | AP1: typical_useful_demand_for_space_heating_terraced_houses_1965_1984 | AQ1: typical_useful_demand_for_space_heating_terraced_houses_1985_2004 | AR1: typical_useful_demand_for_space_heating_terraced_houses_2005_present | AS1: typical_useful_demand_for_space_heating_terraced_houses_future | AT1: present_share_of_apartments_before_1945_in_useful_demand_for_space_heating | AU1: present_share_of_apartments_1945_1964_in_useful_demand_for_space_heating | AV1: present_share_of_apartments_1965_1984_in_useful_demand_for_space_heating | AW1: present_share_of_apartments_1985_2004_in_useful_demand_for_space_heating | AX1: present_share_of_apartments_2005_present_in_useful_demand_for_space_heating | AY1: present_share_of_detached_houses_before_1945_in_useful_demand_for_space_heating | AZ1: present_share_of_detached_houses_1945_1964_in_useful_demand_for_space_heating | BA1: present_share_of_detached_houses_1965_1984_in_useful_demand_for_space_heating | BB1: present_share_of_detached_houses_1985_2004_in_useful_demand_for_space_heating | BC1: present_share_of_detached_houses_2005_present_in_useful_demand_for_space_heating | BD1: present_share_of_semi_detached_houses_before_1945_in_useful_demand_for_space_heating | BE1: present_share_of_semi_detached_houses_1945_1964_in_useful_demand_for_space_heating | BF1: present_share_of_semi_detached_houses_1965_1984_in_useful_demand_for_space_heating | BG1: present_share_of_semi_detached_houses_1985_2004_in_useful_demand_for_space_heating | BH1: present_share_of_semi_detached_houses_2005_present_in_useful_demand_for_space_heating | BI1: present_share_of_terraced_houses_before_1945_in_useful_demand_for_space_heating | BJ1: present_share_of_terraced_houses_1945_1964_in_useful_demand_for_space_heating | BK1: present_share_of_terraced_houses_1965_1984_in_useful_demand_for_space_heating | BL1: present_share_of_terraced_houses_1985_2004_in_useful_demand_for_space_heating | BM1: present_share_of_terraced_houses_2005_present_in_useful_demand_for_space_heating | BN1: present_number_of_buildings | BO1: typical_useful_demand_for_space_heating_buildings_present | BP1: typical_useful_demand_for_space_heating_buildings_future
A2: GM1680 | B2: 43 | C2: 124 | D2: 275 | E2: 310 | F2: 163 | G2: 2007 | H2: 830 | I2: 1200 | J2: 1075 | K2: 300 | L2: 237 | M2: 695 | N2: 1332 | O2: 1067 | P2: 225 | Q2: 13 | R2: 131 | S2: 753 | T2: 224 | U2: 30 | V2: 255.04144 | W2: 179.48383 | X2: 212.73317 | Y2: 159.25393 | Z2: 116.83236 | AA2: 65 | AB2: 287.97955 | AC2: 271.06737 | AD2: 213.46743 | AE2: 155.14786 | AF2: 113.40621 | AG2: 55 | AH2: 289.51774 | AI2: 244.86062 | AJ2: 196.24647 | AK2: 169.84943 | AL2: 119.5515 | AM2: 55 | AN2: 206 | AO2: 226.43959 | AP2: 181.81114 | AQ2: 167.56308 | AR2: 106.563 | AS2: 55 | AT2: 0.00419092 | AU2: 0.01086942 | AV2: 0.02851136 | AW2: 0.02861425 | AX2: 0.01543449 | AY2: 0.1804191 | AZ2: 0.07648173 | BA2: 0.10677521 | BB2: 0.09679759 | BC2: 0.02802251 | BD2: 0.02129478 | BE2: 0.06144921 | BF2: 0.12208785 | BG2: 0.09696767 | BH2: 0.01977039 | BI2: 0.00112194 | BJ2: 0.01197339 | BK2: 0.06827958 | BL2: 0.01912597 | BM2: 0.00181264 | BN2: 2299 | BO2: 249.80024 | BP2: 190
A3: GM0358 | B3: 81 | C3: 211 | D3: 451 | E3: 932 | F3: 1093 | G3: 522 | H3: 356 | I3: 376 | J3: 378 | K3: 355 | L3: 530 | M3: 553 | N3: 990 | O3: 585 | P3: 831 | Q3: 204 | R3: 543 | S3: 1765 | T3: 1065 | U3: 1392 | V3: 278.85887 | W3: 232.77591 | X3: 172.57309 | Y3: 169.39835 | Z3: 118.6536 | AA3: 65 | AB3: 300.90509 | AC3: 284.83164 | AD3: 221.89674 | AE3: 157.04761 | AF3: 115.80882 | AG3: 55 | AH3: 302.87258 | AI3: 248.72678 | AJ3: 191.66859 | AK3: 160.65479 | AL3: 116.84223 | AM3: 55 | AN3: 301.36119 | AO3: 226.09659 | AP3: 171.91145 | AQ3: 158.98165 | AR3: 114.53057 | AS3: 55 | AT3: 0.00689554 | AU3: 0.01704241 | AV3: 0.03596453 | AW3: 0.0711624 | AX3: 0.09066572 | AY3: 0.033703 | AZ3: 0.02283962 | BA3: 0.02664897 | BB3: 0.02695044 | BC3: 0.02819781 | BD3: 0.0379989 | BE3: 0.04322559 | BF3: 0.07354717 | BG3: 0.04204246 | BH3: 0.06591316 | BI3: 0.01694454 | BJ3: 0.0452519 | BK3: 0.13074087 | BL3: 0.07487006 | BM3: 0.10939491 | BN3: 1146 | BO3: 226.76038 | BP3: 190
A4: GM0197 | B4: 455 | C4: 96 | D4: 237 | E4: 681 | F4: 560 | G4: 1154 | H4: 487 | I4: 580 | J4: 603 | K4: 270 | L4: 797 | M4: 905 | N4: 1454 | O4: 820 | P4: 260 | Q4: 102 | R4: 500 | S4: 1516 | T4: 402 | U4: 96 | V4: 268.78303 | W4: 237.51759 | X4: 198.10363 | Y4: 159.03382 | Z4: 123.36616 | AA4: 65 | AB4: 314.49102 | AC4: 287.9236 | AD4: 223.79184 | AE4: 154.36376 | AF4: 114.4651 | AG4: 55 | AH4: 307.82345 | AI4: 264.34766 | AJ4: 213.60408 | AK4: 176.32383 | AL4: 119.34848 | AM4: 55 | AN4: 322.14692 | AO4: 246.22117 | AP4: 200.82639 | AQ4: 175.33664 | AR4: 114.11575 | AS4: 55 | AT4: 0.0404529 | AU4: 0.0088343 | AV4: 0.02025034 | AW4: 0.05759325 | AX4: 0.04419418 | AY4: 0.10114233 | AZ4: 0.04361496 | BA4: 0.04860453 | BB4: 0.0506383 | BC4: 0.02519937 | BD4: 0.0730157 | BE4: 0.08155995 | BF4: 0.11779314 | BG4: 0.0561894 | BH4: 0.02204183 | BI4: 0.00860222 | BJ4: 0.04318317 | BK4: 0.12190507 | BL4: 0.02659552 | BM4: 0.00858954 | BN4: 1073 | BO4: 267.73288 | BP4: 190
A5: GM0059 | B5: 62 | C5: 72 | D5: 560 | E5: 456 | F5: 208 | G5: 1690 | H5: 724 | I5: 1243 | J5: 1258 | K5: 359 | L5: 155 | M5: 667 | N5: 1696 | O5: 731 | P5: 249 | Q5: 16 | R5: 324 | S5: 1436 | T5: 156 | U5: 23 | V5: 175.53456 | W5: 224.42824 | X5: 183.23991 | Y5: 144.5675 | Z5: 113.35062 | AA5: 65 | AB5: 312.65932 | AC5: 289.90564 | AD5: 222.02188 | AE5: 145.76608 | AF5: 113.36333 | AG5: 55 | AH5: 278.77311 | AI5: 251.70733 | AJ5: 219.3139 | AK5: 160.53323 | AL5: 101.48917 | AM5: 55 | AN5: 301.5566 | AO5: 220.13662 | AP5: 211.97698 | AQ5: 179.74219 | AR5: 111.68522 | AS5: 55 | AT5: 0.00610263 | AU5: 0.00653083 | AV5: 0.04507575 | AW5: 0.03670191 | AX5: 0.01900768 | AY5: 0.15231765 | AZ5: 0.0586721 | BA5: 0.09787184 | BB5: 0.10371652 | BC5: 0.03229776 | BD5: 0.01368025 | BE5: 0.05680941 | BF5: 0.13179314 | BG5: 0.05953588 | BH5: 0.02198898 | BI5: 0.00144434 | BJ5: 0.02833367 | BK5: 0.11311276 | BL5: 0.0125565 | BM5: 0.0024504 | BN5: 929 | BO5: 269.96535 | BP5: 190
A6: GM0482 | B6: 42 | C6: 323 | D6: 1131 | E6: 683 | F6: 438 | G6: 154 | H6: 52 | I6: 51 | J6: 145 | K6: 89 | L6: 332 | M6: 567 | N6: 357 | O6: 411 | P6: 194 | Q6: 245 | R6: 1050 | S6: 986 | T6: 792 | U6: 314 | V6: 276.0195 | W6: 248.61294 | X6: 180.89013 | Y6: 145.98119 | Z6: 119.79149 | AA6: 65 | AB6: 320.43304 | AC6: 278.93172 | AD6: 234.44185 | AE6: 163.16372 | AF6: 120.83084 | AG6: 55 | AH6: 303.19224 | AI6: 281.22391 | AJ6: 214.65282 | AK6: 167.26902 | AL6: 117.12603 | AM6: 55 | AN6: 272.72146 | AO6: 249.91111 | AP6: 203.19843 | AQ6: 157.5216 | AR6: 114.85188 | AS6: 55 | AT6: 0.00502966 | AU6: 0.03592243 | AV6: 0.1392709 | AW6: 0.08537429 | AX6: 0.041971 | AY6: 0.0179043 | AZ6: 0.00670895 | BA6: 0.00617816 | BB6: 0.01646055 | BC6: 0.00971979 | BD6: 0.04014345 | BE6: 0.0698103 | BF6: 0.04294237 | BG6: 0.05156385 | BH6: 0.02318853 | BI6: 0.0299539 | BJ6: 0.12748867 | BK6: 0.12081778 | BL6: 0.09529157 | BM6: 0.03425955 | BN6: 836 | BO6: 231.79811 | BP6: 190
A7: GM0613 | B7: 21 | C7: 2 | D7: 453 | E7: 845 | F7: 624 | G7: 249 | H7: 137 | I7: 110 | J7: 315 | K7: 223 | L7: 424 | M7: 505 | N7: 608 | O7: 962 | P7: 526 | Q7: 55 | R7: 660 | S7: 1137 | T7: 1744 | U7: 901 | V7: 163.25965 | W7: 0 | X7: 198.71621 | Y7: 153.47085 | Z7: 114.01173 | AA7: 65 | AB7: 276.10486 | AC7: 263.44985 | AD7: 210.45563 | AE7: 146.88839 | AF7: 116.92909 | AG7: 55 | AH7: 286.28966 | AI7: 243.66893 | AJ7: 208.36889 | AK7: 151.54299 | AL7: 119.12514 | AM7: 55 | AN7: 238.95688 | AO7: 228.00881 | AP7: 201.30004 | AQ7: 146.12119 | AR7: 115.77751 | AS7: 55 | AT7: 0.00207015 | AU7: 0.00015681 | AV7: 0.04194697 | AW7: 0.08392835 | AX7: 0.05600151 | AY7: 0.02194697 | AZ7: 0.01242971 | BA7: 0.01041053 | BB7: 0.03055285 | BC7: 0.02281954 | BD7: 0.04000982 | BE7: 0.04792194 | BF7: 0.05715585 | BG7: 0.09355171 | BH7: 0.05031659 | BI7: 0.00522998 | BJ7: 0.0611955 | BK7: 0.10676368 | BL7: 0.17173021 | BM7: 0.08386133 | BN7: 772 | BO7: 219.48929 | BP7: 190
A8: GM0361 | B8: 1875 | C8: 2376 | D8: 7565 | E8: 4116 | F8: 2366 | G8: 1161 | H8: 347 | I8: 623 | J8: 743 | K8: 305 | L8: 2039 | M8: 876 | N8: 4167 | O8: 1828 | P8: 504 | Q8: 4511 | R8: 1653 | S8: 9766 | T8: 3805 | U8: 862 | V8: 248.84301 | W8: 230.05885 | X8: 192.61029 | Y8: 141.41551 | Z8: 118.50576 | AA8: 65 | AB8: 293.90619 | AC8: 274.68696 | AD8: 214.76569 | AE8: 149.02909 | AF8: 118.786 | AG8: 55 | AH8: 300.62254 | AI8: 251.1804 | AJ8: 203.96395 | AK8: 163.763 | AL8: 118.31353 | AM8: 55 | AN8: 275.65085 | AO8: 239.40585 | AP8: 189.31164 | AQ8: 154.85748 | AR8: 115.07402 | AS8: 55 | AT8: 0.03622623 | AU8: 0.04648821 | AV8: 0.15184591 | AW8: 0.07651879 | AX8: 0.04318525 | AY8: 0.02135611 | AZ8: 0.00675724 | BA8: 0.01145497 | BB8: 0.01376863 | BC8: 0.00563975 | BD8: 0.04086858 | BE8: 0.01710706 | BF8: 0.08116183 | BG8: 0.0345198 | BH8: 0.00906496 | BI8: 0.09063582 | BJ8: 0.03213625 | BK8: 0.19438196 | BL8: 0.07153725 | BM8: 0.0153454 | BN8: 6349 | BO8: 248.46623 | BP8: 190
A9: GM0141 | B9: 442 | C9: 2325 | D9: 2715 | E9: 2711 | F9: 1278 | G9: 861 | H9: 437 | I9: 729 | J9: 1368 | K9: 573 | L9: 2855 | M9: 1440 | N9: 2483 | O9: 1999 | P9: 645 | Q9: 1760 | R9: 1917 | S9: 4107 | T9: 2345 | U9: 639 | V9: 246.2477 | W9: 240.54747 | X9: 198.34551 | Y9: 153.46314 | Z9: 120.63644 | AA9: 65 | AB9: 310.24172 | AC9: 303.36016 | AD9: 212.82905 | AE9: 144.34272 | AF9: 116.46123 | AG9: 55 | AH9: 291.52547 | AI9: 258.50154 | AJ9: 220.6622 | AK9: 165.08014 | AL9: 117.66726 | AM9: 55 | AN9: 261.682 | AO9: 236.66414 | AP9: 213.41239 | AQ9: 159.1462 | AR9: 117.30005 | AS9: 55 | AT9: 0.01292524 | AU9: 0.07122333 | AV9: 0.08500619 | AW9: 0.07286537 | AX9: 0.03446882 | AY9: 0.02611913 | AZ9: 0.01366773 | BA9: 0.0221881 | BB9: 0.03841999 | BC9: 0.01548069 | BD9: 0.08962908 | BE9: 0.04510851 | BF9: 0.07581872 | BG9: 0.05600307 | BH9: 0.01708566 | BI9: 0.05410437 | BJ9: 0.0604863 | BK9: 0.12601831 | BL9: 0.06625937 | BM9: 0.01712202 | BN9: 3541 | BO9: 250.07384 | BP9: 190
A10: GM0034 | B10: 0 | C10: 0 | D10: 3881 | E10: 13048 | F10: 6938 | G10: 0 | H10: 0 | I10: 111 | J10: 2827 | K10: 2139 | L10: 0 | M10: 0 | N10: 2598 | O10: 9518 | P10: 2372 | Q10: 0 | R10: 0 | S10: 7913 | T10: 29660 | U10: 5078 | V10: 0 | W10: 0 | X10: 152.70114 | Y10: 139.62843 | Z10: 118.67463 | AA10: 65 | AB10: 0 | AC10: 0 | AD10: 173.75259 | AE10: 142.10401 | AF10: 115.03156 | AG10: 55 | AH10: 0 | AI10: 0 | AJ10: 172.24177 | AK10: 149.45205 | AL10: 115.067 | AM10: 55 | AN10: 0 | AO10: 0 | AP10: 155.28236 | AQ10: 136.24816 | AR10: 114.01987 | AS10: 55 | AT10: 0 | AU10: 0 | AV10: 0.0452167 | AW10: 0.15387288 | AX10: 0.07583729 | AY10: 0 | AZ10: 0 | BA10: 0.00139551 | BB10: 0.03269703 | BC10: 0.02317326 | BD10: 0 | BE10: 0 | BF10: 0.03023193 | BG10: 0.11179789 | BH10: 0.0263696 | BI10: 0 | BJ10: 0 | BK10: 0.09243494 | BL10: 0.34977806 | BM10: 0.05719491 | BN10: 4305 | BO10: 162.77912 | BP10: 190
A11: GM0484 | B11: 351 | C11: 2380 | D11: 6835 | E11: 4132 | F11: 2879 | G11: 1065 | H11: 298 | I11: 882 | J11: 941 | K11: 548 | L11: 1784 | M11: 1275 | N11: 3128 | O11: 2259 | P11: 1126 | Q11: 1649 | R11: 2078 | S11: 8138 | T11: 5186 | U11: 1429 | V11: 224.39988 | W11: 246.22955 | X11: 179.51771 | Y11: 159.72574 | Z11: 113.96343 | AA11: 65 | AB11: 307.07701 | AC11: 298.43995 | AD11: 220.1994 | AE11: 156.37559 | AF11: 113.45051 | AG11: 55 | AH11: 302.93508 | AI11: 239.44534 | AJ11: 199.46005 | AK11: 165.41854 | AL11: 115.94537 | AM11: 55 | AN11: 286.42872 | AO11: 222.45212 | AP11: 182.80711 | AQ11: 164.93395 | AR11: 111.60716 | AS11: 55 | AT11: 0.00699168 | AU11: 0.04994983 | AV11: 0.14988641 | AW11: 0.08495006 | AX11: 0.05557602 | AY11: 0.02109022 | AZ11: 0.00606115 | BA11: 0.01688626 | BB11: 0.01862189 | BC11: 0.01084475 | BD11: 0.03632678 | BE11: 0.02703626 | BF11: 0.0636638 | BG11: 0.04668207 | BH11: 0.02182 | BI11: 0.03471187 | BJ11: 0.04682721 | BK11: 0.16700413 | BL11: 0.10733354 | BM11: 0.02773607 | BN11: 4632 | BO11: 246.15698 | BP11: 190
A12: GM1723 | B12: 27 | C12: 18 | D12: 55 | E12: 72 | F12: 274 | G12: 398 | H12: 333 | I12: 664 | J12: 411 | K12: 220 | L12: 149 | M12: 158 | N12: 589 | O12: 271 | P12: 156 | Q12: 16 | R12: 16 | S12: 221 | T12: 186 | U12: 160 | V12: 281.9162 | W12: 249.55333 | X12: 168.92496 | Y12: 142.05388 | Z12: 101.73567 | AA12: 65 | AB12: 309.58611 | AC12: 288.46753 | AD12: 225.70943 | AE12: 151.55709 | AF12: 114.63431 | AG12: 55 | AH12: 276.25279 | AI12: 260.01641 | AJ12: 212.79691 | AK12: 157.07528 | AL12: 115.04131 | AM12: 55 | AN12: 248.51606 | AO12: 280.86832 | AP12: 194.0874 | AQ12: 152.75147 | AR12: 114.24808 | AS12: 55 | AT12: 0.00649796 | AU12: 0.003734 | AV12: 0.0124323 | AW12: 0.01644054 | AX12: 0.06363865 | AY12: 0.08756293 | AZ12: 0.07690126 | BA12: 0.15240512 | BB12: 0.09250161 | BC12: 0.0513793 | BD12: 0.03274949 | BE12: 0.03149124 | BF12: 0.13200467 | BG12: 0.06424014 | BH12: 0.03674666 | BI12: 0.00345219 | BJ12: 0.0040129 | BK12: 0.05108119 | BL12: 0.04467814 | BM12: 0.03604971 | BN12: 547 | BO12: 302.63723 | BP12: 190
A13: GM0060 | B13: 84 | C13: 16 | D13: 26 | E13: 135 | F13: 16 | G13: 178 | H13: 159 | I13: 244 | J13: 220 | K13: 84 | L13: 124 | M13: 66 | N13: 178 | O13: 125 | P13: 18 | Q13: 13 | R13: 8 | S13: 31 | T13: 11 | U13: 4 | V13: 302.05071 | W13: 307.94019 | X13: 266.94352 | Y13: 157.85654 | Z13: 137.48718 | AA13: 65 | AB13: 321.3968 | AC13: 268.02132 | AD13: 235.35307 | AE13: 157.11981 | AF13: 115.72286 | AG13: 55 | AH13: 275.06509 | AI13: 202.81457 | AJ13: 171.47134 | AK13: 148.53458 | AL13: 111.07092 | AM13: 55 | AN13: 201.61713 | AO13: 237.18762 | AP13: 151.43959 | AQ13: 133.78105 | AR13: 0 | AS13: 55 | AT13: 0.04796055 | AU13: 0.00928386 | AV13: 0.01456166 | AW13: 0.08240538 | AX13: 0.00923873 | AY13: 0.10168255 | AZ13: 0.09362964 | BA13: 0.12827841 | BB13: 0.12710864 | BC13: 0.04637269 | BD13: 0.08047082 | BE13: 0.039424 | BF13: 0.10174373 | BG13: 0.07049646 | BH13: 0.01140489 | BI13: 0.00713224 | BJ13: 0.00413862 | BK13: 0.01660694 | BL13: 0.00613728 | BM13: 0.00192291 | BN13: 2141 | BO13: 293.30205 | BP13: 190
... A353: GM1979 | B353: 234 | C353: 597 | D353: 1811 | E353: 1035 | F353: 986 | G353: 3589 | H353: 748 | I353: 923 | J353: 1270 | K353: 333 | L353: 1133 | M353: 1393 | N353: 2410 | O353: 862 | P353: 481 | Q353: 350 | R353: 418 | S353: 3361 | T353: 483 | U353: 189 | V353: 270.67658 | W353: 262.90226 | X353: 221.37254 | Y353: 168.00015 | Z353: 116.16498 | AA353: 65 | AB353: 307.70942 | AC353: 291.1325 | AD353: 216.46129 | AE353: 142.02935 | AF353: 116.48993 | AG353: 55 | AH353: 304.54159 | AI353: 257.85006 | AJ353: 214.9623 | AK353: 161.89355 | AL353: 116.06536 | AM353: 55 | AN353: 294.1854 | AO353: 261.86096 | AP353: 204.54413 | AQ353: 171.2493 | AR353: 123.26738 | AS353: 55 | AT353: 0.03202664 | AU353: 0.06446214 | AV353: 0.2067575 | AW353: 0.12823947 | AX353: 0.10677562 | AY353: 0.57969425 | AZ353: 0.10080529 | BA353: 0.11016065 | BB353: 0.1852048 | BC353: 0.049295717 | BD353: 0.1792558 | BE353: 0.19364859 | BF353: 0.30074683 | BG353: 0.11679702 | BH353: 0.063798612 | BI353: 0.053112482 | BJ353: 0.049656197 | BK353: 0.40105884 | BL353: 0.054149095 | BM353: 0.024354468 | BN353: 0 | BO353: 270.58553 | BP353: 190

Sheet Eurostat Cars
A1: Data extracted on 04/04/2025 13:38:19 from [ESTAT]
A2: Dataset: | B2: Passenger cars by age [road_eqs_carage__custom_16126065]
A3: Last updated: | B3: 11/03/2025 23:00
A5: Source | B5: https://doi.org/10.2908/ROAD_EQS_CARAGE
A7: Time frequency | C7: Annual
A8: Unit of measure | C8: Number
A9: Age class | C9: Total
A11: TIME | B11: 2023
A12: GEO (Labels)
A13: Netherlands | B13: 9067393
A15: Special value
A16: : | B16: not available

Sheet Eurostat Buses
A1: Data extracted on 04/04/2025 13:50:34 from [ESTAT]
A2: Dataset: | B2: Motor coaches, buses and trolley buses, by type of vehicle [road_eqs_busveh__custom_16126268]
A3: Last updated: | B3: 11/03/2025 23:00
A5: Source | B5: https://doi.org/10.2908/ROAD_EQS_BUSVEH
A7: Time frequency | C7: Annual
A8: Unit of measure | C8: Number
A9: Geopolitical entity (reporting) | C9: Netherlands
A11: TIME | B11: 2023
A12: VEHICLE (Labels)
A13: Total | B13: 8675
A14: Mini-buses and mini-coaches | B14: :
A15: Buses | B15: :
A16: Trolley buses | B16: :
A17: Motor coaches | B17: :
A19: Special value
A20: : | B20: not available

Sheet Eurostat Vans and trucks
A1: Data extracted on 04/04/2025 13:47:07 from [ESTAT]
A2: Dataset: | B2: Lorries, by type of motor energy [road_eqs_lormot__custom_16126205]
A3: Last updated: | B3: 11/03/2025 23:00
A5: Source | B5: https://doi.org/10.2908/ROAD_EQS_LORMOT
A7: Time frequency | C7: Annual
A8: Unit of measure | C8: Number
A9: Motor energy | C9: Total
A10: Geopolitical entity (reporting) | C10: Netherlands
A12: TIME | B12: 2023
A13: VEHICLE (Labels)
A14: Lorries > 3.5 tonnes | B14: 61521
A15: Goods road motor vehicles <= 3.5 tonnes | B15: 1006477
A17: Special value
A18: : | B18: not available

Sheet CBS
A1: Regionale kerncijfers Nederland
C3: Onderwerp
C4: Bevolking|Bevolkingssamenstelling op 1 januari|Totale bevolking | D4: Landbouw|Oppervlakte cultuurgrond|Totale oppervlakte | E4: Landbouw|Oppervlakte cultuurgrond|Akkerbouw | F4: Landbouw|Oppervlakte cultuurgrond|Tuinbouw open grond | G4: Landbouw|Oppervlakte cultuurgrond|Tuinbouw onder glas | H4: Landbouw|Oppervlakte cultuurgrond|Blijvend grasland | I4: Landbouw|Oppervlakte cultuurgrond|Natuurlijk grasland | J4: Landbouw|Oppervlakte cultuurgrond|Tijdelijk grasland | K4: Landbouw|Oppervlakte cultuurgrond|Groenvoedergewassen | L4: Milieu en bodemgebruik|Bodemgebruik|Oppervlakte|Totale oppervlakte | M4: Milieu en bodemgebruik|Bodemgebruik|Oppervlakte|Land | N4: Milieu en bodemgebruik|Bodemgebruik|Oppervlakte|Water|Water totaal | O4: Milieu en bodemgebruik|Bodemgebruik|Oppervlakte|Water|Binnenwater | P4: Milieu en bodemgebruik|Bodemgebruik|Oppervlakte|Water|Buitenwater
A5: Regio's | B5: Perioden | C5: aantal | D5: are | E5: % | F5: % | G5: % | H5: % | I5: % | J5: % | K5: % | L5: km² | M5: km² | N5: km² | O5: km² | P5: km²
A6: Nederland | B6: 2019 | C6: 17282163 | D6: 181631846 | E6: 29.3 | F6: 5.1 | G6: 0.5 | H6: 38 | I6: 4.2 | J6: 11.9 | K6: 10.9 | L6: 41543.38 | M6: 33671.09 | N6: 7872.28 | O6: 3719.65 | P6: 4152.64
A7: Nederland | B7: 2020 | C7: 17407585 | D7: 181445084 | E7: 29 | F7: 5.1 | G7: 0.6 | H7: 38.3 | I7: 4.3 | J7: 11.3 | K7: 11.4 | L7: 41543.38 | M7: 33671.09 | N7: 7872.28 | O7: 3719.65 | P7: 4152.64
A8: Nederland | B8: 2021 | C8: 17475415 | D8: 181191192 | E8: 29 | F8: 5.2 | G8: 0.6 | H8: 38 | I8: 4.5 | J8: 11.7 | K8: 10.9 | L8: 41543.38 | M8: 33671.09 | N8: 7872.28 | O8: 3719.65 | P8: 4152.64
A9: Nederland | B9: 2022 | C9: 17590672 | D9: 180436921 | E9: 29.6 | F9: 5.3 | G9: 0.6 | H9: 37.7 | I9: 4.6 | J9: 11.4 | K9: 10.8 | L9: 41543.37 | M9: 33647.23 | N9: 7896.14 | O9: 3744.03 | P9: 4152.11
A10: Nederland | B10: 2023 | C10: 17811291 | D10: 180300396 | E10: 30.4 | F10: 5.1 | G10: 0.6 | H10: 37.1 | I10: 5 | J10: 11.1 | K10: 10.8 | L10: 41543.37 | M10: 33647.23 | N10: 7896.14 | O10: 3744.03 | P10: 4152.11
A11: Bron: CBS
A13: Source | B13: https://opendata.cbs.nl/statline/#/CBS/nl/dataset/70072ned/table?dl=C2207

Sheet UNFCCC
A1: Country_code | B1: Country | C1: Format_name | D1: Pollutant_name | E1: Sector_code | F1: Sector_name | G1: Parent_sector_code | H1: Unit | I1: Year | J1: emissions | K1: Notation | L1: PublicationDate | M1: DataSource | O1: Helper: total non-energetic emissions | P1: Helper: other GHG | R1: Source: UNFCCC; National emissions reported to the UNFCCC and to the EU under the Governance Regulation, 2025 ver 2.0
A2: NLD | B2: Netherlands | C2: IPCC Common Reporting Format | D2: CH₄ | E2: 1 | F2: 1 - Energy | G2: Sectors/Totals_incl_incl | H2: Gg | I2: 2023 | J2: 76.27464 | L2: 20250315 | M2: EEA | O2: =IF(OR(G2=2,G2=3,G2=5,G2=6),1,0) -> 0 | R2: https://www.eea.europa.eu/en/datahub/datahubitem-view/3b7fe76c-524a-439a-bfd2-a6e4046302a2?activeAccordion=1095700%2C1095998
A3: NLD | B3: Netherlands | C3: IPCC Common Reporting Format | D3: CO₂ | E3: 1 | F3: 1 - Energy | G3: Sectors/Totals_incl_incl | H3: Gg | I3: 2023 | J3: 105578.86 | L3: 20250315 | M3: EEA | O3: =IF(OR(G3=2,G3=3,G3=5,G3=6),1,0) -> 0
A4: NLD | B4: Netherlands | C4: IPCC Common Reporting Format | D4: All greenhouse gases - (CO2 equivalent) | E4: 1 | F4: 1 - Energy | G4: Sectors/Totals_incl_incl | H4: Gg CO2 equivalent | I4: 2023 | J4: 108310.97 | L4: 20250315 | M4: EEA | O4: =IF(OR(G4=2,G4=3,G4=5,G4=6),1,0) -> 0
A5: NLD | B5: Netherlands | C5: IPCC Common Reporting Format | D5: N₂O | E5: 1 | F5: 1 - Energy | G5: Sectors/Totals_incl_incl | H5: Gg | I5: 2023 | J5: 2.25062 | L5: 20250315 | M5: EEA | O5: =IF(OR(G5=2,G5=3,G5=5,G5=6),1,0) -> 0
A6: NLD | B6: Netherlands | C6: IPCC Common Reporting Format | D6: NF3 - (CO2 equivalent) | E6: 2 | F6: 2 - Industrial Processes and Product Use | G6: Sectors/Totals_incl_incl | H6: Gg CO2 equivalent | I6: 2023 | K6: IE,NA,NO | L6: 20250315 | M6: EEA | O6: =IF(OR(G6=2,G6=3,G6=5,G6=6),1,0) -> 0
A7: NLD | B7: Netherlands | C7: IPCC Common Reporting Format | D7: SF6 - (CO2 equivalent) | E7: 2 | F7: 2 - Industrial Processes and Product Use | G7: Sectors/Totals_incl_incl | H7: Gg CO2 equivalent | I7: 2023 | J7: 105.327 | K7: IE,NA,NO | L7: 20250315 | M7: EEA | O7: =IF(OR(G7=2,G7=3,G7=5,G7=6),1,0) -> 0
A8: NLD | B8: Netherlands | C8: IPCC Common Reporting Format | D8: All greenhouse gases - (CO2 equivalent) | E8: 2 | F8: 2 - Industrial Processes and Product Use | G8: Sectors/Totals_incl_incl | H8: Gg CO2 equivalent | I8: 2023 | J8: 13067.025 | L8: 20250315 | M8: EEA | O8: =IF(OR(G8=2,G8=3,G8=5,G8=6),1,0) -> 0
A9: NLD | B9: Netherlands | C9: IPCC Common Reporting Format | D9: HFCs - (CO2 equivalent) | E9: 2 | F9: 2 - Industrial Processes and Product Use | G9: Sectors/Totals_incl_incl | H9: Gg CO2 equivalent | I9: 2023 | J9: 688.44897 | L9: 20250315 | M9: EEA | O9: =IF(OR(G9=2,G9=3,G9=5,G9=6),1,0) -> 0
A10: NLD | B10: Netherlands | C10: IPCC Common Reporting Format | D10: CO₂ | E10: 2 | F10: 2 - Industrial Processes and Product Use | G10: Sectors/Totals_incl_incl | H10: Gg | I10: 2023 | J10: 11344.31 | L10: 20250315 | M10: EEA | O10: =IF(OR(G10=2,G10=3,G10=5,G10=6),1,0) -> 0
A11: NLD | B11: Netherlands | C11: IPCC Common Reporting Format | D11: Unspecified mix of HFCs and PFCs - (CO2 equivalent) | E11: 2 | F11: 2 - Industrial Processes and Product Use | G11: Sectors/Totals_incl_incl | H11: Gg CO2 equivalent | I11: 2023 | K11: NO | L11: 20250315 | M11: EEA | O11: =IF(OR(G11=2,G11=3,G11=5,G11=6),1,0) -> 0
A12: NLD | B12: Netherlands | C12: IPCC Common Reporting Format | D12: CH₄ | E12: 2 | F12: 2 - Industrial Processes and Product Use | G12: Sectors/Totals_incl_incl | H12: Gg | I12: 2023 | J12: 14.85011 | L12: 20250315 | M12: EEA | O12: =IF(OR(G12=2,G12=3,G12=5,G12=6),1,0) -> 0
A13: NLD | B13: Netherlands | C13: IPCC Common Reporting Format | D13: N₂O | E13: 2 | F13: 2 - Industrial Processes and Product Use | G13: Sectors/Totals_incl_incl | H13: Gg | I13: 2023 | J13: 1.77819 | L13: 20250315 | M13: EEA | O13: =IF(OR(G13=2,G13=3,G13=5,G13=6),1,0) -> 0
A14: NLD | B14: Netherlands | C14: IPCC Common Reporting Format | D14: PFCs - (CO2 equivalent) | E14: 2 | F14: 2 - Industrial Processes and Product Use | G14: Sectors/Totals_incl_incl | H14: Gg CO2 equivalent | I14: 2023 | J14: 41.91602 | L14: 20250315 | M14: EEA | O14: =IF(OR(G14=2,G14=3,G14=5,G14=6),1,0) -> 0
A15: NLD | B15: Netherlands | C15: IPCC Common Reporting Format | D15: CH₄ | E15: 3 | F15: 3 - Agriculture | G15: Sectors/Totals_incl_incl | H15: Gg | I15: 2023 | J15: 465.6263 | L15: 20250315 | M15: EEA | O15: =IF(OR(G15=2,G15=3,G15=5,G15=6),1,0) -> 0
A16: NLD | B16: Netherlands | C16: IPCC Common Reporting Format | D16: N₂O | E16: 3 | F16: 3 - Agriculture | G16: Sectors/Totals_incl_incl | H16: Gg | I16: 2023 | J16: 18.30407 | L16: 20250315 | M16: EEA | O16: =IF(OR(G16=2,G16=3,G16=5,G16=6),1,0) -> 0
A17: NLD | B17: Netherlands | C17: IPCC Common Reporting Format | D17: All greenhouse gases - (CO2 equivalent) | E17: 3 | F17: 3 - Agriculture | G17: Sectors/Totals_incl_incl | H17: Gg CO2 equivalent | I17: 2023 | J17: 17981.328 | L17: 20250315 | M17: EEA | O17: =IF(OR(G17=2,G17=3,G17=5,G17=6),1,0) -> 0
A18: NLD | B18: Netherlands | C18: IPCC Common Reporting Format | D18: CO₂ | E18: 3 | F18: 3 - Agriculture | G18: Sectors/Totals_incl_incl | H18: Gg | I18: 2023 | J18: 93.21328 | L18: 20250315 | M18: EEA | O18: =IF(OR(G18=2,G18=3,G18=5,G18=6),1,0) -> 0
A19: NLD | B19: Netherlands | C19: IPCC Common Reporting Format | D19: All greenhouse gases - (CO2 equivalent) | E19: 4 | F19: 4 - Land Use, Land-Use Change and Forestry | G19: Sectors/Totals_incl_incl | H19: Gg CO2 equivalent | I19: 2023 | J19: 3804.4553 | L19: 20250315 | M19: EEA | O19: =IF(OR(G19=2,G19=3,G19=5,G19=6),1,0) -> 0
A20: NLD | B20: Netherlands | C20: IPCC Common Reporting Format | D20: N₂O | E20: 4 | F20: 4 - Land Use, Land-Use Change and Forestry | G20: Sectors/Totals_incl_incl | H20: Gg | I20: 2023 | J20: 0.38293 | L20: 20250315 | M20: EEA | O20: =IF(OR(G20=2,G20=3,G20=5,G20=6),1,0) -> 0
A21: NLD | B21: Netherlands | C21: IPCC Common Reporting Format | D21: CO₂ | E21: 4 | F21: 4 - Land Use, Land-Use Change and Forestry | G21: Sectors/Totals_incl_incl | H21: Gg | I21: 2023 | J21: 3114.5466 | L21: 20250315 | M21: EEA | O21: =IF(OR(G21=2,G21=3,G21=5,G21=6),1,0) -> 0
A22: NLD | B22: Netherlands | C22: IPCC Common Reporting Format | D22: CH₄ | E22: 4 | F22: 4 - Land Use, Land-Use Change and Forestry | G22: Sectors/Totals_incl_incl | H22: Gg | I22: 2023 | J22: 21.01541 | L22: 20250315 | M22: EEA | O22: =IF(OR(G22=2,G22=3,G22=5,G22=6),1,0) -> 0
A23: NLD | B23: Netherlands | C23: IPCC Common Reporting Format | D23: N₂O | E23: 5 | F23: 5 - Waste management | G23: Sectors/Totals_incl_incl | H23: Gg | I23: 2023 | J23: 2.2001 | L23: 20250315 | M23: EEA | O23: =IF(OR(G23=2,G23=3,G23=5,G23=6),1,0) -> 0
A24: NLD | B24: Netherlands | C24: IPCC Common Reporting Format | D24: CO₂ | E24: 5 | F24: 5 - Waste management | G24: Sectors/Totals_incl_incl | H24: Gg | I24: 2023 | K24: IE,NA,NO | L24: 20250315 | M24: EEA | O24: =IF(OR(G24=2,G24=3,G24=5,G24=6),1,0) -> 0
A25: NLD | B25: Netherlands | C25: IPCC Common Reporting Format | D25: All greenhouse gases - (CO2 equivalent) | E25: 5 | F25: 5 - Waste management | G25: Sectors/Totals_incl_incl | H25: Gg CO2 equivalent | I25: 2023 | J25: 2844.4752 | L25: 20250315 | M25: EEA | O25: =IF(OR(G25=2,G25=3,G25=5,G25=6),1,0) -> 0
A26: NLD | B26: Netherlands | C26: IPCC Common Reporting Format | D26: CH₄ | E26: 5 | F26: 5 - Waste management | G26: Sectors/Totals_incl_incl | H26: Gg | I26: 2023 | J26: 80.76607 | L26: 20250315 | M26: EEA | O26: =IF(OR(G26=2,G26=3,G26=5,G26=6),1,0) -> 0
A27: NLD | B27: Netherlands | C27: IPCC Common Reporting Format | D27: CH₄ | E27: 6 | F27: 6 - Other Sector | G27: Sectors/Totals_incl_incl | H27: Gg | I27: 2023 | K27: NO | L27: 20250315 | M27: EEA | O27: =IF(OR(G27=2,G27=3,G27=5,G27=6),1,0) -> 0
A28: NLD | B28: Netherlands | C28: IPCC Common Reporting Format | D28: All greenhouse gases - (CO2 equivalent) | E28: 6 | F28: 6 - Other Sector | G28: Sectors/Totals_incl_incl | H28: Gg CO2 equivalent | I28: 2023 | K28: NO | L28: 20250315 | M28: EEA | O28: =IF(OR(G28=2,G28=3,G28=5,G28=6),1,0) -> 0
A29: NLD | B29: Netherlands | C29: IPCC Common Reporting Format | D29: NF3 - (CO2 equivalent) | E29: 6 | F29: 6 - Other Sector | G29: Sectors/Totals_incl_incl | H29: Gg CO2 equivalent | I29: 2023 | K29: NO | L29: 20250315 | M29: EEA | O29: =IF(OR(G29=2,G29=3,G29=5,G29=6),1,0) -> 0
A30: NLD | B30: Netherlands | C30: IPCC Common Reporting Format | D30: HFCs - (CO2 equivalent) | E30: 6 | F30: 6 - Other Sector | G30: Sectors/Totals_incl_incl | H30: Gg CO2 equivalent | I30: 2023 | K30: NO | L30: 20250315 | M30: EEA | O30: =IF(OR(G30=2,G30=3,G30=5,G30=6),1,0) -> 0
A31: NLD | B31: Netherlands | C31: IPCC Common Reporting Format | D31: SF6 - (CO2 equivalent) | E31: 6 | F31: 6 - Other Sector | G31: Sectors/Totals_incl_incl | H31: Gg CO2 equivalent | I31: 2023 | K31: NO | L31: 20250315 | M31: EEA | O31: =IF(OR(G31=2,G31=3,G31=5,G31=6),1,0) -> 0
A32: NLD | B32: Netherlands | C32: IPCC Common Reporting Format | D32: CO₂ | E32: 6 | F32: 6 - Other Sector | G32: Sectors/Totals_incl_incl | H32: Gg | I32: 2023 | K32: NO | L32: 20250315 | M32: EEA | O32: =IF(OR(G32=2,G32=3,G32=5,G32=6),1,0) -> 0
A33: NLD | B33: Netherlands | C33: IPCC Common Reporting Format | D33: N₂O | E33: 6 | F33: 6 - Other Sector | G33: Sectors/Totals_incl_incl | H33: Gg | I33: 2023 | K33: NO | L33: 20250315 | M33: EEA | O33: =IF(OR(G33=2,G33=3,G33=5,G33=6),1,0) -> 0
A34: NLD | B34: Netherlands | C34: IPCC Common Reporting Format | D34: PFCs - (CO2 equivalent) | E34: 6 | F34: 6 - Other Sector | G34: Sectors/Totals_incl_incl | H34: Gg CO2 equivalent | I34: 2023 | K34: NO | L34: 20250315 | M34: EEA | O34: =IF(OR(G34=2,G34=3,G34=5,G34=6),1,0) -> 0
A35: NLD | B35: Netherlands | C35: IPCC Common Reporting Format | D35: Unspecified mix of HFCs and PFCs - (CO2 equivalent) | E35: 6 | F35: 6 - Other Sector | G35: Sectors/Totals_incl_incl | H35: Gg CO2 equivalent | I35: 2023 | K35: NO | L35: 20250315 | M35: EEA | O35: =IF(OR(G35=2,G35=3,G35=5,G35=6),1,0) -> 0
A36: NLD | B36: Netherlands | C36: IPCC Common Reporting Format | D36: All greenhouse gases - (CO2 equivalent) | E36: 1.A | F36: 1.A - Fuel combustion activities (sectoral approach) | G36: 1 | H36: Gg CO2 equivalent | I36: 2023 | J36: 106787 | L36: 20250315 | M36: EEA | O36: =IF(OR(G36=2,G36=3,G36=5,G36=6),1,0) -> 0
A37: NLD | B37: Netherlands | C37: IPCC Common Reporting Format | D37: CH₄ | E37: 1.A | F37: 1.A - Fuel combustion activities (sectoral approach) | G37: 1 | H37: Gg | I37: 2023 | J37: 58.94946 | L37: 20250315 | M37: EEA | O37: =IF(OR(G37=2,G37=3,G37=5,G37=6),1,0) -> 0
A38: NLD | B38: Netherlands | C38: IPCC Common Reporting Format | D38: CO₂ | E38: 1.A | F38: 1.A - Fuel combustion activities (sectoral approach) | G38: 1 | H38: Gg | I38: 2023 | J38: 104540 | L38: 20250315 | M38: EEA | O38: =IF(OR(G38=2,G38=3,G38=5,G38=6),1,0) -> 0
A39: NLD | B39: Netherlands | C39: IPCC Common Reporting Format | D39: N₂O | E39: 1.A | F39: 1.A - Fuel combustion activities (sectoral approach) | G39: 1 | H39: Gg | I39: 2023 | J39: 2.25062 | L39: 20250315 | M39: EEA | O39: =IF(OR(G39=2,G39=3,G39=5,G39=6),1,0) -> 0
A40: NLD | B40: Netherlands | C40: IPCC Common Reporting Format | D40: N₂O | E40: 1.A.1 | F40: 1.A.1 - Energy Industries | G40: 1.AA | H40: Gg | I40: 2023 | J40: 0.77137 | L40: 20250315 | M40: EEA | O40: =IF(OR(G40=2,G40=3,G40=5,G40=6),1,0) -> 0
...
