Workbook
Name ap_subfuel_allo: '[1]CEB allocation factors'!$F$12:$BC$12
Name base_year: [1]Dashboard!$E$13
Name country: [1]Dashboard!$E$12
Name Eff_cooking_biomass: [2]technical_specs!$M$50
Name Eff_cooking_electric: [2]technical_specs!$M$47
Name Eff_cooking_gas: [2]technical_specs!$M$46
Name Eff_cooking_halogen: [2]technical_specs!$M$48
Name Eff_cooking_induction: [2]technical_specs!$M$49
Name Eff_cooling_airco: [2]technical_specs!$M$43
Name Eff_cooling_pump_air: [2]technical_specs!$M$42
Name Eff_cooling_pump_ground: [2]technical_specs!$M$41
Name Eff_hot_water_coal: [2]technical_specs!$M$36
Name Eff_hot_water_combi_boiler: [2]technical_specs!$M$26
Name Eff_hot_water_district: [2]technical_specs!$M$30
Name Eff_hot_water_electric: [2]technical_specs!$M$33
Name Eff_hot_water_fuel_cell: [2]technical_specs!$M$37
Name Eff_hot_water_gas: [2]technical_specs!$M$34
Name Eff_hot_water_micro_CHP: [2]technical_specs!$M$29
Name Eff_hot_water_oil: [2]technical_specs!$M$35
Name Eff_hot_water_pump_air: [2]technical_specs!$M$31
Name Eff_hot_water_pump_ground: [2]technical_specs!$M$28
Name Eff_hot_water_solar_thermal_panel: [2]technical_specs!$M$27
Name Eff_hot_water_woodpellets: [2]technical_specs!$M$32
Name Eff_lighting_fluorescent: [2]technical_specs!$M$54
Name Eff_lighting_incandescent: [2]technical_specs!$M$53
Name Eff_lighting_led: [2]technical_specs!$M$55
Name Eff_space_heating_coal: [2]technical_specs!$M$21
Name Eff_space_heating_combi_boiler: [2]technical_specs!$M$11
Name Eff_space_heating_district: [2]technical_specs!$M$15
Name Eff_space_heating_electric: [2]technical_specs!$M$18
Name Eff_space_heating_gas: [2]technical_specs!$M$19
Name Eff_space_heating_micro_CHP: [2]technical_specs!$M$14
Name Eff_space_heating_oil: [2]technical_specs!$M$20
Name Eff_space_heating_pump_add_on: [2]technical_specs!$M$22
Name Eff_space_heating_pump_air: [2]technical_specs!$M$16
Name Eff_space_heating_pump_ground: [2]technical_specs!$M$13
Name Eff_space_heating_solar_thermal: [2]technical_specs!$M$12
Name Eff_space_heating_woodpellets: [2]technical_specs!$M$17
Name ei_subsector_allo: '[1]CEB allocation factors'!$D$17:$D$33
Name Final_demand_appliances: [2]Dashboard!$E$25
Name Final_demand_coal: '[2]Fuel aggregation'!$C$11
Name Final_demand_cooking: [2]Dashboard!$E$24
Name Final_demand_cooling: [2]Dashboard!$E$22
Name Final_demand_electricity: '[2]Fuel aggregation'!$I$11
Name Final_demand_gas: '[2]Fuel aggregation'!$D$11
Name Final_demand_heat: '[2]Fuel aggregation'!$J$11
Name Final_demand_hot_water: [2]Dashboard!$E$21
Name Final_demand_lighting: [2]Dashboard!$E$23
Name Final_demand_oil: '[2]Fuel aggregation'!$E$11
Name Final_demand_residences: '[2]Fuel aggregation'!$L$11
Name Final_demand_solar_thermal: '[2]Fuel aggregation'!$G$11
Name Final_demand_space_heating: [2]Dashboard!$E$20
Name Final_demand_woodpellets: '[2]Fuel aggregation'!$F$11
Name i_subsector_allo: '[1]CEB allocation factors'!$D$37:$D$49
Name kWh_MJ_conversion: [1]Assumptions!$C$174
Name net_gross_conv: '[1]AP net-gross conversion'!$D$12
Name switch_decc: '[1]Fuel allocation'!$C$130
Name switch_iea: '[1]Fuel allocation'!$C$89
Name switch_protermo: '[1]Fuel allocation'!$C$48

Sheet Cover sheet
B2: Cover sheet
B4: Document | C4: Transport source analysis
B5: Version # | C5: 1
B6: Country | C6: nl
B7: Year data | C7: 2023
B8: Date | C8: 45812
B9: Author | C9: Max Kerpel
B10: Organisation | C10: Quintel Intelligence
B12: Legend
B14: Cells | C14: Intermediate (calculation)
C15: Result
C16: Manual input
C17: Reference to manual input or data input
B19: Tabs | C19: Introductory
C20: Dashboard
C21: Research data
C22: Sources
C23: Results
C24: Main calculations
C25: Additional calculations
C26: Output to csv
B29: Comments

Sheet Assumptions
B6: Assumptions - general
B7: Emissions per application type from Emissieregistratie are used to calculate split of cars and vans, which is the same category in Eurostat
B8: Number of electric vehicles is used to find the split in cars and vans.
B9: Number of vehicles from Klimaatmonitor and typical energy consumption are used to calculate the road application shares for electricity and hydrogen transport.
B10: Eurostat data is used to split carriers to rails, motorcycles, trucks, buses, and cars and vans.
B12: Assumptions - debts that might be furhter investigated
B13: According to Emissieregistratie gas is only used by buses, even though e.g. cars using CNG also exist.
B14: Emissieregistratie offers no further split of fuel consumption by trucks, which is why it is assumed that they only use diesel.
B15: Emissieregistratie offers no further split of fuel consumption by mobile machinery, which is why it is assumed that they only use diesel.
B16: Vans are part of trucks fuel consumption.
B17: Mobile machinery is part of trucks fuel consumption.
B18: Specifications of electric vehicles have some missing sources, meaning that the data may be outdated.
B19: Specifications of hydrogen vehicles have some missing sources, meaning that the data may be outdated.

Sheet Dashboard
C4: Values used in transport analysis=
C5: Road Transport
D6: Percentage of gasoline mix delivered to cars | E6: Share | F6: ='Analysis - transport'!AQ28 -> 0.96857162 | I6: 0.96857162
D7: Percentage of gasoline mix delivered to trucks | E7: Share | F7: ='Analysis - transport'!AQ23 -> 0.00015938225 | I7: 0.00015938225
D8: Percentage of gasoline mix delivered to vans | E8: Share | F8: ='Analysis - transport'!AQ29 -> 0.0043171341 | I8: 0.0043171341
D9: Percentage of gasoline mix delivered to busses | E9: Share | F9: ='Analysis - transport'!AQ24 -> 0.0010611656 | I9: 0.0010611656
D10: Percentage of gasoline mix delivered to motorcycles | E10: Share | F10: ='Analysis - transport'!AQ26 -> 0.025890701 | I10: 0.025890701
D12: Percentage of diesel mix delivered to cars | E12: Share | F12: ='Analysis - transport'!AP28 -> 0.19779589 | I12: 0.19779589
D13: Percentage of diesel mix delivered to trucks | E13: Share | F13: ='Analysis - transport'!AP23 -> 0.4845082 | I13: 0.4845082
D14: Percentage of diesel mix delivered to vans | E14: Share | F14: ='Analysis - transport'!AP29 -> 0.29651866 | I14: 0.29651866
D15: Percentage of diesel mix delivered to busses | E15: Share | F15: ='Analysis - transport'!AP24 -> 0.021177248 | I15: 0.021177248
D17: Percentage of electricity delivered to cars | E17: Share | F17: ='Analysis - transport'!AO28 -> 0.86987754 | I17: 0.86987754
D18: Percentage of electricity delivered to trucks | E18: Share | F18: ='Analysis - transport'!AO23 -> 0.0019772237 | I18: 0.0019772237
D19: Percentage of electricity delivered to vans | E19: Share | F19: ='Analysis - transport'!AO29 -> 0.030580376 | I19: 0.030580376
D20: Percentage of electricity delivered to busses | E20: Share | F20: ='Analysis - transport'!AO24 -> 0.086465611 | I20: 0.086465611
D21: Percentage of electricity delivered to motorcycles | E21: Share | F21: ='Analysis - transport'!AV26 -> 0.010147355 | I21: 0.010147355
D22: Percentage of electricity delivered to bicycles | E22: Share | F22: ='Analysis - transport'!AV27 -> 0.00095189452 | I22: 0.00095189452
D24: Percentage of natural gas that is liquefied natural gas | E24: Share | F24: 0 | I24: 0
D25: Percentage of natural gas that is compressed natural gas | E25: Share | F25: 1 | I25: 1
D27: Percentage of lng that is delivered to trucks | E27: Share | F27: 0 | I27: 0
D28: Percentage of lng that is delivered to busses | E28: Share | F28: 1 | I28: 1
D30: Percentage of compressed network gas delivered to cars | E30: Share | F30: ='Analysis - transport'!AR28 -> 0.18003911 | I30: 0.18003911
D31: Percentage of compressed network gas delivered to trucks | E31: Share | F31: ='Analysis - transport'!AR23 -> 0.57136248 | I31: 0.57136248
D32: Percentage of compressed network gas delivered to vans | E32: Share | F32: ='Analysis - transport'!AR29 -> 0.045588414 | I32: 0.045588414
D33: Percentage of compressed network gas delivered to busses | E33: Share | F33: ='Analysis - transport'!AR24 -> 0.20301 | I33: 0.20301
D35: Percentage of lpg delivered to cars | E35: Share | F35: ='Analysis - transport'!AS28 -> 0.71263697 | I35: 0.71263697
D36: Percentage of lpg delivered to vans | E36: Share | F36: ='Analysis - transport'!AS29 -> 0.28736303 | I36: 0.28736303
D38: Biogases in road transport | E38: TJ | F38: 0 | I38: 0
D39: Percentage of bio lng | E39: Share | F39: 0 | I39: 0
D40: Percentage of bio cng | E40: Share | F40: 1 | I40: 1
D42: Passenger kilometers bicycles | E42: million pkm | F42: ='Analysis - transport'!AO38 -> 17800 | I42: 17800
C44: Domestic navigation transport
D46: LNG shipping | E46: TJ | F46: 0 | I46: 0
D47: Percentage of lng for shipping to (pure) lng ship | E47: Share | F47: 0 | I47: 0
D48: Percentage of lng for shipping to hybrid diesel ship | E48: Share | F48: 1 | I48: 1
D50: Bio LNG shipping | E50: TJ | F50: 0 | I50: 0
D51: Percentage of bio lng for shipping to (pure) lng ship | E51: Share | F51: 0 | I51: 0
D52: Percentage of bio lng for shipping to hybrid diesel ship | E52: Share | F52: 1 | I52: 1
C54: Rail transport
D55: Electricity rail | E55: TJ
...

Sheet Analysis - transport
A1: Data extracted on 03/06/2025 09:58:14 from [ESTAT]
A2: Dataset: | B2: Disaggregated final energy consumption in transport by mode of transport - quantities [nrg_d_traq__custom_16868870]
A3: Last updated: | B3: 25/09/2024 23:00
A5: Time frequency | C5: Annual
A6: Unit of measure | C6: Terajoule
A7: Geopolitical entity (reporting) | C7: Netherlands
A8: Time | C8: 2022
A10: SIEC (Labels) | B10: SIEC (Labels) | C10: Solid fossil fuels | E10: Natural gas | G10: Oil and petroleum products (excluding biofuel portion) | I10: Liquefied petroleum gases | K10: Aviation gasoline | M10: Motor gasoline (excluding biofuel portion) | O10: Kerosene-type jet fuel (excluding biofuel portion) | Q10: Gas oil and diesel oil (excluding biofuel portion) | S10: Fuel oil | U10: Renewables and biofuels | W10: Pure biogasoline | Y10: Blended biogasoline | AA10: Pure biodiesels | AC10: Blended biodiesels | AE10: Pure bio jet kerosene | AG10: Blended bio jet kerosene | AI10: Biogases | AK10: Electricity
A11: TRA_MODE (Labels) | B11: NRG_BAL (Labels)
A12: Total | B12: Final consumption - transport sector - rail - energy use | C12: 0 | E12: 0 | G12: 886.946 | H12: p | I12: 0 | K12: 0 | M12: 0 | O12: 0 | Q12: 0 | S12: 0 | U12: 1.522 | W12: 0 | Y12: 0 | AA12: 0 | AC12: 0 | AE12: 0 | AG12: 0 | AI12: 0 | AK12: 6114.172
A13: Total | B13: Final consumption - transport sector - rail - high speed - energy use | C13: 0 | E13: 0 | G13: 0 | H13: p | I13: 0 | K13: 0 | M13: 0 | O13: 0 | Q13: 0 | S13: 0 | U13: 0 | W13: 0 | Y13: 0 | AA13: 0 | AC13: 0 | AE13: 0 | AG13: 0 | AI13: 0 | AK13: 213.271
A14: Total | B14: Final consumption - transport sector - rail - conventional - energy use | C14: 0 | E14: 0 | G14: 886.946 | H14: p | I14: 0 | K14: 0 | M14: 0 | O14: 0 | Q14: 0 | S14: 0 | U14: 1.522 | W14: 0 | Y14: 0 | AA14: 0 | AC14: 0 | AE14: 0 | AG14: 0 | AI14: 0 | AK14: 5425.29
A15: Total | B15: Final consumption - transport sector - rail - metro and tram - energy use | C15: 0 | E15: 0 | G15: 0 | H15: p | I15: 0 | K15: 0 | M15: 0 | O15: 0 | Q15: 0 | S15: 0 | U15: 0 | W15: 0 | Y15: 0 | AA15: 0 | AC15: 0 | AE15: 0 | AG15: 0 | AI15: 0 | AK15: 475.61
A16: Total | B16: Final consumption - transport sector - road - fuel used | C16: 0 | E16: 2656.935 | G16: 353092.08 | H16: p | I16: 4084.319 | K16: 0 | M16: 160956.49 | O16: 0 | Q16: 175608.93 | S16: 0 | U16: 23442.149 | W16: 0 | Y16: 10998.849 | AA16: 0 | AC16: 12442.346 | AE16: 0 | AG16: 0 | AI16: 0 | AK16: 5925.986
A17: Total | B17: Final consumption - transport sector - road - heavy-duty vehicles - fuel used | C17: 0 | E17: 1535.094 | G17: 90699.744 | H17: p | I17: 28.42 | K17: 0 | M17: 24.514 | O17: 0 | Q17: 84649.159 | S17: 0 | U17: 5999.367 | W17: 0 | Y17: 1.675 | AA17: 0 | AC17: 5997.651 | AE17: 0 | AG17: 0 | AI17: 0 | AK17: 11.717
A18: Total | B18: Final consumption - transport sector - road - public - fuel used | C18: 0 | E18: 549.677 | G18: 4199.266 | H18: p | I18: 0.04 | K18: 0 | M18: 163.214 | O18: 0 | Q18: 3769.051 | S18: 0 | U18: 279.031 | W18: 0 | Y18: 11.156 | AA18: 0 | AC18: 266.961 | AE18: 0 | AG18: 0 | AI18: 0 | AK18: 512.394
A19: Total | B19: Final consumption - transport sector - road - cars and vans - fuel used | C19: 0 | E19: 572.164 | G19: 254189.36 | H19: p | I19: 4055.858 | K19: 0 | M19: 156786.61 | O19: 0 | Q19: 87170.594 | S19: 0 | U19: 16890.149 | W19: 0 | Y19: 10713.842 | AA19: 0 | AC19: 6176.307 | AE19: 0 | AG19: 0 | AI19: 0 | AK19: 5336.101
A20: Total | B20: Final consumption - transport sector - road - other - fuel used | C20: 0 | E20: 0 | G20: 4003.704 | H20: p | I20: 0.001 | K20: 0 | M20: 3982.154 | O20: 0 | Q20: 20.122 | S20: 0 | U20: 273.602 | W20: 0 | Y20: 272.176 | AA20: 0 | AC20: 1.427 | AE20: 0 | AG20: 0 | AI20: 0 | AK20: 65.774
A21: Total | B21: Final consumption - transport sector - road - other - 2-wheeled vehicles - fuel used | C21: 0 | E21: 0 | G21: 4003.704 | H21: p | I21: 0.001 | K21: 0 | M21: 3982.154 | O21: 0 | Q21: 20.122 | S21: 0 | U21: 273.602 | W21: 0 | Y21: 272.176 | AA21: 0 | AC21: 1.427 | AE21: 0 | AG21: 0 | AI21: 0 | AK21: 65.774 | AN21: Eurostat data voor splits wegtransport per drager=
A22: Total | B22: Final consumption - transport sector - road - energy use | C22: 0 | E22: 2585.251 | G22: 347934.68 | H22: p | I22: 5208.454 | K22: 0 | M22: 153806.34 | O22: 0 | Q22: 176414.05 | S22: 0 | U22: 23018.331 | W22: 0 | Y22: 10512.494 | AA22: 0 | AC22: 12505.837 | AE22: 0 | AG22: 0 | AI22: 0 | AK22: 5925.986 | AO22: electricity | AP22: diesel | AQ22: gasoline | AR22: natural gas | AS22: lpg
A23: Total | B23: Final consumption - transport sector - road - heavy-duty vehicles - energy use | C23: 0 | E23: 1477.116 | G23: 91582.958 | H23: p | I23: 35.65 | K23: 0 | M23: 24.514 | O23: 0 | Q23: 85464.305 | S23: 0 | U23: 6060.165 | W23: 0 | Y23: 1.675 | AA23: 0 | AC23: 6058.489 | AE23: 0 | AG23: 0 | AI23: 0 | AK23: 11.717 | AN23: trucks | AO23: =AK23/SUM($AK$23:$AK$26) -> 0.0019772237 | AP23: =Q23/SUM($Q$23:$Q$25) -> 0.4845082 | AQ23: =M23/SUM($M$23:$M$26) -> 0.00015938225 | AR23: =E23/SUM($E$23:$E$26) -> 0.57136248 | AS23: 0
A24: Total | B24: Final consumption - transport sector - road - public - energy use | C24: 0 | E24: 524.832 | G24: 4163.611 | H24: p | I24: 0.05 | K24: 0 | M24: 163.214 | O24: 0 | Q24: 3735.538 | S24: 0 | U24: 275.964 | W24: 0 | Y24: 11.156 | AA24: 0 | AC24: 264.809 | AE24: 0 | AG24: 0 | AI24: 0 | AK24: 512.394 | AN24: busses | AO24: =AK24/SUM($AK$23:$AK$26) -> 0.086465611 | AP24: =Q24/SUM($Q$23:$Q$25) -> 0.021177248 | AQ24: =M24/SUM($M$23:$M$26) -> 0.0010611656 | AR24: =E24/SUM($E$23:$E$26) -> 0.20301 | AS24: =I24/SUM($I$23:$I$26) -> 9.5997776e-06 | AU24: klimaatmonitor data voor split 2 wielers=
A25: Total | B25: Final consumption - transport sector - road - cars and vans - energy use | C25: 0 | E25: 583.304 | G25: 248184.41 | H25: p | I25: 5172.753 | K25: 0 | M25: 149636.46 | O25: 0 | Q25: 87194.085 | S25: 0 | U25: 16408.598 | W25: 0 | Y25: 10227.487 | AA25: 0 | AC25: 6181.112 | AE25: 0 | AG25: 0 | AI25: 0 | AK25: 5336.101 | AN25: cars and vans | AO25: =AK25/SUM($AK$23:$AK$26) -> 0.90045792 | AP25: =Q25/SUM($Q$23:$Q$25) -> 0.49431455 | AQ25: =M25/SUM($M$23:$M$26) -> 0.97288875 | AR25: =E25/SUM($E$23:$E$26) -> 0.22562752 | AS25: 1 | AV25: electricity
A26: Total | B26: Final consumption - transport sector - road - other - energy use | C26: 0 | E26: 0 | G26: 4003.704 | H26: p | I26: 0.001 | K26: 0 | M26: 3982.154 | O26: 0 | Q26: 20.122 | S26: 0 | U26: 273.603 | W26: 0 | Y26: 272.176 | AA26: 0 | AC26: 1.427 | AE26: 0 | AG26: 0 | AI26: 0 | AK26: 65.774 | AN26: motorcycles and bicycles | AO26: =AK26/SUM($AK$23:$AK$26) -> 0.01109925 | AP26: - | AQ26: =M26/SUM($M$23:$M$26) -> 0.025890701 | AR26: =E26/SUM($E$23:$E$26) -> 0 | AS26: =I26/SUM($I$23:$I$26) -> 1.9199555e-07 | AU26: motorcycles | AV26: =AX90/(AX90+AX91)*AO26 -> 0.010147355
A27: Total | B27: Final consumption - transport sector - road - other - 2-wheeled vehicles - energy use | C27: 0 | E27: 0 | G27: 4003.704 | H27: p | I27: 0.001 | K27: 0 | M27: 3982.154 | O27: 0 | Q27: 20.122 | S27: 0 | U27: 273.603 | W27: 0 | Y27: 272.176 | AA27: 0 | AC27: 1.427 | AE27: 0 | AG27: 0 | AI27: 0 | AK27: 65.774 | AU27: bicycles | AV27: =AX91/(AX90+AX91)*AO26 -> 0.00095189452
A28: Total | B28: Final consumption - transport sector - aviation - energy use | C28: 0 | E28: 0 | G28: 0 | H28: p | I28: 0 | K28: 0 | M28: 0 | O28: 0 | Q28: 0 | S28: 0 | U28: 0 | W28: 0 | Y28: 0 | AA28: 0 | AC28: 0 | AE28: 0 | AG28: 0 | AI28: 0 | AK28: 0 | AN28: cars | AO28: =AR60/(AR60+AR61)*AO25 -> 0.86987754 | AP28: =AW35/(AW35+AW36)*AP25 -> 0.19779589 | AQ28: =AV35/(AV35+AV36)*AQ25 -> 0.96857162 | AR28: =AY35/(AY35+AY36)*AR25 -> 0.18003911 | AS28: =AX35/(AX35+AX36)*AS25 -> 0.71263697
A29: Total | B29: Final consumption - transport sector - domestic aviation - energy use | C29: 0 | E29: 0 | G29: 0 | H29: p | I29: 0 | K29: 0 | M29: 0 | O29: 0 | Q29: 0 | S29: 0 | U29: 0 | W29: 0 | Y29: 0 | AA29: 0 | AC29: 0 | AE29: 0 | AG29: 0 | AI29: 0 | AK29: 0 | AN29: vans | AO29: =AR61/(AR60+AR61)*AO25 -> 0.030580376 | AP29: =AW36/(AW36+AW35)*AP25 -> 0.29651866 | AQ29: =AV36/(AV36+AV35)*AQ25 -> 0.0043171341 | AR29: =AY36/(AY35+AY36)*AR25 -> 0.045588414 | AS29: =AX36/(AX36+AX35)*AS25 -> 0.28736303
A30: Total | B30: Final consumption - transport sector - international aviation - energy use | C30: 0 | E30: 0 | G30: 0 | H30: p | I30: 0 | K30: 0 | M30: 0 | O30: 0 | Q30: 0 | S30: 0 | U30: 0 | W30: 0 | Y30: 0 | AA30: 0 | AC30: 0 | AE30: 0 | AG30: 0 | AI30: 0 | AK30: 0 | AN30: Eurostat data voor splits railtransport per drager=
A31: Total | B31: Final consumption - transport sector - domestic navigation - energy use | C31: 0 | E31: 0 | G31: 0 | H31: p | I31: 0 | K31: 0 | M31: 0 | O31: 0 | Q31: 0 | S31: 0 | U31: 0 | W31: 0 | Y31: 0 | AA31: 0 | AC31: 0 | AE31: 0 | AG31: 0 | AI31: 0 | AK31: 0 | AO31: diesel | AP31: electricity
A32: Total | B32: Final consumption - transport sector - domestic navigation - maritime - energy use | C32: 0 | E32: 0 | G32: 0 | H32: p | I32: 0 | K32: 0 | M32: 0 | O32: 0 | Q32: 0 | S32: 0 | U32: 0 | W32: 0 | Y32: 0 | AA32: 0 | AC32: 0 | AE32: 0 | AG32: 0 | AI32: 0 | AK32: 0 | AN32: rail passengers | AO32: =G36/(G36+G58) -> 0.48183768 | AP32: =(AK13+AK36)/AQ32 -> 0.82045252 | AQ32: =AK13+AK15+AK58+AK36 -> 6114.171
A33: Total | B33: Final consumption - transport sector - domestic navigation - inland waterways - energy use | C33: 0 | E33: 0 | G33: 0 | H33: p | I33: 0 | K33: 0 | M33: 0 | O33: 0 | Q33: 0 | S33: 0 | U33: 0 | W33: 0 | Y33: 0 | AA33: 0 | AC33: 0 | AE33: 0 | AG33: 0 | AI33: 0 | AK33: 0 | AN33: rail freight | AO33: =G58/(G58+G36) -> 0.51816232 | AP33: =AK58/AQ32 -> 0.10175934 | AU33: emissieregistraties om verhouding auto en busjes te bepalen=
A34: Passenger | B34: Final consumption - transport sector - rail - energy use | C34: : | E34: : | G34: : | I34: : | K34: : | M34: : | O34: : | Q34: : | S34: : | U34: : | W34: : | Y34: : | AA34: : | AC34: : | AE34: : | AG34: : | AI34: : | AK34: : | AN34: metro tram | AP34: =AK15/AQ32 -> 0.077788142 | AV34: gasoline | AW34: diesel | AX34: lpg | AY34: totaal
A35: Passenger | B35: Final consumption - transport sector - rail - high speed - energy use | C35: : | E35: : | G35: : | I35: : | K35: : | M35: : | O35: : | Q35: : | S35: : | U35: : | W35: : | Y35: : | AA35: : | AC35: : | AE35: : | AG35: : | AI35: : | AK35: : | AU35: cars | AV35: 12870250000 | AW35: 2542692000 | AX35: 224099100 | AY35: =SUM(AV35:AX35) -> 15637041100 | AZ35: Bron: Emissie registratie: Datadump - Road fuels
A36: Passenger | B36: Final consumption - transport sector - rail - conventional - energy use | C36: 0 | E36: 0 | G36: 427.364 | H36: p | I36: 0 | K36: 0 | M36: 0 | O36: 0 | Q36: 0 | S36: 0 | U36: 0.733 | W36: 0 | Y36: 0 | AA36: 0 | AC36: 0 | AE36: 0 | AG36: 0 | AI36: 0 | AK36: 4803.116 | AU36: vans | AV36: 57365500 | AW36: 3811786000 | AX36: 90365500 | AY36: =SUM(AV36:AX36) -> 3959517000
A37: Passenger | B37: Final consumption - transport sector - rail - metro and tram - energy use | C37: : | E37: : | G37: : | I37: : | K37: : | M37: : | O37: : | Q37: : | S37: : | U37: : | W37: : | Y37: : | AA37: : | AC37: : | AE37: : | AG37: : | AI37: : | AK37: :
A38: Passenger | B38: Final consumption - transport sector - road - fuel used | C38: : | E38: : | G38: : | I38: : | K38: : | M38: : | O38: : | Q38: : | S38: : | U38: : | W38: : | Y38: : | AA38: : | AC38: : | AE38: : | AG38: : | AI38: : | AK38: : | AN38: fietskilometers in mln | AO38: 17800 | AP38: https://opendata.cbs.nl/statline/#/CBS/nl/dataset/84687NED/table?dl=5526A
A39: Passenger | B39: Final consumption - transport sector - road - heavy-duty vehicles - fuel used | C39: : | E39: : | G39: : | I39: : | K39: : | M39: : | O39: : | Q39: : | S39: : | U39: : | W39: : | Y39: : | AA39: : | AC39: : | AE39: : | AG39: : | AI39: : | AK39: :
A40: Passenger | B40: Final consumption - transport sector - road - public - fuel used | C40: : | E40: : | G40: : | I40: : | K40: : | M40: : | O40: : | Q40: : | S40: : | U40: : | W40: : | Y40: : | AA40: : | AC40: : | AE40: : | AG40: : | AI40: : | AK40: :
A41: Passenger | B41: Final consumption - transport sector - road - cars and vans - fuel used | C41: 0 | E41: 0 | G41: 0 | H41: p | I41: 0 | K41: 0 | M41: 0 | O41: 0 | Q41: 0 | S41: 0 | U41: 0 | W41: 0 | Y41: 0 | AA41: 0 | AC41: 0 | AE41: 0 | AG41: 0 | AI41: 0 | AK41: 0
A42: Passenger | B42: Final consumption - transport sector - road - other - fuel used | C42: : | E42: : | G42: : | I42: : | K42: : | M42: : | O42: : | Q42: : | S42: : | U42: : | W42: : | Y42: : | AA42: : | AC42: : | AE42: : | AG42: : | AI42: : | AK42: :
...

Sheet Datadump - Eurostat
A1: Data extracted on 03/06/2025 09:58:14 from [ESTAT]
A2: Dataset: | B2: Disaggregated final energy consumption in transport by mode of transport - quantities [nrg_d_traq__custom_16868870]
A3: Last updated: | B3: 25/09/2024 23:00
A5: Time frequency | C5: Annual
A6: Unit of measure | C6: Terajoule
A7: Geopolitical entity (reporting) | C7: Netherlands
A8: Time | C8: 2022
A10: SIEC (Labels) | B10: SIEC (Labels) | C10: Solid fossil fuels | E10: Natural gas | G10: Oil and petroleum products (excluding biofuel portion) | I10: Liquefied petroleum gases | K10: Aviation gasoline | M10: Motor gasoline (excluding biofuel portion) | O10: Kerosene-type jet fuel (excluding biofuel portion) | Q10: Gas oil and diesel oil (excluding biofuel portion) | S10: Fuel oil | U10: Renewables and biofuels | W10: Pure biogasoline | Y10: Blended biogasoline | AA10: Pure biodiesels | AC10: Blended biodiesels | AE10: Pure bio jet kerosene | AG10: Blended bio jet kerosene | AI10: Biogases | AK10: Electricity
A11: TRA_MODE (Labels) | B11: NRG_BAL (Labels)
A12: Total | B12: Final consumption - transport sector - rail - energy use | C12: 0 | E12: 0 | G12: 886.946 | H12: p | I12: 0 | K12: 0 | M12: 0 | O12: 0 | Q12: 0 | S12: 0 | U12: 1.522 | W12: 0 | Y12: 0 | AA12: 0 | AC12: 0 | AE12: 0 | AG12: 0 | AI12: 0 | AK12: 6114.172
A13: Total | B13: Final consumption - transport sector - rail - high speed - energy use | C13: 0 | E13: 0 | G13: 0 | H13: p | I13: 0 | K13: 0 | M13: 0 | O13: 0 | Q13: 0 | S13: 0 | U13: 0 | W13: 0 | Y13: 0 | AA13: 0 | AC13: 0 | AE13: 0 | AG13: 0 | AI13: 0 | AK13: 213.271
A14: Total | B14: Final consumption - transport sector - rail - conventional - energy use | C14: 0 | E14: 0 | G14: 886.946 | H14: p | I14: 0 | K14: 0 | M14: 0 | O14: 0 | Q14: 0 | S14: 0 | U14: 1.522 | W14: 0 | Y14: 0 | AA14: 0 | AC14: 0 | AE14: 0 | AG14: 0 | AI14: 0 | AK14: 5425.29
A15: Total | B15: Final consumption - transport sector - rail - metro and tram - energy use | C15: 0 | E15: 0 | G15: 0 | H15: p | I15: 0 | K15: 0 | M15: 0 | O15: 0 | Q15: 0 | S15: 0 | U15: 0 | W15: 0 | Y15: 0 | AA15: 0 | AC15: 0 | AE15: 0 | AG15: 0 | AI15: 0 | AK15: 475.61
A16: Total | B16: Final consumption - transport sector - road - fuel used | C16: 0 | E16: 2656.935 | G16: 353092.08 | H16: p | I16: 4084.319 | K16: 0 | M16: 160956.49 | O16: 0 | Q16: 175608.93 | S16: 0 | U16: 23442.149 | W16: 0 | Y16: 10998.849 | AA16: 0 | AC16: 12442.346 | AE16: 0 | AG16: 0 | AI16: 0 | AK16: 5925.986
A17: Total | B17: Final consumption - transport sector - road - heavy-duty vehicles - fuel used | C17: 0 | E17: 1535.094 | G17: 90699.744 | H17: p | I17: 28.42 | K17: 0 | M17: 24.514 | O17: 0 | Q17: 84649.159 | S17: 0 | U17: 5999.367 | W17: 0 | Y17: 1.675 | AA17: 0 | AC17: 5997.651 | AE17: 0 | AG17: 0 | AI17: 0 | AK17: 11.717
A18: Total | B18: Final consumption - transport sector - road - public - fuel used | C18: 0 | E18: 549.677 | G18: 4199.266 | H18: p | I18: 0.04 | K18: 0 | M18: 163.214 | O18: 0 | Q18: 3769.051 | S18: 0 | U18: 279.031 | W18: 0 | Y18: 11.156 | AA18: 0 | AC18: 266.961 | AE18: 0 | AG18: 0 | AI18: 0 | AK18: 512.394
A19: Total | B19: Final consumption - transport sector - road - cars and vans - fuel used | C19: 0 | E19: 572.164 | G19: 254189.36 | H19: p | I19: 4055.858 | K19: 0 | M19: 156786.61 | O19: 0 | Q19: 87170.594 | S19: 0 | U19: 16890.149 | W19: 0 | Y19: 10713.842 | AA19: 0 | AC19: 6176.307 | AE19: 0 | AG19: 0 | AI19: 0 | AK19: 5336.101
A20: Total | B20: Final consumption - transport sector - road - other - fuel used | C20: 0 | E20: 0 | G20: 4003.704 | H20: p | I20: 0.001 | K20: 0 | M20: 3982.154 | O20: 0 | Q20: 20.122 | S20: 0 | U20: 273.602 | W20: 0 | Y20: 272.176 | AA20: 0 | AC20: 1.427 | AE20: 0 | AG20: 0 | AI20: 0 | AK20: 65.774
A21: Total | B21: Final consumption - transport sector - road - other - 2-wheeled vehicles - fuel used | C21: 0 | E21: 0 | G21: 4003.704 | H21: p | I21: 0.001 | K21: 0 | M21: 3982.154 | O21: 0 | Q21: 20.122 | S21: 0 | U21: 273.602 | W21: 0 | Y21: 272.176 | AA21: 0 | AC21: 1.427 | AE21: 0 | AG21: 0 | AI21: 0 | AK21: 65.774
A22: Total | B22: Final consumption - transport sector - road - energy use | C22: 0 | E22: 2585.251 | G22: 347934.68 | H22: p | I22: 5208.454 | K22: 0 | M22: 153806.34 | O22: 0 | Q22: 176414.05 | S22: 0 | U22: 23018.331 | W22: 0 | Y22: 10512.494 | AA22: 0 | AC22: 12505.837 | AE22: 0 | AG22: 0 | AI22: 0 | AK22: 5925.986 | AN22: electricity | AO22: diesel | AP22: gasoline | AQ22: natural gas | AR22: lpg | AS22: compressed network gas
A23: Total | B23: Final consumption - transport sector - road - heavy-duty vehicles - energy use | C23: 0 | E23: 1477.116 | G23: 91582.958 | H23: p | I23: 35.65 | K23: 0 | M23: 24.514 | O23: 0 | Q23: 85464.305 | S23: 0 | U23: 6060.165 | W23: 0 | Y23: 1.675 | AA23: 0 | AC23: 6058.489 | AE23: 0 | AG23: 0 | AI23: 0 | AK23: 11.717 | AM23: trucks | AN23: =AK23/SUM($AK$23:$AK$26)*100 -> 0.19772237 | AO23: =Q23/SUM($Q$23:$Q$26)*100 -> 48.445294 | AP23: =M23/SUM($M$23:$M$26)*100 -> 0.015938225 | AQ23: =E23/SUM($E$23:$E$26)*100 -> 57.136248 | AR23: =I23/SUM($I$23:$I$26)*100 -> 0.68446414
A24: Total | B24: Final consumption - transport sector - road - public - energy use | C24: 0 | E24: 524.832 | G24: 4163.611 | H24: p | I24: 0.05 | K24: 0 | M24: 163.214 | O24: 0 | Q24: 3735.538 | S24: 0 | U24: 275.964 | W24: 0 | Y24: 11.156 | AA24: 0 | AC24: 264.809 | AE24: 0 | AG24: 0 | AI24: 0 | AK24: 512.394 | AM24: busses | AN24: =AK24/SUM($AK$23:$AK$26)*100 -> 8.6465611 | AO24: =Q24/SUM($Q$23:$Q$26)*100 -> 2.1174833 | AP24: =M24/SUM($M$23:$M$26)*100 -> 0.10611656 | AQ24: =E24/SUM($E$23:$E$26)*100 -> 20.301 | AR24: =I24/SUM($I$23:$I$26)*100 -> 0.00095997776
A25: Total | B25: Final consumption - transport sector - road - cars and vans - energy use | C25: 0 | E25: 583.304 | G25: 248184.41 | H25: p | I25: 5172.753 | K25: 0 | M25: 149636.46 | O25: 0 | Q25: 87194.085 | S25: 0 | U25: 16408.598 | W25: 0 | Y25: 10227.487 | AA25: 0 | AC25: 6181.112 | AE25: 0 | AG25: 0 | AI25: 0 | AK25: 5336.101 | AM25: cars and vans | AN25: =AK25/SUM($AK$23:$AK$26)*100 -> 90.045792 | AO25: =Q25/SUM($Q$23:$Q$26)*100 -> 49.425817 | AP25: =M25/SUM($M$23:$M$26)*100 -> 97.288875 | AQ25: =E25/SUM($E$23:$E$26)*100 -> 22.562752 | AR25: =I25/SUM($I$23:$I$26)*100 -> 99.314557
A26: Total | B26: Final consumption - transport sector - road - other - energy use | C26: 0 | E26: 0 | G26: 4003.704 | H26: p | I26: 0.001 | K26: 0 | M26: 3982.154 | O26: 0 | Q26: 20.122 | S26: 0 | U26: 273.603 | W26: 0 | Y26: 272.176 | AA26: 0 | AC26: 1.427 | AE26: 0 | AG26: 0 | AI26: 0 | AK26: 65.774 | AM26: motorcycles and bicycles | AN26: =AK26/SUM($AK$23:$AK$26)*100 -> 1.109925 | AO26: =Q26/SUM($Q$23:$Q$26)*100 -> 0.011406121 | AP26: =M26/SUM($M$23:$M$26)*100 -> 2.5890701 | AQ26: =E26/SUM($E$23:$E$26)*100 -> 0 | AR26: =I26/SUM($I$23:$I$26)*100 -> 1.9199555e-05
A27: Total | B27: Final consumption - transport sector - road - other - 2-wheeled vehicles - energy use | C27: 0 | E27: 0 | G27: 4003.704 | H27: p | I27: 0.001 | K27: 0 | M27: 3982.154 | O27: 0 | Q27: 20.122 | S27: 0 | U27: 273.603 | W27: 0 | Y27: 272.176 | AA27: 0 | AC27: 1.427 | AE27: 0 | AG27: 0 | AI27: 0 | AK27: 65.774
A28: Total | B28: Final consumption - transport sector - aviation - energy use | C28: 0 | E28: 0 | G28: 0 | H28: p | I28: 0 | K28: 0 | M28: 0 | O28: 0 | Q28: 0 | S28: 0 | U28: 0 | W28: 0 | Y28: 0 | AA28: 0 | AC28: 0 | AE28: 0 | AG28: 0 | AI28: 0 | AK28: 0 | AM28: cars | AN28: =AR77/(AR77+AR78)*AN25 -> 86.424805 | AO28: =AV35/(AV35+AV36)*AO25 -> 19.777333 | AP28: =AU35/(AU35+AU36)*AP25 -> 96.857162 | AR28: =AW35/(AW35+AW36)*AR25 -> 70.775225
A29: Total | B29: Final consumption - transport sector - domestic aviation - energy use | C29: 0 | E29: 0 | G29: 0 | H29: p | I29: 0 | K29: 0 | M29: 0 | O29: 0 | Q29: 0 | S29: 0 | U29: 0 | W29: 0 | Y29: 0 | AA29: 0 | AC29: 0 | AE29: 0 | AG29: 0 | AI29: 0 | AK29: 0 | AM29: vans | AN29: =AR78/(AR78+AR77)*AN25 -> 3.6209867 | AO29: =AV36/(AV36+AV35)*AO25 -> 29.648484 | AP29: =AU36/(AU36+AU35)*AP25 -> 0.43171341 | AR29: =AW36/(AW36+AW35)*AR25 -> 28.539332
A30: Total | B30: Final consumption - transport sector - international aviation - energy use | C30: 0 | E30: 0 | G30: 0 | H30: p | I30: 0 | K30: 0 | M30: 0 | O30: 0 | Q30: 0 | S30: 0 | U30: 0 | W30: 0 | Y30: 0 | AA30: 0 | AC30: 0 | AE30: 0 | AG30: 0 | AI30: 0 | AK30: 0
A31: Total | B31: Final consumption - transport sector - domestic navigation - energy use | C31: 0 | E31: 0 | G31: 0 | H31: p | I31: 0 | K31: 0 | M31: 0 | O31: 0 | Q31: 0 | S31: 0 | U31: 0 | W31: 0 | Y31: 0 | AA31: 0 | AC31: 0 | AE31: 0 | AG31: 0 | AI31: 0 | AK31: 0 | AN31: diesel | AO31: electricity
A32: Total | B32: Final consumption - transport sector - domestic navigation - maritime - energy use | C32: 0 | E32: 0 | G32: 0 | H32: p | I32: 0 | K32: 0 | M32: 0 | O32: 0 | Q32: 0 | S32: 0 | U32: 0 | W32: 0 | Y32: 0 | AA32: 0 | AC32: 0 | AE32: 0 | AG32: 0 | AI32: 0 | AK32: 0 | AM32: rail passengers | AN32: =G36/(G36+G58)*100 -> 48.183768 | AO32: =(AK13+AK36)/AK12*100 -> 82.045239
A33: Total | B33: Final consumption - transport sector - domestic navigation - inland waterways - energy use | C33: 0 | E33: 0 | G33: 0 | H33: p | I33: 0 | K33: 0 | M33: 0 | O33: 0 | Q33: 0 | S33: 0 | U33: 0 | W33: 0 | Y33: 0 | AA33: 0 | AC33: 0 | AE33: 0 | AG33: 0 | AI33: 0 | AK33: 0 | AM33: rail freight | AN33: =G58/(G58+G36)*100 -> 51.816232 | AO33: =AK58/AK12*100 -> 10.175932 | AS33: emissieregistratie (Kyra)
A34: Passenger | B34: Final consumption - transport sector - rail - energy use | C34: : | E34: : | G34: : | I34: : | K34: : | M34: : | O34: : | Q34: : | S34: : | U34: : | W34: : | Y34: : | AA34: : | AC34: : | AE34: : | AG34: : | AI34: : | AK34: : | AM34: metro tram | AO34: =AK15/AK12*100 -> 7.7788129 | AT34: electricity | AU34: gasoline | AV34: diesel | AW34: lpg
A35: Passenger | B35: Final consumption - transport sector - rail - high speed - energy use | C35: : | E35: : | G35: : | I35: : | K35: : | M35: : | O35: : | Q35: : | S35: : | U35: : | W35: : | Y35: : | AA35: : | AC35: : | AE35: : | AG35: : | AI35: : | AK35: : | AS35: cars | AU35: 12870250000 | AV35: 2542692000 | AW35: 224099100
A36: Passenger | B36: Final consumption - transport sector - rail - conventional - energy use | C36: 0 | E36: 0 | G36: 427.364 | H36: p | I36: 0 | K36: 0 | M36: 0 | O36: 0 | Q36: 0 | S36: 0 | U36: 0.733 | W36: 0 | Y36: 0 | AA36: 0 | AC36: 0 | AE36: 0 | AG36: 0 | AI36: 0 | AK36: 4803.116 | AS36: vans | AU36: 57365500 | AV36: 3811786000 | AW36: 90365500
A37: Passenger | B37: Final consumption - transport sector - rail - metro and tram - energy use | C37: : | E37: : | G37: : | I37: : | K37: : | M37: : | O37: : | Q37: : | S37: : | U37: : | W37: : | Y37: : | AA37: : | AC37: : | AE37: : | AG37: : | AI37: : | AK37: : | AM37: fietskilometers in mln | AN37: 18200
A38: Passenger | B38: Final consumption - transport sector - road - fuel used | C38: : | E38: : | G38: : | I38: : | K38: : | M38: : | O38: : | Q38: : | S38: : | U38: : | W38: : | Y38: : | AA38: : | AC38: : | AE38: : | AG38: : | AI38: : | AK38: :
A39: Passenger | B39: Final consumption - transport sector - road - heavy-duty vehicles - fuel used | C39: : | E39: : | G39: : | I39: : | K39: : | M39: : | O39: : | Q39: : | S39: : | U39: : | W39: : | Y39: : | AA39: : | AC39: : | AE39: : | AG39: : | AI39: : | AK39: :
A40: Passenger | B40: Final consumption - transport sector - road - public - fuel used | C40: : | E40: : | G40: : | I40: : | K40: : | M40: : | O40: : | Q40: : | S40: : | U40: : | W40: : | Y40: : | AA40: : | AC40: : | AE40: : | AG40: : | AI40: : | AK40: :
A41: Passenger | B41: Final consumption - transport sector - road - cars and vans - fuel used | C41: 0 | E41: 0 | G41: 0 | H41: p | I41: 0 | K41: 0 | M41: 0 | O41: 0 | Q41: 0 | S41: 0 | U41: 0 | W41: 0 | Y41: 0 | AA41: 0 | AC41: 0 | AE41: 0 | AG41: 0 | AI41: 0 | AK41: 0
A42: Passenger | B42: Final consumption - transport sector - road - other - fuel used | C42: : | E42: : | G42: : | I42: : | K42: : | M42: : | O42: : | Q42: : | S42: : | U42: : | W42: : | Y42: : | AA42: : | AC42: : | AE42: : | AG42: : | AI42: : | AK42: :
...

Sheet Datadump - Emissieregistratie
A3: Road transport fuels analysis
B5: Input | G5: Calculations | M5: Output
B7: Road type combined CO2 emissions (2023) | C7: Value (kg) | D7: Old value (2019) | E7: Comment | G7: (1) | H7: application type combined CO2 emissions | I7: Value (tonne) | J7: Old value (2019) | K7: Comment | M7: (1) | N7: Share LNG and CNG | O7: Value (%) | P7: Old value (2019) | Q7: Comment
A8: Cars | B8: tp_car_gasoline_co2 | C8: =SUMIF('Datadump - road fuels'!$AR$4:$AR$73,_xlfn.CONCAT($B8,"*"),'Datadump - road fuels'!$AQ$4:$AQ$73) -> 12870250000 | D8: 13380790000 | H8: tp_car_gasoline_co2 | I8: =C8*0.001 -> 12870250 | J8: 13380790 | N8: share_lng_total_ng | P8: 0.002962963
B9: tp_car_diesel_co2 | C9: =SUMIF('Datadump - road fuels'!$AR$4:$AR$73,_xlfn.CONCAT($B9,"*"),'Datadump - road fuels'!$AQ$4:$AQ$73) -> 2542692000 | D9: 4905092000 | H9: tp_car_diesel_co2 | I9: =C9*0.001 -> 2542692 | J9: 4905092 | N9: share_cng_total_ng | P9: 0.99703704
B10: tp_car_lpg_co2 | C10: =SUMIF('Datadump - road fuels'!$AR$4:$AR$73,_xlfn.CONCAT($B10,"*"),'Datadump - road fuels'!$AQ$4:$AQ$73) -> 224099100 | D10: 310594800 | H10: tp_car_lpg_co2 | I10: =C10*0.001 -> 224099.1 | J10: 310594.8
A11: Vans | B11: tp_van_gasoline_co2 | C11: =SUMIF('Datadump - road fuels'!$AR$4:$AR$73,_xlfn.CONCAT($B11,"*"),'Datadump - road fuels'!$AQ$4:$AQ$73) -> 57365500 | D11: 33927760 | H11: tp_van_gasoline_co2 | I11: =C11*0.001 -> 57365.5 | J11: 33927.76 | M11: (2) | N11: Share of application per fuel type | O11: Value (%) | P11: Old value (2019) | Q11: Comment
B12: tp_van_diesel_co2 | C12: =SUMIF('Datadump - road fuels'!$AR$4:$AR$73,_xlfn.CONCAT($B12,"*"),'Datadump - road fuels'!$AQ$4:$AQ$73) -> 3811786000 | D12: 3700794000 | H12: tp_van_diesel_co2 | I12: =C12*0.001 -> 3811786 | J12: 3700794 | N12: gasoline_mix_share_cars | O12: =I8/I24 -> 0.97033632 | P12: 0.96255621
B13: tp_van_lpg_co2 | C13: =SUMIF('Datadump - road fuels'!$AR$4:$AR$73,_xlfn.CONCAT($B13,"*"),'Datadump - road fuels'!$AQ$4:$AQ$73) -> 90365500 | D13: 53079900 | H13: tp_van_lpg_co2 | I13: =C13*0.001 -> 90365.5 | J13: 53079.9 | N13: gasoline_mix_share_trucks | O13: =I14/I24 -> 0.00030637605 | P13: 0
A14: Trucks | B14: tp_truck_gasoline_co2 | C14: =SUMIF('Datadump - road fuels'!$AR$4:$AR$73,_xlfn.CONCAT($B14,"*"),'Datadump - road fuels'!$AQ$4:$AQ$73) -> 4063680 | D14: 6388474000 | H14: tp_truck_gasoline_co2 | I14: =C14*0.001 -> 4063.68 | J14: 6388474 | N14: gasoline_mix_share_buses | O14: =I18/I24 -> 0.00097654915 | P14: 0.00014845093
B15: tp_truck_diesel_co2 | C15: =SUMIF('Datadump - road fuels'!$AR$4:$AR$73,_xlfn.CONCAT($B15,"*"),'Datadump - road fuels'!$AQ$4:$AQ$73) -> 6430257000 | H15: tp_truck_diesel_co2 | I15: =C15*0.001 -> 6430257 | N15: gasoline_mix_share_motorcycles | O15: =I17/I24 -> 0.024055753 | P15: 0.034854722
B16: tp_truck_lpg_co2 | C16: =SUMIF('Datadump - road fuels'!$AR$4:$AR$73,_xlfn.CONCAT($B16,"*"),'Datadump - road fuels'!$AQ$4:$AQ$73) -> 96211300 | H16: tp_truck_lpg_co2 | I16: =C16*0.001 -> 96211.3 | N16: gasoline_mix_share_vans | O16: =I11/I24 -> 0.0043249998 | P16: 0.0024406164
A17: Motorcycle | B17: tp_motorcycle_co2 | C17: =SUMIF('Datadump - road fuels'!$AR$4:$AR$73,_xlfn.CONCAT($B17,"*"),'Datadump - road fuels'!$AQ$4:$AQ$73) -> 257530500 | D17: 300991100 | H17: tp_motorcycle_gasoline_co2 | I17: =SUM(C17:C19)*0.001 -> 319068.29 | J17: 484526.22 | K17: Kyra de Haan | N17: diesel_mix_share_cars | O17: =I9/I25 -> 0.19484285 | P17: 0.26059226
A18: Moped | B18: tp_moped_co2 | C18: =SUMIF('Datadump - road fuels'!$AR$4:$AR$73,_xlfn.CONCAT($B18,"*"),'Datadump - road fuels'!$AQ$4:$AQ$73) -> 59956600 | D18: 174521500 | H18: tp_bus_gasoline_co2 | I18: =(C20+C23)*0.001 -> 12952.655 | J18: 478752.94 | K18: Combination of touring cars and public transport buses | N18: diesel_mix_share_trucks | O18: =I15/I25 -> 0.4927414 | P18: 0.51736143 | Q18: tp_mm_diesel used to take part in here - but there is no value in this dataset.
A19: Quadricycle | B19: tp_quadricycle_co2 | C19: =SUMIF('Datadump - road fuels'!$AR$4:$AR$73,_xlfn.CONCAT($B19,"*"),'Datadump - road fuels'!$AQ$4:$AQ$73) -> 1581194 | D19: 9013620 | H19: tp_bus_diesel_co2 | I19: =(C21+C24)*0.001 -> 265227.91 | J19: 41338.268 | K19: Combination of touring cars and public transport buses | N19: diesel_mix_share_vans | O19: =I12/I25 -> 0.29209171 | P19: 0.19661166
A20: Bus touring car | B20: tp_bus_tc_gasoline_co2 | C20: =SUMIF('Datadump - road fuels'!$AR$4:$AR$73,_xlfn.CONCAT($B20,"*"),'Datadump - road fuels'!$AQ$4:$AQ$73) -> 340678.1 | H20: tp_bus_lpg_co2 | I20: =(C22+C25)*0.001 -> 34345.693 | J20: 2063.6621 | K20: Combination of touring cars and public transport buses | N20: diesel_mix_share_buses | O20: =I19/I25 -> 0.020324036 | P20: 0.025434652
B21: tp_bus_tc_diesel_co2 | C21: =SUMIF('Datadump - road fuels'!$AR$4:$AR$73,_xlfn.CONCAT($B21,"*"),'Datadump - road fuels'!$AQ$4:$AQ$73) -> 61348700 | D21: 104463300 | H21: tp_mm_diesel_co2 | J21: 3349748.7 | N21: lpg_mix_share_cars | O21: =I10/I26 -> 0.50356905 | P21: 0.85404566
B22: tp_bus_tc_lpg_co2 | C22: =SUMIF('Datadump - road fuels'!$AR$4:$AR$73,_xlfn.CONCAT($B22,"*"),'Datadump - road fuels'!$AQ$4:$AQ$73) -> 40687.96 | N22: lpg_mix_share_trucks | O22: =I16/I26 -> 0.21619468
A23: Bus OV | B23: tp_bus_ov_gasoline_co2 | C23: =SUMIF('Datadump - road fuels'!$AR$4:$AR$73,_xlfn.CONCAT($B23,"*"),'Datadump - road fuels'!$AQ$4:$AQ$73) -> 12611977 | G23: (2) | H23: total CO2 emissions per fuel type | I23: Value (tonne) | J23: Old value (2019) | K23: Comment | N23: lpg_mix_share_buses | O23: =I20/I26 -> 0.077177588
B24: tp_bus_ov_diesel_co2 | C24: =SUMIF('Datadump - road fuels'!$AR$4:$AR$73,_xlfn.CONCAT($B24,"*"),'Datadump - road fuels'!$AQ$4:$AQ$73) -> 203879210 | D24: 374289640 | H24: gasoline_co2_total | I24: =I8+I11+I14+I17+I18 -> 13263700 | J24: 13901308 | K24: assumed that all applications of a specific fuel use the same fuel mix, with the same energy content and emission factor | N24: lpg_mix_share_vans | O24: =I13/I26 -> 0.20305869 | P24: 0.14595434
B25: tp_bus_ov_lpg_co2 | C25: =SUMIF('Datadump - road fuels'!$AR$4:$AR$73,_xlfn.CONCAT($B25,"*"),'Datadump - road fuels'!$AQ$4:$AQ$73) -> 34305005 | H25: diesel_co2_total | I25: =I9+I12+I15+I19 -> 13049963 | J25: 18822862 | K25: assumed that all applications of a specific fuel use the same fuel mix, with the same energy content and emission factor | N25: lng_share_trucks | P25: 0
A26: Mobile machine sectors | B26: tp_mm_diesel_co2 | E26: No values in new dataset | H26: lpg_co2_total | I26: =I10+I13+I16+I20 -> 445021.59 | J26: 363674.7 | K26: assumed that all applications of a specific fuel use the same fuel mix, with the same energy content and emission factor | N26: lng_share_buses | P26: 1
N27: cng_share_cars | P27: 0
N28: cng_share_trucks | P28: 0
N29: cng_share_buses | P29: 1
N30: cng_share_vans | P30: 0
A33: Results | B33: Use in transport analysis | D33: Share (%) | E33: Old value (2019)
B34: Percentage of gasoline mix delivered to cars | C34: Share | D34: =O12 -> 0.97033632 | E34: 0.96255621
B35: Percentage of gasoline mix delivered to trucks | C35: Share | D35: =O13 -> 0.00030637605 | E35: 0
B36: Percentage of gasoline mix delivered to vans | C36: Share | D36: =O16 -> 0.0043249998 | E36: 0.0024406164
B37: Percentage of gasoline mix delivered to buses | C37: Share | D37: =O14 -> 0.00097654915 | E37: 0.00014845093
B38: Percentage of gasoline mix delivered to motorcycles | C38: Share | D38: =O15 -> 0.024055753 | E38: 0.034854722
B40: Percentage of diesel mix delivered to cars | C40: Share | D40: =O17 -> 0.19484285 | E40: 0.26059226
B41: Percentage of diesel mix delivered to trucks | C41: Share | D41: =O18 -> 0.4927414 | E41: 0.51736143
B42: Percentage of diesel mix delivered to vans | C42: Share | D42: =O19 -> 0.29209171 | E42: 0.19661166
B43: Percentage of diesel mix delivered to buses | C43: Share | D43: =O20 -> 0.020324036 | E43: 0.025434652
B45: Percentage of LPG delivered to cars | C45: Share | D45: =O21 -> 0.50356905 | E45: 0.85404566
B46: Percentage of LPG delivered to vans | C46: Share | D46: =O24 -> 0.20305869 | E46: 0.14595434
B47: Percentage of LPG delivered to trucks | C47: Share | D47: =O22 -> 0.21619468
B48: Percentage of LPG delivered to buses | C48: Share | D48: =O23 -> 0.077177588

Sheet Datadump - road E and H2
A1: Code | C1: 2023 | D1: Beschrijving | E1: variable for calculations
A2: wpelek | B2: Elektrische personenauto's (BEV), geregistreerd bij eigenaar | C2: 442409 | E2: tp_car_bev_nr
A3: wbelek | B3: Elektrische bussen, geregistreerd bij eigenaar | C3: 1554 | E3: tp_bus_bev_nr
A4: wb23whelek | B4: Elektrische twee- en driewielige voertuigen, geregistreerd bij eigenaar | C4: 149067 | D4: driewielig motorvoertuig + trike + light moped 25 + light moped 45 + speedpedelec + motorfiets | E4: tp_motorcycle_bev_nr
A5: wb4whelek | B5: Elektrische vierwielige light voertuigen (quadricycle en microcar), geregistreerd bij eigenaar | C5: 6753 | D5: Quadricycle + microcar | E5: tp_quadricycle_bev_nr
A6: wpphev | B6: Plug-in hybride personenauto's (PHEV), geregistreerd bij eigenaar | C6: 263387 | D6: was eerder 'rangeextend' | E6: tp_car_phev_nr
A7: wbzphev | B7: Plug-in hybride Zware bedrijfsauto (>= 3500 kg, PHEV), geregistreerd bij eigenaar | C7: 73 | E7: tp_truck_phev_nr
A8: wbusphev | B8: Plug-in hybride bussen (PHEV), geregistreerd bij eigenaar | C8: 97 | E8: tp_bus_phev_nr
A9: wpfcev | B9: Personenauto's op waterstof (FCEV), geregistreerd bij eigenaar | C9: 615 | E9: tp_car_fcev_nr
A10: wblfcev | B10: Lichte bedrijfsauto's op waterstof (<3500 kg, FCEV), geregistreerd bij eigenaar | C10: 13 | E10: tp_van_fcev_nr
A11: wbzfcev | B11: Zware bedrijfsauto's op waterstof (>= 3500 kg, FCEV), geregistreerd bij eigenaar | C11: 35 | E11: tp_truck_fcev_nr
A12: wbusfcev | B12: Bussen op waterstof (FCEV), geregistreerd bij eigenaar | C12: 64 | E12: tp_bus_fcev_nr
A13: wblelek | B13: Lichte elektrische bedrijfsauto's (< 3500 kg), geregistreerd bij eigenaar | C13: 23555 | E13: tp_van_bev_nr
A14: wbzelek | B14: Zware elektrische bedrijfsauto's (>= 3500 kg), geregistreerd bij eigenaar | C14: 1459 | E14: tp_truck_bev_nr
A15: wblphev | B15: Plug-in hybride lichte bedrijfsauto (<3500 kg, PHEV), geregistreerd bij eigenaar | C15: 155 | E15: tp_van_phev_nr
A16: wbfsped | B16: Speed pedelecs, geregistreerd bij eigenaar | C16: 34042 | E16: tp_pedelec_bev_nr
B19: Eenheid | C19: aantal
B20: Bron | C20: RVO - Monitoring elektrisch vervoer o.b.v. gegevens RDW
B22: klimaatmonitor.databank.nl

Sheet Datadump - road fuels
A1: Full dataset from emissieregistratie.nl is not available anymore. Emissieregistratie has been contacted and full dataset has been provided over email (Claudia). Units have not been provided, but seems like 'kg'.
A3: EMISSIEBRON | B3: TYPE_DATASET | C3: DATASET | D3: EMISSIEOORZAAK | E3: LOCATIE | F3: GEPRESENTEERDE_STOF | G3: COMPARTIMENT | H3: SOORTEN_EMISSIES | I3: EVE_NAAM | J3: 1990 | K3: 1991 | L3: 1992 | M3: 1993 | N3: 1994 | O3: 1995 | P3: 1996 | Q3: 1997 | R3: 1998 | S3: 1999 | T3: 2000 | U3: 2001 | V3: 2002 | W3: 2003 | X3: 2004 | Y3: 2005 | Z3: 2006 | AA3: 2007 | AB3: 2008 | AC3: 2009 | AD3: 2010 | AE3: 2011 | AF3: 2012 | AG3: 2013 | AH3: 2014 | AI3: 2015 | AJ3: 2016 | AK3: 2017 | AL3: 2018 | AM3: 2019 | AN3: 2020 | AO3: 2021 | AP3: 2022 | AQ3: 2023 | AR3: variable for calculation | AT3: comment
A4: Uitlaatgassen autobussen touringcars, bebouwde kom:diesel | B4: ER | C4: ER Reeks 1990-2023 Definitief (open) | D4: Uitlaatgassen autobussen touringcars | E4: bebouwde kom | F4: Koolstofdioxide | G4: Lucht | H4: Verbranding,Verbranding verkeer,Verbranding kort cyclisch,Proces,Proces feedstock,Proces biogeen | I4: diesel | J4: 26020500 | K4: 23940800 | L4: 23907700 | M4: 21092900 | N4: 20214200 | O4: 26236800 | P4: 25655000 | Q4: 23026100 | R4: 26022900 | S4: 28035500 | T4: 31683900 | U4: 33017900 | V4: 30152600 | W4: 27735500 | X4: 27593600 | Y4: 26354500 | Z4: 25572800 | AA4: 25299900 | AB4: 25112000 | AC4: 23851400 | AD4: 22789600 | AE4: 22294000 | AF4: 22743400 | AG4: 20826300 | AH4: 20787500 | AI4: 21274300 | AJ4: 21732200 | AK4: 23320800 | AL4: 24240400 | AM4: 22307000 | AN4: 8613640 | AO4: 9448210 | AP4: 13541400 | AQ4: 14867400 | AR4: tp_bus_tc_diesel_co2_built_env
A5: Uitlaatgassen zware bedrijfsvoertuigen excl. autobussen, buitenweg:Ureum | B5: ER | C5: ER Reeks 1990-2023 Definitief (open) | D5: Uitlaatgassen zware bedrijfsvoertuigen excl. autobussen | E5: buitenweg | F5: Koolstofdioxide | G5: Lucht | H5: Verbranding,Verbranding verkeer,Verbranding kort cyclisch,Proces,Proces feedstock,Proces biogeen | I5: Ureum | Y5: 627713 | Z5: 1285900 | AA5: 1977700 | AB5: 2700320 | AC5: 3315850 | AD5: 3716590 | AE5: 4116350 | AF5: 4454710 | AG5: 4496370 | AH5: 4731330 | AI5: 5166740 | AJ5: 5670290 | AK5: 5911920 | AL5: 6097680 | AM5: 6320530 | AN5: 6457160 | AO5: 6640590 | AP5: 6920410 | AQ5: 6810970
A6: Uitlaatgassen lichte bedrijfsvoertuigen, bebouwde kom:diesel | B6: ER | C6: ER Reeks 1990-2023 Definitief (open) | D6: Uitlaatgassen lichte bedrijfsvoertuigen | E6: bebouwde kom | F6: Koolstofdioxide | G6: Lucht | H6: Verbranding,Verbranding verkeer,Verbranding kort cyclisch,Proces,Proces feedstock,Proces biogeen | I6: diesel | J6: 883031000 | K6: 872876000 | L6: 918402000 | M6: 952115000 | N6: 914909000 | O6: 857742000 | P6: 822701000 | Q6: 805934000 | R6: 790248000 | S6: 763922000 | T6: 658337000 | U6: 723197000 | V6: 741851000 | W6: 767594000 | X6: 803210000 | Y6: 751676000 | Z6: 676046000 | AA6: 639009000 | AB6: 600069000 | AC6: 537002000 | AD6: 549677000 | AE6: 552517000 | AF6: 551403000 | AG6: 550646000 | AH6: 558897000 | AI6: 572314000 | AJ6: 593181000 | AK6: 612411000 | AL6: 644939000 | AM6: 660282000 | AN6: 640547000 | AO6: 667190000 | AP6: 676212000 | AQ6: 675986000 | AR6: tp_van_diesel_co2_built_env
A7: Uitlaatgassen lichte bedrijfsvoertuigen, autosnelweg:lpg | B7: ER | C7: ER Reeks 1990-2023 Definitief (open) | D7: Uitlaatgassen lichte bedrijfsvoertuigen | E7: autosnelweg | F7: Koolstofdioxide | G7: Lucht | H7: Verbranding,Verbranding verkeer,Verbranding kort cyclisch,Proces,Proces feedstock,Proces biogeen | I7: lpg | J7: 15200800 | K7: 17051400 | L7: 19747700 | M7: 22730300 | N7: 24507800 | O7: 25935700 | P7: 28113100 | Q7: 31144400 | R7: 34795300 | S7: 39048400 | T7: 39561800 | U7: 38884900 | V7: 35555400 | W7: 32319100 | X7: 30225100 | Y7: 27970900 | Z7: 26983000 | AA7: 27256600 | AB7: 28956800 | AC7: 30190400 | AD7: 30287200 | AE7: 30908800 | AF7: 30404500 | AG7: 31226400 | AH7: 31241700 | AI7: 31267800 | AJ7: 31914600 | AK7: 35160400 | AL7: 36749200 | AM7: 40458600 | AN7: 39825900 | AO7: 41306100 | AP7: 43264300 | AQ7: 46112500 | AR7: tp_van_lpg_co2_motorway
A8: Uitlaatgassen autobussen ov, autosnelweg:Ureum | B8: ER | C8: ER Reeks 1990-2023 Definitief (open) | D8: Uitlaatgassen autobussen ov | E8: autosnelweg | F8: Koolstofdioxide | G8: Lucht | H8: Verbranding,Verbranding verkeer,Verbranding kort cyclisch,Proces,Proces feedstock,Proces biogeen | I8: Ureum | Y8: 4841.54 | Z8: 9561.88 | AA8: 15155.8 | AB8: 20861 | AC8: 27421.5 | AD8: 28391.6 | AE8: 25985.3 | AF8: 25928.7 | AG8: 25562.6 | AH8: 24232.6 | AI8: 24186.1 | AJ8: 23058.5 | AK8: 23926 | AL8: 23700.8 | AM8: 22220.4 | AN8: 18720.1 | AO8: 15846.7 | AP8: 14393.3 | AQ8: 13283.5
A9: Uitlaatgassen lichte bedrijfsvoertuigen, buitenweg:benzine | B9: ER | C9: ER Reeks 1990-2023 Definitief (open) | D9: Uitlaatgassen lichte bedrijfsvoertuigen | E9: buitenweg | F9: Koolstofdioxide | G9: Lucht | H9: Verbranding,Verbranding verkeer,Verbranding kort cyclisch,Proces,Proces feedstock,Proces biogeen | I9: benzine | J9: 76311100 | K9: 72902900 | L9: 74117600 | M9: 75075300 | N9: 70661400 | O9: 65363300 | P9: 61751500 | Q9: 59610800 | R9: 57324200 | S9: 53984600 | T9: 45244700 | U9: 35939300 | V9: 31032300 | W9: 26976900 | X9: 27083700 | Y9: 22079400 | Z9: 18431500 | AA9: 16205700 | AB9: 14568800 | AC9: 14078200 | AD9: 12913700 | AE9: 11314400 | AF9: 9448570 | AG9: 9119440 | AH9: 8715720 | AI9: 8226230 | AJ9: 8372470 | AK9: 8841480 | AL9: 9383680 | AM9: 10165600 | AN9: 10395300 | AO9: 12709000 | AP9: 14532000 | AQ9: 17040000 | AR9: tp_van_gasoline_co2_road
A10: Uitlaatgassen motorfietsen, bebouwde kom:verkeersprestatie | B10: ER | C10: ER Reeks 1990-2023 Definitief (open) | D10: Uitlaatgassen motorfietsen | E10: bebouwde kom | F10: Koolstofdioxide | G10: Lucht | H10: Verbranding,Verbranding verkeer,Verbranding kort cyclisch,Proces,Proces feedstock,Proces biogeen | I10: verkeersprestatie | J10: 19101200 | K10: 22252500 | L10: 26669500 | M10: 30480000 | N10: 32815000 | O10: 34632900 | P10: 38464300 | Q10: 40096300 | R10: 41567900 | S10: 43390400 | T10: 45526000 | U10: 47526400 | V10: 50490600 | W10: 52173900 | X10: 53524700 | Y10: 54361400 | Z10: 54826600 | AA10: 55344200 | AB10: 56143700 | AC10: 56545200 | AD10: 56509700 | AE10: 55962300 | AF10: 55032100 | AG10: 53607800 | AH10: 52005600 | AI10: 50438500 | AJ10: 49964600 | AK10: 49839800 | AL10: 49789100 | AM10: 50353600 | AN10: 49967900 | AO10: 49717200 | AP10: 49306100 | AQ10: 48990600 | AR10: tp_motorcycle_co2_built_env
A11: Koelaggregaten zware bedrijfsvoertuigen excl. autobussen, buitenweg:diesel | B11: ER | C11: ER Reeks 1990-2023 Definitief (open) | D11: Koelaggregaten zware bedrijfsvoertuigen excl. autobussen | E11: buitenweg | F11: Koolstofdioxide | G11: Lucht | H11: Verbranding,Verbranding verkeer,Verbranding kort cyclisch,Proces,Proces feedstock,Proces biogeen | I11: diesel | J11: 35907100 | K11: 36958700 | L11: 37753100 | M11: 37495800 | N11: 37635700 | O11: 39224400 | P11: 40276000 | Q11: 40555900 | R11: 42144600 | S11: 43962600 | T11: 45205500 | U11: 45899200 | V11: 45999500 | W11: 45606400 | X11: 45580200 | Y11: 45579800 | Z11: 47500200 | AA11: 48285100 | AB11: 48948600 | AC11: 47319700 | AD11: 46686100 | AE11: 46276700 | AF11: 45563300 | AG11: 45860800 | AH11: 45790100 | AI11: 46465300 | AJ11: 47796500 | AK11: 49597300 | AL11: 51161800 | AM11: 53000500 | AN11: 53342200 | AO11: 54586700 | AP11: 56013700 | AQ11: 58131500
A12: Uitlaatgassen lichte bedrijfsvoertuigen, autosnelweg:Ureum | B12: ER | C12: ER Reeks 1990-2023 Definitief (open) | D12: Uitlaatgassen lichte bedrijfsvoertuigen | E12: autosnelweg | F12: Koolstofdioxide | G12: Lucht | H12: Verbranding,Verbranding verkeer,Verbranding kort cyclisch,Proces,Proces feedstock,Proces biogeen | I12: Ureum | Y12: 568.732 | Z12: 1118.19 | AA12: 1724.26 | AB12: 2365.07 | AC12: 2915.84 | AD12: 9815.6 | AE12: 14899.4 | AF12: 26057.2 | AG12: 34605.2 | AH12: 37708.6 | AI12: 46007.9 | AJ12: 56239.2 | AK12: 61421.3 | AL12: 47626.1 | AM12: 53939.1 | AN12: 125380 | AO12: 425935 | AP12: 1088190 | AQ12: 2048210
A13: Uitlaatgassen brommobielen, bebouwde kom:verkeersprestatie | B13: ER | C13: ER Reeks 1990-2023 Definitief (open) | D13: Uitlaatgassen brommobielen | E13: bebouwde kom | F13: Koolstofdioxide | G13: Lucht | H13: Verbranding,Verbranding verkeer,Verbranding kort cyclisch,Proces,Proces feedstock,Proces biogeen | I13: verkeersprestatie | O13: 35173.5 | P13: 75757.2 | Q13: 190121 | R13: 301021 | S13: 406136 | T13: 497394 | U13: 579701 | V13: 673778 | W13: 705864 | X13: 729020 | Y13: 744787 | Z13: 760445 | AA13: 764473 | AB13: 877904 | AC13: 955120 | AD13: 1148460 | AE13: 1139210 | AF13: 1108880 | AG13: 1059330 | AH13: 1034550 | AI13: 980983 | AJ13: 933396 | AK13: 910921 | AL13: 885435 | AM13: 857280 | AN13: 835579 | AO13: 841313 | AP13: 846858 | AQ13: 833179 | AR13: tp_quadricycle_co2_built_env
A14: Uitlaatgassen autobussen ov, autosnelweg:diesel | B14: ER | C14: ER Reeks 1990-2023 Definitief (open) | D14: Uitlaatgassen autobussen ov | E14: autosnelweg | F14: Koolstofdioxide | G14: Lucht | H14: Verbranding,Verbranding verkeer,Verbranding kort cyclisch,Proces,Proces feedstock,Proces biogeen | I14: diesel | J14: 8227690 | K14: 8442860 | L14: 8379230 | M14: 8622150 | N14: 8745960 | O14: 8496400 | P14: 8521620 | Q14: 8336750 | R14: 7978400 | S14: 7687820 | T14: 7398040 | U14: 7011600 | V14: 7408240 | W14: 7250290 | X14: 6949640 | Y14: 6529790 | Z14: 6393650 | AA14: 6699550 | AB14: 6865440 | AC14: 7157320 | AD14: 7143370 | AE14: 7081030 | AF14: 6673110 | AG14: 6576050 | AH14: 6157010 | AI14: 6081730 | AJ14: 5704360 | AK14: 6024180 | AL14: 5937090 | AM14: 5535670 | AN14: 4646330 | AO14: 3792830 | AP14: 3355080 | AQ14: 3114310 | AR14: tp_bus_ov_diesel_co2_motorway
A15: Uitlaatgassen autobussen ov, bebouwde kom:lpg | B15: ER | C15: ER Reeks 1990-2023 Definitief (open) | D15: Uitlaatgassen autobussen ov | E15: bebouwde kom | F15: Koolstofdioxide | G15: Lucht | H15: Verbranding,Verbranding verkeer,Verbranding kort cyclisch,Proces,Proces feedstock,Proces biogeen | I15: lpg | J15: 0 | K15: 0 | L15: 0 | M15: 0 | N15: 0 | O15: 0 | P15: 0 | Q15: 0 | R15: 0 | S15: 0 | T15: 0 | U15: 0 | V15: 52330.9 | W15: 0 | X15: 0 | Y15: 3623330 | Z15: 6861670 | AA15: 7122070 | AB15: 9967820 | AC15: 16501700 | AD15: 27959100 | AE15: 30749000 | AF15: 31106800 | AG15: 41218500 | AH15: 39099100 | AI15: 35356900 | AJ15: 34616300 | AK15: 34027400 | AL15: 33080700 | AM15: 32991800 | AN15: 26037000 | AO15: 28926700 | AP15: 27651300 | AQ15: 26168800 | AR15: tp_bus_ov_lpg_co2_built_env
A16: Uitlaatgassen personenauto's, bebouwde kom:Ureum | B16: ER | C16: ER Reeks 1990-2023 Definitief (open) | D16: Uitlaatgassen personenauto's | E16: bebouwde kom | F16: Koolstofdioxide | G16: Lucht | H16: Verbranding,Verbranding verkeer,Verbranding kort cyclisch,Proces,Proces feedstock,Proces biogeen | I16: Ureum | Y16: 0 | Z16: 0 | AA16: 0 | AB16: 0 | AC16: 0 | AD16: 0 | AE16: 0 | AF16: 0 | AG16: 0 | AH16: 0 | AI16: 0 | AJ16: 0 | AK16: 0 | AL16: 0 | AM16: 690.004 | AN16: 8933.19 | AO16: 32799.4 | AP16: 65182.4 | AQ16: 99724.5
A17: Uitlaatgassen lichte bedrijfsvoertuigen, bebouwde kom:benzine | B17: ER | C17: ER Reeks 1990-2023 Definitief (open) | D17: Uitlaatgassen lichte bedrijfsvoertuigen | E17: bebouwde kom | F17: Koolstofdioxide | G17: Lucht | H17: Verbranding,Verbranding verkeer,Verbranding kort cyclisch,Proces,Proces feedstock,Proces biogeen | I17: benzine | J17: 308846000 | K17: 276592000 | L17: 257586000 | M17: 241228000 | N17: 206745000 | O17: 172487000 | P17: 145170000 | Q17: 122909000 | R17: 101591000 | S17: 79913700 | T17: 53744400 | U17: 40842600 | V17: 35196100 | W17: 30685800 | X17: 30683400 | Y17: 23272700 | Z17: 18036000 | AA17: 14686100 | AB17: 12194100 | AC17: 10851300 | AD17: 10039300 | AE17: 8886970 | AF17: 7524940 | AG17: 7357190 | AH17: 7098710 | AI17: 6748630 | AJ17: 6874420 | AK17: 7224190 | AL17: 7620180 | AM17: 8327040 | AN17: 8645810 | AO17: 10797200 | AP17: 12697300 | AQ17: 15371300 | AR17: tp_van_gasoline_co2_built_env
A18: Uitlaatgassen zware bedrijfsvoertuigen excl. autobussen, bebouwde kom:Ureum | B18: ER | C18: ER Reeks 1990-2023 Definitief (open) | D18: Uitlaatgassen zware bedrijfsvoertuigen excl. autobussen | E18: bebouwde kom | F18: Koolstofdioxide | G18: Lucht | H18: Verbranding,Verbranding verkeer,Verbranding kort cyclisch,Proces,Proces feedstock,Proces biogeen | I18: Ureum | Y18: 496378 | Z18: 981847 | AA18: 1449880 | AB18: 1892830 | AC18: 2210980 | AD18: 2396290 | AE18: 2608660 | AF18: 2764810 | AG18: 2694700 | AH18: 2686330 | AI18: 2813230 | AJ18: 2984510 | AK18: 2990810 | AL18: 3883240 | AM18: 4019570 | AN18: 4087330 | AO18: 4213850 | AP18: 4371020 | AQ18: 4316620
A19: Uitlaatgassen personenauto's, buitenweg:Ureum | B19: ER | C19: ER Reeks 1990-2023 Definitief (open) | D19: Uitlaatgassen personenauto's | E19: buitenweg | F19: Koolstofdioxide | G19: Lucht | H19: Verbranding,Verbranding verkeer,Verbranding kort cyclisch,Proces,Proces feedstock,Proces biogeen | I19: Ureum | Y19: 0 | Z19: 0 | AA19: 0 | AB19: 0 | AC19: 0 | AD19: 0 | AE19: 0 | AF19: 0 | AG19: 0 | AH19: 0 | AI19: 0 | AJ19: 0 | AK19: 0 | AL19: 0 | AM19: 715.097 | AN19: 15468.3 | AO19: 61532.3 | AP19: 127761 | AQ19: 196766
A20: Uitlaatgassen autobussen touringcars, buitenweg:benzine | B20: ER | C20: ER Reeks 1990-2023 Definitief (open) | D20: Uitlaatgassen autobussen touringcars | E20: buitenweg | F20: Koolstofdioxide | G20: Lucht | H20: Verbranding,Verbranding verkeer,Verbranding kort cyclisch,Proces,Proces feedstock,Proces biogeen | I20: benzine | J20: 58645.4 | K20: 30866 | L20: 30866 | M20: 30866 | N20: 37039.2 | O20: 23149.5 | P20: 21606.2 | Q20: 20062.9 | R20: 19291.3 | S20: 24692.8 | T20: 22377.9 | U20: 24692.8 | V20: 95546.1 | W20: 108607 | X20: 103019 | Y20: 11667.2 | Z20: 3218.3 | AA20: 9840.3 | AB20: 12158.7 | AC20: 6999.59 | AD20: 4303.07 | AE20: 6167.95 | AF20: 2315.77 | AG20: 4567.02 | AH20: 2398.67 | AI20: 257.597 | AJ20: 444.802 | AK20: 312.083 | AL20: 830.385 | AM20: 692.782 | AN20: 4543.27 | AO20: 116169 | AP20: 129052 | AQ20: 136263 | AR20: tp_bus_tc_gasoline_co2_road
A21: Uitlaatgassen bromfietsen, buitenweg:verkeersprestatie | B21: ER | C21: ER Reeks 1990-2023 Definitief (open) | D21: Uitlaatgassen bromfietsen | E21: buitenweg | F21: Koolstofdioxide | G21: Lucht | H21: Verbranding,Verbranding verkeer,Verbranding kort cyclisch,Proces,Proces feedstock,Proces biogeen | I21: verkeersprestatie | J21: 36936300 | K21: 37234500 | L21: 37103600 | M21: 36411100 | N21: 35988500 | O21: 35462000 | P21: 35011400 | Q21: 35042500 | R21: 34826800 | S21: 33841500 | T21: 32107300 | U21: 30667400 | V21: 28982300 | W21: 26916300 | X21: 22959700 | Y21: 22713100 | Z21: 22867200 | AA21: 24347100 | AB21: 26472500 | AC21: 29198800 | AD21: 26870200 | AE21: 27037500 | AF21: 26563700 | AG21: 25720500 | AH21: 25428800 | AI21: 24770800 | AJ21: 24366600 | AK21: 24788200 | AL21: 24266300 | AM21: 23135800 | AN21: 22153600 | AO21: 21514300 | AP21: 19999600 | AQ21: 18151100 | AR21: tp_moped_co2_road
