Workbook

Sheet air temperature 2023
A1: ='Comparison 2023 vs 2019'!A2 -> 15.5
A2: ='Comparison 2023 vs 2019'!A3 -> 15
A3: ='Comparison 2023 vs 2019'!A4 -> 14.9
A4: ='Comparison 2023 vs 2019'!A5 -> 13.9
A5: ='Comparison 2023 vs 2019'!A6 -> 13.1
A6: ='Comparison 2023 vs 2019'!A7 -> 12.9
A7: ='Comparison 2023 vs 2019'!A8 -> 12.5
A8: ='Comparison 2023 vs 2019'!A9 -> 11.6
A9: ='Comparison 2023 vs 2019'!A10 -> 11.5
A10: ='Comparison 2023 vs 2019'!A11 -> 12
A11: ='Comparison 2023 vs 2019'!A12 -> 12.8
A12: ='Comparison 2023 vs 2019'!A13 -> 12.3
... A8760: ='Comparison 2023 vs 2019'!A8761 -> 8.2

Sheet Comparison 2023 vs 2019
A1: 2023 | B1: 2019
A2: ='Dump KNMI data'!D2/10 -> 15.5 | B2: 7.9
A3: ='Dump KNMI data'!D3/10 -> 15 | B3: 8.4
A4: ='Dump KNMI data'!D4/10 -> 14.9 | B4: 8.4
A5: ='Dump KNMI data'!D5/10 -> 13.9 | B5: 8.2
A6: ='Dump KNMI data'!D6/10 -> 13.1 | B6: 8.4
A7: ='Dump KNMI data'!D7/10 -> 12.9 | B7: 8.6
A8: ='Dump KNMI data'!D8/10 -> 12.5 | B8: 8.8
A9: ='Dump KNMI data'!D9/10 -> 11.6 | B9: 8
A10: ='Dump KNMI data'!D10/10 -> 11.5 | B10: 8.2
A11: ='Dump KNMI data'!D11/10 -> 12 | B11: 8.5
A12: ='Dump KNMI data'!D12/10 -> 12.8 | B12: 8.9
A13: ='Dump KNMI data'!D13/10 -> 12.3 | B13: 8.7
... A8761: ='Dump KNMI data'!D8761/10 -> 8.2 | B8761: 1.5

Sheet Dump KNMI data
A1: STN | B1: YYYYMMDD | C1: HH | D1: T | E1: T10N | F1: TD
A2: 260 | B2: 20230101 | C2: 1 | D2: 155 | F2: 75 | I2: Output of script | J2: https://github.com/quintel/etdataset/blob/master/curves/supply/solar/script/weather_years/process_irradiation_data.py
A3: 260 | B3: 20230101 | C3: 2 | D3: 150 | F3: 75
A4: 260 | B4: 20230101 | C4: 3 | D4: 149 | F4: 74
A5: 260 | B5: 20230101 | C5: 4 | D5: 139 | F5: 82 | I5: HH = tijd (HH=uur, UT.12 UT=13 MET, 14 MEZT. Uurvak 05 loopt van 04.00 UT tot 5.00 UT / time (HH uur/hour, UT. 12 UT=13 MET, 14 MEZT. Hourly division 05 runs from 04.00 UT to 5.00 UT
A6: 260 | B6: 20230101 | C6: 5 | D6: 131 | F6: 84 | I6: T = Temperatuur (in 0.1 graden Celsius) op 1.50 m hoogte tijdens de waarneming / Temperature (in 0.1 degrees Celsius) at 1.50 m at the time of observation
A7: 260 | B7: 20230101 | C7: 6 | D7: 129 | E7: 122 | F7: 70 | I7: T10N = Minimumtemperatuur (in 0.1 graden Celsius) op 10 cm hoogte in de afgelopen 6 uur / Minimum temperature (in 0.1 degrees Celsius) at 0.1 m inthe preceding 6-hour period
A8: 260 | B8: 20230101 | C8: 7 | D8: 125 | F8: 60 | I8: TD = Dauwpuntstemperatuur (in 0.1 graden Celsius) op 1.50 m hoogte tijdens de waarneming / Dew point temperature (in 0.1 degrees Celsius) at 1.50 m at the time of observation
A9: 260 | B9: 20230101 | C9: 8 | D9: 116 | F9: 63
A10: 260 | B10: 20230101 | C10: 9 | D10: 115 | F10: 64
A11: 260 | B11: 20230101 | C11: 10 | D11: 120 | F11: 70 | I11: max | J11: =MAX(D:D)/10 -> 31.9
A12: 260 | B12: 20230101 | C12: 11 | D12: 128 | F12: 80 | I12: min | J12: =MIN(D:D)/10 -> -5.6
A13: 260 | B13: 20230101 | C13: 12 | D13: 123 | E13: 107 | F13: 87 | I13: average | J13: =AVERAGE(D:D)/10 -> 11.786176
A14: 260 | B14: 20230101 | C14: 13 | D14: 129 | F14: 80
A15: 260 | B15: 20230101 | C15: 14 | D15: 125 | F15: 82
A16: 260 | B16: 20230101 | C16: 15 | D16: 123 | F16: 84
A17: 260 | B17: 20230101 | C17: 16 | D17: 122 | F17: 84
A18: 260 | B18: 20230101 | C18: 17 | D18: 121 | F18: 86
A19: 260 | B19: 20230101 | C19: 18 | D19: 115 | E19: 109 | F19: 87
A20: 260 | B20: 20230101 | C20: 19 | D20: 107 | F20: 96
A21: 260 | B21: 20230101 | C21: 20 | D21: 106 | F21: 98
A22: 260 | B22: 20230101 | C22: 21 | D22: 105 | F22: 100
A23: 260 | B23: 20230101 | C23: 22 | D23: 106 | F23: 100
A24: 260 | B24: 20230101 | C24: 23 | D24: 113 | F24: 99
A25: 260 | B25: 20230101 | C25: 24 | D25: 114 | E25: 102 | F25: 101
A26: 260 | B26: 20230102 | C26: 1 | D26: 114 | F26: 101
A27: 260 | B27: 20230102 | C27: 2 | D27: 119 | F27: 103
A28: 260 | B28: 20230102 | C28: 3 | D28: 122 | F28: 105
A29: 260 | B29: 20230102 | C29: 4 | D29: 127 | F29: 108
A30: 260 | B30: 20230102 | C30: 5 | D30: 124 | F30: 110
A31: 260 | B31: 20230102 | C31: 6 | D31: 99 | E31: 97 | F31: 89
A32: 260 | B32: 20230102 | C32: 7 | D32: 93 | F32: 83
A33: 260 | B33: 20230102 | C33: 8 | D33: 89 | F33: 78
A34: 260 | B34: 20230102 | C34: 9 | D34: 91 | F34: 74
A35: 260 | B35: 20230102 | C35: 10 | D35: 90 | F35: 71
A36: 260 | B36: 20230102 | C36: 11 | D36: 93 | F36: 73
A37: 260 | B37: 20230102 | C37: 12 | D37: 97 | E37: 87 | F37: 73
A38: 260 | B38: 20230102 | C38: 13 | D38: 97 | F38: 75
A39: 260 | B39: 20230102 | C39: 14 | D39: 91 | F39: 79
A40: 260 | B40: 20230102 | C40: 15 | D40: 92 | F40: 75
...
