Workbook
Name Final_demand_space_heating: [1]Dashboard!$E$23
Name TWh_to_TJ: #REF!

Sheet Overview
A1: Category | B1: value | C1: unit | D1: comment
A2: Final electricity demand used for central ICT | B2: =Eurostat!AB42 -> 20036.862 | C2: TJ | D2: From Eurostat, only electricity demand is accounted for in ICT final demand
A3: Final energy demand used for Space Heating | B3: ='Final demand'!B5 -> 127290.34 | C3: TJ | D3: From RVO databank
A4: Final energy demand used for Space Cooling | B4: ='Final demand'!B6 -> 17646.168 | C4: TJ | D4: From RVO databank
A5: Final energy demand used for Lighting | B5: ='Final demand'!B7 -> 30533.819 | C5: TJ | D5: From RVO databank
A6: Technology split heating: Gas-fired heaters | B6: ='Space heating'!F43 -> 0.721 | D6: Based on CBS energy balance final demand natural gas and gas heater efficiency
A7: Technology split heating: Electric heat pumps with thermal storage | B7: ='Space heating'!F44 -> 0.036 | D7: Based on CBS energy balance final demand ambient heat, technology efficiency and CBS heat pump data
A8: Technology split heating: Gas-fired heat pumps | B8: ='Space heating'!F45 -> 0 | D8: Based on CBS heat pump data
A9: Technology split heating: Electric heaters | B9: ='Space heating'!F46 -> 0.181 | D9: Assumption
A10: Technology split heating: Coal-fired heaters | B10: ='Space heating'!F47 -> 0 | D10: Assumption
A11: Technology split heating: Oil-fired heaters | B11: ='Space heating'!F48 -> 0 | D11: Assumption
A12: Technology split heating: Electric air heatpumps | B12: ='Space heating'!F49 -> 0.062 | D12: Based on CBS energy balance final demand ambient heat, technology efficiency and CBS heat pump data
A13: Technology split cooling: Gas-fired heat pumps | B13: 0 | D13: Based on CBS heat pump data
A14: Technology split cooling: Electric heat pumps with thermal storage | B14: =B7 -> 0.036 | D14: Assumed the same share as for heating
A15: Technology split cooling: Airconditioning | B15: =1-(B14+B16) -> 0.902 | D15: Allocate the rest to airconditiong
A16: Technology split cooling: Electric air heat pumps | B16: =B12 -> 0.062 | D16: Assumed the same share as for heating
A17: Lighting technology: Standard fluorescent tubes | B17: =Lighting!B20 -> 0.158335 | D17: Based on European Commission data for light sources in 2020 in the EU27
A18: Lighting technology: Efficient fluorescent tubes | B18: =Lighting!B21 -> 0.158335 | D18: Based on European Commission data for light sources in 2020 in the EU27
A19: Lighting technology: LED tubes | B19: =Lighting!B22 -> 0.68333 | D19: Based on European Commission data for light sources in 2020 in the EU27

Sheet Final demand
A1: Final energy demand based on RVO shares
A3: Total final energy demand | B3: 238025 | C3: TJ | D3: copied from energy balance analysis
A5: Space heating | B5: =$B$3*RVO!$D$3 -> 127290.34 | C5: TJ
A6: Space cooling | B6: =$B$3*RVO!D6 -> 17646.168 | C6: TJ
A7: Lighting | B7: =$B$3*RVO!D8 -> 30533.819 | C7: TJ

Sheet Space heating
A1: Heat demand heat pumps based on CBS
A2: Note that CBS accounts for aggregated services and agricutlure
A4: Warmtepompen | B4: Energiestromen|Bruto eindverbruik | C4: unit | D4: comment
A5: Warmtepompen; totaal | B5: ='CBS heat pumps'!L6 -> 10155 | C5: TJ
A6: Warmtepompen bodem of water; totaal | B6: ='CBS heat pumps'!L7 -> 3602 | C6: TJ | D6: Assumption: allocate to ground heat pump with thermal storage (TS)
A7: Warmtepompen bodem of water; wv hybride | B7: ='CBS heat pumps'!L8 -> . | C7: TJ | D7: No hybrid heat pumps
A8: Warmtepompen buitenlucht; totaal | B8: ='CBS heat pumps'!L9 -> 6553 | C8: TJ | D8: Assumption: allocate to air heat pump
A9: Warmtepompen buitenlucht-lucht | B9: ='CBS heat pumps'!L10 -> 3000 | C9: TJ
A10: Warmtepompen buitenlucht-water; totaal | B10: ='CBS heat pumps'!L11 -> 3554 | C10: TJ
A11: Warmtepomp buitenlucht-water; wv hybride | B11: ='CBS heat pumps'!L12 -> . | C11: TJ | D11: No hybrid heat pumps
A14: Efficiencies
B15: Ambient heat | C15: Electricity | D15: Comment
A16: Ground heat pump with TS | B16: 0.734 | C16: 0.266 | D16: from node ETSource: buildings_space_heater_collective_heatpump_water_water_ts_electricity
A17: Air heat pump | B17: 0.7778 | C17: 0.2222 | D17: from node ETSource: buildings_space_heater_heatpump_air_water_electricity
A20: Share technology in total demand | B20: value | D20: comment
A21: Ground heat pump with TS | B21: =B6/B5 -> 0.35470212 | D21: since efficiencies are roughly similar, share is determined based on final demand
A22: Air heat pump | B22: =B8/B5 -> 0.64529788 | D22: since efficiencies are roughly similar, share is determined based on final demand
A25: Allocation final demand flows | B25: value | C25: unit | D25: comment
A26: Heat pump total | B26: ='CBS energiebalans'!L5*10^3 -> 9800 | C26: TJ | D26: Taken from energy balance
A27: Ground heat pump with TS | B27: =$B$26*B21 -> 3476.0807 | C27: TJ | D27: Apply shares of calculated ambient heat to total ambient heat energy balance flow
A28: Air heat pump | B28: =$B$26*B22 -> 6323.9193 | C28: TJ | D28: Apply shares of calculated ambient heat to total ambient heat energy balance flow
A31: Demand per carrier
B32: Ambient heat | C32: Electricity | D32: Total | E32: Unit
A33: Ground heat pump with TS | B33: =B27 -> 3476.0807 | C33: =B33/B16*C16 -> 1259.7241 | D33: =SUM(B33:C33) -> 4735.8048 | E33: TJ
A34: Air heat pump | B34: =B28 -> 6323.9193 | C34: =B34/B17*C17 -> 1806.6018 | D34: =SUM(B34:C34) -> 8130.521 | E34: TJ
B35: =SUM(B33:B34) -> 9800 | C35: =SUM(C33:C34) -> 3066.3259 | D35: =SUM(D33:D34) -> 12866.326 | E35: TJ
A37: Allocation other technologies
A38: Based on CBS energiebalans. Ignoring coal and oil since heaters for these technologies are not available for NL.
A39: Solar thermal, biomass heaters and district heating are accounted for in the analysis manager processing steps.
B41: Demand | C41: Efficiency per technology | D41: Useful demand produced | E41: Percentage of heat delivered | F41: Corrected for rounding | H41: Comment
B42: TJ | C42: % | D42: TJ | E42: % | F42: %
A43: Gas-fired heaters | B43: 88881.618 | C43: 1.067 | D43: =B43*C43 -> 94836.686 | E43: =D43/$D$53 -> 0.72146889 | F43: =1-SUM(F44:F49) -> 0.721 | H43: Sourced to match energy balance. Efficiency based on node buildings_space_heater_network_gas
A44: Electric heat pumps with thermal storage | B44: =C33 -> 1259.7241 | C44: =1/C16 -> 3.7593985 | D44: =B44*C44 -> 4735.8048 | E44: =D44/$D$53 -> 0.036027575 | F44: =ROUND(E44,3) -> 0.036 | H44: Calculated from ambient heat use
A45: Gas-fired heat pumps | B45: 0 | C45: not applicable | D45: 0 | E45: =D45/$D$53 -> 0 | F45: =ROUND(E45,3) -> 0 | H45: Assumed to be 0
A46: Electric heaters | B46: 23746.435 | C46: 1 | D46: =B46*C46 -> 23746.435 | E46: =D46/$D$53 -> 0.1806507 | F46: =ROUND(E46,3) -> 0.181 | H46: Used as a degree of freedom to match total space heating demand. Efficiency based on node buildings-space_heater_electricity
A47: Coal-fired heaters | B47: 0 | C47: not applicable | D47: 0 | E47: =D47/$D$53 -> 0 | F47: =ROUND(E47,3) -> 0 | H47: Assumed to be 0
A48: Oil-fired heaters | B48: 0 | C48: not applicable | D48: 0 | E48: =D48/$D$53 -> 0 | F48: =ROUND(E48,3) -> 0 | H48: Assumed to be 0
A49: Electric air heatpumps | B49: =C34 -> 1806.6018 | C49: =1/C17 -> 4.50045 | D49: =B49*C49 -> 8130.521 | E49: =D49/$D$53 -> 0.061852835 | F49: =ROUND(E49,3) -> 0.062 | H49: Calculated from ambient heat use
A50: Wood pellets | B50: 1198.8088 | H50: Sourced directly from energy balance
A51: Solar thermal | B51: 235 | H51: Sourced directly from energy balance
...

Sheet Lighting
A1: Lighting technology European Commission | B1: Value
A2: https://energy-efficient-products.ec.europa.eu/product-list/light-sources_en
A3: LED | B3: 0.41
A4: compact fluorescent | B4: 0.28
A5: linear fluorescent | B5: 0.19
A6: incandescent | B6: 0.11
A7: high-intensity discharge | B7: 0.01
B8: =SUM(B3:B7) -> 1
A10: Allocate to ETM categories
A11: Services sector only has LED and linear fluorescent in ETM
B12: Original value | C12: Re-allocated value | D12: Comment
A13: LED | B13: =B3 -> 0.41 | C13: =ROUND(B13/$B$15,5) -> 0.68333
A14: linear fluorescent | B14: =B5 -> 0.19 | C14: =ROUND(B14/$B$15,5) -> 0.31667
B15: =SUM(B13:B14) -> 0.6 | C15: =SUM(C13:C14) -> 1
A17: Distribution standard and efficienct tubes | B17: 0.5 | D17: It is assumed that 50% of linear fluorescent is standard and 50% is efficient
A19: Percentage of light delivered by
A20: Standard fluorescent tubes | B20: =$B$17*$C$14 -> 0.158335
A21: Efficient fluorescent tubes | B21: =$B$17*$C$14 -> 0.158335
A22: LED tubes | B22: =C13 -> 0.68333
B23: =SUM(B20:B22) -> 1

Sheet Eurostat
A1: Data extracted on 26/05/2025 09:10:03 from [ESTAT]
A2: Dataset: | B2: Disaggregated final energy consumption in services by NACE Rev. 2 activity - quantities [nrg_d_serq_n__custom_16852476]
A3: Last updated: | B3: 21/05/2025 23:00
A5: Time frequency | C5: Annual
A6: Unit of measure | C6: Terajoule (net calorific value - NCV)
A7: Geopolitical entity (reporting) | C7: Netherlands
A8: Time | C8: 2023
A10: https://doi.org/10.2908/NRG_D_SERQ_N
A12: SIEC (Labels) | B12: Solid fossil fuels, peat, peat products, oil shale and oil sands | D12: Manufactured gases | F12: Natural gas | H12: Oil and petroleum products | J12: Liquefied petroleum gases | L12: Gas oil and diesel oil | N12: Renewables and biofuels | P12: Geothermal | R12: Solar thermal | T12: Ambient heat (heat pumps) | V12: Primary solid biofuels | X12: Biogases | Z12: Non-renewable waste | AB12: Electricity | AD12: Heat
A13: NACE_R2 (Labels)
A14: Total - all NACE activities | B14: : | D14: 0 | F14: 88873.079 | H14: 8149.976 | J14: 0 | L14: 6058.232 | N14: 16268.652 | P14: 0 | R14: 0 | T14: 0 | V14: 0 | X14: 0 | Z14: 1339.13 | AB14: 133576.23 | AD14: 8480.849
A15: Repair and installation of machinery and equipment | B15: : | D15: 0 | F15: 430.473 | H15: 34.237 | J15: : | L15: 23.754 | N15: 0 | P15: 0 | R15: 0 | T15: 0 | V15: 0 | X15: 0 | Z15: 0 | AB15: 696.407 | AD15: 14.607 | AE15: u
A16: Water supply; sewerage, waste management and remediation activities | B16: : | D16: 0 | F16: 1764.251 | H16: 637.252 | J16: : | L16: 594.449 | N16: 3432.365 | P16: 0 | R16: 0 | T16: 0 | V16: 0 | X16: 0 | Z16: 1339.13 | AB16: 8498.754 | AD16: 270.305 | AE16: u
A17: Water collection, treatment and supply | B17: : | D17: 0 | F17: 0 | H17: 0 | J17: 0 | L17: 0 | N17: 0 | P17: 0 | R17: 0 | T17: 0 | V17: 0 | X17: 0 | Z17: 0 | AB17: 0 | AD17: 0
A18: Sewerage, waste management, remediation activities | B18: : | D18: 0 | F18: 0 | H18: 0 | J18: 0 | L18: 0 | N18: 0 | P18: 0 | R18: 0 | T18: 0 | V18: 0 | X18: 0 | Z18: 0 | AB18: 0 | AD18: 0
A19: Sewerage | B19: : | D19: 0 | F19: 0 | H19: 0 | J19: 0 | L19: 0 | N19: 0 | P19: 0 | R19: 0 | T19: 0 | V19: 0 | X19: 0 | Z19: 0 | AB19: 0 | AD19: 0
A20: Waste collection, treatment and disposal activities; materials recovery | B20: : | D20: 0 | F20: 0 | H20: 0 | J20: 0 | L20: 0 | N20: 0 | P20: 0 | R20: 0 | T20: 0 | V20: 0 | X20: 0 | Z20: 0 | AB20: 0 | AD20: 0
A21: Remediation activities and other waste management services | B21: : | D21: 0 | F21: 0 | H21: 0 | J21: 0 | L21: 0 | N21: 0 | P21: 0 | R21: 0 | T21: 0 | V21: 0 | X21: 0 | Z21: 0 | AB21: 0 | AD21: 0
A22: Wholesale and retail trade; repair of motor vehicles and motorcycles | B22: : | D22: 0 | F22: 15539.557 | H22: 528.371 | J22: : | L22: 204.121 | N22: 2876.074 | P22: 0 | R22: 0 | T22: 0 | V22: 0 | X22: 0 | Z22: 0 | AB22: 28740.157 | AD22: 366.515 | AE22: u
A23: Wholesale and retail trade and repair of motor vehicles and motorcycles | B23: : | D23: 0 | F23: 0 | H23: 0 | J23: 0 | L23: 0 | N23: 0 | P23: 0 | R23: 0 | T23: 0 | V23: 0 | X23: 0 | Z23: 0 | AB23: 0 | AD23: 0
A24: Wholesale trade, except of motor vehicles and motorcycles | B24: : | D24: 0 | F24: 5278.5 | H24: 528.371 | J24: : | L24: 204.121 | N24: 282.143 | P24: 0 | R24: 0 | T24: 0 | V24: 0 | X24: 0 | Z24: 0 | AB24: 8752.562 | AD24: 194.106 | AE24: u
A25: Retail trade, except of motor vehicles and motorcycles | B25: : | D25: 0 | F25: 7283.108 | H25: 0 | J25: : | L25: 0 | N25: 2593.931 | P25: 0 | R25: 0 | T25: 0 | V25: 0 | X25: 0 | Z25: 0 | AB25: 17258.824 | AD25: 119.269 | AE25: u
A26: Retail trade except of motor vehicles and motorcycles, except retail sale in non-specialised stores | B26: : | D26: 0 | F26: 0 | H26: 0 | J26: 0 | L26: 0 | N26: 0 | P26: 0 | R26: 0 | T26: 0 | V26: 0 | X26: 0 | Z26: 0 | AB26: 0 | AD26: 0
A27: Retail sale in non-specialised stores | B27: : | D27: 0 | F27: 0 | H27: 0 | J27: 0 | L27: 0 | N27: 0 | P27: 0 | R27: 0 | T27: 0 | V27: 0 | X27: 0 | Z27: 0 | AB27: 0 | AD27: 0
A28: Land transport (except transport via pipelines), water transport and air transport - non transport activities | B28: : | D28: 0 | F28: 0 | H28: 0 | J28: 0 | L28: 0 | N28: 0 | P28: 0 | R28: 0 | T28: 0 | V28: 0 | X28: 0 | Z28: 0 | AB28: 0 | AD28: 0
A29: Warehousing and support activities for transportation | B29: : | D29: 0 | F29: 6849.028 | H29: 3739.266 | J29: : | L29: 3623.89 | N29: 389.23 | P29: 0 | R29: 0 | T29: 0 | V29: 0 | X29: 0 | Z29: 0 | AB29: 11338.751 | AD29: 84.693 | AE29: u
A30: Street lighting | B30: : | D30: 0 | F30: 0 | H30: 0 | J30: 0 | L30: 0 | N30: 0 | P30: 0 | R30: 0 | T30: 0 | V30: 0 | X30: 0 | Z30: 0 | AB30: 0 | AD30: 0
A31: Postal and courier activities | B31: : | D31: 0 | F31: 186.45 | H31: 0 | J31: : | L31: 0 | N31: 0 | P31: 0 | R31: 0 | T31: 0 | V31: 0 | X31: 0 | Z31: 0 | AB31: 487.308 | AD31: 30.094 | AE31: u
A32: Accommodation and food service activities | B32: : | D32: 0 | F32: 12821.615 | H32: 0 | J32: : | L32: 0 | N32: 1064.065 | P32: 0 | R32: 0 | T32: 0 | V32: 0 | X32: 0 | Z32: 0 | AB32: 11932.824 | AD32: 548.972 | AE32: u
A33: Accommodation | B33: : | D33: 0 | F33: 5525.531 | H33: 0 | J33: : | L33: 0 | N33: 25.21 | P33: 0 | R33: 0 | T33: 0 | V33: 0 | X33: 0 | Z33: 0 | AB33: 4436.316 | AD33: 345.921 | AE33: u
A34: Hotels and similar accommodation | B34: : | D34: 0 | F34: 0 | H34: 0 | J34: 0 | L34: 0 | N34: 0 | P34: 0 | R34: 0 | T34: 0 | V34: 0 | X34: 0 | Z34: 0 | AB34: 0 | AD34: 0
A35: Holiday and other short-stay accommodation | B35: : | D35: 0 | F35: 0 | H35: 0 | J35: 0 | L35: 0 | N35: 0 | P35: 0 | R35: 0 | T35: 0 | V35: 0 | X35: 0 | Z35: 0 | AB35: 0 | AD35: 0
A36: Camping grounds, recreational vehicle parks and trailer parks | B36: : | D36: 0 | F36: 0 | H36: 0 | J36: 0 | L36: 0 | N36: 0 | P36: 0 | R36: 0 | T36: 0 | V36: 0 | X36: 0 | Z36: 0 | AB36: 0 | AD36: 0
A37: Other accommodation | B37: : | D37: 0 | F37: 0 | H37: 0 | J37: 0 | L37: 0 | N37: 0 | P37: 0 | R37: 0 | T37: 0 | V37: 0 | X37: 0 | Z37: 0 | AB37: 0 | AD37: 0
A38: Food and beverage service activities | B38: : | D38: 0 | F38: 7296.085 | H38: 0 | J38: : | L38: 0 | N38: 1038.855 | P38: 0 | R38: 0 | T38: 0 | V38: 0 | X38: 0 | Z38: 0 | AB38: 7496.508 | AD38: 203.051 | AE38: u
A39: Restaurants and mobile food service activities | B39: : | D39: 0 | F39: 0 | H39: 0 | J39: 0 | L39: 0 | N39: 0 | P39: 0 | R39: 0 | T39: 0 | V39: 0 | X39: 0 | Z39: 0 | AB39: 0 | AD39: 0
A40: Event catering and other food service activities | B40: : | D40: 0 | F40: 0 | H40: 0 | J40: 0 | L40: 0 | N40: 0 | P40: 0 | R40: 0 | T40: 0 | V40: 0 | X40: 0 | Z40: 0 | AB40: 0 | AD40: 0
A41: Beverage serving activities | B41: : | D41: 0 | F41: 0 | H41: 0 | J41: 0 | L41: 0 | N41: 0 | P41: 0 | R41: 0 | T41: 0 | V41: 0 | X41: 0 | Z41: 0 | AB41: 0 | AD41: 0
A42: Information and communication | B42: : | D42: 0 | F42: 904.525 | H42: 0 | J42: : | L42: 0 | N42: 141.385 | P42: 0 | R42: 0 | T42: 0 | V42: 0 | X42: 0 | Z42: 0 | AB42: 20036.862 | AD42: 251.558 | AE42: u
A43: Publishing activities | B43: : | D43: 0 | F43: 0 | H43: 0 | J43: 0 | L43: 0 | N43: 0 | P43: 0 | R43: 0 | T43: 0 | V43: 0 | X43: 0 | Z43: 0 | AB43: 0 | AD43: 0
...

Sheet RVO
A1: Energieverbruik per functie [PJ] Nederland
B2: 2019 | C2: 2023
A3: Ruimteverwarming (1) | B3: 148 | C3: 128.4 | D3: =C3/$C$11 -> 0.53477718
A4: Productbereiding en -koeling, horeca (1) | B4: 19.2 | C4: 18.3
A5: Tapwaterverwarming (1) | B5: 4.4 | C5: 4.5
A6: Ruimtekoeling en ventilatie (1) | B6: 17.5 | C6: 17.8 | D6: =C6/$C$11 -> 0.074135777
A7: Diversen (1) | B7: 14.6 | C7: 17.1
A8: Verlichting (1) | B8: 36.5 | C8: 30.8 | D8: =C8/$C$11 -> 0.12827988
A9: ICT (1) | B9: 17.8 | C9: 20.2
A10: Transport (1) | B10: 2.8 | C10: 2.9
A11: Energieverbruik dienstensector totaal | B11: 260.8 | C11: 240.1
A13: Eenheid | B13: PJ
A14: Bron | B14: TNO EnergieTransitie
A15: Voetnoot
A16: (1) | B16: De getoonde cijfers zijn temperatuur gecorrigeerd.
A18: energiecijfers.databank.nl
A20: Datum export | B20: maandag 26 mei 2025
A22: Link bron | B22: https://energiecijfers.databank.nl/jive?workspace_guid=47b45879-4648-4e06-ad59-44227bff9ff4

Sheet CBS heat pumps
A1: Warmtepompen; aantallen, thermisch vermogen en energiestromen,1994-2021
D3: Onderwerp
D4: Warmtepompen|In gebruik genomen warmtepompen | E4: Warmtepompen|Uit gebruik genomen warmtepompen | F4: Warmtepompen|Opgestelde warmtepompen einde van jaar | G4: Thermisch vermogen van warmtepompen|In gebruik genomen thermisch vermogen | H4: Thermisch vermogen van warmtepompen|Uit gebruik genomen thermisch vermogen | I4: Thermisch vermogen van warmtepompen|Opgesteld thermisch vermogen einde jaar | J4: Energiestromen|Bruto warmteproductie warmtepompen | K4: Energiestromen|Verbruik van elektriciteit en aardgas | L4: Energiestromen|Bruto eindverbruik
A5: Sector | B5: Warmtepompen | C5: Perioden | D5: aantal | E5: aantal | F5: aantal | G5: megawatt | H5: megawatt | I5: megawatt | J5: TJ | K5: TJ | L5: TJ
A6: Utiliteitsgebouwen, kassen en stallen | B6: Warmtepompen; totaal | C6: 2023** | D6: . | E6: 961 | F6: 451633 | G6: . | H6: 96 | I6: 6112 | J6: 15565 | K6: 5410 | L6: 10155
A7: Utiliteitsgebouwen, kassen en stallen | B7: Warmtepompen bodem of water; totaal | C7: 2023** | D7: . | E7: 777 | F7: 9163 | G7: . | H7: 79 | I7: 1216 | J7: 4817 | K7: 1215 | L7: 3602
A8: Utiliteitsgebouwen, kassen en stallen | B8: Warmtepompen bodem of water; wv hybride | C8: 2023** | D8: . | E8: . | F8: . | G8: . | H8: . | I8: . | J8: . | K8: . | L8: .
A9: Utiliteitsgebouwen, kassen en stallen | B9: Warmtepompen buitenlucht; totaal | C9: 2023** | D9: . | E9: 184 | F9: 442470 | G9: . | H9: 17 | I9: 4896 | J9: 10749 | K9: 4195 | L9: 6553
A10: Utiliteitsgebouwen, kassen en stallen | B10: Warmtepompen buitenlucht-lucht | C10: 2023** | D10: . | E10: 0 | F10: 418883 | G10: . | H10: 0 | I10: 3901 | J10: 4876 | K10: 1876 | L10: 3000
A11: Utiliteitsgebouwen, kassen en stallen | B11: Warmtepompen buitenlucht-water; totaal | C11: 2023** | D11: . | E11: 184 | F11: 23587 | G11: . | H11: 17 | I11: 995 | J11: 5873 | K11: 2319 | L11: 3554
A12: Utiliteitsgebouwen, kassen en stallen | B12: Warmtepomp buitenlucht-water; wv hybride | C12: 2023** | D12: . | E12: . | F12: . | G12: . | H12: . | I12: . | J12: . | K12: . | L12: .
A13: Bron: CBS
A15: Link naar bron | B15: https://opendata.cbs.nl/#/CBS/nl/dataset/85523NED/table?dl=C139D

Sheet CBS energiebalans
A1: Energiebalans; aanbod, omzetting en verbruik
A2: Perioden: 2023**
C3: Energiedragers
A4: Onderwerp | C4: Totaal energiedragers | D4: Totaal kool en koolproducten | E4: Aardoliegrond. - en producten, fossiel | F4: Totaal aardoliegrondstoffen, fossiel | G4: Aardgas | H4: Hernieuwbare energie | I4: Waterkracht | J4: Totaal windenergie | K4: Totaal zonne-energie | L4: Omgevingsenergie | M4: Totaal biomassa | N4: Elektriciteit | O4: Warmte | P4: Totaal overige energiedragers
A5: Finaal verbruik|Finaal energieverbruik|Overige afnemers|Diensten, afval, water en reparatie | B5: PJ | C5: 254.8 | D5: 0.3 | E5: 8.1 | G5: 87.4 | H5: 13.9 | K5: 0.2 | L5: 9.8 | M5: 3.8 | N5: 133.6 | O5: 11.6 | P5: 0
A6: Bron: CBS
A8: Link naar bron | B8: https://opendata.cbs.nl/#/CBS/nl/dataset/83140NED/table?dl=C144B
