Workbook
Name ap_subfuel_allo: '[1]CEB allocation factors'!$F$12:$BC$12
Name base_year: [1]Dashboard!$E$13
Name country: [1]Dashboard!$E$12
Name ei_subsector_allo: '[1]CEB allocation factors'!$D$17:$D$33
Name i_subsector_allo: '[1]CEB allocation factors'!$D$37:$D$49
Name kWh_MJ_conversion: [1]Assumptions!$C$174
Name net_gross_conv: '[1]AP net-gross conversion'!$D$12
Name switch_decc: '[1]Fuel allocation'!$C$130
Name switch_iea: '[1]Fuel allocation'!$C$89
Name switch_protermo: '[1]Fuel allocation'!$C$48

Sheet Coversheet
B2: Cover sheet
B4: Document | C4: Carriers source analysis
B5: Version # | C5: 1
B6: Country | C6: nl
B7: Year data | C7: 2023
B8: Date | C8: 45824
B9: Author | C9: Max Kerpel
B10: Organisation | C10: Quintel Intelligence
B12: Legend
B14: Cells | C14: Intermediate (calculation)
C15: Result
C16: Manual input
C17: Reference to manual input or data input
B19: Tabs | C19: Introductory
C20: Dashboard
C21: Research data
C22: Sources
C23: Results
C24: Main calculations
C25: Additional calculations
C26: Output to csv
B29: Comments

Sheet Dashboard
B4: key | C4: co2_conversion_per_mj | D4: cost_per_mj | E4: potential_co2_conversion_per_mj
B5: ambient_cold | D5: 0
B6: ambient_heat | D6: 0
B7: bio_ethanol | C7: 0 | D7: 0.044562085 | E7: 0.0708
B8: bio_kerosene | C8: 0 | D8: 0.027637281 | E8: 0.0796
B9: bio_lng | C9: 0 | D9: 0.017 | E9: 0.0546
B10: bio_oil | C10: 0 | D10: 0.015480927 | E10: 0.074566667
B11: biodiesel | C11: 0 | D11: 0.028960044 | E11: 0.0708
B12: biogas | C12: 0 | D12: 0.015833333 | E12: 0.0546
B13: biogenic_waste | C13: 0 | D13: 0 | E13: 0.1
B14: co | C14: 0.15558699 | D14: 0
B15: co2 | D15: 0
B16: coal | C16: 0.0945 | D16: ='Carrier costs'!C23 -> 0.0066792453
B17: coal_gas | C17: 0.0926835 | D17: 0.002522094
B18: cokes | C18: 0.0926835 | D18: 0.002522094
B19: crude_oil | C19: 0.0733 | D19: ='Carrier costs'!C25 -> 0.013879954
B20: diesel | C20: 0.0743 | D20: 0.015214673
B21: dry_biomass | C21: 0 | D21: 0.002883
B22: electricity | C22: 0
B23: gasoline | C23: 0.072 | D23: 0.016130065
B24: geothermal | C24: 0 | D24: 0
B25: greengas | C25: 0 | D25: 0.017658333 | E25: 0.0546
B26: heavy_fuel_oil | C26: 0.0774 | D26: 0.014813827
B27: hydrogen | C27: 0 | D27: =Hydrogen!D12 -> 0.0298085
B28: imported_electricity | C28: ='Carrier CO2'!B7 -> 0.061111111 | D28: ='Carrier costs'!C27 -> 0.0267292
B29: imported_heat | C29: ='Carrier CO2'!B8 -> 0.03194 | D29: 0.01156944
B30: imported_hydrogen | C30: 0.078 | D30: =Hydrogen!D12 -> 0.0298085
B31: kerosene | C31: 0.0715 | D31: 0.010081803
B32: light | D32: 0
B33: lignite | C33: 0.1012 | D33: 0.0011
B34: lng | C34: 0.0565 | D34: 0.006723917
B35: loss | D35: 0
B36: lpg | C36: 0.0667 | D36: 0.015188765
B37: methanol | C37: 0.0691 | D37: 0.012898
B38: natural_gas | C38: 0.0565 | D38: 0.01478533
B39: non_biogenic_waste | C39: 0.1052 | D39: 0
B40: not_defined | D40: 0
B41: oil_products | C41: 0.0755 | D41: 0.005060687
B42: oily_biomass | C42: 0 | D42: 0.01352924 | E42: 0
B43: refinery_gas | C43: 0.0755 | D43: 0.005060687
...

Sheet Carrier CO2
A1: Imported electricity
B2: 0.22 | C2: kg / kWh
A3: Imported heat
B4: 0.03194 | C4: ton/GJ
B6: co2_conversion_per_mj
A7: imported_electricity | B7: =B2/3.6 -> 0.061111111 | C7: kg/MJ | D7: Assumption: Imported electricity emission factor equal to national average
A8: imported_heat | B8: =B4 -> 0.03194 | C8: kg/MJ | D8: Assumption: Imported heat emission factor equal to national average
D9: Source: Klimaatmonitor; https://klimaatmonitor.databank.nl/Jive?workspace_guid=5bb3f7b3-fa7c-4df4-bc7e-3b60d92d2203

Sheet Carrier costs
B3: Commodity prices input | C3: 2023 | D3: unit | E3: source
B4: Coal | C4: 177 | D4: euro/ton | E4: PBL KEV (2024) https://www.pbl.nl/publicaties/klimaat-en-energieverkenning-2024
B5: Gas | C5: 0.52 | D5: euro/m^3 | E5: PBL KEV (2024) https://www.pbl.nl/publicaties/klimaat-en-energieverkenning-2024
B6: Oil | C6: 76 | D6: euro/barrel | E6: PBL KEV (2024) https://www.pbl.nl/publicaties/klimaat-en-energieverkenning-2024
B7: CO2 | C7: 85 | D7: euro/tonne | E7: PBL KEV (2024) https://www.pbl.nl/publicaties/klimaat-en-energieverkenning-2024
B8: Imported electricity | C8: 95.18 | D8: euro/MWh | E8: Wholesale day-ahead electricity price Germany: https://www.epexspot.com/en/news/all-time-high-volumes-growth-spot-markets-illustrate-trust-trading-participants
B9: Imported electricity | C9: 97.27 | D9: euro/MWh | E9: Wholesale day-ahead electricity price Belgium: https://www.epexspot.com/en/news/all-time-high-volumes-growth-spot-markets-illustrate-trust-trading-participants
B10: Wood pellets | C10: 200 | D10: dollar/ton | E10: CIF NEW historic average price for wood pellets https://www.svebio.se/wp-content/uploads/2024/02/Senerdem_Erisa_NWPC24.pdf
B11: Currency | C11: 0.9241 | D11: euro/dollar | E11: https://www.exchangerates.org.uk/USD-EUR-spot-exchange-rates-history-2023.html
B13: Commodity prices conversion
B14: Coal | C14: 26500 | D14: MJ/ton | E14: ETDataset carriers_source_analyses
B15: Gas | C15: 35.17 | D15: MJ/m^3 | E15: https://www.cbs.nl/en-gb/figures/detail/85666ENG#:~:text=Natural%20gas%20is%20transported%20per,(Gigajoule)%20%3D%2028433%20m3.
B16: Gas | C16: 3600 | D16: MJ/MWh
B17: Oil | C17: 42 | D17: MJ/kg | E17: ETDataset carriers_source_analyses
B18: Oil | C18: 0.82 | D18: kg/l | E18: ETDataset carriers_source_analyses
B19: Oil | C19: 158.98729 | D19: l/barrel
B20: Wood pellets | C20: 18 | D20: MJ/kg | E20: ETDataset carriers_source_analyses
B22: Commodity price output for ETSource
B23: Coal | C23: =C4/C14 -> 0.0066792453 | D23: euro/MJ
B24: Gas | C24: =C5/C15 -> 0.014785328 | D24: euro/MJ
B25: Oil | C25: =C6/C19/C18/C17 -> 0.013879954 | D25: euro/MJ
B26: CO2 | C26: =C7 -> 85 | D26: euro/tonne
B27: Imported electricity | C27: =ROUND(AVERAGE(C8,C9)/C16,7) -> 0.0267292 | D27: euro/MJ | E27: average taken from Belgium and Germany
B28: Wood pellets | C28: =ROUND(C10*C11/1000/C20,7) -> 0.0102678 | D28: euro/MJ
B29: Currency | C29: =1/C11 -> 1.082134 | D29: dollar/euro
B31: Commodity price on ETM
B32: Coal | C32: =C23*C14*C29 -> 191.53771 | D32: dollar/tonne
B33: Gas | C33: =C5*3600/C15 -> 53.227182 | D33: euro/MWh
B34: Oil | C34: =C6*C29 -> 82.242182 | D34: dollar/barrel
B35: CO2 | C35: =C7 -> 85 | D35: euro/tonne
B36: Imported electricity | C36: =AVERAGE(C8:C9) -> 96.225 | D36: euro/MWh | E36: average taken from Belgium and Germany
B37: Wood pellets | C37: =C10*C11 -> 184.82 | D37: euro/tonne

Sheet Hydrogen
C2: Sources | D2: Page | F2: Notes
C5: CAPEX | D5: 0.09
C6: CO2 costs | D6: 0.59
C7: Natural gas costs | D7: 2.81
C8: Other OPEX | D8: 0.09 | E8: +
C9: Total | D9: =SUM(D5:D8) -> 3.58 | E9: €/kg H2
C11: LHV | D11: 120.1 | E11: MJ/kg | F11: ETM value
C12: Carrier costs | D12: =ROUND(D9/D11,7) -> 0.0298085 | E12: €/MJ
G21: Source: https://observatory.clean-hydrogen.europa.eu/sites/default/files/2024-11/The%20European%20hydrogen%20market%20landscape_November%202024.pdf

Sheet Liquid hydrogen
C2: Sources | D2: Attribute | E2: Value | F2: Unit | G2: Notes
C24: imported_hydrogen
D25: cost_per_mj | E25: =Hydrogen!D12 -> 0.0298085 | F25: €/MJ
D26: co2_conversion_per_mj | E26: 0.078 | F26: kg/MJ
C32: IEA | D32: Specs from imported_hydrogen are used and corrected for conversion losses
D35: Liquefaction losses | E35: 0.8 | F35: - | G35: Conversion loss of gaseous hydrogen to liquid hydrogen
D37: Liquid hydrogen costs | E37: =ROUND(E25/E35,7) -> 0.0372606 | F37: €/MJ | G37: Estimated costs of hydrogen produced using SMR after liquefaction
D38: Liquid hydrogen carbon intensity | E38: =ROUND(E26/E35,7) -> 0.0975 | F38: kg CO2/MJ | G38: Estimated direct emissions of hydrogen produced using SMR after liquefaction
R159: https://www.hydrogen.energy.gov/docs/hydrogenprogramlibraries/pdfs/19001_hydrogen_liquefaction_costs.pdf

Sheet LOHC
C2: Sources | D2: Attribute | E2: Value | F2: Unit | G2: Notes
C5: National Research Council
D7: Energy density | E7: 120.1 | F7: MJ/kg | G7: LHV
D9: carbon density | E9: 2.471 | F9: CO2/MJ | G9: In 2030
D12: costs | E12: 12 | F12: $/kg
E14: =ROUND(E12/E7,3) -> 0.1 | F14: $/MJ
E15: =E14*0.94 -> 0.094 | F15: €/MJ
D17: For consistency with imported hydrogen and imported ammonia these value is not used
C21: imported_hydrogen
D22: cost_per_mj | E22: =Hydrogen!D12 -> 0.0298085 | F22: €/MJ
D23: co2_conversion_per_mj | E23: 0.078 | F23: kg/MJ
C26: IEA | D26: Specs from imported_hydrogen are used and corrected for conversion losses
D28: Hydrogenation losses | E28: 0.95 | F28: - | G28: Conversion loss of gaseous hydrogen to LOHC
D30: LOHC costs | E30: =ROUND(E22/E28,7) -> 0.0313774 | F30: €/MJ | G30: Estimated costs of hydrogen produced using SMR after hydrogenation
D31: LOHC carbon intensity | E31: =ROUND(E23/E28,7) -> 0.0821053 | F31: kg CO2/MJ | G31: Estimated direct emissions of hydrogen produced using SMR after hydrogenation
G32: Important to note that we only look at the useful energy content of H2 contained in the LOHC
C35: IRENA
D36: Storage density | E36: =0.061 -> 0.061 | F36: kgH2/kgLOHC | G36: Toluene taken as reference | H36: 2.471
D38: Energy density corrected | E38: =E7*E36 -> 7.3261 | F38: MJH2/kgLOHC | G38: LOHC is not used as an energy carrier
G39: Therefore we are only interested in the useful energy content of H2 contained in the LOHC
G40: Therefore we use the MJ H2 per kg LOHC as reference
L43: https://studenttheses.uu.nl/bitstream/handle/20.500.12932/42337/Report.pdf?sequence=1&isAllowed=y
Q85: https://pubs.rsc.org/en/content/articlehtml/2019/ee/c8ee02700e
H89: IEA

Sheet Ammonia
C2: Sources | D2: Attribute | E2: Value | F2: Unit | G2: Comments
C5: IEA
D6: Energy content | E6: =18.6 -> 18.6 | F6: GJ/t | G6: Based on LHV
E7: =E6 -> 18.6 | F7: MJ/kg
D22: Ammonia carbon intensity | E22: 1.8 | F22: t CO2/t | G22: Natural gas SMR
D23: Ammonia carbon intensity | E23: 3.2 | F23: t CO2/t | G23: Coal gasification
D25: Share in production | E25: 0.72 | G25: Natural gas SMR
D26: Share in production | E26: 0.26 | G26: Coal gasification
D28: Relative share | E28: =E25/SUM(E25:E26) -> 0.73469388 | G28: Natural gas SMR
D29: Relative share | E29: =1-E28 -> 0.26530612 | G29: Coal gasification
D31: Average carbon intensity | E31: =E22 -> 1.8 | F31: t CO2/t | G31: SMR is the main production route for ammonia in the ETM and the assumed method of imported hydrogen production. Therefore only the carbon intensity of SMR based ammonia production is taken.
E32: =E31 -> 1.8 | F32: kg CO2/kg
E33: =E32/E7 -> 0.096774194 | F33: kg CO2/MJ | G33: Using energy content
D48: Carriers price | E48: 510 | F48: $/kg NH3
D50: Exchange rate | E50: 0.8931 | F50: euro/$ | G50: Average for 2019 https://www.exchangerates.org.uk/USD-EUR-spot-exchange-rates-history-2019.html#:~:text=Average%20exchange%20rate%20in%202019%3A%200.8931%20EUR.
D52: Ammonia price | E52: =E50*E48 -> 455.481 | F52: euro/ton
E53: =ROUND(E52/1000/E7,7) -> 0.0244882 | F53: euro/MJ
