Workbook
Name exchange_rate_2011_2010: #REF!
Name Final_demand_residences: '[1]Fuel aggregation'!$L$11
Name hours_a_year: #REF!
Name km2_to_m2: #REF!
Name kW_to_MW: #REF!
Name kW_to_W: #REF!
Name kWp_to_MWp: #REF!
Name labor_cost: Notes!#REF!
Name licensing: Notes!#REF!
Name m2_to_km2: #REF!
Name overhead_GA: Notes!#REF!
Name sensitivity_07: '[2]Tornado Charts'!$I$48
Name STC: #REF!
Name STC_insolation: #REF!
Name tax_insurance: Notes!#REF!
Name W_to_MW: #REF!
Name Wp_to_kWp: #REF!
Name WP_to_MWp: #REF!

Sheet Cover sheet
B2: Cover Sheet
B4: Document | C4: energy_production_pyrolysis_non_biogenic_waste
B5: Author | C5: Kyra de Haan
B6: Organization | C6: Quintel Intelligence
B9: Legend
B11: Cells | C11: Intermediate (calculation)
C12: Result
C13: Manual input
C14: Reference to manual input or data input
B16: Tabs | C16: Introductory
C17: Dashboard
C18: Research data
C19: Sources
C20: Results
C21: Main calculations
C22: Additional calculations
C23: Output to csv

Sheet Dashboard
B2: This sheet summarizes all node attributes formatted in the way they are used by the Energy Transition Model. Use the Excel formulas to find the original data and sources for these numbers. You can also use this document to update the attribute value. Once you have finished updating, save this document and run rake import:node NODE="nodename" to update the node attributes on ETSource.
C9: Attribute | D9: Unit | E9: Value | G9: Definition | I9: Source
C11: Technical
C12: typical_input_capacity | D12: MW | E12: ='Research data'!H7 -> 25
C13: input.non_biogenic_waste | E13: ='Research data'!H8 -> 1
C14: output.pyrolysis_oil | D14: - | E14: ='Research data'!H9 -> 0.623
C15: output.steam_hot_water | D15: - | E15: ='Research data'!H10 -> 0.178
C16: full_load_hours | D16: h | E16: ='Research data'!H11 -> 7500
C17: availability | D17: - | E17: ='Research data'!H12 -> 0.923
C19: Cost
C20: initial_investment | D20: euro | E20: ='Research data'!H15 -> 25200000 | G20: Initial investment costs
C21: ccs_investment | D21: euro | E21: ='Research data'!H16 -> 0 | I21: taken from energy_hydrogen_biomass_gasification_ccs
C22: fixed_operation_and_maintenance_costs_per_year | D22: euro/yr | E22: ='Research data'!H17 -> 1200000 | G22: Fixed operational and maintenance costs per year (incl. ccs)
C23: variable_operation_and_maintenance_costs_per_full_load_hour | D23: euro/flh | E23: ='Research data'!H18 -> 168 | G23: Variable operation and maintenance costs per flh
C24: variable_operation_and_maintenance_costs_for_ccs_per_full_load_hour | D24: euro/flh | E24: ='Research data'!J19 -> 0
C25: cost_of_installing | D25: euro | E25: ='Research data'!H20 -> 0 | G25: Installation costs
C26: decommissioning_costs | D26: euro | E26: ='Research data'!H21 -> 0 | G26: Decommissioning costs
C27: wacc | D27: % | E27: 0.07 | G27: Weighted average cost of capita | I27: See https://docs.energytransitionmodel.com/main/cost-wacc/
C28: takes_part_in_ets | D28: yes=1, no=0 | E28: 1
C30: Other
C31: technical_lifetime | D31: years | E31: ='Research data'!H25 -> 30 | G31: Technical lifetime of the plant
C32: construction_time | D32: years | E32: ='Research data'!H26 -> 2 | G32: Construction time of the plant
C33: free_co2_factor | D33: - | E33: ='Research data'!H27 -> 0

Sheet Research data
C4: Attribute | F4: Unit | H4: Values | J4: DEA & TNO | M4: Comments
C6: Technical
C7: typical_input_capacity | D7: MWe | F7: MW | H7: =ROUND(J7,2) -> 25 | J7: =Notes!D6 -> 25
C8: input.dry_biomass | D8: - | F8: - | H8: =ROUND(J8,3) -> 1 | J8: =Notes!D20 -> 1
C9: output.bio_pyrolysis_oil | D9: - | F9: - | H9: =ROUND(J9,3) -> 0.623 | J9: =Notes!E17 -> 0.623
C10: output.steam_hot_water | F10: - | H10: =ROUND(J10,3) -> 0.178 | J10: =Notes!E18 -> 0.178
C11: full_load_hours | D11: - | F11: hrs/yr | H11: =ROUND(J11,2) -> 7500 | J11: =Notes!D7 -> 7500
C12: availability | H12: =ROUND(J12,3) -> 0.923 | J12: =Notes!D10 -> 0.92307692
C14: Cost
C15: initial_investment | D15: euro | F15: euro | H15: =ROUND(J15,0) -> 25200000 | J15: =Notes!D12 -> 25200000
C16: ccs_investment | F16: euro | H16: =ROUND(J16,0) -> 0 | J16: 0
C17: fixed_operation_and_maintenance_costs_per_year | D17: euro/yr | E17: 0 | F17: euro/yr | H17: =ROUND(J17,0) -> 1200000 | J17: =Notes!D13 -> 1200000
C18: variable_operation_and_maintenance_costs_per_full_load_hour | D18: euro/flh | E18: ='Research data'!H15 -> 25200000 | F18: euro/flh | H18: =ROUND(J18,2) -> 168 | J18: =Notes!D14 -> 168
C19: variable_operation_and_maintenance_costs_for_ccs_per_full_load_hour | E19: ='Research data'!H20 -> 0 | F19: euro/flh | H19: =J19 -> 0 | J19: 0
C20: cost_of_installing | E20: ='Research data'!H18 -> 168 | F20: euro | H20: =J20 -> 0 | J20: 0
C21: decommissioning_costs | E21: ='Research data'!#REF! -> #REF! | F21: euro | H21: =J21 -> 0 | J21: 0
C22: takes_part_in_ets | D22: yes=1, no=0 | E22: 0 | F22: yes=1, no=0 | H22: =J22 -> 0 | J22: 0
C24: Other
C25: technical_lifetime | D25: years | F25: years | H25: =J25 -> 30 | J25: =Notes!D8 -> 30
C26: construction_time | D26: years | F26: years | H26: =J26 -> 2 | J26: =Notes!D9 -> 2
C27: free_co2_factor | D27: - | E27: 0 | F27: - | H27: 0 | J27: 0

Sheet Sources
C3: Definition on the sources
C5: Type | D5: Source | E5: Country | F5: Date published | G5: Subject | H5: Date retrieved | I5: ETM Library URL | J5: Link
B7: Pyrolysis oil production | C7: All specs | D7: TNO - Energy.nl | E7: NL | F7: 2024 | G7: Production of pyrolysis bio-oil from solid biomass via fast pyrolysis | H7: 45888 | J7: https://energy.nl/data/production-of-pyrolysis-bio-oil-from-solid-biomass-via-fast-pyrolysis/
B9: Biomass gassification & Fischer Tropsch | C9: All specs | D9: Danish Energy Agency | E9: DK | F9: 2025 | G9: Renewable fuels: Technology descriptions and projections for long-term energy system planning | H9: 45887 | I9: https://refman.energytransitionmodel.com/publications/2218
C10: All specs | D10: Danish Energy Agency | E10: DK | F10: 2025 | G10: Data Sheets for energy carrier generation and conversion | H10: 45887 | I10: https://refman.energytransitionmodel.com/publications/2219
B12: Pyrolysis oil upgrade | C12: All specs | D12: TNO - Energy.nl | E12: NL | F12: 2024 | G12: Upgrade of pyrolysis bio-oil from fast pyrolysis to biofuels | H12: 45888 | J12: https://energy.nl/data/upgrade-of-pyrolysis-bio-oil-from-fast-pyrolysis-to-biofuels/

Sheet Notes
C3: Source | D3: Page | E3: Notes
C5: Overview
C6: Input capacity | D6: =D39 -> 25 | E6: MW
C7: Full load hours | D7: =D40 -> 7500 | E7: hours
C8: Technical lifetime | D8: =D41 -> 30 | E8: y | N8: Pyrolysis oil production from energy.nl:
C9: Construction period | D9: =R69 -> 2 | E9: y
C10: availability | D10: =1-R67/52 -> 0.92307692
C12: Investment | D12: =D43 -> 25200000 | E12: euro
C13: Fixed O&M | D13: =D44 -> 1200000 | E13: euro/y
C14: Variable O&M | D14: =D46 -> 168 | E14: euro/flh
C16: Input/output | D16: value | E16: tweaked value
C17: output.pyrolysis_oil | D17: =G29 -> 0.62 | E17: 0.623 | F17: values slightly tweaked to get the same ratio pyrolys_oil / steam_hot_water as for fractionation process
C18: output.steam_hot_water | D18: =G30 -> 0.232 | E18: 0.178 | G18: ratio | H18: =E17/E18 -> 3.5
C19: output.loss | D19: =G32 -> 0.148 | E19: =D19+D18-E18 -> 0.202
C20: input.dry_biomass | D20: =G34 -> 1 | E20: =D20 -> 1
C24: Pyrolysis oil production from biomass
C25: Based on specs from energy.nl
C27: In-and output fractions pyrolysis | F27: validation with DEA
C28: Output | D28: Original | E28: Converted to output for 1 PJ input | F28: original | G28: corrected | I28: the values of DEA seem more logic
C29: pyrolysis-oil | D29: 1 | E29: =D29/$D$34 -> 0.87719298 | F29: =R63 -> 0.62 | G29: =F29 -> 0.62
C30: steam | D30: 0.33 | E30: =D30/$D$34 -> 0.28947368 | F30: =R64 -> 0.232 | G30: =F30 -> 0.232
C31: electricity | D31: 0.03 | E31: =D31/$D$34 -> 0.026315789 | F31: =R65 -> 0.016
C32: loss | E32: =1-SUM(E29:E31) -> -0.19298246 | F32: =1-SUM(F29:F31) -> 0.132 | G32: =SUM(F31:F32) -> 0.148 | I32: assumption: allocate electricity to internal consumption / loss
C33: Input
C34: biomass | D34: 1.14 | E34: 1 | F34: =R61 -> 1 | G34: =F34 -> 1
C37: Plant specs
C38: Plant size (output?) | D38: 15 | E38: MWth
C39: Plant size (feedstock input) | D39: 25 | E39: MWth | F39: in the text, the feedstock input capacity of 25 MWth is mentioned
C40: Full load hours | D40: 7500 | E40: h
C41: Technical lifetime | D41: 30 | E41: y
C43: Investment | D43: =1.68*10^6*D38 -> 25200000 | E43: € | F43: values for 'current' are taken, lower costs in 2030 are expected to be insignificant compared to inflation effect from 2015 unitl now
C44: Fixed O&M | D44: =0.08*D38*10^6 -> 1200000 | E44: €/y
C45: Variable O&M | D45: =0.05*D43 -> 1260000 | E45: €/y
C46: Variable O&M | D46: =D45/D40 -> 168 | E46: €/flh
C49: CO2 emissions
C50: CO2 emissions | D50: 63.39 | E50: kton/PJ pyrolysis oil | N50: Pyrolysis oil production:
C51: CO2 emissions | D51: =D50*10^-3 -> 0.06339 | E51: kg CO2 / MJ pyrolysis oil
N53: Technology | P53: Fast Pyrolysis Bio Oil
N54: year | P54: 2015 | Q54: 2020 | R54: 2030 | S54: 2040 | T54: 2050 | U54: 2020 | V54: 2020 | W54: 2050 | X54: 2050 | Y54: Note | Z54: Ref
N55: est | P55: ctrl | Q55: ctrl | R55: ctrl | S55: ctrl | T55: ctrl | U55: Lower | V55: Upper | W55: Lower | X55: Upper | Y55: - | Z55: -
...
