Workbook
Name exchange_rate_2011_2010: #REF!
Name Final_demand_residences: '[1]Fuel aggregation'!$L$11
Name hours_a_year: #REF!
Name km2_to_m2: #REF!
Name kW_to_MW: #REF!
Name kW_to_W: #REF!
Name kWp_to_MWp: #REF!
Name labor_cost: Notes!#REF!
Name licensing: Notes!#REF!
Name m2_to_km2: #REF!
Name overhead_GA: Notes!#REF!
Name sensitivity_07: '[2]Tornado Charts'!$I$48
Name STC: #REF!
Name STC_insolation: #REF!
Name tax_insurance: Notes!#REF!
Name W_to_MW: #REF!
Name Wp_to_kWp: #REF!
Name WP_to_MWp: #REF!

Sheet Cover sheet
B2: Cover Sheet
B4: Document | C4: energy_production_fractionation_pyrolysis_oil
B5: Author | C5: Kyra de Haan
B6: Organization | C6: Quintel Intelligence
B9: Legend
B11: Cells | C11: Intermediate (calculation)
C12: Result
C13: Manual input
C14: Reference to manual input or data input
B16: Tabs | C16: Introductory
C17: Dashboard
C18: Research data
C19: Sources
C20: Results
C21: Main calculations
C22: Additional calculations
C23: Output to csv

Sheet Dashboard
B2: This sheet summarizes all node attributes formatted in the way they are used by the Energy Transition Model. Use the Excel formulas to find the original data and sources for these numbers. You can also use this document to update the attribute value. Once you have finished updating, save this document and run rake import:node NODE="nodename" to update the node attributes on ETSource.
C9: Attribute | D9: Unit | E9: Value | G9: Definition | I9: Source
C11: Technical
C12: typical_input_capacity | D12: MW | E12: =ROUND(Notes!D6,2) -> 44.22 | I12: energy.nl (TNO)
C13: input.pyrolysis_oil | E13: =ROUND(Notes!E20,53) -> 0.56 | I13: energy.nl (TNO)
C14: input.hydrogen | E14: =ROUND(Notes!E21,53) -> 0.28 | I14: energy.nl (TNO)
C15: input.steam_hot_water | D15: - | E15: =ROUND(Notes!E22,53) -> 0.16 | I15: energy.nl (TNO)
C16: output.kerosene | D16: - | E16: =ROUND(Notes!E17,3) -> 0.328 | I16: energy.nl (TNO), CTM and export from Kalavasta
C17: output.naphtha | D17: - | E17: =ROUND(Notes!E18,3) -> 0.169 | I17: energy.nl (TNO), CTM and export from Kalavasta
C18: full_load_hours | D18: h | E18: =Notes!D7 -> 7500 | I18: energy.nl (TNO)
C19: availability | D19: - | E19: =Notes!D10 -> 0.923 | I19: copied from energy_production_pyrolysis_non_biogenic_waste
C21: Cost
C22: initial_investment | D22: euro | E22: =ROUND(Notes!D12,0) -> 10440000 | G22: Initial investment costs | I22: energy.nl (TNO)
C23: ccs_investment | D23: euro | E23: 0 | I23: No CCS
C24: fixed_operation_and_maintenance_costs_per_year | D24: euro/yr | E24: =ROUND(Notes!D13,0) -> 560000 | G24: Fixed operational and maintenance costs per year (incl. ccs) | I24: energy.nl (TNO)
C25: variable_operation_and_maintenance_costs_per_full_load_hour | D25: euro/flh | E25: =ROUND(Notes!D14,2) -> 69.6 | G25: Variable operation and maintenance costs per flh | I25: energy.nl (TNO)
C26: variable_operation_and_maintenance_costs_for_ccs_per_full_load_hour | D26: euro/flh | E26: 0 | I26: No CCS
C27: cost_of_installing | D27: euro | E27: 0 | G27: Installation costs | I27: No data, assumed zero
C28: decommissioning_costs | D28: euro | E28: 0 | G28: Decommissioning costs | I28: No data, assumed zero
C29: wacc | D29: % | E29: 0.07 | G29: Weighted average cost of capita | I29: See https://docs.energytransitionmodel.com/main/cost-wacc/
C30: takes_part_in_ets | D30: yes=1, no=0 | E30: 1 | I30: Quintel assumption
C32: Other
C33: technical_lifetime | D33: years | E33: =Notes!D8 -> 30 | G33: Technical lifetime of the plant | I33: energy.nl (TNO)
C34: construction_time | D34: years | E34: =Notes!D9 -> 2 | G34: Construction time of the plant | I34: copied from energy_production_pyrolysis_non_biogenic_waste
C35: free_co2_factor | D35: - | E35: 0 | I35: Quintel assumption

Sheet Sources
C3: Definition on the sources
C5: Type | D5: Source | E5: Country | F5: Date published | G5: Subject | H5: Date retrieved | I5: ETM Library URL | J5: Link
B7: Pyrolysis oil production | C7: All specs | D7: TNO - Energy.nl | E7: NL | F7: 2024 | G7: Production of pyrolysis bio-oil from solid biomass via fast pyrolysis | H7: 45888 | J7: https://energy.nl/data/production-of-pyrolysis-bio-oil-from-solid-biomass-via-fast-pyrolysis/
B9: Pyrolysis oil upgrade | C9: All specs | D9: TNO - Energy.nl | E9: NL | F9: 2024 | G9: Upgrade of pyrolysis bio-oil from fast pyrolysis to biofuels | H9: 45888 | J9: https://energy.nl/data/upgrade-of-pyrolysis-bio-oil-from-fast-pyrolysis-to-biofuels/

Sheet Notes
C3: Source | D3: Page | E3: Notes
C5: Overview
C6: Input capacity | D6: =D45/(1-E35) -> 44.22 | E6: MW
C7: Full load hours | D7: =D62 -> 7500 | E7: hours | N7: Pyrolysis oil fractionation, from energy.nl:
C8: Technical lifetime | D8: =D47 -> 30 | E8: y
C9: Construction period | D9: 2 | E9: y | F9: copied from energy_production_pyrolysis_non_biogenic_waste
C10: availability | D10: 0.923 | F10: copied from energy_production_pyrolysis_non_biogenic_waste
C12: Investment | D12: =F54 -> 10440000 | E12: euro
C13: Fixed O&M | D13: =F55 -> 560000 | E13: euro/y
C14: Variable O&M | D14: =F57 -> 69.6 | E14: euro/flh
C16: Input/output | D16: value | E16: corrected value
C17: output.kerosene | D17: =E33 -> 0.32835821 | E17: =D17 -> 0.32835821
C18: output.naphtha | D18: =E34 -> 0.16915423 | E18: =D18 -> 0.16915423
C19: output.loss | D19: =E35 -> 0.50248756 | E19: =D19 -> 0.50248756
C20: input.pyrolysis_oil | D20: =E38 -> 0.56218905 | E20: 0.56 | F20: input values slightly tweaked to get the same ratio pyrolysis oil / steam hot water as pyrolysis process
C21: input.hydrogen | D21: =E39 -> 0.28855721 | E21: =1-(E20+E22) -> 0.28 | G21: ratio | H21: =E20/E22 -> 3.5
C22: input.steam_hot_water | D22: =E40 -> 0.14925373 | E22: 0.16
C25: In- and output fractions
C26: Based on specs from energy.nl and output of the CTM
C27: energy.nl assumes that output of biofuels is composed of diesel and gasoline
C28: The CTM focusees on output of kerosene and naphtha, as these are considered to be more relevant fuels in the future.
C29: According to an expert from Kalavasta (maintainer of the CTM), the output of gasoline (which is reported in specs from energy.nl) can be considered a product with carbon range similar to gasoline, but this can also be considered as naphtha
C30: Therefore, the output fractions are aligned with the output fractions from the CTM (see table)
C32: Output | D32: Original | E32: Converted to output for 1 PJ input
C33: kerosene | D33: 0.66 | E33: =D33/$D$41 -> 0.32835821
C34: naphtha | D34: 0.34 | E34: =D34/$D$41 -> 0.16915423
C35: loss | E35: =1-SUM(E33:E34) -> 0.50248756
C36: total | D36: =SUM(D33:D35) -> 1 | E36: =SUM(E33:E35) -> 1
C37: Input
C38: pyrolysis oil | D38: 1.13 | E38: =D38/$D$41 -> 0.56218905
C39: hydrogen | D39: 0.58 | E39: =D39/$D$41 -> 0.28855721
C40: steam | D40: 0.3 | E40: =D40/$D$41 -> 0.14925373
C41: total | D41: =SUM(D38:D40) -> 2.01 | E41: =SUM(E38:E40) -> 1
C43: Plant specs
C44: based on energy.nl
C45: Plant size (output) | D45: 22 | E45: MW
C46: Full load hours | D46: 7500 | E46: h
C47: Technical lifetime | D47: 30 | E47: y
C49: Costs
C50: Note that costs from energy.nl include both pyrolysis and hydrotreating system to final products.
...
