Workbook
Name exchange_rate_2011_2010: #REF!
Name Final_demand_residences: #REF!
Name hours_a_year: #REF!
Name km2_to_m2: #REF!
Name kW_to_MW: #REF!
Name kW_to_W: #REF!
Name kWp_to_MWp: #REF!
Name m2_to_km2: #REF!
Name STC: #REF!
Name STC_insolation: #REF!
Name W_to_MW: #REF!
Name Wp_to_kWp: #REF!
Name WP_to_MWp: #REF!

Sheet Cover sheet
B2: Cover Sheet
B4: Document | C4: energy_production_hvo_bio_kerosene.ad
B5: Author | C5: Kyra de Haan
B6: Organization | C6: Quintel Intelligence
B9: Legend
B11: Cells | C11: Intermediate (calculation)
C12: Result
C13: Manual input
C14: Reference to manual input or data input
B16: Tabs | C16: Introductory
C17: Dashboard
C18: Research data
C19: Sources
C20: Results
C21: Main calculations
C22: Additional calculations
C23: Output to csv

Sheet Dashboard
B2: This sheet summarizes all node attributes formatted in the way they are used by the Energy Transition Model. Use the Excel formulas to find the original data and sources for these numbers. You can also use this document to update the attribute value. Once you have finished updating, save this document and run rake import:node NODE="nodename" to update the node attributes on ETSource.
C9: Attribute | D9: Unit | E9: Value | G9: Definition | I9: Source
C11: Technical
C12: typical_input_capacity | D12: MW | E12: ='Research data'!F7 -> 953.68 | I12: Danish Energy Agency
C13: input.oily_biomass | D13: - | E13: ='Research data'!F8 -> 0.779 | I13: Danish Energy Agency
C14: input.hydrogen | D14: - | E14: ='Research data'!F9 -> 0.099 | I14: Danish Energy Agency
C15: input.network_gas | D15: - | E15: ='Research data'!F10 -> 0.122 | I15: Danish Energy Agency
C16: output.bio_kerosene | D16: - | E16: ='Research data'!F11 -> 0.835 | I16: Danish Energy Agency
C17: output.bionaphtha | D17: - | E17: ='Research data'!F12 -> 0.082 | I17: Danish Energy Agency
C18: full_load_hours | D18: h | E18: ='Research data'!F14 -> 8000 | I18: Danish Energy Agency
C19: availability | D19: - | E19: ='Research data'!F15 -> 0.962
C21: Cost
C22: initial_investment | D22: euro | E22: ='Research data'!F18 -> 754027929 | G22: Initial investment costs | I22: Danish Energy Agency
C23: ccs_investment | D23: euro | E23: ='Research data'!F19 -> 0 | I23: -
C24: fixed_operation_and_maintenance_costs_per_year | D24: euro/yr | E24: ='Research data'!F20 -> 33144935 | G24: Fixed operational and maintenance costs per year (incl. ccs) | I24: Danish Energy Agency
C25: variable_operation_and_maintenance_costs_per_full_load_hour | D25: euro/flh | E25: ='Research data'!F21 -> 7909.52 | G25: Variable operation and maintenance costs per flh | I25: Danish Energy Agency
C26: variable_operation_and_maintenance_costs_for_ccs_per_full_load_hour | D26: euro/flh | E26: ='Research data'!F22 -> 0 | I26: -
C27: cost_of_installing | D27: euro | E27: ='Research data'!F23 -> 0 | G27: Installation costs | I27: -
C28: decommissioning_costs | D28: euro | E28: ='Research data'!F24 -> 0 | G28: Decommissioning costs | I28: -
C29: wacc | D29: % | E29: 0.07 | G29: Weighted average cost of capita | I29: See https://docs.energytransitionmodel.com/main/cost-wacc/
C30: takes_part_in_ets | D30: yes=1, no=0 | E30: 1 | I30: Quintel assumption
C32: Other
C33: technical_lifetime | D33: years | E33: ='Research data'!F28 -> 25 | G33: Technical lifetime of the plant | I33: Danish Energy Agency
C34: construction_time | D34: years | E34: ='Research data'!F29 -> 2 | G34: Construction time of the plant | I34: Danish Energy Agency
C35: free_co2_factor | D35: - | E35: ='Research data'!F30 -> 0 | I35: -

Sheet Research data
C4: Attribute | D4: Unit | F4: Values | H4: DEA | K4: Comments
C6: Technical
C7: typical_input_capacity | D7: MW | F7: =ROUND(H7,2) -> 953.68 | H7: =Notes!B2 -> 953.67847
C8: input.oily_biomass | D8: - | F8: =ROUND(H8,3) -> 0.779 | H8: =Notes!B8 -> 0.779
C9: input.hydrogen | D9: - | F9: =ROUND(H9,3) -> 0.099 | H9: =Notes!B9 -> 0.099
C10: input.network_gas | D10: - | F10: =ROUND(H10,3) -> 0.122 | H10: =Notes!B10 -> 0.122
C11: output.bio_kerosene | D11: - | F11: =ROUND(H11,3) -> 0.835 | H11: =Notes!B11 -> 0.83512619
C12: output.bionaphtha | F12: =ROUND(H12,3) -> 0.082 | H12: =Notes!B12 -> 0.082373811
C13: output.loss | D13: - | F13: =ROUND(H13,3) -> 0.082 | H13: =Notes!B13 -> 0.0825
C14: full_load_hours | D14: hrs/yr | F14: =ROUND(H14,2) -> 8000 | H14: =Notes!B3 -> 8000
C15: availability | F15: =ROUND(H15,3) -> 0.962 | H15: =Notes!B4 -> 0.96153846
C17: Cost
C18: initial_investment | D18: euro | F18: =ROUND(H18,0) -> 754027929 | H18: =Notes!B15 -> 7.5402793e+08
C19: ccs_investment | D19: euro | F19: =ROUND(H19,0) -> 0 | H19: 0
C20: fixed_operation_and_maintenance_costs_per_year | D20: euro/yr | F20: =ROUND(H20,0) -> 33144935 | H20: =Notes!B16 -> 33144935
C21: variable_operation_and_maintenance_costs_per_full_load_hour | D21: euro/flh | F21: =ROUND(H21,2) -> 7909.52 | H21: =Notes!B17 -> 7909.5235
C22: variable_operation_and_maintenance_costs_for_ccs_per_full_load_hour | D22: euro/flh | F22: =H22 -> 0 | H22: 0
C23: cost_of_installing | D23: euro | F23: =H23 -> 0 | H23: 0
C24: decommissioning_costs | D24: euro | F24: =H24 -> 0 | H24: 0
C25: takes_part_in_ets | D25: yes=1, no=0 | F25: =H25 -> 0 | H25: 0
C27: Other
C28: technical_lifetime | D28: years | F28: =H28 -> 25 | H28: =Notes!B5 -> 25
C29: construction_time | D29: years | F29: =H29 -> 2 | H29: =Notes!B6 -> 2
C30: free_co2_factor | D30: - | F30: 0 | H30: 0

Sheet Sources
C3: Definition on the sources
C5: Type | D5: Source | E5: Country | F5: Date published | G5: Subject | H5: Date retrieved | I5: ETM Library URL | J5: Link
C7: HVO jet fuel | D7: Danish Energy Agency | E7: DK | F7: 2025 | G7: Renewable fuels: Technology descriptions and projections for long-term energy system planning | H7: 45887 | I7: https://refman.energytransitionmodel.com/publications/2218
D8: Danish Energy Agency | E8: DK | F8: 2025 | G8: Data Sheets for energy carrier generation and conversion | H8: 45887 | I8: https://refman.energytransitionmodel.com/publications/2219

Sheet Notes
A1: Overview
A2: typical input capacity | B2: =B40/(1-C34) -> 953.67847 | C2: MW
A3: full load hours | B3: =B41 -> 8000 | C3: hrs
A4: availability | B4: =B43 -> 0.96153846 | N4: Data from Danish Energy Agency HVO jet ffuel:
A5: technical lifetime | B5: =B44 -> 25 | C5: yr | N5: Technology | P5: HVO Jet Fuel
A6: construction time | B6: =B45 -> 2 | C6: yr | N6: year | P6: 2015 | Q6: 2020 | R6: 2030 | S6: 2040 | T6: 2050 | U6: 2020 | V6: 2020 | W6: 2050 | X6: 2050 | Y6: Note | Z6: Ref
N7: est | P7: ctrl | Q7: ctrl | R7: ctrl | S7: ctrl | T7: ctrl | U7: Lower | V7: Upper | W7: Lower | X7: Upper | Y7: - | Z7: -
A8: input.oily_biomass | B8: =C24 -> 0.779 | N8: cat | O8: par
A9: input.hydrogen | B9: =C25 -> 0.099 | N9: Energy/technical data
A10: input.network_gas | B10: =C26 -> 0.122 | O10: Typical total plant size [1,000 t HVO/year] | P10: 400 | Q10: 400 | R10: 600 | S10: 700 | T10: 800 | U10: 0.5 | V10: 2 | W10: 0.5 | X10: 1 | Y10: A, B
A11: output.bio_kerosene | B11: =C29 -> 0.83512619 | O11: Typical total plant size MW HVO [MW] | P11: 580 | Q11: 580 | R11: 875 | S11: 1020 | T11: 1165 | U11: 0.5 | V11: 2 | W11: 0.5 | X11: 1 | Y11: A, A1, B
A12: output.bionaphtha | B12: =C30 -> 0.082373811 | O12: Input
A13: output.loss | B13: =C34 -> 0.0825 | O13: Feedstock Consumption [MWh/MWh Total Inputs] | P13: 0.779 | Q13: 0.779 | R13: 0.779 | S13: 0.779 | T13: 0.779 | U13: 0.9 | V13: 1.1 | W13: 0.9 | X13: 1.1 | Y13: C, G | Z13: 2,3
O14: Hydrogen Consumption [MWh/MWh Total Inputs] | P14: 0.099 | Q14: 0.099 | R14: 0.099 | S14: 0.099 | T14: 0.099 | U14: 0.9 | V14: 1.1 | W14: 0.9 | X14: 1.1 | Y14: C,D, G | Z14: 2,3
A15: investment costs | B15: =B47 -> 7.5402793e+08 | C15: € | O15: Electricity Consumption [MWh/MWh Total Inputs] | P15: 0.003 | Q15: 0.003 | R15: 0.003 | S15: 0.003 | T15: 0.003 | U15: 0.9 | V15: 1.1 | W15: 0.9 | X15: 1.1 | Y15: C, G | Z15: 2,3
A16: fixed O&M | B16: =B48 -> 33144935 | C16: €/y | O16: Natural Gas Consumption [MWh/MWh Total Inputs] | P16: 0.119 | Q16: 0.119 | R16: 0.119 | S16: 0.119 | T16: 0.119 | U16: 0.9 | V16: 1.1 | W16: 0.9 | X16: 1.1 | Y16: C, G | Z16: 2,3
A17: variable O&M | B17: =B50 -> 7909.5235 | C17: €/flh | O17: Output
O18: HVO Jet Output [MWh/MWh Total Input] | P18: 0.66 | Q18: 0.66 | R18: 0.66 | S18: 0.66 | T18: 0.66 | U18: 0.9 | V18: 1.1 | W18: 0.9 | X18: 1.1 | Y18: C, H
O19: Naphta Output [MWh/MWh Total Input] | P19: 0.0651 | Q19: 0.0651 | R19: 0.0651 | S19: 0.0651 | T19: 0.0651 | U19: 0.9 | V19: 1.1 | W19: 0.9 | X19: 1.1 | Y19: C, H
A20: Data from Danish Energy Agency | O20: LPG Output [MWh/MWh Total Input] | P20: 0.0924 | Q20: 0.0924 | R20: 0.0924 | S20: 0.0924 | T20: 0.0924 | U20: 0.9 | V20: 1.1 | W20: 0.9 | X20: 1.1 | Y20: C, H
O21: Fuel Gas Output [MWh/MWh Total Input] | P21: 0.1 | Q21: 0.1 | R21: 0.1 | S21: 0.1 | T21: 0.1 | U21: 0.9 | V21: 1.1 | W21: 0.9 | X21: 1.1 | Y21: C, H
A22: Data based on specs table: | O22: District Heating Output [MWh/MWh Total input] | P22: =0.177*0.15 -> 0.02655 | Q22: =0.177*0.15 -> 0.02655 | R22: =0.177*0.15 -> 0.02655 | S22: =0.177*0.15 -> 0.02655 | T22: =0.177*0.15 -> 0.02655 | U22: 0.9 | V22: 1.1 | W22: 0.9 | X22: 1.1 | Y22: C, H
A23: feedstock | B23: original | C23: corrected for 1 MJ input | O23: Forced outage [%] | P23: 0 | Q23: 0 | R23: 0 | S23: 0 | T23: 0 | Y23: I
A24: input.oily_biomass | B24: =R13 -> 0.779 | C24: =B24 -> 0.779 | O24: Planned outage [weeks per year] | P24: 2 | Q24: 2 | R24: 2 | S24: 2 | T24: 2
A25: input.hydrogen | B25: =R14 -> 0.099 | C25: =B25 -> 0.099 | O25: Technical lifetime [years] | P25: 25 | Q25: 25 | R25: 25 | S25: 25 | T25: 25
A26: input.network_gas | B26: =R16 -> 0.119 | C26: =B26+B27 -> 0.122 | O26: Construction time [years] | P26: 2 | Q26: 2 | R26: 2 | S26: 2 | T26: 2
A27: input.electricity | B27: =R15 -> 0.003 | E27: Quintel assumption: minimal electricity input ignored, input share added to network gas | N27: Financial data
A28: total | B28: =SUM(B24:B27) -> 1 | C28: =SUM(C24:C26) -> 1 | O28: Specific investment [M €/MW HVO Jet] | P28: 1.0191115 | Q28: 1.0191115 | R28: 0.86176831 | S28: 0.80276275 | T28: 0.75868235 | U28: 0.5 | V28: 1.5 | W28: 0.5 | X28: 1.5 | Y28: A, E, J, L
A29: output.bio_kerosene | B29: =R18 -> 0.66 | C29: =B29+SUM($B$31:$B$32)*B29/SUM($B$29:$B$30) -> 0.83512619 | O29: -equipment [%] | P29: 75 | Q29: 75 | R29: 75 | S29: 75 | T29: 75 | U29: 0 | V29: 0 | W29: 0 | X29: 0
A30: output.bionaphtha | B30: =R19 -> 0.0651 | C30: =B30+SUM($B$31:$B$32)*B30/SUM($B$29:$B$30) -> 0.082373811 | O30: - installation [%] | P30: 25 | Q30: 25 | R30: 25 | S30: 25 | T30: 25 | U30: 0 | V30: 0 | W30: 0 | X30: 0
A31: output LPG | B31: =R20 -> 0.0924 | C31: 0 | E31: Bio-LPG not modelled, therefore other fuel output proportionally increased | O31: Fixed O&M [M €/MW/year] | P31: 0.038097627 | Q31: 0.038097627 | R31: 0.037879926 | S31: 0.037910873 | T31: 0.037934117 | U31: 0.9 | V31: 1.1 | W31: 0.9 | X31: 1.1 | Y31: F, K, L
A32: output fuel gas | B32: =R21 -> 0.1 | C32: 0 | E32: DEA report states that fuel gas can be used as fuel, but not modelled in ETM. Therefore, other fuel output proportionally increased | O32: Variable O&M [€/MWh] | P32: 9.0394554 | Q32: 9.0394554 | R32: 9.0394554 | S32: 9.0394554 | T32: 9.0394554 | U32: 0.9 | V32: 1.1 | W32: 0.9 | X32: 1.1 | Y32: F, K, L
A33: output district heating | B33: =R22 -> 0.02655 | C33: 0 | E33: Minor heat output ignored, considered loss | O33: Start-up [M €/1,000 t HVO Jet] | P33: 0 | Q33: 0 | R33: 0 | S33: 0 | T33: 0 | U33: 0 | V33: 0 | W33: 0 | X33: 0
A34: output.loss | B34: =1-SUM(B29:B33) -> 0.05595 | C34: =B34+B33 -> 0.0825 | N34: Technology-specific data
A35: total | B35: =SUM(B29:B34) -> 1 | C35: 1 | O35: Specific energy content [GJ/ton] | P35: 44 | Q35: 44 | R35: 44 | S35: 44 | T35: 44
O36: Specific density [kg/l] or [ton/m3] | P36: 0.77 | Q36: 0.77 | R36: 0.77 | S36: 0.77 | T36: 0.77
O37: Specific investment [M €/1000 t HVO Jet] | P37: 1.4776738 | Q37: 1.4776738 | R37: 1.2567132 | S37: 1.16971 | T37: 1.1048028 | U37: 0.5 | V37: 1.5 | W37: 0.5 | X37: 1.5 | Y37: A, E, J, L
A38: Plant specs | O38: -equipment [%] | P38: 75 | Q38: 75 | R38: 75 | S38: 75 | T38: 75
A39: Plant size (output) | B39: =R10*10^3 -> 600000 | C39: kg HVO/yr | O39: - installation [%] | P39: 25 | Q39: 25 | R39: 25 | S39: 25 | T39: 25
A40: Plant size (output) | B40: =R11 -> 875 | C40: MW | O40: Fixed O&M [M €/1,000 t HVO] | P40: 0.055240141 | Q40: 0.055240141 | R40: 0.055240141 | S40: 0.055240141 | T40: 0.055240141 | U40: 0.9 | V40: 1.1 | W40: 0.9 | X40: 1.1 | Y40: F, K, L
...
