Workbook
Name exchange_rate_2011_2010: #REF!
Name Final_demand_residences: '[1]Fuel aggregation'!$L$11
Name hours_a_year: #REF!
Name km2_to_m2: #REF!
Name kW_to_MW: #REF!
Name kW_to_W: #REF!
Name kWp_to_MWp: #REF!
Name labor_cost: Notes!#REF!
Name licensing: Notes!#REF!
Name m2_to_km2: #REF!
Name overhead_GA: Notes!#REF!
Name sensitivity_07: '[2]Tornado Charts'!$I$48
Name STC: #REF!
Name STC_insolation: #REF!
Name tax_insurance: Notes!#REF!
Name W_to_MW: #REF!
Name Wp_to_kWp: #REF!
Name WP_to_MWp: #REF!

Sheet Cover sheet
B2: Cover Sheet
B4: Document | C4: energy_production_fischer_tropsch_synthetic_dispatchable | E4: Note: the same technical and financial specs as energy_production_fischer_tropsch_synthetic_must_run are used
B5: Author | C5: Kyra de Haan
B6: Organization | C6: Quintel Intelligence
B9: Legend
B11: Cells | C11: Intermediate (calculation)
C12: Result
C13: Manual input
C14: Reference to manual input or data input
B16: Tabs | C16: Introductory
C17: Dashboard
C18: Research data
C19: Sources
C20: Results
C21: Main calculations
C22: Additional calculations
C23: Output to csv

Sheet Dashboard
B2: This sheet summarizes all node attributes formatted in the way they are used by the Energy Transition Model. Use the Excel formulas to find the original data and sources for these numbers. You can also use this document to update the attribute value. Once you have finished updating, save this document and run rake import:node NODE="nodename" to update the node attributes on ETSource.
C9: Attribute | D9: Unit | E9: Value | G9: Definition | I9: Source
C11: Technical
C12: typical_input_capacity | D12: MWe | E12: =ROUND(Notes!F6,3) -> 288.444 | I12: Danish Energy Agency
C13: input.hydrogen | D13: - | E13: =ROUND(Notes!F20,5) -> 0.995 | I13: Danish Energy Agency
C14: input.electricity | D14: - | E14: =ROUND(Notes!F21,5) -> 0.005 | I14: Danish Energy Agency
C15: output.kerosene | D15: - | E15: =ROUND(Notes!F17,5) -> 0.525 | I15: Danish Energy Agency
C16: output.gasoline | D16: - | E16: =ROUND(Notes!F18,5) -> 0.175 | I16: Danish Energy Agency
C17: full_load_hours | D17: - | E17: =Notes!F7 -> 8000 | I17: Danish Energy Agency
C18: availability | D18: - | E18: =ROUND(Notes!F10,5) -> 0.94231 | I18: Danish Energy Agency
C20: Cost
C21: initial_investment | D21: euro | E21: =ROUND(Notes!F12,0) -> 871988000 | G21: Initial investment costs | I21: Danish Energy Agency
C22: ccs_investment | D22: euro | E22: 0 | I22: no CCS
C23: fixed_operation_and_maintenance_costs_per_year | D23: euro/yr | E23: =ROUND(Notes!F13,0) -> 2214850 | G23: Fixed operational and maintenance costs per year (incl. ccs) | I23: Danish Energy Agency
C24: variable_operation_and_maintenance_costs_per_full_load_hour | D24: euro/flh | E24: =ROUND(Notes!F14,2) -> 91.56 | G24: Variable operation and maintenance costs per flh | I24: Danish Energy Agency
C25: variable_operation_and_maintenance_costs_for_ccs_per_full_load_hour | D25: euro/flh | E25: 0 | I25: no CCS
C26: cost_of_installing | E26: 0 | G26: Installation costs | I26: No data available, assumed to be part of initial investment
C27: decommissioning_costs | E27: 0 | G27: Decommissioning costs | I27: No data available, assumed to be part of initial investment
C28: wacc | D28: % | E28: 0.07 | G28: Weighted average cost of capita | I28: See https://github.com/quintel/documentation/blob/master/general/cost_calculations.md#weighted-average-cost-of-capital
C29: takes_part_in_ets | D29: yes=1, no=0 | E29: 1 | I29: Quintel assumption
C31: Other
C32: technical_lifetime | D32: years | E32: =Notes!F8 -> 25 | G32: Technical lifetime of the plant | I32: Danish Energy Agency
C33: construction_time | D33: years | E33: =Notes!F9 -> 2 | G33: Construction time of the plant | I33: Danish Energy Agency
C34: free_co2_factor | D34: - | E34: 0 | I34: Quintel assumption
C35: co2_utilisation_per_mj | D35: kg CO2/MJ | E35: =ROUND(Notes!F49,5) -> 0.09038 | G35: CO2 utilisation per MJ product output | I35: Danish Energy Agency

Sheet Sources
C3: Definition on the sources
C5: Type | D5: Source | E5: Country | F5: Date published | G5: Subject | H5: Date retrieved | I5: ETM Library URL | J5: Link
C7: All specs | D7: Danish Energy Agency | E7: DK | F7: 2025 | G7: Renewable fuels: Technology descriptions and projections for long-term energy system planning | H7: 45951 | I7: https://refman.energytransitionmodel.com/publications/2218
D8: Danish Energy Agency | E8: DK | F8: 2025 | G8: Data Sheets for energy carrier generation and conversion | H8: 45951 | I8: https://refman.energytransitionmodel.com/publications/2219

Sheet Notes
C3: Source | D3: Page | E3: Notes
C5: Danish Energy Agency | E5: Overview | O5: Hydrogen and CO2 to Fischer Tropsch, from DEA:
E6: Input capacity | F6: =T12/(1-F32) -> 288.44444 | G6: MW | H6: note: in line with the input capacity of other Fischer-Tropsch technologies, the input capacity is now based on the 2050 value | O6: Technology | Q6: Hydrogen to Jet Fuel
E7: Full load hours | F7: =F57 -> 8000 | G7: hours | H7: otherwise, the input capacity would be significantly lower is the 2030 value would've been taken | O7: year | Q7: 2020 | R7: 2030 | S7: 2040 | T7: 2050 | U7: 2020 | V7: 2020 | W7: 2050 | X7: 2050 | Y7: Note | Z7: Ref
E8: Technical lifetime | F8: =F58 -> 25 | G8: y | O8: est | Q8: ctrl | R8: ctrl | S8: ctrl | T8: ctrl | U8: Lower | V8: Upper | W8: Lower | X8: Upper | Y8: - | Z8: -
E9: Construction period | F9: =F59 -> 2 | G9: y | O9: cat | P9: par
E10: Availability | F10: =F60 -> 0.94230769 | O10: Energy/technical data
P11: Typical total plant size [1,000 kt FT Liquids/year] | Q11: 2 | R11: 13 | S11: 41 | T11: 165 | U11: 0.5 | V11: 1.5 | W11: 0.5 | X11: 1.5 | Y11: A, B, | Z11: 18, 20, 23
E12: Investment | F12: =F62 -> 871988000 | G12: euro | P12: Typical total plant size [MW] Output | Q12: 3.1 | R12: 20.5 | S12: 64.5 | T12: 259.6 | U12: 0.5 | V12: 1.5 | W12: 0.5 | X12: 1.5 | Y12: A,B,C | Z12: 18, 20
E13: Fixed O&M | F13: =F63 -> 2214849.5 | G13: euro/y | P13: Input
E14: Variable O&M | F14: =F65 -> 91.55874 | G14: euro/flh | P14: CO2 Consumption [t/t FT Liquids] | Q14: 4.3 | R14: 3.9 | S14: 3.6 | T14: 3.3 | U14: 1 | V14: 1.1 | W14: 1 | X14: 1.1 | Y14: C, D, E
P15: Hydrogen Consumption [MWh/MWh Total Input] | Q15: 0.995 | R15: 0.995 | S15: 0.995 | T15: 0.995 | U15: 0.75 | V15: 1.25 | W15: 0.75 | X15: 1.25 | Y15: E
E16: Input/output | P16: Power Consumption [MWh/MWh Total Input] | Q16: 0.005 | R16: 0.005 | S16: 0.005 | T16: 0.005 | U16: 0.75 | V16: 1.25 | W16: 0.75 | X16: 1.25 | Y16: E
E17: output.kerosene | F17: =H40 -> 0.525 | P17: Output
E18: output.gasoline | F18: =H41 -> 0.175 | P18: FT Liquids Output [MWh/MWh Total Input] | Q18: 0.65 | R18: 0.7 | S18: 0.73 | T18: 0.75 | U18: 0.8 | V18: 1.2 | W18: 0.8 | X18: 1.2 | Y18: F, G, O | Z18: 20, 18
E19: output.loss | F19: =G32 -> 0.3 | P19: District Heating Output [MWh/MWh Total Input] | Q19: 0.25 | R19: 0.2 | S19: 0.17 | T19: 0.15 | U19: 0.8 | V19: 1.2 | W19: 0.8 | X19: 1.2 | Y19: H
E20: input.hydrogen | F20: =F26 -> 0.995 | P20: Forced outage [%] | Q20: 0 | R20: 0 | S20: 0 | T20: 0 | Y20: I
E21: input.electricity | F21: =F27 -> 0.005 | P21: Planned outage [weeks per year] | Q21: 3 | Z21: 18
P22: Technical lifetime [years] | Q22: 25
P23: Construction time [years] | Q23: 2
E24: Feedstock in- and output | O24: Financial data
E25: input | F25: original | G25: corrected | P25: Specific investment [M€/MW Liquids/year] | Q25: 2.23314 | R25: 1.70144 | S25: 1.16974 | T25: 0.95706 | U25: 0.75 | V25: 1.5 | W25: 0.75 | X25: 1.25 | Y25: G, J | Z25: 18, 20, 26, 30
E26: hydrogen | F26: =R15 -> 0.995 | G26: =F26 -> 0.995 | P26: - equipment [%] | Q26: 75 | R26: 75 | S26: 75 | T26: 75 | Y26: K
E27: electricity | F27: =R16 -> 0.005 | G27: =F27 -> 0.005 | P27: - installation [%] | Q27: 25 | R27: 25 | S27: 25 | T27: 25
E28: total | F28: =SUM(F26:F27) -> 1 | G28: =SUM(G26:G27) -> 1 | P28: Fixed O&M [€/MWH Liquids] | Q28: 17.97146 | R28: 13.50518 | S28: 9.0389 | T28: 7.86916 | U28: 0.9 | V28: 1.1 | W28: 0.9 | X28: 1.1 | Y28: L | Z28: 18
E29: output | P29: Variable O&M [€/MWH Liquids] | Q29: 5.63602 | R29: 4.46628 | S29: 3.40288 | T29: 2.23314 | U29: 0.9 | V29: 1.1 | W29: 0.9 | X29: 1.1 | Y29: M | Z29: 26
E30: FT liquids | F30: =R18 -> 0.7 | G30: =F30 -> 0.7 | P30: Start up [€/l FT Liquids] | Q30: 0 | R30: 0 | S30: 0 | T30: 0
E31: District heating output | F31: =R19 -> 0.2 | O31: Technology-specific data
E32: loss | F32: =1-SUM(F30:F31) -> 0.1 | G32: =1-G30 -> 0.3 | P32: Specific investment [€/l FT Liquids/year] | Q32: 3.50913 | R32: 2.6584318 | S32: 1.8077336 | T32: 1.4887218 | U32: 0.75 | V32: 1.5 | W32: 0.75 | X32: 1.25 | Y32: G, J | Z32: 18, 20, 26, 30
P33: - equipment [%] | Q33: 75 | R33: 75 | S33: 75 | T33: 75 | Y33: K
E34: Composition of FT liquids | P34: - installation [%] | Q34: 25 | R34: 25 | S34: 25 | T34: 25
E35: See note at bottom of the table: | P35: Fixed O&M [€/l FT Liquids] | Q35: 0.17013964 | R35: 0.12760473 | S35: 0.085069818 | T35: 0.07443609 | U35: 0.9 | V35: 1.1 | W35: 0.9 | X35: 1.1 | Y35: L | Z35: 18
E36: =P54 -> O. A reasonable distribution of the FT fuels might be 60% jet fuel, 20% gasoline, and 20% lighter products (LPG and fuel gas), but the distribution of outputs could be very different depending on the plant design, catalyst and the operating conditions. | P36: Variable O&M [€/l FT Liquids] | Q36: 0.053168636 | R36: 0.042534909 | S36: 0.031901182 | T36: 0.021267454 | U36: 0.9 | V36: 1.1 | W36: 0.9 | X36: 1.1 | Y36: M | Z36: 26
E37: It is assumed that these percentages are based on energy value (MJ) in the total FT liquids output | P37: Start up [€/l FT Liquids] | Q37: 0 | R37: 0 | S37: 0 | T37: 0
E39: output | F39: MJ | G39: converted to 0.7 MJ FT liquids | H39: corrected | O39: Notes:
E40: kerosene | F40: =0.6 -> 0.6 | G40: =$F$30*F40 -> 0.42 | H40: =G40+$G$42*G40/SUM($G$40:$G$41) -> 0.525 | P40: A. The plant size range is based on the Schmidt and Mortensen reports and other analysis in the literature. Scale up is our assumption.
E41: gasoline | F41: 0.2 | G41: =$F$30*F41 -> 0.14 | H41: =G41+$G$42*G41/SUM($G$40:$G$41) -> 0.175 | P41: B. CO2 availability is likely to determine the maximum plant size.
E42: lighter products | F42: 0.2 | G42: =$F$30*F42 -> 0.14 | H42: 0 | I42: lighter products not specified further in specific fractions per carrier; | P42: C. Conversion to MW is based on 8,000 operating hours per year and the energy output in all liquid fuels. The conversion is rounded. Some reports are based on only 4,000 hours of operation. Figure 1-2 utilizes the 2050 estimates.
E43: total | F43: =SUM(F40:F42) -> 1 | G43: =SUM(G40:G42) -> 0.7 | H43: =SUM(H40:H42) -> 0.7 | I43: assumption: ligther products assumed zero, kerosene / gasoline output increased proportionally | P43: D. Carbon efficiency in the literature ranges from 75 to 95%. Assuming that the early plants have low carbon efficiency and increase over time.
P44: E. Denominator of FT liquids is the total liquid fuel output.
...
