Workbook
Name exchange_rate_2011_2010: #REF!
Name Final_demand_residences: #REF!
Name hours_a_year: #REF!
Name km2_to_m2: #REF!
Name kW_to_MW: #REF!
Name kW_to_W: #REF!
Name kWp_to_MWp: #REF!
Name m2_to_km2: #REF!
Name STC: #REF!
Name STC_insolation: #REF!
Name W_to_MW: #REF!
Name Wp_to_kWp: #REF!
Name WP_to_MWp: #REF!

Sheet Cover sheet
B2: Cover Sheet
B4: Document | C4: energy_production_hvo_biodiesel.ad
B5: Author | C5: Kyra de Haan
B6: Organization | C6: Quintel Intelligence
B9: Legend
B11: Cells | C11: Intermediate (calculation)
C12: Result
C13: Manual input
C14: Reference to manual input or data input
B16: Tabs | C16: Introductory
C17: Dashboard
C18: Research data
C19: Sources
C20: Results
C21: Main calculations
C22: Additional calculations
C23: Output to csv

Sheet Dashboard
B2: This sheet summarizes all node attributes formatted in the way they are used by the Energy Transition Model. Use the Excel formulas to find the original data and sources for these numbers. You can also use this document to update the attribute value. Once you have finished updating, save this document and run rake import:node NODE="nodename" to update the node attributes on ETSource.
C9: Attribute | D9: Unit | E9: Value | G9: Definition | I9: Source
C11: Technical
C12: typical_input_capacity | D12: MW | E12: ='Research data'!E7 -> 1126.47 | I12: Danish Energy Agency
C13: input.oily_biomass | D13: - | E13: ='Research data'!E8 -> 0.881 | I13: Danish Energy Agency
C14: input.hydrogen | D14: - | E14: ='Research data'!E9 -> 0.119 | I14: Danish Energy Agency
C15: output.biodiesel | D15: - | E15: ='Research data'!E10 -> 0.906 | I15: Danish Energy Agency
C16: output.bionaphtha | D16: - | E16: ='Research data'!E11 -> 0.07 | I16: Danish Energy Agency
C17: full_load_hours | D17: h | E17: ='Research data'!E13 -> 8000 | I17: Danish Energy Agency
C18: availability | D18: - | E18: ='Research data'!E14 -> 0.962
C20: Cost
C21: initial_investment | D21: euro | E21: ='Research data'!E17 -> 745741908 | G21: Initial investment costs | I21: Danish Energy Agency
C22: ccs_investment | D22: euro | E22: ='Research data'!E18 -> 0 | I22: -
C23: fixed_operation_and_maintenance_costs_per_year | D23: euro/yr | E23: ='Research data'!E19 -> 41431169 | G23: Fixed operational and maintenance costs per year (incl. ccs) | I23: Danish Energy Agency
C24: variable_operation_and_maintenance_costs_per_full_load_hour | D24: euro/flh | E24: ='Research data'!E20 -> 7200 | G24: Variable operation and maintenance costs per flh | I24: Danish Energy Agency
C25: variable_operation_and_maintenance_costs_for_ccs_per_full_load_hour | D25: euro/flh | E25: ='Research data'!E21 -> 0 | I25: -
C26: cost_of_installing | D26: euro | E26: ='Research data'!E22 -> 0 | G26: Installation costs | I26: -
C27: decommissioning_costs | D27: euro | E27: ='Research data'!E23 -> 0 | G27: Decommissioning costs | I27: -
C28: wacc | D28: % | E28: 0.07 | G28: Weighted average cost of capita | I28: See https://docs.energytransitionmodel.com/main/cost-wacc/
C29: takes_part_in_ets | D29: yes=1, no=0 | E29: 1 | I29: Quintel assumption
C31: Other
C32: technical_lifetime | D32: years | E32: ='Research data'!E27 -> 25 | G32: Technical lifetime of the plant | I32: Danish Energy Agency
C33: construction_time | D33: years | E33: ='Research data'!E28 -> 2 | G33: Construction time of the plant | I33: Danish Energy Agency
C34: free_co2_factor | D34: - | E34: ='Research data'!E29 -> 0 | I34: Quintel assumption

Sheet Research data
C4: Attribute | E4: Values | G4: DEA | J4: Comments
C6: Technical
C7: typical_input_capacity | E7: =ROUND(G7,2) -> 1126.47 | G7: =Notes!B2 -> 1126.4721
C8: input.oily_biomass | E8: =ROUND(G8,3) -> 0.881 | G8: =Notes!B8 -> 0.881
C9: input.hydrogen | E9: =ROUND(G9,3) -> 0.119 | G9: =Notes!B9 -> 0.119
C10: output.biodiesel | E10: =ROUND(G10,3) -> 0.906 | G10: =Notes!B10 -> 0.90614083
C11: output.bionaphtha | E11: =ROUND(G11,3) -> 0.07 | G11: =Notes!B11 -> 0.07035917
C12: output.loss | E12: =ROUND(G12,3) -> 0.024 | G12: =Notes!B12 -> 0.0235
C13: full_load_hours | E13: =ROUND(G13,2) -> 8000 | G13: =Notes!B3 -> 8000
C14: availability | E14: =ROUND(G14,3) -> 0.962 | G14: =Notes!B4 -> 0.96153846
C16: Cost
C17: initial_investment | E17: =ROUND(G17,0) -> 745741908 | G17: =Notes!B14 -> 7.4574191e+08
C18: ccs_investment | E18: =ROUND(G18,0) -> 0 | G18: 0
C19: fixed_operation_and_maintenance_costs_per_year | E19: =ROUND(G19,0) -> 41431169 | G19: =Notes!B15 -> 41431169
C20: variable_operation_and_maintenance_costs_per_full_load_hour | E20: =ROUND(G20,2) -> 7200 | G20: =Notes!B16 -> 7200
C21: variable_operation_and_maintenance_costs_for_ccs_per_full_load_hour | E21: =G21 -> 0 | G21: 0
C22: cost_of_installing | E22: =G22 -> 0 | G22: 0
C23: decommissioning_costs | E23: =G23 -> 0 | G23: 0
C24: takes_part_in_ets | E24: =G24 -> 0 | G24: 0
C26: Other
C27: technical_lifetime | E27: =G27 -> 25 | G27: =Notes!B5 -> 25
C28: construction_time | E28: =G28 -> 2 | G28: =Notes!B6 -> 2
C29: free_co2_factor | E29: 0 | G29: 0

Sheet Sources
C3: Definition on the sources
C5: Type | D5: Source | E5: Country | F5: Date published | G5: Subject | H5: Date retrieved | I5: ETM Library URL | J5: Link
C7: HVO renewable diesel | D7: Danish Energy Agency | E7: DK | F7: 2025 | G7: Renewable fuels: Technology descriptions and projections for long-term energy system planning | H7: 45887 | I7: https://refman.energytransitionmodel.com/publications/2218
D8: Danish Energy Agency | E8: DK | F8: 2025 | G8: Data Sheets for energy carrier generation and conversion | H8: 45887 | I8: https://refman.energytransitionmodel.com/publications/2219

Sheet Notes
A1: Overview
A2: typical input capacity | B2: =B37/(1-C31) -> 1126.4721 | C2: MW
A3: full load hours | B3: =B38 -> 8000 | C3: hrs
A4: availability | B4: =B40 -> 0.96153846 | L4: Data from Danish Energy Agency HVO renewable diesel:
A5: technical lifetime | B5: =B41 -> 25 | C5: yr | L5: Technology | N5: HVO / renwable diesel
A6: construction time | B6: =B42 -> 2 | C6: yr | L6: year | N6: 2015 | O6: 2020 | P6: 2030 | Q6: 2040 | R6: 2050 | S6: 2020 | T6: 2020 | U6: 2050 | V6: 2050 | W6: Note | X6: Ref
L7: est | N7: ctrl | O7: ctrl | P7: ctrl | Q7: ctrl | R7: ctrl | S7: Lower | T7: Upper | U7: Lower | V7: Upper | W7: - | X7: -
A8: input.oily_biomass | B8: =C21 -> 0.881 | L8: cat | M8: par
A9: input.hydrogen | B9: =C22 -> 0.119 | L9: Energy/technical data
A10: output.biodiesel | B10: =C26 -> 0.90614083 | M10: Typical total plant size [1,000 t HVO/year] | N10: 500 | O10: 500 | P10: 750 | Q10: 850 | R10: 1000 | S10: 0.5 | T10: 2 | U10: 0.5 | V10: 1 | W10: A, B
A11: output.bionaphtha | B11: =C27 -> 0.07035917 | M11: Typical total plant size [MW HVO] | N11: 730 | O11: 730 | P11: 1100 | Q11: 1250 | R11: 1460 | S11: 0.5 | T11: 2 | U11: 0.5 | V11: 1 | W11: A, A1, B
A12: output.loss | B12: =C31 -> 0.0235 | M12: Input
M13: Feedstock Consumption [MWh/MWh Total Inputs] | N13: 0.881 | O13: 0.881 | P13: 0.881 | Q13: 0.881 | R13: 0.881 | S13: 0.99 | T13: 1.01 | U13: 0.99 | V13: 1.01 | W13: C | X13: 3,4,11
A14: investment costs | B14: =B44 -> 7.4574191e+08 | C14: € | M14: Hydrogen Consumption [MWh/MWh Total Inputs] | N14: 0.105 | O14: 0.105 | P14: 0.105 | Q14: 0.105 | R14: 0.105 | S14: 0.93 | T14: 1.07 | U14: 0.93 | V14: 1.07 | W14: C, D | X14: 3,4,11
A15: fixed O&M | B15: =B45 -> 41431169 | C15: €/y | M15: Electricity Consumption [MWh/MWh Total Inputs] | N15: 0.008 | O15: 0.008 | P15: 0.008 | Q15: 0.008 | R15: 0.008 | S15: 0.5 | T15: 1.5 | U15: 0.5 | V15: 1.5 | W15: C | X15: 3,4,11
A16: variable O&M | B16: =B52 -> 7200 | C16: €/flh | M16: Natural Gas Consumption [MWh/MWh Total Inputs] | N16: 0.007 | O16: 0.007 | P16: 0.007 | Q16: 0.007 | R16: 0.007 | S16: 0.5 | T16: 0.5 | U16: 0.5 | V16: 0.5 | W16: C | X16: 3,4,11
M17: Output
M18: HVO Output [MWh/MWh Total Input] | N18: 0.85 | O18: 0.85 | P18: 0.85 | Q18: 0.85 | R18: 0.85 | S18: 0.99 | T18: 1.01 | U18: 0.99 | V18: 1.01 | W18: C, H
A19: Data from Danish Energy Agency | M19: Naphta Output [MWh/MWh Total Input] | N19: 0.066 | O19: 0.066 | P19: 0.066 | Q19: 0.066 | R19: 0.066 | S19: 0.99 | T19: 1.01 | U19: 0.99 | V19: 1.01 | W19: C, H
A20: feedstock | B20: original | C20: corrected for 1 MJ input | M20: Fuel Gas Output [MWh/MWh Total Input] | N20: 0.033 | O20: 0.033 | P20: 0.033 | Q20: 0.033 | R20: 0.033 | S20: 0.99 | T20: 1.01 | U20: 0.99 | V20: 1.01 | W20: C, H
A21: input.oily_biomass | B21: =P13 -> 0.881 | C21: =B21 -> 0.881 | E21: Quintel assumption: minimal electricity and natural gas consumption ignored | M21: LPG Output [MWh/MWh Total Input] | N21: 0.0275 | O21: 0.0275 | P21: 0.0275 | Q21: 0.0275 | R21: 0.0275 | S21: 0.99 | T21: 1.01 | U21: 0.99 | V21: 1.01 | W21: C, H
A22: input.hydrogen | B22: =P14 -> 0.105 | C22: =1-C21 -> 0.119 | M22: District Heating Output [MWh/MWh Total input] | N22: =0.0237*0.15 -> 0.003555 | O22: =0.0237*0.15 -> 0.003555 | P22: =0.0237*0.15 -> 0.003555 | Q22: =0.0237*0.15 -> 0.003555 | R22: =0.0237*0.15 -> 0.003555 | S22: 0.99 | T22: 1.01 | U22: 0.99 | V22: 1.01 | W22: C, H
A23: input.electricity | B23: =P15 -> 0.008 | E23: Minimal electricity consumption ignored, input share added to hydrogen input | M23: Forced outage [%] | N23: 0 | O23: 0 | P23: 0 | Q23: 0 | R23: 0 | W23: I
A24: input natural gas | B24: =P16 -> 0.007 | E24: Minimal heat consumption ignored, input share added to hydrogen input | M24: Planned outage [weeks per year] | N24: 2 | O24: 2 | P24: 2 | Q24: 2 | R24: 2 | X24: 7
A25: total | B25: =SUM(B21:B24) -> 1.001 | C25: =SUM(C21:C22) -> 1 | M25: Technical lifetime [years] | N25: 25 | O25: 25 | P25: 25 | Q25: 25 | R25: 25
A26: output.biodiesel | B26: =P18 -> 0.85 | C26: =B26+SUM($B$28:$B$29)*B26/SUM($B$26:$B$27) -> 0.90614083 | M26: Construction time [years] | N26: 2 | O26: 2 | P26: 2 | Q26: 2 | R26: 2
A27: output.bionaphtha | B27: =P19 -> 0.066 | C27: =B27+SUM($B$28:$B$29)*B27/SUM($B$26:$B$27) -> 0.07035917 | L27: Financial data
A28: output fuel gas | B28: =P20 -> 0.033 | E28: DEA report states that fuel gas can be used as fuel, but not modelled in ETM. Therefore, other fuel output proportionally increased | M28: Specific investment [M €/MW] | N28: 0.8134887 | O28: 0.80402953 | P28: 0.67796458 | Q28: 0.63633856 | R28: 0.61484611 | S28: 0.9 | T28: 1.1 | U28: 0.9 | V28: 1.1 | W28: E, J, L | X28: 10, 12
A29: output LPG | B29: =P21 -> 0.0275 | E29: Bio-LPG not modelled, therefore other fuel output proportionally increased | M29: - equipment [%] | N29: 75 | O29: 75 | P29: 75 | Q29: 75 | R29: 75
A30: output district heating | B30: =P22 -> 0.003555 | E30: Minor heat output ignored, considered loss | M30: - installation [%] | N30: 25 | O30: 25 | P30: 25 | Q30: 25 | R30: 25
A31: output.loss | B31: =1-SUM(B26:B30) -> 0.019945 | C31: =B31+B30 -> 0.0235 | E31: Quintel assumption: fuel gas, LPG and district heating output assumed as loss | M31: Fixed O&M [M €/MW/year] | N31: 0.037836684 | O31: 0.037836684 | P31: 0.037664699 | Q31: 0.03756426 | R31: 0.037836684 | S31: 0.9 | T31: 1.1 | U31: 0.9 | V31: 1.1 | W31: F, K, L | X31: 7
A32: total | B32: =SUM(B26:B31) -> 1 | C32: =SUM(C26:C31) -> 1 | M32: Variable O&M [€/MWh] | N32: 9.0189578 | O32: 9.0189578 | P32: 9.0189578 | Q32: 9.0189578 | R32: 9.0189578 | S32: 0.9 | T32: 1.1 | U32: 0.9 | V32: 1.1 | W32: F, K, L | X32: 7
M33: start up [M €/MW] | N33: 0 | O33: 0 | P33: 0 | Q33: 0 | R33: 0 | S33: 0 | T33: 0 | U33: 0 | V33: 0
L34: Technology-specific data
A35: Plant specs | M35: Specific energy content [GJ/ton] | N35: 44.1 | O35: 44.1 | P35: 44.1 | Q35: 44.1 | R35: 44.1
A36: Plant size (output) | B36: =P10*10^3 -> 750000 | C36: kg HVO/yr | M36: Specific density [kg/l] or [ton/m3] | N36: 0.77 | O36: 0.77 | P36: 0.77 | Q36: 0.77 | R36: 0.77
A37: Plant size (output) | B37: =P11 -> 1100 | C37: MW | M37: Specific investment [M €/1,000 t HVO] | N37: 1.187663 | O37: 1.173853 | P37: 0.99432254 | Q37: 0.93576799 | R37: 0.8976523 | S37: 0.9 | T37: 1.1 | U37: 0.9 | V37: 1.1 | W37: E, J, L | X37: 10, 12
A38: full load hours | B38: 8000 | C38: h/yr | M38: - equipment [%] | N38: 75 | O38: 75 | P38: 75 | Q38: 75 | R38: 75
A39: production | B39: =B37*B38 -> 8800000 | C39: MWh/yr | M39: - installation [%] | N39: 25 | O39: 25 | P39: 25 | Q39: 25 | R39: 25
A40: availability | B40: =1-P24/52 -> 0.96153846 | M40: Fixed O&M [M €/1,000 t HVO] | N40: 0.055240141 | O40: 0.055240141 | P40: 0.055240141 | Q40: 0.055240141 | R40: 0.055240141 | S40: 0.9 | T40: 1.1 | U40: 0.9 | V40: 1.1 | W40: F, K, L | X40: 7
...
