Workbook
Name exchange_rate_2011_2010: #REF!
Name Final_demand_residences: '[1]Fuel aggregation'!$L$11
Name hours_a_year: #REF!
Name km2_to_m2: #REF!
Name kW_to_MW: #REF!
Name kW_to_W: #REF!
Name kWp_to_MWp: #REF!
Name m2_to_km2: #REF!
Name STC: #REF!
Name STC_insolation: #REF!
Name W_to_MW: #REF!
Name Wp_to_kWp: #REF!
Name WP_to_MWp: #REF!

Sheet Cover sheet
B2: Cover Sheet
B4: Document | C4: energy_power_turbine_network_gas_must_run.ad
B5: Author | C5: Claudia Valkenier
B6: Organization | C6: Quintel Intelligence
B9: Legend
B11: Cells | C11: Intermediate (calculation)
C12: Result
C13: Manual input
C14: Reference to manual input or data input
B16: Tabs | C16: Introductory
C17: Dashboard
C18: Research data
C19: Sources
C20: Results
C21: Main calculations
C22: Additional calculations
C23: Output to csv

Sheet Dashboard
B2: This sheet summarizes all node attributes formatted in the way they are used by the Energy Transition Model. Use the Excel formulas to find the original data and sources for these numbers. You can also use this document to update the attribute value. Once you have finished updating, save this document and run rake import:node NODE="nodename" to update the node attributes on ETSource.
C8: Attribute | D8: Unit | E8: Value | G8: Definition | I8: Source
C10: Technical
C11: availability | D11: - | E11: 0.9 | I11: quintel/etsource@0277ad226491f5aae44c874b298cbcf694d2f6cb
C12: capacity_credit | D12: - | E12: 1 | I12: quintel/etsource@0277ad226491f5aae44c874b298cbcf694d2f6cb
C13: forecasting_error | D13: - | E13: 0 | I13: quintel/etsource@0277ad226491f5aae44c874b298cbcf694d2f6cb
C14: households_supplied_per_unit | D14: - | E14: 0 | I14: quintel/etsource@0277ad226491f5aae44c874b298cbcf694d2f6cb
C15: part_load_efficiency_penalty | D15: - | E15: 0.034 | I15: quintel/etsource@0277ad226491f5aae44c874b298cbcf694d2f6cb
C16: part_load_operating_point | D16: - | E16: 0.65 | I16: quintel/etsource@0277ad226491f5aae44c874b298cbcf694d2f6cb
C17: electricity_output_capacity | D17: MW | E17: ='Research data'!H6 -> 75 | G17: Electricity output capacity | I17: quintel/etsource@0277ad226491f5aae44c874b298cbcf694d2f6cb
C18: heat_output_capacity | D18: MW | E18: 0 | G18: Heat output capacity | I18: quintel/etsource@0277ad226491f5aae44c874b298cbcf694d2f6cb
C20: Cost
C21: initial_investment | D21: euro | E21: ='Research data'!H15 -> 56175000 | G21: Initial investment costs | I21: EIA
C22: ccs_investment | D22: euro | E22: 0 | G22: Investment cost with ccs | I22: quintel/etsource@0277ad226491f5aae44c874b298cbcf694d2f6cb
C23: cost_of_installing | D23: euro | E23: 0 | G23: Installation cost | I23: quintel/etsource@0277ad226491f5aae44c874b298cbcf694d2f6cb
C24: decommissioning_costs | D24: euro | E24: 0 | G24: Decmmmissioning cost | I24: quintel/etsource@0277ad226491f5aae44c874b298cbcf694d2f6cb
C25: fixed_operation_and_maintenance_costs_per_year | D25: euro/year | E25: ='Research data'!H17 -> 564000 | G25: Fixed operational and maintenance costs per year | I25: PB
C26: variable_operation_and_maintenance_costs_per_full_load_hour | D26: euro/FLH | E26: ='Research data'!H19 -> 282 | G26: Variable operational and maintenance costs | I26: PB
C27: variable_operation_and_maintenance_costs_for_ccs_per_full_load_hour | D27: euro/FLH | E27: 0 | G27: Variable operational and maintenance costs for ccs | I27: quintel/etsource@0277ad226491f5aae44c874b298cbcf694d2f6cb
C28: wacc | D28: % | E28: 0.04 | G28: Weighted average cost of capita | I28: See https://github.com/quintel/documentation/blob/master/general/cost_calculations.md#weighted-average-cost-of-capital
C29: takes_part_in_ets | D29: yes=1, no=0 | E29: 1 | I29: quintel/etsource@0277ad226491f5aae44c874b298cbcf694d2f6cb
C31: Other
C32: land_use_per_unit | D32: km2 | E32: ='Research data'!H10 -> 0.1 | G32: Land use of plant in NL | I32: Moerdijk
C33: construction_time | D33: years | E33: ='Research data'!H11 -> 1 | G33: Construction time of the plant | I33: ICF
C34: technical_lifetime | D34: years | E34: ='Research data'!H12 -> 40 | G34: Technical lifetime of the plant | I34: PB
C35: free_co2_factor | D35: - | E35: 0 | I35: quintel/etsource@0277ad226491f5aae44c874b298cbcf694d2f6cb

Sheet Research data
C3: Parameter | F3: Unit | H3: Results | J3: Siemens | M3: GE | O3: Ansald | Q3: Alstom | S3: EIA | U3: ICF | W3: PB | Y3: Moerdijk | AA3: Comments
C5: Technical
C6: Electricity output capacity | F6: MW | H6: 75 | J6: =Notes!D38 -> 50.5 | K6: =Notes!$D$11 -> 112 | M6: =Notes!D51 -> 75.9 | O6: =Notes!D66 -> 75 | Q6: 113 | S6: =Notes!D152 -> 85 | W6: 45 | AA6: It is assumed that the most appropriate electricity output capacity is 75 MW with an efficiency of 36%
C7: Output electricity | F7: % | H7: =ROUND(36,0) -> 36 | J7: =Notes!D39 -> 38.3 | K7: =Notes!$D$12 -> 33.9 | M7: =Notes!D52 -> 35 | O7: =Notes!D67 -> 35.9 | Q7: 33
C9: Other | AA9: Moerdijk gas turbine plant is used for the calculation of land use. Dimensions are taken from:
C10: Land use of plant | F10: km2 | H10: =ROUND(0.1,1) -> 0.1 | Y10: =428*303/1000000 -> 0.129684 | AA10: Google maps
C11: Construction time | F11: years | H11: =ROUND(1,0) -> 1 | U11: =Notes!D109/12 -> 1 | AA11: Constructiont time: 6-18 months
C12: Technical lifetime | F12: years | H12: =ROUND(40,0) -> 40 | W12: =Notes!D116 -> 42
C14: Costs
C15: Initial investment costs | F15: euro | H15: =ROUND(H16*H6*1000,2) -> 56175000
C16: Initial investment costs | F16: euro/KWe | H16: =S16 -> 749 | S16: =Notes!D154 -> 749
C17: Fixed operational and maintenance costs | F17: euro/year | H17: =ROUND(H18*H6*1000,2) -> 564000
C18: Fixed operational and maintenance costs | F18: euro/KW/year | H18: =W18 -> 7.52 | S18: =Notes!D157 -> 5.7 | W18: =Notes!D120 -> 7.52 | AA18: Fixed operational and maintenance costs: 16 NZ$/KW/yr
C19: Variable operational and maintenance costs | F19: euro/FLH | H19: =ROUND(H20*H22/H21,2) -> 282 | AA19: Variable operational and maintenance costs: 8 NZ$/MWh
C20: Variable operational and maintenance costs | F20: euro/MWh | H20: =ROUND(W20,2) -> 3.76 | S20: =Notes!D160 -> 11.9 | W20: =Notes!D118 -> 3.76 | AA20: Fixed and variable O&M costs are converted to euros (1NZ$=0.47euros)
C21: Full load hours | F21: FLH | H21: 200 | AA21: For the calculation of fixed and variable O&M costs, the New Zealand case is chosen as it has the most reliable values
C22: Production Electricity yearly | F22: MWh/year | H22: =H21*H6 -> 15000

Sheet Sources
C3: Definition on the sources
C5: Type | E5: Source | F5: Country | G5: Date published | H5: Subject year | I5: Date retrived | J5: ETM Library URL | K5: Link
E7: GE | F7: EU | G7: 2013 | H7: 2013 | J7: http://refman.et-model.com/publications/1952 | K7: http://www.filter.ee/extensions/filter/brochures/113-27620.pdf
C8: Electricity output capacity
C9: Output electricity
E11: Siemens a | F11: EU | G11: 2011 | H11: 2011 | J11: http://refman.et-model.com/publications/1953 | K11: http://www.energy.siemens.com/hq/pool/hq/power-generation/gas-turbines/SGT5-2000E/gas-turbine-sgt5-2000e-brochure.pdf
C12: Electricity output capacity
C13: Output electricity
E14: Siemens b | G14: 2013 | H14: 2013 | J14: http://refman.et-model.com/publications/1954 | K14: http://www.energy.siemens.com/hq/pool/hq/power-generation/gas-turbines/SGT-800/SGT-800_Gas_Turbine_EN.pdf
C15: Electricity output capacity
C16: Output electricity
E18: Ansald | F18: EU | G18: 2012 | H18: 2012 | J18: http://refman.et-model.com/publications/1955 | K18: http://www.ansaldoenergia.it/easyUp/file/scheda_gas_turbine_ae64_3a_lo.pdf
C19: Electricity output capacity
C20: Output electricity
E22: PB | F22: NZ | G22: 2012 | H22: 2012 | J22: http://refman.et-model.com/publications/1956 | K22: http://www.med.govt.nz/sectors-industries/energy/pdf-docs-library/energy-data-and-modelling/technical-papers/2011%20NZ%20Generation%20Data%20Update%20v006a.pdf
C23: Fixed operational and maintenance cost
C24: Variable operational and maintenance cost
C25: Technical lifetime
E27: ICF | F27: US | G27: 2008 | H27: 2007 | J27: http://refman.et-model.com/publications/1957 | K27: http://www.epa.gov/chp/documents/catalog_chptech_gas_turbines.pdf
C28: Construction time
E30: EEI | F30: US | G30: 2013 | H30: 2013 | J30: http://refman.et-model.com/publications/1958 | K30: http://www.eia.gov/forecasts/capitalcost/pdf/updated_capcost.pdf
C31: Investment cost
C32: Fixed operational and maintenance cost
C33: Variable operational and maintenance cost
E35: Google maps | F35: NL | I35: 20.10.2014 | K35: https://www.google.com/maps/place/Middenweg+36,+4782+PM+Moerdijk,+The+Netherlands/@51.6827777,4.5903138,1584m/data=!3m1!1e3!4m2!3m1!1s0x47c4249b2c8d2cc1:0x78741010c6d8f35?hl=en-US
C36: Land Use | E36: Moerdijk

Sheet Notes
C2: Source | D2: Notes
C4: Siemens a
C5: p.2
D11: 112 | E11: MW
D12: 33.9 | E12: %
C29: Siemens b
C30: p.5
D38: 50.5 | E38: MW
D39: 38.3 | E39: %
C49: GE
C50: p.7
D51: 75.9 | E51: MW
D52: 35 | E52: %
C63: Ansald
C64: p.2
D66: 75 | E66: MW
D67: 35.9 | E67: %
C84: EC
C85: p.17
D87: 450 | E87: euro/KW
C99: ICF
C100: p.13
D108: 6 - 18 | E108: months
C109: Average | D109: 12 | E109: months
C112: PB
C113: p.12
D115: 45 | E115: MW
C116: Lifetime | D116: 42 | E116: yr
C117: Variable O&M | D117: 8 | E117: NZ$/MWh
D118: =D117*0.47 -> 3.76
C119: Fixed O&M | D119: 16 | E119: NZ$/KW/yr
D120: =D119*0.47 -> 7.52
C143: EIA
C144: p.19
D152: 85 | E152: MW
D153: 973 | E153: $/KW
D154: 749 | E154: euro/KW
D156: 7.34 | E156: $/KW
D157: 5.7 | E157: euro/KW
D159: 15.45 | E159: $/MWh
...
