Workbook
Name exchange_rate_2011_2010: #REF!
Name Final_demand_residences: '[1]Fuel aggregation'!$L$11
Name hours_a_year: #REF!
Name km2_to_m2: #REF!
Name kW_to_MW: #REF!
Name kW_to_W: #REF!
Name kWp_to_MWp: #REF!
Name labor_cost: Notes!#REF!
Name licensing: Notes!#REF!
Name m2_to_km2: #REF!
Name overhead_GA: Notes!#REF!
Name sensitivity_07: '[2]Tornado Charts'!$I$48
Name STC: #REF!
Name STC_insolation: #REF!
Name tax_insurance: Notes!#REF!
Name W_to_MW: #REF!
Name Wp_to_kWp: #REF!
Name WP_to_MWp: #REF!

Sheet Cover sheet
B2: Cover Sheet
B4: Document | C4: energy_production_methanol_synthesis_dry_biomass_ccs
B5: Author | C5: Kyra de Haan
B6: Organization | C6: Quintel
B9: Legend
B11: Cells | C11: Intermediate (calculation)
C12: Result
C13: Manual input
C14: Reference to manual input or data input
B16: Tabs | C16: Introductory
C17: Dashboard
C18: Research data
C19: Sources
C20: Results
C21: Main calculations
C22: Additional calculations
C23: Output to csv

Sheet Dashboard
B2: This sheet summarizes all node attributes formatted in the way they are used by the Energy Transition Model. Use the Excel formulas to find the original data and sources for these numbers. You can also use this document to update the attribute value. Once you have finished updating, save this document and run rake import:node NODE="nodename" to update the node attributes on ETSource.
C9: Attribute | D9: Unit | E9: Value | G9: Definition | I9: Source
C11: Technical
C12: typical_input_capacity | D12: MWe | E12: =Notes!D6 -> 213.11 | I12: Danish Energy Agency
C13: input.dry_biomass | E13: =Notes!D18 -> 1 | I13: Danish Energy Agency
C14: output.biomethanol | D14: - | E14: =Notes!D16 -> 0.61 | I14: Danish Energy Agency
C15: full_load_hours | D15: h | E15: =Notes!D7 -> 8000 | I15: Danish Energy Agency
C16: availability | D16: - | E16: =Notes!D45 -> 0.96
C18: Cost
C19: initial_investment | D19: euro | E19: =Notes!D11 -> 403812425 | G19: Initial investment costs | I19: Danish Energy Agency
C20: ccs_investment | D20: euro | E20: =Notes!D21 -> 38988246 | I20: taken from energy_hydrogen_biomass_gasification_ccs
C21: fixed_operation_and_maintenance_costs_per_year | D21: euro/yr | E21: =Notes!D12 -> 5384166 | G21: Fixed operational and maintenance costs per year (incl. ccs) | I21: Danish Energy Agency
C22: variable_operation_and_maintenance_costs_per_full_load_hour | D22: euro/flh | E22: =Notes!D13 -> 2019.06 | G22: Variable operation and maintenance costs per flh | I22: Danish Energy Agency
C23: variable_operation_and_maintenance_costs_for_ccs_per_full_load_hour | D23: euro/flh | E23: 0 | I23: Quintel assumption
C24: cost_of_installing | E24: 0 | G24: Installation costs | I24: No data available, assumed to be part of initial investment
C25: decommissioning_costs | E25: 0 | G25: Decommissioning costs | I25: No data available, assumed to be part of initial investment
C26: wacc | D26: % | E26: 0.07 | G26: Weighted average cost of capita | I26: See https://docs.energytransitionmodel.com/main/cost-wacc/
C27: takes_part_in_ets | D27: yes=1, no=0 | E27: 1 | I27: Quintel assumption
C29: Other
C30: technical_lifetime | D30: years | E30: =Notes!D8 -> 20 | G30: Technical lifetime of the plant | I30: Danish Energy Agency
C31: construction_time | D31: years | E31: =Notes!D9 -> 2.5 | G31: Construction time of the plant | I31: Danish Energy Agency
C32: free_co2_factor | D32: - | E32: =Notes!D96 -> 0.522288 | I32: Calculated using carbon balance
C33: ccs_capture_rate | D33: - | E33: =Notes!D97 -> 0.9 | I33: Taken from energy_hydrogen_biomass_gasification_ccs

Sheet Research data
C4: Attribute | F4: Unit | H4: Values | J4: DEA | M4: Comments
C6: Technical
C7: typical_input_capacity | D7: MWe | F7: MWe | H7: =ROUND(J7,2) -> 213.11 | J7: =Notes!D6 -> 213.11
C8: input.dry_biomass | D8: - | F8: - | H8: =ROUND(J8,3) -> 1 | J8: =Notes!D18 -> 1
C9: output.biomethanol | D9: - | F9: - | H9: =ROUND(J9,3) -> 0.61 | J9: =Notes!D16 -> 0.61
C10: output.loss | F10: - | H10: =ROUND(J10,3) -> 0.39 | J10: =Notes!D17 -> 0.39
C11: full_load_hours | D11: - | F11: hrs/yr | H11: =ROUND(J11,2) -> 8000 | J11: =Notes!D7 -> 8000
C12: availability | H12: =ROUND(J12,2) -> 0.96 | J12: =Notes!D45 -> 0.96
C14: Cost
C15: initial_investment | D15: euro | F15: euro | H15: =ROUND(J15,0) -> 403812425 | J15: =Notes!D11 -> 403812425
C16: ccs_investment | F16: euro | H16: =ROUND(J16,0) -> 38988246 | J16: =Notes!D21 -> 38988246 | M16: taken from energy_hydrogen_biomass_gasification_ccs
C17: fixed_operation_and_maintenance_costs_per_year | D17: euro/yr | E17: 0 | F17: euro/yr | H17: =ROUND(J17,0) -> 5384166 | J17: =Notes!D12 -> 5384166
C18: variable_operation_and_maintenance_costs_per_full_load_hour | D18: euro/flh | E18: ='Research data'!H15 -> 403812425 | F18: euro/flh | H18: =ROUND(J18,2) -> 2019.06 | J18: =Notes!D13 -> 2019.06
C19: variable_operation_and_maintenance_costs_for_ccs_per_full_load_hour | E19: ='Research data'!H20 -> 0 | H19: =J19 -> 0 | J19: 0
C20: cost_of_installing | E20: ='Research data'!H18 -> 2019.06 | H20: =J20 -> 0 | J20: 0
C21: decommissioning_costs | E21: ='Research data'!#REF! -> #REF! | H21: =J21 -> 0 | J21: 0
C22: takes_part_in_ets | D22: yes=1, no=0 | E22: 0 | F22: yes=1, no=0 | H22: =J22 -> 0 | J22: 0
C24: Other
C25: technical_lifetime | D25: years | F25: years | H25: =J25 -> 20 | J25: =Notes!D8 -> 20
C26: construction_time | D26: years | F26: years | H26: =J26 -> 2.5 | J26: =Notes!D9 -> 2.5
C27: free_co2_factor | D27: - | E27: 0 | F27: - | H27: 0 | J27: 0

Sheet Sources
C3: Definition on the sources
C5: Type | D5: Source | E5: Country | F5: Date published | G5: Subject | H5: Date retrieved | I5: ETM Library URL | J5: Link
B8: Biomass gassification for biomethanol production | C8: All specs | D8: Danish Energy Agency | E8: DK | F8: 2025 | G8: Renewable fuels: Technology descriptions and projections for long-term energy system planning | H8: 45887 | I8: https://refman.energytransitionmodel.com/publications/2218
C9: All specs | D9: Danish Energy Agency | E9: DK | F9: 2025 | G9: Data Sheets for energy carrier generation and conversion | H9: 45887 | I9: https://refman.energytransitionmodel.com/publications/2219

Sheet Notes
C3: Source | D3: Page | E3: Notes
C5: Overview
C6: Input capacity | D6: =ROUND(D41/D16,2) -> 213.11 | E6: MW
C7: Full load hours | D7: =ROUND(D42,2) -> 8000 | E7: hours
C8: Technical lifetime | D8: =D43 -> 20 | E8: y
C9: Construction period | D9: =D44 -> 2.5 | E9: y
C11: Investment | D11: =ROUND(D47,0) -> 403812425 | E11: euro
C12: Fixed O&M | D12: =ROUND(D48,0) -> 5384166 | E12: euro/y
C13: Variable O&M | D13: =ROUND(D50,2) -> 2019.06 | E13: euro/flh
C15: Input/output
C16: output.biomethanol | D16: =ROUND(E30,3) -> 0.61
C17: output.loss | D17: =ROUND(E33,3) -> 0.39
C18: input.dry_biomass | D18: =ROUND(E35,3) -> 1
C20: CCS
C21: ccs_investment | D21: =ROUND(D61,0) -> 38988246 | E21: €
N23: From DEA, methanol from biomass gasification
C25: Biomethanol from biomass gasification | N25: Technology | P25: Bio Methanol
C26: Based on specs from Danish Energy Agency, 2030 values taken | N26: year | P26: 2015 | Q26: 2020 | R26: 2030 | S26: 2040 | T26: 2050 | U26: 2020 | V26: 2020 | W26: 2050 | X26: 2050 | Y26: Note | Z26: Ref
N27: est | P27: ctrl | Q27: ctrl | R27: ctrl | S27: ctrl | T27: ctrl | U27: Lower | V27: Upper | W27: Lower | X27: Upper | Y27: - | Z27: -
C28: in- and output fractions | N28: cat | O28: par
C29: Output | D29: original | E29: corrected | N29: Energy/technical data
C30: biomethanol | D30: =R35 -> 0.61 | E30: =D30 -> 0.61 | O30: Typical total plant size [1,000 t Methanol/year] | P30: 100 | Q30: 100 | R30: 200 | S30: 250 | T30: 300 | U30: 0.5 | V30: 2 | W30: 0.5 | X30: 1.25 | Y30: A, B | Z30: 3, 5, 6
C31: heat | D31: =R36 -> 0.22 | E31: 0 | F31: assumption that heat will be used for internal process | O31: Typical total plant size [MW] | P31: 65 | Q31: 65 | R31: 130 | S31: 165 | T31: 195 | U31: 0.5 | V31: 2 | W31: 0.5 | X31: 1.25 | Y31: A, A1, B | Z31: 3, 5, 6
C32: electricity | D32: =R37 -> 0.02 | E32: 0 | F32: assumption that electricity will be used for internal process | O32: Input
C33: loss | D33: =1-SUM(D30:D32) -> 0.15 | E33: =SUM(D31:D33) -> 0.39 | O33: Feedstock Consumption, [MWh/MWh Total Input] | P33: 1 | Q33: 1 | R33: 1 | S33: 1 | T33: 1 | U33: 0.9 | V33: 1.5 | W33: 0.9 | X33: 1.2 | Z33: 1
C34: Input | O34: Output
C35: biomass | D35: =R33 -> 1 | E35: =D35 -> 1 | O35: Methanol Output [MWh/MWh Total Input] | P35: 0.58 | Q35: 0.58 | R35: 0.61 | S35: 0.63 | T35: 0.65 | U35: 1 | V35: 1.33 | W35: 1 | X35: 1.33 | Y35: D | Z35: 1
O36: District Heating Output [MWh/MWh Total Input] | P36: 0.22 | Q36: 0.22 | R36: 0.22 | S36: 0.22 | T36: 0.22 | U36: 0.8 | V36: 1.25 | W36: 0.8 | X36: 1.25 | Y36: D | Z36: 1
O37: Electricity Output [MWh/MWh Total Input] | P37: 0.02 | Q37: 0.02 | R37: 0.02 | S37: 0.02 | T37: 0.02 | U37: 0.8 | V37: 1.25 | W37: 0.8 | X37: 1.25 | Y37: D | Z37: 1
C38: Plant specs | O38: Forced outage [%] | P38: 4 | Q38: 4 | R38: 0 | S38: 0 | T38: 0
C39: Based on DEA data, year 2030 is taken | O39: Planned outage [weeks per year] | P39: 2 | Q39: 2 | R39: 2 | S39: 2 | T39: 2
C40: Plant size | D40: =R30*10^3 -> 200000 | E40: t methanol/y | O40: Technical lifetime [years] | P40: 25 | Q40: 20 | R40: 20 | S40: 20 | T40: 20
C41: Plant size (production output) | D41: =R31 -> 130 | E41: MW | O41: Construction time [years] | P41: 2.5 | Q41: 2.5 | R41: 2.5 | S41: 2.5 | T41: 2.5
C42: Full load hours | D42: 8000 | E42: h | N42: Financial data
C43: Technical lifetime | D43: =R40 -> 20 | E43: y | O43: Specific investment [M€/MW Methanol] | P43: 5.5913924 | Q43: 5.5913924 | R43: 3.1063291 | S43: 2.255697 | T43: 1.5531646 | U43: 0.5 | V43: 1.0634 | W43: 0.85072 | X43: 1.2 | Y43: F | Z43: 1, 3, 5, 6
C44: Construction time | D44: =R41 -> 2.5 | E44: y | O44: - equipment [%] | P44: 75 | Q44: 75 | R44: 75 | S44: 75 | T44: 75
C45: availability | D45: =ROUND(1-R39/52,2) -> 0.96 | O45: - installation [%] | P45: 25 | Q45: 25 | R45: 25 | S45: 25 | T45: 25
O46: Fixed O&M [M€/MW/year Methanol] | P46: 0.062126582 | Q46: 0.062126582 | R46: 0.041417722 | S46: 0.04079018 | T46: 0.041417722 | U46: 0.9 | V46: 1.1 | W46: 0.9 | X46: 1.1 | Y46: E, F | Z46: 1
C47: Investment | D47: =R52*$R$30*10^6 -> 4.0381243e+08 | E47: € | O47: Variable O&M [€/MWh methanol] | P47: 21.697941 | Q47: 21.697941 | R47: 14.465294 | S47: 14.465294 | T47: 14.465294 | U47: 0.9 | V47: 1.1 | W47: 0.9 | X47: 1.1 | Y47: E,,F | Z47: 1
C48: Fixed O&M | D48: =R53*$R$30*10^6 -> 5384165.7 | E48: €/y | O48: Start up [M€/1,000 t Methanoll] | P48: 0 | Q48: 0 | R48: 0 | S48: 0 | T48: 0 | U48: 0 | V48: 0 | W48: 0 | X48: 0
...
