Workbook
Name exchange_rate_2011_2010: #REF!
Name Final_demand_residences: #REF!
Name hours_a_year: #REF!
Name km2_to_m2: #REF!
Name kW_to_MW: #REF!
Name kW_to_W: #REF!
Name kWp_to_MWp: #REF!
Name m2_to_km2: #REF!
Name STC: #REF!
Name STC_insolation: #REF!
Name W_to_MW: #REF!
Name Wp_to_kWp: #REF!
Name WP_to_MWp: #REF!

Sheet Cover sheet
B2: Cover Sheet
B4: Document | C4: energy_production_bio_ethanol_to_jet
B5: Author | C5: Kyra de Haan
B6: Organization | C6: Quintel
B9: Legend
B11: Cells | C11: Intermediate (calculation)
C12: Result
C13: Manual input
C14: Reference to manual input or data input
B16: Tabs | C16: Introductory
C17: Dashboard
C18: Research data
C19: Sources
C20: Results
C21: Main calculations
C22: Additional calculations
C23: Output to csv

Sheet Dashboard
B2: This sheet summarizes all node attributes formatted in the way they are used by the Energy Transition Model. Use the Excel formulas to find the original data and sources for these numbers. You can also use this document to update the attribute value. Once you have finished updating, save this document and run rake import:node NODE="nodename" to update the node attributes on ETSource.
C9: Attribute | D9: Unit | E9: Value | G9: Definition | I9: Source
C11: Technical
C12: typical_input_capacity | D12: MW | E12: =Notes!C2 -> 62.037037 | I12: Geleynse et al. (2018)
C13: input.bio_ethanol | D13: - | E13: =ROUND(Notes!C6,5) -> 0.97405 | I13: Geleynse et al. (2018)
C14: input.hydrogen | D14: - | E14: =ROUND(Notes!C7,5) -> 0.02595 | I14: Geleynse et al. (2018)
C15: output.bio_kerosene | D15: - | E15: =ROUND(Notes!C8,5) -> 0.70358 | I15: Geleynse et al. (2018)
C16: output.biodiesel | D16: - | E16: =ROUND(Notes!C9,5) -> 0.1733 | I16: Geleynse et al. (2018)
C17: full_load_hours | D17: h | E17: =Notes!C3 -> 8000 | I17: De Jong et al. (2018)
C18: availability | D18: - | E18: 0.962 | I18: Copied from energy_production_hvo_bio_kerosene
C20: Cost
C21: initial_investment | D21: euro | E21: =Notes!C11 -> 22194120 | G21: Initial investment costs | I21: Geleynse et al. (2018)
C22: ccs_investment | D22: euro | E22: 0 | I22: No CCS
C23: fixed_operation_and_maintenance_costs_per_year | D23: euro/yr | E23: =Notes!C12 -> 2616380 | G23: Fixed operational and maintenance costs per year (incl. ccs) | I23: Geleynse et al. (2018)
C24: variable_operation_and_maintenance_costs_per_full_load_hour | D24: euro/flh | E24: =Notes!C13 -> 360.88 | G24: Variable operation and maintenance costs per flh | I24: Geleynse et al. (2018)
C25: variable_operation_and_maintenance_costs_for_ccs_per_full_load_hour | D25: euro/flh | E25: 0 | I25: No CCS
C26: cost_of_installing | D26: euro | E26: 0 | G26: Installation costs | I26: No data available, assumed to be 0
C27: decommissioning_costs | D27: euro | E27: 0 | G27: Decommissioning costs | I27: No data available, assumed to be 0
C28: wacc | D28: % | E28: 0.07 | G28: Weighted average cost of capita | I28: See https://docs.energytransitionmodel.com/main/cost-wacc/
C29: takes_part_in_ets | D29: yes=1, no=0 | E29: 1 | I29: Quintel assumption
C31: Other
C32: technical_lifetime | D32: years | E32: =Notes!C17 -> 25 | G32: Technical lifetime of the plant | I32: De Jong et al. (2015)
C33: construction_time | D33: years | E33: 0 | G33: Construction time of the plant | I33: No data available, assumed to be 0
C34: free_co2_factor | D34: - | E34: 0 | I34: Quintel assumption

Sheet Sources
C3: Definition on the sources
C5: Type | D5: Source | E5: Country | F5: Date published | G5: Subject | H5: Date retrieved | I5: ETM Library URL | J5: Link
C7: Output product yields | D7: Geleynse et al. | F7: 2018 | G7: The Alcohol-to-Jet Conversion Pathway for Drop-In Biofuels: Techno-Economic Evaluation | H7: 14-10-2025 | J7: https://chemistry-europe.onlinelibrary.wiley.com/doi/abs/10.1002/cssc.201801690
C8: Plant size and costs
C10: Output product yields | D10: De Jong et al. | F10: 2018 | G10: Renewable jet fuel supply scenarios in the European Union in 2021–2030 in the context of proposed biofuel policy and competing biomass demand | H10: 14-10-2025 | J10: https://onlinelibrary.wiley.com/doi/10.1111/gcbb.12525
C11: full load hours
C13: Output product yields | D13: De Jong et al. | F13: 2015 | G13: The feasibility of short-term production strategies for renewable jet fuels – a comprehensive techno-economic comparison | H13: 14-10-2025 | J13: https://scijournals.onlinelibrary.wiley.com/doi/abs/10.1002/bbb.1613
C14: technical lifetime

Sheet Notes
B1: Overview
B2: typical input capacity | C2: =C27 -> 62.037037 | D2: MW
B3: full load hours | C3: =C21 -> 8000 | D3: hrs
B4: technical lifetime | C4: =C17 -> 25 | D4: yr
K5: De Jong et al. (2015)
B6: input.bio_ethanol | C6: =E77 -> 0.97404575
B7: input.hydrogen | C7: =E78 -> 0.025954252
B8: ouptut.bio_kerosene | C8: =E81 -> 0.70357759
B9: output.biodiesel | C9: =E82 -> 0.17330301
B11: investment costs | C11: =C37 -> 22194120 | D11: €
B12: fixed O&M | C12: =C38 -> 2616380 | D12: €/y
B13: variable O&M | C13: =C39 -> 360.88 | D13: €/flh
A16: De Jong et al. (2015)
B17: technical lifetime | C17: 25 | D17: yr
K19: De Jong et al. (2018)
A20: De Jong et al. (2018)
B21: full load hours | C21: 8000 | D21: h/yr
A25: Geleynse et al. (2018) | B25: Scale and costs
B26: production scale | C26: 200 | D26: tonne biothanol input / day
B27: typical input capacity | C27: =C26*10^3*C89/(24*60*60) -> 62.037037 | D27: MW
B29: Investment costs | C29: 24.6 | D29: million $
B30: fixed O&M | C30: 2.9 | D30: million $ / y
B31: variable O&M | C31: =2.7+0.5 -> 3.2 | D31: million $ /y
B32: variable O&M per flh | C32: =C31/C21 -> 0.0004 | D32: million $ /y
B34: euro per dollar | C34: 0.9022 | D34: euro per dollar 2024 | E34: https://www.ecb.europa.eu/stats/policy_and_exchange_rates/euro_reference_exchange_rates/html/eurofxref-graph-usd.en.html
B36: conversion
B37: Investment costs | C37: =C29*$C$34*10^6 -> 22194120 | D37: €
B38: fixed O&M | C38: =C30*$C$34*10^6 -> 2616380 | D38: €/y
B39: variable O&M per flh | C39: =C32*$C$34*10^6 -> 360.88 | D39: €/flh
B43: hydrogen required in hydrogenation process | K43: Geleynse et al. (2018):
B45: bioethanol input | C45: 185 | D45: t / day
B46: hydrogen input | C46: 1.1 | D46: t / day
B48: Conversion
B49: bioethanol input | C49: =C45*C89*10^3 -> 4958000 | D49: MJ / day
B50: hydrogen input | C50: =C46*C90*10^3 -> 132110 | D50: MJ / day
B51: ratio | C51: =C50/C49 -> 0.026645825 | D51: MJ hydrogen / MJ bioethanol
B54: feestock output
B55: product yield
B56: mass yield | C56: 0.6 | D56: t / t feedstock | E56: from Geleynse et al. (2018)
B57: mass yield | C57: 0.56 | D57: t / t feedstock | E57: from De Jong et al. (2015)
...
